Workbook

Sheet RESUMEN
A1: FACTURACIÓN ENTREGA DE DATAFONO A GESTORES
A2: 1 AL 3O DE DICIEMBRE 2025
A3: WOMPI
A4: CONCEPTOS | B4: CANTIDAD | C4: TOTAL
A5: ENTREGA DE DATAFONOS EN BODEGAS | B5: =COUNTA('ENTREGA DE DATAFONOS EN BODEGAS'!A:A)-1 -> 783 | C5: ='ENTREGA DE DATAFONOS EN BODEGAS'!W785 -> 60581744
A6: SUBTOTAL | C6: =SUM(C5:C5) -> 60581744
A7: Iva | C7: =C6*0.19 -> 11510531
A8: TOTAL | C8: =SUM(C6:C7) -> 72092275

Sheet BASE TARIFA 2025
A1: PROPONENTE | B1: TIPO ACTIVIDAD | C1: BODEGA | D1: CENTRO DE COSTOS | E1: ENTREGA DE DATAFONOS EN BODEGAS | F1: ENTREGA DE ROLLOS EN BODEGAS
A2: WOMPI (SOLICITUD ADICIONAL) | B2: ENTREGA DE DATAFONOS EN BODEGAS UBICADAS EN CIUDADES PRINCIPALES | C2: MEDELLIN | D2: WOMPI NOROCCIDENTE | E2: 37313 | F2: 15709.5
A3: WOMPI (SOLICITUD ADICIONAL) | B3: ENTREGA DE DATAFONOS EN BODEGAS UBICADAS EN CIUDADES PRINCIPALES | C3: BOGOTA | D3: WOMPI CENTRO | E3: 37313 | F3: 15709.5
A4: WOMPI (SOLICITUD ADICIONAL) | B4: ENTREGA DE DATAFONOS EN BODEGAS UBICADAS EN CIUDADES PRINCIPALES | C4: CALI | D4: WOMPI SUROCCIDENTE | E4: 37313 | F4: 15709.5
A5: WOMPI (SOLICITUD ADICIONAL) | B5: ENTREGA DE DATAFONOS EN BODEGAS UBICADAS EN CIUDADES PRINCIPALES | C5: PEREIRA | D5: WOMPI EJE CAFETERO | E5: 37313 | F5: 15709.5
A6: WOMPI (SOLICITUD ADICIONAL) | B6: ENTREGA DE DATAFONOS EN BODEGAS UBICADAS EN CIUDADES PRINCIPALES | C6: BARRANQUILLA | D6: WOMPI COSTA | E6: 37313 | F6: 15709.5
A7: WOMPI (SOLICITUD ADICIONAL) | B7: ENTREGA DE DATAFONOS EN BODEGAS UBICADAS EN CIUDADES PRINCIPALES | C7: BUCARAMANGA | D7: WOMPI SANTANDERES | E7: 37313 | F7: 15709.5
A8: WOMPI (SOLICITUD ADICIONAL) | B8: ENTREGA DE DATAFONOS EN BODEGAS UBICADAS EN CIUDADES PRINCIPALES | C8: MONTERIA | D8: WOMPI COSTA | E8: 37313 | F8: 15709.5
A9: WOMPI (SOLICITUD ADICIONAL) | B9: ENTREGA DE DATAFONOS EN BODEGAS UBICADAS EN CIUDADES REMOTAS CERTIFICADAS | C9: CUCUTA | D9: WOMPI SANTANDERES | E9: 49671.7 | F9: 28277.1
A10: WOMPI (SOLICITUD ADICIONAL) | B10: ENTREGA DE DATAFONOS EN BODEGAS UBICADAS EN CIUDADES REMOTAS CERTIFICADAS | C10: NEIVA | D10: WOMPI ORIENTE | E10: 49671.7 | F10: 28277.1
A11: WOMPI (SOLICITUD ADICIONAL) | B11: ENTREGA DE DATAFONOS EN BODEGAS UBICADAS EN CIUDADES REMOTAS CERTIFICADAS | C11: SANTA MARTA | D11: WOMPI COSTA | E11: 49671.7 | F11: 28277.1
A12: WOMPI (SOLICITUD ADICIONAL) | B12: ENTREGA DE DATAFONOS EN BODEGAS UBICADAS EN CIUDADES REMOTAS CERTIFICADAS | C12: TUNJA | D12: WOMPI SANTANDERES | E12: 49671.7 | F12: 28277.1
A13: WOMPI (SOLICITUD ADICIONAL) | B13: ENTREGA DE DATAFONOS EN BODEGAS UBICADAS EN CIUDADES REMOTAS CERTIFICADAS | C13: VILLAVICENCIO | D13: WOMPI ORIENTE | E13: 49671.7 | F13: 28277.1
... A23: WOMPI (SOLICITUD ADICIONAL) | B23: ENTREGA DE DATAFONOS EN BODEGAS UBICADAS EN CIUDADES REMOTAS NO CERTIFICADAS | C23: YOPAL | D23: WOMPI ORIENTE | E23: 49671.7 | F23: 28277.1

Sheet ENTREGA DE DATAFONOS EN BODEGAS
A1: Codigo_Punto | B1: Nombre_Punto | C1: Nit_CC_Persona | D1: TelefonoCB | E1: Celular_Contacto1 | F1: Celular_dueno | G1: Dirección_Establecimiento | H1: Latitud | I1: Longitud | J1: Departamento | K1: Municipio | L1: Corregimiento | M1: Codigo_Dane | N1: Fecha_Migracion | O1: Formulario | P1: Forma de atención | Q1: Descripción de la Solución | R1: Estado | S1: Cantidad de quipos por CB | T1: Bodega | U1: Centro_de_Costos | V1: Valor por datáfono | W1: valor total
A2: 15190 | B2: BARRIO CALATRAVA ITAGUI | C2: 70786438 | D2: 3762974 | E2: 3147834317 | F2: 3209825116 | G2: CR 59A 57-04 CALATRAVA | H2: 6.1796942 | I2: -75.6092411 | J2: ANTIOQUIA | K2: ITAGÜÍ | L2: ITAGÜÍ | M2: 5360 | N2: 2025-12-04 | S2: =VLOOKUP(A2,Hoja1!A:D,4,0) -> 4 | T2: =VLOOKUP(M2,[1]TIPOLOGIAS!$A:$F,4,0) -> MEDELLIN | U2: =VLOOKUP(T2,'BASE TARIFA 2025'!C:D,2,0) -> WOMPI NOROCCIDENTE | V2: =VLOOKUP(T2,'BASE TARIFA 2025'!C:F,3,0) -> 37313 | W2: =V2*S2 -> 149252
A3: 78376 | B3: BARRIO PLAZA MAYORISTA ITAGUI 1 | C3: 8353513 | D3: 3116351859 | E3: 3117912430 | F3: 3192876016 | G3: CL 85 48 1 BL 8 LC 16,CENTRAL MAYORISTA DE ANTIOQUIA | H3: 6.1891746 | I3: -75.5914119 | J3: ANTIOQUIA | K3: ITAGÜÍ | L3: ITAGÜÍ | M3: 5360 | N3: 2025-12-01 | S3: =VLOOKUP(A3,Hoja1!A:D,4,0) -> 2 | T3: =VLOOKUP(M3,[1]TIPOLOGIAS!$A:$F,4,0) -> MEDELLIN | U3: =VLOOKUP(T3,'BASE TARIFA 2025'!C:D,2,0) -> WOMPI NOROCCIDENTE | V3: =VLOOKUP(T3,'BASE TARIFA 2025'!C:F,3,0) -> 37313 | W3: =V3*S3 -> 74626
A4: 77534 | B4: BARRIO SAN JOSE ITAGUI 2 | C4: 901583748 | D4: 0 | E4: 3136046087 | F4: 3104251385 | G4: CL 36 A 38 30,SAN JOSE | H4: 6.1660099 | I4: -75.6135985 | J4: ANTIOQUIA | K4: ITAGÜÍ | L4: ITAGÜÍ | M4: 5360 | N4: 2025-12-01 | S4: =VLOOKUP(A4,Hoja1!A:D,4,0) -> 2 | T4: =VLOOKUP(M4,[1]TIPOLOGIAS!$A:$F,4,0) -> MEDELLIN | U4: =VLOOKUP(T4,'BASE TARIFA 2025'!C:D,2,0) -> WOMPI NOROCCIDENTE | V4: =VLOOKUP(T4,'BASE TARIFA 2025'!C:F,3,0) -> 37313 | W4: =V4*S4 -> 74626
A5: 77399 | B5: BARRIO ITAGUI ITAGUI 28 | C5: 28056870 | D5: 3117713940 | E5: 3117713940 | F5: 3208484493 | G5: CR 50 85 153 LC 1,ITAGUI | H5: 6.191957 | I5: -75.590091 | J5: ANTIOQUIA | K5: ITAGÜÍ | L5: ITAGÜÍ | M5: 5360 | N5: 2025-12-01 | S5: =VLOOKUP(A5,Hoja1!A:D,4,0) -> 3 | T5: =VLOOKUP(M5,[1]TIPOLOGIAS!$A:$F,4,0) -> MEDELLIN | U5: =VLOOKUP(T5,'BASE TARIFA 2025'!C:D,2,0) -> WOMPI NOROCCIDENTE | V5: =VLOOKUP(T5,'BASE TARIFA 2025'!C:F,3,0) -> 37313 | W5: =V5*S5 -> 111939
A6: 73721 | B6: BARRIO ITAGUI SANTA MARIA ITAGUI 1 | C6: 1129508911 | D6: 3192107219 | E6: 3192107219 | F6: 3192107219 | G6: CALLE 31 50 C 37,ITAGÜÍ SANTAMARÍA | H6: 6.1636230 | I6: -75.6242027 | J6: ANTIOQUIA | K6: ITAGÜÍ | L6: ITAGÜÍ | M6: 5360 | N6: 2025-12-01 | S6: =VLOOKUP(A6,Hoja1!A:D,4,0) -> 1 | T6: =VLOOKUP(M6,[1]TIPOLOGIAS!$A:$F,4,0) -> MEDELLIN | U6: =VLOOKUP(T6,'BASE TARIFA 2025'!C:D,2,0) -> WOMPI NOROCCIDENTE | V6: =VLOOKUP(T6,'BASE TARIFA 2025'!C:F,3,0) -> 37313 | W6: =V6*S6 -> 37313
A7: 72556 | B7: SAMARIA ITAGUI ANTIOQUIA | C7: 901340974 | D7: 2776243 | E7: 3136143749 | F7: 3136143749 | G7: CALLE 34 A 54 A 64,SAMARIA | H7: 6.1679867 | I7: -75.6245184 | J7: ANTIOQUIA | K7: ITAGÜÍ | L7: ITAGÜÍ | M7: 5360 | N7: 2025-12-03 | S7: =VLOOKUP(A7,Hoja1!A:D,4,0) -> 1 | T7: =VLOOKUP(M7,[1]TIPOLOGIAS!$A:$F,4,0) -> MEDELLIN | U7: =VLOOKUP(T7,'BASE TARIFA 2025'!C:D,2,0) -> WOMPI NOROCCIDENTE | V7: =VLOOKUP(T7,'BASE TARIFA 2025'!C:F,3,0) -> 37313 | W7: =V7*S7 -> 37313
A8: 44132 | B8: BARRIO ITAGUI ITAGUI 4 | C8: 800046457 | D8: 4445499 | E8: 3108442514 | F8: 3103741199 | G8: CL 72 42 - 33 LC 101 CE Capri Centro BRR La Esmeralda | H8: 6.1790439 | I8: -75.5930340 | J8: ANTIOQUIA | K8: ITAGÜÍ | L8: ITAGÜÍ | M8: 5360 | N8: 2025-12-01 | S8: =VLOOKUP(A8,Hoja1!A:D,4,0) -> 1 | T8: =VLOOKUP(M8,[1]TIPOLOGIAS!$A:$F,4,0) -> MEDELLIN | U8: =VLOOKUP(T8,'BASE TARIFA 2025'!C:D,2,0) -> WOMPI NOROCCIDENTE | V8: =VLOOKUP(T8,'BASE TARIFA 2025'!C:F,3,0) -> 37313 | W8: =V8*S8 -> 37313
A9: 46735 | B9: BARRIO ITAGUI ITAGUI 8 | C9: 900872708 | D9: 3720051 | E9: 3002919589 | F9: 3002919589 | G9: CL 49 48 52,ITAGUI | H9: 6.1704157 | I9: -75.6100435 | J9: ANTIOQUIA | K9: ITAGÜÍ | L9: ITAGÜÍ | M9: 5360 | N9: 2025-12-03 | S9: =VLOOKUP(A9,Hoja1!A:D,4,0) -> 2 | T9: =VLOOKUP(M9,[1]TIPOLOGIAS!$A:$F,4,0) -> MEDELLIN | U9: =VLOOKUP(T9,'BASE TARIFA 2025'!C:D,2,0) -> WOMPI NOROCCIDENTE | V9: =VLOOKUP(T9,'BASE TARIFA 2025'!C:F,3,0) -> 37313 | W9: =V9*S9 -> 74626
A10: 44593 | B10: BARRIO SANTA MARIA MEDELLIN | C10: 901340974 | D10: 2776243 | E10: 3195730489 | F10: 3195730489 | G10: CR 52 D 68 16,SANTA MARÍA | H10: 6.1828006 | I10: -75.6000425 | J10: ANTIOQUIA | K10: ITAGÜÍ | L10: ITAGÜÍ | M10: 5360 | N10: 2025-12-04 | S10: =VLOOKUP(A10,Hoja1!A:D,4,0) -> 1 | T10: =VLOOKUP(M10,[1]TIPOLOGIAS!$A:$F,4,0) -> MEDELLIN | U10: =VLOOKUP(T10,'BASE TARIFA 2025'!C:D,2,0) -> WOMPI NOROCCIDENTE | V10: =VLOOKUP(T10,'BASE TARIFA 2025'!C:F,3,0) -> 37313 | W10: =V10*S10 -> 37313
A11: 33798 | B11: BARRIO SAMARIA ITAGUI 2 | C11: 900014642 | D11: 3227815 | E11: 3218122144 | F11: 3217806471 | G11: CL 75 A A SUR 52 G 36 | H11: 6.1633840 | I11: -75.6351319 | J11: ANTIOQUIA | K11: ITAGÜÍ | L11: ITAGÜÍ | M11: 5360 | N11: 2025-12-03 | S11: =VLOOKUP(A11,Hoja1!A:D,4,0) -> 3 | T11: =VLOOKUP(M11,[1]TIPOLOGIAS!$A:$F,4,0) -> MEDELLIN | U11: =VLOOKUP(T11,'BASE TARIFA 2025'!C:D,2,0) -> WOMPI NOROCCIDENTE | V11: =VLOOKUP(T11,'BASE TARIFA 2025'!C:F,3,0) -> 37313 | W11: =V11*S11 -> 111939
A12: 37129 | B12: BARRIO ASTURIAS ITAGUI | C12: 10183532 | D12: 6125923 | E12: 3116266883 | F12: 3116266883 | G12: CL 47 48 13 ASTURIAS | H12: 6.16951777 | I12: -75.6110402 | J12: ANTIOQUIA | K12: ITAGÜÍ | L12: ITAGÜÍ | M12: 5360 | N12: 2025-12-01 | S12: =VLOOKUP(A12,Hoja1!A:D,4,0) -> 2 | T12: =VLOOKUP(M12,[1]TIPOLOGIAS!$A:$F,4,0) -> MEDELLIN | U12: =VLOOKUP(T12,'BASE TARIFA 2025'!C:D,2,0) -> WOMPI NOROCCIDENTE | V12: =VLOOKUP(T12,'BASE TARIFA 2025'!C:F,3,0) -> 37313 | W12: =V12*S12 -> 74626
A13: 34176 | B13: BARRIO PARQUE ITAGUI 5 | C13: 1037586135 | D13: 2819792 | E13: 3015133808 | F13: 3015133808 | G13: CR 50 50 66 LC 124 | H13: 6.1719033 | I13: -75.6090500 | J13: ANTIOQUIA | K13: ITAGÜÍ | L13: ITAGÜÍ | M13: 5360 | N13: 2025-12-03 | S13: =VLOOKUP(A13,Hoja1!A:D,4,0) -> 6 | T13: =VLOOKUP(M13,[1]TIPOLOGIAS!$A:$F,4,0) -> MEDELLIN | U13: =VLOOKUP(T13,'BASE TARIFA 2025'!C:D,2,0) -> WOMPI NOROCCIDENTE | V13: =VLOOKUP(T13,'BASE TARIFA 2025'!C:F,3,0) -> 37313 | W13: =V13*S13 -> 223878
... A18: 18551 | B18: BARRIO SIMON BOLIVAR II ITAGUI | C18: 71992351 | D18: 5992099 | E18: 3116075486 | F18: 3116075486 | G18: CR 45 A 65 27 SIMON BOLIVAR | H18: 6.1784909 | I18: -75.5972578 | J18: ANTIOQUIA | K18: ITAGÜÍ | L18: ITAGÜÍ | M18: 5360 | N18: 2025-12-04 | S18: =VLOOKUP(A18,Hoja1!A:D,4,0) -> 5 | T18: =VLOOKUP(M18,[1]TIPOLOGIAS!$A:$F,4,0) -> MEDELLIN | U18: =VLOOKUP(T18,'BASE TARIFA 2025'!C:D,2,0) -> WOMPI NOROCCIDENTE | V18: =VLOOKUP(T18,'BASE TARIFA 2025'!C:F,3,0) -> 37313 | W18: =V18*S18 -> 186565
A19: 78777 | B19: BARRIO SAN PEDRO BARRANQUILLA | C19: 1046398325 | D19: 3168688837 | E19: 3168688837 | G19: CR 6 LC1 # 102 -04 | H19: 10.9489988 | I19: -74.8329493 | J19: ATLÁNTICO | K19: BARRANQUILLA | L19: BARRANQUILLA | M19: 8001 | N19: 2025-12-05 | S19: =VLOOKUP(A19,Hoja1!A:D,4,0) -> 3 | T19: =VLOOKUP(M19,[1]TIPOLOGIAS!$A:$F,4,0) -> BARRANQUILLA | U19: =VLOOKUP(T19,'BASE TARIFA 2025'!C:D,2,0) -> WOMPI COSTA | V19: =VLOOKUP(T19,'BASE TARIFA 2025'!C:F,3,0) -> 37313 | W19: =V19*S19 -> 111939
A20: 77516 | B20: BARRIO GALAN BARRANQUILLA 6 | C20: 1140896804 | D20: 3022835339 | E20: 3015567707 | F20: 3022835339 | G20: CR 2 39 - 50 P1,GALAN | H20: 10.93495 | I20: -74.79484 | J20: ATLÁNTICO | K20: BARRANQUILLA | L20: BARRANQUILLA | M20: 8001 | N20: 2025-12-03 | S20: =VLOOKUP(A20,Hoja1!A:D,4,0) -> 2 | T20: =VLOOKUP(M20,[1]TIPOLOGIAS!$A:$F,4,0) -> BARRANQUILLA | U20: =VLOOKUP(T20,'BASE TARIFA 2025'!C:D,2,0) -> WOMPI COSTA | V20: =VLOOKUP(T20,'BASE TARIFA 2025'!C:F,3,0) -> 37313 | W20: =V20*S20 -> 74626
A21: 78064 | B21: BARRIO MERCEDES SUR BARRANQUILLA | C21: 8520914 | D21: 3027089849 | E21: 3027089849 | F21: 3205770977 | G21: CR 35 C 76 - 101,MERCEDES SUR | H21: 10.98476 | I21: -74.81783 | J21: ATLÁNTICO | K21: BARRANQUILLA | L21: BARRANQUILLA | M21: 8001 | N21: 2025-12-04 | S21: =VLOOKUP(A21,Hoja1!A:D,4,0) -> 2 | T21: =VLOOKUP(M21,[1]TIPOLOGIAS!$A:$F,4,0) -> BARRANQUILLA | U21: =VLOOKUP(T21,'BASE TARIFA 2025'!C:D,2,0) -> WOMPI COSTA | V21: =VLOOKUP(T21,'BASE TARIFA 2025'!C:F,3,0) -> 37313 | W21: =V21*S21 -> 74626
A22: 77514 | B22: BARRIO CENTRO BARRANQUILLA 52 | C22: 901526326 | D22: 3002141697 | E22: 3023702967 | F22: 3002141697 | G22: CL 40 41 - 83,CENTRO | H22: 10.98167 | I22: -74.78207 | J22: ATLÁNTICO | K22: BARRANQUILLA | L22: BARRANQUILLA | M22: 8001 | N22: 2025-12-04 | S22: =VLOOKUP(A22,Hoja1!A:D,4,0) -> 2 | T22: =VLOOKUP(M22,[1]TIPOLOGIAS!$A:$F,4,0) -> BARRANQUILLA | U22: =VLOOKUP(T22,'BASE TARIFA 2025'!C:D,2,0) -> WOMPI COSTA | V22: =VLOOKUP(T22,'BASE TARIFA 2025'!C:F,3,0) -> 37313 | W22: =V22*S22 -> 74626
A23: 77194 | B23: BARRIO VILLANUEVA BARRANQUILLA 1 | C23: 73550509 | D23: 3157119627 | E23: 3506423188 | F23: 3126652819 | G23: CR 43 08 - 48,VILLANUEVA | H23: 10.98165 | I23: -74.77303 | J23: ATLÁNTICO | K23: BARRANQUILLA | L23: BARRANQUILLA | M23: 8001 | N23: 2025-12-05 | S23: =VLOOKUP(A23,Hoja1!A:D,4,0) -> 2 | T23: =VLOOKUP(M23,[1]TIPOLOGIAS!$A:$F,4,0) -> BARRANQUILLA | U23: =VLOOKUP(T23,'BASE TARIFA 2025'!C:D,2,0) -> WOMPI COSTA | V23: =VLOOKUP(T23,'BASE TARIFA 2025'!C:F,3,0) -> 37313 | W23: =V23*S23 -> 74626
A24: 77215 | B24: BARRIO NUEVA GRANADA BARRANQUILLA 1 | C24: 8709578 | D24: 3237879555 | E24: 3237879555 | F24: 3237879555 | G24: CL 68 32 - 7,NUEVA GRANADA | H24: 10.98102 | I24: -74.80477 | J24: ATLÁNTICO | K24: BARRANQUILLA | L24: BARRANQUILLA | M24: 8001 | N24: 2025-12-04 | S24: =VLOOKUP(A24,Hoja1!A:D,4,0) -> 2 | T24: =VLOOKUP(M24,[1]TIPOLOGIAS!$A:$F,4,0) -> BARRANQUILLA | U24: =VLOOKUP(T24,'BASE TARIFA 2025'!C:D,2,0) -> WOMPI COSTA | V24: =VLOOKUP(T24,'BASE TARIFA 2025'!C:F,3,0) -> 37313 | W24: =V24*S24 -> 74626
A25: 77298 | B25: BARRIO EVARISTO SOURDIS BARRANQUILLA | C25: 1143259355 | D25: 3018014395 | E25: 3018014395 | F25: 3003610821 | G25: CR 9 G 70 C - 55,EVARISTO SOURDIS | H25: 10.95937 | I25: -74.82014 | J25: ATLÁNTICO | K25: BARRANQUILLA | L25: BARRANQUILLA | M25: 8001 | N25: 2025-12-03 | S25: =VLOOKUP(A25,Hoja1!A:D,4,0) -> 2 | T25: =VLOOKUP(M25,[1]TIPOLOGIAS!$A:$F,4,0) -> BARRANQUILLA | U25: =VLOOKUP(T25,'BASE TARIFA 2025'!C:D,2,0) -> WOMPI COSTA | V25: =VLOOKUP(T25,'BASE TARIFA 2025'!C:F,3,0) -> 37313 | W25: =V25*S25 -> 74626
A26: 76876 | B26: BARRIO 7 DE ABRIL BARRANQUILLA 3 | C26: 1042472912 | D26: 3245993871 | E26: 3002690327 | F26: 3245993871 | G26: CL 51 B 7 SUR - 44,7 DE ABRIL | H26: 10.92771 | I26: -74.81407 | J26: ATLÁNTICO | K26: BARRANQUILLA | L26: BARRANQUILLA | M26: 8001 | N26: 2025-12-04 | S26: =VLOOKUP(A26,Hoja1!A:D,4,0) -> 2 | T26: =VLOOKUP(M26,[1]TIPOLOGIAS!$A:$F,4,0) -> BARRANQUILLA | U26: =VLOOKUP(T26,'BASE TARIFA 2025'!C:D,2,0) -> WOMPI COSTA | V26: =VLOOKUP(T26,'BASE TARIFA 2025'!C:F,3,0) -> 37313 | W26: =V26*S26 -> 74626
A27: 74251 | B27: BARRIO ALTOS DEL PRADO BARRANQUILLA | C27: 901449900 | D27: 3017292085 | E27: 3245482276 | F27: 3017292085 | G27: CR 53 75-87,ALTOS DEL PRADO | H27: 11.0017917 | I27: -74.8053730 | J27: ATLÁNTICO | K27: BARRANQUILLA | L27: BARRANQUILLA | M27: 8001 | N27: 2025-12-04 | S27: =VLOOKUP(A27,Hoja1!A:D,4,0) -> 2 | T27: =VLOOKUP(M27,[1]TIPOLOGIAS!$A:$F,4,0) -> BARRANQUILLA | U27: =VLOOKUP(T27,'BASE TARIFA 2025'!C:D,2,0) -> WOMPI COSTA | V27: =VLOOKUP(T27,'BASE TARIFA 2025'!C:F,3,0) -> 37313 | W27: =V27*S27 -> 74626
A28: 75412 | B28: BARRIO LAS MALVINAS BARRANQUILLA 3 | C28: 72263142 | D28: 3104266711 | E28: 3004153169 | F28: 3104266711 | G28: CL 99 C 9 E - 43,LAS MALVINAS | H28: 10.95687 | I28: -74.83266 | J28: ATLÁNTICO | K28: BARRANQUILLA | L28: BARRANQUILLA | M28: 8001 | N28: 2025-12-03 | S28: =VLOOKUP(A28,Hoja1!A:D,4,0) -> 2 | T28: =VLOOKUP(M28,[1]TIPOLOGIAS!$A:$F,4,0) -> BARRANQUILLA | U28: =VLOOKUP(T28,'BASE TARIFA 2025'!C:D,2,0) -> WOMPI COSTA | V28: =VLOOKUP(T28,'BASE TARIFA 2025'!C:F,3,0) -> 37313 | W28: =V28*S28 -> 74626
A29: 73101 | B29: BARRIO LAS NIEVES BARRANQUILLA 5 | C29: 1129518575 | D29: 3008865988 | E29: 3004205276 | F29: 3004205276 | G29: CL 26 21-27,LAS NIEVES | H29: 10.95885 | I29: -74.78160 | J29: ATLÁNTICO | K29: BARRANQUILLA | L29: BARRANQUILLA | M29: 8001 | N29: 2025-12-02 | S29: =VLOOKUP(A29,Hoja1!A:D,4,0) -> 4 | T29: =VLOOKUP(M29,[1]TIPOLOGIAS!$A:$F,4,0) -> BARRANQUILLA | U29: =VLOOKUP(T29,'BASE TARIFA 2025'!C:D,2,0) -> WOMPI COSTA | V29: =VLOOKUP(T29,'BASE TARIFA 2025'!C:F,3,0) -> 37313 | W29: =V29*S29 -> 149252
A30: 74121 | B30: BARRIO CIUDADELA 20 DE JULIO BARRANQUILLA | C30: 1001945227 | D30: 3013911818 | E30: 3008093515 | F30: 3008093515 | G30: CL 45 D 01 F - 21,CIUDADELA 20 DE JULIO | H30: 10.93235 | I30: -74.80072 | J30: ATLÁNTICO | K30: BARRANQUILLA | L30: BARRANQUILLA | M30: 8001 | N30: 2025-12-02 | S30: =VLOOKUP(A30,Hoja1!A:D,4,0) -> 2 | T30: =VLOOKUP(M30,[1]TIPOLOGIAS!$A:$F,4,0) -> BARRANQUILLA | U30: =VLOOKUP(T30,'BASE TARIFA 2025'!C:D,2,0) -> WOMPI COSTA | V30: =VLOOKUP(T30,'BASE TARIFA 2025'!C:F,3,0) -> 37313 | W30: =V30*S30 -> 74626
A31: 74522 | B31: BARRIO LAS NIEVES BARRANQUILLA 6 | C31: 901678042 | D31: 3106669192 | E31: 3106669192 | F31: 3106700410 | G31: CR 11 23-107,LAS NIEVES | H31: 10.95023 | I31: -74.77793 | J31: ATLÁNTICO | K31: BARRANQUILLA | L31: BARRANQUILLA | M31: 8001 | N31: 2025-12-02 | S31: =VLOOKUP(A31,Hoja1!A:D,4,0) -> 2 | T31: =VLOOKUP(M31,[1]TIPOLOGIAS!$A:$F,4,0) -> BARRANQUILLA | U31: =VLOOKUP(T31,'BASE TARIFA 2025'!C:D,2,0) -> WOMPI COSTA | V31: =VLOOKUP(T31,'BASE TARIFA 2025'!C:F,3,0) -> 37313 | W31: =V31*S31 -> 74626
... A35: 69230 | B35: BARRIO LA UNION BARRANQUILLA 2 | C35: 1045674976 | D35: 3136607428 | E35: 0 | F35: 3136607428 | G35: CL 12 12 68,SECTOR EL HOSPITAL | H35: 5.9741124 | I35: -75.3642466 | J35: ANTIOQUIA | K35: LA UNIÓN | L35: LA UNIÓN | M35: 5400 | N35: 2025-11-07 | S35: =VLOOKUP(A35,Hoja1!A:D,4,0) -> 2 | T35: =VLOOKUP(M35,[1]TIPOLOGIAS!$A:$F,4,0) -> MEDELLIN | U35: =VLOOKUP(T35,'BASE TARIFA 2025'!C:D,2,0) -> WOMPI NOROCCIDENTE | V35: =VLOOKUP(T35,'BASE TARIFA 2025'!C:F,3,0) -> 37313 | W35: =V35*S35 -> 74626
A36: 66702 | B36: BARRIO CENTRO BARRANQUILLA 44 | C36: 1042440613 | D36: 3163088919 | E36: 3163088919 | G36: VRD QUIRBAQUIRA, SECTOR CASA BLANCA,VEREDA QUIRBAQUIRA | H36: 5.6912697 | I36: -73.3675628 | J36: BOYACÁ | K36: ARCABUCO | L36: ARCABUCO | M36: 15051 | N36: 2025-11-05 | S36: =VLOOKUP(A36,Hoja1!A:D,4,0) -> 2 | T36: =VLOOKUP(M36,[1]TIPOLOGIAS!$A:$F,4,0) -> TUNJA | U36: =VLOOKUP(T36,'BASE TARIFA 2025'!C:D,2,0) -> WOMPI SANTANDERES | V36: =VLOOKUP(T36,'BASE TARIFA 2025'!C:F,3,0) -> 49671.7 | W36: =V36*S36 -> 99343.4
A37: 64402 | B37: BARRIO GALAN BARRANQUILLA 2 | C37: 901192464 | D37: 3165362959 | E37: 3165362959 | F37: 3165362959 | G37: Carrera 5 # 3 - 31 Centro | H37: 5.454 | I37: -73.362 | J37: BOYACÁ | K37: BOYACÁ | L37: BOYACÁ | M37: 15104 | N37: 2025-11-13 | S37: =VLOOKUP(A37,Hoja1!A:D,4,0) -> 5 | T37: =VLOOKUP(M37,[1]TIPOLOGIAS!$A:$F,4,0) -> TUNJA | U37: =VLOOKUP(T37,'BASE TARIFA 2025'!C:D,2,0) -> WOMPI SANTANDERES | V37: =VLOOKUP(T37,'BASE TARIFA 2025'!C:F,3,0) -> 49671.7 | W37: =V37*S37 -> 248358.5
A38: 63348 | B38: BARRIO ZONA FRANCA BARRANQUILLA 1 | C38: 33172327 | D38: 3144233419 | E38: 3144233419 | F38: 3144233419 | G38: CR 4 A 3 85,CENTRO | H38: 5.4538173 | I38: -73.3630605 | J38: BOYACÁ | K38: BOYACÁ | L38: BOYACÁ | M38: 15104 | N38: 2025-11-13 | S38: =VLOOKUP(A38,Hoja1!A:D,4,0) -> 2 | T38: =VLOOKUP(M38,[1]TIPOLOGIAS!$A:$F,4,0) -> TUNJA | U38: =VLOOKUP(T38,'BASE TARIFA 2025'!C:D,2,0) -> WOMPI SANTANDERES | V38: =VLOOKUP(T38,'BASE TARIFA 2025'!C:F,3,0) -> 49671.7 | W38: =V38*S38 -> 99343.4
A39: 59489 | B39: BARRIO VILLA SAN PEDRO BARRANQUILLA 1 | C39: 8708961 | D39: 3225201619 | E39: 3225201619 | F39: 3225201619 | G39: CR 9 A 3 9,BOYACA BAJO | H39: 5.61052869 | I39: -73.82480853 | J39: BOYACÁ | K39: CHIQUINQUIRÁ | L39: CHIQUINQUIRÁ | M39: 15176 | N39: 2025-11-14 | S39: =VLOOKUP(A39,Hoja1!A:D,4,0) -> 2 | T39: =VLOOKUP(M39,[1]TIPOLOGIAS!$A:$F,4,0) -> TUNJA | U39: =VLOOKUP(T39,'BASE TARIFA 2025'!C:D,2,0) -> WOMPI SANTANDERES | V39: =VLOOKUP(T39,'BASE TARIFA 2025'!C:F,3,0) -> 49671.7 | W39: =V39*S39 -> 99343.4
A40: 54423 | B40: BARRIO CIUDADELA 20 DE JULIO BARRANQUILLA 10 | C40: 1042440613 | D40: 0 | E40: 3103830426 | F40: 3103830426 | G40: CL 42 A NR0. 8 -6 BRR LLERAS | H40: 6.4860518 | I40: -74.4055606 | J40: ANTIOQUIA | K40: PUERTO BERRÍO | L40: PUERTO BERRÍO | M40: 5579 | N40: 2025-11-06 | S40: =VLOOKUP(A40,Hoja1!A:D,4,0) -> 2 | T40: =VLOOKUP(M40,[1]TIPOLOGIAS!$A:$F,4,0) -> MEDELLIN | U40: =VLOOKUP(T40,'BASE TARIFA 2025'!C:D,2,0) -> WOMPI NOROCCIDENTE | V40: =VLOOKUP(T40,'BASE TARIFA 2025'!C:F,3,0) -> 37313 | W40: =V40*S40 -> 74626
A41: 80520 | B41: BARRIO LA QUINTA CARTAGENA DE INDIAS | C41: 901820974 | D41: 8330068 | E41: 3016209379 | F41: 3016209379 | G41: VRD LA MARGARITA,LA MARGARITA | H41: 6.495189 | I41: -74.474370 | J41: ANTIOQUIA | K41: PUERTO BERRÍO | L41: PUERTO BERRÍO | M41: 5579 | N41: 2025-11-06 | S41: =VLOOKUP(A41,Hoja1!A:D,4,0) -> 1 | T41: =VLOOKUP(M41,[1]TIPOLOGIAS!$A:$F,4,0) -> MEDELLIN | U41: =VLOOKUP(T41,'BASE TARIFA 2025'!C:D,2,0) -> WOMPI NOROCCIDENTE | V41: =VLOOKUP(T41,'BASE TARIFA 2025'!C:F,3,0) -> 37313 | W41: =V41*S41 -> 37313
A42: 78900 | B42: BARRIO MANGA CARTAGENA INDIAS | C42: 1007207649 | D42: 0 | E42: 3137979779 | F42: 3137979779 | G42: CR 3 57 97 | H42: 6.4928787 | I42: -74.399246 | J42: ANTIOQUIA | K42: PUERTO BERRÍO | L42: PUERTO BERRÍO | M42: 5579 | N42: 2025-11-07 | S42: =VLOOKUP(A42,Hoja1!A:D,4,0) -> 1 | T42: =VLOOKUP(M42,[1]TIPOLOGIAS!$A:$F,4,0) -> MEDELLIN | U42: =VLOOKUP(T42,'BASE TARIFA 2025'!C:D,2,0) -> WOMPI NOROCCIDENTE | V42: =VLOOKUP(T42,'BASE TARIFA 2025'!C:F,3,0) -> 37313 | W42: =V42*S42 -> 37313
A43: 10182 | B43: NOBSA - BOYACA | C43: 7218435 | D43: 3136557113 | E43: 3136557113 | F43: 3136557113 | G43: CALLE 50 7 20 BRR CENTRO,CENTRO | H43: 6.4896454 | I43: -74.4034766 | J43: ANTIOQUIA | K43: PUERTO BERRÍO | L43: PUERTO BERRÍO | M43: 5579 | N43: 2025-11-07 | S43: =VLOOKUP(A43,Hoja1!A:D,4,0) -> 1 | T43: =VLOOKUP(M43,[1]TIPOLOGIAS!$A:$F,4,0) -> MEDELLIN | U43: =VLOOKUP(T43,'BASE TARIFA 2025'!C:D,2,0) -> WOMPI NOROCCIDENTE | V43: =VLOOKUP(T43,'BASE TARIFA 2025'!C:F,3,0) -> 37313 | W43: =V43*S43 -> 37313
A44: 39438 | B44: BARRIO JERONIMO HOLGUIN NOBSA | C44: 7218435 | D44: 0 | E44: 3229306882 | F44: 3229306882 | G44: VRA MINAS DEL VAPOR - VDA MINAS DEL VAPOR ,VRA MINAS DEL VAPOR | H44: 6.4564882 | I44: -74.6306562 | J44: ANTIOQUIA | K44: PUERTO BERRÍO | L44: PUERTO BERRÍO | M44: 5579 | N44: 2025-11-10 | S44: =VLOOKUP(A44,Hoja1!A:D,4,0) -> 1 | T44: =VLOOKUP(M44,[1]TIPOLOGIAS!$A:$F,4,0) -> MEDELLIN | U44: =VLOOKUP(T44,'BASE TARIFA 2025'!C:D,2,0) -> WOMPI NOROCCIDENTE | V44: =VLOOKUP(T44,'BASE TARIFA 2025'!C:F,3,0) -> 37313 | W44: =V44*S44 -> 37313
A45: 71811 | B45: BARRIO CENTRO NOBSA | C45: 46383377 | D45: 8821750 | E45: 3103292709 | F45: 3103292709 | G45: CL 54 7-13 LA GRANJA | H45: 5.56117952 | I45: -73.34892293 | J45: BOYACÁ | K45: TUNJA | L45: TUNJA | M45: 15001 | N45: 2025-11-20 | S45: =VLOOKUP(A45,Hoja1!A:D,4,0) -> 1 | T45: =VLOOKUP(M45,[1]TIPOLOGIAS!$A:$F,4,0) -> TUNJA | U45: =VLOOKUP(T45,'BASE TARIFA 2025'!C:D,2,0) -> WOMPI SANTANDERES | V45: =VLOOKUP(T45,'BASE TARIFA 2025'!C:F,3,0) -> 49671.7 | W45: =V45*S45 -> 49671.7
A46: 51286 | B46: BARRIO BUENOS AIRES BARRANQUILLA 1 | C46: 1143135432 | D46: 3108181835 | E46: 3143145414 | F46: 3143145414 | G46: CR 8 B 58 05,SANTA RITA | H46: 5.5653133 | I46: -73.3478377 | J46: BOYACÁ | K46: TUNJA | L46: TUNJA | M46: 15001 | N46: 2025-11-05 | S46: =VLOOKUP(A46,Hoja1!A:D,4,0) -> 2 | T46: =VLOOKUP(M46,[1]TIPOLOGIAS!$A:$F,4,0) -> TUNJA | U46: =VLOOKUP(T46,'BASE TARIFA 2025'!C:D,2,0) -> WOMPI SANTANDERES | V46: =VLOOKUP(T46,'BASE TARIFA 2025'!C:F,3,0) -> 49671.7 | W46: =V46*S46 -> 99343.4
A47: 50827 | B47: BARRIO EL ROMANCE BARRANQUILLA | C47: 32836762 | D47: 3228080370 | E47: 3228080370 | F47: 3228080370 | G47: CR 9 20 09,CENTRO | H47: 5.53291885 | I47: -73.36089901 | J47: BOYACÁ | K47: TUNJA | L47: TUNJA | M47: 15001 | N47: 2025-11-20 | S47: =VLOOKUP(A47,Hoja1!A:D,4,0) -> 3 | T47: =VLOOKUP(M47,[1]TIPOLOGIAS!$A:$F,4,0) -> TUNJA | U47: =VLOOKUP(T47,'BASE TARIFA 2025'!C:D,2,0) -> WOMPI SANTANDERES | V47: =VLOOKUP(T47,'BASE TARIFA 2025'!C:F,3,0) -> 49671.7 | W47: =V47*S47 -> 149015.1
...

Sheet TD
A1: Centro_de_Costos | B1: Suma de valor total
A2: WOMPI CENTRO | B2: 10074510
A3: WOMPI COSTA | B3: 5060077.2
A4: WOMPI EJE CAFETERO | B4: 3120985.7
A5: WOMPI NOROCCIDENTE | B5: 4328308
A6: WOMPI ORIENTE | B6: 11176133
A7: WOMPI SANTANDERES | B7: 21812746
A8: WOMPI SUROCCIDENTE | B8: 5008984.1
A9: Total general | B9: 60581744

Sheet Hoja1
A1: CODIGO PUNTO DE SERVICIO | B1: cantidad_equipos | C1: Pinpad | D1: cantidad equipos
A2: 10007 | B2: =+VLOOKUP(#REF!,'[2]Inverntario Redeban'!#REF!,2,0) -> #REF! | C2: =+VLOOKUP(#REF!,'[2]Inverntario Redeban'!#REF!,3,0) -> #REF! | D2: =B2+C2 -> #REF!
A3: 10015 | B3: 1 | C3: 1 | D3: =B3+C3 -> 2
A4: 10016 | B4: 1 | C4: 1 | D4: =B4+C4 -> 2
A5: 10018 | B5: 3 | C5: 0 | D5: =B5+C5 -> 3
A6: 10023 | B6: 1 | C6: 0 | D6: =B6+C6 -> 1
A7: 10024 | B7: 3 | C7: 3 | D7: =B7+C7 -> 6
A8: 10028 | B8: 1 | C8: 0 | D8: =B8+C8 -> 1
A9: 10029 | B9: 3 | C9: 2 | D9: =B9+C9 -> 5
A10: 10030 | B10: 2 | C10: 0 | D10: =B10+C10 -> 2
A11: 10032 | B11: 2 | C11: 2 | D11: =B11+C11 -> 4
A12: 10033 | B12: 1 | C12: 0 | D12: =B12+C12 -> 1
A13: 10035 | B13: 4 | C13: 1 | D13: =B13+C13 -> 5
A14: 10036 | B14: 1 | C14: 0 | D14: =B14+C14 -> 1
... A17890: 81253 | B17890: 1 | C17890: 0 | D17890: =B17890+C17890 -> 1
