Workbook
Name A: #REF!
Name Actividad: [1]Formulas!$H$2:$H$5000
Name arearesponsable: '[2]Listas desplegables'!$BB$2:$BB$100
Name Clientes: [1]Clientes!$A$2:$A$100
Name COORDINADOR: [3]Hoja2!$D$2:$D$30
Name Coordinadores: [1]Coordinadores!$A$2:$A$1000
Name DOCUMENTADOR: [3]Hoja2!$A$2:$A$30
Name ES: [3]Hoja2!$K$2:$K$30
Name ESS: [3]Hoja2!$K$2:$K$30
Name Estado: [1]Formulas!$K$2:$K$5000
Name ESTADOACTIVIDAD: [3]Hoja2!$M$2:$M$30
Name ESTADOS: '[4]Listas desplegables'!$B$1:$D$1
Name ESTADOSCIERRES: '[5]lista desplegable'!$CX$1:$DA$1
Name Facturacion: '[6]Listas desplegables'!$AO$1:$AR$1
Name FACTURACIÓN: '[4]Listas desplegables'!$Y$1:$AB$1
Name falla: #REF!
Name Fallas: '[7]Listas desplegables'!$F$2:$L$2
Name Grupo_Falla: '[8]Listas Desplegables'!$CH$2:$CH$5
Name inconservmanager: '[9]Listas desplegables'!$BC$2:$BC$100
Name INCUMPLIMIENTO: '[2]Listas desplegables'!$AK$1:$AN$1
Name LISTA: [10]Dptos!$A$1139:$A$1171
Name LISTA2: #REF!
Name LOLO: [11]Coordinadores!$A$2:$A$1000
Name solicitudes: '[12]Listas desplegables'!$AF$1:$AQ$1
Name Tecnicos: [1]Tecnicos!$A$2:$A$1000
Name Version: [1]Formulas!$I$2:$I$3

Sheet BASE LIQUIDACION
A1: TARIFAS 2025 | E1: Incremento 2025
A2: Tipificación | B2: Descripción | C2: Dia actividad Exitosa | D2: Dia actividad Fallida | E2: 0.052
A3: Tipo I | B3: Metropolitano | C3: =62700.07*(1+$E$2) -> 65960.474 | D3: =42357.4*(1+$E$2) -> 44559.985
A4: Tipo II | B4: Hasta 3 horas | C4: =155716.31*(1+$E$2) -> 163813.56 | D4: =127766.53*(1+$E$2) -> 134410.39
A5: Tipo III | B5: De 3 a 5 horas | C5: =262099.22*(1+$E$2) -> 275728.38 | D5: =211886.19*(1+$E$2) -> 222904.27
A6: Tipo IV | B6: Más de 5 horas | C6: =455883.78*(1+$E$2) -> 479589.74 | D6: =441833.68*(1+$E$2) -> 464809.03
A7: Destino aereo | B7: No incluye valor del Tiquete | C7: =455883.78*(1+$E$2) -> 479589.74 | D7: =441833.68*(1+$E$2) -> 464809.03
A8: *Donde se requiera transporte aéreo o fluvial se factura adicional a tarifa TIPO IV el valor del tiquete + el 12% de admon.
A10: Gestión Telefónica | B10: =36031.04*(1+$E$2) -> 37904.654
A11: Mts Acometida electrica | B11: =30182.1*(1+$E$2) -> 31751.569
A12: Mts Acometida datos | B12: =15432.22*(1+$E$2) -> 16234.695
A13: switche | B13: =244669.03*(1+$E$2) -> 257391.82
A14: Router | B14: =291399.51*(1+$E$2) -> 306552.28
A15: Envio operador Logistico | B15: =53547.34*(1+$E$2) -> 56331.802

Sheet RESUMEN LIQUIDACIONES
A1: LÍNEA COMUNICACIONES S.A.S | F1: FACTURACIÓN CORRESPONSALES BANCARIOS TIQUIETES AEREOS
A2: FACTURACIÓN PROYECTO CB BANCOLOMBIA | F2: =A3 -> 45960
A3: 45960
F4: CONCEPTOS | G4: TRAYECTOS | H4: TOTAL | I4: % Administración | J4: TOTAL
A5: CONCEPTOS | B5: CANTIDAD | C5: VALOR UNITARIO | D5: VALOR TOTAL | F5: INCIDENTE 2890962 | G5: ARAUCA-SARAVENA-ARAUCA | H5: =416200+565450 -> 981650 | I5: =H5*0.12 -> 117798 | J5: =H5+I5 -> 1099448
A6: Adecuaciones CB | B6: =COUNTA(ADECUCACIONES!A:A)-1 -> 20 | C6: 0 | D6: =ADECUCACIONES!AE22 -> 2624774 | I6: =H6*0.12 -> 0 | J6: =H6+I6 -> 0
A7: Incidentes | B7: =COUNTA(INCIDENTES!A:A)-1 -> 114 | C7: 0 | D7: =INCIDENTES!AH116 -> 13289236 | I7: =H7*0.12 -> 0 | J7: =H7+I7 -> 0
A8: Ordenes de Cambio | B8: =COUNTA(OC!A:A)-1 -> 10 | C8: 0 | D8: =OC!AG12 -> 561069 | I8: =H8*0.12 -> 0 | J8: =H8+I8 -> 0
A9: Tiquetes | B9: 0 | C9: 0 | D9: =J12 -> 1099448 | I9: =H9*0.12 -> 0 | J9: =H9+I9 -> 0
A10: SUBTOTAL | D10: =SUM(D6:D9) -> 17574527 | I10: =H10*0.12 -> 0 | J10: =H10+I10 -> 0
A11: Iva | D11: =D10*0.19 -> 3339160.1 | I11: =H11*0.12 -> 0 | J11: =H11+I11 -> 0
A12: TOTAL | D12: =D10+D11 -> 20913687 | F12: TOTAL | H12: =SUM(H5:H11) -> 981650 | I12: =SUM(I5:I11) -> 117798 | J12: =SUM(J5:J11) -> 1099448

Sheet ADECUCACIONES
A1: CIUDAD SEDE | B1: ZONA | C1: CENTRO DE COSTOS LINEACOM | D1: CODIGO DANE | E1: TA/CODIGO ACTIVIDAD | F1: CODIGO CB | G1: ACTIVIDAD | H1: TIPO DE APERTURA | I1: DEPARTAMENTO | J1: CIUDAD | K1: NOMBRE DEL CB | L1: RED | M1: FO | N1: FECHA LISTA | O1: FECHA ULTIMA ACTUALIZACION | P1: FORMATO | Q1: CADENA | R1: ESTADO | S1: OBSERVACIONES CLIENTE | T1: FORMA DE ATENCION | U1: TERMINAL(ES) | V1: TIPIFICACION | W1: TIPO DE TRAYECTO | X1: NOMBRE DEL TECNICO | Y1: ACOMETIDA DATOS | Z1: ACOMETIDA ELECTRICA | AA1: SWITCH | AB1: ROUTER | AC1: VALOR DIAS ACTIVIDAD FACTURABLES | AD1: DIAS ACTIVIDAD FACTURABLES | AE1: VALOR TOTAL INSTALACION DE PUBLICIDAD
A2: PASTO | B2: SUROCCIDENTE Y EJE CAFETERO | C2: 0004-0003 | D2: 86568 | E2: TA-25-1145877 | F2: 3007081676 | G2: APERTURA | H2: CB CRECIMIENTO ALIANZA - NUEVO | I2: PUTUMAYO | J2: PUERTO ASIS | K2: DISTRICOL FERRETERIA PRADO HC | L2: REDEBAN | M2: FO-25-1577758 | N2: 45924.619 | O2: 45932.457 | P2: AGREGADOR | Q2: DISTRICOL | R2: EJECUTADO/CANCELADO | S2: 24/09/2025 24-09 PROGRAMACIÓN REALIZADA POR LA ALIANZA | 30/09/2025 NO SE OGRA LLEGAR EL DIA DE HOY A SITIO POR PROBLEMAS EN LAS VIAS , SE LLEGARA EL DIA DE MAÑANA PARA ATENCION DE ACTIVIDADES | 02/10/2025 SE VISITA EL COMERCIO PARA REVISAR APERTURA DEL CORRESPONSAL PERO NO ES POSIBLE POR DIRECCIÓN ERRADA, EN CÁMARA DE COMERCIO APARECE DIRECCIÓN CR 27 CL 22 BRR EL PRADO Y EL COMERCIO ESTÁ UBICADO EN DIRECCIÓN CRA 22 # 27 POR LO TANTO SE CANCELA LA INSTALACIÓN | T2: VISITA TECNICA | V2: TIPO IV | W2: TERRESTRE | X2: GUERRERO RAMIREZ OSCAR DARIO | Y2: 0 | Z2: 0 | AA2: 0 | AB2: 0 | AC2: 1 | AD2: 464809 | AE2: 464809
A3: CALI | B3: SUROCCIDENTE Y EJE CAFETERO | C3: 0004-0003 | D3: 76001 | E3: TA-25-1157236 | F3: 3007081704 | G3: APERTURA | H3: CB CRECIMIENTO ALIANZA - NUEVO | I3: VALLE DEL CAUCA | J3: CALI | K3: DISTRICOL DISTRIB EL GRANJERO | L3: REDEBAN | M3: FO-25-1598686 | N3: 45929.697 | O3: 45952.646 | P3: AGREGADOR | Q3: DISTRICOL | R3: EJECUTADO/CANCELADO | S3: 29/09/2025 29-09 PROGRAMACIÓN REALIZADA POR LA ALIANZA | 22/10/2025 SE LLAMA AL CLIENTE SE VÁLIDA LA INFORMACIÓN, DISPONIBILIDAD Y LUGAR DE LA DIRECCIÓN DE LA INSTALACIÓN, SE LLEGA AL COMERCIO SE EVIDENCIA PROXIMIDAD 30 MTS CON OTRO CORRESPONSAL 1 A 1 AL FRENTE CB 40569 BARRIO LA BUITRERA EL PORTENTO CALI, EL CASO SE ESCALA PARA CONSULTAR LA INSTALACIÓN DE AUTORIZACIÓN | T3: VISITA TECNICA | V3: TIPO I | W3: TERRESTRE | X3: HERRERA MONAR GEOVANNY | Y3: 0 | Z3: 0 | AA3: 0 | AB3: 0 | AC3: 1 | AD3: 44560 | AE3: 44560
A4: MEDELLIN | B4: NOROCCIDENTE | C4: 0004-0005 | D4: 5360 | E4: TA-25-1165179 | F4: 3007081728 | G4: APERTURA | H4: CB CRECIMIENTO ALIANZA - NUEVO | I4: ANTIOQUIA | J4: ITAGUI | K4: DISTRICOL RG | L4: REDEBAN | M4: FO-25-1624400 | FO-25-1611140 | N4: 45931.707 | O4: 45936.61 | P4: AGREGADOR | Q4: DISTRICOL | R4: EJECUTADO | EJECUTADO/CANCELADO | S4: 06/10/2025 SE INSTALA CORRESPONSAL OK | T4: VISITA TECNICA | U4: SUZZZ674 | V4: TIPO I | W4: TERRESTRE | X4: RUA ALVAREZ RICHARD ANDRES | Y4: 0 | Z4: 0 | AA4: 0 | AB4: 0 | AC4: 1 | AD4: 44560 | AE4: 44560
A5: CALI | B5: SUROCCIDENTE Y EJE CAFETERO | C5: 0004-0003 | D5: 19698 | E5: TA-25-1165186 | F5: 3007081737 | G5: APERTURA | H5: CB CRECIMIENTO ALIANZA - NUEVO | I5: CAUCA | J5: SANTANDER DE QUILICHAO | K5: DISTRICOL DANICELL PLUS | L5: REDEBAN | M5: FO-25-1611165 | N5: 45931.741 | O5: 45932.625 | P5: AGREGADOR | Q5: DISTRICOL | R5: EJECUTADO/CANCELADO | S5: 01/10/2025 01-10 PROGRAMACIÓN REALIZADA POR LA ALIANZA | 02/10/2025 SE REALIZA VISITA TÉCNICA PERO AL MOMENTO DE INICIALIZAR EL EQUIPO ARROJA ERROR EN CONEXIÓN SE COMPRUEBAN CONEXIONES Y TODO OK, EL COMERCIO NO CUENTA CON INTERNET EN EL MOMENTO SE ESPERAN AL REDEDOR DE 30-40MIN PERO EL PROBLEMA NO ES SOLUCIONADO, EL CLIENTE VALIDA CON EL PROVEEDOR DE INTERNET PERO INDICA QUE NO TIENE FECHA DE SOLUCION. | T5: VISITA TECNICA | V5: TIPO II | W5: TERRESTRE | X5: MONTERO MUESES GIAN CARLO | Y5: 0 | Z5: 0 | AA5: 0 | AB5: 0 | AC5: 1 | AD5: 134410 | AE5: 134410
A6: PASTO | B6: SUROCCIDENTE Y EJE CAFETERO | C6: 0004-0003 | D6: 52687 | E6: TA-25-1165197 | F6: 3007081735 | G6: APERTURA | H6: CB CRECIMIENTO ALIANZA - NUEVO | I6: NARIÑO | J6: SAN LORENZO | K6: DISTRICOL PIPE CELL | L6: REDEBAN | M6: FO-25-1611190 | N6: 45931.698 | O6: 45937.377 | P6: AGREGADOR | Q6: DISTRICOL | R6: EJECUTADO/CANCELADO | S6: 01/10/2025 01-10 PROGRAMACIÓN REALIZADA POR LA ALIANZA | 02/10/2025 NO SE PUEDE REALIZAR DESPLAZAMIENTO A SITIO POR FALTA DE TRANSPORTE Y CUPO, EL CUAL INFORMAN QUE SOLO SALE EN UNA JORNADA DEL MEDIO DÍA Y NO SE ENCUENTRA DISPONIBILIDAD EN HORARIO DE LA MAÑANA, SE LLAMÓ AL CLIENTE INFORMANDO QUE APENAS HAYA TRANSPORTE O CUPO A SITIO SE PROGRAMARÁ LA VISITA | 07/10/2025 SE VISITO E COMERCIO PARA INSTALAR CB NO ES POSIBIE POR DIRECCION ERRADA YA QUE EN SYTEX APARECE CR 3 MZ 10 LADO D CA 22 BRR CENTRO Y EN FACTURA DE SERVICIOS PUBLICOS APARECE CRA 3 M2 10 LADO D CASA 23 POR LO QUE SE CANCELA LA INSTALACION. TAMPOCO ES POSIBLE VALIDAR CON CAMARA DE COMERCIO PORQUE CUENTA CON UNA DIRECCIÓN DIFERENTE | T6: VISITA TECNICA | V6: TIPO II | W6: TERRESTRE | X6: GUERRERO RAMIREZ OSCAR DARIO | Y6: 0 | Z6: 0 | AA6: 0 | AB6: 0 | AC6: 1 | AD6: 134410 | AE6: 134410
A7: BOGOTA | B7: CUNDINAMARCA | C7: 0004-0004 | D7: 11001 | E7: TA-25-1165210 | F7: 3007081717 | G7: APERTURA | H7: CB CRECIMIENTO ALIANZA - NUEVO | I7: CUNDINAMARCA | J7: BOGOTA | K7: DISTRICOL TODO A LA MANO | L7: REDEBAN | M7: FO-25-1611242 | N7: 45931.333 | O7: 45932.518 | P7: AGREGADOR | Q7: DISTRICOL | R7: EJECUTADO/CANCELADO | S7: 01/10/2025 01-10 PROGRAMACIÓN REALIZADA POR LA ALIANZA | 02/10/2025 DURANTE LA IMPLEMENTACIÓN DE CORRESPONSAL BANCARIO AL LLEGAR SE EVIDENCIA QUE COMERCIO SU ACTIVIDAD ECONÓMICA ES DE JUEGOS DE AZAR Y APUESTAS LO CUAL, IMPIDE REALIZAR LA IMPLEMENTACIÓN DE CORRESPONSAL, SE REALIZA ESCALAMIENTO A LA ENTIDAD NOS ENCONTRAMOS A LA ESPERA DE RESPUESTA DE LA MISMA PARA REALIZAR CANCELACIÓN DE LA IMPLEMENTACIÓN O CONTINUAR CON LA MISMA SE BRINDA INFORMACIÓN A COMERCIO | T7: VISITA TECNICA | V7: TIPO I | W7: TERRESTRE | X7: GALEANO SORIANO JUAN DAVID | Y7: 0 | Z7: 0 | AA7: 0 | AB7: 0 | AC7: 1 | AD7: 44560 | AE7: 44560
A8: BOGOTA | B8: CUNDINAMARCA | C8: 0004-0004 | D8: 11001 | E8: TA-25-1165214 | F8: 3007081718 | G8: APERTURA | H8: CB CRECIMIENTO ALIANZA - NUEVO | I8: CUNDINAMARCA | J8: BOGOTA | K8: DISTRICOL TODO EN UNO SUBA | L8: REDEBAN | M8: FO-25-1611245 | N8: 45931.5 | O8: 45932.592 | P8: AGREGADOR | Q8: DISTRICOL | R8: EJECUTADO/CANCELADO | S8: 01/10/2025 01-10 PROGRAMACIÓN REALIZADA POR LA ALIANZA | 02/10/2025 SE VISITA COMERCIO PARA REALIZAR LA INSTALACIÓN DEL CB BANCOLOMBIA RBM, SE EVIDENCIA QUE LA DIRECCIÓN DADA EN LA ORDEN ES (CR 103B #152-32) PERO ESTÁ DIRECCIÓN NO ES LA REAL YA QUE LA CORRECTA DONDE ESTÁ EL ESTABLECIMIENTO ES (CR 103B #152-35) EN LA ACERA DE EN FRENTE, LA CÁMARA Y COMERCIO SI TIENE LA DIRECCIÓN DE LA ORDEN PERO LA DIRECCIÓN DADA SE SITÚA EN EL PATIO DE DESCANSO DE UN COLEGIO, TAMBIÉN SE VÁLIDA Y EL ESTABLECIMIENTO CUENTA COMO ACTIVIDAD REALIZAR APUESTAS (LOTERÍA Y CHANCE) ALGO POR LO QUE NO ESTÁ PERMITIDO REALIZAR INSTALACIÓN EN DICHOS COMERCIOS, SE ESCALA AL COORDINADOR Y A RBM Y LUEGO DAN RESPUESTA DE NO INSTALAR, SE LE EXPLICA LA SITUACION AL CLIENTE Y ENTIENDE. | T8: VISITA TECNICA | V8: TIPO I | W8: TERRESTRE | X8: VEGA MANRIQUE JONATAN MAURICIO | Y8: 0 | Z8: 0 | AA8: 0 | AB8: 0 | AC8: 1 | AD8: 44560 | AE8: 44560
A9: NEIVA | B9: REMOTAS | C9: 0004-0007 | D9: 41319 | E9: TA-25-1194778 | F9: 3007081860 | G9: APERTURA | H9: CB CRECIMIENTO ALIANZA - NUEVO | I9: HUILA | J9: GUADALUPE | K9: PTM GUADALUPE VARIEDADES ANDRE | L9: REDEBAN | M9: FO-25-1666972 | N9: 45940.315 | O9: 45945.482 | P9: AGREGADOR | Q9: COMCARD - PTM | R9: EJECUTADO/CANCELADO | S9: 10/10/2025 9/10/2025 PROGRAMACIÓN REALIZADA POR LA ALIANZA| INSTALACIÓN PROGRAMADA PARA EL 2025-10-15 | 15/10/2025 SE REALIZA VISITA PARA IMPLEMENTAR CB PTM 81860, PERO SE EVIDENCIA QUE APROXIMADAMENTE 40 MTS HAY UN CB UNO A UNO INSTALADO (35020), SE ESCALA CASO A ENTIDAD DONDE FUE CANCELADA POR LA MISMA | T9: VISITA TECNICA | V9: TIPO III | W9: TERRESTRE | X9: ANDRADE HERNANDEZ JUAN CARLOS | Y9: 0 | Z9: 0 | AA9: 0 | AB9: 0 | AC9: 1 | AD9: 222904 | AE9: 222904
A10: PASTO | B10: SUROCCIDENTE Y EJE CAFETERO | C10: 0004-0003 | D10: 52001 | E10: TA-25-1194785 | F10: 3007081861 | G10: APERTURA | H10: CB CRECIMIENTO ALIANZA - NUEVO | I10: NARIÑO | J10: PASTO | K10: PTM PASTO R&R STORE | L10: REDEBAN | M10: FO-25-1687223 | FO-25-1666979 | N10: 45940.734 | O10: 45946.548 | P10: AGREGADOR | Q10: COMCARD - PTM | R10: EJECUTADO | EJECUTADO/CANCELADO | S10: 16/10/2025 SE REALIZÓ LA INSTALACIÓN DE EQUIPOS PUBLICIDAD Y ACCESORIOS PARA APERTURA CB BANCOLOMBIA SE DIO CAPACITACIÓN MANEJO DE DATÁFONO CB Y SOMOS BANCOLOMBIA SE EJECUTAN PRUEBAS TX EXITOSAS QUEDA OPERATIVO | T10: VISITA TECNICA | U10: VWZZZ800 // VYZZZ068 | V10: TIPO I | W10: TERRESTRE | X10: REMICIO AMADO JOHN HEBER | Y10: 0 | Z10: 0 | AA10: 0 | AB10: 0 | AC10: 1 | AD10: 44560 | AE10: 44560
A11: BUCARAMANGA | B11: SANTANDERES | C11: 0004-0008 | D11: 68276 | E11: TA-25-1194794 | F11: 3007081858 | G11: APERTURA | H11: CB CRECIMIENTO ALIANZA - NUEVO | I11: SANTANDER | J11: FLORIDABLANCA | K11: PTM FLORIDABLANCA TIENDA LA AN | L11: REDEBAN | M11: FO-25-1683636 | FO-25-1666991 | N11: 45940.442 | O11: 45946.618 | P11: AGREGADOR | Q11: COMCARD - PTM | R11: EJECUTADO | EJECUTADO/CANCELADO | S11: 15/10/2025 LUEGO DE CONTESTACION EMITIDA POR LA RED NOS INDICAN QUE SE PROCEDERA CON UN CAMBIO DE TERMINALES SE PROCEDERA CON LA CULMINACIÓN DE LA ACTIVIDAD UNA VEZ INFORME LA RED SE ESTABLECE CONTACTO CON LA USUARIA QUE A LA VEZ NOS INDICA QUE NOS PODRÁ ATENDER EL DÍA MAÑANA SIN NINGÚN PROBLEMA | 16/10/2025 SE REALIZA INSTALACIÓN DE AVISO EXTERIOR FLANGER DISPLAY LEGAL IDENTIFICADOR DE PUNTO BASE DATÁFONO LECTORA CAMBIO DE SISTEMA OPERATIVO INVERSION 9.90 CREACIÓN DE USUARIOS CAPACITACIÓN ADMINISTRATIVA OPERATIVA PRUEBAS OK SERVICIO OPERATIVO | T11: VISITA TECNICA | U11: VYZZZ063 / VWZZZ803 | V11: TIPO I | W11: TERRESTRE | X11: ECHEVERRI ECHEVERRI EVELIN DANIELA | Y11: 0 | Z11: 0 | AA11: 0 | AB11: 0 | AC11: 1 | AD11: 44560 | AE11: 44560
A12: CALI | B12: SUROCCIDENTE Y EJE CAFETERO | C12: 0004-0003 | D12: 76001 | E12: TA-25-1194800 | F12: 3007081855 | G12: APERTURA | H12: CB CRECIMIENTO ALIANZA - NUEVO | I12: VALLE DEL CAUCA | J12: CALI | K12: PTM CALI PAPELERIA Y VARIEDADE | L12: REDEBAN | M12: FO-25-1686966 | FO-25-1667001 | N12: 45940.713 | O12: 45946.249 | P12: AGREGADOR | Q12: COMCARD - PTM | R12: EJECUTADO | EJECUTADO/CANCELADO | S12: 15/10/2025 SE INSTALA DATÁFONO SE CAPACITA AL CLIENTE SE ENTREGAN ROLLOS SE HACEN PRUEBAS CB QUEDA FUNCIONANDO CORRECTAMENTE NO SE HACEN MÁS PRUEBAS YA QUE CLIENTE NO TENÍA TARJETA BANCOLOMBIA Y LA DEL TECNICO ESTABA BLOQUEADA | T12: VISITA TECNICA | U12: VWZZZ805 - VYZZZ065 | V12: TIPO I | W12: TERRESTRE | X12: CUERO RUIZ JHONNY | Y12: 0 | Z12: 0 | AA12: 0 | AB12: 0 | AC12: 1 | AD12: 44560 | AE12: 44560
A13: SANTA MARTA | B13: COSTA | C13: 0004-0001 | D13: 44090 | E13: TA-25-1220622 | F13: 3007081877 | G13: APERTURA | H13: CB CRECIMIENTO ALIANZA - NUEVO | I13: LA GUAJIRA | J13: DIBULLA | K13: PTM DIBULLA PAPELERIA Y VARIED | L13: REDEBAN | M13: FO-25-1706158 | N13: 45950.333 | O13: 45952.556 | P13: AGREGADOR | Q13: COMCARD - PTM | R13: EJECUTADO/CANCELADO | S13: 20/10/2025 20-10 PROGRAMACIÓN REALIZADA POR LA ALIANZA| INSTALACIÓN PROGRAMADA PARA EL 2025-10-21 | 21/10/2025 SE REALIZA GESTIÓN TELEFÓNICA, EL USUARIO INFORMA QUE EN EL DÍA DE HOY EL MUNICIPIO NO CONTARÁ CON SERVICIO ELÉCTRICO YA QUE LA VAN A QUITAR DURANTE TODO EL DÍA, QUE SE REPROGRAME LA INSTALACIÓN PARA EL MIÉRCOLES 22 | 22/10/2025 NO SE PUEDE REALIZAR LA APERTURA POR DIRECCIÓN ERRADA YA QUE LA DIRECCIÓN EN EL SISTEMA APARECE DIFERENTE AL DEL PUNTO, SE ESCALA EL CASO CON EL COORDINADOR Y SE CANCELA LA INSTALACIÓN | T13: VISITA TECNICA | V13: TIPO III | W13: TERRESTRE | X13: THOMAS CAMPO SIGIFREDO SEGUNDO | Y13: 0 | Z13: 0 | AA13: 0 | AB13: 0 | AC13: 1 | AD13: 222904 | AE13: 222904
A14: BOGOTA | B14: CUNDINAMARCA | C14: 0004-0004 | D14: 11001 | E14: TA-25-1220633 | F14: 3007081873 | G14: APERTURA | H14: CB CRECIMIENTO ALIANZA - NUEVO | I14: CUNDINAMARCA | J14: BOGOTA | K14: PTM BOGOTA FLAG MART | L14: REDEBAN | M14: FO-25-1716863 | FO-25-1706191 | N14: 45950.333 | O14: 45953.287 | P14: AGREGADOR | Q14: COMCARD - PTM | R14: EJECUTADO | EJECUTADO/CANCELADO | S14: 22/10/2025 SE REALIZA LA INSTALACIÓN DEL CB PTM BOGOTA FLAG MARY, EL CLIENTE Y TÉCNICO NO MANEJAN TARJETA BANCOLOMBIA SE REALIZAN PRUEBAS ENVIANDO Y RETIRANDO POR NEQUI | T14: VISITA TECNICA | U14: AE001940 | V14: TIPO I | W14: TERRESTRE | X14: ALARCON AREVALO JOHAN STIVEN | Y14: 0 | Z14: 0 | AA14: 0 | AB14: 0 | AC14: 1 | AD14: 44560 | AE14: 44560
A15: CALI | B15: SUROCCIDENTE Y EJE CAFETERO | C15: 0004-0003 | D15: 76001 | E15: TA-25-1229179 | F15: 3007081937 | G15: APERTURA | H15: CB CRECIMIENTO ALIANZA - NUEVO | I15: VALLE DEL CAUCA | J15: CALI | K15: PTM CALI SKYNET 2.2 | L15: REDEBAN | M15: FO-25-1718419 | N15: 45952.715 | O15: 45954.647 | P15: AGREGADOR | Q15: COMCARD - PTM | R15: EJECUTADO/CANCELADO | S15: 22/10/2025 22-10 PROGRAMACIÓN REALIZADA POR LA ALIANZA| INSTALACIÓN PROGRAMADA PARA EL 2025-10-24 | 24/10/2025 SE CANCELA LA APERTURA POR DIRECCIÓN ERRADA, LA DIRECCIÓN CORRECTA ES CALLE 39A # 43 - 03 QUE ES OA DIRECCIÓN DE LA CAMARA Y COMERCIO Y LA DIRECCIÓN DE LA ORDEN ES KRA 39A # 43 - 03 | T15: VISITA TECNICA | V15: TIPO I | W15: TERRESTRE | X15: PAREDES CASTILLO DIEGO | Y15: 0 | Z15: 0 | AA15: 0 | AB15: 0 | AC15: 1 | AD15: 44560 | AE15: 44560
A16: MEDELLIN | B16: NOROCCIDENTE | C16: 0004-0005 | D16: 5001 | E16: TA-25-1247954 | F16: 3007082076 | G16: APERTURA | H16: CB CRECIMIENTO ALIANZA - NUEVO | I16: ANTIOQUIA | J16: MEDELLIN | K16: DISTRICOL CANO TIENDA | L16: REDEBAN | M16: FO-25-1751685 | N16: 45959.881 | O16: 45961.287 | P16: AGREGADOR | Q16: DISTRICOL | R16: EJECUTADO/CANCELADO | S16: 29/10/2025 29-10 PROGRAMACIÓN REALIZADA POR LA ALIANZA| INSTALACIÓN PROGRAMADA PARA EL 2025-10-30 | 30/10/2025 VISITA FALLIDA SE LLEGA A LA DIRECCIÓN DADA Y NO SE ENCUENTRA EL COMERCIO INDICADO PARA LA INSTALACIÓN TAMPOCO CONOCEN LA PERSONA Y NO CONTESTAN LLAMADAS NI WPP EN EL NÚMERO DE CONTACTO SE ESTÁ EN LA DIRECCIÓN Y LOCAL CORRECTO PERO NO SABEN NADA SOBRE LA INSTALACIÓN | T16: VISITA TECNICA | V16: TIPO I | W16: TERRESTRE | X16: PAREJA ECHAVARRIA JHON DAVID | Y16: 0 | Z16: 0 | AA16: 0 | AB16: 0 | AC16: 1 | AD16: 44560 | AE16: 44560
A17: MEDELLIN | B17: NOROCCIDENTE | C17: 0004-0005 | D17: 5736 | E17: TA-25-1247964 | F17: 3007082061 | G17: APERTURA | H17: CB CRECIMIENTO ALIANZA - NUEVO | I17: ANTIOQUIA | J17: SEGOVIA | K17: DISTRICOL PLANETARIO 2000 | L17: REDEBAN | M17: FO-25-1751719 | N17: 45959.882 | O17: 45961.484 | P17: AGREGADOR | Q17: DISTRICOL | R17: EJECUTADO/CANCELADO | S17: 29/10/2025 29-10 PROGRAMACIÓN REALIZADA POR LA ALIANZA| INSTALACIÓN PROGRAMADA PARA EL 2025-10-31 | 31/10/2025 SE LLEGA A PUNTO Y EN DIRECCIÓN NO SE ENCUENTRA LOCAL, SE COMUNICA CON CLIENTE Y NO BRINDA UBICACIÓN DEL PUNTO, SE CANCELA | T17: VISITA TECNICA | V17: TIPO IV | W17: TERRESTRE | X17: QUINTERO SANCHEZ JUAN SEBASTIAN | Y17: 0 | Z17: 0 | AA17: 0 | AB17: 0 | AC17: 1 | AD17: 464809 | AE17: 464809
A18: PASTO | B18: SUROCCIDENTE Y EJE CAFETERO | C18: 0004-0003 | D18: 52001 | E18: TA-25-1247984 | F18: 3007082052 | G18: APERTURA | H18: CB CRECIMIENTO ALIANZA - NUEVO | I18: NARIÑO | J18: PASTO | K18: DISTRICOL AS SER TRANS ON LINE | L18: REDEBAN | M18: FO-25-1751773 | N18: 45959.681 | O18: 45961.555 | P18: AGREGADOR | Q18: DISTRICOL | R18: EJECUTADO/CANCELADO | S18: 29/10/2025 29-10 PROGRAMACIÓN REALIZADA POR LA ALIANZA| INSTALACIÓN PROGRAMADA PARA EL 2025-10-31 | 31/10/2025 SE LLEGÓ AL PUNTO PARA EJECUTAR LA IMPLEMENTACIÓN DE CB BANCOLOMBIA POR PARTE DE LA ALIANZA DISTRICOL PERO SE ENCONTRÓ OTRO CORRESPONSAL A MENOS DE 50 M POR LO QUE SE ESCALÓ LA NOVEDAD A RBM Y BANCOLOMBIA NOTIFICANDO A LA HORA QUE LA IMPLEMENTACIÓN DEBE SER CANCELADA SE NOTIFICA AL CLIENTE EL MOTIVO POR EL CUAL NO SE HACE LA IMPLEMENTACIÓN, NO SE ENTREGA NINGÚN ELEMENTO POR ACTIVIDAD CANCELADA. | T18: VISITA TECNICA | V18: TIPO I | W18: TERRESTRE | X18: REMICIO AMADO JOHN HEBER | Y18: 0 | Z18: 0 | AA18: 0 | AB18: 0 | AC18: 1 | AD18: 44560 | AE18: 44560
A19: PASTO | B19: SUROCCIDENTE Y EJE CAFETERO | C19: 0004-0003 | D19: 52378 | E19: TA-25-1247988 | F19: 3007082041 | G19: APERTURA | H19: CB CRECIMIENTO ALIANZA - NUEVO | I19: NARIÑO | J19: LA CRUZ | K19: DISTRICOL MASCOTIENDA LA CRUZ | L19: REDEBAN | M19: FO-25-1751783 | N19: 45959.684 | O19: 45961.715 | P19: AGREGADOR | Q19: DISTRICOL | R19: EJECUTADO/CANCELADO | S19: 29/10/2025 29-10 PROGRAMACIÓN REALIZADA POR LA ALIANZA| INSTALACIÓN PROGRAMADA PARA EL 2025-10-31 | 31/10/2025 SE VISITA CLIENTE EN UBICACIÓN INDICADA POR ELLA YA QUE EN ZONA NO HAY NOMENCLATURA. AL LLEGAR AL COMERCIO SE EVIDENCIA QUE EL NOMBRE DEL COMERCIO ES FARMACENTER LA HUMANIDAD 2 Y NO MASCOTIENDA LA CRUZ. SE SOLICITA CÁMARA DE COMERCIO Y EN ELLA EL NOMBRE ES MASCOTIENDA LA CRUZ Y LA DIRECCIÓN ES LA MISMA DEL CORREO ELECTRÓNICO. SE ESCALA A REDEBAN Y LA RESPUESTA ES QUE NO SE PROCEDA A INSTALAR YA QUE LA CÁMARA DE COMERCIO NO COINCIDE CON EL COMERCIO QUE SE VISITA. SE CANCELA INSTALACION PORQUE NOMBRE DE COMERCIO NO COINCIDE CON CAMARA DE COMERCIO | T19: VISITA TECNICA | V19: TIPO III | W19: TERRESTRE | X19: CASTILLO HERRERA ALEX RICARDO | Y19: 0 | Z19: 0 | AA19: 0 | AB19: 0 | AC19: 1 | AD19: 222904 | AE19: 222904
A20: PEREIRA | B20: SUROCCIDENTE Y EJE CAFETERO | C20: 0004-0002 | D20: 66001 | E20: TA-25-1247994 | F20: 3007082056 | G20: APERTURA | H20: CB CRECIMIENTO ALIANZA - NUEVO | I20: RISARALDA | J20: PEREIRA | K20: DISTRICOL PAPELERIA ALAN JU | L20: REDEBAN | M20: FO-25-1751801 | N20: 45959.641 | O20: 45960.581 | P20: AGREGADOR | Q20: DISTRICOL | R20: EJECUTADO/CANCELADO | S20: 29/10/2025 29-10 PROGRAMACIÓN REALIZADA POR LA ALIANZA| INSTALACIÓN PROGRAMADA PARA EL 2025-10-30 | 30/10/2025 SE LLEGA AL PUNTO, SE EVIDENCIA QUE HAY OTRO CB UNO A UNO CERCA, SE ESCALA CON RBM EL CASO Y SE QUEDA A LA ESPERA DE UNA RESPUESTA. | T20: VISITA TECNICA | V20: TIPO I | W20: TERRESTRE | X20: FRANCO CAÑAVERAL YAMID RAUL | Y20: 0 | Z20: 0 | AA20: 0 | AB20: 0 | AC20: 1 | AD20: 44560 | AE20: 44560
A21: SINCELEJO | B21: COSTA | C21: 0004-0001 | D21: 70708 | E21: TA-25-1247995 | F21: 3007082064 | G21: APERTURA | H21: CB CRECIMIENTO ALIANZA - NUEVO | I21: SUCRE | J21: SAN MARCOS | K21: DISTRICOL DROGUERÍA FARMASUCRE | L21: REDEBAN | M21: FO-25-1751804 | N21: 45959.485 | O21: 45961.57 | P21: AGREGADOR | Q21: DISTRICOL | R21: EJECUTADO/CANCELADO | S21: 29/10/2025 29-10 PROGRAMACIÓN REALIZADA POR LA ALIANZA| INSTALACIÓN PROGRAMADA PARA EL 2025-10-31 | 31/10/2025 SE VISITA COMERCIO PARA INSTALACIÓN DEL CB, PERO NO ES POSIBLE REALIZAR LA APERTURA YA QUE SE ESCALÓ EL CASO CON RBM, PUESTO QUE EL BARRIO NO CONCUERDA CON EL DE LA ORDEN DE SERVICIO, LA RESPUESTA DADA POR LA ENTIDAD ES CANCELAR LA IMPLEMENTACIÓN. | T21: VISITA TECNICA | V21: TIPO III | W21: TERRESTRE | X21: CACERES HERNANDEZ ANDRES | Y21: 0 | Z21: 0 | AA21: 0 | AB21: 0 | AC21: 1 | AD21: 222904 | AE21: 222904
AE22: =SUM(AE2:AE21) -> 2624774

Sheet INCIDENTES
A1: CIUDAD SEDE | B1: ZONA | C1: CENTRO DE COSTOS LINEACOM | D1: CODIGO DANE | E1: TA/CODIGO ACTIVIDAD | F1: CODIGO CB | G1: ACTIVIDAD | H1: DEPARTAMENTO | I1: CIUDAD | J1: NOMBRE DEL CB | K1: RED | L1: FO | M1: FECHA ASIGNACION A LINEA COMUNICACIONES | N1: FECHA CIERRE DEL TICKET (DD/MM/AAAA HH:MM) | O1: ACOMETIDA | P1: GRUPO_FALLA | Q1: CATEGORIA | R1: FALLA | S1: FORMATO | T1: CADENA | U1: ESTADO | V1: OBSERVACION | W1: FORMA DE ATENCION | X1: TERMINAL(ES) | Y1: TIPIFICACION | Z1: TIPO DE TRAYECTO | AA1: NOMBRE DEL TECNICO | AB1: DIAS DE VISITA | AC1: ACOMETIDA DATOS | AD1: ACOMETIDA ELÉCTRICA | AE1: SWITCH | AF1: ROUTER | AG1: VALOR DIAS ACTIVIDAD FACTURABLES | AH1: VALOR DIAS ACOMPAÑAMIENTO FACTURABLES
A2: NEIVA | B2: REMOTAS | C2: 0004-0007 | D2: 41349 | E2: 2807230 | F2: 3007031383 | G2: INCIDENTE | H2: HUILA | I2: HOBO | J2: BARRIO LOS PINOS | K2: REDEBAN | L2: FO-25-1607884 | FO-25-1598160 | M2: 45929.441 | N2: 45931.434 | O2: NO | P2: ENTIDAD | Q2: ERROR DE TRANSACCIONES | R2: TRANSACCION NO PERMITIDA | S2: CB UNO A UNO | T2: CB UNO A UNO | U2: EJECUTADO | EJECUTADO / CANCELADO | V2: 01/10/2025 SE REALIZA VISITA AL PUNTO NUEVAMENTE YA QUE ESTE HABIA QUEDADO EN RECHAZO GENERAL DESPUÉS DEL CAMBIO QUE SE REALIZO POR DAÑO, RG QUE NO SE PUDO GESTIONAR POR FALTA DE SOPORTE POR HORA . SE REALIZA GESTIÓN CON RBM SE INICIALIZA EQUIPO SE REALIZAN PRUEBAS EXITOSAS. SE DEJA EQUIPO CON VR 10.3 PRUEBAS CB OK . ***SE REALIZA LLAMADA A LA LÍNEA DEL BANCO 018000953344, LOS CUALES INDICAN QUE EL PUNTO SE ENCONTRABA BLOQUEADO POR RAZONES SE ASUNTOS INTERNOS, SE DESBLOQUEA PUNTO SE REALIZAN PRUEBAS PERO EN LA LÍNEA INDICAN QUE POSIBLEMENTE LO VOVERAN A BLOQUEAR. SE LE INDICA AL CLIENTE QUE SI ESTO OCURRE DEBE COMUNICACARSE DIRECTAMENTE A LA LÍNEA Y VALIDAR EL MOTIVO DEL BLOQEO . | W2: VISITA TECNICA | X2: BL01Y558 | Y2: TIPO II | Z2: TERRESTRE | AA2: DEVIA REINOSO JUAN CARLOS | AB2: 1 | AC2: 0 | AD2: 0 | AE2: 0 | AF2: 0 | AG2: 163814 | AH2: 163814
A3: CUCUTA | B3: SANTANDERES | C3: 0004-0008 | D3: 54874 | E3: 2813895 | F3: 3007071930 | G3: INCIDENTE | H3: NORTE DE SANTANDER | I3: VILLA DEL ROSARIO | J3: PTM LA PALMITA VILLA DEL ROSAR | K3: REDEBAN | L3: FO-25-1603466 | M3: 45930.414 | N3: 45931.413 | O3: NO | P3: ENTIDAD | Q3: ERROR DE TRANSACCIONES | R3: TRANSACCION NO PERMITIDA | S3: AGREGADOR | T3: COMCARD - PTM | U3: CANCELADO | V3: 30/09/2025 SE ESCALA PARA VISITA. LLAMAR ANTES DE VISITAR, CONFIRMAR FALLA Y DATOS | 01/10/2025 SE REALIZA VISITA, COMERCIO NO EXISTEN EN LA DIRECCIÓN, SE INTENTA CONTACTAR TELEFÓNICAMENTE AL CLIENTE PERO NO RESPONDE, SE VALIDA CON RBM Y LA DIRECCIÓN DE ENCUENTRA CORRECTA Y NO EXISTE INFORMACIÓN DE SOLICITUD DE TRASLADO. | W3: VISITA TECNICA | X3: NONE - NONE | Y3: TIPO I | Z3: TERRESTRE | AA3: PACHECO BUITRAGO JAVIER ALONSO | AB3: 1 | AC3: 0 | AD3: 0 | AE3: 0 | AF3: 0 | AG3: 65960 | AH3: 65960
A4: SINCELEJO | B4: COSTA | C4: 0004-0001 | D4: 70742 | E4: 2818336 | F4: 3007046075 | G4: INCIDENTE | H4: SUCRE | I4: SAN LUIS DE SINCE | J4: PTM SAN LUIS DE SINCE PUNTO SE | K4: REDEBAN | L4: FO-25-1607028 | M4: 45930.709 | N4: 45931.585 | O4: NO | P4: USUARIO | Q4: CIERRE | R4: COMERCIO NO REALIZA CIERRE | S4: AGREGADOR | T4: COMCARD - PTM | U4: EJECUTADO | V4: 30/09/2025 SE ESCALA PARA VISITA. LLAMAR ANTES DE VISITAR, CONFIRMAR FALLA Y DATOS | 01/10/2025 SE VISITA SITIO SE VERIFICA INFORMACIÓN, SE REALIZA PRIMEROS AUXILIOS, CB CON CIERRE ACUMULADO NO IMPRIME, SE REALIZA CIERRE DE TRANS, SE RETROALIMENTA EN EL PROCESO CIERRE, LA FALLA REPORTADA CORRESPONDE A QUE EL OPERARIO REALIZA LA OPERACIÓN DE RECAUDO POR DEPOSITO CTA CTE. SE REALIZA PRUEBA PRUEBAS TRX EXITOSAS. | W4: VISITA TECNICA | X4: XP004617 | Y4: TIPO II | Z4: TERRESTRE | AA4: SANTOS GUZMAN CHRISTIAN FELIPE | AB4: 1 | AC4: 0 | AD4: 0 | AE4: 0 | AF4: 0 | AG4: 163814 | AH4: 163814
A5: BOGOTA | B5: CUNDINAMARCA | C5: 0004-0004 | D5: 25754 | E5: 2818811 | F5: 3007068813 | G5: INCIDENTE | H5: CUNDINAMARCA | I5: SOACHA | J5: BARRIO HOGAR DEL SOL SOACHA SO | K5: REDEBAN | L5: FO-25-1608422 | M5: 45931.333 | N5: 45931.485 | O5: NO | P5: USUARIO | Q5: MANTENIMIENTO | R5: MANTENIMIENTO GENERAL | S5: CB UNO A UNO | T5: CB UNO A UNO | V5: 01/10/2025 SE PROCEDE A CERRAR ESTE CASO YAQUE QUEDO MAL CREADO YA QUE EL CB ES WOMPI Y QUEDO COMO REDEBAN, SE LE INFORMA AL USUARIO QUE SE DEBE COMUNICAR DE NUEVO PARA GENERAR OTRO RADICADO | 01/10/2025 SE PROCEDE A CERRAR ESTE CASO YAQUE QUEDO MAL CREADO YA QUE EL CB ES WOMPI Y QUEDO COMO REDEBAN, SE LE INFORMA AL USUARIO QUE SE DEBE COMUNICAR DE NUEVO PARA GENERAR OTRO RADICADO | 01/10/2025 SE PROCEDE A CERRAR ESTE CASO YAQUE QUEDO MAL CREADO YA QUE EL CB ES WOMPI Y QUEDO COMO REDEBAN, SE LE INFORMA AL USUARIO QUE SE DEBE COMUNICAR DE NUEVO PARA GENERAR OTRO RADICADO | 01/10/2025 SE PROCEDE A CERRAR ESTE CASO YAQUE QUEDO MAL CREADO YA QUE EL CB ES WOMPI Y QUEDO COMO REDEBAN, SE LE INFORMA AL USUARIO QUE SE DEBE COMUNICAR DE NUEVO PARA GENERAR OTRO RADICADO | W5: SOPORTE TELEFONICO | Y5: TIPO I | Z5: TERRESTRE | AA5: ORTIZ MARTINEZ STIVEN | AB5: 0 | AC5: 0 | AD5: 0 | AE5: 0 | AF5: 0 | AG5: 37905 | AH5: 37905
A6: YOPAL | B6: REMOTAS | C6: 0004-0007 | D6: 85001 | E6: 2821677 | F6: 3007036905 | G6: INCIDENTE | H6: CASANARE | I6: YOPAL | J6: BARRIO YOPAL CASANARE | K6: REDEBAN | L6: FO-25-1609710 | M6: 45931.448 | N6: 45931.959 | O6: NO | P6: USUARIO | Q6: CIERRE | R6: COMERCIO NO REALIZA CIERRE | S6: CB UNO A UNO | T6: CB UNO A UNO | V6: 01/10/2025 SE ESCALA PARA VISITA. LLAMAR ANTES DE VISITAR, CONFIRMAR FALLA Y DATOS | 01/10/2025 EN COMUNICACIÓN CON LA SEÑORA LAURA SIERRA AL NUMERO 3145591437, SE ORIENTA PARA REALIZAR EL BORRADO TRANS. SE LE INDICA EL PROCESO PARA REALIZAR LOS CIERRES TODOS LOS DIAS. | W6: SOPORTE TELEFONICO | Y6: TIPO I | Z6: TERRESTRE | AA6: BERNAL ELAICA EDGAR ALEXIS | AB6: 0 | AC6: 0 | AD6: 0 | AE6: 0 | AF6: 0 | AG6: 37905 | AH6: 37905
A7: CUCUTA | B7: SANTANDERES | C7: 0004-0008 | D7: 54874 | E7: 2822103 | F7: 3007080549 | G7: INCIDENTE | H7: NORTE DE SANTANDER | I7: VILLA DEL ROSARIO | J7: BARRIO TRAPICHES VILLA DEL ROSARIO | K7: REDEBAN | L7: FO-25-1610689 | M7: 45931.462 | N7: 45931.963 | O7: NO | P7: USUARIO | Q7: MANTENIMIENTO | R7: MANTENIMIENTO GENERAL | S7: UNO A UNO | T7: UNO A UNO | U7: EJECUTADO | V7: 01/10/2025 SE ESCALA PARA VISITA. LLAMAR ANTES DE VISITAR, CONFIRMAR FALLA Y DATOS | 01/10/2025 SE REALIZA VISITA, SE REALIZA MANTENIMIENTO, SE REALIZAN PRUEBAS Y CIERRES OK | W7: VISITA TECNICA | X7: SEZZZ162 | Y7: TIPO I | Z7: TERRESTRE | AA7: PACHECO BUITRAGO JAVIER ALONSO | AB7: 1 | AC7: 0 | AD7: 0 | AE7: 0 | AF7: 0 | AG7: 65960 | AH7: 65960
A8: MEDELLIN | B8: NOROCCIDENTE | C8: 0004-0005 | D8: 5615 | E8: 2823798 | F8: 3007074672 | G8: INCIDENTE | H8: ANTIOQUIA | I8: RIONEGRO | J8: PTM LLANOGRANDE MEDELLIN PAPEL | K8: REDEBAN | L8: FO-25-1611652 | M8: 45931.612 | N8: 45933.495 | O8: NO | P8: USUARIO | Q8: COMUNICACION | R8: CANAL DEL COMERCIO | S8: AGREGADOR | T8: COMCARD - PTM | U8: EJECUTADO | V8: 01/10/2025 SE ESCALA PARA VISITA. LLAMAR ANTES DE VISITAR, CONFIRMAR FALLA Y DATOS | 03/10/2025 SE REALIZA VALIDACIÓN DEL CB SE HACEN PRUEBAS OK , SE LLEGA Y USUARIO E UD OCA QUE HABÍA SOLICITADO CAMBIO PERO DEL DATAFONO DEL COMERCIO | W8: VISITA TECNICA | X8: LNQZZ022 | Y8: TIPO II | Z8: TERRESTRE | AA8: MONTOYA VELEZ ANDRES FELIPE | AB8: 1 | AC8: 0 | AD8: 0 | AE8: 0 | AF8: 0 | AG8: 163814 | AH8: 163814
A9: CALI | B9: SUROCCIDENTE Y EJE CAFETERO | C9: 0004-0003 | D9: 76126 | E9: 2823985 | F9: 3007079619 | G9: INCIDENTE | H9: VALLE DEL CAUCA | I9: CALIMA | J9: BARRIO OBRERO CALIMA | K9: REDEBAN | L9: FO-25-1611647 | M9: 45931.617 | N9: 45932.646 | O9: NO | P9: USUARIO | Q9: MANTENIMIENTO | R9: MANTENIMIENTO GENERAL | S9: CB UNO A UNO | T9: CB UNO A UNO | U9: EJECUTADO | V9: 01/10/2025 SE ESCALA PARA VISITA. LLAMAR ANTES DE VISITAR, CONFIRMAR FALLA Y DATOS | 02/10/2025 SE VISITA CORRESPONSAL Y SE RECONFIGURA DATÁFONO. TRANSACCIONES DE PRUEBA EXITOSAS. | W9: VISITA TECNICA | X9: SXUZZ145 | Y9: TIPO II | Z9: TERRESTRE | AA9: BOLAÑOS TABORDA JORGE ENRIQUE | AB9: 1 | AC9: 0 | AD9: 0 | AE9: 0 | AF9: 0 | AG9: 163814 | AH9: 163814
A10: CALI | B10: SUROCCIDENTE Y EJE CAFETERO | C10: 0004-0003 | D10: 76001 | E10: 2826164 | F10: 3007059017 | G10: INCIDENTE | H10: VALLE DEL CAUCA | I10: CALI | J10: REDY GUADALUPE | K10: REDEBAN | L10: FO-25-1613641 | M10: 45932.333 | N10: 45932.64 | O10: NO | P10: USUARIO | Q10: MANTENIMIENTO | R10: MANTENIMIENTO GENERAL | S10: ROBUSTO | T10: REDY | U10: EJECUTADO / CANCELADO | V10: 02/10/2025 SE ESCALA PARA VISITA. LLAMAR ANTES DE VISITAR | 02/10/2025 SE REALIZA VISITA TÉCNICA EN DONDE SE ENTREGA EL CARNET Y SE ESPERA 45 MINUTOS EN DONDE NO LE DAN RESPUESTA DE INGRESO Y SE PROCEDE A CERRAR, SE LE INDICA AL CLIENTE QUE POR FAVOR VUELVA A REPORTAR PARA QUE LE GENEREN OTRA VISITA | W10: VISITA TECNICA | X10: NO | Y10: TIPO I | Z10: TERRESTRE | AA10: ESCOBAR LENIS JUAN SEBASTIAN | AB10: 1 | AC10: 0 | AD10: 0 | AE10: 0 | AF10: 0 | AG10: 65960 | AH10: 65960
A11: CALI | B11: SUROCCIDENTE Y EJE CAFETERO | C11: 0004-0003 | D11: 19256 | E11: 2827571 | F11: 3007066562 | G11: INCIDENTE | H11: CAUCA | I11: EL TAMBO | J11: BARRIO LA CAPILLA EL TAMBO | K11: REDEBAN | L11: FO-25-1614205 | M11: 45932.373 | N11: 45934.44 | O11: NO | P11: USUARIO | Q11: COMUNICACION | R11: CANAL DEL COMERCIO | S11: CB UNO A UNO | T11: CB UNO A UNO | V11: 02/10/2025 SE REALIZAN 3 INTENTOS DE LLAMADA AL NUMERO DE CONTACTO 3226466689 PERO NO FUE POSIBLE LA COMUNICACION | 04/10/2025 SE VALIDA CON EL CLIENTE POR PROBLEMAS DE CONEXION , SE LE INDICA QUE POR FAVOR REALIZR REINICIO DEL ROUTER DE INTENET, EL CLIENTE REALIZA LO PERTIENENTE Y CONFIRMA SERVICIO Y OPERATIVIDAD DEL DATAFONO, SE CIERRA CASO | W11: SOPORTE TELEFONICO | Y11: TIPO III | Z11: TERRESTRE | AA11: HENAO CARDONA DIEGO FERNANDO | AB11: 0 | AC11: 0 | AD11: 0 | AE11: 0 | AF11: 0 | AG11: 37905 | AH11: 37905
A12: CUCUTA | B12: SANTANDERES | C12: 0004-0008 | D12: 54874 | E12: 2829063 | F12: 3007077939 | G12: INCIDENTE | H12: NORTE DE SANTANDER | I12: VILLA DEL ROSARIO | J12: BARRIO 20 JULIO VILLA DEL ROSA | K12: REDEBAN | L12: FO-25-1615600 | M12: 45932.446 | N12: 45933.384 | O12: NO | P12: USUARIO | Q12: COMUNICACION | R12: CONEXIONES DE COMERCIO | S12: CB UNO A UNO | T12: CB UNO A UNO | U12: EJECUTADO | V12: 02/10/2025 SE ESCALA PARA VISITA. LLAMAR ANTES DE VISITAR | 03/10/2025 SE VISITA COMERCIO Y SE EVIDENCIA SWITCH DEL CLIENTE DAÑADO, SE ALIMENTAN DATOS DE DATÁFONO DIRECTAMENTE, SE LE INDICA AL CLIENTE EL EQUIPO QUE TIENEN DAÑADO, SE REALIZAN CIERRES Y PRUEBAS OK. | W12: VISITA TECNICA | X12: A1NZZ992 | Y12: TIPO I | Z12: TERRESTRE | AA12: TORRES MANTILLA JOSE DANIEL | AB12: 1 | AC12: 0 | AD12: 0 | AE12: 0 | AF12: 0 | AG12: 65960 | AH12: 65960
A13: PASTO | B13: SUROCCIDENTE Y EJE CAFETERO | C13: 0004-0003 | D13: 86568 | E13: 2829426 | F13: 3007067186 | G13: INCIDENTE | H13: PUTUMAYO | I13: PUERTO ASIS | J13: DISTRICOL LUXURY GM | K13: REDEBAN | L13: FO-25-1615579 | M13: 45932.457 | N13: 45932.749 | O13: NO | P13: USUARIO | Q13: MANTENIMIENTO | R13: MANTENIMIENTO GENERAL | S13: AGREGADOR | T13: DISTRICOL | U13: EJECUTADO | V13: 02/10/2025 SE REALIZÓ VISITAR CORRESPONSAL PARA REVISAR FALLAS DE LECTORA Y DE IMPRESIÓN, SE REALIZÓ CONFIGURACIÓN DE LECTORA, Y LIMPIEZA DE DATÁFONO, SE REALIZÓ PRUEBAS EXITOSAS, EL CORRESPONSAL ESTÁ OPERATIVO | W13: VISITA TECNICA | X13: AAL06527 | Y13: TIPO IV | Z13: TERRESTRE | AA13: GUERRERO RAMIREZ OSCAR DARIO | AB13: 1 | AC13: 0 | AD13: 0 | AE13: 0 | AF13: 0 | AG13: 479590 | AH13: 479590
A14: CALI | B14: SUROCCIDENTE Y EJE CAFETERO | C14: 0004-0003 | D14: 76001 | E14: 2830256 | F14: 3007034770 | G14: INCIDENTE | H14: VALLE DEL CAUCA | I14: CALI | J14: BARRIO MONTEBELLO 1 CALI | K14: REDEBAN | L14: FO-25-1616165 | M14: 45932.513 | N14: 45933.381 | O14: NO | P14: USUARIO | Q14: USUARIOS | R14: USUARIOS BLOQUEADOS | S14: UNO A UNO | T14: CB UNO A UNO | V14: 02/10/2025 SE ESCALA PARA VISITA. LLAMAR ANTES DE VISITAR | 03/10/2025 SE REALIZA VALIDACION CON EL CLIENTE INDICA QUE EL USUARIO SE LE HABIA BLOQUEADO Y NO LE DEJABA INGRESAR PERO , QUE PUDO ORGANIZARLO COMO LO NECESITABA | W14: SOPORTE TELEFONICO | Y14: TIPO I | Z14: TERRESTRE | AA14: HENAO CARDONA DIEGO FERNANDO | AB14: 0 | AC14: 0 | AD14: 0 | AE14: 0 | AF14: 0 | AG14: 37905 | AH14: 37905
A15: PASTO | B15: SUROCCIDENTE Y EJE CAFETERO | C15: 0004-0003 | D15: 52051 | E15: 2832368 | F15: 3007047683 | G15: INCIDENTE | H15: NARIÑO | I15: ARBOLEDA | J15: DISTRICOL DROGUERIA JUAN JOSE | K15: REDEBAN | L15: FO-25-1617910 | M15: 45932.684 | N15: 45934.443 | O15: NO | P15: USUARIO | Q15: COMUNICACION | R15: CANAL DEL COMERCIO | S15: AGREGADOR | T15: DISTRICOL | V15: 02/10/2025 SE COMUNICA CON EL SR RICARDO PARA REPORTAR QUE EL DATÁFONO SE VIENE REINICIANDO A DIARIO 1 VEZ POR DÍA, PER HOY SE HA REINICIADO DE MANERA AUTOMÁTICA MÁS DE 3 VECES, | 04/10/2025 SE VALIDA CON EL CLIENTE POR PROBLEMAS DE CONEXION , SE LE INDICA QUE POR FAVOR REALIZR REINICIO DEL ROUTER DE INTENET, EL CLIENTE REALIZA LO PERTIENENTE Y CONFIRMA SERVICIO Y OPERATIVIDAD DEL DATAFONO, SE CIERRA CASO | W15: SOPORTE TELEFONICO | Y15: TIPO II | Z15: TERRESTRE | AA15: HENAO CARDONA DIEGO FERNANDO | AB15: 0 | AC15: 0 | AD15: 0 | AE15: 0 | AF15: 0 | AG15: 37905 | AH15: 37905
A16: MONTERIA | B16: COSTA | C16: 0004-0001 | D16: 5154 | E16: 2832487 | F16: 3007075821 | G16: INCIDENTE | H16: ANTIOQUIA | I16: CAUCASIA | J16: PTM CAUCASIA PAPELERIA G J | K16: REDEBAN | L16: FO-25-1626785 | M16: 45932.696 | N16: 45937.706 | O16: NO | P16: USUARIO | Q16: MANTENIMIENTO | R16: MANTENIMIENTO GENERAL | S16: AGREGADOR | T16: COMCARD - PTM | U16: EJECUTADO | V16: 03/10/2025 SE ESCALA PARA VISITA. LLAMAR ANTES DE VISITAR | 07/10/2025 SE VISITA SITIO, SE INSTALA DATAFONO DEK3500 POR REPOSICIÓN OK. SE INICIALIZA TERMINALES DE CB Y ADQUIRENCIA PERO DATAFONO NO MUESTRA MÓDULO DE CB, SE REALIZA REFRESH DE TERMINALES PERO SIGUE CON NOVEDAD, CB INDICA QUE NO UTILIZA MÓDULO DE ADQUIRENCIA, POR LO CUAL AUTORIZA QUE SE DEJE EQUIPO COMO PURO, SE CAMBIA DATAFONO INSTALADO POR DAÑO RG, NO SE REALIZAN PRUEBAS CB BLOQUEADO POR ENTIDAD | W16: VISITA TECNICA | X16: VRZZZ270 | Y16: TIPO II | Z16: TERRESTRE | AA16: COGOLLO VERTEL EDER LUIS | AB16: 1 | AC16: 0 | AD16: 0 | AE16: 0 | AF16: 0 | AG16: 163814 | AH16: 163814
A17: MEDELLIN | B17: NOROCCIDENTE | C17: 0004-0005 | D17: 5001 | E17: 2832687 | F17: 3007068764 | G17: INCIDENTE | H17: ANTIOQUIA | I17: MEDELLIN | J17: PTM MEDELLIN DISTRIBUIDORA MOR | K17: REDEBAN | L17: FO-25-1618123 | M17: 45932.721 | N17: 45933.481 | O17: NO | P17: USUARIO | Q17: MANTENIMIENTO | R17: MANTENIMIENTO GENERAL | S17: AGREGADOR | T17: COMCARD - PTM | U17: EJECUTADO | V17: 02/10/2025 SE ESCALA PARA VISITA. LLAMAR ANTES DE VISITAR | 03/10/2025 SE VERIFICAN PARÁMETROS SE VERIFICA CABLEADO Y TAMBIÉN SE REALIZA MANTENIMIENTO DE LECTOR DE TARJETAS HACIENDO LIMPIEZA CON ALCOHOL. TODO ESTÁ FUNCIONANDO CORRECTAMENTE. | W17: VISITA TECNICA | X17: AALUZ190 - AALUZ336 | Y17: TIPO I | Z17: TERRESTRE | AA17: RAMIREZ TABARES JUAN DIEGO | AB17: 1 | AC17: 0 | AD17: 0 | AE17: 0 | AF17: 0 | AG17: 65960 | AH17: 65960
A18: PASTO | B18: SUROCCIDENTE Y EJE CAFETERO | C18: 0004-0003 | D18: 52835 | E18: 2837077 | F18: 3007046106 | G18: INCIDENTE | H18: NARIÑO | I18: SAN ANDRES DE TUMACO | J18: BARRIO PUENTE ORTIZ SAN ANDRES | K18: REDEBAN | L18: FO-25-1625936 | M18: 45933.607 | N18: 45937.387 | O18: NO | P18: USUARIO | Q18: MANTENIMIENTO | R18: MANTENIMIENTO GENERAL | S18: CB UNO A UNO | T18: CB UNO A UNO | U18: EJECUTADO | V18: 03/10/2025 SE COMUNICA CON EL SR LUIS ANGULO PARA REPORTAR QUE LA IMPRESORA ESTA DAÑADA YA QUE, IMPRIME BORROSO, YA CAMBIO EL ROLLO PERO PERSISTE E INDICA QUE HA TENIDO PROBLEMA CON VARIOS CLIENTES 3003709163 2: 47 PM | 07/10/2025 SE ENCUENTRA DATAFONO CON IMPRESIÓN BORROSA SE REALIZA MANTENIMIENTO GENERAL AL DATAFONO Y SE OBTIENE FUNCIONAMIENTO EXITOSO CONFIGURACIÓN OK PARÁMETROS OK Y SE REALIZAN PRUEBAS EXITOSAS DE TRANSACCIONES | W18: VISITA TECNICA | X18: TR003801 | Y18: TIPO IV | Z18: TERRESTRE | AA18: PAZ MARTINEZ RICHARD HUMBERTO | AB18: 1 | AC18: 0 | AD18: 0 | AE18: 0 | AF18: 0 | AG18: 479590 | AH18: 479590
A19: VILLAVICENCIO | B19: REMOTAS | C19: 0004-0007 | D19: 50686 | E19: 2837222 | F19: 3007021483 | G19: INCIDENTE | H19: META | I19: SAN JUANITO | J19: SAN JUANITO META | K19: REDEBAN | L19: FO-25-1625929 | M19: 45933.612 | N19: 45936.409 | O19: NO | P19: USUARIO | Q19: COMUNICACION | R19: CONEXIONES DE COMERCIO | S19: CB UNO A UNO | T19: CB UNO A UNO | V19: 03/10/2025 LUIS ANGULO PARA REPORTAR QUE LA IMPRESORA ESTA DAÑADA YA QUE, IMPRIME BORROSO, YA CAMBIO EL ROLLO PERO PERSISTE E INDICA QUE HA TENIDO PROBLEMA CON VARIOS CLIENTES | 06/10/2025 SE CONTACTA AL CLIENTE VIKI ORTIS E INFORMA QUE EL SERVICIO YA SE ENCUENTRA OPERATIVO Y QUE HABÍA LLAMADO A DESISTIR DE LA VISITA TÉCNICO ERA LAS CONEXIONES FÍSICAS | W19: SOPORTE TELEFONICO | Y19: TIPO IV | Z19: TERRESTRE | AA19: ROZO JIMENEZ EDGAR ARMANDO | AB19: 0 | AC19: 0 | AD19: 0 | AE19: 0 | AF19: 0 | AG19: 37905 | AH19: 37905
A20: SANTA MARTA | B20: COSTA | C20: 0004-0001 | D20: 44430 | E20: 2837542 | F20: 3007078712 | G20: INCIDENTE | H20: LA GUAJIRA | I20: MAICAO | J20: PTM MAICAO TIENDA Y VARIEDADES | K20: REDEBAN | L20: FO-25-1626342 | M20: 45933.641 | N20: 45936.583 | O20: NO | P20: ENTIDAD | Q20: ERROR DE TRANSACCIONES | R20: TRANSACCION NO PERMITIDA | S20: AGREGADOR | T20: COMCARD - PTM | U20: EJECUTADO | V20: 03/10/2025 SE COMUNICA CON EL SR HOLMER, DATAFONO ARROJA MUY BORROSO LOS VOUCHER, INTERNET PROPIO Y FUNCIONA BIEN 3115485300 3:25 PM | 06/10/2025 SE REALIZA LA VISITA, EL USUARIO INFORMA QUE YA EL DATÁFONO ESTÁ TRABAJANDO BIEN DE HECHO AL DÍA SIGUIENTE QUE SE PRESENTÓ EL DAÑO, SE REALIZA PRUEBAS DE TRANSACCIÓN Y TODO OK | W20: VISITA TECNICA | X20: A1RZZ262 - A1RZZ369 | Y20: TIPO IV | Z20: TERRESTRE | AA20: THOMAS CAMPO SIGIFREDO SEGUNDO | AB20: 1 | AC20: 0 | AD20: 0 | AE20: 0 | AF20: 0 | AG20: 479590 | AH20: 479590
A21: CALI | B21: SUROCCIDENTE Y EJE CAFETERO | C21: 0004-0003 | D21: 76892 | E21: 2838376 | F21: 3007079709 | G21: INCIDENTE | H21: VALLE DEL CAUCA | I21: YUMBO | J21: PTM YUMBO PAPELERIA MILU YUMBO | K21: REDEBAN | L21: FO-25-1626991 | M21: 45933.728 | N21: 45934.51 | O21: NO | P21: USUARIO | Q21: USUARIOS | R21: MALA MANIPULACION POS | S21: AGREGADOR | T21: COMCARD - PTM | U21: EJECUTADO | V21: 03/10/2025 SE ESCALA PARA VISITA. LLAMAR ANTES DE VISITAR | 04/10/2025 SE VISITA CORRESPONSAL E INFORMA QUE EL DATÁFONO FUNCIONA CORRECTAMENTE . PIDE CERRAR CASO. NO SE MANIPULAN EQUIPOS NI SE INGRESA AL CB. | W21: VISITA TECNICA | X21: V1YZZ451 | Y21: TIPO I | Z21: TERRESTRE | AA21: BOLAÑOS TABORDA JORGE ENRIQUE | AB21: 1 | AC21: 0 | AD21: 0 | AE21: 0 | AF21: 0 | AG21: 65960 | AH21: 65960
A22: BARRANQUILLA | B22: COSTA | C22: 0004-0001 | D22: 47675 | E22: 2838839 | F22: 3007035493 | G22: INCIDENTE | H22: MAGDALENA | I22: SALAMINA | J22: DISTRICOL LA PERSEVERANCIA | K22: REDEBAN | L22: FO-25-1628331 | M22: 45934.333 | N22: 45936.456 | O22: NO | P22: USUARIO | Q22: COMUNICACION | R22: CONEXIONES DE COMERCIO | S22: AGREGADOR | T22: DISTRICOL | V22: 04/10/2025 SE ESCALA PARA VISITA. LLAMAR ANTES DE VISITAR | 06/10/2025 EN COMUNICACIÓN CON EL SEÑOR LUIS PERTUZ AL NÚMERO 3004626987, ME INFORMA QUE YA NO ES NECESARIA LA VISITA , QUE TENÍAN PROBLEMAS CON UNA CONEXIÓN INTERNA, PERO QUE YA LO SOLUCIONARON | W22: SOPORTE TELEFONICO | Y22: TIPO II | Z22: TERRESTRE | AA22: DE AVILA SIADES ALBERTO ENRIQUE | AB22: 0 | AC22: 0 | AD22: 0 | AE22: 0 | AF22: 0 | AG22: 37905 | AH22: 37905
A23: MEDELLIN | B23: NOROCCIDENTE | C23: 0004-0005 | D23: 5756 | E23: 2840606 | F23: 3007076637 | G23: INCIDENTE | H23: ANTIOQUIA | I23: SONSON | J23: BARRIO SONSON SONSON 6 | K23: REDEBAN | L23: FO-25-1631222 | M23: 45935.448 | N23: 45936.627 | O23: NO | P23: USUARIO | Q23: COMUNICACION | R23: CANAL DEL COMERCIO | S23: CB UNO A UNO | T23: CB UNO A UNO | V23: 05/10/2025 SE ESCALA PARA VISITA. LLAMAR ANTES DE VISITAR, CONFIRMAR FALLA Y DATOS | 06/10/2025 SE LLAMA AL 3205395286 Y SE HA LA CON ANGIE LA CUAL INFORMA QUE YA FUNCIONA BIEN Y NO NECESITA VISITA | W23: SOPORTE TELEFONICO | Y23: TIPO III | Z23: TERRESTRE | AA23: ALVAREZ ARENAS VICTOR HUGO | AB23: 0 | AC23: 0 | AD23: 0 | AE23: 0 | AF23: 0 | AG23: 37905 | AH23: 37905
A24: MONTERIA | B24: COSTA | C24: 0004-0001 | D24: 5154 | E24: 2843176 | F24: 3007080876 | G24: INCIDENTE | H24: ANTIOQUIA | I24: CAUCASIA | J24: BARRIO ASOVIVIENDA CAUCASIA 2 | K24: REDEBAN | L24: FO-25-1634137 | M24: 45936.43 | N24: 45937.503 | O24: NO | P24: USUARIO | Q24: USUARIOS | R24: USUARIOS BLOQUEADOS | S24: UNO A UNO | T24: UNO A UNO | U24: EJECUTADO | V24: 06/10/2025 SE ESCALA PARA VISITA. LLAMAR ANTES DE VISITAR, CONFIRMAR FALLA Y DATOS | 07/10/2025 SE VISITA SITIO, SE REALIZA DESBLOQUEO DE TECLADO CON CLAVE SUPERVISOR OK PRUEBAS EXITOSAS | W24: VISITA TECNICA | X24: FGZZZ910 | Y24: TIPO II | Z24: TERRESTRE | AA24: COGOLLO VERTEL EDER LUIS | AB24: 1 | AC24: 0 | AD24: 0 | AE24: 0 | AF24: 0 | AG24: 163814 | AH24: 163814
A25: YOPAL | B25: REMOTAS | C25: 0004-0007 | D25: 85001 | E25: 2845916 | F25: 3007080510 | G25: INCIDENTE | H25: CASANARE | I25: YOPAL | J25: DISTRICOL DROGUE FARMA ORIENTE | K25: REDEBAN | L25: FO-25-1635899 | M25: 45936.606 | N25: 45936.738 | O25: NO | P25: USUARIO | Q25: COMUNICACION | R25: CONEXIONES DE COMERCIO | S25: AGREGADOR | T25: DISTRICOL | V25: 06/10/2025 SE ESCALA PARA VISITA. LLAMAR ANTES DE VISITAR, CONFIRMAR FALLA Y DATOS | 06/10/2025 EN COMUNICACIÓN CON LA SEÑORA NICOL ZAPATA 3106889846, INDICA QUE NO REQUIERE LA VISITA, LA FALLA FUE RESUELTA POR PERSONAL DE INTERNET PROPIO. INDICA OPERATIVO EL SERVICIO. | W25: SOPORTE TELEFONICO | Y25: TIPO I | Z25: TERRESTRE | AA25: BERNAL ELAICA EDGAR ALEXIS | AB25: 0 | AC25: 0 | AD25: 0 | AE25: 0 | AF25: 0 | AG25: 37905 | AH25: 37905
A26: BOGOTA | B26: CUNDINAMARCA | C26: 0004-0004 | D26: 11001 | E26: 2847580 | F26: 3007061294 | G26: INCIDENTE | H26: CUNDINAMARCA | I26: BOGOTA | J26: BARRIO BOSA LIBERTAD BOGOTA 4 | K26: REDEBAN | L26: FO-25-1637291 | M26: 45936.708 | N26: 45937.703 | O26: NO | P26: USUARIO | Q26: MANTENIMIENTO | R26: MANTENIMIENTO GENERAL | S26: CB UNO A UNO | T26: CB UNO A UNO | U26: EJECUTADO / CANCELADO | V26: 06/10/2025 SE ESCALA PARA VISITA. LLAMAR ANTES DE VISITAR, CONFIRMAR FALLA Y DATOS | 07/10/2025 SE REALIZA VISITA AL LLEGAR A CB SE ENCUENTRA CERRADO SE LLAMA A ENCARGADA ALEJANDRA MUÑOZ AL NUMERO 3133404113 EL CUAL NO SE TIENE COMUNICACIÓN SE DEJA REGISTRO FOTOGRÁFICO | W26: VISITA TECNICA | X26: FUAOH983 | Y26: TIPO I | Z26: TERRESTRE | AA26: JAIMES VALERO NELSON RICARDO | AB26: 1 | AC26: 0 | AD26: 0 | AE26: 0 | AF26: 0 | AG26: 65960 | AH26: 65960
A27: NEIVA | B27: REMOTAS | C27: 0004-0007 | D27: 18001 | E27: 2847972 | F27: 3007076544 | G27: INCIDENTE | H27: CAQUETA | I27: FLORENCIA | J27: OPRAP EXITO GRAN PLAZA FLORENC | K27: REDEBAN | L27: FO-25-1638491 | M27: 45937.333 | N27: 45938.626 | O27: NO | P27: USUARIO | Q27: COMUNICACION | R27: CONEXIONES DE COMERCIO | S27: ROBUSTO | T27: OPRAP | U27: EJECUTADO | V27: 07/10/2025 SE ESCALA PARA VISITA. LLAMAR ANTES DE VISITAR, CONFIRMAR FALLA Y DATOS | 07/10/2025 SE REALIZO CONTACTÓ TELEFÓNICO Y VÍA WHATSAPP CON LA SEÑORA MARCELA AL NÚMERO 320 9153649 PARA REALIZAR LA VISITA AL OPPRAP, PERO SE DEBE GENERAR UN PERMISO DE INGRESO POR PARTE DE OPPRAP PARA QUE PUEDA ENTRAR AL ESTACIONAMIENTO, SE ENVÍA CERTIFICADO DE SEGURIDAD SOCIAL PARA EL INGRESO, ESTOY ATENTO A QUE LA SEÑORA MARCELA ME CONFIRME SI PUEDE INGRESAR AL ESTABLECIMIENTO. | 08/10/2025 SE REALIZA BORRADO DE MEMORIA POR LENTITUD EN LAS TRANSACCIONES Y SE ORGANIZAN LOS CABLES YA QUE ESTABAN GENERANDO DESCONEXIÓN EN EL EQUIPO, PRUEBAS CB OK SE DEJA OPERATIVO. | W27: VISITA TECNICA | X27: 103ZZ224 | Y27: TIPO IV | Z27: TERRESTRE | AA27: BERMUDEZ SANCHEZ JOSE NEYBER | AB27: 1 | AC27: 0 | AD27: 0 | AE27: 0 | AF27: 0 | AG27: 479590 | AH27: 479590
A28: PASTO | B28: SUROCCIDENTE Y EJE CAFETERO | C28: 0004-0003 | D28: 52001 | E28: 2850211 | F28: 3007029176 | G28: INCIDENTE | H28: NARIÑO | I28: PASTO | J28: BARRIO CENTENARIO 3 PASTO | K28: REDEBAN | L28: FO-25-1639582 | M28: 45937.425 | N28: 45937.653 | O28: NO | P28: USUARIO | Q28: COMUNICACION | R28: CANAL DEL COMERCIO | S28: CB UNO A UNO | T28: CB UNO A UNO | U28: EJECUTADO | V28: 07/10/2025 SE ESCALA PARA VISITA. LLAMAR ANTES DE VISITAR, CONFIRMAR FALLA Y DATOS | 07/10/2025 SE VERIFICÓ FALLA DE ERROR DE CONEXIÓN, SE VERIFICA CABLEADO, SE REVISO CONEXIÓN CON CADA ROUTER DEL CLIENTE PERO FALLA PERSISTE, SE INTENTÓ CONECTAR OTROS DATÁFONOS HACIENDO PRUEBAS DE CONEXIÓN PERO FALLA PERSISTE, SE ESTABLECIÓ IP ESTÁTICA Y LIBRE PERO AÚN SIGUE LA FALLA, POR LO CUAL LA FALLA ES DEL MODEN DEL OPERADOR DE INTERNET PERO ESTE NO SE PUEDE REINICIAR YA QUE ES LA CONEXIÓN PRINCIPAL DEL CLIENTE PORQUE MANEJA CONEXIONES DE SERVIDOR INTERNAS, POR LO CUAL NO SE PUDE RESTABLECER LA CONEXIÓN AL DATÁFONO ASÍ QUE SE LE INDICO AL CLIENTE QUE APENAS EN LA NOCHE CUANDO YA NO REALICEN MÁS ACTIVIDADES DE COMERCIO REINICIEN EL MÓDEM Y REALICEN PRUEBAS DE COMUNICACIÓN EL DÍA SIGUIENTE SI LA FALLA PERSISTE QUE POR FAVOR VERIFIQUEN CON EL OPERADOR DE INTERNET O EN SU CASO REPORTAR NUEVAMENTE A LA ENTIDAD BANCARIA. | W28: VISITA TECNICA | X28: BBBBI984 | Y28: TIPO I | Z28: TERRESTRE | AA28: REMICIO AMADO JOHN HEBER | AB28: 1 | AC28: 0 | AD28: 0 | AE28: 0 | AF28: 0 | AG28: 65960 | AH28: 65960
A29: MEDELLIN | B29: NOROCCIDENTE | C29: 0004-0005 | D29: 5353 | E29: 2850255 | F29: 3007038046 | G29: INCIDENTE | H29: ANTIOQUIA | I29: HISPANIA | J29: BARRIO CALLE SALIDA HISPANIA H | K29: REDEBAN | L29: FO-25-1640061 | M29: 45937.432 | N29: 45939.605 | O29: NO | P29: USUARIO | Q29: COMUNICACION | R29: CONEXIONES DE COMERCIO | S29: CB UNO A UNO | T29: CB UNO A UNO | U29: EJECUTADO | V29: 07/10/2025 SE COMUNICA CON LA SRE ELSA PARA REPORTAR QUE EL CABLE QUE VA CONECTADO AL DATAFONO SE DAÑO, Y EL DATAFONO YA NO CONECTA CON LA CAJA, POR QUE E CABLE NO FUNCIONA 3117333003 10:44 | 09/10/2025 SE CAMBIA LECTOR DE BARRAS CON CABLE DAÑADO | W29: VISITA TECNICA | X29: AA00T745 | Y29: TIPO III | Z29: TERRESTRE | AA29: CASTAÑEDA PALACIO CARLOS FELIPE | AB29: 1 | AC29: 0 | AD29: 0 | AE29: 0 | AF29: 0 | AG29: 275728 | AH29: 275728
A30: MONTERIA | B30: COSTA | C30: 0004-0001 | D30: 23001 | E30: 2850429 | F30: 3007075532 | G30: INCIDENTE | H30: CORDOBA | I30: MONTERIA | J30: PTM MONTERIA PAPELERIA +X- | K30: REDEBAN | L30: FO-25-1640048 | M30: 45937.435 | N30: 45937.656 | O30: NO | P30: USUARIO | Q30: COMUNICACION | R30: CANAL DEL COMERCIO | S30: AGREGADOR | T30: COMCARD - PTM | U30: EJECUTADO | V30: 07/10/2025 SE ESCALA PARA VISITA. LLAMAR ANTES DE VISITAR, CONFIRMAR FALLA Y DATOS | 07/10/2025 SE REALIZA VISITA TÉCNICA Y SE ENCONTRÓ FALLAS CON PTO LAN DEL COMERCIO, SE HACE NECESARIO CAMBIAR DE PTO LA CONEXIÓN LAN DEL DATÁFONO PARA VOLVER RESTABLECER EL SERVICIO Y DEJAR OK. SE REALIZAN PRUEBAS OK. | W30: VISITA TECNICA | X30: SX00J089 - SX00J151 | Y30: TIPO I | Z30: TERRESTRE | AA30: CASSIANI PEREZ RAUL RAMIRO | AB30: 1 | AC30: 0 | AD30: 0 | AE30: 0 | AF30: 0 | AG30: 65960 | AH30: 65960
A31: BUCARAMANGA | B31: SANTANDERES | C31: 0004-0008 | D31: 20770 | E31: 2851577 | F31: 3007081736 | G31: INCIDENTE | H31: CESAR | I31: SAN MARTIN | J31: DISTRICOL MISCELANIA ISAVIC | K31: REDEBAN | L31: FO-25-1641179 | M31: 45937.513 | N31: 45939.618 | O31: NO | P31: USUARIO | Q31: COMUNICACION | R31: CONEXIONES DE COMERCIO | S31: AGREGADOR | T31: DISTRICOL | V31: 07/10/2025 SE REALIZAN 3 INTENTOS DE LLAMADAS AL NUMERO DE CONTACTO 3165079528 PERO NO FUE POSIBLE LA COMUNICACION | 09/10/2025 EN COMUNICACIÓN CON LA SEÑORA LEIDY GELVEZ , MANIFIESTA Q ERA UNA FALLLA DEL INTERNET QUE EL DATAFONO YA SE ENCUENTRA FUNCIONANDO CORRECTAMENTE ,Y ESTA OPERATIVO, SE LE INDICA AL CLIENTE Q SE PROCEDE A CERRAR ORDEN. | W31: SOPORTE TELEFONICO | Y31: TIPO III | Z31: TERRESTRE | AA31: GELVEZ MOGOLLON JOSE ELISEO | AB31: 0 | AC31: 0 | AD31: 0 | AE31: 0 | AF31: 0 | AG31: 37905 | AH31: 37905
A32: NEIVA | B32: REMOTAS | C32: 0004-0007 | D32: 41001 | E32: 2851722 | F32: 3007040764 | G32: INCIDENTE | H32: HUILA | I32: NEIVA | J32: DISTRICOL FRUVER DON EDER | K32: REDEBAN | L32: FO-25-1641165 | M32: 45937.519 | N32: 45938.456 | O32: NO | P32: USUARIO | Q32: MANTENIMIENTO | R32: MANTENIMIENTO GENERAL | S32: AGREGADOR | T32: DISTRICOL | V32: 07/10/2025 SE ESCALA PARA VISITA. LLAMAR ANTES DE VISITAR, CONFIRMAR FALLA Y DATOS | 08/10/2025 SE LLAMA AL CLIENTE EDER PASCUAS AL CELULAR 3152980015 , SE COMENTA QUE DE NUESTRA PARTE NO PODEMOS REALIZAR EL CAMBIO DE NOMBRE DE CB EN EL BAUCHER HASTA QUE DISTRICOL REALICE Y AUTORICE EL CAMBIO DE RAZÓN SOCIAL Y SALGA LA ORDEN COMO INSTALACIÓN NUEVA PARA NOSOTROS PROCEDER CON EL CAMBIO DE EQUIPOS Y ACTUALIZACIÓN DE LA INFORMACIÓN EN EL BAUCHER . | W32: SOPORTE TELEFONICO | Y32: TIPO I | Z32: TERRESTRE | AA32: ANDRADE HERNANDEZ JUAN CARLOS | AB32: 0 | AC32: 0 | AD32: 0 | AE32: 0 | AF32: 0 | AG32: 37905 | AH32: 37905
A33: MEDELLIN | B33: NOROCCIDENTE | C33: 0004-0005 | D33: 5001 | E33: 2851978 | F33: 3007069146 | G33: INCIDENTE | H33: ANTIOQUIA | I33: MEDELLIN | J33: DISTRICOL DIGITAL SAS | K33: REDEBAN | L33: FO-25-1641699 | M33: 45937.573 | N33: 45938.618 | O33: NO | P33: USUARIO | Q33: COMUNICACION | R33: CONEXIONES DE COMERCIO | S33: AGREGADOR | T33: DISTRICOL | U33: EJECUTADO | V33: 07/10/2025 SE ESCALA PARA VISITA. LLAMAR ANTES DE VISITAR, CONFIRMAR FALLA Y DATOS | 08/10/2025 SE REALIZA LA PONCHADA DEL CONECTOR RJ45 SE HACEN PRUEBAS QUEDA OK | W33: VISITA TECNICA | X33: A103Z552 | Y33: TIPO I | Z33: TERRESTRE | AA33: MONTOYA VELEZ ANDRES FELIPE | AB33: 1 | AC33: 0 | AD33: 0 | AE33: 0 | AF33: 0 | AG33: 65960 | AH33: 65960
A34: BOGOTA | B34: CUNDINAMARCA | C34: 0004-0004 | D34: 11001 | E34: 2854023 | F34: 3007055845 | G34: INCIDENTE | H34: CUNDINAMARCA | I34: BOGOTA | J34: PTM BOGOTA DROGUERIA EL GUARDI | K34: REDEBAN | L34: FO-25-1643246 | M34: 45937.702 | N34: 45938.628 | O34: NO | P34: USUARIO | Q34: COMUNICACION | R34: CONEXIONES DE COMERCIO | S34: AGREGADOR | T34: COMCARD - PTM | U34: EJECUTADO | V34: 07/10/2025 SE ESCALA PARA VISITA. LLAMAR ANTES DE VISITAR, CONFIRMAR FALLA Y DATOS | 08/10/2025 SE REVISA CONEXIONES, EQUIPO SE REALIZAN PRUEBAS DEL EQUIPO NO SE ENCUENTRA FALLO AL MOMENTO, INDICA QUE EL FALLO SE PRESENTÓ EL DÍA 07-10-2025 CON BLOQUEO DEL DATÁFONO PERO NO SÉ OBSERVAN ANORMALIDADES EN EL EQUIPO NI EN LAS CONEXIONES | W34: VISITA TECNICA | X34: XPJZZ846 - XPJZZ710 | Y34: TIPO I | Z34: TERRESTRE | AA34: ALARCON AREVALO JOHAN STIVEN | AB34: 1 | AC34: 0 | AD34: 0 | AE34: 0 | AF34: 0 | AG34: 65960 | AH34: 65960
A35: CALI | B35: SUROCCIDENTE Y EJE CAFETERO | C35: 0004-0003 | D35: 76275 | E35: 2855347 | F35: 3007080944 | G35: INCIDENTE | H35: VALLE DEL CAUCA | I35: FLORIDA | J35: BARRIO LA ESPERANZA FLORIDA 1 | K35: REDEBAN | L35: FO-25-1644159 | M35: 45938.343 | N35: 45938.588 | O35: NO | P35: USUARIO | Q35: COMUNICACION | R35: CANAL DEL COMERCIO | S35: UNO A UNO | T35: UNO A UNO | V35: 08/10/2025 SE ESCALA ACTIVIDAD PARA GESTION WOMPI | 08/10/2025 SE LLAMA AL CLIENTE E INDICA QUE ERA PROBLEMA DE ENERGÍA Y QUE EL DATAFONO YA ESTA FUNCIONANDO CORRECTAMENTE | W35: SOPORTE TELEFONICO | Y35: TIPO II | Z35: TERRESTRE | AA35: CUERO RUIZ JHONNY | AB35: 0 | AC35: 0 | AD35: 0 | AE35: 0 | AF35: 0 | AG35: 37905 | AH35: 37905
A36: NEIVA | B36: REMOTAS | C36: 0004-0007 | D36: 41551 | E36: 2855467 | F36: 3007053192 | G36: INCIDENTE | H36: HUILA | I36: PITALITO | J36: BARRIO LOS NOGALES PITALITO 2 | K36: REDEBAN | L36: FO-25-1644778 | M36: 45938.362 | N36: 45939.753 | O36: NO | P36: USUARIO | Q36: MANTENIMIENTO | R36: MANTENIMIENTO GENERAL | S36: CB UNO A UNO | T36: CB UNO A UNO | U36: EJECUTADO | V36: 08/10/2025 SE REALIZAN 3 INTENTOS DE LLAMADA AL NUMERO DE CONTACTO 3227711342 PERO NO FUE POSIBLE LA COMUNICACION | 09/10/2025 SE REALIZA FORMATEO, CONFIGURACIÓN E INICIALIZA DATAFONO, SE CREA USUARIO Y CLAVE CON EL CLIENTE, SE REALIZA PRUEBAS OK | W36: VISITA TECNICA | X36: XP0OZ148 | Y36: TIPO III | Z36: TERRESTRE | AA36: ANDRADE HERNANDEZ JUAN CARLOS | AB36: 1 | AC36: 0 | AD36: 0 | AE36: 0 | AF36: 0 | AG36: 275728 | AH36: 275728
A37: CALI | B37: SUROCCIDENTE Y EJE CAFETERO | C37: 0004-0003 | D37: 76001 | E37: 2857908 | F37: 3007076411 | G37: INCIDENTE | H37: VALLE DEL CAUCA | I37: CALI | J37: PTM CALI PAPELERIA Y VARIEDADE | K37: REDEBAN | L37: FO-25-1647109 | M37: 45938.529 | N37: 45939.438 | O37: NO | P37: USUARIO | Q37: MANTENIMIENTO | R37: MANTENIMIENTO GENERAL | S37: AGREGADOR | T37: COMCARD - PTM | U37: EJECUTADO | V37: 08/10/2025 SE ESCALA PARA VISITA. LLAMAR ANTES DE VISITAR, CONFIRMAR FALLA Y DATOS | 09/10/2025 SE VISITA CORRESPONSAL Y CLIENTE INFORMÓ QUE EL DATÁFONO ESTABA IMPRIMIENDO MAL PERO QUE REALIZÓ LIMPIEZA DE IMPRESORA Y QUEDÓ BIEN. PIDE CERRAR CASO Y NO SE INGRESA A CB. | W37: VISITA TECNICA | X37: A40UZ499 | Y37: TIPO I | Z37: TERRESTRE | AA37: BOLAÑOS TABORDA JORGE ENRIQUE | AB37: 1 | AC37: 0 | AD37: 0 | AE37: 0 | AF37: 0 | AG37: 65960 | AH37: 65960
A38: PASTO | B38: SUROCCIDENTE Y EJE CAFETERO | C38: 0004-0003 | D38: 52001 | E38: 2859764 | F38: 3007029176 | G38: INCIDENTE | H38: NARIÑO | I38: PASTO | J38: BARRIO CENTENARIO 3 PASTO | K38: REDEBAN | L38: FO-25-1648704 | M38: 45938.687 | N38: 45939.525 | O38: NO | P38: USUARIO | Q38: COMUNICACION | R38: CANAL DEL COMERCIO | S38: CB UNO A UNO | T38: CB UNO A UNO | U38: EJECUTADO | V38: 08/10/2025 SE ESCALA PARA VISITA. LLAMAR ANTES DE VISITAR, CONFIRMAR FALLA Y DATOS | 09/10/2025 SE LLEGO A SITIO PARA VERIFICAR FALLA DE COMUNICACIÓN ERROR DE CONEXIÓN PERO EL CLIENTE NO FORMA QUE EL SISTEMA SE REESTABLECIÓ SOLO EL DÍA DE AYER EN HORAS DE LA TARDE, SE REALIZO PRUEBAS DE CONEXIÓN Y TX EXITOSAS QUEDA OPERATIVO | W38: VISITA TECNICA | X38: BBBBI984 | Y38: TIPO I | Z38: TERRESTRE | AA38: REMICIO AMADO JOHN HEBER | AB38: 1 | AC38: 0 | AD38: 0 | AE38: 0 | AF38: 0 | AG38: 65960 | AH38: 65960
A39: TUNJA | B39: SANTANDERES | C39: 0004-0008 | D39: 15759 | E39: 2861978 | F39: 3007080408 | G39: INCIDENTE | H39: BOYACA | I39: SOGAMOSO | J39: BARRIO LA FLORESTA SOGAMOSO 4 | K39: REDEBAN | L39: FO-25-1652261 | M39: 45939.411 | N39: 45940.505 | O39: NO | P39: USUARIO | Q39: USUARIOS | R39: CREACION DE USUARIOS | S39: UNO A UNO | T39: UNO A UNO | U39: EJECUTADO | V39: 09/10/2025 SE ESCALA PARA VISITA. LLAMAR ANTES DE VISITAR, CONFIRMAR FALLA Y DATOS | 10/10/2025 SE VISITA PUNTO SE REALIZAR CREACIÓN DE USUARIOS SOLUCIONANDO LA FALLA REPORTADA SE LE INDICA NUEVAMENTE COMO CREAR MODIFICAR O ELIMINAR UN USUARIO PRUEBAS OK CLIENTE CONFORME | W39: VISITA TECNICA | X39: LBZZZ666 | Y39: TIPO II | Z39: TERRESTRE | AA39: RODRIGUEZ MURCIA YERSON IVAN | AB39: 1 | AC39: 0 | AD39: 0 | AE39: 0 | AF39: 0 | AG39: 163814 | AH39: 163814
A40: APARTADO | B40: NOROCCIDENTE | C40: 0004-0005 | D40: 5045 | E40: 2862896 | F40: 3007034146 | G40: INCIDENTE | H40: ANTIOQUIA | I40: APARTADO | J40: DISTRICOL RECARGAS MOVILES | K40: REDEBAN | L40: FO-25-1654928 | M40: 45939.468 | N40: 45940.371 | O40: NO | P40: USUARIO | Q40: MANTENIMIENTO | R40: MANTENIMIENTO GENERAL | S40: AGREGADOR | T40: DISTRICOL | U40: EJECUTADO | V40: 09/10/2025 SE ESCALA ACTIVIDAD PARA GESTION WOMPI | 09/10/2025 CLIENTE INDICA QUE DATAFONO FUNCIONA BIEN SOLO SE REINICIA CUANDO INTRODUCE TARJETAS VIEJAS. | W40: VISITA TECNICA | X40: 1QZZZ786 | Y40: TIPO I | Z40: TERRESTRE | AA40: CASTRO HENAO DANIEL ESTEBAN | AB40: 1 | AC40: 0 | AD40: 0 | AE40: 0 | AF40: 0 | AG40: 65960 | AH40: 65960
...

Sheet OC
A1: CIUDAD SEDE | B1: ZONA | C1: CENTRO DE COSTOS LINEACOM | D1: CODIGO DANE | E1: TA/CODIGO ACTIVIDAD | F1: CODIGO CB | G1: ACTIVIDAD | H1: DEPARTAMENTO | I1: CIUDAD | J1: NOMBRE DEL CB | K1: RED | L1: FO | M1: FECHA ASIGNACION A LINEA COMUNICACIONES | N1: FECHA CIERRE DEL TICKET (DD/MM/AAAA HH:MM) | O1: ACOMETIDA | P1: SOLICITUD | Q1: DESCRIPCION | R1: FORMATO | S1: CADENA | T1: ESTADO | U1: CAUSAL ESTADO | V1: OBSERVACION | W1: FORMA DE ATENCION | X1: TERMINAL(ES) | Y1: TIPIFICACION | Z1: TIPO DE TRAYECTO | AA1: NOMBRE DEL TECNICO | AB1: DIAS DE VISITA | AC1: SWITCH | AD1: ACOMETIDA DATOS | AE1: ACOMETIDA ELÉCTRICA | AF1: VALOR ACTIVIDAD | AG1: VALOR TOTAL
