Workbook
Name A: #REF!
Name Actividad: #REF!
Name Analistas: #REF!
Name arearesponsable: #REF!
Name CCO: #REF!
Name Clientes: #REF!
Name COORDINADOR: #REF!
Name Coordinadores: #REF!
Name DOCUMENTADOR: #REF!
Name ES: #REF!
Name ESS: #REF!
Name Estado: #REF!
Name ESTADOACTIVIDAD: #REF!
Name ESTADOS: #REF!
Name ESTADOSCIERRES: #REF!
Name Facturacion: #REF!
Name FACTURACIÓN: #REF!
Name falla: #REF!
Name Fallas: #REF!
Name Grupo_Falla: #REF!
Name inconservmanager: #REF!
Name INCUMPLIMIENTO: #REF!
Name LISTA: #REF!
Name LISTA2: #REF!
Name LOLO: #REF!
Name solicitudes: #REF!
Name Tecnicos: #REF!
Name Version: #REF!

Sheet BASE LIQUIDACION REDEBAN 2025
A1: Tipificación | B1: Implementaciones | C1: Incidentes – Ordenes de Cambio | D1: Fallida | G1: Tipificación | H1: Actividad sin cambio de datafono | J1: Actividad + adicional cambio de datafono | L1: Visita Fallida | N1: Incremento 2025
A2: TIPO I | B2: =71384.4052*(1+$N$2) -> 75096.394 | C2: =62699.6885*(1+$N$2) -> 65960.072 | D2: =35693.4343*(1+$N$2) -> 37549.493 | H2: Instalación Pinpad + HUB | I2: Segunda actividad en mismo comercio, misma visita | J2: Instalación Pinpad + HUB | K2: Segunda actividad en mismo comercio, misma visita | N2: 0.052
A3: TIPO II | B3: =155716.4408*(1+$N$2) -> 163813.7 | C3: =137802.16*(1+$N$2) -> 144967.87 | D3: =117879.8485*(1+$N$2) -> 124009.6 | G3: Tipo I | H3: =31819.23994686*(1+$N$2) -> 33473.84 | I3: =26222.67548178*(1+$N$2) -> 27586.255 | J3: =51196.46628516*(1+$N$2) -> 53858.683 | K3: =42157.66342524*(1+$N$2) -> 44349.862 | L3: =28948.10610808*(1+$N$2) -> 30453.408
A4: TIPO III | B4: =262099.6015*(1+$N$2) -> 275728.78 | C4: =262099.6015*(1+$N$2) -> 275728.78 | D4: =262099.6015*(1+$N$2) -> 275728.78 | G4: Tipo II | H4: =98014.03066668*(1+$N$2) -> 103110.76 | I4: =26222.67548178*(1+$N$2) -> 27586.255 | J4: =119562.49505524*(1+$N$2) -> 125779.74 | K4: =42157.66342524*(1+$N$2) -> 44349.862 | L4: =94765.6295813*(1+$N$2) -> 99693.442
A5: TIPO IV | B5: =479878.9419*(1+$N$2) -> 504832.65 | C5: =455882.9625*(1+$N$2) -> 479588.88 | D5: =370911.6746*(1+$N$2) -> 390199.08 | G5: Tipo III | H5: =189140.9827006*(1+$N$2) -> 198976.31 | I5: =26222.67548178*(1+$N$2) -> 27586.255 | J5: =200461.60194168*(1+$N$2) -> 210885.61 | K5: =42157.66342524*(1+$N$2) -> 44349.862 | L5: =171492.68108896*(1+$N$2) -> 180410.3
A6: Destino Aéreo | B6: =939603.5767*(1+$N$2) -> 988462.96 | C6: a partir del 5to servicio | G6: Tipo IV | H6: =461621.60109668*(1+$N$2) -> 485625.92 | I6: =26222.67548178*(1+$N$2) -> 27586.255 | J6: =461621.60109668*(1+$N$2) -> 485625.92 | K6: =42157.66342524*(1+$N$2) -> 44349.862 | L6: =461621.60109668*(1+$N$2) -> 485625.92
G7: * Tipo IV Especial Donde se requiera desplazamiento aéreo o fluvial será facturado el valor de la actividad y adicional el valor de $988.463 por cada 5 actividades de esta tipología
A8: Tarifas para día adicional de actividades:
A9: Tipificación | B9: Día adicional- menos de dos horas | C9: Medio día adicional | D9: Día adicional- más de 4 horas
A10: Tipo I | B10: =71384.4052*(1+$N$2) -> 75096.394 | C10: =133455.9267*(1+$N$2) -> 140395.63 | D10: =191225.1201*(1+$N$2) -> 201168.83 | G10: Actividad | H10: Unidad | I10: Valor Unitario
A11: Tipo II | B11: =133455.9267*(1+$N$2) -> 140395.63 | C11: =191225.1201*(1+$N$2) -> 201168.83 | D11: =257740.6152*(1+$N$2) -> 271143.13 | G11: Gestión telefónica y cierre de incidente de bloqueo | H11: Unidad | I11: =17639.19516086*(1+$N$2) -> 18556.433
A12: Tipo III | B12: =186821.7926*(1+$N$2) -> 196536.53 | C12: =248892.0824*(1+$N$2) -> 261834.47 | D12: =306662.5075*(1+$N$2) -> 322608.96 | G12: Servicio de cierre de incidente de bloqueo | H12: Unidad | I12: =4810.80785492*(1+$N$2) -> 5060.9699
A13: Tipo IV | B13: =186821.7926*(1+$N$2) -> 196536.53 | C13: =248892.0824*(1+$N$2) -> 261834.47 | D13: =306662.5075*(1+$N$2) -> 322608.96
A16: Servicio | B16: Tarifa actividad | D16: VALOR DE LA TERMINAL ADICIONAL | E16: VALOR DE INSTALACIÓN DE BASE EN "Y"
A17: Papelería – Tarifa única | B17: =34010.9321*(1+$N$2) -> 35779.501 | D17: =20537.3658*(1+$N$2) -> 21605.309 | E17: =10737.9606*(1+$N$2) -> 11296.335
A18: Papelería Tipo II - Visita técnica | B18: =64310*(1+$N$2) -> 67654.12
A19: Solución telefónica | B19: =39202.5476*(1+$N$2) -> 41241.08
A22: Traifas 2024
A23: Tipificación | B23: Implementaciones | C23: Incidentes – Ordenes de Cambio | D23: Fallida | G23: Tipificación | H23: Actividad sin cambio de datafono | J23: Actividad + adicional cambio de datafono | L23: Visita Fallida
A24: TIPO I | B24: 71384.405 | C24: 62699.688 | D24: 35693.434 | H24: Instalación Pinpad + HUB | I24: Segunda actividad en mismo comercio, misma visita | J24: Instalación Pinpad + HUB | K24: Segunda actividad en mismo comercio, misma visita
A25: TIPO II | B25: 155716.44 | C25: 137802.16 | D25: 117879.85 | G25: Tipo I | H25: 31819.24 | I25: 26222.675 | J25: 51196.466 | K25: 42157.663 | L25: 28948.106
A26: TIPO III | B26: 262099.6 | C26: 262099.6 | D26: 262099.6 | G26: Tipo II | H26: 98014.031 | I26: 26222.675 | J26: 119562.5 | K26: 42157.663 | L26: 94765.63
A27: TIPO IV | B27: 479878.94 | C27: 455882.96 | D27: 370911.67 | G27: Tipo III | H27: 189140.98 | I27: 26222.675 | J27: 200461.6 | K27: 42157.663 | L27: 171492.68
A28: Destino Aéreo | B28: 939603.58 | C28: a partir del 5to servicio | G28: Tipo IV | H28: 461621.6 | I28: 26222.675 | J28: 461621.6 | K28: 42157.663 | L28: 461621.6
G29: * Tipo IV Especial Donde se requiera desplazamiento aéreo o fluvial será facturado el valor de la actividad y adicional el valor de $939,604 por cada 5 actividades de esta tipología
A30: Tarifas para día adicional de actividades:
A31: Tipificación | B31: Día adicional- menos de dos horas | C31: Medio día adicional | D31: Día adicional- más de 4 horas
A32: Tipo I | B32: 71384.405 | C32: 133455.93 | D32: 191225.12 | G32: Actividad | H32: Unidad | I32: Valor Unitario
A33: Tipo II | B33: 133455.93 | C33: 191225.12 | D33: 257740.62 | G33: Gestión telefónica y cierre de incidente de bloqueo | H33: Unidad | I33: 17639.195
A34: Tipo III | B34: 186821.79 | C34: 248892.08 | D34: 306662.51 | G34: Servicio de cierre de incidente de bloqueo | H34: Unidad | I34: 4810.8079
A35: Tipo IV | B35: 186821.79 | C35: 248892.08 | D35: 306662.51
A38: Servicio | B38: Tarifa actividad | D38: VALOR DE LA TERMINAL ADICIONAL | E38: VALOR DE INSTALACIÓN DE BASE EN "Y"
A39: Papelería – Tarifa única | B39: 34010.932 | D39: 20537.366 | E39: 10737.961
A40: Papelería Tipo II - Visita técnica | B40: 64310
A41: Solución telefónica | B41: 39202.548

Sheet RESUMEN LIQUIDACION
A1: FACTURACIÓN ACTIVIDADES REDEBAN CB BANCOLOMBIA Y AVAL
A2: 1 AL 30 DE OCTUBRE 2025
A4: CONCEPTOS | B4: CANTIDAD | C4: TOTAL
A5: Aperturas Bancolombia | B5: =COUNTA(APERTURAS_BANCOLOMBIA!A:A)-1 -> 180 | C5: =APERTURAS_BANCOLOMBIA!AB182 -> 28693432
A6: Incidentes Bancolombia | B6: =COUNTA(INCIDENTES_BANCOLOMBIA!A:A)-1 -> 975 | C6: =INCIDENTES_BANCOLOMBIA!AE977 -> 162740088
A7: Gestión de Campo Bancolombia | B7: =COUNTA(OC_BANCOLOMBIA!A:A)-1 -> 353 | C7: =OC_BANCOLOMBIA!AE355 -> 57676313
A8: Soporte Papelería Bancolombia | B8: =COUNTA(PAPELERIA!A:A)-1 -> 2311 | C8: =PAPELERIA!AD2313 -> 103538227
A9: Aperturas Aval | B9: =COUNTA(APERTURAS_AVAL!A:A)-1 -> 223 | C9: =APERTURAS_AVAL!AB225 -> 37006327
A10: Incidentes Aval | B10: =COUNTA(INCIDENTES_AVAL!A:A)-1 -> 342 | C10: =INCIDENTES_AVAL!AC344 -> 38230031
A11: Gestión de Campo Aval | B11: =COUNTA(OC_AVAL!A:A)-1 -> 102 | C11: =OC_AVAL!AE104 -> 13704688
A12: Aperturas BBVA | B12: =COUNTA(APERTURAS_BBVA!A:A)-1 -> 1 | C12: =APERTURAS_BBVA!AB3 -> 75096
A13: Gestión de Campo BBVA | B13: =COUNTA(OC_BBVA!A:A)-1 -> 2 | C13: =OC_BBVA!AE4 -> 289935.74
A14: Incidentes BBVA | B14: =COUNTA(INCIDENTES_BBVA!A:A)-1 -> 2 | C14: =INCIDENTES_BBVA!AB4 -> 289936
A15: SUBTOTAL | C15: =SUM(C5:C14) -> 4.4224407e+08
A16: Iva | C16: =C15*0.19 -> 84026374
A17: TOTAL | C17: =SUM(C15:C16) -> 5.2627045e+08

Sheet APERTURAS_BANCOLOMBIA
A1: CIUDAD SEDE | B1: ZONA | C1: CENTRO DE COSTOS LINEACOM | D1: CODIGO DANE | E1: TA/CODIGO ACTIVIDAD | F1: CODIGO CB | G1: ACTIVIDAD | H1: TIPO DE APERTURA | I1: DEPARTAMENTO | J1: CIUDAD | K1: NOMBRE DEL CB | L1: RED | M1: FO | N1: FECHA LISTA | O1: FECHA ULTIMA ACTUALIZACION | P1: FORMATO | Q1: CADENA | R1: ESTADO | S1: OBSERVACIONES CLIENTE | T1: FORMA DE ATENCION | U1: TERMINAL(ES) | V1: TIPIFICACION | W1: TIPO DE TRAYECTO | X1: NOMBRE DEL TECNICO | Y1: DIAS DE VISITA | Z1: DIA ADICIONAL | AA1: VALOR DIAS ACTIVIDAD FACTURABLES | AB1: VALOR TOTAL
A2: PASTO | B2: SUROCCIDENTE Y EJE CAFETERO | C2: 0004-0003 | D2: 86320 | E2: TA-25-1145855 | F2: 3007081670 | G2: APERTURA | H2: CB CRECIMIENTO ALIANZA - NUEVO | I2: PUTUMAYO | J2: ORITO | K2: DISTRICOL BOUTIQUEMISANGELITOS | L2: REDEBAN | M2: FO-25-1577742 | N2: 45924.523 | O2: 45931.706 | P2: AGREGADOR | Q2: DISTRICOL | R2: EJECUTADO | S2: 24/09/2025 24-09 PROGRAMACIÓN REALIZADA POR LA ALIANZA | 29/09/2025 SE ESPERA REALIZAR INSTALACIÓN EL MIÉRCOLES EN LA JORNADA DE LA TARDE YA QUE HAY VARIAS ACTIVIDADES EN LA ZONA | 01/10/2025 SE REALIZA INSTALACIÓN DE CB. SE CAPACITA SOBRE SOMOS BANCOLOMBIA, MANEJO DE DATAFONO Y PARTE ADMINISTRATIVA. SE INSTALA AVISO EXTERIOR, FLANGER Y DISPLAY LEGAL CON INSERTO HORARIO, TARIFAS Y NÚMERO DE CB. SE ENTREGAN 40 ROLLOS. SE REALIZA PRUEBAS TX EXITOSAS. QUEDA OPERATIVO | T2: VISITA TECNICA | U2: FWZZZ496 | V2: TIPO IV | W2: TERRESTRE | X2: CASTILLO HERRERA ALEX RICARDO | Y2: 1 | Z2: 0 | AA2: 504833 | AB2: 504833
A3: PASTO | B3: SUROCCIDENTE Y EJE CAFETERO | C3: 0004-0003 | D3: 86568 | E3: TA-25-1145861 | F3: 3007081675 | G3: APERTURA | H3: CB CRECIMIENTO ALIANZA - NUEVO | I3: PUTUMAYO | J3: PUERTO ASIS | K3: DISTRICOL SOCCER LAGUNA | L3: REDEBAN | M3: FO-25-1577748 | N3: 45924.619 | O3: 45931.733 | P3: AGREGADOR | Q3: DISTRICOL | R3: EJECUTADO | S3: 24/09/2025 24-09 PROGRAMACIÓN REALIZADA POR LA ALIANZA | 30/09/2025 NO SE LOGRA LLEGAR AL DESTINO EL DIA DE HOY POR PROBLEMAS EN LAS VIAS, SE LLEGARA EL DIA DE MAÑANA PARA ATENCION DE ACTIVIDADES | 01/10/2025 SE VISITO EL COMERCIO PARA DAR APERTURA AL CB, SE INSTALA DATAFONO CON LECTORA BASE Y MAGIC BOX, SE INSTALA PUBLICIDAD Y SE ENTREGA ROLLOS, SE CAPACITA OK, PRUEBAS OK EXCEPTO RECAUDO POR NO TENER ELEMENTOS PARA HACERLA, SOMOS BANCOLOMBIA OK, CB OPERATIVO | T3: VISITA TECNICA | U3: FWZZZ497 | V3: TIPO IV | W3: TERRESTRE | X3: GUERRERO RAMIREZ OSCAR DARIO | Y3: 1 | Z3: 0 | AA3: 504833 | AB3: 504833
A4: PASTO | B4: SUROCCIDENTE Y EJE CAFETERO | C4: 0004-0003 | D4: 86568 | E4: TA-25-1145865 | F4: 3007081677 | G4: APERTURA | H4: CB CRECIMIENTO ALIANZA - NUEVO | I4: PUTUMAYO | J4: PUERTO ASIS | K4: DISTRICOL DROGUERIA SANTANA | L4: REDEBAN | M4: FO-25-1577752 | N4: 45924.619 | O4: 45932.633 | P4: AGREGADOR | Q4: DISTRICOL | R4: EJECUTADO | S4: 24/09/2025 24-09 PROGRAMACIÓN REALIZADA POR LA ALIANZA | 30/09/2025 NO SE LOGRA LLEGAR EL DIA DE HOY AL DESTINO POR PROBLEMAS EN LA VIA, SE LLEGARA AL SITIO EL DIA DE MAÑANA PARA ATENCION DE ACTIVIDADES . | 02/10/2025 SE VISITO EL COMERCIO PARA DAR APERTURA AL CB, SE INSTALA DATAFONO CON LECTORA BASE Y MAGIC BOX, SE INSTALA PUBLICIDAD Y SE ENTREGA ROLLOS, SE CAPACITA OK, PRUEBAS OK EXCEPTO RECAUDO POR NO TENER ELEMENTOS PARA HACERLA, SOMOS BANCOLOMBIA OK, CB OPERATIVO | T4: VISITA TECNICA | U4: FWZZZ498 | V4: TIPO IV | W4: TERRESTRE | X4: GUERRERO RAMIREZ OSCAR DARIO | Y4: 1 | Z4: 0 | AA4: 504833 | AB4: 504833
A5: PASTO | B5: SUROCCIDENTE Y EJE CAFETERO | C5: 0004-0003 | D5: 86757 | E5: TA-25-1145899 | F5: 3007081680 | G5: APERTURA | H5: CB CRECIMIENTO ALIANZA - NUEVO | I5: PUTUMAYO | J5: SAN MIGUEL | K5: DISTRICOL MI PAPALERIA MP | L5: REDEBAN | M5: FO-25-1577762 | N5: 45924.523 | O5: 45931.459 | P5: AGREGADOR | Q5: DISTRICOL | R5: EJECUTADO | S5: 24/09/2025 24-09 PROGRAMACIÓN REALIZADA POR LA ALIANZA | 29/09/2025 ACTIVIDAD SE REALIZARÁ EL DÍA MIÉRCOLES DEBIDO YA QUE EL TRAYECTO ES DE MÁS DE 9 HORAS DESDE LA CIUDAD DE PASTO | 01/10/2025 SE REALIZA INSTALACIÓN DE CB. SE CAPACITA SOBRE SOMOS BANCOLOMBIA, MANEJO DE DATAFONO Y PARTE ADMINISTRATIVA. SE INSTALA AVISO EXTERIOR, FLANGER Y DISPLAY LEGAL CON INSERTO HORARIO, TARIFAS Y NÚMERO DE CB. SE ENTREGAN 40 ROLLOS. SE REALIZA PRUEBAS TX EXITOSAS. QUEDA OPERATIVO | T5: VISITA TECNICA | U5: FWZZZ500 | V5: TIPO IV | W5: TERRESTRE | X5: CASTILLO HERRERA ALEX RICARDO | Y5: 1 | Z5: 0 | AA5: 504833 | AB5: 504833
A6: NEIVA | B6: REMOTAS | C6: 0004-0007 | D6: 18001 | E6: TA-25-1157218 | F6: 3007081709 | G6: APERTURA | H6: CB CRECIMIENTO ALIANZA - NUEVO | I6: CAQUETA | J6: FLORENCIA | K6: DISTRICOL CILEA A&V | L6: REDEBAN | M6: FO-25-1598630 | N6: 45929.795 | O6: 45931.478 | P6: AGREGADOR | Q6: DISTRICOL | R6: EJECUTADO | S6: 29/09/2025 29-09 PROGRAMACIÓN REALIZADA POR LA ALIANZA | 01/10/2025 SE REALIZA INSTALACIÓN DE DATAFONO LECTORA BASE FUENTE DE PODER CABLE DE RED SE ENTREGAN 40 ROLLOS RBM SE INSTALA AVISO EXTERIOR Y PUBLICIDAD SE CAPACITA EN CB Y SOMOS BANCOLOMBIA TIENE CREADO EL USUARIO SOMOS BANCOLOMBIA PRUEBAS CB OK SE DEJA OPERATIVO | T6: VISITA TECNICA | U6: FYZZZ187 | V6: TIPO IV | W6: TERRESTRE | X6: BERMUDEZ SANCHEZ JOSE NEYBER | Y6: 1 | Z6: 0 | AA6: 504833 | AB6: 504833
A7: NEIVA | B7: REMOTAS | C7: 0004-0007 | D7: 18150 | E7: TA-25-1157223 | F7: 3007081706 | G7: APERTURA | H7: CB CRECIMIENTO ALIANZA - NUEVO | I7: CAQUETA | J7: CARTAGENA DEL CHAIRA | K7: DISTRICOL ANGELA’S BOUTIQUE | L7: REDEBAN | M7: FO-25-1598635 | N7: 45929.795 | O7: 45933.487 | P7: AGREGADOR | Q7: DISTRICOL | R7: EJECUTADO | S7: 29/09/2025 29-09 PROGRAMACIÓN REALIZADA POR LA ALIANZA | 03/10/2025 SE REALIZA INSTALACIÓN DE DATÁFONO LECTORA BASE FUENTE DE PODER CABLE DE RED SE ENTREGAN 40 ROLLOS RBM SE INSTALA AVISO EXTERIOR Y PUBLICIDAD SE CAPACITA EN CB Y SOMOS BANCOLOMBIA TIENE CREADO EL USUARIO SOMOS BANCOLOMBIA PRUEBAS CB OK SE DEJA OPERATIVO | T7: VISITA TECNICA | U7: FYZZZ188 | V7: TIPO V | W7: TERRESTRE | X7: BERMUDEZ SANCHEZ JOSE NEYBER | Y7: 1 | Z7: 0 | AA7: 504833 | AB7: 504833
A8: PASTO | B8: SUROCCIDENTE Y EJE CAFETERO | C8: 0004-0003 | D8: 52227 | E8: TA-25-1157227 | F8: 3007081708 | G8: APERTURA | H8: CB CRECIMIENTO ALIANZA - NUEVO | I8: NARIÑO | J8: CUMBAL | K8: DISTRICOL MEGANET PANAN | L8: REDEBAN | M8: FO-25-1598652 | N8: 45929.694 | O8: 45931.655 | P8: AGREGADOR | Q8: DISTRICOL | R8: EJECUTADO | S8: 29/09/2025 29-09 PROGRAMACIÓN REALIZADA POR LA ALIANZA | 01/10/2025 SE REALIZÓ LA INSTALACIÓN DE EQUIPOS PUBLICIDAD Y ACCESORIOS PARA APERTURA CB BANCOLOMBIA SE DIO CAPACITACIÓN MANEJO DE DATÁFONO CB Y SOMOS BANCOLOMBIA SE EJECUTAN PRUEBAS TX EXITOSAS QUEDA OPERATIVO | T8: VISITA TECNICA | U8: FYZZZ191 | V8: TIPO III | W8: TERRESTRE | X8: REMICIO AMADO JOHN HEBER | Y8: 1 | Z8: 0 | AA8: 275729 | AB8: 275729
A9: CUCUTA | B9: SANTANDERES | C9: 0004-0008 | D9: 54498 | E9: TA-25-1157229 | F9: 3007081710 | G9: APERTURA | H9: CB CRECIMIENTO ALIANZA - NUEVO | I9: NORTE DE SANTANDER | J9: OCAÑA | K9: DISTRICOL MAXILIAM | L9: REDEBAN | M9: FO-25-1598662 | N9: 45929.29 | O9: 45932.68 | P9: AGREGADOR | Q9: DISTRICOL | R9: EJECUTADO | S9: 29/09/2025 29-09 PROGRAMACIÓN REALIZADA POR LA ALIANZA | 01/10/2025 SE COMUNICA CON LA CLIENTE SE PROGRAMA VISITA PARA MAÑANA POR DISPONIBILIDAD DEL CLIENTE, ZONA CATATUMBO. | 02/10/2025 SE VISITA COMERCIO, SE INSTALA DATAFONO, BASE, SCANNER, AVISO EXTERIOR, PUBLICIDAD DEL BANCO, SE CAPACITA PERSONAL, PRUEBAS Y CIERRES EXITOSO, CB OPERATIVO. | T9: VISITA TECNICA | U9: FYZZZ193 | V9: TIPO IV | W9: TERRESTRE | X9: NARANJO AFANADOR RUBEN JESUS | Y9: 1 | Z9: 0 | AA9: 504833 | AB9: 504833
A10: CUCUTA | B10: SANTANDERES | C10: 0004-0008 | D10: 54800 | E10: TA-25-1157231 | F10: 3007081714 | G10: APERTURA | H10: CB CRECIMIENTO ALIANZA - NUEVO | I10: NORTE DE SANTANDER | J10: TEORAMA | K10: DISTRICOL FABRICAMUEBLESVALENT | L10: REDEBAN | M10: FO-25-1598665 | N10: 45929.29 | O10: 45933.478 | P10: AGREGADOR | Q10: DISTRICOL | R10: EJECUTADO | S10: 29/09/2025 29-09 PROGRAMACIÓN REALIZADA POR LA ALIANZA | 06/10/2025 SE REALIZA APERTURA EN SITIO ACORDADA CON EL CLIENTE EN OCAÑA, SE INSTALA BATAFONO, VERSION, SE REALIZAN PRUEBAS EXITOSA, SE CAPACITA CLIENTE, PUBLICIDAD, CB OPERATIVO. | T10: VISITA TECNICA | U10: FYZZZ194 | V10: TIPO IV | W10: TERRESTRE | X10: NARANJO AFANADOR RUBEN JESUS | Y10: 1 | Z10: 0 | AA10: 504833 | AB10: 504833
A11: PASTO | B11: SUROCCIDENTE Y EJE CAFETERO | C11: 0004-0003 | D11: 86568 | E11: TA-25-1157240 | F11: 3007081713 | G11: APERTURA | H11: CB CRECIMIENTO ALIANZA - NUEVO | I11: PUTUMAYO | J11: PUERTO ASIS | K11: DISTRICOL FERRETERIA A/S S.A.S | L11: REDEBAN | M11: FO-25-1598692 | N11: 45929.618 | O11: 45932.38 | P11: AGREGADOR | Q11: DISTRICOL | R11: EJECUTADO | S11: 29/09/2025 29-09 PROGRAMACIÓN REALIZADA POR LA ALIANZA | 01/10/2025 NO SE HA PODIDO REALIZAR INSTALACIÓN DE PUBLICIDAD POR PROBLEMAS CLIMATICOS EN LA ZONA, LO CUAL RETRASO LA LABOR, Y EL COMERCIO CIERRA A LAS 17:30 HORAS, POR LO QUE NO SE PUEDE REALIZAR LA INSTALACIÓN EL DIA DE HOY | 02/10/2025 SE VISITO EL COMERCIO PARA DAR APERTURA AL CB, SE INSTALA DATAFONO CON LECTORA BASE Y MAGIC BOX, SE INSTALA PUBLICIDAD Y SE ENTREGA ROLLOS, SE CAPACITA OK, PRUEBAS OK EXCEPTO RECAUDO POR NO TENER ELEMENTOS PARA HACERLA, SOMOS BANCOLOMBIA OK, CB OPERATIVO | T11: VISITA TECNICA | U11: FYZZZ198 | V11: TIPO IV | W11: TERRESTRE | X11: GUERRERO RAMIREZ OSCAR DARIO | Y11: 1 | Z11: 0 | AA11: 504833 | AB11: 504833
A12: PASTO | B12: SUROCCIDENTE Y EJE CAFETERO | C12: 0004-0003 | D12: 52838 | E12: TA-25-1157243 | F12: 3007079019 | G12: APERTURA | H12: DATAFONO ADICIONAL - ALIANZA | I12: NARIÑO | J12: TUQUERRES | K12: PTM NARINO PORTIPLASTICO | L12: REDEBAN | M12: FO-25-1598697 | N12: 45929.622 | O12: 45931.662 | P12: AGREGADOR | Q12: COMCARD - PTM | R12: EJECUTADO | S12: 29/09/2025 29-09 PROGRAMACIÓN REALIZADA POR LA ALIANZA | 22/10/2025 SE REALIZA INSTALACIÓN DE DATAFONO ADICIONAL SE REALIZA PRUEBAS DE RETIRO, DEPOSITO, CONSULTA DE SALDO, NO SE PUEDE REALIZAR PRUEBAS DE OTRAS TRANSACCIONES YA QUE NO SE CUENTA CON RECURSOS PARA REALIZAR DEMÁS TRANSACCIONES CB QUEDA OPERATIVO COMERCIO INFORMA TENER TODA LA PUBLICIDAD DE CB | T12: VISITA TECNICA | U12: FYZZZ199 | V12: TIPO II | W12: TERRESTRE | X12: BRAVO MADROÑERO OSCAR ESTEBAN | Y12: 1 | Z12: 0 | AA12: 163814 | AB12: 163814
A13: MEDELLIN | B13: NOROCCIDENTE | C13: 0004-0005 | D13: 5001 | E13: TA-25-1165173 | F13: 3007081741 | G13: APERTURA | H13: CB CRECIMIENTO ALIANZA - NUEVO | I13: ANTIOQUIA | J13: MEDELLIN | K13: DISTRICOL DROGUERIA EL VERGEL | L13: REDEBAN | M13: FO-25-1611123 | N13: 45931.706 | O13: 45933.517 | P13: AGREGADOR | Q13: DISTRICOL | R13: EJECUTADO | S13: 01/10/2025 01-10 PROGRAMACIÓN REALIZADA POR LA ALIANZA | 03/10/2025 SE INSTALAN EQUIPOS OK | T13: VISITA TECNICA | U13: SUZZZ670 | V13: TIPO I | W13: TERRESTRE | X13: QUINTERO SANCHEZ JUAN SEBASTIAN | Y13: 1 | Z13: 0 | AA13: 75096 | AB13: 75096
... A181: BOGOTA | B181: CUNDINAMARCA | C181: 0004-0004 | D181: 11001 | E181: TA-25-1248010 | F181: 3007082028 | G181: APERTURA | H181: CB CRECIMIENTO ALIANZA - NUEVO | I181: CUNDINAMARCA | J181: BOGOTA | K181: DISTRICOL LUXUR | L181: REDEBAN | M181: FO-25-1751850 | N181: 45959.542 | O181: 45960.586 | P181: AGREGADOR | Q181: DISTRICOL | R181: EJECUTADO | S181: 29/10/2025 29-10 PROGRAMACIÓN REALIZADA POR LA ALIANZA| INSTALACIÓN PROGRAMADA PARA EL 2025-10-30 | 30/10/2025 INSTALACIÓN DE CORRESPONSAL OK PRUEBA OK CAPACITACIÓN SOMOS BANCOLOMBIA OK CAPACITACIÓN IVA OK CAPACITACIÓN DATAFONO OK NO SE REALIZAN PRUEBAS CON TARJETA YA QUE CLIENTE NO CUENTA CON TARJETA DE PRUEBA | T181: VISITA TECNICA | U181: CA002319 | V181: TIPO I | W181: TERRESTRE | X181: GOMEZ VEGA DAVID SNEYDER | Y181: 1 | Z181: 0 | AA181: 75096 | AB181: 75096
AB182: =SUM(AB2:AB181) -> 28693432

Sheet APERTURAS_BBVA
A1: CIUDAD SEDE | B1: ZONA | C1: CENTRO DE COSTOS LINEACOM | D1: CODIGO DANE | E1: TA/CODIGO ACTIVIDAD | F1: CODIGO CB | G1: ACTIVIDAD | H1: TIPO DE APERTURA | I1: DEPARTAMENTO | J1: CIUDAD | K1: NOMBRE DEL CB | L1: RED | M1: FO | N1: FECHA LISTA | O1: FECHA ULTIMA ACTUALIZACION | P1: CODIGO CIIU | Q1: BANCO | R1: ESTADO | S1: OBSERVACIONES CLIENTE | T1: FORMA DE ATENCION | U1: TERMINAL(ES) | V1: TIPIFICACION | W1: TIPO DE TRAYECTO | X1: NOMBRE DEL TECNICO | Y1: DIAS DE VISITA | Z1: DIA ADICIONAL | AA1: VALOR DIAS ACTIVIDAD FACTURABLES | AB1: VALOR TOTAL
A2: MEDELLIN | B2: NOROCCIDENTE | C2: 0004-0005 | D2: 5001 | E2: TA-25-1237761 | F2: 3013001502 | G2: APERTURA | I2: ANTIOQUIA | J2: MEDELLIN | K2: EXPOSICIONES | L2: BBVA | M2: FO-25-1730672 | N2: 45954.701 | O2: 45958.485 | R2: EJECUTADO | S2: 24/10/2025 24/10/2025 23-10 SE REALIZA LLAMADA AL CLIENTE, SE HABLA CON EL SR JUAN CASTAÑEDA SE VALIDA DIRECCIÓN OK, CANAL OK, DISPONIBILIDAD TOTA, LLAMAR EL DÍA LA INSTALACIÓN PARA CONFIRMAR VISITA | 28/10/2025 INSTALACIÓN EXITOSA SE ENTREGARON 20 ROLLOS | T2: VISITA TECNICA | U2: AE004031 | V2: TIPO I | W2: TERRESTRE | X2: CASTAÑEDA PALACIO CARLOS FELIPE | Y2: 1 | Z2: 0 | AA2: 75096 | AB2: =AA2*Y2 -> 75096
AB3: =SUM(AB2) -> 75096

Sheet INCIDENTES_BANCOLOMBIA
A1: CIUDAD SEDE | B1: ZONA | C1: CENTRO DE COSTOS LINEACOM | D1: CODIGO DANE | E1: TA/CODIGO ACTIVIDAD | F1: CODIGO CB | G1: ACTIVIDAD | H1: DEPARTAMENTO | I1: CIUDAD | J1: NOMBRE DEL CB | K1: RED | L1: FO | M1: FECHA ASIGNACION A LINEA COMUNICACIONES | N1: FECHA CIERRE DEL TICKET (DD/MM/AAAA HH:MM) | O1: ACOMETIDA | P1: GRUPO_FALLA | Q1: CATEGORIA | R1: FALLA | S1: FORMATO | T1: CADENA | U1: ESTADO | V1: OBSERVACION | W1: FORMA DE ATENCION | X1: TERMINAL(ES) | Y1: TIPIFICACION | Z1: TIPO DE TRAYECTO | AA1: NOMBRE DEL TECNICO | AB1: DIAS DE VISITA | AC1: DIA ADICIONAL | AD1: VALOR DIAS ACTIVIDAD FACTURABLES | AE1: VALOR TOTAL
A2: MEDELLIN | B2: NOROCCIDENTE | C2: 0004-0005 | D2: 27075 | E2: 2769787 | F2: 3007050373 | G2: INCIDENTE | H2: CHOCO | I2: BAHIA SOLANO | J2: BARRIO FILLO CASTRO BAHIA SOLA | K2: REDEBAN | L2: FO-25-1560569 | M2: 45920.643 | N2: 45932.56 | O2: NO | P2: HARDWARE | Q2: LECTOR DE TARJETAS | R2: DAÑO POS | S2: UNO A UNO | T2: CB UNO A UNO | U2: EJECUTADO | V2: 21/09/2025 SE ESCALA PARA VISITA. LLAMAR ANTES DE VISITAR, CONFIRMAR FALLA Y DATOS | 24/09/2025 NO SE HA LOGRADO CONSEGUIR VUELO IDONEO DEBIDO A TEMPORADA ALTA EN LA ZONA POR AVISTAMIENTO DE BALLENAS. CONTINUAMOS EN CONSULTA CON AEROLINEAS PARA CONSEGUIR VUELO. | 02/10/2025 SE CAMBIA EQUIPO POR DAÑO EN LECTOR CHIP | W2: VISITA TECNICA | X2: TR00D584 | Y2: TIPO V | Z2: AEREO | AA2: BADEL ACUÑA LUIS ALBERTO | AB2: 1 | AC2: 0 | AD2: 988463 | AE2: 988463
A3: PASTO | B3: SUROCCIDENTE Y EJE CAFETERO | C3: 0004-0003 | D3: 86320 | E3: 2790533 | F3: 3007060644 | G3: INCIDENTE | H3: PUTUMAYO | I3: ORITO | J3: DISTRICOL JPULIDO | K3: REDEBAN | L3: FO-25-1580246 | M3: 45924.74 | N3: 45932.567 | O3: NO | P3: HARDWARE | Q3: TECLADO | R3: DAÑO POS | S3: AGREGADOR | T3: DISTRICOL | U3: EJECUTADO | V3: 24/09/2025 SE ESCALA PARA VISITA. LLAMAR ANTES DE VISITAR, CONFIRMAR FALLA Y DATOS | 27/09/2025 NO SE PUEDE REALIZAR DESPLAZAMIENTO A LA ZONA POR PROBLEMAS EN LA VIA, DADO SE REQUIERE CAMBIO DE EQUIPO, SE REALIZARA VALIDACION PARA DESPLAZARNOS LA PROXIMA SEMANA. | 02/10/2025 SE VISITA CB. SE EVIDENCIA DATAFONO CON DETERIORO EN EL TECLADO, SE REALIZA CAMBIO DE EQUIPO. SE REALIZAN PRUEBAS TX EXITOSAS. QUEDA OPERATIVO | W3: VISITA TECNICA | X3: MA00C933 | Y3: TIPO IV | Z3: TERRESTRE | AA3: CASTILLO HERRERA ALEX RICARDO | AB3: 1 | AC3: 0 | AD3: 479589 | AE3: 479589
A4: VILLAVICENCIO | B4: REMOTAS | C4: 0004-0007 | D4: 95001 | E4: 2791700 | F4: 3007080059 | G4: INCIDENTE | H4: GUAVIARE | I4: SAN JOSE DEL GUAVIARE | J4: BARRIO EL PORVENIR SAN JOSE DEL GUAVIARE 4 | K4: REDEBAN | L4: FO-25-1581442 | M4: 45925.357 | N4: 45931.732 | O4: NO | P4: HARDWARE | Q4: IMPRESION | R4: NO AVANZA PAPEL | S4: UNO A UNO | T4: UNO A UNO | U4: EJECUTADO | V4: 25/09/2025 EN COMUNICACIÓN CON LA SRA MARY RESTREPO AL NÚMERO 3134977520 NOS INFORMA QUE LA FALLA ES CON LA IMPRESION, CONFIRMA DATOS E INDICA QUE LA RED ES REDEBAN, SE ESCALA PARA VISITA | 01/10/2025 SE REALIZA CAMBIO DE EQUIPO POR DAÑO EN ENGRANAJE DE ENTREGA OPERATIVO SIN NOVEDAD | W4: VISITA TECNICA | X4: SAXZZ468 | Y4: TIPO IV | Z4: TERRESTRE | AA4: ROZO JIMENEZ EDGAR ARMANDO | AB4: 1 | AC4: 0 | AD4: 479589 | AE4: 479589
A5: MEDELLIN | B5: NOROCCIDENTE | C5: 0004-0005 | D5: 5040 | E5: 2802931 | F5: 3007031338 | G5: INCIDENTE | H5: ANTIOQUIA | I5: ANORI | J5: BARRIO PARQUE 2 | K5: REDEBAN | L5: FO-25-1592836 | M5: 45927.453 | N5: 45931.343 | O5: NO | P5: HARDWARE | Q5: IMPRESION | R5: NO IMPRIME UNO O VARIOS CARACTERES | S5: CB UNO A UNO | T5: CB UNO A UNO | U5: EJECUTADO | V5: 27/09/2025 EN COMUNICACIÓN CON LA SRA MARIA DURLEY MEJIA TELÉFONO AL NÚMERO 3105209400 NOS INFORMA QUE LA FALLA ES CON LA IMPRESION, CONFIRMA DATOS E INDICA QUE LA RED ES REDEBAN, SE ESCALA PARA VISTA | 30/09/2025 SE REALIZA VISITA TÉCNICA EN RESPUESTA AL INCIDENTE REPORTADO CON EL DATÁFONO DEL CORRESPONSAL BANCOLOMBIA. EL USUARIO CONFIRMA SU IDENTIFICACIÓN Y PROCEDE A INFORMAR QUE EL EQUIPO ESTÁ GENERANDO VOUCHERS CON IMPRESIÓN BORROSA, OMITIENDO ALGUNOS CARACTERES. TRAS LA VALIDACIÓN DEL FUNCIONAMIENTO, SE IDENTIFICA DESGASTE EN EL RODILLO DE IMPRESIÓN. SE PROCEDE AL REEMPLAZO DEL COMPONENTE, DEJANDO EL DATÁFONO OPERATIVO Y CON IMPRESIÓN LEGIBLE. EL USUARIO VERIFICA Y CONFIRMA LA CORRECTA RESOLUCIÓN DEL INCONVENIENTE. | W5: VISITA TECNICA | X5: 11116372 | Y5: TIPO IV | Z5: TERRESTRE | AA5: MARTINEZ TOVAR OSCAR DAVID | AB5: 1 | AC5: 0 | AD5: 479589 | AE5: 479589
A6: APARTADO | B6: NOROCCIDENTE | C6: 0004-0005 | D6: 27615 | E6: 2802933 | F6: 3007076760 | G6: INCIDENTE | H6: CHOCO | I6: RIOSUCIO | J6: BARRIO ESCOBAR AL LADO DEL COL | K6: REDEBAN | L6: FO-25-1592828 | M6: 45927.454 | N6: 45931.416 | O6: NO | P6: SOFTWARE | Q6: LECTOR DE TARJETAS | R6: CTL CONFIGURACION LECTOR INTERNAL | S6: CB UNO A UNO | T6: CB UNO A UNO | U6: EJECUTADO | V6: 27/09/2025 EN COMUNICACIÓN CON EL SR LUIS FERNANDO ORTIZ TELÉFONO AL NÚMERO 3105142732 NOS INDICA QUE LA FALLA ES CON EL LECTOR DE TARJETAS, CONFIRMA DATOS E INDICA QUE LA RED ES REDEBAN, SE ESCALA PARA VISITA | 01/10/2025 SE REALIZA LIMPIEZA Y MANTENIMIENTO DEL EQUIPO Y LEE LAS TARJETAS PERFECTAMENTE, PRUEBAS EXITOSAS SERVICIO OPERATIVO OK | W6: VISITA TECNICA | X6: A48ZZ319 | Y6: TIPO V | Z6: TERRESTRE/FLUVIAL | AA6: ZAPATA LOPEZ EDWARD ASDRUBAL | AB6: 1 | AC6: 0 | AD6: 479589 | AE6: 479589
A7: CARTAGENA | B7: COSTA | C7: 0004-0001 | D7: 13430 | E7: 2803330 | F7: 3007016325 | G7: INCIDENTE | H7: BOLIVAR | I7: MAGANGUE | J7: ARRIO CENTRO MAGANGUE | K7: REDEBAN | L7: FO-25-1594667 | M7: 45927.644 | N7: 45931.598 | O7: NO | P7: HARDWARE | Q7: FLAS FULL | R7: MEMORIA DEL DISPOSITIVO INSUFICIENTE | S7: CB UNO A UNO | T7: CB UNO A UNO | U7: EJECUTADO | V7: 28/09/2025 SE ESCALA PARA VISITA. LLAMAR ANTES DE VISITAR, CONFIRMAR FALLA Y DATOS | 01/10/2025 SE VISITA COMERCIO POR FALLA, SE HACE BORRADO S.O Y SE CARGA NUEVAMENTE, SE DEJA CON LA VERSIÓN 9.90, SE INICIALIZA DATÁFONO, SE REALIZA PRUEBA OK. | W7: VISITA TECNICA | X7: ON004007 | Y7: TIPO IV | Z7: TERRESTRE | AA7: CACERES HERNANDEZ ANDRES | AB7: 1 | AC7: 0 | AD7: 479589 | AE7: 479589
A8: MEDELLIN | B8: NOROCCIDENTE | C8: 0004-0005 | D8: 5086 | E8: 2805048 | F8: 3007081138 | G8: INCIDENTE | H8: ANTIOQUIA | I8: BELMIRA | J8: BARRIO BELMIRA BELMIRA | K8: REDEBAN | L8: FO-25-1596229 | M8: 45929.351 | N8: 45931.328 | O8: NO | P8: SOFTWARE | Q8: LECTOR DE TARJETAS | R8: CTL CONFIGURACION LECTOR INTERNAL | S8: UNO A UNO | T8: UNO A UNO | U8: EJECUTADO | V8: 29/09/2025 SE ESCALA PARA VISITA. LLAMAR ANTES DE VISITAR, CONFIRMAR FALLA Y DATOS | 04/10/2025 SE RECONGIFURA EL EQUIPO NUEVAMENTE Y SE INICIALIZA NUEVAMENTE | W8: VISITA TECNICA | X8: SIZZZ882 | Y8: TIPO II | Z8: TERRESTRE | AA8: CARDONA MOLINA BROLIN STIVEN | AB8: 1 | AC8: 0 | AD8: 144968 | AE8: 144968
A9: NEIVA | B9: REMOTAS | C9: 0004-0007 | D9: 41349 | E9: 2807230 | F9: 3007031383 | G9: INCIDENTE | H9: HUILA | I9: HOBO | J9: BARRIO LOS PINOS | K9: REDEBAN | L9: FO-25-1607884 | FO-25-1598160 | M9: 45929.441 | N9: 45931.434 | O9: NO | P9: ENTIDAD | Q9: ERROR DE TRANSACCIONES | R9: TRANSACCION NO PERMITIDA | S9: CB UNO A UNO | T9: CB UNO A UNO | U9: EJECUTADO | EJECUTADO / CANCELADO | V9: 01/10/2025 SE REALIZA VISITA AL PUNTO NUEVAMENTE YA QUE ESTE HABIA QUEDADO EN RECHAZO GENERAL DESPUÉS DEL CAMBIO QUE SE REALIZO POR DAÑO, RG QUE NO SE PUDO GESTIONAR POR FALTA DE SOPORTE POR HORA . SE REALIZA GESTIÓN CON RBM SE INICIALIZA EQUIPO SE REALIZAN PRUEBAS EXITOSAS. SE DEJA EQUIPO CON VR 10.3 PRUEBAS CB OK . ***SE REALIZA LLAMADA A LA LÍNEA DEL BANCO 018000953344, LOS CUALES INDICAN QUE EL PUNTO SE ENCONTRABA BLOQUEADO POR RAZONES SE ASUNTOS INTERNOS, SE DESBLOQUEA PUNTO SE REALIZAN PRUEBAS PERO EN LA LÍNEA INDICAN QUE POSIBLEMENTE LO VOVERAN A BLOQUEAR. SE LE INDICA AL CLIENTE QUE SI ESTO OCURRE DEBE COMUNICACARSE DIRECTAMENTE A LA LÍNEA Y VALIDAR EL MOTIVO DEL BLOQEO . | W9: VISITA TECNICA | X9: BL01Y558 | Y9: TIPO II | Z9: TERRESTRE | AA9: DEVIA REINOSO JUAN CARLOS | AB9: 1 | AC9: 0 | AD9: 144968 | AE9: 144968
A10: YOPAL | B10: REMOTAS | C10: 0004-0007 | D10: 85230 | E10: 2807561 | F10: 3007073242 | G10: INCIDENTE | H10: CASANARE | I10: OROCUE | J10: DISTRICOL DROGAS OROCUE | K10: REDEBAN | L10: FO-25-1598133 | M10: 45929.461 | N10: 45931.728 | O10: NO | P10: SOFTWARE | Q10: LECTOR DE BARRAS | R10: LECTOR DESCONFIGURADO | S10: AGREGADOR | T10: DISTRICOL | U10: EJECUTADO | V10: 29/09/2025 SE ESCALA PARA VISITA. LLAMAR ANTES DE VISITAR, CONFIRMAR FALLA Y DATOS SE COMUNICA AL 3124832415 SE LE MARCA EN REPETIDAS OCACIONES PERO NO FUE POSIBLE LA COMUNICACION | 02/10/2025 SE VISITA COMERCIO, SE REALIZA CAMBIA DE LECTOR DE BARRAS. PRUEBAS OK. OPERATIVO EL SERVICIO | W10: VISITA TECNICA | X10: SV00T122 | Y10: TIPO V | Z10: TERRESTRE/FLUVIAL | AA10: BERNAL ELAICA EDGAR ALEXIS | AB10: 1 | AC10: 0 | AD10: 479589 | AE10: 479589
A11: MEDELLIN | B11: NOROCCIDENTE | C11: 0004-0005 | D11: 27245 | E11: 2807610 | F11: 3007060835 | G11: INCIDENTE | H11: CHOCO | I11: EL CARMEN DE ATRATO | J11: BARRIO EL SIETE EL CARMEN DE A | K11: REDEBAN | L11: FO-25-1598127 | M11: 45929.462 | N11: 45932.569 | O11: NO | P11: HARDWARE | Q11: ALERT IRRUPTION | R11: ALERT IRRUPTION | S11: CB UNO A UNO | T11: CB UNO A UNO | U11: EJECUTADO | V11: 29/09/2025 SE ESCALA PARA VISITA. SE COMUNICA JUAN ALEJO PARA REPORTAR QUE SU DATÁFONO SE LE QUEDÓ BLOQUEADO, SE LE QUEDÓ EN PANTALLA AZUL CON EL ERROR "ALERT INTERRUPTION LLAMAR ANTES DE VISITAR, CONFIRMAR FALLA Y DATOS | 02/10/2025 SE CAMBIA EQUIPO POR ALERTA INTERRUPTION TODO OK | W11: VISITA TECNICA | X11: FUA0G719 | Y11: TIPO IV | Z11: TERRESTRE | AA11: ALVAREZ ARENAS VICTOR HUGO | AB11: 1 | AC11: 0 | AD11: 479589 | AE11: 479589
A12: VALLEDUPAR | B12: COSTA | C12: 0004-0001 | D12: 20383 | E12: 2808585 | F12: 3007032450 | G12: INCIDENTE | H12: CESAR | I12: LA GLORIA | J12: BARRIO LA MATA LA GLORIA CESAR | K12: REDEBAN | L12: FO-25-1598871 | M12: 45929.527 | N12: 45931.419 | O12: NO | P12: HARDWARE | Q12: LECTOR DE TARJETAS | R12: DAÑO POS | S12: CB UNO A UNO | T12: CB UNO A UNO | U12: EJECUTADO | V12: 29/09/2025 SE ESCALA PARA VISITA. LLAMAR ANTES DE VISITAR, CONFIRMAR FALLA Y DATOS | 01/10/2025 BUENOS DÍAS SE VISITA CB Y SE VALIDA QUE EL DATAFONO NO LEE TARJETAS, SE PROCEDE A HACER EL CAMBIO Y TODO QUEDA OK SE HACEN PRUEBAS DE TRANSACCIONES | W12: VISITA TECNICA | X12: 11GZZ509 | Y12: TIPO IV | Z12: TERRESTRE | AA12: BENITEZ CARVAJAL ALVARO JAVIER | AB12: 1 | AC12: 0 | AD12: 479589 | AE12: 479589
A13: VALLEDUPAR | B13: COSTA | C13: 0004-0001 | D13: 13473 | E13: 2809305 | F13: 3007061347 | G13: INCIDENTE | H13: BOLIVAR | I13: MORALES | J13: BARRIO MINA GALLO MORALES | K13: REDEBAN | L13: FO-25-1599476 | M13: 45929.591 | N13: 45931.385 | O13: NO | P13: HARDWARE | Q13: COMUNICACION | R13: MENSAJE CABLE DE RED DESCONECTADO | S13: CB UNO A UNO | T13: CB UNO A UNO | U13: EJECUTADO | V13: 29/09/2025 SE ESCALA PARA VISITA. LLAMAR ANTES DE VISITAR, CONFIRMAR FALLA Y DATOS SE MARCA EN DIFERENTES OCACIONES A LOS N- DE CONTACTO PERO NO FUE POSIBLE LA COMUNICACION 3128020947 - 3148118261 | 01/10/2025 SE REALIZAN VARIOS INTENTOS DE PODER TENER COMUNICACIÓN CON LA SRA ANGELICA ARRIETA Y/O LEDYS RINCON A LOS NUMEROS DE CONTACTO 3128020947- 3148118261 PROPORCIONADOS EN LA ORDEN Y NO HA SIDO POSIBLE COMUNICARME CON ELLAS POR MEDIO DE WHATSAPP TAMBIEN SE HA TRATADO DE ESTABLECER COMUNICACIÓN Y TAMPOCO SE HA LOGRADO, PARA PODER SABER LAS INDICACIONES DE LA CLIENTE Y PODER LLEGAR AL SITIO YA QUE ES ZONA ROJA Y QUEDA DICHO SITIO BASTANTE RETIRADO | 01/10/2025 SE REALIZA VISITA AL CB, SE VALIDA Y EL CLIENTE COMENTA QUE EL DATÁFONO PIERDE CONSTANTEMENTE LA CONEXIÓN A INTERNET, SE HACEN PRUEBAS SONDE SE EVIDENCIO EL DAÑO, SE PROCEDE A HACER CAMBIO DEL EQUIPO, SE CONFIGURA Y SE HACEN PRUEBAS DEJANDO TODO OK | W13: VISITA TECNICA | X13: HA00J530 | Y13: TIPO IV | Z13: TERRESTRE | AA13: GONZALEZ ESTUPIÑAN YEISON WALTER ANTONIO | AB13: 1 | AC13: 0 | AD13: 479589 | AE13: 479589
A14: VILLAVICENCIO | B14: REMOTAS | C14: 0004-0007 | D14: 50318 | E14: 2810965 | F14: 3007053978 | G14: INCIDENTE | H14: META | I14: GUAMAL | J14: BARRIO FUNDADORES GUAMAL 2 | K14: REDEBAN | L14: FO-25-1600762 | M14: 45929.688 | N14: 45931.545 | O14: NO | P14: SOFTWARE | Q14: COMUNICACION | R14: VERIFIQUE PARAMETROS | S14: CB UNO A UNO | T14: CB UNO A UNO | U14: EJECUTADO | V14: 29/09/2025 SE ESCALA ACTIVIDAD PARA GESTION WOMPI | 01/10/2025 SE REALIZA AJUSTES SE VERIFICA PARÁMETROS SE ENTREGA OPERATIVO YA QUE PRECENTABA BLOQUEO | W14: VISITA TECNICA | X14: XP1ZZ999 | Y14: TIPO II | Z14: TERRESTRE | AA14: ROZO JIMENEZ EDGAR ARMANDO | AB14: 1 | AC14: 0 | AD14: 144968 | AE14: 144968
A15: CARTAGENA | B15: COSTA | C15: 0004-0001 | D15: 13657 | E15: 2812340 | F15: 3007038271 | G15: INCIDENTE | H15: BOLIVAR | I15: SAN JUAN NEPOMUCENO | J15: BARRIO LA TRONCAL SAN JUAN DE | K15: REDEBAN | L15: FO-25-1601504 | M15: 45930.333 | N15: 45931.62 | O15: NO | P15: HARDWARE | Q15: LECTOR DE TARJETAS | R15: MENSAJE RETIRE TARJETA | S15: CB UNO A UNO | T15: CB UNO A UNO | U15: EJECUTADO | V15: 30/09/2025 SE ESCALA PARA VISITA. LLAMAR ANTES DE VISITAR, CONFIRMAR FALLA Y DATOS | 01/10/2025 SE REALIZA VISITA TÉCNICA, SE CAMBIA EL DATAFONO, SE REALIZAN PRUEBAS EXITOSAS, EQUIPO FUNCIONA CORRECTAMENTE, CB QUEDA OPERATIVO. | W15: VISITA TECNICA | X15: AB00U639 | Y15: TIPO II | Z15: TERRESTRE | AA15: DE AGUAS MUÑOZ DAVID JOSE | AB15: 1 | AC15: 0 | AD15: 144968 | AE15: 144968
A16: BOGOTA | B16: CUNDINAMARCA | C16: 0004-0004 | D16: 25483 | E16: 2812525 | F16: 3007068889 | G16: INCIDENTE | H16: CUNDINAMARCA | I16: NARIÑO | J16: INMACULADA NARINO | K16: REDEBAN | L16: FO-25-1601513 | M16: 45930.333 | N16: 45931.438 | O16: NO | P16: HARDWARE | Q16: LECTOR DE BARRAS | R16: CABLE LECTORA AVERIADO | S16: CB UNO A UNO | T16: CB UNO A UNO | U16: EJECUTADO | V16: 30/09/2025 SE INTENTA COMUNICACIÓN CON LA SRA ADRIANA LUCÍA BERMUDEZ RAMÍREZ AL NÚMERO 3204940662 PARA CONFIRMAR DATOS Y FALLA PERO NO HAY CONTACTO, SE ESCALA AL COORDINADOR DE ZONA PARA VALIDAR EN SITIO | 01/10/2025 SE REALIZA VISITA DE CAMPO ENCONTRADO QUE LECTORA NO PRENDE, POR LO ANTERIOR SE REALIZA CAMBIO DE LECTORA PRUEBAS CUPO Y USUARIO OK. | W16: VISITA TECNICA | X16: AAJYZ123 | Y16: TIPO III | Z16: TERRESTRE | AA16: LOZADA ROJAS CHRISTIAN ANDRES | AB16: 1 | AC16: 0 | AD16: 275729 | AE16: 275729
A17: BUCARAMANGA | B17: SANTANDERES | C17: 0004-0008 | D17: 68235 | E17: 2812626 | F17: 3007066522 | G17: INCIDENTE | H17: SANTANDER | I17: EL CARMEN DE CHUCURI | J17: BARRIO EL CARMEN DE CHUCURI EL | K17: REDEBAN | L17: FO-25-1601956 | M17: 45930.347 | N17: 45931.622 | O17: NO | P17: HARDWARE | Q17: SE REINICIA | R17: DAÑO POS | S17: CB UNO A UNO | T17: CB UNO A UNO | U17: EJECUTADO | V17: 30/09/2025 SE ESCALA PARA VISITA. LLAMAR ANTES DE VISITAR, CONFIRMAR FALLA Y DATOS, SE CONTACTA CON LA SRA JENNY MAGALLY MIELES REPORTAR QUE EL DATAFONO NO ESTA FUNCIONANDO, REGISTRA ERROR DE CONEXION, CABLE TST DESCONECTADO 3102645047 8 : 40 | 01/10/2025 CB CON EQUIPO EN DAÑO, CAMBIO DE DATAFONO Y FUENTE, BORRADO E INYECCION DE SO +VER 9.90, CONFIGURACION CB OK, CUBRE CLAVE OK, PRUEBAS OK. | W17: VISITA TECNICA | X17: 4A00W942 | Y17: TIPO IV | Z17: TERRESTRE | AA17: SANTOS GONZALEZ JOHAN FABIAN | AB17: 1 | AC17: 0 | AD17: 479589 | AE17: 479589
A18: PASTO | B18: SUROCCIDENTE Y EJE CAFETERO | C18: 0004-0003 | D18: 52788 | E18: 2812696 | F18: 3007030800 | G18: INCIDENTE | H18: NARIÑO | I18: TANGUA | J18: BARRIO SAN RAFAEL | K18: REDEBAN | L18: FO-25-1602098 | M18: 45930.361 | N18: 45931.628 | O18: NO | P18: HARDWARE | Q18: COMUNICACION | R18: DAÑO POS | S18: CB UNO A UNO | T18: CB UNO A UNO | U18: EJECUTADO | V18: 30/09/2025 SE ESCALA PARA VISITA. LLAMAR ANTES DE VISITAR, CONFIRMAR FALLA Y DATOS | 01/10/2025 SE REALIZA CAMBIO DE DATAFONO POR DAÑO EN PUERTO DE INTERNET, SE RECONFIGURA OK PARÁMETROS OK Y SE REALIZAN PRUEBAS ÉXITOSAS DE TRANSACCIONES | W18: VISITA TECNICA | X18: BRZZZ268 | Y18: TIPO II | Z18: TERRESTRE | AA18: PAZ MARTINEZ RICHARD HUMBERTO | AB18: 1 | AC18: 0 | AD18: 144968 | AE18: 144968
A19: MEDELLIN | B19: NOROCCIDENTE | C19: 0004-0005 | D19: 5030 | E19: 2812900 | F19: 3007041623 | G19: INCIDENTE | H19: ANTIOQUIA | I19: AMAGA | J19: BARRIO MINAS AMAGA | K19: REDEBAN | L19: FO-25-1602091 | M19: 45930.363 | N19: 45931.625 | O19: NO | P19: HARDWARE | Q19: LECTOR DE TARJETAS | R19: DAÑO POS | S19: CB UNO A UNO | T19: CB UNO A UNO | U19: EJECUTADO | V19: 30/09/2025 SE ESCALA PARA VISITA. LLAMAR ANTES DE VISITAR, CONFIRMAR FALLA Y DATOS | 01/10/2025 SE REALIZA CAMBIO DE DATAFONO POR LECTOR DE TARJETAS MALO , RAYA LAS TARJETAS SE HACEN PRUEBAS OK | W19: VISITA TECNICA | X19: FUA0U710 | Y19: TIPO II | Z19: TERRESTRE | AA19: MONTOYA VELEZ ANDRES FELIPE | AB19: 1 | AC19: 0 | AD19: 144968 | AE19: 144968
A20: MEDELLIN | B20: NOROCCIDENTE | C20: 0004-0005 | D20: 5400 | E20: 2813256 | F20: 3007079629 | G20: INCIDENTE | H20: ANTIOQUIA | I20: LA UNION | J20: BARRIO EL EDEN LA UNION | K20: REDEBAN | L20: FO-25-1602346 | M20: 45930.387 | N20: 45931.501 | O20: NO | P20: HARDWARE | Q20: IMPRESION | R20: NO AVANZA PAPEL | S20: CB UNO A UNO | T20: CB UNO A UNO | U20: EJECUTADO | V20: 01/10/2025 CAMBIO EQUIPO POR DAÑO NO AVANZA PAPEL PRUEBAS OK NO TELECARGA | W20: VISITA TECNICA | X20: SXUZZ155 | Y20: TIPO II | Z20: TERRESTRE | AA20: PAREJA ECHAVARRIA JHON DAVID | AB20: 1 | AC20: 0 | AD20: 144968 | AE20: 144968
A21: CALI | B21: SUROCCIDENTE Y EJE CAFETERO | C21: 0004-0003 | D21: 76306 | E21: 2813273 | F21: 3007029986 | G21: INCIDENTE | H21: VALLE DEL CAUCA | I21: GINEBRA | J21: BARRIO GINEBRA GINEBRA | K21: REDEBAN | L21: FO-25-1602545 | M21: 45930.388 | N21: 45931.444 | O21: NO | P21: HARDWARE | Q21: CABLEADO | R21: CABLE MAGICBOX AVERIADO | S21: CB UNO A UNO | T21: CB UNO A UNO | U21: EJECUTADO | V21: 30/09/2025 SE ESCALA PARA VISITA. LLAMAR ANTES DE VISITAR, CONFIRMAR FALLA Y DATOS | 01/10/2025 EN LA VISITA TÉCNICA VISITA TÉCNICA SE REALIZÓ EL CAMBIO DE LA FUENTE DE PODER Y CABLE MAGIC BOX TETRA DESK 3500,YA QUE DICHO CABLE SE ENCONTRÓ AVERIADO,SE REALIZÓ LIMPIEZA A LA IMPRESORA Y SE AJUSTÓ EL RODILLO CORRECTAMENTE,EL SERVICIO QUEDÓ OPERATIVO SIN FALLAS Y SIN NOVEDAD. | W21: VISITA TECNICA | X21: BBJZZ206 | Y21: TIPO II | Z21: TERRESTRE | AA21: SANCHEZ URREGO ROBINSON DAVID | AB21: 1 | AC21: 0 | AD21: 144968 | AE21: 144968
... A38: BOGOTA | B38: CUNDINAMARCA | C38: 0004-0004 | D38: 25126 | E38: 2816002 | F38: 3007024381 | G38: INCIDENTE | H38: CUNDINAMARCA | I38: CAJICA | J38: MULTIPAGAS CAJICA | K38: REDEBAN | L38: FO-25-1605147 | M38: 45930.546 | N38: 45931.571 | O38: NO | P38: HARDWARE | Q38: HUB | R38: SE REINICIA | S38: ROBUSTO | T38: MULTIPAGAS | U38: EJECUTADO | V38: 30/09/2025 SE ESCALA PARA VISITA. LLAMAR ANTES DE VISITAR, CONFIRMAR FALLA Y DATOS | 01/10/2025 ME ENCUENTRO EN SITIO EN ESPERA DE INGRESO, SE ENCUENTRAN VALIDANDO IDENTIDAD DEL TÉCNICO | 01/10/2025 SE REALIZA VISITA DE CAMPO ENCONTRANDO QUE HUB REINICIA EL DATAFONO AL MOMENTO DE REALIZAR UNA TX SE CAMBIA HUB REALIZANDO PRUEBAS OK PARÁMETROS OKAY A CONFORMIDAD DE CORRESPONSAL SIN NOVEDAD EN INCIDENTE | W38: VISITA TECNICA | X38: ABCFZ919 | Y38: TIPO II | Z38: TERRESTRE | AA38: GALEANO SORIANO JUAN DAVID | AB38: 1 | AC38: 0 | AD38: 144968 | AE38: 144968
A39: VILLAVICENCIO | B39: REMOTAS | C39: 0004-0007 | D39: 50370 | E39: 2816008 | F39: 3007067482 | G39: INCIDENTE | H39: META | I39: URIBE | J39: BARRIO DIVISO ZONA RURAL URIBE | K39: REDEBAN | L39: FO-25-1605144 | M39: 45930.547 | N39: 45939.39 | P39: HARDWARE | Q39: CABLEADO | R39: CABLE MAGICBOX AVERIADO | S39: UNO A UNO | T39: CB UNO A UNO | V39: 30/09/2025 SE ESCALA PARA VISITA. LLAMAR ANTES DE VISITAR, CONFIRMAR FALLA Y DATOS | 06/10/2025 POR TEMAS DE ORDEN PÚBLICO EN LA ZONA, SE REALIZARA ENVÍO DE CABLES POR CARROS DE LA ZONA. AUTORIZADO POR YENNY GARZÓN | 07/10/2025 SE REALIZA CONTACTO TELEFÓNICO CON LA SEÑORA LILIANA Y SE LE INFORMA QUE LOS CABLES FUERON ENVIADOS POR EL MEDIO DE TRANSPORTE QUE NOS INFORMO. SE REALIZO CONTACTO CON LA SEÑORA LILIANA LA CUAL INFORMA QUE REALIZO EL CAMBIO DE CABLEADO Y QUEDO FUNCIONANDO OK | W39: SOPORTE TELEFONICO | Y39: TIPO V | Z39: AEREO | AA39: PEDREROS CONTRERAS MICHAEL STEVENS | AB39: 0 | AC39: 0 | AD39: 41241 | AE39: 41241
A40: BOGOTA | B40: CUNDINAMARCA | C40: 0004-0004 | D40: 11001 | E40: 2816020 | F40: 3007053507 | G40: INCIDENTE | H40: CUNDINAMARCA | I40: BOGOTA | J40: BARRIO CHUSACA BOGOTA | K40: REDEBAN | L40: FO-25-1605135 | M40: 45930.553 | N40: 45931.615 | O40: NO | P40: HARDWARE | Q40: LECTOR DE TARJETAS | R40: MENSAJE RETIRE TARJETA | S40: CB UNO A UNO | T40: CB UNO A UNO | U40: EJECUTADO | V40: 30/09/2025 SE ESCALA PARA VISITA. LLAMAR ANTES DE VISITAR, CONFIRMAR FALLA Y DATOS | 01/10/2025 11:45 DURANTE LA VISITA ES NECESARIO CAMBIAR EL EQUIPO YA QUE ES RECURRENTE LA FALLA, TÉCNICO CUENTA CON DOS EQUIPOS DE BACKUP DESK 2600 PERO NINGUNO CARGA INTERNET SE REALIZAN VARIAS PRENDAS DESCARTANDO MAGIC BOX, CABLES ETC PERO LA FALLA PERSISTE, INTERNET DEL CLIENTE OK SE PRUEBA CON OTROS DISPOSITIVOS TÉCNICO RECOGERÁ UN DATAFONO DESK 3500 PARA REALIZAR LAS PRUEBAS | 01/10/2025 SE REALIZA CAMBIO DE EQUIPO POR DAÑO RETIRE TARJETA CONSTANTE SERVICIO OPERATIVO PRUEBAS OK TRNA RBM CB CUENTA CON IP FIJA 10.35.201.60 PUERTA DE ENLACE TERMINADA EN 1, ANTES DE CULMINAR EL EQUIPO DE SISTEMAS REALIZARÁ CAMBIO DE ESTÁ IP PARA QUE QUEDE EN DHCP PIDEN ESPERAR MIENTRAS CONFIGURAN EL SWITCH 14:00 TÉCNICO INDICA QUE MÁXIMO PUEDE ESPERAR 20 MINUTOS | W40: VISITA TECNICA | X40: TR0VZ584 | Y40: TIPO I | Z40: TERRESTRE | AA40: BUSTOS MORA DIEGO MANUEL | AB40: 1 | AC40: 0 | AD40: 65960 | AE40: 65960
A41: MEDELLIN | B41: NOROCCIDENTE | C41: 0004-0005 | D41: 5001 | E41: 2816392 | F41: 3007017886 | G41: INCIDENTE | H41: ANTIOQUIA | I41: MEDELLIN | J41: ALKOMPRAR SAN DIEGO | K41: REDEBAN | L41: FO-25-1605638 | M41: 45930.601 | N41: 45931.464 | O41: NO | P41: HARDWARE | Q41: CABLEADO | R41: DAÑO POS | S41: RETAIL | T41: ALKOMPRAR | U41: EJECUTADO | V41: 30/09/2025 SE ESCALA PARA VISITA. LLAMAR ANTES DE VISITAR, CONFIRMAR FALLA Y DATOS | 01/10/2025 SE CAMBIA CABLE ENSORTIJADO YA QUE ESTA PARTIDO Y ESTABA CAUSANDO REINICIOS | W41: VISITA TECNICA | X41: JRZZZ853 | Y41: TIPO I | Z41: TERRESTRE | AA41: BADEL ACUÑA LUIS ALBERTO | AB41: 1 | AC41: 0 | AD41: 65960 | AE41: 65960
A42: CARTAGENA | B42: COSTA | C42: 0004-0001 | D42: 13838 | E42: 2816831 | F42: 3007035963 | G42: INCIDENTE | H42: BOLIVAR | I42: TURBANA | J42: BARRIO LOS NISPEROS TURBANA | K42: REDEBAN | L42: FO-25-1606014 | M42: 45930.62 | N42: 45932.609 | O42: NO | P42: HARDWARE | Q42: HUB | R42: SE REINICIA | S42: CB UNO A UNO | T42: CB UNO A UNO | U42: EJECUTADO | V42: 30/09/2025 SE ESCALA PARA VISITA. LLAMAR ANTES DE VISITAR, CONFIRMAR FALLA Y DATOS | 02/10/2025 EN SITIO ESPERANDO AUTORIZACIÓN DE INGRESO INFORMAN QUE LA PERSONA ENCARGADA NO SE ENCUENTRA PERO QUE LO VAN A LLAMAR PARA VALIDAR LA NOVEDAD | 02/10/2025 SE CAMBIA HUB POR REINICIOS Y SE CAMBIA FUENTE DE PODER POR CABLE DEGOLLADO SE PRUEBA Y TODO QUEDA OK | W42: VISITA TECNICA | X42: GZ006904 | Y42: TIPO II | Z42: TERRESTRE | AA42: MARTINEZ SALGUEDO ANDRES AUGUSTO | AB42: 1 | AC42: 0 | AD42: 144968 | AE42: 144968
A43: APARTADO | B43: NOROCCIDENTE | C43: 0004-0005 | D43: 5045 | E43: 2817082 | F43: 3007081497 | G43: INCIDENTE | H43: ANTIOQUIA | I43: APARTADO | J43: DISTRICOL FERROUNO | K43: REDEBAN | L43: FO-25-1606216 | M43: 45930.633 | N43: 45931.617 | O43: NO | P43: SOFTWARE | Q43: ERROR DE TRANSACCIONES | R43: RECHAZO GENERAL | S43: AGREGADOR | T43: DISTRICOL | U43: EJECUTADO | V43: 30/09/2025 SE ESCALA ACTIVIDAD PARA GESTION WOMPI | 01/10/2025 DATAFONO PIERDE COMUNICACIÓN SE VERIFICA PARÁMETROS Y CONFIGURACIÓN DESAPARECIÓ, SE PREINSTALA Y SE REINICIALIZA. DATAFONO QUEDA OPERATIVO | W43: VISITA TECNICA | X43: FSZZZ896 | Y43: TIPO I | Z43: TERRESTRE | AA43: CASTRO HENAO DANIEL ESTEBAN | AB43: 1 | AC43: 0 | AD43: 65960 | AE43: 65960
A44: VALLEDUPAR | B44: COSTA | C44: 0004-0001 | D44: 44378 | E44: 2817274 | F44: 3007034454 | G44: INCIDENTE | H44: LA GUAJIRA | I44: HATONUEVO | J44: BARRIO CENTRO HATONUEVO 1 | K44: REDEBAN | L44: FO-25-1606537 | M44: 45930.652 | N44: 45932.572 | O44: NO | P44: HARDWARE | Q44: LECTOR DE BARRAS | R44: CABLE LECTORA AVERIADO | S44: CB UNO A UNO | T44: CB UNO A UNO | U44: EJECUTADO | V44: 30/09/2025 SE ESCALA PARA VISITA. LLAMAR ANTES DE VISITAR, CONFIRMAR FALLA Y DATOS, SE REALIZAN 3 INTENTOS DE LLAMADA AL NUMERO DE CONTACTO 3157435907 PERO NO FUE POSIBLE LA COMUNICACION | 02/10/2025 SE REALIZA CAMBIO DE LECTOR, YA QUE EL LECTOR DEL CLIENTE TENIA EL CABLE AVERIADO, SE REALIZAN PRUEBAS DEJANDO SERVICIO FUNCIONAL AL 100 % | W44: VISITA TECNICA | X44: NN001067 - A1KZZ149 | Y44: TIPO III | Z44: TERRESTRE | AA44: MONTES DIAZ JOHN FRED | AB44: 1 | AC44: 0 | AD44: 275729 | AE44: 275729
A45: MONTERIA | B45: COSTA | C45: 0004-0001 | D45: 23807 | E45: 2817279 | F45: 3007080411 | G45: INCIDENTE | H45: CORDOBA | I45: TIERRALTA | J45: BARRIO EL PRADO TIERRALTA 3 | K45: REDEBAN | L45: FO-25-1606531 | M45: 45930.654 | N45: 45931.643 | O45: NO | P45: HARDWARE | Q45: IMPRESION | R45: DAÑO POS | S45: UNO A UNO | T45: UNO A UNO | U45: EJECUTADO | V45: 30/09/2025 SE ESCALA PARA VISITA. LLAMAR ANTES DE VISITAR, CONFIRMAR FALLA Y DATOS, SE REALIZAN 3 INTENTOS DE LLAMADA AL NUMERO DE CONTACTO 3222779180 PERO NO FUE POSIBLE LA COMUNICACION | 01/10/2025 SE VISITA SITIO, SE CAMBIA DATAFONO POR DAÑO EN IMPRESORA, NO AVANZA PAPEL, SE REALIZAN PRUEBAS EXITOSAS OK | W45: VISITA TECNICA | X45: LBZZZ669 | Y45: TIPO III | Z45: TERRESTRE | AA45: COGOLLO VERTEL EDER LUIS | AB45: 1 | AC45: 0 | AD45: 275729 | AE45: 275729
A46: BUCARAMANGA | B46: SANTANDERES | C46: 0004-0008 | D46: 68655 | E46: 2817585 | F46: 3007064502 | G46: INCIDENTE | H46: SANTANDER | I46: SABANA DE TORRES | J46: PMT SABANA DE TORRES FERRETAL | K46: REDEBAN | L46: FO-25-1606772 | M46: 45930.672 | N46: 45931.495 | O46: NO | P46: HARDWARE | Q46: LECTOR DE BARRAS | R46: CABLE LECTORA AVERIADO | S46: AGREGADOR | T46: COMCARD - PTM | U46: EJECUTADO | V46: 30/09/2025 SE ESCALA PARA VISITA. LLAMAR ANTES DE VISITAR, CONFIRMAR FALLA Y DATOS, SE REALIZA 3 INTENTOS DE LLAMADAS AL CONTACTO 3164418359 PERO NOFUE POSIBLE LA COMUNICACION | 01/10/2025 SE REALIZA CAMBIO DE LECTOR DE BARRAS POR CABLE AVERIADO. PRUEBAS Y LIMPIEZA DE EQUIPOS OK | W46: VISITA TECNICA | X46: 1A003458 | Y46: TIPO III | Z46: TERRESTRE | AA46: MARTINEZ FLOREZ DONIS ALBERTO | AB46: 1 | AC46: 0 | AD46: 275729 | AE46: 275729
A47: BOGOTA | B47: CUNDINAMARCA | C47: 0004-0004 | D47: 25290 | E47: 2817738 | F47: 3007063003 | G47: INCIDENTE | H47: CUNDINAMARCA | I47: FUSAGASUGA | J47: BARRIO SAN FERNANDO FUSAGASUGA | K47: REDEBAN | L47: FO-25-1606765 | M47: 45930.673 | N47: 45931.608 | O47: NO | P47: HARDWARE | Q47: SE REINICIA | R47: DAÑO POS | S47: CB UNO A UNO | T47: CB UNO A UNO | U47: EJECUTADO | V47: 30/09/2025 SE ESCALA PARA VISITA. LLAMAR ANTES DE VISITAR, CONFIRMAR FALLA Y DATOS | 01/10/2025 CAMBIO DE MAGIC BOX SE REALIZA ACTUALIZACIÓN SE ENTREGA SERVICIO OPERATIVO | W47: VISITA TECNICA | X47: SXOZZ718 | Y47: TIPO II | Z47: TERRESTRE | AA47: HERNANDEZ NARANJO OSCAR EDUARDO | AB47: 1 | AC47: 0 | AD47: 144968 | AE47: 144968
A48: BOGOTA | B48: CUNDINAMARCA | C48: 0004-0004 | D48: 25286 | E48: 2817773 | F48: 3007081076 | G48: INCIDENTE | H48: CUNDINAMARCA | I48: FUNZA | J48: BARRIO PADRE FUNZA FUNZA | K48: REDEBAN | L48: FO-25-1606753 | M48: 45930.678 | N48: 45932.574 | O48: NO | P48: HARDWARE | Q48: IMPRESION | R48: NO AVANZA PAPEL | S48: UNO A UNO | T48: UNO A UNO | U48: EJECUTADO | V48: 30/09/2025 SE ESCALA PARA VISITA. LLAMAR ANTES DE VISITAR, CONFIRMAR FALLA Y DATOS | 02/10/2025 SE REALIZA LLEGA A COMERCIO EN EL CUAL INFORMAN QUE EN EL MOMENTO NO TIENEN SERVICIO DE INTERNET PERO QUE EL DATAFONO YA SE ENCUENTRA FUNCIONANDO EN PERFECTAS CONDICIONES SE REALIZAR IMPRESIONES DE VERSIÓN. OK | W48: VISITA TECNICA | X48: SHZZZ002 | Y48: TIPO II | Z48: TERRESTRE | AA48: ORTIZ MARTINEZ STIVEN | AB48: 1 | AC48: 0 | AD48: 144968 | AE48: 144968
A49: BOGOTA | B49: CUNDINAMARCA | C49: 0004-0004 | D49: 11001 | E49: 2817810 | F49: 3007055704 | G49: INCIDENTE | H49: CUNDINAMARCA | I49: BOGOTA | J49: PTM BOGOTA TIENDA Y MISCELANEA | K49: REDEBAN | L49: FO-25-1606756 | M49: 45930.676 | N49: 45931.592 | O49: NO | P49: HARDWARE | Q49: DETERIORO | R49: DATAFONO | S49: AGREGADOR | T49: COMCARD - PTM | U49: EJECUTADO | V49: 30/09/2025 SE ESCALA PARA VISITA. LLAMAR ANTES DE VISITAR, CONFIRMAR FALLA Y DATOS | 01/10/2025 SE LLEGA A LA DIRECCIÓN INDICADA Y SE REALIZA CAMBIO DE DATAFONO POR DETERIORO Y FALLO EN IMPRESORA, VERSIONAMIENTO Y CONFIGURACIÓN OK, USUARIO OK , CUPO OK, SE REALIZAN PRUEBAS EXITOSAS | W49: VISITA TECNICA | X49: IIGZZ984 - TRDZZ663 | Y49: TIPO I | Z49: TERRESTRE | AA49: GARCIA PASTRANA KEVIN FERNANDO | AB49: 1 | AC49: 0 | AD49: 65960 | AE49: 65960
A50: CALI | B50: SUROCCIDENTE Y EJE CAFETERO | C50: 0004-0003 | D50: 76001 | E50: 2817919 | F50: 3007076951 | G50: INCIDENTE | H50: VALLE DEL CAUCA | I50: CALI | J50: BARRIO CENTRAL CALI | K50: REDEBAN | L50: FO-25-1610814 | FO-25-1606780 | M50: 45930.682 | N50: 45933.439 | O50: NO | P50: HARDWARE | Q50: COMUNICACION | R50: MENSAJE CABLE DE RED DESCONECTADO | S50: CB UNO A UNO | T50: CB UNO A UNO | U50: EJECUTADO | EJECUTADO / CANCELADO | V50: 03/10/2025 SE REALIZA CAMBIO DE EQUIPO E6 PUERTO IP MALO, CB BANCOLOMBIA PURO, PRUEBAS OK | W50: VISITA TECNICA | X50: A18ZZ388 | Y50: TIPO I | Z50: TERRESTRE | AA50: PAREDES CASTILLO DIEGO | AB50: 2 | AC50: 0 | AD50: 131920 | AE50: 131920
A51: IBAGUE | B51: REMOTAS | C51: 0004-0007 | D51: 73001 | E51: 2818398 | F51: 3007065322 | G51: INCIDENTE | H51: TOLIMA | I51: IBAGUE | J51: BARRIO GALAN IBAGUE 1 | K51: REDEBAN | L51: FO-25-1607152 | M51: 45930.733 | N51: 45931.449 | O51: NO | P51: HARDWARE | Q51: ALERT IRRUPTION | R51: ALERT IRRUPTION | S51: CB UNO A UNO | T51: CB UNO A UNO | U51: EJECUTADO | V51: 30/09/2025 SE ESCALA PARA VISITA. LLAMAR ANTES DE VISITAR, CONFIRMAR FALLA Y DATOS | 01/10/2025 SE REALIZA CAMBIO DE EQUIPO POR DAÑO, SE REALIZA PRUEBAS DE FUNCIONAMIENTO OK; CUBRE CLAVE INSTALADO. | W51: VISITA TECNICA | X51: 4A005663 | Y51: TIPO I | Z51: TERRESTRE | AA51: BARRAGAN TAFUR EDWIN ESTEBAN | AB51: 1 | AC51: 0 | AD51: 65960 | AE51: 65960
... A54: CALI | B54: SUROCCIDENTE Y EJE CAFETERO | C54: 0004-0003 | D54: 19075 | E54: 2818692 | F54: 3007062988 | G54: INCIDENTE | H54: CAUCA | I54: BALBOA | J54: BARRIO LA LOMITA BALBOA | K54: REDEBAN | L54: FO-25-1608429 | M54: 45931.333 | N54: 45933.65 | O54: NO | P54: HARDWARE | Q54: ALERT IRRUPTION | R54: ALERT IRRUPTION | S54: CB UNO A UNO | T54: CB UNO A UNO | U54: EJECUTADO | V54: 01/10/2025 SE REALIZA 3 INTENTOS DE LLAMADA AL NUMERO DE CONTACTO 3103215073 PERO NO FUE POSIBLE LA COMUNICACION | 03/10/2025 SE INGRESA EQUIPO CON ALERTINTERRUPTION SE PROCEDE A CAMBIAR EQUIPO SE HACEN PRUEBAS OK TELECARGA DRNA | W54: VISITA TECNICA | X54: CZZZZ704 | Y54: TIPO IV | Z54: TERRESTRE | AA54: GIMBUEL LASSO LUIS GERMAN | AB54: 1 | AC54: 0 | AD54: 479589 | AE54: 479589
A55: MONTERIA | B55: COSTA | C55: 0004-0001 | D55: 23162 | E55: 2818693 | F55: 3007058775 | G55: INCIDENTE | H55: CORDOBA | I55: CERETE | J55: ARA0873 CERETE VENUS | K55: REDEBAN | L55: FO-25-1608794 | M55: 45931.333 | N55: 45931.992 | P55: HARDWARE | Q55: SE REINICIA | R55: DAÑO POS | S55: RETAIL | T55: TIENDAS ARA | V55: 01/10/2025 SE ESCALA CASO ARA A LA RED** TU SOLICITUD REFERENTE A GENERACIÓN DE CASOS CB ARA BANCOLOMBIA QUEDÓ RADICADA BAJO EL TICKET NÚMERO 5821571 AL ÁREA ENCARGADA. | 01/10/2025 SE ESCALA CASO ARA A LA RED** TU SOLICITUD REFERENTE A GENERACIÓN DE CASOS CB ARA BANCOLOMBIA QUEDÓ RADICADA BAJO EL TICKET NÚMERO 5821571 AL ÁREA ENCARGADA. | 01/10/2025 SE ESCALA CASO ARA A LA RED** TU SOLICITUD REFERENTE A GENERACIÓN DE CASOS CB ARA BANCOLOMBIA QUEDÓ RADICADA BAJO EL TICKET NÚMERO 5821571 AL ÁREA ENCARGADA. | 01/10/2025 SE ESCALA CASO ARA A LA RED** TU SOLICITUD REFERENTE A GENERACIÓN DE CASOS CB ARA BANCOLOMBIA QUEDÓ RADICADA BAJO EL TICKET NÚMERO 5821571 AL ÁREA ENCARGADA. | W55: SOPORTE TELEFONICO | Y55: TIPO I | Z55: TERRESTRE | AA55: DIAZ ACOSTA MARIA ISABEL | AB55: 0 | AC55: 0 | AD55: 41241 | AE55: 41241
A56: CALI | B56: SUROCCIDENTE Y EJE CAFETERO | C56: 0004-0003 | D56: 19022 | E56: 2818857 | F56: 3007037307 | G56: INCIDENTE | H56: CAUCA | I56: ALMAGUER | J56: BARRIO SAN FRANCISCO ALMAGUER | K56: REDEBAN | L56: FO-25-1608408 | M56: 45931.333 | N56: 45932.576 | P56: HARDWARE | Q56: COMUNICACION | R56: MENSAJE CABLE DE RED DESCONECTADO | S56: UNO A UNO | T56: CB UNO A UNO | V56: 01/10/2025 SE ESCALA PARA VISITA. LLAMAR ANTES DE VISITAR, CONFIRMAR FALLA Y DATOS, SE REALIZA 3 INTENTOS DE LLAMADA AL NUMERO DE CONTACTO 3147008853 PERO NO FUE POSIBLE LA COMUNICACION | 02/10/2025 SE REALIZA LLAMADA CELULAR CON LA SEÑORA ALBA INFORMA YA TIENE CONEXION A INTERNET OK EL DATOFONO | W56: SOPORTE TELEFONICO | Y56: TIPO IV | Z56: TERRESTRE | AA56: GIMBUEL LASSO LUIS GERMAN | AB56: 0 | AC56: 0 | AD56: 41241 | AE56: 41241
A57: CALI | B57: SUROCCIDENTE Y EJE CAFETERO | C57: 0004-0003 | D57: 19001 | E57: 2819731 | F57: 3007030339 | G57: INCIDENTE | H57: CAUCA | I57: POPAYAN | J57: BARRIO SAN EDUARDO POPAYAN | K57: REDEBAN | L57: FO-25-1608474 | M57: 45931.35 | N57: 45932.744 | O57: NO | P57: HARDWARE | Q57: PINPAD | R57: DAÑO POS | S57: CB UNO A UNO | T57: CB UNO A UNO | U57: EJECUTADO | V57: 01/10/2025 SE REALIZA 3 INTENTOS DE LLAMADA AL NUMERO DE CONTACTO 3105396586 PERO NO FUE POSIBLE LA COMUNICACION 3105396586 | 02/10/2025 SE INGRESA EQUIPO PIN PAD CON LECTOR CHIP TARJETAS NO LEE TARJETAS SE PROCEDE HACER LIMPIEZA A LECTOR CHIP SE HACEN PRUEBAS OK TELECARGA DRNA | W57: VISITA TECNICA | X57: AB000272 | Y57: TIPO III | Z57: TERRESTRE | AA57: GIMBUEL LASSO LUIS GERMAN | AB57: 1 | AC57: 0 | AD57: 275729 | AE57: 275729
A58: IBAGUE | B58: REMOTAS | C58: 0004-0007 | D58: 73168 | E58: 2820041 | F58: 3007032030 | G58: INCIDENTE | H58: TOLIMA | I58: CHAPARRAL | J58: BARRIO PRIMERO DE MAYO CHAPARR | K58: REDEBAN | L58: FO-25-1609233 | M58: 45931.365 | N58: 45932.603 | O58: NO | P58: SOFTWARE | Q58: COMUNICACION | R58: VERIFIQUE PARAMETROS | S58: CB UNO A UNO | T58: CB UNO A UNO | U58: EJECUTADO | V58: 01/10/2025 SE ESCALA PARA VISITA. LLAMAR ANTES DE VISITAR, CONFIRMAR FALLA Y DATOS,SE MARACA EN REPETIDAS OCACIONES AL NUMERO DEL CONTACTO 3134243169 PERO NO FUE POSIBLE LA COMUNICACION | 02/10/2025 SE CAMBIA DATÁFONO POR FALLA DE COMUNICACIÓN CONSTANTE. SE HACEN PRUEBAS DE TRANSACCIONES TODO OK | W58: VISITA TECNICA | X58: A16ZZ720 | Y58: TIPO III | Z58: TERRESTRE | AA58: VARGAS HERRERA JHON JAIRO | AB58: 1 | AC58: 0 | AD58: 275729 | AE58: 275729
...

Sheet OC_BANCOLOMBIA
A1: CIUDAD SEDE | B1: ZONA | C1: CENTRO DE COSTOS LINEACOM | D1: CODIGO DANE | E1: TA/CODIGO ACTIVIDAD | F1: CODIGO CB | G1: ACTIVIDAD | H1: DEPARTAMENTO | I1: CIUDAD | J1: NOMBRE DEL CB | K1: RED | L1: FO | M1: FECHA ASIGNACION A LINEA COMUNICACIONES | N1: FECHA CIERRE DEL TICKET (DD/MM/AAAA HH:MM) | O1: ACOMETIDA | P1: SOLICITUD | Q1: DESCRIPCION | R1: FORMATO | S1: CADENA | T1: ESTADO | U1: CAUSAL ESTADO | V1: OBSERVACION | W1: FORMA DE ATENCION | X1: TERMINAL(ES) | Y1: TIPIFICACION | Z1: TIPO DE TRAYECTO | AA1: NOMBRE DEL TECNICO | AB1: DIAS DE VISITA | AC1: DIA ADICIONAL | AD1: VALOR DIAS ACTIVIDAD FACTURABLES | AE1: VALOR TOTAL
A2: CARTAGENA | B2: COSTA | C2: 0004-0001 | D2: 13673 | E2: 14105000 | F2: 3007078615 | G2: OC TRASLADO | H2: BOLIVAR | I2: SANTA CATALINA | J2: BARRIO EL MERCADO SANTA CATALI | K2: REDEBAN | L2: FO-25-1615743 | M2: 45931.333 | N2: 45933.536 | O2: NO | P2: TRASLADO | Q2: TRASLADO EXTERNO | R2: CB UNO A UNO | S2: CB UNO A UNO | T2: EJECUTADO | U2: EJECUTADO EXITOSO | V2: 02/10/2025 SE INTENTA COMUNICACIÓN A LOS NÚMEROS 3006988881 - 3160679119 Y SE ENCUENTRAN APAGADOS Y NO HAY RESPUESTA POR WHATSAPP. POR FAVOR, COMUNICARSE CON USUARIO PARA CONFIRMAR UBICACION, SOLICITUD Y PROGRAMAR VISITA TECNICA | 03/10/2025 SE REALIZA TRASLADO EXITOSO | W2: VISITA TECNICA | X2: F1MZZ644 | Y2: TIPO II | Z2: TERRESTRE | AA2: MARTINEZ SALGUEDO ANDRES AUGUSTO | AB2: 1 | AC2: 0 | AD2: 144968 | AE2: 144968
A3: MONTERIA | B3: COSTA | C3: 0004-0001 | D3: 23001 | E3: 14122320 | F3: 3007040354 | G3: OC TRASLADO | H3: CORDOBA | I3: MONTERIA | J3: BARRIO KM 12 MONTERIA | K3: REDEBAN | L3: FO-25-1615739 | M3: 45931.333 | N3: 45933.442 | O3: NO | P3: TRASLADO | Q3: TRASLADO EXTERNO | R3: UNO A UNO | S3: CB UNO A UNO | T3: EJECUTADO | U3: EJECUTADO EXITOSO | V3: 02/10/2025 EN COMUNICACIÓN CON LA SEÑORA DANNA PAOLA CASARRUBIA ORTEGA AL NÚMERO 3147811755 CONFIRMA SOLICITUD, DATOS CORRECTOS. SE ESCALA PARA VISITA | 03/10/2025 SE REALIZA TRASLADO DE CB DE DIRECCIÓN KM 12 VÍA PLANERA RICA A CLL 1 CRA 2 VDA JARAQUIEL OK SE INICIALIZA TERMINAL Y SE CONFIRMA CAMBIO DE DIRECCIÓN. CB BLOQUEADO POR ENTIDAD, NO SE REALIZAN PRUEBAS | W3: VISITA TECNICA | X3: 9A0KZ257 | Y3: TIPO I | Z3: TERRESTRE | AA3: COGOLLO VERTEL EDER LUIS | AB3: 1 | AC3: 0 | AD3: 65960 | AE3: 65960
A4: MONTERIA | B4: COSTA | C4: 0004-0001 | D4: 23001 | E4: 14123100 | F4: 3007057438 | G4: OC TRASLADO | H4: CORDOBA | I4: MONTERIA | J4: BARRIO CENTRO MONTERIA 38 | K4: REDEBAN | L4: FO-25-1615735 | M4: 45931.333 | N4: 45933.694 | O4: NO | P4: TRASLADO | Q4: TRASLADO EXTERNO | R4: CB UNO A UNO | S4: CB UNO A UNO | T4: EJECUTADO | U4: EJECUTADO EXITOSO | V4: 02/10/2025 EN COMUNICACIÓN CON LA SEÑORA ELIZABETH CARTAGENA MONTOYA AL NÚMERO 3156727761 CONFIRMA SOLICITUD, DATOS CORRECTOS. SE ESCALA PARA VISITA | 03/10/2025 SE VISITA SITIO, SE REALIZA TRASLADO DE CB A DIRECCIÓN CLL 1 B # 28 SE INICIALIZA TERMINAL Y SE VERIFICA CAMBIO DE DIRECCIÓN OK CB BLOQUEADO POR ENTIDAD, NO SE REALIZAN PRUEBAS. EQUIPOS EN SITIO. | W4: VISITA TECNICA | X4: 9CUZZ957 | Y4: TIPO I | Z4: TERRESTRE | AA4: COGOLLO VERTEL EDER LUIS | AB4: 1 | AC4: 0 | AD4: 65960 | AE4: 65960
A5: CALI | B5: SUROCCIDENTE Y EJE CAFETERO | C5: 0004-0003 | D5: 76001 | E5: 14125738 | F5: 3007064801 | G5: OC TRASLADO | H5: VALLE DEL CAUCA | I5: CALI | J5: BARRIO CRISTOBAL COLON CALI 3 | K5: REDEBAN | L5: FO-25-1636246 | M5: 45933.333 | N5: 45937.51 | O5: NO | P5: TRASLADO | Q5: TRASLADO EXTERNO | R5: CB UNO A UNO | S5: CB UNO A UNO | T5: EJECUTADO | U5: EJECUTADO EXITOSO | V5: 06/10/2025 EN COMUNICACIÓN CON EL SEÑOR CARLOS PAREDES AL NUMERO 3103793424 CONFIRMA SOLICITUD DE TRASLADO EXTERNO, INFORMA QUE LOS EQUIPOS SE ENCUENTRAN EN LA NUEVA DIRECCION, CONFIRMA DATOS, SE ESCALA PARA VISITA | 06/10/2025 EN COMUNICACIÓN CON EL SEÑOR CARLOS PAREDES AL NUMERO 3103793424 CONFIRMA SOLICITUD DE TRASLADO EXTERNO, INFORMA QUE LOS EQUIPOS SE ENCUENTRAN EN LA NUEVA DIRECCION, CONFIRMA DATOS, SE ESCALA PARA VISITA | 06/10/2025 EN COMUNICACIÓN CON EL SEÑOR CARLOS PAREDES AL NUMERO 3103793424 CONFIRMA SOLICITUD DE TRASLADO EXTERNO, INFORMA QUE LOS EQUIPOS SE ENCUENTRAN EN LA NUEVA DIRECCION, CONFIRMA DATOS, SE ESCALA PARA VISITA | 07/10/2025 SE REALIZA VISITA TÉCNICA EN LA NUEVA DIRECCIÓN, DONDE SE ENCUENTRA EL COMERCIO CARRERA 16 32B-23 SE PROCEDE A INICIALIZAR EL EQUIPO Y SE REALIZAN PRUEBAS OK | W5: VISITA TECNICA | X5: 3A003178 | Y5: TIPO I | Z5: TERRESTRE | AA5: ESCOBAR LENIS JUAN SEBASTIAN | AB5: 1 | AC5: 0 | AD5: 65960 | AE5: 65960
