Workbook
Name A: #REF!
Name Actividad: #REF!
Name Analistas: #REF!
Name arearesponsable: #REF!
Name CCO: #REF!
Name Clientes: #REF!
Name COORDINADOR: #REF!
Name Coordinadores: #REF!
Name DOCUMENTADOR: #REF!
Name ES: #REF!
Name ESS: #REF!
Name Estado: #REF!
Name ESTADOACTIVIDAD: #REF!
Name ESTADOS: #REF!
Name ESTADOSCIERRES: #REF!
Name Facturacion: #REF!
Name FACTURACIÓN: #REF!
Name falla: #REF!
Name Fallas: #REF!
Name Grupo_Falla: #REF!
Name inconservmanager: #REF!
Name INCUMPLIMIENTO: #REF!
Name LISTA: #REF!
Name LISTA2: #REF!
Name LOLO: #REF!
Name solicitudes: #REF!
Name Tecnicos: #REF!
Name Version: #REF!

Sheet Hoja1
A2: aperturas bancol
A3: Etiquetas de fila | B3: Suma de VALOR TOTAL
A4: COSTA | B4: 2291476 | C4: cc | D4: valor
A5: 0004-0001 | B5: 2291476 | C5: =A5 -> 0004-0001 | D5: =B5 -> 2291476 | H5: Etiquetas de fila | I5: Suma de valor
A6: NOROCCIDENTE | B6: 5027174 | G6: costa | H6: 0004-0001 | I6: 54060187
A7: 0004-0005 | B7: 5027174 | C7: =A7 -> 0004-0005 | D7: =B7 -> 5027174 | G7: eje | H7: 0004-0002 | I7: 9675354
A8: SANTANDERES | B8: 2466323 | G8: sur | H8: 0004-0003 | I8: 46546603
A9: 0004-0008 | B9: 2466323 | C9: =A9 -> 0004-0008 | D9: =B9 -> 2466323 | G9: centro | H9: 0004-0004 | I9: 37256173
A10: SUROCCIDENTE Y EJE CAFETERO | B10: 655025 | G10: noroccidente | H10: 0004-0005 | I10: 81773717
A11: 0004-0002 | B11: 75096 | C11: =A11 -> 0004-0002 | D11: =B11 -> 75096 | G11: oriente | H11: 0004-0007 | I11: 41222756
A12: 0004-0003 | B12: 579929 | C12: =A12 -> 0004-0003 | D12: =B12 -> 579929 | G12: santanderes | H12: 0004-0008 | I12: 58086348
A13: CENTRO | B13: 903741 | H13: Total general | I13: 328621138
A14: 0004-0004 | B14: 903741 | C14: =A14 -> 0004-0004 | D14: =B14 -> 903741
A15: ORIENTE | B15: 1343284
A16: 0004-0007 | B16: 1343284 | C16: =A16 -> 0004-0007 | D16: =B16 -> 1343284
A17: SUROCCIDENTE | B17: 2826954
A18: 0004-0003 | B18: 2826954 | C18: =A18 -> 0004-0003 | D18: =B18 -> 2826954
A19: EJE CAFETERO | B19: 477820
A20: 0004-0002 | B20: 477820 | C20: =A20 -> 0004-0002 | D20: =B20 -> 477820
A21: Total general | B21: 15991797
A24: incidentes bancol
A25: Etiquetas de fila | B25: Suma de VALOR TOTAL
A26: COSTA | B26: 27964716
A27: 0004-0001 | B27: 27964716 | C27: =A27 -> 0004-0001 | D27: =B27 -> 27964716
A28: CUNDINAMARCA | B28: 9650846
A29: 0004-0004 | B29: 9650846 | C29: =A29 -> 0004-0004 | D29: =B29 -> 9650846
A30: NOROCCIDENTE | B30: 38628762
A31: 0004-0005 | B31: 38628762 | C31: =A31 -> 0004-0005 | D31: =B31 -> 38628762
A32: REMOTAS | B32: 12478601
A33: 0004-0007 | B33: 12478601 | C33: =A33 -> 0004-0007 | D33: =B33 -> 12478601
A34: SANTANDERES | B34: 17736345
A35: 0004-0008 | B35: 17736345 | C35: =A35 -> 0004-0008 | D35: =B35 -> 17736345
A36: SUROCCIDENTE Y EJE CAFETERO | B36: 23915193
A37: 0004-0002 | B37: 4069894 | C37: =A37 -> 0004-0002 | D37: =B37 -> 4069894
A38: 0004-0003 | B38: 19845299 | C38: =A38 -> 0004-0003 | D38: =B38 -> 19845299
A39: SUROCCIDENTE | B39: 144968
A40: 0004-0003 | B40: 144968 | C40: =A40 -> 0004-0003 | D40: =B40 -> 144968
A41: Total general | B41: 130519431
A44: oc bancol
A45: Etiquetas de fila | B45: Suma de VALOR TOTAL
...

Sheet BASE LIQUIDACION REDEBAN 2025
A1: Tipificación | B1: Implementaciones | C1: Incidentes – Ordenes de Cambio | D1: Fallida | G1: Tipificación | H1: Actividad sin cambio de datafono | J1: Actividad + adicional cambio de datafono | L1: Visita Fallida | N1: Incremento 2025
A2: TIPO I | B2: =71384.4052*(1+$N$2) -> 75096.394 | C2: =62699.6885*(1+$N$2) -> 65960.072 | D2: =35693.4343*(1+$N$2) -> 37549.493 | H2: Instalación Pinpad + HUB | I2: Segunda actividad en mismo comercio, misma visita | J2: Instalación Pinpad + HUB | K2: Segunda actividad en mismo comercio, misma visita | N2: 0.052
A3: TIPO II | B3: =155716.4408*(1+$N$2) -> 163813.7 | C3: =137802.16*(1+$N$2) -> 144967.87 | D3: =117879.8485*(1+$N$2) -> 124009.6 | G3: Tipo I | H3: =31819.23994686*(1+$N$2) -> 33473.84 | I3: =26222.67548178*(1+$N$2) -> 27586.255 | J3: =51196.46628516*(1+$N$2) -> 53858.683 | K3: =42157.66342524*(1+$N$2) -> 44349.862 | L3: =28948.10610808*(1+$N$2) -> 30453.408
A4: TIPO III | B4: =262099.6015*(1+$N$2) -> 275728.78 | C4: =262099.6015*(1+$N$2) -> 275728.78 | D4: =262099.6015*(1+$N$2) -> 275728.78 | G4: Tipo II | H4: =98014.03066668*(1+$N$2) -> 103110.76 | I4: =26222.67548178*(1+$N$2) -> 27586.255 | J4: =119562.49505524*(1+$N$2) -> 125779.74 | K4: =42157.66342524*(1+$N$2) -> 44349.862 | L4: =94765.6295813*(1+$N$2) -> 99693.442
A5: TIPO IV | B5: =479878.9419*(1+$N$2) -> 504832.65 | C5: =455882.9625*(1+$N$2) -> 479588.88 | D5: =370911.6746*(1+$N$2) -> 390199.08 | G5: Tipo III | H5: =189140.9827006*(1+$N$2) -> 198976.31 | I5: =26222.67548178*(1+$N$2) -> 27586.255 | J5: =200461.60194168*(1+$N$2) -> 210885.61 | K5: =42157.66342524*(1+$N$2) -> 44349.862 | L5: =171492.68108896*(1+$N$2) -> 180410.3
A6: Destino Aéreo | B6: =939603.5767*(1+$N$2) -> 988462.96 | C6: a partir del 5to servicio | G6: Tipo IV | H6: =461621.60109668*(1+$N$2) -> 485625.92 | I6: =26222.67548178*(1+$N$2) -> 27586.255 | J6: =461621.60109668*(1+$N$2) -> 485625.92 | K6: =42157.66342524*(1+$N$2) -> 44349.862 | L6: =461621.60109668*(1+$N$2) -> 485625.92
G7: * Tipo IV Especial Donde se requiera desplazamiento aéreo o fluvial será facturado el valor de la actividad y adicional el valor de $988.463 por cada 5 actividades de esta tipología
A8: Tarifas para día adicional de actividades:
A9: Tipificación | B9: Día adicional- menos de dos horas | C9: Medio día adicional | D9: Día adicional- más de 4 horas
A10: Tipo I | B10: =71384.4052*(1+$N$2) -> 75096.394 | C10: =133455.9267*(1+$N$2) -> 140395.63 | D10: =191225.1201*(1+$N$2) -> 201168.83 | G10: Actividad | H10: Unidad | I10: Valor Unitario
A11: Tipo II | B11: =133455.9267*(1+$N$2) -> 140395.63 | C11: =191225.1201*(1+$N$2) -> 201168.83 | D11: =257740.6152*(1+$N$2) -> 271143.13 | G11: Gestión telefónica y cierre de incidente de bloqueo | H11: Unidad | I11: =17639.19516086*(1+$N$2) -> 18556.433
A12: Tipo III | B12: =186821.7926*(1+$N$2) -> 196536.53 | C12: =248892.0824*(1+$N$2) -> 261834.47 | D12: =306662.5075*(1+$N$2) -> 322608.96 | G12: Servicio de cierre de incidente de bloqueo | H12: Unidad | I12: =4810.80785492*(1+$N$2) -> 5060.9699
A13: Tipo IV | B13: =186821.7926*(1+$N$2) -> 196536.53 | C13: =248892.0824*(1+$N$2) -> 261834.47 | D13: =306662.5075*(1+$N$2) -> 322608.96
A16: Servicio | B16: Tarifa actividad | D16: VALOR DE LA TERMINAL ADICIONAL | E16: VALOR DE INSTALACIÓN DE BASE EN "Y"
A17: Papelería – Tarifa única | B17: =34010.9321*(1+$N$2) -> 35779.501 | D17: =20537.3658*(1+$N$2) -> 21605.309 | E17: =10737.9606*(1+$N$2) -> 11296.335
A18: Papelería Tipo II - Visita técnica | B18: =64310*(1+$N$2) -> 67654.12
A19: Solución telefónica | B19: =39202.5476*(1+$N$2) -> 41241.08
A22: Traifas 2024
A23: Tipificación | B23: Implementaciones | C23: Incidentes – Ordenes de Cambio | D23: Fallida | G23: Tipificación | H23: Actividad sin cambio de datafono | J23: Actividad + adicional cambio de datafono | L23: Visita Fallida
A24: TIPO I | B24: 71384.405 | C24: 62699.688 | D24: 35693.434 | H24: Instalación Pinpad + HUB | I24: Segunda actividad en mismo comercio, misma visita | J24: Instalación Pinpad + HUB | K24: Segunda actividad en mismo comercio, misma visita
A25: TIPO II | B25: 155716.44 | C25: 137802.16 | D25: 117879.85 | G25: Tipo I | H25: 31819.24 | I25: 26222.675 | J25: 51196.466 | K25: 42157.663 | L25: 28948.106
A26: TIPO III | B26: 262099.6 | C26: 262099.6 | D26: 262099.6 | G26: Tipo II | H26: 98014.031 | I26: 26222.675 | J26: 119562.5 | K26: 42157.663 | L26: 94765.63
A27: TIPO IV | B27: 479878.94 | C27: 455882.96 | D27: 370911.67 | G27: Tipo III | H27: 189140.98 | I27: 26222.675 | J27: 200461.6 | K27: 42157.663 | L27: 171492.68
A28: Destino Aéreo | B28: 939603.58 | C28: a partir del 5to servicio | G28: Tipo IV | H28: 461621.6 | I28: 26222.675 | J28: 461621.6 | K28: 42157.663 | L28: 461621.6
G29: * Tipo IV Especial Donde se requiera desplazamiento aéreo o fluvial será facturado el valor de la actividad y adicional el valor de $939,604 por cada 5 actividades de esta tipología
A30: Tarifas para día adicional de actividades:
A31: Tipificación | B31: Día adicional- menos de dos horas | C31: Medio día adicional | D31: Día adicional- más de 4 horas
A32: Tipo I | B32: 71384.405 | C32: 133455.93 | D32: 191225.12 | G32: Actividad | H32: Unidad | I32: Valor Unitario
A33: Tipo II | B33: 133455.93 | C33: 191225.12 | D33: 257740.62 | G33: Gestión telefónica y cierre de incidente de bloqueo | H33: Unidad | I33: 17639.195
A34: Tipo III | B34: 186821.79 | C34: 248892.08 | D34: 306662.51 | G34: Servicio de cierre de incidente de bloqueo | H34: Unidad | I34: 4810.8079
A35: Tipo IV | B35: 186821.79 | C35: 248892.08 | D35: 306662.51
A38: Servicio | B38: Tarifa actividad | D38: VALOR DE LA TERMINAL ADICIONAL | E38: VALOR DE INSTALACIÓN DE BASE EN "Y"
A39: Papelería – Tarifa única | B39: 34010.932 | D39: 20537.366 | E39: 10737.961
A40: Papelería Tipo II - Visita técnica | B40: 64310
A41: Solución telefónica | B41: 39202.548

Sheet RESUMEN LIQUIDACION
B1: Fecha | C1: 46022
A3: FACTURACIÓN ACTIVIDADES REDEBAN CB BANCOLOMBIA Y AVAL
A4: =UPPER("01" & " al " & TEXT(DAY(EOMONTH(C1,0)),"00") & " de " & TEXT(C1,"MMMM") & " de " & YEAR(C1)) -> 01 AL 31 DE DICIEMBRE DE 2025
A6: CONCEPTOS | B6: CANTIDAD | C6: TOTAL
A7: Aperturas Bancolombia | B7: =(COUNTA(APERTURAS_BANCOLOMBIA!A:A)-1) -> 87 | C7: =SUM(APERTURAS_BANCOLOMBIA!$AC$2:$AC$1048576) -> 15991797
A8: Incidentes Bancolombia | B8: =(COUNTA(INCIDENTES_BANCOLOMBIA!A:A)-1) -> 786 | C8: =SUM(INCIDENTES_BANCOLOMBIA!$AF$2:$AF$1048576) -> 130519431
A9: Gestión de Campo Bancolombia | B9: =(COUNTA(OC_BANCOLOMBIA!A:A)-1) -> 258 | C9: =SUM(OC_BANCOLOMBIA!$AF$2:$AF$1048576) -> 47286096
A10: Soporte Papelería Bancolombia | B10: =(COUNTA(PAPELERIA!A:A)-1) -> 1151 | C10: =(SUM(PAPELERIA!$AE$2:$AE$1048576)) -> 51303620
A11: Aperturas Aval | B11: =(COUNTA(APERTURAS_AVAL!A:A)-1) -> 154 | C11: =SUM(APERTURAS_AVAL!$AB$2:$AB$1048576) -> 26836633
A12: Incidentes Aval | B12: =(COUNTA(INCIDENTES_AVAL!A:A)-1) -> 309 | C12: =SUM(INCIDENTES_AVAL!$AD$2:$AD$1048576) -> 37489862
A13: Gestión de Campo Aval | B13: =(COUNTA(OC_AVAL!A:A)-1) -> 117 | C13: =SUM(OC_AVAL!$AF$2:$AF$1048576) -> 17756347
A14: Aperturas BBVA | B14: =(COUNTA(APERTURAS_BBVA!A:A)-1) -> 16 | C14: =SUM(APERTURAS_BBVA!$AC$2:$AC$1048576) -> 1437352
A15: Gestión de Campo BBVA | B15: 0 | C15: =SUM(OC_BBVA!$AC$2:$AC$1048576) -> 0
A16: Incidentes BBVA | B16: 0 | C16: =SUM(INCIDENTES_BBVA!$AB$2:$AB$1048576) -> 0
A17: SUBTOTAL | C17: =SUM(C7:C16) -> 328621138
A18: Iva | C18: =C17*0.19 -> 62438016
A19: TOTAL | C19: =SUM(C17:C18) -> 3.9105915e+08

Sheet APERTURAS_BANCOLOMBIA
A1: CIUDAD SEDE | B1: ZONA | C1: CENTRO DE COSTOS LINEACOM | D1: CODIGO DANE | E1: TA/CODIGO ACTIVIDAD | F1: CODIGO CB | G1: ACTIVIDAD | H1: TIPO DE APERTURA | I1: DEPARTAMENTO | J1: CIUDAD | K1: NOMBRE DEL CB | L1: RED | M1: FO | N1: FECHA LISTA | O1: FECHA ULTIMA ACTUALIZACION | P1: FORMATO | Q1: CADENA | R1: ESTADO | S1: OBSERVACIONES CLIENTE | T1: FORMA DE ATENCION | U1: TERMINAL(ES) | V1: TIPIFICACION | W1: TIPO DE TRAYECTO | X1: NOMBRE DEL TECNICO | Y1: DIAS DE VISITA | Z1: DIA ADICIONAL | AA1: VALOR DIAS ACTIVIDAD FACTURABLES | AB1: VALOR DIAS ACOMPAÑAMIENTO FACTURABLES | AC1: VALOR TOTAL
A2: CUCUTA | B2: SANTANDERES | C2: 0004-0008 | D2: 54810 | E2: TA-25-1330512 | F2: 3007050974 | G2: APERTURA | H2: DATAFONO ADICIONAL - ALIANZA | I2: NORTE DE SANTANDER | J2: TIBU | K2: PTM TIBU VARIEDADES DUQUE ER | L2: REDEBAN | M2: FO-25-1884057 | N2: 45988.333 | O2: 46009.444 | P2: AGREGADOR | Q2: COMCARD - PTM | R2: EJECUTADO | S2: 26/11/2025 26-11 PROGRAMACION REALIZADA POR LA ALIANZA| INSTALACIÓN PROGRAMADA PARA EL 2025-12-04 | 04/12/2025 SE CONTACTA TELEFÓNICAMENTE AL COMERCIO, SE LE INFORMA AL SEÑOR JAVIER DUQUE QUE POR CUESTIONES DE ORDEN PÚBLICO NO ES POSIBLE DESPLAZARSE A LA ZONA PARA REALIZAR LA INSTALACIÓN Y POR LO TANTO SE REQUIERE QUE SE ACERCA A LA BODEGA EN LA CIUDAD DE CÚCUTA. EL SEÑOR JAVIER DUQUE INFORMA QUE EL DÍA DE MAÑANA 05/12 INDICARÁ VÍA WHATSAPP LA FECHA Y LOS DATOS DE LA PERSONA QUE SERÁ LA ENCARGADA DE RECIBIR LA INSTALACIÓN. 3214439731 | 10/12/2025 SE INTENTA CONTACTAR TELEFÓNICAMENTE AL CLIENTE PARA CONFIRMAR DATOS DE LA PERSONA QUE VA A RECIBIR EL EQUIPO EN BODEGA CÚCUTA PERO LA LÍNEA SE ENCUENTRA SIN SEÑAL, SE INTENTA CONTACTAR VÍA WHATSAPP PERO NO LE LLEGAN LOS MENSAJES AL CLIENTE. 3214439731 | 18/12/2025 POR MOTIVO DE ORDEN PÚBLICO, SE REALIZA ENTREGA DE DATAFONO ADICIONAL EN BODEGA CÚCUTA, SE INSTALA ÚLTIMA VERSIÓN, SE CREAN USUARIOS OK SE REALIZAN PRUEBAS Y CIERRES OK | T2: VISITA TECNICA | U2: OB004864 | V2: TIPO V | W2: TERRESTRE | X2: PACHECO BUITRAGO JAVIER ALONSO | Y2: 1 | Z2: 0 | AA2: 504833 | AB2: 196537 | AC2: 504833
A3: PASTO | B3: SUROCCIDENTE Y EJE CAFETERO | C3: 0004-0003 | D3: 86865 | E3: TA-25-1330515 | F3: 3007082070 | G3: APERTURA | H3: CB CRECIMIENTO ALIANZA - OTRAS LISTAS | I3: PUTUMAYO | J3: VALLE DEL GUAMUEZ | K3: DISTRICOL ESTILO REAL | L3: REDEBAN | M3: FO-25-1884068 | N3: 45988.333 | O3: 45993.773 | P3: AGREGADOR | Q3: DISTRICOL | R3: EJECUTADO | S3: 26/11/2025 26-11 PROGRAMACION REALIZADA POR LA ALIANZA| INSTALACIÓN PROGRAMADA PARA EL 2025-11-28 | 30/11/2025 SE REALIZARA DESPLAZAMIENTO EL DIA 1 DE DICIEMBRE YA QUE POR CIERRE DE VIA HACIA PUTUMAYO NO SE HA PODIDO REALIZAR | 22/12/2025 SE LLEGA A SITIO A REALIZAR INSTALACIÓN DE CORRESPONSAL BANCARIO SE CONFIGURA EQUIPO SE INICIALIZA SE REALIZA PRUEBAS DE FUNCIONAMIENTO FALLIDAS EQUIPO EN RECHAZO GENERAL SE REALIZA CAMBIO DE EQUIPO FALLA PERSISTE SE ESCALA A RBM MAIRA ALEJANDRO AUTORIZA CERRAR ORDEN POR POSIBLE BLOQUEO POR PARTE DE LA ENTIDAD SE LE INFORMA A CLIENTE QUE SE ESTÁ ALA ESPERA RESPUESTA PARA QUE PUEDA EMPEZAR A OPERAR INSTALACION DE PUBLICIDAD OK CAPACITACIÓN OK | T3: VISITA TECNICA | U3: OB004867 | V3: TIPO IV | W3: TERRESTRE | X3: BRAVO MADROÑERO OSCAR ESTEBAN | Y3: 1 | Z3: 0 | AA3: 504833 | AB3: 196537 | AC3: 504833
A4: VALLEDUPAR | B4: COSTA | C4: 0004-0001 | D4: 44279 | E4: TA-25-1341465 | F4: 3007028414 | G4: APERTURA | H4: DATAFONO ADICIONAL - ALIANZA | I4: LA GUAJIRA | J4: FONSECA | K4: DISTRICOL SEGUROS M M | L4: REDEBAN | M4: FO-25-1911533 | N4: 45993.333 | O4: 45993.99 | P4: AGREGADOR | Q4: DISTRICOL | R4: EJECUTADO | S4: 01/12/2025 01-12 PROGRAMACION REALIZADA POR LA ALIANZA| INSTALACIÓN PROGRAMADA PARA EL 2025-12-02 | 02/12/2025 SE REALIZA INSTALACIÓN DE DATAFONO ADICIONAL, SE INSTALA DATAFONO, LECTOR, SE ENTREGAN 40 ROLLOS, NO SE INSTALA PUBLICIDAD YA QUE EL CB CUENTA CON ELLA Y NO APLICA POR SER DATAFONO ADICIONAL, SE REALIZAN PRUEBAS DEJANDO SERVICIO FUNCIONAL AL 100 % | T4: VISITA TECNICA | U4: AE007353 | V4: TIPO II | W4: TERRESTRE | X4: MONTES DIAZ JOHN FRED | Y4: 1 | Z4: 0 | AA4: 163814 | AB4: 140396 | AC4: 163814
A5: VALLEDUPAR | B5: COSTA | C5: 0004-0001 | D5: 44378 | E5: TA-25-1341466 | F5: 3007057635 | G5: APERTURA | H5: DATAFONO ADICIONAL - ALIANZA | I5: LA GUAJIRA | J5: HATONUEVO | K5: MULTIPAGAS HATONUEVO | L5: REDEBAN | M5: FO-25-1921921 | FO-25-1911535 | N5: 45993.333 | O5: 45997.455 | P5: ROBUSTO | Q5: MULTIPAGAS | R5: EJECUTADO | EJECUTADO/CANCELADO | S5: [FO-25-1921921] 09/12/2025 SE REALIZA INSTALACIÓN DE DATAFONO ADICIONAL, SE INSTALA DATAFONO, LECTOR, PINPAD Y MAGICBOX 2600, SE ENTREGAN 40 ROLLOS, SE BRINDA CAPACITACIÓN, SE REALIZAN PRUEBAS DE TRANSACCIONES, DEJANDO SERVICIO FUNCIONAL AL 100 % || [FO-25-1911535] 01/12/2025 01-12 SE REALIZA LLAMADA AL CLIENTE, SE HABLA CON LA SRA TATIANA TOLOZA SE VALIDA DIRECCIÓN OK, CANAL OK, DISPONIBILIDAD TOTAL, LLAMAR EL DÍA LA INSTALACIÓN PARA CONFIRMAR VISITA | 03/12/2025 SE LLEGA A SITIO, COMERCIO INDICA QUE PARA PODER INGRESAR SE NECESITA LA AUTORIZACIÓN Y VALIDACION DE BANCOLOMBIA, PROCEDEN A LLAMAR A LA LINEA PERO ESTA NO RESPONDEN, SE INTENTA POR OTROS MEDIOS COMO WPP Y TAMPOCO CONTESTAN, SE LE INDICA AL JEFE DEL MULTIPAGAS QUE VAMOS A REALIZAR UNA INSTALACIÓN DE UN DATAFONO ADICIONAL Y ESTE INDICA QUE SIN LA AUTORIZACIÓN DEL BANCO, NO ME PERMITEN EL INGRESO, SE INTENTA COMUNICAR CON LA LINEA DE BANCOLOMBIA EN UN LAPSO DE TIEMPO DE UNA HORA Y MEDIA, Y NUNCA CONTESTARON, ME COMUNICO CON EL COORDINADOR JOSE HERNÁNDEZ Y ESTE MANIFIESTA QUE SE TIENE QUE REAGENDAR LA VISITA Y QUE ME RETIRE DEL SITIO | T5: VISITA TECNICA | U5: AE007354 | V5: TIPO III | W5: TERRESTRE | X5: MONTES DIAZ JOHN FRED | Y5: 1 | Z5: 0 | AA5: 275729 | AB5: 196537 | AC5: 275729
A6: SANTA MARTA | B6: COSTA | C6: 0004-0001 | D6: 47555 | E6: TA-25-1341467 | F6: 3007056043 | G6: APERTURA | H6: DATAFONO ADICIONAL - ALIANZA | I6: MAGDALENA | J6: PLATO | K6: REVAL PLATO | L6: REDEBAN | M6: FO-25-1911541 | N6: 45993.333 | O6: 45994.629 | P6: ROBUSTO | Q6: REVAL | R6: EJECUTADO | S6: 01/12/2025 01-12 SE REALIZA LLAMADA AL CLIENTE, SE HABLA CON EL SR RAFAEL ROYS SE VALIDA DIRECCIÓN OK, CANAL OK, DISPONIBILIDAD TOTAL, LLAMAR EL DÍA LA INSTALACIÓN PARA CONFIRMAR VISITA | 03/12/2025 SE VISITA SITIO SE VERIFICA INFORMACIÓN SE REALIZA INSTALACIÓN DE DATÁFONO ADICIONAL CON SU RESPECTIVO ESCANEAR FUENTE PODER, CABLE DE RED, MAGIC BOX, BASE SOPORTE, LECTURA DE CHIP OK, TECLADO OK, IMPRESIÓN. PRUEBAS TRX EXITOSAS. | T6: VISITA TECNICA | U6: 9CQZZ890 | V6: TIPO IV | W6: TERRESTRE | X6: SANTOS GUZMAN CHRISTIAN FELIPE | Y6: 1 | Z6: 0 | AA6: 504833 | AB6: 196537 | AC6: 504833
A7: MANIZALES | B7: SUROCCIDENTE Y EJE CAFETERO | C7: 0004-0002 | D7: 17001 | E7: TA-25-1382428 | F7: 3007082464 | G7: APERTURA | H7: CB CRECIMIENTO ALIANZA - NUEVO | I7: CALDAS | J7: MANIZALES | K7: DISTRICOL DROGUERIA GENERIK | L7: REDEBAN | M7: FO-25-1949034 | N7: 46001.333 | O7: 46002.708 | R7: EJECUTADO | S7: 09/12/2025 09-12 PROGRAMACION REALIZADA POR LA ALIANZA| INSTALACIÓN PROGRAMADA PARA EL 2025-12-11 | 11/12/2025 SE REALIZA INSTALACIÓN DE DATAFONO Y ACCESORIOS BASE LECTOR 40 ROLLOS Y PUBLICIDAD SE CAPACITA AL COMERCIO SE CREAN USUARIOS SE HACEN PRUEBAS DE CONSULTA DE SALDO SOLAMENTE YA QUE USUARIO NO CUENTA CON HERRAMIENTAS PARA REALIZAR RETIRO RECAUDO NI CONSIGNACIÓN SERVICIO OK | T7: VISITA TECNICA | U7: DA006233 | V7: TIPO I | W7: TERRESTRE | X7: AGUIRRE HENAO RAUL EDUARDO | Y7: 1 | Z7: 0 | AA7: 75096 | AB7: 75096 | AC7: 75096
A8: VALLEDUPAR | B8: COSTA | C8: 0004-0001 | D8: 20011 | E8: TA-25-1382429 | F8: 3007082460 | G8: APERTURA | H8: CB CRECIMIENTO ALIANZA - NUEVO | I8: CESAR | J8: AGUACHICA | K8: DISTRIOL PAPELERIA PERF ZAMI | L8: REDEBAN | M8: FO-25-1949036 | N8: 46001.333 | O8: 46002.521 | R8: EJECUTADO | S8: 09/12/2025 09-12 PROGRAMACION REALIZADA POR LA ALIANZA| INSTALACIÓN PROGRAMADA PARA EL 2025-12-11 | 11/12/2025 SE REALIZA APERTURA DE CB, SE INSTALA DATAFONO, LECTOR Y PINPAD, YA QUE CLIENTE CONTABA CON VIDRIO DE SEGURIDAD, SE INSTALA PUBLICIDAD, SE ENTREGAN 40 ROLLOS, SE BRINDA CAPACITACIÓN, SE REALIZAN PRUEBAS DE TRANSACCIONES, DEJANDO SERVICIO FUNCIONAL AL 100 % | T8: VISITA TECNICA | U8: DA006234 | V8: TIPO IV | W8: TERRESTRE | X8: MONTES DIAZ JOHN FRED | Y8: 1 | Z8: 0 | AA8: 504833 | AB8: 196537 | AC8: 504833
A9: PASTO | B9: SUROCCIDENTE Y EJE CAFETERO | C9: 0004-0003 | D9: 52001 | E9: TA-25-1382430 | F9: 3007082466 | G9: APERTURA | H9: CB CRECIMIENTO ALIANZA - NUEVO | I9: NARIÑO | J9: PASTO | K9: DISTRICOL CENTROMARKET | L9: REDEBAN | M9: FO-25-1949039 | N9: 46001.333 | O9: 46002.622 | R9: EJECUTADO | S9: 09/12/2025 09-12 PROGRAMACION REALIZADA POR LA ALIANZA| INSTALACIÓN PROGRAMADA PARA EL 2025-12-11 | 11/12/2025 SE REALIZÓ LA INSTALACIÓN DE EQUIPOS PUBLICIDAD Y ACCESORIOS PARA APERTURA CB BANCOLOMBIA SE DIO CAPACITACIÓN MANEJO DE DATÁFONO CB Y SOMOS BANCOLOMBIA SE EJECUTAN PRUEBAS TX EXITOSAS QUEDA OPERATIVO. | T9: VISITA TECNICA | U9: DA006235 | V9: TIPO I | W9: TERRESTRE | X9: REMICIO AMADO JOHN HEBER | Y9: 1 | Z9: 0 | AA9: 75096 | AB9: 75096 | AC9: 75096
A10: MEDELLIN | B10: NOROCCIDENTE | C10: 0004-0005 | D10: 5628 | E10: TA-25-1382432 | F10: 3007067237 | G10: APERTURA | H10: DATAFONO ADICIONAL - ALIANZA | I10: ANTIOQUIA | J10: SABANALARGA | K10: PTM SABANALARGA TU DROGUERIA | L10: REDEBAN | M10: FO-25-1949046 | N10: 46001.333 | O10: 46002.701 | P10: AGREGADOR | Q10: COMCARD - PTM | R10: EJECUTADO | S10: 09/12/2025 09-12 PROGRAMACION REALIZADA POR LA ALIANZA| INSTALACIÓN PROGRAMADA PARA EL 2025-12-11 | 11/12/2025 SE REALIZA INSTALACIÓN DE DATAFONO ADICIONAL OK | T10: VISITA TECNICA | U10: DA006237 | V10: TIPO III | W10: TERRESTRE | X10: QUINTERO SANCHEZ JUAN SEBASTIAN | Y10: 1 | Z10: 0 | AA10: 275729 | AB10: 196537 | AC10: 275729
A11: CUCUTA | B11: SANTANDERES | C11: 0004-0008 | D11: 54001 | E11: TA-25-1382439 | F11: 3007072968 | G11: APERTURA | H11: DATAFONO ADICIONAL - ALIANZA | I11: NORTE DE SANTANDER | J11: CUCUTA | K11: DISTRICOL DE TODITO YAYUYA | L11: REDEBAN | M11: FO-25-1949049 | N11: 46001.333 | O11: 46001.986 | P11: AGREGADOR | Q11: DISTRICOL | R11: EJECUTADO | S11: 09/12/2025 09-12 PROGRAMACION REALIZADA POR LA ALIANZA| INSTALACIÓN PROGRAMADA PARA EL 2025-12-10 | 10/12/2025 SE INSTALA DATAFONO LECTOR BASE Y ACCESORIOS SE DEJA NUEVA VERSIÓN CIERRES Y PRUEBAS OK | T11: VISITA TECNICA | U11: DA006238 | V11: TIPO I | W11: TERRESTRE | X11: DURAN ACOSTA FRANK YONNY | Y11: 1 | Z11: 0 | AA11: 75096 | AB11: 75096 | AC11: 75096
A12: MEDELLIN | B12: NOROCCIDENTE | C12: 0004-0005 | D12: 5001 | E12: TA-25-1393484 | F12: 3007082483 | G12: APERTURA | H12: CB CRECIMIENTO ALIANZA - NUEVO | I12: ANTIOQUIA | J12: MEDELLIN | K12: PTM MEDELLIN PLANET SHOPPING | L12: REDEBAN | M12: FO-25-1959628 | N12: 46003.333 | O12: 46003.681 | P12: AGREGADOR | Q12: COMCARD - PTM | R12: EJECUTADO | S12: 11/12/2025 11-12 PROGRAMACION REALIZADA POR LA ALIANZA| INSTALACIÓN PROGRAMADA PARA EL 2025-12-12 | 12/12/2025 INSTALACIÓN DE CB MIXTO OK PUBLICIDAD Y CAPACITACIÓN OK PRUEBAS SOLO CONSULTA DE SALDO NO HAY PARA MÁS CUBRE CLAVE OK NO TELECARGA | T12: VISITA TECNICA | U12: DA007308 | V12: TIPO I | W12: TERRESTRE | X12: PAREJA ECHAVARRIA JHON DAVID | Y12: 1 | Z12: 0 | AA12: 75096 | AB12: 75096 | AC12: 75096
A13: MEDELLIN | B13: NOROCCIDENTE | C13: 0004-0005 | D13: 5001 | E13: TA-25-1393485 | F13: 3007082484 | G13: APERTURA | H13: CB CRECIMIENTO ALIANZA - NUEVO | I13: ANTIOQUIA | J13: MEDELLIN | K13: PTM MEDELLIN SURTIBELLEZA LOS | L13: REDEBAN | M13: FO-25-1959631 | N13: 46003.333 | O13: 46003.581 | P13: AGREGADOR | Q13: COMCARD - PTM | R13: EJECUTADO | S13: 11/12/2025 11-12 PROGRAMACION REALIZADA POR LA ALIANZA| INSTALACIÓN PROGRAMADA PARA EL 2025-12-12 | 15/12/2025 INSTALACIÓN DE CB MIXTO OK PUBLICIDAD Y CAPACITACIÓN OK PRUEBAS SOLO CONSULTA SALDO NO HAY MAS CUBRE CLAVE OK NO TELECARGA | T13: VISITA TECNICA | U13: DA007309 | V13: TIPO I | W13: TERRESTRE | X13: PAREJA ECHAVARRIA JHON DAVID | Y13: 1 | Z13: 0 | AA13: 75096 | AB13: 75096 | AC13: 75096
A14: MEDELLIN | B14: NOROCCIDENTE | C14: 0004-0005 | D14: 5001 | E14: TA-25-1393486 | F14: 3007082485 | G14: APERTURA | H14: CB CRECIMIENTO ALIANZA - NUEVO | I14: ANTIOQUIA | J14: MEDELLIN | K14: PTM MEDELLIN MINIMERCADO EL MA | L14: REDEBAN | M14: FO-25-1959633 | N14: 46003.333 | O14: 46003.626 | P14: AGREGADOR | Q14: COMCARD - PTM | R14: EJECUTADO | S14: 11/12/2025 11-12 PROGRAMACION REALIZADA POR LA ALIANZA| INSTALACIÓN PROGRAMADA PARA EL 2025-12-12 | 12/12/2025 SE HACE APERTURA DE CB EXITOSAMENTE | T14: VISITA TECNICA | U14: DA007310 | V14: TIPO I | W14: TERRESTRE | X14: RUA ALVAREZ RICHARD ANDRES | Y14: 1 | Z14: 0 | AA14: 75096 | AB14: 75096 | AC14: 75096
A15: TUNJA | B15: SANTANDERES | C15: 0004-0008 | D15: 15516 | E15: TA-25-1393487 | F15: 3007082475 | G15: APERTURA | H15: CB CRECIMIENTO ALIANZA - NUEVO | I15: BOYACA | J15: PAIPA | K15: PTM PAIPA FARMA DIAZ MAS | L15: REDEBAN | M15: FO-25-1959638 | N15: 46003.333 | O15: 46006.638 | P15: AGREGADOR | Q15: COMCARD - PTM | R15: EJECUTADO | S15: 11/12/2025 11-12 PROGRAMACION REALIZADA POR LA ALIANZA| INSTALACIÓN PROGRAMADA PARA EL 2025-12-15 | 15/12/2025 SE REALIZA VISITA AL COMERCIO, SE INSTALAN EQUIPOS Y ACCESORIOS, SE CAPACITA AL CLIENTE Y SE HACEN PRUEBAS OK. | T15: VISITA TECNICA | U15: DA007311 | V15: TIPO II | W15: TERRESTRE | X15: SOLER HOYOS CRISTIAN LEONARDO | Y15: 1 | Z15: 0 | AA15: 163814 | AB15: 140396 | AC15: 163814
A16: BOGOTA | B16: CENTRO | C16: 0004-0004 | D16: 25269 | E16: TA-25-1393489 | F16: 3007082472 | G16: APERTURA | H16: CB CRECIMIENTO ALIANZA - NUEVO | I16: CUNDINAMARCA | J16: FACATATIVA | K16: PTM FACATATIVA AUTO SERVICIO E | L16: REDEBAN | M16: FO-25-1959649 | N16: 46003.333 | O16: 46003.578 | P16: AGREGADOR | Q16: COMCARD - PTM | R16: EJECUTADO | S16: 11/12/2025 11-12 PROGRAMACION REALIZADA POR LA ALIANZA| INSTALACIÓN PROGRAMADA PARA EL 2025-12-12 | 12/12/2025 APERTURA BANCOLOMBIA OK CAPACITACIÓN OK PUBLICIDAD OK SERVICIO OPERATIVO SE REALIZA PRUEBAS CON INFORMACIÓN QUE NOS SUMINISTRO EL CLIENTE | T16: VISITA TECNICA | U16: DA007314 - DA007184 | V16: TIPO II | W16: TERRESTRE | X16: HERNANDEZ NARANJO OSCAR EDUARDO | Y16: 1 | Z16: 0 | AA16: 163814 | AB16: 140396 | AC16: 163814
A17: BOGOTA | B17: CENTRO | C17: 0004-0004 | D17: 25473 | E17: TA-25-1393490 | F17: 3007082474 | G17: APERTURA | H17: CB CRECIMIENTO ALIANZA - NUEVO | I17: CUNDINAMARCA | J17: MOSQUERA | K17: PTM MOSQUERA PAPELERIA LISETTE | L17: REDEBAN | M17: FO-25-1959655 | N17: 46003.333 | O17: 46003.516 | P17: AGREGADOR | Q17: COMCARD - PTM | R17: EJECUTADO | S17: 11/12/2025 11-12 PROGRAMACION REALIZADA POR LA ALIANZA| INSTALACIÓN PROGRAMADA PARA EL 2025-12-12 | 12/12/2025 SE REALIZA INSTALACIÓN DE DATAFONO LECTOR BASE PUBLICIDAD COMPLETA SE CAPACITA COMERCIO SE REALIZAN PRUEBAS OK NO SE TIENE TARJETA DE BANCOLOMBIA | T17: VISITA TECNICA | U17: DA007315 | V17: TIPO I | W17: TERRESTRE | X17: SOTO LONDOÑO FREDY ALEXANDER | Y17: 1 | Z17: 0 | AA17: 75096 | AB17: 75096 | AC17: 75096
A18: BOGOTA | B18: CENTRO | C18: 0004-0004 | D18: 25817 | E18: TA-25-1393492 | F18: 3007082480 | G18: APERTURA | H18: CB CRECIMIENTO ALIANZA - NUEVO | I18: CUNDINAMARCA | J18: TOCANCIPA | K18: PTM TOCANCIPA LOKYAN DIVERTPAR | L18: REDEBAN | M18: FO-25-1959661 | N18: 46003.333 | O18: 46003.572 | P18: AGREGADOR | Q18: COMCARD - PTM | R18: EJECUTADO | S18: 11/12/2025 11-12 PROGRAMACION REALIZADA POR LA ALIANZA| INSTALACIÓN PROGRAMADA PARA EL 2025-12-12 | 12/12/2025 INSTALACIÓN BANCOLOMBIA CON PUBLICIDAD DATAFONO LECTORA ROLLOS BASE FUENTE DATOS SERVICIO OPERATIVO PRUEBAS OK CON UNA CONSULTA DE SALDO NO HAY VINO HACER CONSIGNACION O RETIRO TRNA RBM SE INSTALA CUBRE TECLADO | T18: VISITA TECNICA | U18: DA007316 | V18: TIPO II | W18: TERRESTRE | X18: BUSTOS MORA DIEGO MANUEL | Y18: 1 | Z18: 0 | AA18: 163814 | AB18: 140396 | AC18: 163814
A19: MEDELLIN | B19: NOROCCIDENTE | C19: 0004-0005 | D19: 27361 | E19: TA-25-1393494 | F19: 3007082473 | G19: APERTURA | H19: CB CRECIMIENTO ALIANZA - NUEVO | I19: CHOCO | J19: ISTMINA | K19: PTM ISTMINA TIENDA Y VARIEDADE | L19: REDEBAN | M19: FO-25-1959664 | N19: 46003.333 | O19: 46009.711 | P19: AGREGADOR | Q19: COMCARD - PTM | R19: EJECUTADO | S19: 11/12/2025 11-12 PROGRAMACION REALIZADA POR LA ALIANZA| INSTALACIÓN PROGRAMADA PARA EL 2025-12-18 | 19/12/2025 SE REALIZA INSTALACIÓN, CAPACITACION Y PRUEBAS CON EL CLIENTE YBEL CB QUEDA OPERATIVO | T19: VISITA TECNICA | U19: DA007188 - DA007317 | V19: TIPO V | W19: AEREO | X19: ROBLEDO DIAZ ANDRES FELIPE | Y19: 1 | Z19: 0 | AA19: 988463 | AB19: 196537 | AC19: 988463
A20: VILLAVICENCIO | B20: ORIENTE | C20: 0004-0007 | D20: 50573 | E20: TA-25-1393495 | F20: 3007082479 | G20: APERTURA | H20: CB CRECIMIENTO ALIANZA - NUEVO | I20: META | J20: PUERTO LOPEZ | K20: PTM META VARIEDADES JOBAP | L20: REDEBAN | M20: FO-25-1959667 | N20: 46003.333 | O20: 46006.558 | P20: AGREGADOR | Q20: COMCARD - PTM | R20: EJECUTADO | S20: 11/12/2025 11-12 PROGRAMACION REALIZADA POR LA ALIANZA| INSTALACIÓN PROGRAMADA PARA EL 2025-12-15 | 17/12/2025 SE REALIZA INSTALACION CORRESPONSAL BANCOLOMBIA, SE REALIZAN PRUEBAS Y CAPACITACIÓN TODO OK | T20: VISITA TECNICA | U20: DA007318 - DA007189 | V20: TIPO II | W20: TERRESTRE | X20: PEDREROS CONTRERAS MICHAEL STEVENS | Y20: 1 | Z20: 0 | AA20: 163814 | AB20: 140396 | AC20: 163814
A21: CALI | B21: SUROCCIDENTE | C21: 0004-0003 | D21: 76520 | E21: TA-25-1393496 | F21: 3007082476 | G21: APERTURA | H21: CB CRECIMIENTO ALIANZA - NUEVO | I21: VALLE DEL CAUCA | J21: PALMIRA | K21: PTM PALMIRA TIENDA Y VARIEDADE | L21: REDEBAN | M21: FO-25-1959673 | N21: 46003.333 | O21: 46006.28 | P21: AGREGADOR | Q21: COMCARD - PTM | R21: EJECUTADO | S21: 11/12/2025 11-12 PROGRAMACION REALIZADA POR LA ALIANZA| INSTALACIÓN PROGRAMADA PARA EL 2025-12-15 | 15/12/2025 SE REALIZÓ LA INSTALACIÓN DE EL CORRESPONSAL BANCOLOMBIA MIXTO, DATÁFONO, LECTOR, MAGIC BOX 2600 BASE SOPORTE DE EL DATÁFONO Y SE IMPLEMENTARON LOS ROLLOS Y LA PUBLICIDAD DE BANCOLOMBIA,SE BRINDA CAPACITACIÓN Y SE REALIZARON LAS PRUEBAS CON EL CLIENTE DEJANDO EL SERVICIO OPERANDO SIN FALLAS Y SIN NOVEDAD. | T21: VISITA TECNICA | U21: DA007320 -DA007190 | V21: TIPO I | W21: TERRESTRE | X21: SANCHEZ URREGO ROBINSON DAVID | Y21: 1 | Z21: 0 | AA21: 75096 | AB21: 75096 | AC21: 75096
... A42: CALI | B42: SUROCCIDENTE | C42: 0004-0003 | D42: 76001 | E42: TA-25-1429969 | F42: 3007082500 | G42: APERTURA | H42: CB CRECIMIENTO ALIANZA - NUEVO | I42: VALLE DEL CAUCA | J42: CALI | K42: PTM CALI MISCELANEA Y PAPELERI | L42: REDEBAN | M42: FO-25-1990033 | N42: 46009.333 | O42: 46009.59 | P42: AGREGADOR | Q42: COMCARD - PTM | R42: EJECUTADO | S42: 17/12/2025 17-12 PROGRAMACION REALIZADA POR LA ALIANZA| INSTALACIÓN PROGRAMADA PARA EL 2025-12-18 | 18/12/2025 SE LLAMA AL CLIENTE, SE VALIDA LA VISITA DE LA INSTALACION, DIRECCION Y DISPONIBILIDAD, SE VISITA EL COMERCIO, SE INSTALA DATAFONO, LECTORA, ACCESORIOS EN APERTURA CB BANCOLOMBIA MIXTO, INSTALÓ PUBLICIDAD, SE CAPACITA, PRUEBAS OK, TELECARGA TRNA | T42: VISITA TECNICA | U42: FB007698 | V42: TIPO I | W42: TERRESTRE | X42: HERRERA MONAR GEOVANNY | Y42: 1 | Z42: 0 | AA42: 75096 | AB42: 75096 | AC42: 75096
A43: CALI | B43: SUROCCIDENTE | C43: 0004-0003 | D43: 76834 | E43: TA-25-1429972 | F43: 3007082513 | G43: APERTURA | H43: CB CRECIMIENTO ALIANZA - NUEVO | I43: VALLE DEL CAUCA | J43: TULUA | K43: PTM TULUA CORREO Y DOMICILIOS | L43: REDEBAN | M43: FO-25-1999658 | FO-25-1990037 | N43: 46009.333 | O43: 46010.438 | P43: AGREGADOR | Q43: COMCARD - PTM | R43: EJECUTADO | S43: [FO-25-1999658] 19/12/2025 SE VISITA CORRESPONSAL Y SE PROCEDE A REALIZA INSTALACIÓN DE PIN PAD. TRANSACCIONES DE PRUEBA EXITOSAS || [FO-25-1990037] 17/12/2025 17-12 PROGRAMACION REALIZADA POR LA ALIANZA| INSTALACIÓN PROGRAMADA PARA EL 2025-12-18 | 18/12/2025 SE VISITA ESTABLECIMIENTO, SE REALIZA INSTALACIÓN CORRESPONSAL BANCOLOMBIA. TRANSACCIONES DE PRUEBA EXITOSAS SOLO CON LAS QUE DISPONE EL CLIENTE Y SE REALIZARON PRUEBAS CON TARJETA DE OTRO BANCO PARA SIMULAR PROCESO . SE INSTALA PUBLICIDAD COMPLETA Y SE CAPACITA. | T43: VISITA TECNICA | V43: TIPO II | W43: TERRESTRE | X43: BOLAÑOS TABORDA JORGE ENRIQUE | Y43: 2 | Z43: 0 | AA43: 327628 | AB43: 140396 | AC43: 327628
A44: YOPAL | B44: ORIENTE | C44: 0004-0007 | D44: 85001 | E44: TA-25-1429974 | F44: 3007082515 | G44: APERTURA | H44: CB CRECIMIENTO ALIANZA - NUEVO | I44: CASANARE | J44: YOPAL | K44: DISTRICOL MISCELANEA LAVADERO | L44: REDEBAN | M44: FO-25-1990041 | N44: 46009.333 | O44: 46009.7 | P44: AGREGADOR | Q44: DISTRICOL | R44: EJECUTADO | S44: 17/12/2025 17-12 PROGRAMACION REALIZADA POR LA ALIANZA| INSTALACIÓN PROGRAMADA PARA EL 2025-12-18 | 18/12/2025 SE VISITA COMERCIO, SE INSTALA DATÁFONO LECTOR BASE Y CUBRE TECLADO. PRUEBAS OK. OPERATIVO EL SERVICIO. SOMOS BANCOLOMBIA OK. SE CAPACITA CLIENTE. NO SE REALIZA PRUEBA DE TRANSFERENCIA NO SE CUENTA CON TARJETA | T44: VISITA TECNICA | U44: FB007700 | V44: TIPO I | W44: TERRESTRE | X44: BERNAL ELAICA EDGAR ALEXIS | Y44: 1 | Z44: 0 | AA44: 75096 | AB44: 75096 | AC44: 75096
A45: YOPAL | B45: ORIENTE | C45: 0004-0007 | D45: 85001 | E45: TA-25-1429976 | F45: 3007082516 | G45: APERTURA | H45: CB CRECIMIENTO ALIANZA - NUEVO | I45: CASANARE | J45: YOPAL | K45: DISTRICOL CASFARMA YOPAL | L45: REDEBAN | M45: FO-25-1990045 | N45: 46009.333 | O45: 46010.604 | P45: AGREGADOR | Q45: DISTRICOL | R45: EJECUTADO | S45: 17/12/2025 17-12 PROGRAMACION REALIZADA POR LA ALIANZA| INSTALACIÓN PROGRAMADA PARA EL 2025-12-19 | 20/12/2025 SE VISITA COMERCIO, SE INSTALA DATÁFONO LECTOR BASE Y CUBRE TECLADO. PRUEBAS OK. OPERATIVO EL SERVICIO. SE CAPACITA CLIENTE SOMOS BANCOLOMBIA OK. NO SE REALIZA PRUEBA DE TRANSFERENCIA NO SE CUENTA CON TARJETA | T45: VISITA TECNICA | U45: FB007701 | V45: TIPO I | W45: TERRESTRE | X45: BERNAL ELAICA EDGAR ALEXIS | Y45: 1 | Z45: 0 | AA45: 75096 | AB45: 75096 | AC45: 75096
A46: BOGOTA | B46: CENTRO | C46: 0004-0004 | D46: 11001 | E46: TA-25-1429979 | F46: 3007082498 | G46: APERTURA | H46: CB CRECIMIENTO ALIANZA - NUEVO | I46: CUNDINAMARCA | J46: BOGOTA | K46: PTM BOGOTA MTG PRINCIPAL | L46: REDEBAN | M46: FO-25-1990054 | N46: 46009.333 | O46: 46010.503 | P46: AGREGADOR | Q46: COMCARD - PTM | R46: EJECUTADO | S46: 17/12/2025 17-12 PROGRAMACION REALIZADA POR LA ALIANZA| INSTALACIÓN PROGRAMADA PARA EL 2025-12-19 | 26/12/2025 SE REALIZA APERTURA DE CORRESPONSAL BANCOLOMBIA, SE INSTALA PUBLICIDAD, EQUIPOS . SE REALIZA CAPACITACIÓN AL RESPONSABLE DEL CB Y SE ENTREGAN LOS ROLLOS PARA EL PUNTO | T46: VISITA TECNICA | U46: FB007702 | V46: TIPO I | W46: TERRESTRE | X46: ALARCON AREVALO JOHAN STIVEN | Y46: 1 | Z46: 0 | AA46: 75096 | AB46: 75096 | AC46: 75096
A47: BOGOTA | B47: CENTRO | C47: 0004-0004 | D47: 11001 | E47: TA-25-1429983 | F47: 3007082496 | G47: APERTURA | H47: CB CRECIMIENTO ALIANZA - NUEVO | I47: CUNDINAMARCA | J47: BOGOTA | K47: PTM BOGOTA COMPU EMI | L47: REDEBAN | M47: FO-25-1990059 | N47: 46009.333 | O47: 46010.55 | P47: AGREGADOR | Q47: COMCARD - PTM | R47: EJECUTADO | S47: 17/12/2025 17-12 PROGRAMACION REALIZADA POR LA ALIANZA| INSTALACIÓN PROGRAMADA PARA EL 2025-12-19 | 19/12/2025 APERTURA BANCOLOMBIA OK CAPACITACIÓN OK PUBLICIDAD OK SERVICIO OPERATIVO | T47: VISITA TECNICA | U47: FB007703 | V47: TIPO I | W47: TERRESTRE | X47: HERNANDEZ NARANJO OSCAR EDUARDO | Y47: 1 | Z47: 0 | AA47: 75096 | AB47: 75096 | AC47: 75096
A48: MEDELLIN | B48: NOROCCIDENTE | C48: 0004-0005 | D48: 5001 | E48: TA-25-1429986 | F48: 3007038563 | G48: APERTURA | H48: DATAFONO ADICIONAL - ALIANZA | I48: ANTIOQUIA | J48: MEDELLIN | K48: DISTRICOL PAPELERIA TOBY | L48: REDEBAN | M48: FO-25-1990064 | N48: 46009.333 | O48: 46009.499 | P48: AGREGADOR | Q48: DISTRICOL | R48: EJECUTADO | S48: 17/12/2025 17-12 PROGRAMACION REALIZADA POR LA ALIANZA| INSTALACIÓN PROGRAMADA PARA EL 2025-12-18 | 18/12/2025 SE INSTALA DATAFONO ADICIONAL EXITOSAMENTE | T48: VISITA TECNICA | U48: FB007704 | V48: TIPO I | W48: TERRESTRE | X48: RUA ALVAREZ RICHARD ANDRES | Y48: 1 | Z48: 0 | AA48: 75096 | AB48: 75096 | AC48: 75096
A49: MEDELLIN | B49: NOROCCIDENTE | C49: 0004-0005 | D49: 5615 | E49: TA-25-1429989 | F49: 3007035275 | G49: APERTURA | H49: DATAFONO ADICIONAL - ALIANZA | I49: ANTIOQUIA | J49: RIONEGRO | K49: DISTRICOL MERCADOS BARCELONA | L49: REDEBAN | M49: FO-25-1990068 | N49: 46009.333 | O49: 46010.675 | P49: AGREGADOR | Q49: DISTRICOL | R49: EJECUTADO | S49: 17/12/2025 17-12 PROGRAMACION REALIZADA POR LA ALIANZA| INSTALACIÓN PROGRAMADA PARA EL 2025-12-19 | 19/12/2025 SE INSTALA DATAFONO ADICIONAL | T49: VISITA TECNICA | U49: FB007705 | V49: TIPO II | W49: TERRESTRE | X49: BADEL ACUÑA LUIS ALBERTO | Y49: 1 | Z49: 0 | AA49: 163814 | AB49: 140396 | AC49: 163814
A50: MONTERIA | B50: COSTA | C50: 0004-0001 | D50: 23555 | E50: TA-25-1429991 | F50: 3007035487 | G50: APERTURA | H50: DATAFONO ADICIONAL - ALIANZA | I50: CORDOBA | J50: PLANETA RICA | K50: DISTRICOL CAFETERIA COFFE HOUSE | L50: REDEBAN | M50: FO-25-1990071 | N50: 46009.333 | O50: 46009.602 | P50: AGREGADOR | Q50: DISTRICOL | R50: EJECUTADO | S50: 17/12/2025 17-12 PROGRAMACION REALIZADA POR LA ALIANZA| INSTALACIÓN PROGRAMADA PARA EL 2025-12-18 | 18/12/2025 SE REALIZA VISITA TÉCNICA PARA APERTURA, DATAFONO ADICIONAL, SE INSTALA DATAFONO PLACA 1196702, LECTORA SYMBOL PLACA 902751, CUBRE CLAVES Y ACCESORIOS, SE REALIZAN PRUEBAS OK, NO SE REALIZA CAPACITACIÓN YA QUE EL CB SE ENCUENTRA CAPACITADO. NOTA: NO SE INSTALA PUBLICIDAD YA QUE ES DATAFONO ADICIONAL. SE DEJA EQUIPO LISTO PARA OPERACIONES. | T50: VISITA TECNICA | U50: FB007706 | V50: TIPO II | W50: TERRESTRE | X50: CASSIANI PEREZ RAUL RAMIRO | Y50: 1 | Z50: 0 | AA50: 163814 | AB50: 140396 | AC50: 163814
A51: YOPAL | B51: ORIENTE | C51: 0004-0007 | D51: 85001 | E51: TA-25-1429993 | F51: 3007059188 | G51: APERTURA | H51: DATAFONO ADICIONAL - ALIANZA | I51: CASANARE | J51: YOPAL | K51: MULTIPAGAS YOPAL CENTRO | L51: REDEBAN | M51: FO-25-1990075 | N51: 46009.333 | O51: 46009.467 | P51: ROBUSTO | Q51: MULTIPAGAS | R51: EJECUTADO | S51: 17/12/2025 17-12 SE REALIZA LLAMADA AL CLIENTE, SE HABLA CON LA SRA EIDY RUIZ AL NUMERO 3223525164 SE VALIDA DIRECCIÓN OK, CANAL OK, DISPONIBILIDAD TOTAL, LLAMAR EL DÍA LA INSTALACIÓN PARA CONFIRMAR VISITA | 18/12/2025 SE VISITA COMERCIO, SE INSTALA DATÁFONO PINPAD Y LECTOR ADICIONAL. OPERATIVO EL SERVICIO. PRUEBAS OK. NO SE REALIZA PRUEBA DE TRANSFERENCIA NO SE CUENTA CON TARJETA. EIDY RUIZ INDICA NO REQUIERE BASE POR LA POSICIÓN Y EL ESPACIO ES MUY REDUCIDO. CB INDICA NO TENER ACCESO A DOCUMENTOS COMO CAMARA DE COMERCIO Y RECIBOS, MOTIVO QUE ES UN ROBUSTO Y ESOS DOCUMENTOS LO TIENEN OTRAS PERSONAS. | T51: VISITA TECNICA | U51: FB007707 | V51: TIPO I | W51: TERRESTRE | X51: BERNAL ELAICA EDGAR ALEXIS | Y51: 1 | Z51: 0 | AA51: 75096 | AB51: 75096 | AC51: 75096
A52: MEDELLIN | B52: NOROCCIDENTE | C52: 0004-0005 | D52: 5631 | E52: TA-25-1429995 | F52: 3007082468 | G52: APERTURA | H52: CB CRECIMIENTO ALIANZA - OTRAS LISTAS | I52: ANTIOQUIA | J52: SABANETA | K52: DISTRICOL PARENTESIS A&C | L52: REDEBAN | M52: FO-25-1990081 | N52: 46009.333 | O52: 46009.595 | P52: AGREGADOR | Q52: DISTRICOL | R52: EJECUTADO | S52: 17/12/2025 17-12 PROGRAMACION REALIZADA POR LA ALIANZA| INSTALACIÓN PROGRAMADA PARA EL 2025-12-18 | 18/12/2025 SE HACE IMPLEMENTACION OK EQUIPOS OPERATIVOS PRUEBAS EXITOSAS SOMOS BANCOLOMBIA ACTIVO, CAPACITACIÓN Y PUBLICIDAD OK | T52: VISITA TECNICA | U52: FB007708 | V52: TIPO I | W52: TERRESTRE | X52: DIAZ ZABALA FRANCIS DUBAN | Y52: 1 | Z52: 0 | AA52: 75096 | AB52: 75096 | AC52: 75096
A53: MEDELLIN | B53: NOROCCIDENTE | C53: 0004-0005 | D53: 5001 | E53: TA-25-1446312 | F53: 3007082585 | G53: APERTURA | H53: CB CRECIMIENTO ALIANZA - NUEVO | I53: ANTIOQUIA | J53: MEDELLIN | K53: DISTRICOL DROGUERIA SIRDALUD | L53: REDEBAN | M53: FO-25-2024417 | N53: 46015.333 | O53: 46015.463 | P53: AGREGADOR | Q53: DISTRICOL | R53: EJECUTADO | S53: 23/12/2025 23-12 PROGRAMACION REALIZADA POR LA ALIANZA| INSTALACIÓN PROGRAMADA PARA EL 2025-12-24 | 24/12/2025 INSTALACIÓN DE CB PURO OK PUBLICIDAD Y CAPACITACIÓN OK PRUEBAS SOLO CONSULTA DE SALDO NO HAY PARA MÁS CUBRE CLAVE OK NO TELECARGA | T53: VISITA TECNICA | U53: OB007835 | V53: TIPO I | W53: TERRESTRE | X53: PAREJA ECHAVARRIA JHON DAVID | Y53: 1 | Z53: 0 | AA53: 75096 | AB53: 75096 | AC53: 75096
A54: MEDELLIN | B54: NOROCCIDENTE | C54: 0004-0005 | D54: 5001 | E54: TA-25-1446314 | F54: 3007082586 | G54: APERTURA | H54: CB CRECIMIENTO ALIANZA - NUEVO | I54: ANTIOQUIA | J54: MEDELLIN | K54: DISTRICOL TIENDA DEL PELUQUERO | L54: REDEBAN | M54: FO-25-2024424 | N54: 46015.333 | O54: 46015.572 | P54: AGREGADOR | Q54: DISTRICOL | R54: EJECUTADO | S54: 23/12/2025 23-12 PROGRAMACION REALIZADA POR LA ALIANZA| INSTALACIÓN PROGRAMADA PARA EL 2025-12-24 | 24/12/2025 SE INSTALAN EQUIPOS OK | T54: VISITA TECNICA | U54: OB007836 | V54: TIPO I | W54: TERRESTRE | X54: QUINTERO SANCHEZ JUAN SEBASTIAN | Y54: 1 | Z54: 0 | AA54: 75096 | AB54: 75096 | AC54: 75096
A55: MEDELLIN | B55: NOROCCIDENTE | C55: 0004-0005 | D55: 5001 | E55: TA-25-1446315 | F55: 3007082587 | G55: APERTURA | H55: CB CRECIMIENTO ALIANZA - NUEVO | I55: ANTIOQUIA | J55: MEDELLIN | K55: DISTRICOL COMERCIALIZADORA KTE | L55: REDEBAN | M55: FO-25-2024425 | N55: 46015.333 | O55: 46015.54 | P55: AGREGADOR | Q55: DISTRICOL | R55: EJECUTADO | S55: 23/12/2025 23-12 PROGRAMACION REALIZADA POR LA ALIANZA| INSTALACIÓN PROGRAMADA PARA EL 2025-12-24 | 24/12/2025 INSTALACIÓN CB OK | T55: VISITA TECNICA | U55: OB007837 | V55: TIPO I | W55: TERRESTRE | X55: BADEL ACUÑA LUIS ALBERTO | Y55: 1 | Z55: 0 | AA55: 75096 | AB55: 75096 | AC55: 75096
... A88: MEDELLIN | B88: NOROCCIDENTE | C88: 0004-0005 | D88: 5789 | E88: TA-25-1463252 | F88: 3007021280 | G88: APERTURA | H88: DATAFONO ADICIONAL - ALIANZA | I88: ANTIOQUIA | J88: TAMESIS | K88: PTM TAMESIS TELECOM | L88: REDEBAN | M88: FO-25-2046848 | N88: 46020.333 | O88: 46021.575 | P88: AGREGADOR | Q88: COMCARD - PTM | R88: EJECUTADO | S88: 29/12/2025 29-12 SE REALIZA LLAMADA AL CLIENTE, SE HABLA CON EL SR DIEGO SALGADO AL NUMERO 3147338903 SE VALIDA DIRECCIÓN OK, CANAL OK, DISPONIBILIDAD TOTAL, LLAMAR EL DÍA LA INSTALACIÓN PARA CONFIRMAR VISITA | 02/01/2026 SE REALIZA LA INSTALACIÓN DE 1 DATAFONO ADICIONAL, 1 LECTOR, SE INSTALA BASE DE DATAFONO, 60 ROLLOS INSTALACION OK | T88: VISITA TECNICA | U88: AE00D133 | V88: TIPO III | W88: TERRESTRE | X88: MONTOYA VELEZ ANDRES FELIPE | Y88: 1 | Z88: 0 | AA88: 275729 | AB88: 196537 | AC88: 275729

Sheet INCIDENTES_BANCOLOMBIA
A1: CIUDAD SEDE | B1: ZONA | C1: CENTRO DE COSTOS LINEACOM | D1: CODIGO DANE | E1: TA/CODIGO ACTIVIDAD | F1: CODIGO CB | G1: ACTIVIDAD | H1: DEPARTAMENTO | I1: CIUDAD | J1: NOMBRE DEL CB | K1: RED | L1: FO | M1: FECHA ASIGNACION A LINEA COMUNICACIONES | N1: FECHA CIERRE DEL TICKET (DD/MM/AAAA HH:MM) | O1: ACOMETIDA | P1: GRUPO_FALLA | Q1: CATEGORIA | R1: FALLA | S1: FORMATO | T1: CADENA | U1: ESTADO | V1: OBSERVACION | W1: FORMA DE ATENCION | X1: TERMINAL(ES) | Y1: TIPIFICACION | Z1: TIPO DE TRAYECTO | AA1: NOMBRE DEL TECNICO | AB1: DIAS DE VISITA | AC1: DIA ADICIONAL | AD1: VALOR DIAS ACTIVIDAD FACTURABLES | AE1: VALOR DIAS ACOMPAÑAMIENTO FACTURABLES | AF1: VALOR TOTAL
A2: MONTERIA | B2: COSTA | C2: 0004-0001 | D2: 5495 | E2: 3040690 | F2: 3007060039 | G2: INCIDENTE | H2: ANTIOQUIA | I2: NECHI | J2: DISTRICOL DISTRIBUIDORA EL AHI | K2: REDEBAN | L2: FO-25-1851887 | M2: 45981.482 | N2: 45993.362 | P2: HARDWARE | Q2: IMPRESION | R2: NO AVANZA PAPEL | S2: AGREGADOR | T2: DISTRICOL | V2: 20/11/2025 SE ESCALA PARA VISITA. LLAMAR ANTES DE VISITAR, CONFIRMAR FALLA Y DATOS | 21/11/2025 SE LLEGA A MUNICIPIO DE NECHÍ - ANTIOQUIA, NO SE LOGRA CONTACTAR A LA PERSONA ENCARGADA DEL CB PARA VALIDAR PERMISOS DE INGRESO , AL CORREGIMIENTO QUÉ SE ENCUENTRA EN ZONA ROJA CON PROBLEMAS DE ORDEN PÚBLICO MOTIVO POR EL CUAL NO SE REALIZA DESPLAZAMIENTO DIRECTO, SE REPROGRAMA VISITA HASTA PODER CONTACTAR AL CLIENTE PARA GARANTIZAR LA INTEGRIDAD DEL PERSONAL TÉCNICO EN LA ZONA. | 02/12/2025 SE ESTABLECE COMUNICACIÓN TELEFÓNICA CON EL CLIENTE SEÑORA MARTA ROJAS QUIEN CONFIRMA QUE EL DATAFONO SE ENCUENTRA OPERATIVO REALIZÓ REINICIO DEL EQUIPO, CAMBIO PAPEL Y FUNCIONÓ, ACTUALMENTE SE CONFIRMA CON LA SEÑORA QUE SE ENCUENTRA OPERATIVO SIN NOVEDAD OK, SE PROCEDE A CERRAR LA ORDEN OK | W2: SOPORTE TELEFONICO | Y2: TIPO III | Z2: TERRESTRE | AA2: GONZALEZ FERRER JESUS ALEXANDER | AB2: 0 | AC2: 0 | AD2: 41241 | AE2: 0 | AF2: 41241
A3: YOPAL | B3: REMOTAS | C3: 0004-0007 | D3: 85001 | E3: 3073318 | F3: 3007034137 | G3: INCIDENTE | H3: CASANARE | I3: YOPAL | J3: BARRIO NUEVO HABITAT II YOPAL | K3: REDEBAN | L3: FO-25-1899408 | M3: 45988.668 | N3: 45993.65 | P3: HARDWARE | Q3: ALERT IRRUPTION | R3: ALERT IRRUPTION | S3: UNO A UNO | T3: CB UNO A UNO | V3: 27/11/2025 SE ESCALA PARA VISITA. LLAMAR ANTES DE VISITAR, CONFIRMAR FALLA Y DATOS | 02/12/2025 EN COMUNICACIÓN CON EL SEÑOR ARLEY OROZCO AL NUMERO 3208005960, INDICA NO REQUIERE LA VISITA, LE REALIZARON LA MIGRACIÓN A WOMPI Y YA NO UTILIZA EL DATAFONO DE RBM. INFORMA QUE TIENE OPERATIVO EL SERVICIO | W3: SOPORTE TELEFONICO | Y3: TIPO I | Z3: TERRESTRE | AA3: BERNAL ELAICA EDGAR ALEXIS | AB3: 0 | AC3: 0 | AD3: 41241 | AE3: 0 | AF3: 41241
A4: PASTO | B4: SUROCCIDENTE Y EJE CAFETERO | C4: 0004-0003 | D4: 52835 | E4: 3073329 | F4: 3007024652 | G4: INCIDENTE | H4: NARIÑO | I4: SAN ANDRES DE TUMACO | J4: BARRIO CALLE SUCRE SAN ANDRES | K4: REDEBAN | L4: FO-25-1899402 | M4: 45988.671 | N4: 45994.387 | O4: NO | P4: HARDWARE | Q4: IMPRESION | R4: NO IMPRIME UNO O VARIOS CARACTERES | S4: CB UNO A UNO | T4: CB UNO A UNO | U4: EJECUTADO | V4: 27/11/2025 SE ESCALA PARA VISITA. LLAMAR ANTES DE VISITAR, CONFIRMAR FALLA Y DATOS | 01/12/2025 NO SE PUEDE REALIZAR DESPLAZAMIENTO HOY HACIA TUMACO POR PROBLEMAS EN LA VIA, HACIA BARBACOAS, SE VALIDARA EL DIA DE MAÑANA | 03/12/2025 SE REALIZA CAMBIO DE DATÁFONO POR DAÑO EN IMPRESORA SE RECONFIGURA OK PARÁMETROS OK Y SE REALIZAN PRUEBAS EXITOSAS DE TRANSACCIONES | W4: VISITA TECNICA | X4: SA09Z857 | Y4: TIPO IV | Z4: TERRESTRE | AA4: PAZ MARTINEZ RICHARD HUMBERTO | AB4: 1 | AC4: 0 | AD4: 479589 | AE4: 196537 | AF4: 479589
A5: CALI | B5: SUROCCIDENTE Y EJE CAFETERO | C5: 0004-0003 | D5: 19075 | E5: 3073403 | F5: 3007059688 | G5: INCIDENTE | H5: CAUCA | I5: BALBOA | J5: BARRIO BOLIVAR BALBOA | K5: REDEBAN | L5: FO-25-1899405 | M5: 45988.669 | N5: 45992.417 | P5: HARDWARE | Q5: COMUNICACION | R5: MENSAJE CABLE DE RED DESCONECTADO | S5: CB UNO A UNO | T5: CB UNO A UNO | V5: 27/11/2025 SE ESCALA PARA VISITA. LLAMAR ANTES DE VISITAR, CONFIRMAR FALLA Y DATOS | 01/12/2025 SE REALIZA LLAMADA CON LA SEÑORA YAQUELINE VELASCO INFORMA YA EL DATAFONO FUNCIONA OK | W5: SOPORTE TELEFONICO | Y5: TIPO IV | Z5: TERRESTRE | AA5: GIMBUEL LASSO LUIS GERMAN | AB5: 0 | AC5: 0 | AD5: 41241 | AE5: 0 | AF5: 41241
A6: MONTERIA | B6: COSTA | C6: 0004-0001 | D6: 5250 | E6: 3073446 | F6: 3007058297 | G6: INCIDENTE | H6: ANTIOQUIA | I6: EL BAGRE | J6: BARRIO BRR EL PORVENIR EL BAGR | K6: REDEBAN | L6: FO-25-1899746 | M6: 45988.682 | N6: 45993.647 | O6: NO | P6: HARDWARE | Q6: PANTALLA | R6: DAÑO POS | S6: CB UNO A UNO | T6: CB UNO A UNO | U6: EJECUTADO | V6: 27/11/2025 SE ESCALA PARA VISITA. LLAMAR ANTES DE VISITAR, CONFIRMAR FALLA Y DATOS | 02/12/2025 SE REALIZA CAMBIO DE EQUIPO POR DAÑO, DISPLAY BLANCO E INTERMITENTE, ADICIONAL SE CAMBIA EN PINPAD POR COMPATIBILIDAD, SE RETIRA MAGICBOX OK, EQUIPOS Y ACCESORIOS INSTALADOS OPERATIVOS, PRUEBAS EXITOSAS, CLIENTE CB VALIDA SALDO ANTES Y DESPUÉS DEL MANTENIMIENTO OK, CB SE DEJA OPERATIVO SIN NOVEDAD OK | W6: VISITA TECNICA | X6: IMZZZ418 | Y6: TIPO IV | Z6: TERRESTRE | AA6: GONZALEZ FERRER JESUS ALEXANDER | AB6: 1 | AC6: 0 | AD6: 479589 | AE6: 196537 | AF6: 479589
A7: CALI | B7: SUROCCIDENTE Y EJE CAFETERO | C7: 0004-0003 | D7: 76001 | E7: 3074172 | F7: 3007014454 | G7: INCIDENTE | H7: VALLE DEL CAUCA | I7: CALI | J7: BARRIO EL JARDIN II CALI | K7: REDEBAN | L7: FO-25-1903340 | M7: 45989.345 | N7: 45993.548 | O7: NO | P7: SOFTWARE | Q7: ACTUALIZACION | R7: VERSION CARGA SO VR | S7: CB UNO A UNO | T7: CB UNO A UNO | U7: EJECUTADO | V7: 03/12/2025 SE INICIALIZA EL EQUIPO YA QUE SE CREA TERMINAL DE SERVIR PARA MIXTO POR SOLICITUD DE REDEBAN SE REALIZAN PRUEBAS EXITOSAS | W7: VISITA TECNICA | X7: AE007395 IZ00Q965 | Y7: TIPO I | Z7: TERRESTRE | AA7: PALACIOS GOMEZ BRAHIAN ANDRES | AB7: 1 | AC7: 0 | AD7: 65960 | AE7: 75096 | AF7: 65960
A8: IBAGUE | B8: REMOTAS | C8: 0004-0007 | D8: 73555 | E8: 3074742 | F8: 3007011707 | G8: INCIDENTE | H8: TOLIMA | I8: PLANADAS | J8: PLANADAS TOLIMA | K8: REDEBAN | L8: FO-25-1900998 | M8: 45989.36 | N8: 45993.401 | O8: NO | P8: HARDWARE | Q8: ALERT IRRUPTION | R8: ALERT IRRUPTION | S8: CB UNO A UNO | T8: CB UNO A UNO | U8: EJECUTADO | V8: 28/11/2025 SE ESCALA PARA VISITA. LLAMAR ANTES DE VISITAR, CONFIRMAR FALLA Y DATOS | 01/12/2025 DEBIDO LA POCA FRECUENCIA DE TRANSPORTE HACIA LA ZONA Y AL ESTADO DE LAS VÍAS HAY DEMORAS PARA LLEGAR AL MUNICIPIO DE PLANADAS | 02/12/2025 SE REALIZA CAMBIO DE EQUIPO ALERT IRRUPTION | W8: VISITA TECNICA | X8: JAAAE398 | Y8: TIPO IV | Z8: TERRESTRE | AA8: GUTIERREZ CAMILO ANDRES | AB8: 1 | AC8: 0 | AD8: 479589 | AE8: 196537 | AF8: 479589
A9: MEDELLIN | B9: NOROCCIDENTE | C9: 0004-0005 | D9: 5736 | E9: 3075174 | F9: 3007076067 | G9: INCIDENTE | H9: ANTIOQUIA | I9: SEGOVIA | J9: BARRIO GALAN SEGOVIA 1 | K9: REDEBAN | L9: FO-25-1901273 | M9: 45989.399 | N9: 45992.415 | P9: HARDWARE | Q9: CABLEADO | R9: DAÑO POS | S9: CB UNO A UNO | T9: CB UNO A UNO | V9: [FO-25-1901273] 28/11/2025 SE ESCALA PARA VISITA. LLAMAR ANTES DE VISITAR, CONFIRMAR FALLA Y DATOS | 01/12/2025 SE INTENTA COMUNICACIÓN CON CLIENTE AL 3137588872 SIN ÉXITO EN LLAMADA O WHATSAPP | 01/12/2025 SE COMUNICA CON CLIENTE E INFORMA QUE EL EQUIPO YA ESTÁ FUNCIONANDO CORRECTAMENTE DESPUÉS DE REINICIAR EL MÓDEM, SE CIERRA || [FO-25-1901273] 28/11/2025 SE ESCALA PARA VISITA. LLAMAR ANTES DE VISITAR, CONFIRMAR FALLA Y DATOS | 01/12/2025 SE INTENTA COMUNICACIÓN CON CLIENTE AL 3137588872 SIN ÉXITO EN LLAMADA O WHATSAPP | 01/12/2025 SE COMUNICA CON CLIENTE E INFORMA QUE EL EQUIPO YA ESTÁ FUNCIONANDO CORRECTAMENTE DESPUÉS DE REINICIAR EL MÓDEM, SE CIERRA | W9: SOPORTE TELEFONICO | Y9: TIPO IV | Z9: TERRESTRE | AA9: QUINTERO SANCHEZ JUAN SEBASTIAN | AB9: 0 | AC9: 0 | AD9: 82482 | AE9: 0 | AF9: 82482
A10: BOGOTA | B10: CUNDINAMARCA | C10: 0004-0004 | D10: 25843 | E10: 3075604 | F10: 3007079958 | G10: INCIDENTE | H10: CUNDINAMARCA | I10: VILLA DE SAN DIEGO DE UBATE | J10: BARRIO SIMON BOLIVAR VILLA DE SAN DIEGO DE UBATE 3 | K10: REDEBAN | L10: FO-25-1901795 | M10: 45989.43 | N10: 45992.629 | O10: NO | P10: HARDWARE | Q10: DETERIORO | R10: DATAFONO | S10: UNO A UNO | T10: UNO A UNO | U10: EJECUTADO | V10: 28/11/2025 SE ESCALA PARA VISITA. LLAMAR ANTES DE VISITAR, CONFIRMAR FALLA Y DATOS | 29/11/2025 DEBIDO A QUE NO HAY SOPORTE DE ACTIVOS REDEBAN Y POR DESPLAZAMIENTO, NO SE PUEDE VISITAR COMERCIO. SE HABLA LA SRA NORMA LETICIA 3123742690 M QUIEN INFORMA RECIBIR VISITA EL DÍA LUNES 01-12-2025 | 01/12/2025 SE VISITA COMERCIO CB BANCOLOMBIA, SE CAMBIA DATAFONO POR QUÉ TIENE EL PUERTO USB DETERIORADO Y EL CABLE DE LA LECTORA TAMBIÉN, SE DEJA EL EQUIPO NUEVO EN BUEN ESTADO CON LOS USUARIOS DEL CLIENTE, SE REALIZAN PRUEBAS OK, NO UPS. | W10: VISITA TECNICA | X10: SAUZZ586 | Y10: TIPO II | Z10: TERRESTRE | AA10: VEGA MANRIQUE JONATAN MAURICIO | AB10: 1 | AC10: 0 | AD10: 144968 | AE10: 140396 | AF10: 144968
A11: VILLAVICENCIO | B11: REMOTAS | C11: 0004-0007 | D11: 50568 | E11: 3076614 | F11: 3007081862 | G11: INCIDENTE | H11: META | I11: PUERTO GAITAN | J11: PTM PUERTO GAITAN DROGUERIA JA | K11: REDEBAN | L11: FO-25-1903554 | M11: 45989.538 | N11: 45992.722 | O11: NO | P11: HARDWARE | Q11: ALERT IRRUPTION | R11: ALERT IRRUPTION | S11: AGREGADOR | T11: COMCARD - PTM | U11: EJECUTADO | V11: 28/11/2025 SE ESCALA PARA VISITA. LLAMAR ANTES DE VISITAR, CONFIRMAR FALLA Y DATOS | 01/12/2025 SE REALIZA CAMBIO DE EQUIPO POR DAÑO SE ENCONTRABA ALERTADO | W11: VISITA TECNICA | X11: VWZZZ799 VTZZZ904 | Y11: TIPO III | Z11: TERRESTRE | AA11: ROZO JIMENEZ EDGAR ARMANDO | AB11: 1 | AC11: 0 | AD11: 275729 | AE11: 196537 | AF11: 275729
A12: BOGOTA | B12: CUNDINAMARCA | C12: 0004-0004 | D12: 11001 | E12: 3077409 | F12: 3007025523 | G12: INCIDENTE | H12: CUNDINAMARCA | I12: BOGOTA | J12: PAGAFACIL TERMINAL TRANSPORTE | K12: REDEBAN | L12: FO-25-1907819 | FO-25-1904338 | M12: 45989.652 | N12: 45992.549 | O12: NO | P12: SOFTWARE | Q12: PINPAD | R12: PINPAD DESCONFIGURADO | S12: ROBUSTO | T12: PAGAFACIL | U12: EJECUTADO | EJECUTADO / CANCELADO | V12: [FO-25-1907819] 01/12/2025 SE REALIZA REVISIÓN DE LOS EQUIPOS SE ENCUENTRA QUE EL CABLE DE CONEXIÓN DATÁFONO-PINPAD ESTÁ DAÑADO, FALLO MASIVO EN EL MOMENTO DE REALIZAR INCIDENTE SE PROCEDE A TOMAR FOTO DE LAS PRIMERAS TRANSACCIONES QUE SALIERON || [FO-25-1904338] 28/11/2025 SE ESCALA PARA VISITA. LLAMAR ANTES DE VISITAR, CONFIRMAR FALLA Y DATOS | 29/11/2025 SE REPROGRAMA VISITA PARA EL DÍA LUNES NO SE CUENTAN CON EQUIPOS DE BAKCUP EN DISPONIBILIDAD, ADICIONAL DEMORAS PARA CAMBIO DE EQUIPO. | W12: VISITA TECNICA | X12: BL0GZ758 | Y12: TIPO I | Z12: TERRESTRE | AA12: ALARCON AREVALO JOHAN STIVEN | AB12: 2 | AC12: 0 | AD12: 131920 | AE12: 75096 | AF12: 131920
A13: MONTERIA | B13: COSTA | C13: 0004-0001 | D13: 23500 | E13: 3077810 | F13: 3007042001 | G13: INCIDENTE | H13: CORDOBA | I13: MOÑITOS | J13: DISTRICOL AGROVETERINARIA JIRE | K13: REDEBAN | L13: FO-25-1904843 | M13: 45989.718 | N13: 45992.735 | O13: NO | P13: HARDWARE | Q13: TECLADO | R13: DAÑO POS | S13: AGREGADOR | T13: DISTRICOL | U13: EJECUTADO | V13: 28/11/2025 SE ESCALA PARA VISITA. LLAMAR ANTES DE VISITAR, CONFIRMAR FALLA Y DATOS | 01/12/2025 DEBIDO A INCONVENIENTE CON LOS CAMBIOS DE EQUIPO POR PARTE DE REDEBAN, NOS TENEMOS RETRASO PARA LLEGAR AL SITIO YA QUE NOS ENCONTRAMOS EN UN INCIDENTE REALIZANDO UN CAMBIO Y HAY INCONVENIENTES CON LOS CAMBIOS POR PARTE DE REDEBAN. TENIENDO EN CUENTA LAS NOTAS ACÁ TAMBIÉN SERÁ UN POSIBLE CAMBIO DE EQUIPO, LO QUE REQUIERE DEL TIEMPO REGLAMENTARIO PARA LA ATENCIÓN Y LA HORA LÍMITE ESTÁ A LAS 17:14. | 01/12/2025 SE REALIZA VISITA TÉCNICA Y SE CAMBIA DATAFONO POR DAÑO DE TECLADO, TECLAS BORROSA Y DURAS, SE INSTALA DATÁFONO PLACA 1255207 Y SE RETIRA DATAFONO PLACA 1173969, SE REALIZAN PRUEBAS Y SE DEJA EL SERVICIO FUNCIONANDO CORRECTAMENTE. | W13: VISITA TECNICA | X13: GZ0XZ403 | Y13: TIPO III | Z13: TERRESTRE | AA13: CASSIANI PEREZ RAUL RAMIRO | AB13: 1 | AC13: 0 | AD13: 275729 | AE13: 196537 | AF13: 275729
A14: CALI | B14: SUROCCIDENTE Y EJE CAFETERO | C14: 0004-0003 | D14: 19100 | E14: 3077881 | F14: 3007045599 | G14: INCIDENTE | H14: CAUCA | I14: BOLIVAR | J14: BARRIO NARINO BOLIVAR | K14: REDEBAN | L14: FO-25-1905863 | M14: 45990.384 | N14: 45993.604 | O14: NO | P14: HARDWARE | Q14: TECLADO | R14: DAÑO POS | S14: CB UNO A UNO | T14: CB UNO A UNO | U14: EJECUTADO | V14: 29/11/2025 SE ESCALA PARA VISITA. LLAMAR ANTES DE VISITAR, CONFIRMAR FALLA Y DATOS | 01/12/2025 POR TEMA DE ORDEN PUBLICO EN LA ZONA Y RIESGO SE CUADRA CON EL CB PARA ATENDER ACTIVIDAD EN UN LUGAR SEGURO SE GESTIONO CON EL CB A ESPERA DE LA PRONTA SOLUCION | 02/12/2025 SE INGRESA EQUIPO CON TECLADO DETERIORO DURO SE PROCEDE A CAMBIAR EQUIPO SE HACEN PRUEBAS OK TELECARG DRNA | W14: VISITA TECNICA | X14: AD000826 | Y14: TIPO IV | Z14: TERRESTRE | AA14: GIMBUEL LASSO LUIS GERMAN | AB14: 1 | AC14: 0 | AD14: 479589 | AE14: 196537 | AF14: 479589
A15: APARTADO | B15: NOROCCIDENTE | C15: 0004-0005 | D15: 5490 | E15: 3077889 | F15: 3007052873 | G15: INCIDENTE | H15: ANTIOQUIA | I15: NECOCLI | J15: BARRIO SIMON BOLIVAR NECOCLI | K15: REDEBAN | L15: FO-25-1906249 | M15: 45990.41 | N15: 45992.532 | O15: NO | P15: HARDWARE | Q15: DETERIORO | R15: DATAFONO | S15: CB UNO A UNO | T15: CB UNO A UNO | U15: EJECUTADO | V15: 29/11/2025 SE ESCALA PARA VISITA. LLAMAR ANTES DE VISITAR, CONFIRMAR FALLA Y DATOS | 01/12/2025 ESTAMOS EN DESPLAZAMIENTO PARA NECOCLI, CONDUCTORES MANIFIESTA QUE ALGUNOS NO ESTÁN LLEGANDO POR PROBLEMAS DE ORDEN PÚBLICO SOBRE UN PARO COMUNITARIO DEBIDO AL MAL ESTADO DE LA VIA. SE LLAMA A LA USUARIA EN DÓNDE SE LE INDICA LO SUCEDIDO Y QUE ESTAMOS EN CAMINO A ATENDER LA NOVEDAD. | 01/12/2025 DATÁFONO ATASCA EL PAPEL, SE VALIDA Y SE ENCUENTRA QUE LOS PIÑONES DE LA IMPRESORA ESTÁ DESGASTADOS SE HACE CAMBIO DE EQUIPO Y SE HACEN PRUEBAS DEJANDO TODO FUNCIONANDO CORRECTAMENTE | W15: VISITA TECNICA | X15: BA0IZ176 | Y15: TIPO II | Z15: TERRESTRE | AA15: SALDARRIAGA MIRANDA SANTIAGO | AB15: 1 | AC15: 0 | AD15: 144968 | AE15: 140396 | AF15: 144968
A16: MANIZALES | B16: SUROCCIDENTE Y EJE CAFETERO | C16: 0004-0002 | D16: 17614 | E16: 3077933 | F16: 3007029915 | G16: INCIDENTE | H16: CALDAS | I16: RIOSUCIO | J16: COMCARD RIOSUCIO LA CIGARRA | K16: REDEBAN | L16: FO-25-1904987 | M16: 45989.739 | N16: 45992.535 | O16: NO | P16: HARDWARE | Q16: IMPRESION | R16: NO IMPRIME UNO O VARIOS CARACTERES | S16: AGREGADOR | T16: COMCARD - PTM | U16: EJECUTADO | V16: 28/11/2025 SE ESCALA PARA VISITA. LLAMAR ANTES DE VISITAR, CONFIRMAR FALLA Y DATOS | 29/11/2025 EL CLIENTE REQUIERE CAMBIO DE EQUIPO SE DEBE VALIDAR VISITA A A PARTIR DEL DÍA LUNES | 01/12/2025 VISITAMOS COMERCIO EL DATÁFONO NO IMPRIME BIEN LAS TRX REALIZAMOS CAMBIO DE DATAFONO LO CONFIGURAMOS Y REALIZAMOS PRUEBAS PERO SALE RECHAZO GENERAL YA QUE BANCOLOMBIA ESTA PRESENTANDO FALLAS Y NO ES POSIBLE HACER NINGUNA TRANSACCIÓN ADJUNTAMOS LA TRANSACCIÓN DEL RECHAZO, SOLO ES POSIBLE HACER PRUEBAS EXITOSAS DE COMERCIO. | W16: VISITA TECNICA | X16: BBBUZ776 AB11O682 | Y16: TIPO II | Z16: TERRESTRE | AA16: ARROYAVE CANO MANUEL GUILLERMO | AB16: 1 | AC16: 0 | AD16: 144968 | AE16: 140396 | AF16: 144968
A17: NEIVA | B17: REMOTAS | C17: 0004-0007 | D17: 41078 | E17: 3077949 | F17: 3007048893 | G17: INCIDENTE | H17: HUILA | I17: BARAYA | J17: PTM PAGA TODO BARAYA | K17: REDEBAN | L17: FO-25-1904984 | M17: 45990.333 | N17: 45994.48 | O17: NO | P17: HARDWARE | Q17: DETERIORO | R17: DATAFONO | S17: AGREGADOR | T17: COMCARD - PTM | U17: EJECUTADO | V17: 28/11/2025 SE ESCALA PARA VISITA. LLAMAR ANTES DE VISITAR, CONFIRMAR FALLA Y DATOS | 03/12/2025 SE REALIZA CAMBIO DE EQUIPO YA QUE ESTE PRESENTA DESGASTE EN EL TECLADO, IMPRESORA Y PARTE DE LA CARCAZA , SE DEJA EQUIPO INSTALADO CON VR 9.90 PRUEBAS CB OK, CON OPERARIVO | W17: VISITA TECNICA | X17: AD00M825 | Y17: TIPO II | Z17: TERRESTRE | AA17: DEVIA REINOSO JUAN CARLOS | AB17: 1 | AC17: 0 | AD17: 144968 | AE17: 140396 | AF17: 144968
A18: VILLAVICENCIO | B18: REMOTAS | C18: 0004-0007 | D18: 50689 | E18: 3077964 | F18: 3007052948 | G18: INCIDENTE | H18: META | I18: SAN MARTIN | J18: PTM SAN MARTIN DROGERIA V&E | K18: REDEBAN | L18: FO-25-1905797 | M18: 45990.333 | N18: 45992.62 | O18: NO | P18: HARDWARE | Q18: LECTOR DE BARRAS | R18: DAÑO POS | S18: AGREGADOR | T18: COMCARD - PTM | U18: EJECUTADO | V18: 29/11/2025 SE ESCALA PARA VISITA. LLAMAR ANTES DE VISITAR, CONFIRMAR FALLA Y DATOS | 01/12/2025 SE REALIZA CAMBIO DE LECTOR DE BARRAS PRUEBAS OK SIN NOVEDADES | W18: VISITA TECNICA | X18: 9C0LZ863 | Y18: TIPO II | Z18: TERRESTRE | AA18: CASTRILLON URREA LONDIER LEANDRO | AB18: 1 | AC18: 0 | AD18: 144968 | AE18: 140396 | AF18: 144968
A19: MEDELLIN | B19: NOROCCIDENTE | C19: 0004-0005 | D19: 5360 | E19: 3078038 | F19: 3007032941 | G19: INCIDENTE | H19: ANTIOQUIA | I19: ITAGUI | J19: COMCARD ITAGUI PAPELERIA ASTUR | K19: REDEBAN | L19: FO-25-1904985 | M19: 45989.747 | N19: 45992.372 | O19: NO | P19: SOFTWARE | Q19: ACTUALIZACION | R19: VERSION CARGA SO VR | S19: AGREGADOR | T19: COMCARD - PTM | U19: EJECUTADO | V19: 28/11/2025 SE ESCALA PARA VISITA. LLAMAR ANTES DE VISITAR, CONFIRMAR FALLA Y DATOS | 01/12/2025 SE REALIZA INICIALIZACIÓN DE PARÁMETROS SE HACEN PRUEBAS OK | W19: VISITA TECNICA | X19: 11XZZ538 | Y19: TIPO I | Z19: TERRESTRE | AA19: MONTOYA VELEZ ANDRES FELIPE | AB19: 1 | AC19: 0 | AD19: 65960 | AE19: 75096 | AF19: 65960
A20: SANTA MARTA | B20: COSTA | C20: 0004-0001 | D20: 47288 | E20: 3078507 | F20: 3007069387 | G20: INCIDENTE | H20: MAGDALENA | I20: FUNDACION | J20: BARRIO SAN MARTIN FUNDACION | K20: REDEBAN | L20: FO-25-1905777 | M20: 45990.378 | N20: 45992.622 | O20: NO | P20: SOFTWARE | Q20: LLT | R20: LLT | S20: CB UNO A UNO | T20: CB UNO A UNO | U20: EJECUTADO | V20: 29/11/2025 SE ESCALA PARA VISITA. LLAMAR ANTES DE VISITAR, CONFIRMAR FALLA Y DATOS | 01/12/2025 SE REALI ALA VISITA SE ENCUENTRA EL ESTADO O CON PANTALLA AZUL Y ALERTADO, SE PROCEDE A CAMBIAR EL EQUIPO, SE REALIZAN PRUEBAS Y TODO OK | W20: VISITA TECNICA | X20: 10OZZ565 EF00X698 | Y20: TIPO III | Z20: TERRESTRE | AA20: THOMAS CAMPO SIGIFREDO SEGUNDO | AB20: 1 | AC20: 0 | AD20: 275729 | AE20: 196537 | AF20: 275729
