Workbook

Sheet RESUMEN
A1: FACTURACIÓN ENTREGA DE ROLLOS A GESTORES
A2: 1 AL 3O DE OCTUBRE 2025
A3: WOMPI
A4: CONCEPTOS | B4: CANTIDAD | C4: TOTAL
A5: ='ENTREGA DE ROLLOS EN BODEGAS'!R1 -> ENTREGA DE ROLLOS EN BODEGAS | B5: =COUNTA('ENTREGA DE ROLLOS EN BODEGAS'!A:A)-1 -> 3484 | C5: ='ENTREGA DE ROLLOS EN BODEGAS'!R3486 -> 72452214
A6: SUBTOTAL | C6: =SUM(C5:C5) -> 72452214
A7: Iva | C7: =C6*0.19 -> 13765921
A8: TOTAL | C8: =SUM(C6:C7) -> 86218135

Sheet BASE TARIFA 2025
A1: PROPONENTE | B1: TIPO ACTIVIDAD | C1: BODEGA | D1: CENTRO DE COSTOS | E1: ENTREGA DE DATAFONOS EN BODEGAS | F1: ENTREGA DE ROLLOS EN BODEGAS
A2: WOMPI (SOLICITUD ADICIONAL) | B2: ENTREGA DE DATAFONOS EN BODEGAS UBICADAS EN CIUDADES PRINCIPALES | C2: MEDELLIN | D2: WOMPI NOROCCIDENTE | E2: 37313 | F2: 15709.5
A3: WOMPI (SOLICITUD ADICIONAL) | B3: ENTREGA DE DATAFONOS EN BODEGAS UBICADAS EN CIUDADES PRINCIPALES | C3: BOGOTA | D3: WOMPI CENTRO | E3: 37313 | F3: 15709.5
A4: WOMPI (SOLICITUD ADICIONAL) | B4: ENTREGA DE DATAFONOS EN BODEGAS UBICADAS EN CIUDADES PRINCIPALES | C4: CALI | D4: WOMPI SUROCCIDENTE | E4: 37313 | F4: 15709.5
A5: WOMPI (SOLICITUD ADICIONAL) | B5: ENTREGA DE DATAFONOS EN BODEGAS UBICADAS EN CIUDADES PRINCIPALES | C5: PEREIRA | D5: WOMPI EJE CAFETERO | E5: 37313 | F5: 15709.5
A6: WOMPI (SOLICITUD ADICIONAL) | B6: ENTREGA DE DATAFONOS EN BODEGAS UBICADAS EN CIUDADES PRINCIPALES | C6: BARRANQUILLA | D6: WOMPI COSTA | E6: 37313 | F6: 15709.5
A7: WOMPI (SOLICITUD ADICIONAL) | B7: ENTREGA DE DATAFONOS EN BODEGAS UBICADAS EN CIUDADES PRINCIPALES | C7: BUCARAMANGA | D7: WOMPI SANTANDERES | E7: 37313 | F7: 15709.5
A8: WOMPI (SOLICITUD ADICIONAL) | B8: ENTREGA DE DATAFONOS EN BODEGAS UBICADAS EN CIUDADES PRINCIPALES | C8: MONTERIA | D8: WOMPI COSTA | E8: 37313 | F8: 15709.5
A9: WOMPI (SOLICITUD ADICIONAL) | B9: ENTREGA DE DATAFONOS EN BODEGAS UBICADAS EN CIUDADES REMOTAS CERTIFICADAS | C9: CUCUTA | D9: WOMPI SANTANDERES | E9: 49671.7 | F9: 28277.1
A10: WOMPI (SOLICITUD ADICIONAL) | B10: ENTREGA DE DATAFONOS EN BODEGAS UBICADAS EN CIUDADES REMOTAS CERTIFICADAS | C10: NEIVA | D10: WOMPI ORIENTE | E10: 49671.7 | F10: 28277.1
A11: WOMPI (SOLICITUD ADICIONAL) | B11: ENTREGA DE DATAFONOS EN BODEGAS UBICADAS EN CIUDADES REMOTAS CERTIFICADAS | C11: SANTA MARTA | D11: WOMPI COSTA | E11: 49671.7 | F11: 28277.1
A12: WOMPI (SOLICITUD ADICIONAL) | B12: ENTREGA DE DATAFONOS EN BODEGAS UBICADAS EN CIUDADES REMOTAS CERTIFICADAS | C12: TUNJA | D12: WOMPI SANTANDERES | E12: 49671.7 | F12: 28277.1
A13: WOMPI (SOLICITUD ADICIONAL) | B13: ENTREGA DE DATAFONOS EN BODEGAS UBICADAS EN CIUDADES REMOTAS CERTIFICADAS | C13: VILLAVICENCIO | D13: WOMPI ORIENTE | E13: 49671.7 | F13: 28277.1
... A23: WOMPI (SOLICITUD ADICIONAL) | B23: ENTREGA DE DATAFONOS EN BODEGAS UBICADAS EN CIUDADES REMOTAS NO CERTIFICADAS | C23: YOPAL | D23: WOMPI ORIENTE | E23: 49671.7 | F23: 28277.1

Sheet TD
A1: Centro_de_Costos | B1: Suma de ENTREGA DE ROLLOS EN BODEGAS
A2: WOMPI CENTRO | B2: 11499354
A3: WOMPI COSTA | B3: 10374554
A4: WOMPI EJE CAFETERO | B4: 5674271.4
A5: WOMPI NOROCCIDENTE | B5: 5067884.7
A6: WOMPI ORIENTE | B6: 13516454
A7: WOMPI SANTANDERES | B7: 15920007
A8: WOMPI SUROCCIDENTE | B8: 10399689
A9: Total general | B9: 72452214

Sheet Hoja1
A1: Codigo_Punto | B1: cantidad_equipos | C1: CANTIDAD DE ROLLOS
A2: 77794 | B2: 1 | C2: 8
A3: 75357 | B3: 1 | C3: 8
A4: 68846 | B4: 1 | C4: 8
A5: 66944 | B5: 1 | C5: 8
A6: 61928 | B6: 1 | C6: 8
A7: 47809 | B7: 1 | C7: 8
A8: 46151 | B8: 1 | C8: 8
A9: 44901 | B9: 1 | C9: 8
A10: 43438 | B10: 1 | C10: 8
A11: 40045 | B11: 1 | C11: 8
A12: 39165 | B12: 1 | C12: 8
A13: 33954 | B13: 1 | C13: 8
... A12120: 81210 | B12120: 1 | C12120: 8

Sheet ENTREGA DE ROLLOS EN BODEGAS
A1: Codigo_Punto | B1: Nombre_Punto | C1: Nit_CC_Persona | D1: TelefonoCB | E1: Celular_Contacto1 | F1: Celular_dueno | G1: Dirección_Establecimiento | H1: Latitud | I1: Longitud | J1: Departamento | K1: Municipio | L1: Corregimiento | M1: Codigo_Dane | N1: Fecha_Migracion | O1: Cantidad de Rollos por CB | P1: Bodega | Q1: Centro_de_Costos | R1: ENTREGA DE ROLLOS EN BODEGAS
A2: 36442 | B2: BARRIO SANTA TERESITA RIONEGRO | C2: 15429397 | D2: 6146333 | E2: 3225817414 | F2: 3219593986 | G2: CL 47 B 68 B 13 | H2: 6.1514384 | I2: -75.3879517 | J2: ANTIOQUIA | K2: RIONEGRO | L2: RIONEGRO | M2: 5615 | N2: 2025-10-01 | O2: =VLOOKUP(A2,Hoja1!A:C,3,0) -> 16 | P2: =VLOOKUP(M2,[1]TIPOLOGIAS_CB!$A:$F,4,0) -> MEDELLIN | Q2: =VLOOKUP(P2,'BASE TARIFA 2025'!C:D,2,0) -> WOMPI NOROCCIDENTE | R2: =VLOOKUP(P2,'BASE TARIFA 2025'!C:F,4,0) -> 15709.5
A3: 50236 | B3: BARRIO AL CAPILLA RIONEGRO | C3: 70289578 | D3: 0 | E3: 3113483494 | F3: 3113483494 | G3: CL 47 53 A 06,LA CAPILLA | H3: 6.1517454 | I3: -75.3766195 | J3: ANTIOQUIA | K3: RIONEGRO | L3: RIONEGRO | M3: 5615 | N3: 2025-10-01 | O3: =VLOOKUP(A3,Hoja1!A:C,3,0) -> 8 | P3: =VLOOKUP(M3,[1]TIPOLOGIAS_CB!$A:$F,4,0) -> MEDELLIN | Q3: =VLOOKUP(P3,'BASE TARIFA 2025'!C:D,2,0) -> WOMPI NOROCCIDENTE | R3: =VLOOKUP(P3,'BASE TARIFA 2025'!C:F,4,0) -> 15709.5
A4: 63252 | B4: BARRIO LA CAPILLA RIONEGRO 1 | C4: 52112772 | D4: 3052234534 | E4: 3052234534 | F4: 3052234534 | G4: CL 47 53 11 ZN URBANA RIONEGRO ANT,LA CAPILLA | H4: 6.1516913 | I4: -75.3763106 | J4: ANTIOQUIA | K4: RIONEGRO | L4: RIONEGRO | M4: 5615 | N4: 2025-10-01 | O4: =VLOOKUP(A4,Hoja1!A:C,3,0) -> 16 | P4: =VLOOKUP(M4,[1]TIPOLOGIAS_CB!$A:$F,4,0) -> MEDELLIN | Q4: =VLOOKUP(P4,'BASE TARIFA 2025'!C:D,2,0) -> WOMPI NOROCCIDENTE | R4: =VLOOKUP(P4,'BASE TARIFA 2025'!C:F,4,0) -> 15709.5
A5: 77015 | B5: BARRIO CENTRO RIONEGRO 4 | C5: 79570514 | D5: 3144207916 | E5: 3015438349 | F5: 3144207916 | G5: CL 47 76 30 CC RESERVA PLAZA LC 1013,CENTRO | H5: 6.1515052 | I5: -75.3924254 | J5: ANTIOQUIA | K5: RIONEGRO | L5: RIONEGRO | M5: 5615 | N5: 2025-10-01 | O5: =VLOOKUP(A5,Hoja1!A:C,3,0) -> 8 | P5: =VLOOKUP(M5,[1]TIPOLOGIAS_CB!$A:$F,4,0) -> MEDELLIN | Q5: =VLOOKUP(P5,'BASE TARIFA 2025'!C:D,2,0) -> WOMPI NOROCCIDENTE | R5: =VLOOKUP(P5,'BASE TARIFA 2025'!C:F,4,0) -> 15709.5
A6: 10438 | B6: CHINA - ANTIOQUIA | C6: 21464812 | D6: 4388717 | E6: 3122011685 | F6: 3122011685 | G6: RURAL_SAN FELIX VRD LA CHINA | H6: 6.3991575 | I6: -75.6147664 | J6: ANTIOQUIA | K6: SAN PEDRO DE LOS MILAGROS | L6: SAN PEDRO DE LOS MILAGROS | M6: 5664 | N6: 2025-10-02 | O6: =VLOOKUP(A6,Hoja1!A:C,3,0) -> 8 | P6: =VLOOKUP(M6,[1]TIPOLOGIAS_CB!$A:$F,4,0) -> MEDELLIN | Q6: =VLOOKUP(P6,'BASE TARIFA 2025'!C:D,2,0) -> WOMPI NOROCCIDENTE | R6: =VLOOKUP(P6,'BASE TARIFA 2025'!C:F,4,0) -> 15709.5
A7: 25843 | B7: CRA 50 #46-92 SAN PEDRO DE LOS MILAGROS - ANTIOQUIA | C7: 98664630 | D7: 8688702 | E7: 3104575719 | F7: 3104575719 | G7: CR 50 46 92 | H7: 6.4608238 | I7: -75.5568907 | J7: ANTIOQUIA | K7: SAN PEDRO DE LOS MILAGROS | L7: SAN PEDRO DE LOS MILAGROS | M7: 5664 | N7: 2025-10-02 | O7: =VLOOKUP(A7,Hoja1!A:C,3,0) -> 8 | P7: =VLOOKUP(M7,[1]TIPOLOGIAS_CB!$A:$F,4,0) -> MEDELLIN | Q7: =VLOOKUP(P7,'BASE TARIFA 2025'!C:D,2,0) -> WOMPI NOROCCIDENTE | R7: =VLOOKUP(P7,'BASE TARIFA 2025'!C:F,4,0) -> 15709.5
A8: 25984 | B8: BELEN SAN PEDRO DE LOS MILAGROS - ANTIOQUIA | C8: 42903068 | D8: 8663993 | E8: 3144822263 | F8: 3144822263 | G8: CL49N51A31 SAN PEDRO DE LOS MILAGROS SAN PEDRO ANTIOQUIA | H8: 6.46200115 | I8: -75.55670518 | J8: ANTIOQUIA | K8: SAN PEDRO DE LOS MILAGROS | L8: SAN PEDRO DE LOS MILAGROS | M8: 5664 | N8: 2025-10-02 | O8: =VLOOKUP(A8,Hoja1!A:C,3,0) -> 8 | P8: =VLOOKUP(M8,[1]TIPOLOGIAS_CB!$A:$F,4,0) -> MEDELLIN | Q8: =VLOOKUP(P8,'BASE TARIFA 2025'!C:D,2,0) -> WOMPI NOROCCIDENTE | R8: =VLOOKUP(P8,'BASE TARIFA 2025'!C:F,4,0) -> 15709.5
A9: 21444 | B9: CL PRINCIPAL SAN PEDRO | C9: 70197042 | D9: 8687415 | E9: 3137339977 | F9: 3137339977 | G9: CR 51B 50 49 | H9: 6.46120599 | I9: -75.55607688 | J9: ANTIOQUIA | K9: SAN PEDRO DE LOS MILAGROS | L9: SAN PEDRO DE LOS MILAGROS | M9: 5664 | N9: 2025-10-02 | O9: =VLOOKUP(A9,Hoja1!A:C,3,0) -> 16 | P9: =VLOOKUP(M9,[1]TIPOLOGIAS_CB!$A:$F,4,0) -> MEDELLIN | Q9: =VLOOKUP(P9,'BASE TARIFA 2025'!C:D,2,0) -> WOMPI NOROCCIDENTE | R9: =VLOOKUP(P9,'BASE TARIFA 2025'!C:F,4,0) -> 15709.5
A10: 10105 | B10: RETIRO II | C10: 71555939 | D10: 5411057 | E10: 3206750647 | F10: 3206750647 | G10: KM 2 VIA LA MARIA FRENTE A ESTACION PINARES | H10: 6.0748682 | I10: -75.4970617 | J10: ANTIOQUIA | K10: RETIRO | L10: RETIRO | M10: 5607 | N10: 2025-10-22 | O10: =VLOOKUP(A10,Hoja1!A:C,3,0) -> 8 | P10: =VLOOKUP(M10,[1]TIPOLOGIAS_CB!$A:$F,4,0) -> MEDELLIN | Q10: =VLOOKUP(P10,'BASE TARIFA 2025'!C:D,2,0) -> WOMPI NOROCCIDENTE | R10: =VLOOKUP(P10,'BASE TARIFA 2025'!C:F,4,0) -> 15709.5
A11: 31280 | B11: BARRIO EL PINO | C11: 1040180913 | D11: 5410393 | E11: 3136371106 | F11: 3136371106 | G11: CR 22 23 A 17 | H11: 6.0600423 | I11: -75.5038871 | J11: ANTIOQUIA | K11: RETIRO | L11: RETIRO | M11: 5607 | N11: 2025-10-22 | O11: =VLOOKUP(A11,Hoja1!A:C,3,0) -> 16 | P11: =VLOOKUP(M11,[1]TIPOLOGIAS_CB!$A:$F,4,0) -> MEDELLIN | Q11: =VLOOKUP(P11,'BASE TARIFA 2025'!C:D,2,0) -> WOMPI NOROCCIDENTE | R11: =VLOOKUP(P11,'BASE TARIFA 2025'!C:F,4,0) -> 15709.5
A12: 36661 | B12: BARRIO EL RETIRO RETIRO | C12: 21954026 | D12: 5414611 | E12: 3154037196 | F12: 3154037196 | G12: CR 20 CL 24 190 EL RETIRO | H12: 6.0622023 | I12: -75.5020615 | J12: ANTIOQUIA | K12: RETIRO | L12: RETIRO | M12: 5607 | N12: 2025-10-22 | O12: =VLOOKUP(A12,Hoja1!A:C,3,0) -> 8 | P12: =VLOOKUP(M12,[1]TIPOLOGIAS_CB!$A:$F,4,0) -> MEDELLIN | Q12: =VLOOKUP(P12,'BASE TARIFA 2025'!C:D,2,0) -> WOMPI NOROCCIDENTE | R12: =VLOOKUP(P12,'BASE TARIFA 2025'!C:F,4,0) -> 15709.5
A13: 37131 | B13: BARRIO BICENTENARIO RETIRO | C13: 1040180195 | E13: 3147315434 | F13: 3147315434 | G13: CL 28 17 53 | H13: 6.062802 | I13: -75.499519 | J13: ANTIOQUIA | K13: RETIRO | L13: RETIRO | M13: 5607 | N13: 2025-10-22 | O13: =VLOOKUP(A13,Hoja1!A:C,3,0) -> 8 | P13: =VLOOKUP(M13,[1]TIPOLOGIAS_CB!$A:$F,4,0) -> MEDELLIN | Q13: =VLOOKUP(P13,'BASE TARIFA 2025'!C:D,2,0) -> WOMPI NOROCCIDENTE | R13: =VLOOKUP(P13,'BASE TARIFA 2025'!C:F,4,0) -> 15709.5
A14: 48261 | B14: BARRIO CENTRO RETIRO 1 | C14: 43689639 | D14: 0 | E14: 3233720447 | F14: 3213535244 | G14: CR 20 23 69,CENTRO | H14: 6.0602618 | I14: -75.5028651 | J14: ANTIOQUIA | K14: RETIRO | L14: RETIRO | M14: 5607 | N14: 2025-10-22 | O14: =VLOOKUP(A14,Hoja1!A:C,3,0) -> 8 | P14: =VLOOKUP(M14,[1]TIPOLOGIAS_CB!$A:$F,4,0) -> MEDELLIN | Q14: =VLOOKUP(P14,'BASE TARIFA 2025'!C:D,2,0) -> WOMPI NOROCCIDENTE | R14: =VLOOKUP(P14,'BASE TARIFA 2025'!C:F,4,0) -> 15709.5
A15: 53856 | B15: BARRIO OBRERO AGUSTIN CODAZZI | C15: 1065598199 | D15: 318 6436957 | E15: 3186436957 | F15: 3186436957 | G15: CL 12 10 26 LC 1,BRR OBRERO | H15: 10.03343861 | I15: -73.22936569 | J15: CESAR | K15: AGUSTÍN CODAZZI | L15: AGUSTÍN CODAZZI | M15: 20013 | N15: 2025-10-01 | O15: =VLOOKUP(A15,Hoja1!A:C,3,0) -> 16 | P15: =VLOOKUP(M15,[1]TIPOLOGIAS_CB!$A:$F,4,0) -> VALLEDUPAR | Q15: =VLOOKUP(P15,'BASE TARIFA 2025'!C:D,2,0) -> WOMPI COSTA | R15: =VLOOKUP(P15,'BASE TARIFA 2025'!C:F,4,0) -> 28277.1
A16: 63270 | B16: BARRIO CENTRO AGUSTIN CODAZZI 5 | C16: 1065873778 | D16: 3226493768 | E16: 3106153055 | F16: 3226493768 | G16: CR 14B 10 14 | H16: 10.028191 | I16: -73.2344330 | J16: CESAR | K16: AGUSTÍN CODAZZI | L16: AGUSTÍN CODAZZI | M16: 20013 | N16: 2025-10-01 | O16: =VLOOKUP(A16,Hoja1!A:C,3,0) -> 8 | P16: =VLOOKUP(M16,[1]TIPOLOGIAS_CB!$A:$F,4,0) -> VALLEDUPAR | Q16: =VLOOKUP(P16,'BASE TARIFA 2025'!C:D,2,0) -> WOMPI COSTA | R16: =VLOOKUP(P16,'BASE TARIFA 2025'!C:F,4,0) -> 28277.1
A17: 77212 | B17: BARRIO LOS LAURELES AGUSTÍN CODAZZI | C17: 1037369385 | D17: 3134473122 | E17: 3138547320 | F17: 3138547320 | G17: CL 25 10A 55,LOS LAURELES | H17: 10.04127909 | I17: -73.23060437 | J17: CESAR | K17: AGUSTÍN CODAZZI | L17: AGUSTÍN CODAZZI | M17: 20013 | N17: 2025-10-20 | O17: =VLOOKUP(A17,Hoja1!A:C,3,0) -> 16 | P17: =VLOOKUP(M17,[1]TIPOLOGIAS_CB!$A:$F,4,0) -> VALLEDUPAR | Q17: =VLOOKUP(P17,'BASE TARIFA 2025'!C:D,2,0) -> WOMPI COSTA | R17: =VLOOKUP(P17,'BASE TARIFA 2025'!C:F,4,0) -> 28277.1
A18: 79176 | B18: BARRIO SAN VICENTE AGUSTIN CODAZZI | C18: 1019038961 | D18: 3112107629 | E18: 3112107629 | G18: CL 16 7 A 81 BRR SAN VICENTE FRENTE AL MEGACOLEGIO,SAN VICENTE | H18: 10.0366189 | I18: -73.2281743 | J18: CESAR | K18: AGUSTÍN CODAZZI | L18: AGUSTÍN CODAZZI | M18: 20013 | N18: 2025-10-20 | O18: =VLOOKUP(A18,Hoja1!A:C,3,0) -> 8 | P18: =VLOOKUP(M18,[1]TIPOLOGIAS_CB!$A:$F,4,0) -> VALLEDUPAR | Q18: =VLOOKUP(P18,'BASE TARIFA 2025'!C:D,2,0) -> WOMPI COSTA | R18: =VLOOKUP(P18,'BASE TARIFA 2025'!C:F,4,0) -> 28277.1
A19: 78147 | B19: BARRIO EL CARMEN AGUSTIN CODAZZI 1 | C19: 15207169 | D19: 3206849190 | E19: 3138054270 | F19: 3206849190 | G19: CR 2 CL 8-37 CGT DE CASACARA,EL CARMEN | H19: 9.83297781 | I19: -73.26544097 | J19: CESAR | K19: AGUSTÍN CODAZZI | L19: AGUSTÍN CODAZZI | M19: 20013 | N19: 2025-10-20 | O19: =VLOOKUP(A19,Hoja1!A:C,3,0) -> 8 | P19: =VLOOKUP(M19,[1]TIPOLOGIAS_CB!$A:$F,4,0) -> VALLEDUPAR | Q19: =VLOOKUP(P19,'BASE TARIFA 2025'!C:D,2,0) -> WOMPI COSTA | R19: =VLOOKUP(P19,'BASE TARIFA 2025'!C:F,4,0) -> 28277.1
A20: 23981 | B20: BARRIO INSPECCIÓN SAN ANTONIO - ANAPOIMA | C20: 178740 | D20: 3113377 | E20: 3166265023 | F20: 3166265023 | G20: CL 2 0 39 | H20: 4.54834744 | I20: -74.53531745 | J20: CUNDINAMARCA | K20: ANAPOIMA | L20: ANAPOIMA | M20: 25035 | N20: 2025-10-29 | O20: =VLOOKUP(A20,Hoja1!A:C,3,0) -> 8 | P20: =VLOOKUP(M20,[1]TIPOLOGIAS_CB!$A:$F,4,0) -> BOGOTA | Q20: =VLOOKUP(P20,'BASE TARIFA 2025'!C:D,2,0) -> WOMPI CENTRO | R20: =VLOOKUP(P20,'BASE TARIFA 2025'!C:F,4,0) -> 15709.5
A21: 61831 | B21: BARRIO SAN JOSE ANAPOIMA | C21: 1072963209 | D21: 0 | E21: 3105832113 | F21: 3105832113 | G21: CL 4 SUR 2 - 25 BRR SAN JOSE | H21: 4.546282 | I21: -74.537522 | J21: CUNDINAMARCA | K21: ANAPOIMA | L21: ANAPOIMA | M21: 25035 | N21: 2025-10-29 | O21: =VLOOKUP(A21,Hoja1!A:C,3,0) -> 8 | P21: =VLOOKUP(M21,[1]TIPOLOGIAS_CB!$A:$F,4,0) -> BOGOTA | Q21: =VLOOKUP(P21,'BASE TARIFA 2025'!C:D,2,0) -> WOMPI CENTRO | R21: =VLOOKUP(P21,'BASE TARIFA 2025'!C:F,4,0) -> 15709.5
A22: 64899 | B22: BARRIO CENTRO ANAPOIMA | C22: 179625 | D22: 3104857101 | E22: 3212072633 | F22: 3104857101 | G22: CR 5 2 42,CENTRO | H22: 4.5506814 | I22: -74.5370481 | J22: CUNDINAMARCA | K22: ANAPOIMA | L22: ANAPOIMA | M22: 25035 | N22: 2025-10-29 | O22: =VLOOKUP(A22,Hoja1!A:C,3,0) -> 8 | P22: =VLOOKUP(M22,[1]TIPOLOGIAS_CB!$A:$F,4,0) -> BOGOTA | Q22: =VLOOKUP(P22,'BASE TARIFA 2025'!C:D,2,0) -> WOMPI CENTRO | R22: =VLOOKUP(P22,'BASE TARIFA 2025'!C:F,4,0) -> 15709.5
A23: 79593 | B23: BARRIO CENTRO ANAPOIMA ANAPOIMA | C23: 1072421882 | D23: 3103092748 | E23: 3143987547 | F23: 3103092748 | G23: CR 4 4 34 CENTRO LC 3,CENTRO ANAPOIMA | H23: 4.5511976 | I23: -74.5358795 | J23: CUNDINAMARCA | K23: ANAPOIMA | L23: ANAPOIMA | M23: 25035 | N23: 2025-10-29 | O23: =VLOOKUP(A23,Hoja1!A:C,3,0) -> 8 | P23: =VLOOKUP(M23,[1]TIPOLOGIAS_CB!$A:$F,4,0) -> BOGOTA | Q23: =VLOOKUP(P23,'BASE TARIFA 2025'!C:D,2,0) -> WOMPI CENTRO | R23: =VLOOKUP(P23,'BASE TARIFA 2025'!C:F,4,0) -> 15709.5
A24: 25026 | B24: BARRIO LA FLORIDA - ANOLAIMA | C24: 2956676 | D24: 7917958 | E24: 3125207038 | F24: 3227175040 | G24: CARRERA 3 N 2 64 | H24: 4.7722716 | I24: -74.4327333 | J24: CUNDINAMARCA | K24: ANOLAIMA | L24: ANOLAIMA | M24: 25040 | N24: 2025-10-22 | O24: =VLOOKUP(A24,Hoja1!A:C,3,0) -> 8 | P24: =VLOOKUP(M24,[1]TIPOLOGIAS_CB!$A:$F,4,0) -> BOGOTA | Q24: =VLOOKUP(P24,'BASE TARIFA 2025'!C:D,2,0) -> WOMPI CENTRO | R24: =VLOOKUP(P24,'BASE TARIFA 2025'!C:F,4,0) -> 15709.5
A25: 24659 | B25: BARRIO CENTRO - ANOLAIMA | C25: 20371142 | E25: 3102528191 | F25: 3102528191 | G25: CR 5 2 49 | H25: 4.7618002 | I25: -74.4643374 | J25: CUNDINAMARCA | K25: ANOLAIMA | L25: ANOLAIMA | M25: 25040 | N25: 2025-10-21 | O25: =VLOOKUP(A25,Hoja1!A:C,3,0) -> 8 | P25: =VLOOKUP(M25,[1]TIPOLOGIAS_CB!$A:$F,4,0) -> BOGOTA | Q25: =VLOOKUP(P25,'BASE TARIFA 2025'!C:D,2,0) -> WOMPI CENTRO | R25: =VLOOKUP(P25,'BASE TARIFA 2025'!C:F,4,0) -> 15709.5
A26: 50472 | B26: BARRIO ANOLAIMA ANOLAIMA | C26: 1068929088 | D26: 0 | E26: 3102406542 | F26: 3134389229 | G26: CL 6 3 15 B SAN VICENTE,ANOLAIMA | H26: 4.76050633 | I26: -74.466162 | J26: CUNDINAMARCA | K26: ANOLAIMA | L26: ANOLAIMA | M26: 25040 | N26: 2025-10-21 | O26: =VLOOKUP(A26,Hoja1!A:C,3,0) -> 8 | P26: =VLOOKUP(M26,[1]TIPOLOGIAS_CB!$A:$F,4,0) -> BOGOTA | Q26: =VLOOKUP(P26,'BASE TARIFA 2025'!C:D,2,0) -> WOMPI CENTRO | R26: =VLOOKUP(P26,'BASE TARIFA 2025'!C:F,4,0) -> 15709.5
A27: 52972 | B27: BARRIO CENTRO POBLADO REDENTORES ANOLAIMA | C27: 1068927112 | D27: 1111111 | E27: 3143248816 | F27: 3143248816 | G27: CARRERA 1 2 - 12 CENTRO POBLADO REDENTORES , | H27: 4.806786 | I27: -74.494767 | J27: CUNDINAMARCA | K27: ANOLAIMA | L27: ANOLAIMA | M27: 25040 | N27: 2025-10-21 | O27: =VLOOKUP(A27,Hoja1!A:C,3,0) -> 8 | P27: =VLOOKUP(M27,[1]TIPOLOGIAS_CB!$A:$F,4,0) -> BOGOTA | Q27: =VLOOKUP(P27,'BASE TARIFA 2025'!C:D,2,0) -> WOMPI CENTRO | R27: =VLOOKUP(P27,'BASE TARIFA 2025'!C:F,4,0) -> 15709.5
A28: 59691 | B28: BARRIO CENTRO ANOLAIMA 1 | C28: 1071549590 | D28: 0 | E28: 3184412533 | F28: 3184412533 | G28: CR 5 4 75 | H28: 4.7605148 | I28: -74.4650747 | J28: CUNDINAMARCA | K28: ANOLAIMA | L28: ANOLAIMA | M28: 25040 | N28: 2025-10-21 | O28: =VLOOKUP(A28,Hoja1!A:C,3,0) -> 8 | P28: =VLOOKUP(M28,[1]TIPOLOGIAS_CB!$A:$F,4,0) -> BOGOTA | Q28: =VLOOKUP(P28,'BASE TARIFA 2025'!C:D,2,0) -> WOMPI CENTRO | R28: =VLOOKUP(P28,'BASE TARIFA 2025'!C:F,4,0) -> 15709.5
A29: 68730 | B29: SANTANDER ANOLAIMA | C29: 20371157 | D29: 3125687479 | E29: 3125687479 | F29: 3125687479 | G29: CR 5 1 A 22 BRR SANTANDER.SANTANDER | H29: 4.7624000 | I29: -74.4640210 | J29: CUNDINAMARCA | K29: ANOLAIMA | L29: ANOLAIMA | M29: 25040 | N29: 2025-10-22 | O29: =VLOOKUP(A29,Hoja1!A:C,3,0) -> 8 | P29: =VLOOKUP(M29,[1]TIPOLOGIAS_CB!$A:$F,4,0) -> BOGOTA | Q29: =VLOOKUP(P29,'BASE TARIFA 2025'!C:D,2,0) -> WOMPI CENTRO | R29: =VLOOKUP(P29,'BASE TARIFA 2025'!C:F,4,0) -> 15709.5
A30: 77795 | B30: BARRIO VRD RINCON SANTO CAJICA | C30: 52665811 | D30: 3014751724 | E30: 3014751724 | F30: 3112845456 | G30: CL 22A 1B - 98.VRD RINCON SANTO | H30: 4.934245 | I30: -74.015613 | J30: CUNDINAMARCA | K30: CAJICÁ | L30: CAJICÁ | M30: 25126 | N30: 2025-10-20 | O30: =VLOOKUP(A30,Hoja1!A:C,3,0) -> 8 | P30: =VLOOKUP(M30,[1]TIPOLOGIAS_CB!$A:$F,4,0) -> BOGOTA | Q30: =VLOOKUP(P30,'BASE TARIFA 2025'!C:D,2,0) -> WOMPI CENTRO | R30: =VLOOKUP(P30,'BASE TARIFA 2025'!C:F,4,0) -> 15709.5
A31: 76713 | B31: BARRIO CAPELLANIA CAJICA 7 | C31: 11275209 | D31: 3229429247 | E31: 3229429247 | F31: 3138650773 | G31: CR 4 3 246,CAPELLANIA | H31: 4.9396277 | I31: -74.0224145 | J31: CUNDINAMARCA | K31: CAJICÁ | L31: CAJICÁ | M31: 25126 | N31: 2025-10-16 | O31: =VLOOKUP(A31,Hoja1!A:C,3,0) -> 8 | P31: =VLOOKUP(M31,[1]TIPOLOGIAS_CB!$A:$F,4,0) -> BOGOTA | Q31: =VLOOKUP(P31,'BASE TARIFA 2025'!C:D,2,0) -> WOMPI CENTRO | R31: =VLOOKUP(P31,'BASE TARIFA 2025'!C:F,4,0) -> 15709.5
A32: 80355 | B32: BARRIO GRAN COLOMBIA CAJICA 1 | C32: 1001289276 | D32: 3155854356 | E32: 3155854356 | G32: CR 1A 7A ESTE 05,GRAN COLOMBIA | H32: 4.9135360 | I32: -74.0181870 | J32: CUNDINAMARCA | K32: CAJICÁ | L32: CAJICÁ | M32: 25126 | N32: 2025-10-20 | O32: =VLOOKUP(A32,Hoja1!A:C,3,0) -> 8 | P32: =VLOOKUP(M32,[1]TIPOLOGIAS_CB!$A:$F,4,0) -> BOGOTA | Q32: =VLOOKUP(P32,'BASE TARIFA 2025'!C:D,2,0) -> WOMPI CENTRO | R32: =VLOOKUP(P32,'BASE TARIFA 2025'!C:F,4,0) -> 15709.5
A33: 62450 | B33: BARRIO EL TEJAR CAJICA 1 | C33: 1074188491 | D33: 3195833415 | E33: 3195833415 | F33: 3195833415 | G33: CR 14 5 10,EL TEJAR | H33: 4.922845 | I33: -74.032923 | J33: CUNDINAMARCA | K33: CAJICÁ | L33: CAJICÁ | M33: 25126 | N33: 2025-10-16 | O33: =VLOOKUP(A33,Hoja1!A:C,3,0) -> 8 | P33: =VLOOKUP(M33,[1]TIPOLOGIAS_CB!$A:$F,4,0) -> BOGOTA | Q33: =VLOOKUP(P33,'BASE TARIFA 2025'!C:D,2,0) -> WOMPI CENTRO | R33: =VLOOKUP(P33,'BASE TARIFA 2025'!C:F,4,0) -> 15709.5
A34: 71891 | B34: CAJICA CENTRO 1 | C34: 1070010215 | D34: 3107561770 | E34: 3107561770 | F34: 3107561770 | G34: CL 5 9 04.CENTRO | H34: 4.9211968 | I34: -74.0288862 | J34: CUNDINAMARCA | K34: CAJICÁ | L34: CAJICÁ | M34: 25126 | N34: 2025-10-10 | O34: =VLOOKUP(A34,Hoja1!A:C,3,0) -> 8 | P34: =VLOOKUP(M34,[1]TIPOLOGIAS_CB!$A:$F,4,0) -> BOGOTA | Q34: =VLOOKUP(P34,'BASE TARIFA 2025'!C:D,2,0) -> WOMPI CENTRO | R34: =VLOOKUP(P34,'BASE TARIFA 2025'!C:F,4,0) -> 15709.5
A35: 74202 | B35: BARRIO EL MISTERIO CAJICÁ | C35: 1026302804 | D35: 3183568255 | E35: 3183568255 | F35: 3183568255 | G35: CR 1 ESTE 11 - 44,EL MISTERIO | H35: 4.9245981 | I35: -74.0206736 | J35: CUNDINAMARCA | K35: CAJICÁ | L35: CAJICÁ | M35: 25126 | N35: 2025-10-16 | O35: =VLOOKUP(A35,Hoja1!A:C,3,0) -> 8 | P35: =VLOOKUP(M35,[1]TIPOLOGIAS_CB!$A:$F,4,0) -> BOGOTA | Q35: =VLOOKUP(P35,'BASE TARIFA 2025'!C:D,2,0) -> WOMPI CENTRO | R35: =VLOOKUP(P35,'BASE TARIFA 2025'!C:F,4,0) -> 15709.5
A36: 74506 | B36: BARRIO AVENIDA CAVALIER CAJICA | C36: 46386203 | D36: 3142764027 | E36: 3142764027 | F36: 3142764027 | G36: CL 3 9 66.AV CAVALIER | H36: 4.9191024 | I36: -74.0301437 | J36: CUNDINAMARCA | K36: CAJICÁ | L36: CAJICÁ | M36: 25126 | N36: 2025-10-10 | O36: =VLOOKUP(A36,Hoja1!A:C,3,0) -> 8 | P36: =VLOOKUP(M36,[1]TIPOLOGIAS_CB!$A:$F,4,0) -> BOGOTA | Q36: =VLOOKUP(P36,'BASE TARIFA 2025'!C:D,2,0) -> WOMPI CENTRO | R36: =VLOOKUP(P36,'BASE TARIFA 2025'!C:F,4,0) -> 15709.5
A37: 57440 | B37: BARRIO ROSIO CAJICA | C37: 1049604411 | D37: 6018664566 | E37: 3172463319 | F37: 3172463319 | G37: CL 7 6 80 | H37: 4.9224814 | I37: -74.0257304 | J37: CUNDINAMARCA | K37: CAJICÁ | L37: CAJICÁ | M37: 25126 | N37: 2025-10-10 | O37: =VLOOKUP(A37,Hoja1!A:C,3,0) -> 16 | P37: =VLOOKUP(M37,[1]TIPOLOGIAS_CB!$A:$F,4,0) -> BOGOTA | Q37: =VLOOKUP(P37,'BASE TARIFA 2025'!C:D,2,0) -> WOMPI CENTRO | R37: =VLOOKUP(P37,'BASE TARIFA 2025'!C:F,4,0) -> 15709.5
A38: 57533 | B38: BARRIO CENTRO CAJICA 6 | C38: 52665591 | D38: 3127052145 | E38: 3127052145 | F38: 3127052145 | G38: CL 6 9A - 114E GRANJITAS | H38: 4.918143 | I38: -74.013866 | J38: CUNDINAMARCA | K38: CAJICÁ | L38: CAJICÁ | M38: 25126 | N38: 2025-10-16 | O38: =VLOOKUP(A38,Hoja1!A:C,3,0) -> 16 | P38: =VLOOKUP(M38,[1]TIPOLOGIAS_CB!$A:$F,4,0) -> BOGOTA | Q38: =VLOOKUP(P38,'BASE TARIFA 2025'!C:D,2,0) -> WOMPI CENTRO | R38: =VLOOKUP(P38,'BASE TARIFA 2025'!C:F,4,0) -> 15709.5
A39: 28143 | B39: BARRIO CENTRO CHOACHI | C39: 80392700 | D39: 8486166 | E39: 3108516383 | F39: 3108516383 | G39: CL 5 2 15 | H39: 4.5301188 | I39: -73.9221893 | J39: CUNDINAMARCA | K39: CHOACHÍ | L39: CHOACHÍ | M39: 25181 | N39: 2025-10-16 | O39: =VLOOKUP(A39,Hoja1!A:C,3,0) -> 8 | P39: =VLOOKUP(M39,[1]TIPOLOGIAS_CB!$A:$F,4,0) -> BOGOTA | Q39: =VLOOKUP(P39,'BASE TARIFA 2025'!C:D,2,0) -> WOMPI CENTRO | R39: =VLOOKUP(P39,'BASE TARIFA 2025'!C:F,4,0) -> 15709.5
A40: 29328 | B40: BARRIO CHOACHI CUNDINAMARCA | C40: 55190017 | D40: 8832853 | E40: 3125065158 | F40: 3125065158 | G40: CL 3 2 13 | H40: 4.5286479 | I40: -73.9219420 | J40: CUNDINAMARCA | K40: CHOACHÍ | L40: CHOACHÍ | M40: 25181 | N40: 2025-10-16 | O40: =VLOOKUP(A40,Hoja1!A:C,3,0) -> 8 | P40: =VLOOKUP(M40,[1]TIPOLOGIAS_CB!$A:$F,4,0) -> BOGOTA | Q40: =VLOOKUP(P40,'BASE TARIFA 2025'!C:D,2,0) -> WOMPI CENTRO | R40: =VLOOKUP(P40,'BASE TARIFA 2025'!C:F,4,0) -> 15709.5
...
