Workbook

Sheet RESUMEN
A1: FACTURACIÓN ACTIVIDADES CORRESPONSAL BANCARIO WOMPI | E1: FACTURACIÓN SERVICIOS ADICIONALES
A2: 1 AL 30 DE OCTUBRE 2025 | E2: 1 AL 30 DE OCTUBRE 2025
A4: CONCEPTOS | B4: CANTIDAD | C4: TOTAL | E4: CONCEPTOS | F4: CANTIDAD | G4: VALOR UNITARIO | H4: TOTAL
A5: Aperturas | B5: =COUNTA(APERTURAS!A:A)-1 -> 150 | C5: =APERTURAS!Y152 -> 74829004 | E5: Acometida de datos (ML)-CB 45522 | F5: 12 | G5: ='TARIFAS 2025'!B18 -> 16235 | H5: =F5*G5 -> 194820
A6: Incidentes | B6: =COUNTA(INCIDENTES!A:A)-1 -> 567 | C6: =INCIDENTES!AA569 -> 41590853
A7: OC Papelería | B7: =COUNTA('OC PAPALERÍA'!A:A)-1 -> 2330 | C7: ='OC PAPALERÍA'!AA2332 -> 78241253
A8: OC Cierres | B8: =COUNTA('OC CIERRES'!A:A)-1 -> 40 | C8: ='OC CIERRES'!AA42 -> 9070672
A9: OC Publicidad | B9: =COUNTA('OC PUBLICIDAD'!A:A)-1 -> 29 | C9: ='OC PUBLICIDAD'!AA31 -> 4765410
A10: OC Traslados | B10: =COUNTA('OC TRASLADOS'!A:A)-1 -> 12 | C10: ='OC TRASLADOS'!AA14 -> 2446663 | H10: =SUM(H5:H9) -> 194820
A11: Servicios Adicionales | C11: =H10 -> 194820
A12: SUBTOTAL | C12: =SUM(C5:C11) -> 211138675
A13: Iva | C13: =C12*0.19 -> 40116348
A14: TOTAL | C14: =SUM(C12:C13) -> 2.5125502e+08

Sheet TD
A1: ACTIVIDAD | B1: APERTURA
A3: DESCRIPCION CENTRO DE COSTOS | B3: Suma de VALOR TOTAL | C3: CENTRO DE COSTOS | D3: VALOR
A4: Wompi Centro | B4: 14539661 | C4: =A4 -> Wompi Centro | D4: =B4 -> 14539661 | H4: CENTRO DE COSTOS | I4: Suma de VALOR
A5: Wompi Costa | B5: 9031931 | C5: =A5 -> Wompi Costa | D5: =B5 -> 9031931 | H5: Wompi Centro | I5: 36483158
A6: Wompi Eje Cafetero | B6: 7686309 | C6: =A6 -> Wompi Eje Cafetero | D6: =B6 -> 7686309 | H6: Wompi Costa | I6: 26943227
A7: Wompi Noroccidente | B7: 5835873 | C7: =A7 -> Wompi Noroccidente | D7: =B7 -> 5835873 | H7: Wompi Eje Cafetero | I7: 15752402
A8: Wompi Oriente | B8: 8678589 | C8: =A8 -> Wompi Oriente | D8: =B8 -> 8678589 | H8: Wompi Noroccidente | I8: 32205102
A9: Wompi Santander | B9: 14025509 | C9: =A9 -> Wompi Santander | D9: =B9 -> 14025509 | H9: Wompi Oriente | I9: 26764391
A10: Wompi Suroccidente | B10: 15031132 | C10: =A10 -> Wompi Suroccidente | D10: =B10 -> 15031132 | H10: Wompi Santander | I10: 34579886
A11: Total general | B11: 74829004 | H11: Wompi Suroccidente | I11: 38215689
H12: Total general | I12: 210943855
A15: ACTIVIDAD | B15: INCIDENTE
A17: DESCRIPCION CENTRO DE COSTOS | B17: Suma de VALOR TOTAL
A18: Wompi Centro | B18: 7149102 | C18: =A18 -> Wompi Centro | D18: =B18 -> 7149102
A19: Wompi Costa | B19: 6553224 | C19: =A19 -> Wompi Costa | D19: =B19 -> 6553224
A20: Wompi Eje Cafetero | B20: 2103611 | C20: =A20 -> Wompi Eje Cafetero | D20: =B20 -> 2103611
A21: Wompi Noroccidente | B21: 5966201 | C21: =A21 -> Wompi Noroccidente | D21: =B21 -> 5966201
A22: Wompi Oriente | B22: 5627328 | C22: =A22 -> Wompi Oriente | D22: =B22 -> 5627328
A23: Wompi Santander | B23: 5997673 | C23: =A23 -> Wompi Santander | D23: =B23 -> 5997673
A24: Wompi Suroccidente | B24: 8193714 | C24: =A24 -> Wompi Suroccidente | D24: =B24 -> 8193714
A25: Total general | B25: 41590853
A29: ACTIVIDAD | B29: ORDEN DE CAMBIO
A30: SOLICITUD | B30: ROLLOS
A32: DESCRIPCION CENTRO DE COSTOS | B32: Suma de VALOR TOTAL
A33: Wompi Centro | B33: 12738595 | C33: =A33 -> Wompi Centro | D33: =B33 -> 12738595
A34: Wompi Costa | B34: 10005932 | C34: =A34 -> Wompi Costa | D34: =B34 -> 10005932
A35: Wompi Eje Cafetero | B35: 5184656 | C35: =A35 -> Wompi Eje Cafetero | D35: =B35 -> 5184656
A36: Wompi Noroccidente | B36: 16237033 | C36: =A36 -> Wompi Noroccidente | D36: =B36 -> 16237033
A37: Wompi Oriente | B37: 9499872 | C37: =A37 -> Wompi Oriente | D37: =B37 -> 9499872
A38: Wompi Santander | B38: 12610038 | C38: =A38 -> Wompi Santander | D38: =B38 -> 12610038
A39: Wompi Suroccidente | B39: 11965127 | C39: =A39 -> Wompi Suroccidente | D39: =B39 -> 11965127
A40: Total general | B40: 78241253
A44: ACTIVIDAD | B44: ORDEN DE CAMBIO
A45: SOLICITUD | B45: CIERRE
A47: DESCRIPCION CENTRO DE COSTOS | B47: Suma de VALOR TOTAL
A48: Wompi Centro | B48: 1362264 | C48: =A48 -> Wompi Centro | D48: =B48 -> 1362264
A49: Wompi Costa | B49: 203532 | C49: =A49 -> Wompi Costa | D49: =B49 -> 203532
A50: Wompi Noroccidente | B50: 2914958 | C50: =A50 -> Wompi Noroccidente | D50: =B50 -> 2914958
A51: Wompi Oriente | B51: 2228348 | C51: =A51 -> Wompi Oriente | D51: =B51 -> 2228348
A52: Wompi Santander | B52: 1636106 | C52: =A52 -> Wompi Santander | D52: =B52 -> 1636106
...

Sheet TARIFAS 2025
A1: TIPO ACTIVIDAD | B1: PRINCIPAL | C1: INTERMEDIA | D1: LEJANA
A2: ENVIO DATAFONO | B2: 39706 | C2: 49474 | D2: 51412
A3: ENVIO VISITA DATAFONO | B3: 59451 | C3: 182458 | D3: 462012
A4: INSTALACIÓN DATAFONO | B4: 130010 | C4: 222882 | D4: 474719
A5: INSTALACIÓN DATAFONO Y MATERIAL POP | B5: 367716 | C5: 488953 | D5: 598334
A6: LOGISTICA INVERSA DATAFONO | B6: 49274 | C6: 188826 | D6: 454487
A7: LOGISTICA INVERSA MATERIAL POP | B7: 95829 | C7: 287147 | D7: 551974
A8: SOPORTE TÉCNICO | B8: 51282 | C8: 172989 | D8: 452148
A9: ORDENES DE CAMBIO_CIERRES DESTRUCCIÓN DE POP EN SITIO | B9: 71290 | C9: 206527 | D9: 602411
A10: ORDENES DE CAMBIO_CIERRES RETORNO DE POP A BODEGA | B10: 101766 | C10: 318400 | D10: 707110
A11: ORDENES DE CAMBIO_PAPELERÍA | B11: 31419 | C11: 36351 | D11: 40250
A12: ORDENES DE CAMBIO_PUBLICIDAD | B12: 95829 | C12: 287147 | D12: 551974
A13: ORDENES DE CAMBIO_OTRAS | B13: 59451 | C13: 182458 | D13: 462012
A14: SOPORTE TELEFÓNICO | B14: 22000 | C14: 22000 | D14: 22000
A16: SERVICIOS ADICIONALES EN SITIO | B16: Estos valores aplican en las actividades que se requieran, previa autorización de Wompi.
A17: Acometida eléctrica 3N12 Cu THHN (ml) | B17: 21000 | C17: 21000 | D17: 21000
A18: Acometida de datos (ML) | B18: 16235 | C18: 16235 | D18: 16235
A19: Switch | B19: 257392 | C19: 257392 | D19: 257392
A20: Router | B20: 306552 | C20: 306552 | D20: 306552

Sheet CENTROS DE COSTOS
A1: CIUDAD | B1: CENTRO_COSTO | C1: DESCRIPCION CENTRO DE COSTOS | D1: COORDINADOR DE ZONA
A2: APARTADO | B2: 0036-0005 | C2: Wompi Noroccidente | D2: JUAN SEBASTIÁN RÍOS CASTRILLÓN
A3: BARRANQUILLA | B3: 0036-0001 | C3: Wompi Costa | D3: JOSE MAURICIO HERNANDEZ ROJAS
A4: BOGOTA | B4: 0036-0004 | C4: Wompi Centro | D4: WILLIAM ASDRUBAL ROZO ROZO
A5: BUCARAMANGA | B5: 0036-0007 | C5: Wompi Santander | D5: MIGUEL JULIÁN HERNÁNDEZ GUARÍN
A6: CALI | B6: 0036-0003 | C6: Wompi Suroccidente | D6: DIEGO FERNANDO HENAO CARDONA
A7: CARTAGENA | B7: 0036-0001 | C7: Wompi Costa | D7: JOSE MAURICIO HERNANDEZ ROJAS
A8: CUCUTA | B8: 0036-0007 | C8: Wompi Santander | D8: MIGUEL JULIÁN HERNÁNDEZ GUARÍN
A9: FLORENCIA | B9: 0036-0006 | C9: Wompi Oriente | D9: KEVIN ALEXIS CORZO BUSTOS
A10: IBAGUE | B10: 0036-0006 | C10: Wompi Oriente | D10: KEVIN ALEXIS CORZO BUSTOS
A11: MANIZALES | B11: 0036-0002 | C11: Wompi Eje Cafetero | D11: DIEGO FERNANDO HENAO CARDONA
A12: MEDELLIN | B12: 0036-0005 | C12: Wompi Noroccidente | D12: JUAN SEBASTIÁN RÍOS CASTRILLÓN
... A23: YOPAL | B23: 0036-0006 | C23: Wompi Oriente | D23: KEVIN ALEXIS CORZO BUSTOS

Sheet TIPOLOGIA
A1: COD. CIUDAD | B1: CIUDAD | C1: DEPARTAMENTO | D1: DESDE DONDE SE ATIENDE | E1: TIPOLOGIA WOMPI | F1: TIPO DE TRAYECTO | G1: BODEGA WOMPI
A2: 91430 | B2: LA VICTORIA | C2: AMAZONAS | D2: BOGOTA | E2: LEJANA | F2: AEREO | G2: BOGOTA
A3: 91669 | B3: PUERTO SANTANDER | C3: AMAZONAS | D3: BOGOTA | E3: LEJANA | F3: AEREO | G3: BOGOTA
A4: 91263 | B4: EL ENCANTO | C4: AMAZONAS | D4: BOGOTA | E4: LEJANA | F4: AEREO | G4: BOGOTA
A5: 91405 | B5: LA CHORRERA | C5: AMAZONAS | D5: BOGOTA | E5: LEJANA | F5: AEREO | G5: BOGOTA
A6: 91407 | B6: LA PEDRERA | C6: AMAZONAS | D6: BOGOTA | E6: LEJANA | F6: AEREO | G6: BOGOTA
A7: 91001 | B7: LETICIA | C7: AMAZONAS | D7: BOGOTA | E7: LEJANA | F7: AEREO | G7: BOGOTA
A8: 91460 | B8: MIRITI - PARANA | C8: AMAZONAS | D8: BOGOTA | E8: LEJANA | F8: AEREO | G8: BOGOTA
A9: 91530 | B9: PUERTO ALEGRIA | C9: AMAZONAS | D9: BOGOTA | E9: LEJANA | F9: AEREO | G9: BOGOTA
A10: 91536 | B10: PUERTO ARICA | C10: AMAZONAS | D10: BOGOTA | E10: LEJANA | F10: AEREO | G10: BOGOTA
A11: 91540 | B11: PUERTO NARIÑO | C11: AMAZONAS | D11: BOGOTA | E11: LEJANA | F11: AEREO | G11: BOGOTA
A12: 91798 | B12: TARAPACA | C12: AMAZONAS | D12: BOGOTA | E12: LEJANA | F12: AEREO | G12: BOGOTA
A13: 5055 | B13: ARGELIA | C13: ANTIOQUIA | D13: MEDELLIN | E13: LEJANA | F13: TERRESTRE | G13: MEDELLIN
... A1124: 23682 | B1124: SAN JOSE DE URE | C1124: CORDOBA | D1124: MONTERIA | E1124: LEJANA | F1124: TERRESTRE | G1124: MONTERIA

Sheet APERTURAS
A1: CIUDAD SEDE | B1: CENTRO_COSTO | C1: DESCRIPCION CENTRO DE COSTOS | D1: CÓDIGO DANE | E1: TA/CODIGO ACTIVIDAD | F1: CODIGO CB | G1: ACTIVIDAD | H1: TIPO DE APERTURA | I1: DEPARTAMENTO | J1: CIUDAD | K1: NOMBRE DEL CB | L1: RED | M1: FO | N1: FECHA LISTA | O1: FECHA ULTIMA ACTUALIZACION | P1: ESTADO | Q1: OBSERVACIONES CLIENTE | R1: FORMA DE ATENCIÓN | S1: TERMINALES | T1: TIPOLOGIA | U1: TIPO DE TRAYECTO | V1: NOMBRE DEL TECNICO | W1: DIAS DE VISITA | X1: VALOR DIAS ACTIVIDAD | Y1: VALOR TOTAL
A2: CALI | B2: =VLOOKUP(A2,'CENTROS DE COSTOS'!A:D,2,0) -> 0036-0003 | C2: =VLOOKUP(A2,'CENTROS DE COSTOS'!A:D,3,0) -> Wompi Suroccidente | D2: 76520 | E2: TA-25-1046221 | F2: 81148 | G2: APERTURA | H2: CB CRECIMIENTO - OTRAS LISTAS | I2: VALLE DEL CAUCA | J2: PALMIRA | K2: BARRIO LA SULTANA PALMIRA | L2: WOMPI | M2: FO-25-1457847 | N2: 45901 | O2: 45939 | P2: EJECUTADO | Q2: 12-09 SE REALIZA LLAMADA AL CLIENTE, SE HABLA CON AURA ELENA BENAVIDES ROJAS EL CUAL INDICA QUE EL CORREO CON LAS CREDENCIALES POR PARTE DE WOMPI AUN NO HA LLEGADO 22-09 SE HABLA CON LA SRA AURA ELENA BENAVIDES ROJAS LA CUAL INDICA QUE AUN NO TIENE EL CORREO 08-10 SE REALIZA LLAMADA AL CLIENTE, SE HABLA CON LA SRA AURA ELENA BENAVIDES ROJAS. SE VALIDA DIRECCIÓN OK, CANAL OK, DISPONIBILIDAD TOTAL, LLAMAR EL DÍA LA INSTALACIÓN PARA CONFIRMAR VISITA, AVISO EXTERIOR ALTURA APROX 2 METROS; CREDENCIALES: NO 9/10/2025 SE REALIZA INSTALACIÓN DE CORRESPONSAL, SE INSTALAN EQUIPOS CON PRUEBAS EXITOSAS, SE CAPACITA Y SE EVALÚA AL CLIENTE, SE INSTALA PUBLICIDAD COMPLETA, CB QUEDA OPERATIVO. USUARIO SOMOS BANCOLOMBIA ACTIVO | R2: VISITA_TÉCNICA | S2: 254MMD4X2530 | T2: PRINCIPAL | U2: TERRESTRE | V2: MONTERO MUESES GIAN CARLO | W2: 1 | X2: =IF(T2="PRINCIPAL",'TARIFAS 2025'!$B$5,IF(T2="INTERMEDIA",'TARIFAS 2025'!$C$5,IF(T2="LEJANA",'TARIFAS 2025'!$D$5))) -> 367716 | Y2: =X2*W2 -> 367716
A3: PEREIRA | B3: =VLOOKUP(A3,'CENTROS DE COSTOS'!A:D,2,0) -> 0036-0002 | C3: =VLOOKUP(A3,'CENTROS DE COSTOS'!A:D,3,0) -> Wompi Eje Cafetero | D3: 66001 | E3: TA-25-1187978 | F3: 81418 | G3: APERTURA | H3: CB CRECIMIENTO - NUEVO | I3: RISARALDA | J3: PEREIRA | K3: BARRIO LOS ANGELES PEREIRA | L3: WOMPI | M3: FO-25-1646754 | N3: 45908 | O3: 45939 | P3: EJECUTADO | Q3: 12-09 SE REALIZA LLAMADA AL CLIENTE, SE HABLA CON LA SRA MARIA MANUELA LARGO SOTO EL CUAL INDICA QUE EL CORREO CON LAS CREDENCIALES POR PARTE DE WOMPI AUN NO HA LLEGADO // 22/09/2025 SE REALIZA LLAMADA AL NUMERO DE LA LISTA SE HABLA CON LA SEÑORA MARIA QUIEN INDICA QUE NO LES HA LLEGADO EL CORREO CON LAS CREDENCIALES, YA BUSCARON EN TODO EL BUZON Y NADA 08-10 SE REALIZA LLAMADA AL CLIENTE, SE HABLA CON LA SRA MARIA MANUELA LARGO SOTO. SE VALIDA DIRECCIÓN OK, CANAL OK, DISPONIBILIDAD TOTAL, LLAMAR EL DÍA LA INSTALACIÓN PARA CONFIRMAR VISITA, AVISO EXTERIOR ALTURA APROX 1 METROS; CREDENCIALES: SI 9/10/2025 SE REALIZA INSTALACIÓN DE CORRESPONSAL, SE INSTALAN EQUIPOS CON PRUEBAS EXITOSAS, SE CAPACITA Y SE EVALÚA AL CLIENTE, SE INSTALA PUBLICIDAD COMPLETA, CB QUEDA OPERATIVO. USUARIO SOMOS BANCOLOMBIA ACTIVO | R3: VISITA_TÉCNICA | S3: 254MMD4X0196 | T3: PRINCIPAL | U3: TERRESTRE | V3: ARROYAVE CANO MANUEL GUILLERMO | W3: 1 | X3: =IF(T3="PRINCIPAL",'TARIFAS 2025'!$B$5,IF(T3="INTERMEDIA",'TARIFAS 2025'!$C$5,IF(T3="LEJANA",'TARIFAS 2025'!$D$5))) -> 367716 | Y3: =X3*W3 -> 367716
A4: BOGOTA | B4: =VLOOKUP(A4,'CENTROS DE COSTOS'!A:D,2,0) -> 0036-0004 | C4: =VLOOKUP(A4,'CENTROS DE COSTOS'!A:D,3,0) -> Wompi Centro | D4: 25843 | E4: TA-25-1100744 | F4: 81453 | G4: APERTURA | H4: CB CRECIMIENTO - NUEVO | I4: CUNDINAMARCA | J4: VILLA DE SAN DIEGO DE UBATE | K4: BARRIO JUAN JOSE NEIRA VILLA DE SAN DIEGO DE UBATE 5 | L4: WOMPI | M4: FO-25-1668980 | N4: 45908 | O4: 45960 | P4: EJECUTADO | Q4: 12-09 SE REALIZA LLAMADA AL CLIENTE, SE HABLA CON LA SR JHON FERNANDO GONZALEZ LANCHEROS SE VALIDA DIRECCIÓN OK, CANAL OK, DISPONIBILIDAD TOTAL, USUARIO Y CONTRASEÑA WOMPI OK, LLAMAR EL DÍA LA INSTALACIÓN PARA CONFIRMAR VISITA, AVISO EXTERIOR ALTURA APROX 2 METROS 16-09 SE VISITA COMERCIO, EN EL SITIO EL CLIENTE NOS MANIFIESTA QUE NO LE HA LLEGADO EL CORREO DE WOMPI PARA HABILITAR LAS CREDENCIALES, POR LO QUE SE ESCALA AL COORDINADOR DANDO LOS DATOS DEL CLIENTE JUNTO CON EL CORREO PERO TAMBIÉN SE EVIDENCIA YA EN EL EQUIPO QUE EL CORREO QUE TOMARON AL PARECER POR PARTE DE WOMPI ESTÁ MAL (CORREO CORRECTO: GONZALEZJOHN046@GMAIL.COM) (CORREO ERRADO: GONZALEZJHONN04@GMAIL.COM), SE ESCALA PARA QUE SE RESUELVA EL DATO PERO INDICAN TIEMPO DE RESPUESTA DE 1 A 3 DÍAS HÁBILES POR LO QUE SE ESPERARA RESPUESTA DEL ÁREA ENCARGADA Y SE REPROGRAMADA ACTIVIDAD. 19-09 EL DÍA DE HOY LLEGA CORREO CON LA SIGUIENTE RESPUESTA: "CASO N° 465292, CON ASUNTO CORREO SATURADO DEL COMERCIO, NO TIENE LAS CREDENCIALES HA SIDO SOLUCIONADO" EN COMUNICACIÓN CON EL COMERCIO, MANIFIESTA NO LE HA LLEGADO CORREO CON LA INFORMACIÓN 08-10 SE REALIZA LLAMADA AL CLIENTE, SE HABLA CON LA SRA NELLY OPAYOME. SE VALIDA DIRECCIÓN OK, CANAL OK, DISPONIBILIDAD TOTAL, LLAMAR EL DÍA LA INSTALACIÓN PARA CONFIRMAR VISITA, AVISO EXTERIOR ALTURA APROX 2 METROS; CREDENCIALES: NO 10-10 RESUMEN DEL CASO: SE REALIZA APERTURA WOMPI DONDE AL LLEGAR AL COMERCIO CLIENTE CONFIRMA NO HA RECIBIDO CORREO DE COMPLETA TU REGISTRO AL VALIDAR EL CORREO REGISTRADO EN EL DATÁFONO REGISTRA GONZALEZJHONN04@GMAIL.COM Y EL CORREO CORRECTO ES GONZALEZJOHN046@GMAIL.COM POR LO QUE NO LLEGA EL CORREO DE ACTIVACION EN CREDENCIALES SERIAL: 254UMX3181 TICKET N° (471570), | EN NUEVA COMUNICACIÓN CON EL USUARIO INDICA QUE YA TIENE EL CORREO POR PARTE DE WOMPI, ALTURA DEL AVISO 2 MT | 30/10/2025 SE REALIZA INSTALACIÓN DE CORRESPONSAL, SE INSTALAN EQUIPOS CON PRUEBAS EXITOSAS, SE CAPACITA Y SE EVALÚA AL CLIENTE, SE INSTALA PUBLICIDAD COMPLETA, CB QUEDA OPERATIVO. USUARIO SOMOS BANCOLOMBIA ACTIVO | R4: VISITA_TÉCNICA | S4: 254MMD4X3181 | T4: INTERMEDIA | U4: TERRESTRE | V4: ROMERO ROJAS BREIDY JHOHAN | W4: 3 | X4: =IF(T4="PRINCIPAL",'TARIFAS 2025'!$B$5,IF(T4="INTERMEDIA",'TARIFAS 2025'!$C$5,IF(T4="LEJANA",'TARIFAS 2025'!$D$5))) -> 488953 | Y4: =X4*W4 -> 1466859
A5: MONTERIA | B5: =VLOOKUP(A5,'CENTROS DE COSTOS'!A:D,2,0) -> 0036-0001 | C5: =VLOOKUP(A5,'CENTROS DE COSTOS'!A:D,3,0) -> Wompi Costa | D5: 23670 | E5: TA-25-1100787 | F5: 81431 | G5: APERTURA | H5: CB CRECIMIENTO - NUEVO | I5: CORDOBA | J5: SAN ANDRES SOTAVENTO | K5: BARRIO BOCA CANOA SAN ANDRES DE SOTAVENTO | L5: WOMPI | M5: FO-25-1554843 | N5: 45908 | O5: 45940 | P5: EJECUTADO | Q5: 12-09 SE REALIZA LLAMADA AL CLIENTE, SE HABLA CON LA SRA DIANA RAMIREZ HOYOS SE VALIDA DIRECCIÓN OK, CANAL OK, DISPONIBILIDAD TOTAL, USUARIO Y CONTRASEÑA WOMPI OK, LLAMAR EL DÍA LA INSTALACIÓN PARA CONFIRMAR VISITA, AVISO EXTERIOR ALTURA APROX 3.5 METROS - COMUNICACIÓN POR WPP 16/09/2025 SE VISITA COMERCIO PERO NO ES POSIBLE REALIZAR LA INSTALACIÓN, SE CREAN CREDENCIALES, SE INGRESA A LA APLICACIÓN CON EL USUARIO PERO NO MUESTRA EL MENÚ TRANSACCIONAL EN EL EQUIPO, SE HACE ESCALAMIENTO MEDIANTE AL TICKET N° (465381), DESPUÉS DE 40 MINUTOS NO TUVIMOS RESPUESTA, POR LO QUE EL COORDINADOR NOS INDICA QUE NOS PODEMOS RETIRAR DEL SITIO. 08-10 SE SE PROGRAMA ACTIVIDAD POR SOLICITUD DE WOMPI, INDICAN QUE YA ESTA TODO LISTO PARA CONFIGURAR EL EQUIPO 10-10 SE REALIZA INSTALACIÓN DE CORRESPONSAL, SE INSTALAN EQUIPOS CON PRUEBAS EXITOSAS, SE CAPACITA Y SE EVALÚA AL CLIENTE, SE INSTALA PUBLICIDAD COMPLETA, CB QUEDA OPERATIVO. USUARIO SOMOS BANCOLOMBIA ACTIVO | R5: VISITA_TÉCNICA | S5: 254UMD4X8138 | T5: INTERMEDIA | U5: TERRESTRE | V5: CACERES HERNANDEZ ANDRES | W5: 2 | X5: =IF(T5="PRINCIPAL",'TARIFAS 2025'!$B$5,IF(T5="INTERMEDIA",'TARIFAS 2025'!$C$5,IF(T5="LEJANA",'TARIFAS 2025'!$D$5))) -> 488953 | Y5: =X5*W5 -> 977906
A6: NEIVA | B6: =VLOOKUP(A6,'CENTROS DE COSTOS'!A:D,2,0) -> 0036-0006 | C6: =VLOOKUP(A6,'CENTROS DE COSTOS'!A:D,3,0) -> Wompi Oriente | D6: 41001 | E6: TA-25-1187980 | F6: 81412 | G6: APERTURA | H6: CB CRECIMIENTO - NUEVO | I6: HUILA | J6: NEIVA | K6: BARRIO LA GAITANA NEIVA 1 | L6: WOMPI | M6: FO-25-1659812 | N6: 45908 | O6: 45960 | P6: EJECUTADO | Q6: 12-09 SE REALIZA LLAMADA AL CLIENTE, SE HABLA CON LA SRA DANIELA RUBIANO VASQUEZ LA CUAL INDICA QUE NO PUEDE VERIFICAR LOS DATOS POR QUE SE ENCUNTRA OCUPADA Y QUE ELLA NO HA RECIBIDO HASTA AHORA NINGUN CORREO - COMUNICACIÓN POR WPP // 22/09/2025 SE REALIZA LLAMADA AL NUMERO DE LA LISTA SE HABLA CON EL ESPOSO DE LA SEÑORA DANIELA QUIEN INDICA QUE EL CORREO CON EL QUE HICIERON LA SOLICITUD TIENE NOVEDAD, SOLICITA QUE LE CAMBIEN EL CORREO PARA PODER RECIBIR LA APERTURA (rubivadani@gmail.com) 08-10 SE SE PROGRAMA ACTIVIDAD POR SOLICITUD DE WOMPI, INDICAN QUE YA ESTA TODO LISTO PARA CONFIGURAR EL EQUIPO 9/10/2025 SE VISTA EL CB PARA IMPLEMENTACIÓN, PERO EL USUARIO INDICA QUE EL CORREO REGISTRADO LO PERDIÓ, POR LO QUE NO FUE POSIBLE ACCEDER Y ACTIVAR LAS CREDENCIALES, EL USUARIO INDICA QUE EL CORREO QUE TIENE ACTUALMENTE ES RUBIVADANI@GMAIL.COM. | 28/10/2025 EN NUEVA COMUNIACIÓN CON LA USUARIA POR WPP INDICA QUE YA TIENE EL CORREO POR PARTE DE WOMPI - COMUNICACIÓN POR WPP | 30-10 SE REALIZA INSTALACIÓN DE CORRESPONSAL, SE INSTALAN EQUIPOS CON PRUEBAS EXITOSAS, SE CAPACITA Y SE EVALÚA AL CLIENTE, SE INSTALA PUBLICIDAD COMPLETA, CB QUEDA OPERATIVO. USUARIO SOMOS BANCOLOMBIA ACTIVO | R6: VISITA_TÉCNICA | S6: 254UMD4X6246 | T6: PRINCIPAL | U6: TERRESTRE | V6: DEVIA REINOSO JUAN CARLOS | W6: 2 | X6: =IF(T6="PRINCIPAL",'TARIFAS 2025'!$B$5,IF(T6="INTERMEDIA",'TARIFAS 2025'!$C$5,IF(T6="LEJANA",'TARIFAS 2025'!$D$5))) -> 367716 | Y6: =X6*W6 -> 735432
A7: BUCARAMANGA | B7: =VLOOKUP(A7,'CENTROS DE COSTOS'!A:D,2,0) -> 0036-0007 | C7: =VLOOKUP(A7,'CENTROS DE COSTOS'!A:D,3,0) -> Wompi Santander | D7: 68001 | E7: TA-25-1187982 | F7: 81380 | G7: APERTURA | H7: CB CRECIMIENTO - NUEVO | I7: SANTANDER | J7: BUCARAMANGA | K7: BARRIO SAN FRANCISCO BUCARAMANGA 20 | L7: WOMPI | M7: FO-25-1646760 | N7: 45908 | O7: 45961 | P7: EJECUTADO | Q7: 12-09 SE REALIZA LLAMADA AL CLIENTE, SE HABLA CON LA SRA LENIS DAYANA DURAN FARFAN LA CUAL INIDCA QUE EL CORREO ESTA ERRADO, EL CORREO CORRECTO ES lenis120417@gmail.com 22-09 SE REALIZA LLAMADA AL CLIENTE, SE HABLA CON LA SRA LENIS DAYANA DURAN FARFAN LA CUAL INDICA QUE NO TIENE EL CORREO POR PARTE DE WOMPI 08-10 SE REALIZA CONTACTO POR WPP CON LA SRA LENIS DAYANA DURAN FARFAN. SE VALIDA DIRECCIÓN OK, CANAL OK, DISPONIBILIDAD TOTAL, LLAMAR EL DÍA LA INSTALACIÓN PARA CONFIRMAR VISITA, AVISO EXTERIOR ALTURA APROX 2.5 METROS; CREDENCIALES: SI 09/10/2025 RESUMEN DEL CASO: CLIENTE INDICA QUE NO LE HA LLEGADO CORREO CON LAS CREDENCIALES INFORMA QUE EL CORREO NO ES EL CORRECTO CORREO EXACTO ES LENIS120417@GMAIL.COM SE REALIZAN PRUEBAS A DICHO CORREO EXITOSAS SE INTENTA REGISTRO A WOMPI POR MEDIO DEL LINK Y NO DEJA ESCRIBIR SERIAL: 254MMD4W8890 TICKET N° (471140), | 28-10 EN NUEVA COMUNICACIÓN CON EL USUARIO INDICA QUE YA TIENE EL CORREO DE WOMPI, ALTURA DEL AVISO 3.5 MT | 31/10/2025 SE REALIZA INSTALACIÓN DE CORRESPONSAL, SE INSTALAN EQUIPOS CON PRUEBAS EXITOSAS, SE CAPACITA Y SE EVALÚA AL CLIENTE, SE INSTALA PUBLICIDAD COMPLETA, CB QUEDA OPERATIVO. USUARIO SOMOS BANCOLOMBIA ACTIVO | R7: VISITA_TÉCNICA | S7: 254MMD4W8890 | T7: PRINCIPAL | U7: TERRESTRE | V7: MARIÑO PABON JORGE ENRIQUE | W7: 1 | X7: =IF(T7="PRINCIPAL",'TARIFAS 2025'!$B$5,IF(T7="INTERMEDIA",'TARIFAS 2025'!$C$5,IF(T7="LEJANA",'TARIFAS 2025'!$D$5))) -> 367716 | Y7: =X7*W7 -> 367716
A8: BOGOTA | B8: =VLOOKUP(A8,'CENTROS DE COSTOS'!A:D,2,0) -> 0036-0004 | C8: =VLOOKUP(A8,'CENTROS DE COSTOS'!A:D,3,0) -> Wompi Centro | D8: 11001 | E8: TA-25-1100805 | F8: 81375 | G8: APERTURA | H8: CB CRECIMIENTO - NUEVO | I8: CUNDINAMARCA | J8: BOGOTA | K8: BARRIO EL TROPEZON BOGOTA 1 | L8: WOMPI | M8: FO-25-1554883 | N8: 45908 | O8: 45939 | P8: EJECUTADO | Q8: 12-09 SE REALIZA LLAMDA AL CLIENTE, SE HABLA CON EL SR ISAAC KAMILO VALERA MORENO DIRECCIÓN OK, CANAL OK, DISPONIBILIDAD TOTAL, USUARIO Y CONTRASEÑA WOMPI OK, LLAMAR EL DÍA LA INSTALACIÓN PARA CONFIRMAR VISITA, AVISO EXTERIOR ALTURA APROX 2 METROS 16/09/2025 SE REALIZA CIERRE DE VISITA YA QUE NO HAN LLEGADO CORREO DE CREDENCIALES INDICA QUE LO RECIBIO PERO ELIMINO UNOS CORREOS Y NO SE DIO CUENTA. SE ESCALA CASO A COORDINADOR WILLIAM ROZO QUIEN AUTORIZA TICKET 465275 19-09 EL DÍA DE HOY LLEGA CORREO CON LA SIGUIENTE RESPUESTA: "SU CASO N° 465275, CON ASUNTO COMERCIO INFORMA NO LE LLEGARON LAS CREDENCIALES HA SIDO SOLUCIONADO" DE ACUERDO CON LA VALIDACIÓN CON EL COMERCIO, INFORMA NO LE HA LLEGADO INFORMACIÓN COMO LO DICE EL CORREO, ACTIVIDAD SIGUE PENDIENTE 08-10 SE REALIZA LLAMADA AL CLIENTE, SE HABLA CON EL SR ISAAC KAMILO VALERA MORENO. SE VALIDA DIRECCIÓN OK, CANAL OK, DISPONIBILIDAD TOTAL, LLAMAR EL DÍA LA INSTALACIÓN PARA CONFIRMAR VISITA, AVISO EXTERIOR ALTURA APROX 2.5 METROS; CREDENCIALES: NO 9/10/2025 SE REALIZA INSTALACIÓN DE CORRESPONSAL, SE INSTALAN EQUIPOS CON PRUEBAS EXITOSAS, SE CAPACITA Y SE EVALÚA AL CLIENTE, SE INSTALA PUBLICIDAD COMPLETA, CB QUEDA OPERATIVO. USUARIO SOMOS BANCOLOMBIA NO ACTIVO , SE CAPACITA CON EL DE PRUEBA | R8: VISITA_TÉCNICA | S8: 254MMD4X3304 | T8: PRINCIPAL | U8: TERRESTRE | V8: HERNANDEZ NARANJO OSCAR EDUARDO | W8: 2 | X8: =IF(T8="PRINCIPAL",'TARIFAS 2025'!$B$5,IF(T8="INTERMEDIA",'TARIFAS 2025'!$C$5,IF(T8="LEJANA",'TARIFAS 2025'!$D$5))) -> 367716 | Y8: =X8*W8 -> 735432
A9: VILLAVICENCIO | B9: =VLOOKUP(A9,'CENTROS DE COSTOS'!A:D,2,0) -> 0036-0006 | C9: =VLOOKUP(A9,'CENTROS DE COSTOS'!A:D,3,0) -> Wompi Oriente | D9: 50568 | E9: TA-25-1187984 | F9: 81424 | G9: APERTURA | H9: CB CRECIMIENTO - NUEVO | I9: META | J9: PUERTO GAITAN | K9: BARRIO ALTOS DEL MANACACIAS PUERTO GAITAN | L9: WOMPI | M9: FO-25-1646763 | N9: 45908 | O9: 45940 | P9: EJECUTADO | Q9: 12-09 EN COMUNICACIÓN VIA WHATSAPP, SE HABLA CON LA SRA YINEHT SELENA BARRERA MURCIA SE VALIDA DIRECCIÓN OK, CANAL OK, DISPONIBILIDAD TOTAL, USUARIO Y CONTRASEÑA WOMPI NO LE HA LLEGADO, INDICA QUE EL CORREO QUE SE ENCUENTRA EN LA LISTA DE CHEQUEO ESTÁ ERRADO, SU CORREO Selenabm18@gmail.com // 22/09/2025 SE REALIZA LLAMADA AL NUMERO DE LA LISTA SE HABLA CON LA SEÑORA SELENA SOLICITA QUE LE CAMBIEN EL CORREO (Selenabm18@gmail.com), EL OTRO ESTA ERRADO 08-10 SE REALIZA LLAMADA AL CLIENTE, SE HABLA CON LA SRA YINEHT SELENA BARRERA MURCIA SE VALIDA DIRECCIÓN OK, CANAL OK, DISPONIBILIDAD TOTAL 10/10/2025 SE REALIZA INSTALACIÓN DE CORRESPONSAL, SE INSTALAN EQUIPOS CON PRUEBAS EXITOSAS, SE CAPACITA Y SE EVALÚA AL CLIENTE, SE INSTALA PUBLICIDAD COMPLETA, CB QUEDA OPERATIVO. USUARIO SOMOS BANCOLOMBIA ACTIVO. COMERCIO SIN AVISO PUBLICITARIO, SIN EMBARGO SI ES EL MISMO OBJETIVO COMERCIAL, LA DIRECCION COINCIDE Y LA CÁMARA DE COMERCIO TAMBIEN TIENE EL MISMO NOMBRE DE LISTA DE CHEQUEO. | R9: VISITA_TÉCNICA | S9: 254UMD4X8310 | T9: LEJANA | U9: TERRESTRE | V9: ROZO JIMENEZ EDGAR ARMANDO | W9: 1 | X9: =IF(T9="PRINCIPAL",'TARIFAS 2025'!$B$5,IF(T9="INTERMEDIA",'TARIFAS 2025'!$C$5,IF(T9="LEJANA",'TARIFAS 2025'!$D$5))) -> 598334 | Y9: =X9*W9 -> 598334
A10: MONTERIA | B10: =VLOOKUP(A10,'CENTROS DE COSTOS'!A:D,2,0) -> 0036-0001 | C10: =VLOOKUP(A10,'CENTROS DE COSTOS'!A:D,3,0) -> Wompi Costa | D10: 23001 | E10: TA-25-1187986 | F10: 81410 | G10: APERTURA | H10: CB CRECIMIENTO - NUEVO | I10: CORDOBA | J10: MONTERIA | K10: BARRIO CENTRO MONTERIA 61 | L10: WOMPI | M10: FO-25-1646765 | N10: 45908 | O10: 45939 | P10: EJECUTADO | Q10: 12-09 SE REALIZA LLAMADA AL CLIENTE, SE HABLA CON EL SR JAMIS JABID MARTINEZ ORTEGA SE VALIDA DIRECCIÓN OK, CANAL OK, DISPONIBILIDAD TOTAL, USUARIO Y CONTRASEÑA WOMPI NO LE HA LLEGADO-INSTALACIÓN SIN PROGRAMAR // 22/09/2025 SE REALIZA LLAMADA AL NUMERO DE LA LISTA SE HABLA CON EL SEÑOR JAMIS, SE LE CONFIRMA EL CORREO INDICA ESTAR BIEN, SE PREGUNTA POR CORREO DE WOMPI ME DICE QUE NO LE HA LLEGADO, HACE BUSQUEDA POR EL BUSCADOR Y ME SIGUE INDICANDO QUE NO LO TIENEN EN NINGUNA BANDEJA DE MENSAJES 08-10 SE REALIZA LLAMADA AL CLIENTE, SE HABLA CON LA SR JAMIS JABID MARTINEZ ORTEGA SE VALIDA DIRECCIÓN OK, CANAL OK, DISPONIBILIDAD TOTAL, YA TIENE CORREO CON CREDENCIALES 9/10/2025 SE REALIZA INSTALACIÓN DE CORRESPONSAL, SE INSTALAN EQUIPOS CON PRUEBAS EXITOSAS, SE CAPACITA Y SE EVALÚA AL CLIENTE, SE INSTALA PUBLICIDAD COMPLETA, CB QUEDA OPERATIVO. USUARIO SOMOS BANCOLOMBIA NO ACTIVO, SE CAPACITA CON EL DE PRUEBA | R10: VISITA_TÉCNICA | S10: 254UMD4X8492 | T10: PRINCIPAL | U10: TERRESTRE | V10: COGOLLO VERTEL EDER LUIS | W10: 1 | X10: =IF(T10="PRINCIPAL",'TARIFAS 2025'!$B$5,IF(T10="INTERMEDIA",'TARIFAS 2025'!$C$5,IF(T10="LEJANA",'TARIFAS 2025'!$D$5))) -> 367716 | Y10: =X10*W10 -> 367716
A11: BUCARAMANGA | B11: =VLOOKUP(A11,'CENTROS DE COSTOS'!A:D,2,0) -> 0036-0007 | C11: =VLOOKUP(A11,'CENTROS DE COSTOS'!A:D,3,0) -> Wompi Santander | D11: 68092 | E11: TA-25-1100984 | F11: 81369 | G11: APERTURA | H11: CB CRECIMIENTO - NUEVO | I11: SANTANDER | J11: BETULIA | K11: SAN BERNARDO BETULIA | L11: WOMPI | M11: FO-25-1554914 | N11: 45908 | O11: 45940 | P11: EJECUTADO | Q11: 12-09 EN COMUNICACIÓN VIA WHATSAPP, SE HABLA CON LA SRA PAULA ANDREA GARCIA CRUZSE VALIDA DIRECCIÓN OK, CANAL OK, DISPONIBILIDAD TOTAL, USUARIO Y CONTRASEÑA WOMPI OK, LLAMAR EL DÍA LA INSTALACIÓN PARA CONFIRMAR VISITA, AVISO EXTERIOR ALTURA APROX 2.5 METROS 17/09/2025 SE LLEGA AL SITIO Y SE REALIZA EL PROCESO DE IDENTIFICACIÓN. SE ACCEDE CORRECTAMENTE AL CORREO ELECTRÓNICO DEL USUARIO. SE GENERA EL LINK PARA LA ACTIVACIÓN DEL CORRESPONSAL. AL MOMENTO DE INGRESAR AL ENLACE, LA APLICACIÓN NO PERMITE MODIFICAR NI DIGITAR LOS SIGUIENTES CAMPOS: NOMBRE DE USUARIO, CORREO ELECTRÓNICO, WHATSAPP. ACCIONES REALIZADAS: SE EJECUTA BORRADO DE CACHÉ DE LA APLICACIÓN WOMPI. SE REALIZA LA ACTUALIZACIÓN DE LA APLICACIÓN A LA ÚLTIMA VERSIÓN DISPONIBLE. SE LOGRA EL CAMBIO DE CONTRASEÑA CORRECTAMENTE. SIN EMBARGO, AL INTENTAR COMPLETAR LA ACTIVACIÓN, LA APP MUESTRA EL SIGUIENTE MENSAJE DE ERROR: "¡UPS! ALGO SALIÓ MAL". EL PROCESO NO SE PUEDE COMPLETAR DEBIDO A UN POSIBLE FALLO EN LA PLATAFORMA O CONFLICTO CON LA APP, PESE A QUE LOS PASOS ANTERIORES SE EJECUTARON CORRECTAMENTE. ESCALAR EL CASO AL SOPORTE TÉCNICO DE WOMPI PARA SU REVISIÓN Y SOLUCIÓN. 08-10 SE REALIZA LLAMADA AL CLIENTE, SE HABLA CON LA SRA PAULA ANDREA GARCIA CRUZ ORTEGA SE VALIDA DIRECCIÓN OK, CANAL OK, DISPONIBILIDAD TOTAL, YA TIENE CORREO CON CREDENCIALES 09-10 SE COMUNICA CON LA SEÑORITA CON LA SEÑORITA PAULA AL NÚMERO DE TELÉFONO 3138266161 , SE CONFIRMA QUE LA USUARIA CUENTA CON LAS CREDENCIALES WOMPI, SE VALIDA EN OFICINA CON COORDINADOR Y SI DEJA INGRESAR, SE PROCEDE A REALIZAR LA APERTURA EN BETULIA 10-10 SE REALIZA INSTALACIÓN DE CORRESPONSAL, SE INSTALAN EQUIPOS CON PRUEBAS EXITOSAS, SE CAPACITA Y SE EVALÚA AL CLIENTE, SE INSTALA PUBLICIDAD COMPLETA, CB QUEDA OPERATIVO. USUARIO SOMOS BANCOLOMBIA ACTIVO | R11: VISITA_TÉCNICA | S11: 254MMD4W8945 | T11: LEJANA | U11: TERRESTRE | V11: HERRERA LUQUE SAUL JAVIER | W11: 1 | X11: =IF(T11="PRINCIPAL",'TARIFAS 2025'!$B$5,IF(T11="INTERMEDIA",'TARIFAS 2025'!$C$5,IF(T11="LEJANA",'TARIFAS 2025'!$D$5))) -> 598334 | Y11: =X11*W11 -> 598334
A12: TUNJA | B12: =VLOOKUP(A12,'CENTROS DE COSTOS'!A:D,2,0) -> 0036-0007 | C12: =VLOOKUP(A12,'CENTROS DE COSTOS'!A:D,3,0) -> Wompi Santander | D12: 15001 | E12: TA-25-1187992 | F12: 81446 | G12: APERTURA | H12: CB CRECIMIENTO - NUEVO | I12: BOYACA | J12: TUNJA | K12: BARRIO SAN CARLOS TUNJA 3 | L12: WOMPI | M12: FO-25-1646768 | N12: 45908 | O12: 45961 | P12: EJECUTADO/CANCELADO | Q12: 12-09 SE REALIZA LLAMADA AL CLIENTE, SE HABLA CON LA SRA JENNY ANGELICA MORENO CALDAS SE VALIDA DIRECCIÓN OK, CANAL OK, DISPONIBILIDAD TOTAL, USUARIO Y CONTRASEÑA WOMPI NO LE HA LLEGADO-INSTALACIÓN SIN PROGRAMAR 22-09 SE REALIZA LLAMADA AL CLIENTE, SE HABLA CON LA SRA JENNY ANGELICA MORENO CALDAS LA CUAL INDICA EL CORREO CORRECTO ES angelicamoreno83@hotmail.com NO TIENE ACCESO AL OTRO CORREO 08-10 SE REALIZA LLAMADA AL CLIENTE, SE HABLA CON LA SRA JENNY ANGELICA MORENO CALDAS SE VALIDA DIRECCIÓN OK, CANAL OK, DISPONIBILIDAD TOTAL, CORREO ESTA ERRADO 09-10 RESUMEN DEL CASO: CLIENTE INFORMA QUE EL CORREO DE LA ACTIVIDAD DEBE SER ANGELICAMORENO83@HOTMAIL.COM, YA QUE EL OTRO CORREO NO LE SIRVE. ACTUALIZAR CORREO A ANGELICAMORENO83@HOTMAIL.COM SERIAL: 254MMD4W7987 TICKET N° (471147) | 28/10/2025 EN NUEVA COMUNICACIÓN CON LA USUARIA INDICA QUE YA TIENE EL CORREO POR PARTE DE WOMPI, NO IDNICA ALTURA DEL AVISO | 31/10/2025 VISITAMOS EL SITIO Y VERIFICAMOS QUE LA DIRECCIÓN REGISTRADA EN LA ORDEN CORRESPONDE A CL 6 SUR #7–09, SAN CARLOS, LA MISMA QUE FIGURA EN LA CÁMARA DE COMERCIO. SIN EMBARGO, AL VALIDAR LA NOMENCLATURA DIRECTAMENTE EN EL SITIO, SE EVIDENCIA QUE LA DIRECCIÓN CORRECTA ES CL 6 SUR #9–07. SE CANCELA ACTIVIDAD POR DIRECCION ERRADA | R12: VISITA_TÉCNICA | S12: 254MMD4W7987 | T12: PRINCIPAL | U12: TERRESTRE | V12: HERRERA GARZON JEYSON STEVENT | W12: 1 | X12: =IF(T12="PRINCIPAL",'TARIFAS 2025'!$B$5,IF(T12="INTERMEDIA",'TARIFAS 2025'!$C$5,IF(T12="LEJANA",'TARIFAS 2025'!$D$5))) -> 367716 | Y12: =X12*W12 -> 367716
A13: BOGOTA | B13: =VLOOKUP(A13,'CENTROS DE COSTOS'!A:D,2,0) -> 0036-0004 | C13: =VLOOKUP(A13,'CENTROS DE COSTOS'!A:D,3,0) -> Wompi Centro | D13: 11001 | E13: TA-25-1187994 | F13: 81373 | G13: APERTURA | H13: CB CRECIMIENTO - NUEVO | I13: CUNDINAMARCA | J13: BOGOTA | K13: BARRIO NUEVA MARSELLA BOGOTA 3 | L13: WOMPI | M13: FO-25-1646770 | N13: 45908 | O13: 45939 | P13: EJECUTADO | Q13: 12-09 SE REALIZA LLAMADA AL CLIENTE, SE HABLA CON LA SRA BETTY YAJAIRA GRAZZIANI HERNANDEZ SE VALIDA DIRECCIÓN OK, CANAL OK, DISPONIBILIDAD TOTAL, USUARIO Y CONTRASEÑA WOMPI NO LE HA LLEGADO-INSTALACIÓN SIN PROGRAMAR 22-09 SE REALIZA LLAMADA AL CLIENTE, SE HABLA CON LA SRA BETTY YAJAIRA GRAZZIANI HERNANDEZ LA CUAL INDICA QUE AUN NO TIENE EL CORREO DE PARTE DE WOMPI 08-10 SE REALIZA LLAMADA AL CLIENTE, SE HABLA CON LA SRA BETTY YAJAIRA GRAZZIANI HERNANDEZ SE VALIDA DIRECCIÓN OK, CANAL OK, DISPONIBILIDAD TOTAL 9/10/2025 SE REALIZA INSTALACIÓN DE CORRESPONSAL, SE INSTALAN EQUIPOS CON PRUEBAS EXITOSAS, SE CAPACITA Y SE EVALÚA AL CLIENTE, SE INSTALA PUBLICIDAD COMPLETA, CB QUEDA OPERATIVO. USUARIO SOMOS BANCOLOMBIA ACTIVO. COMERCIO SIN AVISO COMERCIAL | R13: VISITA_TÉCNICA | S13: 254UMD4X6466 | T13: PRINCIPAL | U13: TERRESTRE | V13: HERNANDEZ NARANJO OSCAR EDUARDO | W13: 1 | X13: =IF(T13="PRINCIPAL",'TARIFAS 2025'!$B$5,IF(T13="INTERMEDIA",'TARIFAS 2025'!$C$5,IF(T13="LEJANA",'TARIFAS 2025'!$D$5))) -> 367716 | Y13: =X13*W13 -> 367716
... A151: TUNJA | B151: =VLOOKUP(A151,'CENTROS DE COSTOS'!A:D,2,0) -> 0036-0007 | C151: =VLOOKUP(A151,'CENTROS DE COSTOS'!A:D,3,0) -> Wompi Santander | D151: 15599 | E151: TA-25-1246673 | F151: 81595 | G151: APERTURA | H151: CB CRECIMIENTO - OTRAS LISTAS | I151: BOYACA | J151: RAMIRIQUI | K151: BARRIO CENTRO RAMIRIQUI 3 | L151: WOMPI | M151: FO-25-1748452 | N151: 45952 | O151: 45960 | P151: EJECUTADO | Q151: 23/10/2025 SE ESTABLECE COMUNICACIÓN CON FARIDES RASEDA PÉREZ VIA WPP, EL CUAL INDICA QUE EL CORREO ESTA BIEN PERO NO LE HA LLEGADO CORREO PARA COMPLETAR REGISTRO POR PARTE DE WOMPI // 28-10 SE REALIZA CONTACTO POR WHATSAPP AL CLIENTE, SE HABLA CON EL SR FARIDES RASEDA PÉREZ SE VALIDA DIRECCIÓN OK, CANAL OK, DISPONIBILIDAD TOTAL, USUARIO Y CONTRASEÑA WOMPI OK, LLAMAR EL DÍA LA INSTALACIÓN PARA CONFIRMAR VISITA, AVISO EXTERIOR ALTURA APROX 2 METROS | 30/10/2025 SE REALIZA INSTALACIÓN DE CORRESPONSAL, SE INSTALAN EQUIPOS CON PRUEBAS EXITOSAS, SE CAPACITA Y SE EVALÚA AL CLIENTE, SE INSTALA PUBLICIDAD COMPLETA, CB QUEDA OPERATIVO. USUARIO SOMOS BANCOLOMBIA ACTIVO | R151: VISITA_TÉCNICA | S151: 254MMD4W8952 | T151: INTERMEDIA | U151: TERRESTRE | V151: RODRIGUEZ MURCIA YERSON IVAN | W151: 1 | X151: =IF(T151="PRINCIPAL",'TARIFAS 2025'!$B$5,IF(T151="INTERMEDIA",'TARIFAS 2025'!$C$5,IF(T151="LEJANA",'TARIFAS 2025'!$D$5))) -> 488953 | Y151: =X151*W151 -> 488953
Y152: =SUM(Y2:Y151) -> 74829004

Sheet INCIDENTES
A1: CIUDAD SEDE | B1: CENTRO_COSTO | C1: DESCRIPCION CENTRO DE COSTOS | D1: CÓDIGO DANE | E1: TA/CODIGO ACTIVIDAD | F1: CODIGO CB | G1: ACTIVIDAD | H1: DEPARTAMENTO | I1: CIUDAD | J1: NOMBRE DEL CB | K1: RED | L1: FO | M1: FECHA ASIGNACION A LINEA COMUNICACIONES | N1: FECHA DEL CIERRE DEL TICKET (DD/MM/AAAA) | O1: SOLICITUD | P1: GRUPO_FALLA | Q1: CATEGORÍA | R1: FALLA | S1: OBSERVACION | T1: FORMA DE ATENCIÓN | U1: INVENTARIO ACTUAL DE ROLLOS | V1: TIPOLOGIA | W1: TIPO DE TRAYECTO | X1: NOMBRE DEL TECNICO | Y1: DIAS DE ACTIVIDAD | Z1: VALOR DIAS ACTIVIDAD | AA1: VALOR TOTAL
A2: MEDELLIN | B2: =VLOOKUP(A2,'CENTROS DE COSTOS'!A:D,2,0) -> 0036-0005 | C2: =VLOOKUP(A2,'CENTROS DE COSTOS'!A:D,3,0) -> Wompi Noroccidente | D2: 5088 | E2: 2777957 | F2: 21427 | G2: INCIDENTE | H2: ANTIOQUIA | I2: BELLO | J2: JHOMAR | K2: WOMPI | L2: FO-25-1573859 | FO-25-1568169 | M2: 45923.333 | N2: 45931.358 | O2: INCIDENTE | P2: LECTURA | Q2: NO LEE NINGUNA FACTURA | R2: SUCIEDAD EN LA CAMARA | S2: 23/09/2025 SE EVIDENCIA QUE EL EQUIPO NO LEE FACTURAS EPM NI DEL FONDO NACIONAL DEL AHORRO, OTRAS SI, DATÁFONO ACTUALIZADO, SE ESCALA A WOMPI CON TICKET 467172. 01/10/2025 ELECTRÓNICO. JESUS DAVID JUVINAO PEREZ (WOMPI COLOMBIA) 30 SEPT 2025, 8:58 A. M. GMT-5 HOLA BROLIN, ¿CÓMO ESTÁS? QUIERO COMENTARTE QUE JUNTO CON EL EQUIPO HEMOS REVISADO EN DETALLE LA SITUACIÓN QUE NOS REPORTASTE Y, TRAS EL ANÁLISIS, IDENTIFICAMOS EL PROBLEMA. ACTUALMENTE YA SE ESTÁ TRABAJANDO EN UNA SOLUCIÓN DEFINITIVA, NO SOLO PARA ESTE CASO PUNTUAL, SINO TAMBIÉN PARA OTROS INCONVENIENTES RELACIONADOS CON EL FUNCIONAMIENTO DEL LECTOR DE CÓDIGOS DE BARRAS. MIENTRAS TANTO, COMO MEDIDA TEMPORAL Y RÁPIDA, LES RECOMENDAMOS REINICIAR EL DATÁFONO ANTES DE REALIZAR CADA LECTURA. ESTO PERMITE LIBERAR MEMORIA Y EVITAR QUE SE GENERE RUIDO EN LA CAPTURA DE LA IMAGEN, LO CUAL PUEDE PROVOCAR QUE EL ESCANEO SE VEA BORROSO O NO SE LEA CORRECTAMENTE. TAMBIÉN ES IMPORTANTE ASEGURARSE DE CONTAR CON UNA BUENA ILUMINACIÓN AL MOMENTO DE ES | T2: VISITA_TÉCNICA | U2: 40 | V2: PRINCIPAL | W2: TERRESTRE | X2: CARDONA MOLINA BROLIN STIVEN | Y2: 2 | Z2: =IF(T2="SOPORTE_TELEFÓNICO",'TARIFAS 2025'!$B$14,IF(V2="PRINCIPAL",'TARIFAS 2025'!$B$8,IF(V2="INTERMEDIA",'TARIFAS 2025'!$C$8,IF(V2="LEJANA",'TARIFAS 2025'!$D$8)))) -> 51282 | AA2: =Z2*Y2 -> 102564
A3: BUCARAMANGA | B3: =VLOOKUP(A3,'CENTROS DE COSTOS'!A:D,2,0) -> 0036-0007 | C3: =VLOOKUP(A3,'CENTROS DE COSTOS'!A:D,3,0) -> Wompi Santander | D3: 68001 | E3: 2814842 | F3: 74106 | G3: INCIDENTE | H3: SANTANDER | I3: BUCARAMANGA | J3: BARRIO REAL DE MINAS BUCARAMANGA 3 | K3: WOMPI | L3: FO-25-1604069 | M3: 45930.453 | N3: 45931.36 | O3: INCIDENTE | P3: CREDENCIALES DE ACCESO (USUARIO/CONTRASEÑA) | Q3: INGRESO DE CREDENCIALES ERRADAS | R3: EL USUARIO NO RECUERDA LA CONTRASEÑA O EL USUARIO | S3: 01/10/2025 EN COMUNICACIÓN TELEFÓNICA AL NÚMERO 3187878933 SE ESTABLECE COMUNICACIÓN CON LA SEÑORA MILENA JIMÉNEZ LO CUAL NOS INDICA QUE NO ES NECESARIO REALIZAR LA VISITA TÉCNICA DEBIDO A QUE YA ESTÁ FUNCIONANDO CORRECTAMENTE EL DATAFONO INDICA QUE LLAMO A LA LÍNEA PARA CANCELAR LA VISITA TÉCNICA | T3: SOPORTE_TELEFÓNICO | U3: 32 | V3: PRINCIPAL | W3: TERRESTRE | X3: MARIÑO PABON JORGE ENRIQUE | Y3: 1 | Z3: =IF(T3="SOPORTE_TELEFÓNICO",'TARIFAS 2025'!$B$14,IF(V3="PRINCIPAL",'TARIFAS 2025'!$B$8,IF(V3="INTERMEDIA",'TARIFAS 2025'!$C$8,IF(V3="LEJANA",'TARIFAS 2025'!$D$8)))) -> 22000 | AA3: =Z3*Y3 -> 22000
A4: PEREIRA | B4: =VLOOKUP(A4,'CENTROS DE COSTOS'!A:D,2,0) -> 0036-0002 | C4: =VLOOKUP(A4,'CENTROS DE COSTOS'!A:D,3,0) -> Wompi Eje Cafetero | D4: 66001 | E4: 2801979 | F4: 64295 | G4: INCIDENTE | H4: RISARALDA | I4: PEREIRA | J4: DISTRIBUIDORA SAN MIGUEL O | K4: WOMPI | L4: FO-25-1593834 | FO-25-1591064 | M4: 45927.375 | N4: 45931.365 | O4: INCIDENTE | P4: NAVEGACION LENTA | Q4: USUARIO NO PUEDE NAVEGAR ENTRE PANTALLAS O LA APP NO ABRE SE QUEDA CARGANDO | R4: CACHE | S4: 27/09/2025 SE LLEGA AL PUNTO, SE REPROGRAMA ACTIVIDAD YA QUE TOCA ESCALARLO CON WOMPI , SE EVIDENCIA QUE EL EQUIPO TRABAJA LENTO YA SEA CONECTADO CON EL WIFI DEL PUNTO O CON LA RED COMPARTIDA DEL TELÉFONO PERSONAL, SE REALIZA TRX DEPÓSITO Y EN SOMOS SALE COMO SI SE HUBIERA REALIZADO DOS VECES LA MISMA TRANSACCIÓN, SE PRUEBA UN RETIRO DE NEQUI Y EN EL DATÁFONO SALE RECHAZO, PERO AL REVISAR EN SOMOS SALE APROBADO. 01/10/2025 EN COMUNICACIÓN CON LA SR SE LE INDICA QUE WOMPI DICE QUE EL PROBLEMA NO ES DEL EQUIPO, NI DEL CANAL DE INTERNET DEL COMERCIO, EL PROBLEMA ES DEL APLICATIVO DE WOMPI Y QUE SE DEBE ESPERAR A LA ACTUALIZACIÓN DE LA APP | T4: VISITA_TÉCNICA | U4: 40 | V4: PRINCIPAL | W4: TERRESTRE | X4: FRANCO CAÑAVERAL YAMID RAUL | Y4: 2 | Z4: =IF(T4="SOPORTE_TELEFÓNICO",'TARIFAS 2025'!$B$14,IF(V4="PRINCIPAL",'TARIFAS 2025'!$B$8,IF(V4="INTERMEDIA",'TARIFAS 2025'!$C$8,IF(V4="LEJANA",'TARIFAS 2025'!$D$8)))) -> 51282 | AA4: =Z4*Y4 -> 102564
A5: CALI | B5: =VLOOKUP(A5,'CENTROS DE COSTOS'!A:D,2,0) -> 0036-0003 | C5: =VLOOKUP(A5,'CENTROS DE COSTOS'!A:D,3,0) -> Wompi Suroccidente | D5: 76001 | E5: 2815169 | F5: 78269 | G5: INCIDENTE | H5: VALLE DEL CAUCA | I5: CALI | J5: H.J IMPRESORES | K5: WOMPI | L5: FO-25-1604472 | M5: 45930.482 | N5: 45931.397 | O5: INCIDENTE | P5: CONEXIÓN | Q5: CONEXIÓN DEFICIENTE WIFI | R5: WIFI | S5: 01/10/2025 SE LLEGA AL COMERCIO CLIENTE ME MUESTRA VIDEOS DE QUE EL EQUIPO DURO 5 MINUTOS EN SACAR TIRILLA SE REVISA EL EQUIPO Y SE HACEN PRUEBAS TIRILLA SALE A LOS 5 SEGUNDO SE LE EXPLICA AL CLIENTE QUE PODRÍA SER QUE EN ESE MOMENTO EL INTERNET ESTABA LENTO QUEDA FUNCIONANDO CORRECTAMENTE | T5: VISITA_TÉCNICA | U5: 32 | V5: PRINCIPAL | W5: TERRESTRE | X5: CUERO RUIZ JHONNY | Y5: 1 | Z5: =IF(T5="SOPORTE_TELEFÓNICO",'TARIFAS 2025'!$B$14,IF(V5="PRINCIPAL",'TARIFAS 2025'!$B$8,IF(V5="INTERMEDIA",'TARIFAS 2025'!$C$8,IF(V5="LEJANA",'TARIFAS 2025'!$D$8)))) -> 51282 | AA5: =Z5*Y5 -> 51282
A6: VILLAVICENCIO | B6: =VLOOKUP(A6,'CENTROS DE COSTOS'!A:D,2,0) -> 0036-0006 | C6: =VLOOKUP(A6,'CENTROS DE COSTOS'!A:D,3,0) -> Wompi Oriente | D6: 50001 | E6: 2814599 | F6: 58407 | G6: INCIDENTE | H6: META | I6: VILLAVICENCIO | J6: MECELL | K6: WOMPI | L6: FO-25-1604081 | M6: 45930.446 | N6: 45931.401 | O6: INCIDENTE | P6: CONEXIÓN | Q6: CONEXIÓN DEFICIENTE WIFI | R6: WIFI | S6: 01/10/2025 SE REALIZA VISITA A COMERCIO SE REALIZA ACTUALIZACIÓN DE SISTEMA OPERATIVO SE REALIZA BORRADO DE CACHÉ SE LE BRINDA ASESORÍA TÉCNICA A CLIENTE SOBRE EL CORRECTO USO DEL DATÁFONO | T6: VISITA_TÉCNICA | U6: 64 | V6: PRINCIPAL | W6: TERRESTRE | X6: CASTRILLON URREA LONDIER LEANDRO | Y6: 1 | Z6: =IF(T6="SOPORTE_TELEFÓNICO",'TARIFAS 2025'!$B$14,IF(V6="PRINCIPAL",'TARIFAS 2025'!$B$8,IF(V6="INTERMEDIA",'TARIFAS 2025'!$C$8,IF(V6="LEJANA",'TARIFAS 2025'!$D$8)))) -> 51282 | AA6: =Z6*Y6 -> 51282
A7: NEIVA | B7: =VLOOKUP(A7,'CENTROS DE COSTOS'!A:D,2,0) -> 0036-0006 | C7: =VLOOKUP(A7,'CENTROS DE COSTOS'!A:D,3,0) -> Wompi Oriente | D7: 41001 | E7: TA-25-1160168 | F7: 62389 | G7: INCIDENTE | H7: HUILA | I7: NEIVA | J7: FOTOCOPIAS HELIO'S | K7: WOMPI | L7: FO-25-1602438 | M7: 45925.674 | N7: 45931.422 | O7: INCIDENTE | P7: SOFTWARE | Q7: APP ELIMINADA | R7: APP ELIMINADA POR EL CB | S7: 01/10/2025 SE REALIZA CAMBIO DE QUIPO POR AUTORIZACION DE WOMPI | T7: VISITA_TÉCNICA | U7: 24 | V7: PRINCIPAL | W7: TERRESTRE | X7: DIAZ VARGAS JONATHAN MIGUEL | Y7: 1 | Z7: =IF(T7="SOPORTE_TELEFÓNICO",'TARIFAS 2025'!$B$14,IF(V7="PRINCIPAL",'TARIFAS 2025'!$B$8,IF(V7="INTERMEDIA",'TARIFAS 2025'!$C$8,IF(V7="LEJANA",'TARIFAS 2025'!$D$8)))) -> 51282 | AA7: =Z7*Y7 -> 51282
A8: CUCUTA | B8: =VLOOKUP(A8,'CENTROS DE COSTOS'!A:D,2,0) -> 0036-0007 | C8: =VLOOKUP(A8,'CENTROS DE COSTOS'!A:D,3,0) -> Wompi Santander | D8: 54001 | E8: 2798806 | F8: 67824 | G8: INCIDENTE | H8: NORTE DE SANTANDER | I8: CUCUTA | J8: TECNICELL CASI TODO | K8: WOMPI | L8: FO-25-1591907 | FO-25-1588202 | M8: 45926.431 | N8: 45931.448 | O8: INCIDENTE | P8: IMPRESIÓN | Q8: DAÑO FÍSICO DE LA IMPRESORA | R8: MALA MANIPULACIÓN DEL DATAFONO | S8: 26/09/2025 INCIDENTE CB: 67824 RESUMEN DEL CASO: REPORTE TÉCNICO RESUMEN DE ACTIVIDAD: SE REALIZÓ ACTUALIZACIÓN DE VERSIÓN DEL SISTEMA OK SE PROCEDIÓ CON EL BORRADO DE CACHÉ DEL DISPOSITIVO. SE CONECTÓ EL EQUIPO A DATOS MÓVILES. SE EFECTUARON PRUEBAS FUNCIONALES EXITOSAS (CONECTIVIDAD, MENÚS, OPERACIONES, ETC.). INCIDENCIA DETECTADA: AL MOMENTO DE ENVIAR LA IMPRESIÓN DEL RECIBO, EL EQUIPO SE REINICIÓ INESPERADAMENTE. SE REALIZARON PRUEBAS CON VARIOS ROLLOS DE PAPEL TÉRMICO. CLIENTE INDICA QUE EL EQUIPO DEJÓ DE IMPRIMIR COMPLETAMENTE. AL INTENTAR IMPRIMIR NUEVAMENTE, LA IMPRESIÓN SALE EN BLANCO (ROLLO AVANZA PERO NO IMPRIME CONTENIDO). ? GESTIÓN REALIZADA: SE BRINDÓ ASISTENCIA TELEFÓNICA AL CLIENTE PARA PRUEBAS Y VERIFICACIÓN DE FALLAS. SIN EXITO SE REALIZÓ VISITA TÉCNICA PRESENCIAL EN ESTA GESTIÓN. . SERIAL: 254MMD4W8169 TICKET 468198 01/10/2025 SE REALIZA CAMBIO DE DATAFONO POR DAÑO EN LA IMPRESORA, PRUEBAS OK | T8: VISITA_TÉCNICA | U8: 32 | V8: PRINCIPAL | W8: TERRESTRE | X8: DURAN ACOSTA FRANK YONNY | Y8: 2 | Z8: =IF(T8="SOPORTE_TELEFÓNICO",'TARIFAS 2025'!$B$14,IF(V8="PRINCIPAL",'TARIFAS 2025'!$B$8,IF(V8="INTERMEDIA",'TARIFAS 2025'!$C$8,IF(V8="LEJANA",'TARIFAS 2025'!$D$8)))) -> 51282 | AA8: =Z8*Y8 -> 102564
A9: MEDELLIN | B9: =VLOOKUP(A9,'CENTROS DE COSTOS'!A:D,2,0) -> 0036-0005 | C9: =VLOOKUP(A9,'CENTROS DE COSTOS'!A:D,3,0) -> Wompi Noroccidente | D9: 5001 | E9: 2818691 | F9: 27011 | G9: INCIDENTE | H9: ANTIOQUIA | I9: MEDELLÍN | J9: MERCADO UNION 2 | K9: WOMPI | L9: FO-25-1608433 | M9: 45931.333 | N9: 45931.453 | O9: INCIDENTE | P9: NAVEGACION LENTA | Q9: USUARIO NO PUEDE NAVEGAR ENTRE PANTALLAS O LA APP NO ABRE SE QUEDA CARGANDO | R9: CACHE | S9: 01/10/2025 ANTES EL DATÁFONO ESTABA CON EL SISTEMA LENTO Y NO DEJABA INGRESAR EL USUARIO, APARTIR DE HOY AUNQUE SIGUE LENTO FUNCIONA CORRECTAMENTE. | T9: VISITA_TÉCNICA | U9: 32 | V9: PRINCIPAL | W9: TERRESTRE | X9: HENAO JARAMILLO JUAN JOSE | Y9: 1 | Z9: =IF(T9="SOPORTE_TELEFÓNICO",'TARIFAS 2025'!$B$14,IF(V9="PRINCIPAL",'TARIFAS 2025'!$B$8,IF(V9="INTERMEDIA",'TARIFAS 2025'!$C$8,IF(V9="LEJANA",'TARIFAS 2025'!$D$8)))) -> 51282 | AA9: =Z9*Y9 -> 51282
A10: MEDELLIN | B10: =VLOOKUP(A10,'CENTROS DE COSTOS'!A:D,2,0) -> 0036-0005 | C10: =VLOOKUP(A10,'CENTROS DE COSTOS'!A:D,3,0) -> Wompi Noroccidente | D10: 5088 | E10: 2818710 | F10: 74187 | G10: INCIDENTE | H10: ANTIOQUIA | I10: BELLO | J10: DOCTORFARMA NORTE | K10: WOMPI | L10: FO-25-1608456 | M10: 45931.333 | N10: 45931.456 | O10: INCIDENTE | P10: NAVEGACION LENTA | Q10: USUARIO NO PUEDE NAVEGAR ENTRE PANTALLAS O LA APP NO ABRE SE QUEDA CARGANDO | R10: CACHE | S10: 01/10/2025 SE REALIZA ACTUALIZACIÓN Y BORRADO DE CACHÉ YA QUE INFORMABA QUE NO LE DABA AYER EL ACCESO A LA APLICACIÓN, ADICIONAL EN OCASIONES BUSCA NÚMERO DE CONVENIO DE EPM Y NO SALE, PERO TODO YA ESTÁ FUNCIONANDO CORRECTAMENTE. | T10: VISITA_TÉCNICA | U10: 48 | V10: PRINCIPAL | W10: TERRESTRE | X10: RAMIREZ TABARES JUAN DIEGO | Y10: 1 | Z10: =IF(T10="SOPORTE_TELEFÓNICO",'TARIFAS 2025'!$B$14,IF(V10="PRINCIPAL",'TARIFAS 2025'!$B$8,IF(V10="INTERMEDIA",'TARIFAS 2025'!$C$8,IF(V10="LEJANA",'TARIFAS 2025'!$D$8)))) -> 51282 | AA10: =Z10*Y10 -> 51282
A11: CALI | B11: =VLOOKUP(A11,'CENTROS DE COSTOS'!A:D,2,0) -> 0036-0003 | C11: =VLOOKUP(A11,'CENTROS DE COSTOS'!A:D,3,0) -> Wompi Suroccidente | D11: 76001 | E11: 2817239 | F11: 64018 | G11: INCIDENTE | H11: VALLE DEL CAUCA | I11: CALI | J11: ESTILO LIBRE PELUQUERIA UNISEX | K11: WOMPI | L11: FO-25-1606542 | M11: 45930.644 | N11: 45931.458 | O11: INCIDENTE | P11: IMPRESIÓN | Q11: ROLLO MAL PUESTO | R11: MALA MANIPULACIÓN DEL DATAFONO | S11: 01/10/2025 SE LLEGA AL COMERCIO CLIENTE INDICA QUE TIENE QUE CORTAR EL RECIBO CON TIJERAS YA QUE EL BAUCHER QUEDA ATASCADO SE LE EXPLICA LA MANERA CORRECTA DE CORTAR LA TIRILLA HACE PRUEVAS Y QUEDA OK SE LE EXPLICA COMO SE DEBE DE PONER EL EQUIPO PARA QUE LEA LOS CODIGOS DE BARRAS HACE PRUEBAS QUEDA OK EL DATAFONO QUEDA FUNCIONANDO CORRECTAMENTE | T11: VISITA_TÉCNICA | U11: 24 | V11: PRINCIPAL | W11: TERRESTRE | X11: CUERO RUIZ JHONNY | Y11: 1 | Z11: =IF(T11="SOPORTE_TELEFÓNICO",'TARIFAS 2025'!$B$14,IF(V11="PRINCIPAL",'TARIFAS 2025'!$B$8,IF(V11="INTERMEDIA",'TARIFAS 2025'!$C$8,IF(V11="LEJANA",'TARIFAS 2025'!$D$8)))) -> 51282 | AA11: =Z11*Y11 -> 51282
A12: BOGOTA | B12: =VLOOKUP(A12,'CENTROS DE COSTOS'!A:D,2,0) -> 0036-0004 | C12: =VLOOKUP(A12,'CENTROS DE COSTOS'!A:D,3,0) -> Wompi Centro | D12: 11001 | E12: 2817195 | F12: 59897 | G12: INCIDENTE | H12: CUNDINAMARCA | I12: BOGOTÁ | J12: DROGUERIA SU SALUD PRIMERO | K12: WOMPI | L12: FO-25-1606282 | M12: 45930.644 | N12: 45931.461 | O12: INCIDENTE | P12: CONEXIÓN | Q12: CONEXIÓN DEFICIENTE WIFI | R12: FALLAS EN CANAL DE COMUNICACIÓN DEL CLIENTE (INTERNET) | S12: 01/10/2025 SE LLEGA COMERCIO SE REALIZAN VALIDACIONES DE WIFI DEL CLIENTE SE LE INFLA QUE EL MODNE ESTÁ A MUCHA DISTANCIA ADICIONAL ESTÁ CON MUCHOS OBSTÁCULOS METÁLICOS DEL COMERCIO SE LE REALIZAN PRUEBAS CERCA AL MÓDEM OK Y CON LOS DATOS MOVILES OK SE LE REALIZA ACTUALIZACIÓN VERSIÓN Y PRUEBAS OK | T12: VISITA_TÉCNICA | U12: 32 | V12: PRINCIPAL | W12: TERRESTRE | X12: GOMEZ VEGA DAVID SNEYDER | Y12: 1 | Z12: =IF(T12="SOPORTE_TELEFÓNICO",'TARIFAS 2025'!$B$14,IF(V12="PRINCIPAL",'TARIFAS 2025'!$B$8,IF(V12="INTERMEDIA",'TARIFAS 2025'!$C$8,IF(V12="LEJANA",'TARIFAS 2025'!$D$8)))) -> 51282 | AA12: =Z12*Y12 -> 51282
A13: BARRANQUILLA | B13: =VLOOKUP(A13,'CENTROS DE COSTOS'!A:D,2,0) -> 0036-0001 | C13: =VLOOKUP(A13,'CENTROS DE COSTOS'!A:D,3,0) -> Wompi Costa | D13: 8001 | E13: 2816012 | F13: 60460 | G13: INCIDENTE | H13: ATLANTICO | I13: BARRANQUILLA | J13: PORTAL DE CEVILLAR | K13: WOMPI | L13: FO-25-1605140 | M13: 45930.547 | N13: 45931.465 | O13: INCIDENTE | P13: CONEXIÓN | Q13: CONEXIÓN DEFICIENTE WIFI | R13: WIFI | S13: 01/10/2025 SE REALIZA VISITA AL COMERCIO SE ENCUENTRA DATÁFONO CON PROBLEMAS DE LENTITUD POR INTERNET VERIFICO QUE EL MÓDEM SE ENCUENTRA RETIRADO DEL DATAFONO COMO A 5 METROS SE REALIZA UNA PRUEBA CERCA AL MÓDEM Y SALE PERFECTAMENTE SE LE DICE AL CLIENTE SI PUEDE RODAR EL MÓDEM LO CUAL ME MANIFIESTA QUE VA LLEMAR A SU PRESTADOR DE SERVICIO SE REALIZAN PRUEBAS Y EL CB QUEDA OPERATIVO | T13: VISITA_TÉCNICA | U13: 56 | V13: PRINCIPAL | W13: TERRESTRE | X13: PEÑALOZA GUTIERREZ RAFAEL GUSTAVO | Y13: 1 | Z13: =IF(T13="SOPORTE_TELEFÓNICO",'TARIFAS 2025'!$B$14,IF(V13="PRINCIPAL",'TARIFAS 2025'!$B$8,IF(V13="INTERMEDIA",'TARIFAS 2025'!$C$8,IF(V13="LEJANA",'TARIFAS 2025'!$D$8)))) -> 51282 | AA13: =Z13*Y13 -> 51282
A14: TUNJA | B14: =VLOOKUP(A14,'CENTROS DE COSTOS'!A:D,2,0) -> 0036-0007 | C14: =VLOOKUP(A14,'CENTROS DE COSTOS'!A:D,3,0) -> Wompi Santander | D14: 15001 | E14: 2760623 | F14: 69853 | G14: INCIDENTE | H14: BOYACA | I14: TUNJA | J14: SUPERMERCADO LOS HÉROES | K14: WOMPI | L14: FO-25-1553187 | FO-25-1548594 | M14: 45918.472 | N14: 45931.47 | O14: INCIDENTE | P14: CONEXION AL DATAFONO | Q14: USUARIO NO PUEDE NAVEGAR ENTRE PANTALLAS O LA APP NO ABRE SE QUEDA CARGANDO | R14: MALA MANIPULACION DEL ESTABLECIMIENTO | S14: 19/09/2025 SE LLEGA AL SITIO Y SE CONFIRMA EL BORRADO DE LA APP POR PARTE DEL CLIENTE. SE PROCEDE A ESCALAR EL CASO COMO INCIDENTE. CASO ESCALADO. SE ENVÍA FORMATO DE ORDEN (FO) Y SE REPROGRAMA LA VISITA SEGÚN INDICACIONES DE WOMPI. CB:69853 RESUMEN DEL CASO: LA APP DE WOMPI FUE BORRADA DEL SISTEMA, NO APARECE HACIENDO TEM CALL SERIAL:254MMD4X2815 ECALADO QUEREMOS CONTARLE QUE CREAMOS EL TICKET N° (466214), PARA DAR SEGUIMIENTO A LA ATENCIÓN DE SU COMERCI 01/10/2025 SE LLAMA A LA LÍNEA DE CONTACTO 3106666976 CLIENTE CONFIRMA QUE EL SERVICIO FUNCIONA PERFECTAMENTE, COMPARTE BAUCHER VÍA WHATSAPP, SE CIERRA ORDEN EXITOSA | T14: VISITA_TÉCNICA | U14: 16 | V14: PRINCIPAL | W14: TERRESTRE | X14: HERNANDEZ GUARIN MIGUEL JULIAN | Y14: 2 | Z14: =IF(T14="SOPORTE_TELEFÓNICO",'TARIFAS 2025'!$B$14,IF(V14="PRINCIPAL",'TARIFAS 2025'!$B$8,IF(V14="INTERMEDIA",'TARIFAS 2025'!$C$8,IF(V14="LEJANA",'TARIFAS 2025'!$D$8)))) -> 51282 | AA14: =Z14*Y14 -> 102564
A15: MEDELLIN | B15: =VLOOKUP(A15,'CENTROS DE COSTOS'!A:D,2,0) -> 0036-0005 | C15: =VLOOKUP(A15,'CENTROS DE COSTOS'!A:D,3,0) -> Wompi Noroccidente | D15: 5761 | E15: 2818456 | F15: 62255 | G15: INCIDENTE | H15: ANTIOQUIA | I15: SOPETRAN | J15: BARRIO SOPETRAN SOPETRAN | K15: WOMPI | L15: FO-25-1607193 | M15: 45931.333 | N15: 45931.476 | O15: INCIDENTE | P15: NAVEGACION LENTA | Q15: USUARIO NO PUEDE NAVEGAR ENTRE PANTALLAS O LA APP NO ABRE SE QUEDA CARGANDO | R15: CACHE | S15: 01/10/2025 SE REALIZA VERIFICACIÓN DE EQUIPO PRESENTA CONSUMÓ NORMAL DE BATERÍA, SE INDICA A USUARIO QUE EL CONSUMÓ ES NORMAL EN MOMENTOS QUE HACE MÁS USO DEL EQUIPO | T15: VISITA_TÉCNICA | U15: 64 | V15: INTERMEDIA | W15: TERRESTRE | X15: HERNANDEZ CHAVARRIA JUAN CAMILO | Y15: 1 | Z15: =IF(T15="SOPORTE_TELEFÓNICO",'TARIFAS 2025'!$B$14,IF(V15="PRINCIPAL",'TARIFAS 2025'!$B$8,IF(V15="INTERMEDIA",'TARIFAS 2025'!$C$8,IF(V15="LEJANA",'TARIFAS 2025'!$D$8)))) -> 172989 | AA15: =Z15*Y15 -> 172989
A16: BOGOTA | B16: =VLOOKUP(A16,'CENTROS DE COSTOS'!A:D,2,0) -> 0036-0004 | C16: =VLOOKUP(A16,'CENTROS DE COSTOS'!A:D,3,0) -> Wompi Centro | D16: 11001 | E16: 2820364 | F16: 44901 | G16: INCIDENTE | H16: CUNDINAMARCA | I16: BOGOTÁ | J16: TODO REPUESTOS HB SAS | K16: WOMPI | L16: FO-25-1609208 | M16: 45931.38 | N16: 45931.49 | O16: INCIDENTE | P16: SOFTWARE | Q16: VERSIÓN DESACTUALIZADA | R16: VERSIÓN NO ACTUALIZADA | S16: 01/10/2025 SE REALIZA VISITA A COMERCIO SE REALIZA ACTUALIZACIÓN DE APLICACION SE BORRA CACHE. SE REALIZAN PRUEBAS DE TRANSACCIÓN | T16: VISITA_TÉCNICA | U16: 16 | V16: PRINCIPAL | W16: TERRESTRE | X16: JAIMES VALERO NELSON RICARDO | Y16: 1 | Z16: =IF(T16="SOPORTE_TELEFÓNICO",'TARIFAS 2025'!$B$14,IF(V16="PRINCIPAL",'TARIFAS 2025'!$B$8,IF(V16="INTERMEDIA",'TARIFAS 2025'!$C$8,IF(V16="LEJANA",'TARIFAS 2025'!$D$8)))) -> 51282 | AA16: =Z16*Y16 -> 51282
A17: CALI | B17: =VLOOKUP(A17,'CENTROS DE COSTOS'!A:D,2,0) -> 0036-0003 | C17: =VLOOKUP(A17,'CENTROS DE COSTOS'!A:D,3,0) -> Wompi Suroccidente | D17: 76001 | E17: 2815722 | F17: 33042 | G17: INCIDENTE | H17: VALLE DEL CAUCA | I17: CALI | J17: BARRIO HOLGUINES CALI 1 | K17: WOMPI | L17: FO-25-1604818 | M17: 45930.512 | N17: 45931.499 | O17: INCIDENTE | P17: NAVEGACION LENTA | Q17: USUARIO NO PUEDE NAVEGAR ENTRE PANTALLAS O LA APP NO ABRE SE QUEDA CARGANDO | R17: CACHE | S17: 01/10/2025 SE REALIZA ACTUALIZACIÓN DE APLICACIÓN WPI CON BORRADO DE CACHÉ Y REINICIO EL DISPOSITIVO SE REALIZAN PRUEBAS Y LOS DISPOSITIVOS QUEDAN OK | T17: VISITA_TÉCNICA | U17: 64 | V17: PRINCIPAL | W17: TERRESTRE | X17: ESCOBAR LENIS JUAN SEBASTIAN | Y17: 1 | Z17: =IF(T17="SOPORTE_TELEFÓNICO",'TARIFAS 2025'!$B$14,IF(V17="PRINCIPAL",'TARIFAS 2025'!$B$8,IF(V17="INTERMEDIA",'TARIFAS 2025'!$C$8,IF(V17="LEJANA",'TARIFAS 2025'!$D$8)))) -> 51282 | AA17: =Z17*Y17 -> 51282
A18: MEDELLIN | B18: =VLOOKUP(A18,'CENTROS DE COSTOS'!A:D,2,0) -> 0036-0005 | C18: =VLOOKUP(A18,'CENTROS DE COSTOS'!A:D,3,0) -> Wompi Noroccidente | D18: 5001 | E18: 2815940 | F18: 79677 | G18: INCIDENTE | H18: ANTIOQUIA | I18: MEDELLÍN | J18: MOTO Z | K18: WOMPI | L18: FO-25-1605133 | M18: 45930.553 | N18: 45931.506 | O18: INCIDENTE | P18: LECTOR DE TARJETAS | Q18: NO LEE TARJETAS | R18: DAÑO DEL LECTOR DE TARJETAS | S18: 01/10/2025 SE LLAMA A CLIENTE PARA CONFIRMAR VISITA Y SE HABLA CON EL SEÑOR ANDRES ZAPATA Y COMENTA QUE EL DATAFONO YA FUNCIONA CORRECTAMENTE | T18: SOPORTE_TELEFÓNICO | U18: 16 | V18: PRINCIPAL | W18: TERRESTRE | X18: BADEL ACUÑA LUIS ALBERTO | Y18: 1 | Z18: =IF(T18="SOPORTE_TELEFÓNICO",'TARIFAS 2025'!$B$14,IF(V18="PRINCIPAL",'TARIFAS 2025'!$B$8,IF(V18="INTERMEDIA",'TARIFAS 2025'!$C$8,IF(V18="LEJANA",'TARIFAS 2025'!$D$8)))) -> 22000 | AA18: =Z18*Y18 -> 22000
A19: CALI | B19: =VLOOKUP(A19,'CENTROS DE COSTOS'!A:D,2,0) -> 0036-0003 | C19: =VLOOKUP(A19,'CENTROS DE COSTOS'!A:D,3,0) -> Wompi Suroccidente | D19: 76001 | E19: 2758595 | F19: 73384 | G19: INCIDENTE | H19: VALLE DEL CAUCA | I19: CALI | J19: VARIEDADES ROSSY CALI | K19: WOMPI | L19: FO-25-1547354 | M19: 45918.365 | N19: 45931.514 | O19: INCIDENTE | P19: CREDENCIALES DE ACCESO (USUARIO/CONTRASEÑA) | Q19: NO FUNCIONA EL USUARIO O CONTRASEÑA | R19: HAY UNA FALLA EN LA OPCIÓN DE OLVIDO DE CONTRASEÑA O USUARIO | S19: 01/10/2025 CLIENTE TENÍA PROBLEMAS DE CREDENCIALES SE LE LLAMA EL DÍA DE HOY Y CONFIRMA QUE YA PUEDE INGRESAR A HACER TRANSACCIONES | T19: SOPORTE_TELEFÓNICO | U19: 48 | V19: PRINCIPAL | W19: TERRESTRE | X19: CUERO RUIZ JHONNY | Y19: 1 | Z19: =IF(T19="SOPORTE_TELEFÓNICO",'TARIFAS 2025'!$B$14,IF(V19="PRINCIPAL",'TARIFAS 2025'!$B$8,IF(V19="INTERMEDIA",'TARIFAS 2025'!$C$8,IF(V19="LEJANA",'TARIFAS 2025'!$D$8)))) -> 22000 | AA19: =Z19*Y19 -> 22000
... A163: PASTO | B163: =VLOOKUP(A163,'CENTROS DE COSTOS'!A:D,2,0) -> 0036-0003 | C163: =VLOOKUP(A163,'CENTROS DE COSTOS'!A:D,3,0) -> Wompi Suroccidente | D163: 52001 | E163: 2858520 | F163: 19074 | G163: INCIDENTE | H163: NARIÑO | I163: PASTO | J163: ASESORÍAS EN SEGUROS AMP | K163: WOMPI | L163: FO-25-1647779 | M163: 45938.601 | N163: 45938.744 | O163: INCIDENTE | P163: IMPRESIÓN | Q163: FALTA DE ROLLO | R163: MALA MANIPULACIÓN DEL DATAFONO | S163: 08/10/2025 SE VISITA CB. SE ENCUENTRA DATAFONO SIN ROLLOS DE PAPEL, POR LO TANTO LA OPCIÓN IMPRIMIR RECIBO APARECE INACTIVA. SE INSTALA ROLLO NUEVO. SE REALIZAN PRUEBAS TX EXITOSAS. QUEDA OPERATIVO CLIENTE PIDE SE LE ENVÍEN ROLLOS WOMPI, SE LE ESTÁN TERMINANDO, SE LE INDICA FORMA DE SOLICITAR | T163: VISITA_TÉCNICA | U163: 16 | V163: PRINCIPAL | W163: TERRESTRE | X163: CASTILLO HERRERA ALEX RICARDO | Y163: 1 | Z163: =IF(T163="SOPORTE_TELEFÓNICO",'TARIFAS 2025'!$B$14,IF(V163="PRINCIPAL",'TARIFAS 2025'!$B$8,IF(V163="INTERMEDIA",'TARIFAS 2025'!$C$8,IF(V163="LEJANA",'TARIFAS 2025'!$D$8)))) -> 51282 | AA163: =Z163*Y163 -> 51282
A164: MEDELLIN | B164: =VLOOKUP(A164,'CENTROS DE COSTOS'!A:D,2,0) -> 0036-0005 | C164: =VLOOKUP(A164,'CENTROS DE COSTOS'!A:D,3,0) -> Wompi Noroccidente | D164: 5001 | E164: TA-25-1186670 | F164: 49302 | G164: INCIDENTE | H164: ANTIOQUIA | I164: MEDELLÍN | J164: SMART PLUS AE | K164: WOMPI | L164: FO-25-1644227 | M164: 45938.333 | N164: 45938.751 | O164: INCIDENTE | P164: CONEXIÓN | Q164: APARECEN ERRORES EN PANTALLA: HUBO UNA DESCONEXION DE LA RED | R164: WIFI | S164: 08/10/2025 SE CAMBIA DATÁFONO POR FALLAS REPORTADAS POR EL USUARIO, DESCONEXIÓN REPENTINA CON EL WIFI, LENTITUD EN EL SISTEMA, NO IMPRIME BAUCHER, AUTORIZA EL CAMBIO DE EQUIPO CENTRO DE GESTIÓN WOMPI | T164: VISITA_TÉCNICA | U164: 64 | V164: PRINCIPAL | W164: TERRESTRE | X164: BARRIENTOS HERNANDEZ CRISTIAN HORACIO | Y164: 1 | Z164: =IF(T164="SOPORTE_TELEFÓNICO",'TARIFAS 2025'!$B$14,IF(V164="PRINCIPAL",'TARIFAS 2025'!$B$8,IF(V164="INTERMEDIA",'TARIFAS 2025'!$C$8,IF(V164="LEJANA",'TARIFAS 2025'!$D$8)))) -> 51282 | AA164: =Z164*Y164 -> 51282
A165: BOGOTA | B165: =VLOOKUP(A165,'CENTROS DE COSTOS'!A:D,2,0) -> 0036-0004 | C165: =VLOOKUP(A165,'CENTROS DE COSTOS'!A:D,3,0) -> Wompi Centro | D165: 11001 | E165: TA-25-1187371 | F165: 31442 | G165: INCIDENTE | H165: CUNDINAMARCA | I165: BOGOTÁ | J165: MULTISERVICIOS EDUARDOÑO | K165: WOMPI | L165: FO-25-1645330 | M165: 45938.426 | N165: 45938.753 | O165: INCIDENTE | P165: NAVEGACION LENTA | Q165: USUARIO NO PUEDE NAVEGAR ENTRE PANTALLAS O LA APP NO ABRE SE QUEDA CARGANDO | R165: CANAL DE COMUNICACIÓN | S165: 08/10/2025 SE REALIZA VISITA PARA VALIDAR ERROR DE CONEXIÓN AUN DESPUÉS DE ACTUALIZAR SE VALIDA VERSIÓN 26.0.2 EL EQUIPO TRANSA CORRECTO HASTA LA TERCERA O QUINTA TRANSACCIÓN LUEGO DA ERROR DE CONEXIÓN Y NO DEJA SE CIERRA SESIÓN Y YA NO DEJA ABRIRLA NUEVAMENTE SE DEBE REINICIAR EL DATAFONO PARA QUE FUNCIONE INGRESANDO LAS MISMAS CREDENCIALES, SE HACE SOPORTE CON WOMPI SE DESINSTALA APLICACION Y SE VUELVE A REINSTALAR Y SE HACE SEGUIMIENTONY EMPIEZA A DEMORARSE LAS TRANSACCIONES Y VUELVE OTRA VEZ A DAR ERROR SE CIERRA SESIÓN Y NO INGRESA SOLO. FUNCIONA SI SE VUELVE A REINICIAR EL DATAFONO ADEMÁS DE NOTARSE LENTITUD SE ESCALA A WOMPI, CUANDO NO SALE LA TRANSACCIÓN SE REALIZA BORRADO DE CACHE Y STOP EN LA APP Y VUELVE A FUNCIONAR | T165: VISITA_TÉCNICA | U165: 40 | V165: PRINCIPAL | W165: TERRESTRE | X165: JAIMES VALERO NELSON RICARDO | Y165: 1 | Z165: =IF(T165="SOPORTE_TELEFÓNICO",'TARIFAS 2025'!$B$14,IF(V165="PRINCIPAL",'TARIFAS 2025'!$B$8,IF(V165="INTERMEDIA",'TARIFAS 2025'!$C$8,IF(V165="LEJANA",'TARIFAS 2025'!$D$8)))) -> 51282 | AA165: =Z165*Y165 -> 51282
A166: IBAGUE | B166: =VLOOKUP(A166,'CENTROS DE COSTOS'!A:D,2,0) -> 0036-0006 | C166: =VLOOKUP(A166,'CENTROS DE COSTOS'!A:D,3,0) -> Wompi Oriente | D166: 73001 | E166: 2857811 | F166: 66444 | G166: INCIDENTE | H166: TOLIMA | I166: IBAGUE | J166: PUCHYS | K166: WOMPI | L166: FO-25-1646717 | M166: 45938.513 | N166: 45939.396 | O166: INCIDENTE | P166: CONEXIÓN | Q166: CONEXIÓN DEFICIENTE WIFI | R166: FALLAS EN CANAL DE COMUNICACIÓN DEL CLIENTE (INTERNET) | S166: 09/10/2025 SE REALIZA RECUPERACIÓN DE CONTRASEÑA, EL CLIENTE MANIFIESTA QUE DESDE QUE LE HICIERON LA MIGRACIÓN NO A PODIDO UTILIZAR EL EQUIPO WOMPI, SE CONECTA A RED WIFI DEL COMERCIO NO ES FUNCIONAL, SE REALIZA CONEXIÓN CON DISPOSITIVO MÓVIL "CELULAR" FUNCIONANDO EQUIPO WOMPI SE LE RECOMIENDA AL CLIENTE SOLICITAR REVISIÓN POR PARTE DEL OPERADOR DE INTERNET YA QUE NO PERMITE CONECTAR EQUIPO POR LA RED WIFI DEL CLIENTE | T166: VISITA_TÉCNICA | U166: 16 | V166: PRINCIPAL | W166: TERRESTRE | X166: GUTIERREZ CAMILO ANDRES | Y166: 1 | Z166: =IF(T166="SOPORTE_TELEFÓNICO",'TARIFAS 2025'!$B$14,IF(V166="PRINCIPAL",'TARIFAS 2025'!$B$8,IF(V166="INTERMEDIA",'TARIFAS 2025'!$C$8,IF(V166="LEJANA",'TARIFAS 2025'!$D$8)))) -> 51282 | AA166: =Z166*Y166 -> 51282
A167: BUCARAMANGA | B167: =VLOOKUP(A167,'CENTROS DE COSTOS'!A:D,2,0) -> 0036-0007 | C167: =VLOOKUP(A167,'CENTROS DE COSTOS'!A:D,3,0) -> Wompi Santander | D167: 68001 | E167: 2856504 | F167: 74163 | G167: INCIDENTE | H167: SANTANDER | I167: BUCARAMANGA | J167: BARRIO COLORADOS BUCARAMANGA | K167: WOMPI | L167: FO-25-1645269 | M167: 45938.416 | N167: 45939.397 | O167: INCIDENTE | P167: CONEXIÓN | Q167: CONEXIÓN DEFICIENTE WIFI | R167: WIFI | S167: 09/10/2025 SE COMUNICA CON EL CLIENTE , SE LE INDICA COMO ACTUALIZAR APP , COMO BORRAR CACHÉ , SE LE ENTREGA CONTRASEÑA DE USUARIO, SE LE INDICA COMO CAMBIAR CONTRASEÑA WIFI, PRUEBAS OK | T167: SOPORTE_TELEFÓNICO | U167: 32 | V167: PRINCIPAL | W167: TERRESTRE | X167: BARRERA ORTEGA MARLON STWAR | Y167: 1 | Z167: =IF(T167="SOPORTE_TELEFÓNICO",'TARIFAS 2025'!$B$14,IF(V167="PRINCIPAL",'TARIFAS 2025'!$B$8,IF(V167="INTERMEDIA",'TARIFAS 2025'!$C$8,IF(V167="LEJANA",'TARIFAS 2025'!$D$8)))) -> 22000 | AA167: =Z167*Y167 -> 22000
A168: MANIZALES | B168: =VLOOKUP(A168,'CENTROS DE COSTOS'!A:D,2,0) -> 0036-0002 | C168: =VLOOKUP(A168,'CENTROS DE COSTOS'!A:D,3,0) -> Wompi Eje Cafetero | D168: 17001 | E168: 2856387 | F168: 19208 | G168: INCIDENTE | H168: CALDAS | I168: MANIZALES | J168: LOS NAVEGANTES NRO 2 | K168: WOMPI | L168: FO-25-1645445 | M168: 45938.428 | N168: 45939.42 | O168: INCIDENTE | P168: LECTURA | Q168: NO LEE NINGUNA FACTURA | R168: NO LEE CODIGOS DE BARRAS CORTOS | S168: 09/10/2025 SE REALIZA VISITA SE EVIDENCIA QUE DATÁFONO LEÉ FACTURAS CON NORMALIDAD, SE LE EXPLICA AL USUARIO COMO REALIZAR LECTURA DE LAS FACTURAS SERVICIO OK | T168: VISITA_TÉCNICA | U168: 16 | V168: PRINCIPAL | W168: TERRESTRE | X168: AGUIRRE HENAO RAUL EDUARDO | Y168: 1 | Z168: =IF(T168="SOPORTE_TELEFÓNICO",'TARIFAS 2025'!$B$14,IF(V168="PRINCIPAL",'TARIFAS 2025'!$B$8,IF(V168="INTERMEDIA",'TARIFAS 2025'!$C$8,IF(V168="LEJANA",'TARIFAS 2025'!$D$8)))) -> 51282 | AA168: =Z168*Y168 -> 51282
