Workbook
Name A: #REF!
Name ACTIVIDAD: [1]Hoja2!$P$2:$P$30
Name Actividad: [2]Formulas!$H$2:$H$5000
Name arearesponsable: '[3]Listas desplegables'!$BB$2:$BB$100
Name Clientes: [4]Clientes!$A$2:$A$100
Name Clientes: [2]Clientes!$A$2:$A$100
Name COORDINADOR: [1]Hoja2!$D$2:$D$30
Name Coordinadores: [5]Coordinadores!$A$2:$A$1000
Name Coordinadores: [2]Coordinadores!$A$2:$A$1000
Name DOCUMENTADOR: [1]Hoja2!$A$2:$A$30
Name ES: [1]Hoja2!$K$2:$K$30
Name ESS: [1]Hoja2!$K$2:$K$30
Name Estado: [4]Formulas!$K$2:$K$5000
Name Estado: [2]Formulas!$K$2:$K$5000
Name ESTADOACTIVIDAD: [1]Hoja2!$M$2:$M$30
Name ESTADOS: '[6]Listas desplegables'!$B$1:$D$1
Name ESTADOSCIERRES: '[7]lista desplegable'!$CX$1:$DA$1
Name Facturacion: '[8]Listas desplegables'!$AO$1:$AR$1
Name FACTURACIÓN: '[6]Listas desplegables'!$Y$1:$AB$1
Name falla: #REF!
Name Fallas: '[9]Listas desplegables'!$F$2:$L$2
Name Grupo_Falla: '[10]Listas Desplegables'!$CH$2:$CH$5
Name inconservmanager: '[11]Listas desplegables'!$BC$2:$BC$100
Name INCUMPLIMIENTO: '[3]Listas desplegables'!$AK$1:$AN$1
Name LISTA: [12]Dptos!$A$1139:$A$1171
Name LISTA2: #REF!
Name LOLO: [13]Coordinadores!$A$2:$A$1000
Name solicitudes: '[8]Listas desplegables'!$U$1:$AF$1
Name solicitudes: '[14]Listas desplegables'!$AF$1:$AQ$1
Name Tecnicos: [4]Tecnicos!$A$2:$A$1000
Name Tecnicos: [2]Tecnicos!$A$2:$A$1000
Name Version: [2]Formulas!$I$2:$I$3

Sheet RESUMEN
A1: LÍNEA COMUNICACIONES S.A.S | F1: FACTURACIÓN CORRESPONSALES BANCARIOS TIQUIETES AEREOS
A2: FACTURACIÓN PROYECTO CB BANCOLOMBIA | F2: =A3 -> 45899
A3: 45899
F4: CONCEPTOS | G4: TRAYECTOS | H4: TOTAL | I4: % Administración | J4: TOTAL
A5: CONCEPTOS | B5: CANTIDAD | C5: VALOR UNITARIO | D5: VALOR TOTAL | I5: =H5*0.12 -> 0 | J5: =H5+I5 -> 0
A6: Adecuaciones CB | B6: =COUNTA(ADECUACIONES!A:A)-1 -> 50 | C6: 0 | D6: =ADECUACIONES!AE52 -> 9390985.8 | I6: =H6*0.12 -> 0 | J6: =H6+I6 -> 0
A7: Incidentes | B7: =COUNTA(INCIDENTES!A:A)-1 -> 184 | C7: 0 | D7: =INCIDENTES!AG187 -> 20560730 | I7: =H7*0.12 -> 0 | J7: =H7+I7 -> 0
A8: Ordenes de Cambio | B8: =COUNTA(OC!A:A)-1 -> 9 | C8: 0 | D8: =OC!AG11 -> 565588.44 | I8: =H8*0.12 -> 0 | J8: =H8+I8 -> 0
A9: Tiquetes | B9: 0 | C9: 0 | D9: =J12 -> 0 | I9: =H9*0.12 -> 0 | J9: =H9+I9 -> 0
A10: SUBTOTAL | D10: =SUM(D6:D9) -> 30517305 | I10: =H10*0.12 -> 0 | J10: =H10+I10 -> 0
A11: Iva | D11: =D10*0.19 -> 5798287.9 | I11: =H11*0.12 -> 0 | J11: =H11+I11 -> 0
A12: TOTAL | D12: =D10+D11 -> 36315593 | F12: TOTAL | H12: =SUM(H5:H11) -> 0 | I12: =SUM(I5:I11) -> 0 | J12: =SUM(J5:J11) -> 0

Sheet BASE LIQUIDACION
A1: TARIFAS 2025 | E1: Incremento 2025
A2: Tipificación | B2: Descripción | C2: Dia actividad Exitosa | D2: Dia actividad Fallida | E2: 0.052
A3: Tipo I | B3: Metropolitano | C3: =62700.07*(1+$E$2) -> 65960.474 | D3: =42357.4*(1+$E$2) -> 44559.985
A4: Tipo II | B4: Hasta 3 horas | C4: =155716.31*(1+$E$2) -> 163813.56 | D4: =127766.53*(1+$E$2) -> 134410.39
A5: Tipo III | B5: De 3 a 5 horas | C5: =262099.22*(1+$E$2) -> 275728.38 | D5: =211886.19*(1+$E$2) -> 222904.27
A6: Tipo IV | B6: Más de 5 horas | C6: =455883.78*(1+$E$2) -> 479589.74 | D6: =441833.68*(1+$E$2) -> 464809.03
A7: Destino aereo | B7: No incluye valor del Tiquete | C7: =455883.78*(1+$E$2) -> 479589.74 | D7: =441833.68*(1+$E$2) -> 464809.03
A8: *Donde se requiera transporte aéreo o fluvial se factura adicional a tarifa TIPO IV el valor del tiquete + el 12% de admon.
A10: Gestión Telefónica | B10: =36031.04*(1+$E$2) -> 37904.654
A11: Mts Acometida electrica | B11: =30182.1*(1+$E$2) -> 31751.569
A12: Mts Acometida datos | B12: =15432.22*(1+$E$2) -> 16234.695
A13: switche | B13: =244669.03*(1+$E$2) -> 257391.82
A14: Router | B14: =291399.51*(1+$E$2) -> 306552.28
A15: Envio operador Logistico | B15: =53547.34*(1+$E$2) -> 56331.802
D16: 37905

Sheet Tablas dinámicas
A2: ADECUACIONES | J2: NOMBRE CC | K2: Suma de VALOR | L2: Suma de VALOR2
A3: COORDINADOR | B3: CENTRO DE COSTOS LÍNEACOM | C3: % | D3: $ | E3: NOMBRE CC | F3: VALOR | J3: Redeban Centro ( Bogotá) | K3: 2212350.5 | L3: 0.072494951
A4: DIEGO FERNANDO HENAO CARDONA | B4: 0004-0002 | C4: 0.046717726 | D4: 438725.5 | E4: =VLOOKUP(B4,'CENTRO DE COSTOS'!B:C,2,0) -> Redeban Eje Cafetero (Pereira) | F4: =D4 -> 438725.5 | J4: Redeban Costa (Barranqullla) | K4: 2874053.7 | L4: 0.094177834
B5: 0004-0003 | C5: 0.28224146 | D5: 2650525.6 | E5: =VLOOKUP(B5,'CENTRO DE COSTOS'!B:C,2,0) -> Redeban Suroccidente (Cali) | F5: =D5 -> 2650525.6 | J5: Redeban Eje Cafetero (Pereira) | K5: 2184768.3 | L5: 0.071591128
A6: JOSE MAURICIO HERNANDEZ ROJAS | B6: 0004-0001 | C6: 0.022032505 | D6: 206906.94 | E6: =VLOOKUP(B6,'CENTRO DE COSTOS'!B:C,2,0) -> Redeban Costa (Barranqullla) | F6: =D6 -> 206906.94 | J6: Redeban Noroccidente (Medellín) | K6: 8975285.7 | L6: 0.2941048
A7: JUAN SEBASTIÁN RÍOS CASTRILLÓN | B7: 0004-0005 | C7: 0.25193016 | D7: 2365872.6 | E7: =VLOOKUP(B7,'CENTRO DE COSTOS'!B:C,2,0) -> Redeban Noroccidente (Medellín) | F7: =D7 -> 2365872.6 | J7: Redeban Oriente (Otros) | K7: 3944468 | L7: 0.12925348
A8: KEVIN ALEXIS CORZO BUSTOS | B8: 0004-0007 | C8: 0.14727076 | D8: 1383017.6 | E8: =VLOOKUP(B8,'CENTRO DE COSTOS'!B:C,2,0) -> Redeban Oriente (Otros) | F8: =D8 -> 1383017.6 | J8: Redeban Santander | K8: 6147592.3 | L8: 0.20144611
A9: MIGUEL JULIÁN HERNÁNDEZ GUARÍN | B9: 0004-0008 | C9: 0.19488717 | D9: 1830182.7 | E9: =VLOOKUP(B9,'CENTRO DE COSTOS'!B:C,2,0) -> Redeban Santander | F9: =D9 -> 1830182.7 | J9: Redeban Suroccidente (Cali) | K9: 4178786.3 | L9: 0.1369317
A10: WILLIAM ASDRUBAL ROZO ROZO | B10: 0004-0004 | C10: 0.054920206 | D10: 515754.88 | E10: =VLOOKUP(B10,'CENTRO DE COSTOS'!B:C,2,0) -> Redeban Centro ( Bogotá) | F10: =D10 -> 515754.88 | J10: Total general | K10: 30517305 | L10: 1
A11: Total general | C11: 1 | D11: 9390985.8
A15: INCIDENTES
A16: COORDINADOR | B16: CENTRO DE COSTOS LÍNEACOM | C16: % | D16: $ | E16: NOMBRE CC
A17: DIEGO FERNANDO HENAO CARDONA | B17: 0004-0002 | C17: 0.081713162 | D17: 1680082.3 | E17: =VLOOKUP(B17,'CENTRO DE COSTOS'!B:C,2,0) -> Redeban Eje Cafetero (Pereira) | F17: =D17 -> 1680082.3
B18: 0004-0003 | C18: 0.06927748 | D18: 1424395.6 | E18: =VLOOKUP(B18,'CENTRO DE COSTOS'!B:C,2,0) -> Redeban Suroccidente (Cali) | F18: =D18 -> 1424395.6
A19: JOSE MAURICIO HERNANDEZ ROJAS | B19: 0004-0001 | C19: 0.12972043 | D19: 2667146.7 | E19: =VLOOKUP(B19,'CENTRO DE COSTOS'!B:C,2,0) -> Redeban Costa (Barranqullla) | F19: =D19 -> 2667146.7
A20: JUAN SEBASTIÁN RÍOS CASTRILLÓN | B20: 0004-0005 | C20: 0.32145809 | D20: 6609413.1 | E20: =VLOOKUP(B20,'CENTRO DE COSTOS'!B:C,2,0) -> Redeban Noroccidente (Medellín) | F20: =D20 -> 6609413.1
A21: KEVIN ALEXIS CORZO BUSTOS | B21: 0004-0007 | C21: 0.12137165 | D21: 2495489.9 | E21: =VLOOKUP(B21,'CENTRO DE COSTOS'!B:C,2,0) -> Redeban Oriente (Otros) | F21: =D21 -> 2495489.9
A22: MIGUEL JULIÁN HERNÁNDEZ GUARÍN | B22: 0004-0008 | C22: 0.2067752 | D22: 4251449.1 | E22: =VLOOKUP(B22,'CENTRO DE COSTOS'!B:C,2,0) -> Redeban Santander | F22: =D22 -> 4251449.1
A23: WILLIAM ASDRUBAL ROZO ROZO | B23: 0004-0004 | C23: 0.06968399 | D23: 1432753.7 | E23: =VLOOKUP(B23,'CENTRO DE COSTOS'!B:C,2,0) -> Redeban Centro ( Bogotá) | F23: =D23 -> 1432753.7
A24: Total general | C24: 1 | D24: 20560730
A29: OC
A30: COORDINADOR | B30: CENTRO DE COSTOS LÍNEACOM | C30: % | D30: $ | E30: NOMBRE CC
A31: DIEGO FERNANDO HENAO CARDONA | B31: 0004-0003 | C31: 0.18364082 | D31: 103865.13 | E31: =VLOOKUP(B31,'CENTRO DE COSTOS'!B:C,2,0) -> Redeban Suroccidente (Cali) | F31: =D31 -> 103865.13
B32: 0004-0002 | C32: 0.11662274 | D32: 65960.474 | E32: =VLOOKUP(B32,'CENTRO DE COSTOS'!B:C,2,0) -> Redeban Eje Cafetero (Pereira) | F32: =D32 -> 65960.474
A33: KEVIN ALEXIS CORZO BUSTOS | B33: 0004-0007 | C33: 0.11662274 | D33: 65960.474 | E33: =VLOOKUP(B33,'CENTRO DE COSTOS'!B:C,2,0) -> Redeban Oriente (Otros) | F33: =D33 -> 65960.474
A34: MIGUEL JULIÁN HERNÁNDEZ GUARÍN | B34: 0004-0008 | C34: 0.11662274 | D34: 65960.474 | E34: =VLOOKUP(B34,'CENTRO DE COSTOS'!B:C,2,0) -> Redeban Santander | F34: =D34 -> 65960.474
A35: WILLIAM ASDRUBAL ROZO ROZO | B35: 0004-0004 | C35: 0.46649096 | D35: 263841.89 | E35: =VLOOKUP(B35,'CENTRO DE COSTOS'!B:C,2,0) -> Redeban Centro ( Bogotá) | F35: =D35 -> 263841.89
A36: Total general | C36: 1 | D36: 565588.44 | E36: =VLOOKUP(B36,'CENTRO DE COSTOS'!B:C,2,0) -> #N/A | F36: =D36 -> 565588.44

Sheet ADECUACIONES
A1: 1 | B1: =A1+1 -> 2 | C1: =B1+1 -> 3 | D1: =C1+1 -> 4 | E1: =D1+1 -> 5 | F1: =E1+1 -> 6 | G1: =F1+1 -> 7 | H1: =G1+1 -> 8 | I1: =H1+1 -> 9 | ... AE1: =AD1+1 -> 31
A2: CIUDAD SEDE | B2: COORDINADOR | C2: CENTRO DE COSTOS LÍNEACOM | D2: CÓDIGO DANE | E2: TA/CODIGO ACTIVIDAD | F2: CODIGO CB | G2: ACTIVIDAD | H2: TIPO DE APERTURA | I2: DEPARTAMENTO | J2: CIUDAD | K2: NOMBRE DEL CB | L2: RED | M2: FO | N2: FECHA LISTA | O2: FECHA ULTIMA ACTUALIZACION | P2: FORMATO | Q2: CADENA | R2: ESTADO | S2: OBSERVACIONES CLIENTE | T2: FORMA DE ATENCIÓN | U2: TERMINALES | V2: TIPIFICACION | W2: TIPO DE TRAYECTO | X2: NOMBRE DEL TECNICO | Y2: ACOMETIDA DATOS | Z2: ACOMETIDA ELECTRICA | AA2: SWITCH | AB2: ROUTER | AC2: VALOR DIAS ACTIVIDAD FACTURABLES | AD2: DIAS ACTIVIDAD FACTURABLES | AE2: VALOR TOTAL INSTALACION DE PUBLICIDAD
A3: MEDELLIN | B3: =VLOOKUP(A3,'CENTRO DE COSTOS'!A:D,4,FALSE) -> JUAN SEBASTIÁN RÍOS CASTRILLÓN | C3: =VLOOKUP(A3,'CENTRO DE COSTOS'!A:C,2,FALSE) -> 0004-0005 | D3: 5001 | E3: TA-25-904105 | F3: 80761 | G3: APERTURA | H3: CB CRECIMIENTO - NUEVO | I3: ANTIOQUIA | J3: MEDELLIN | K3: BARRIO CAICEDO MEDELLIN 17 | L3: REDEBAN | M3: FO-25-1305113 | N3: 45868 | O3: 45870 | P3: UNO A UNO | Q3: UNO A UNO | R3: EJECUTADO | S3: 30-07 SE REALIZA LLAMADA AL CLIENTE, SE HABLA CON LA SRA GEISER LUCILA PALACIO CORDOBA SE VALIDA DIRECCIÓN OK, CANAL OK, DISPONIBILIDAD TOTAL, LLAMAR EL DÍA LA INSTALACIÓN PARA CONFIRMAR VISITA, AVISO EXTERIOR ALTURA; NO INDICA ALTURA; TOMACORRIENTE CERCANO: SI; TIENE CABINA DE SEGURIDAD: NO - COMUNICACIÓN POR WPP - EL MODEM ESTA A 7 MT 01-08 SE REALIZA INSTALACIÓN DE CORRESPONSAL, SE INSTALAN EQUIPOS CON PRUEBAS EXITOSAS, SE CAPACITA Y SE EVALÚA AL CLIENTE, SE INSTALA PUBLICIDAD COMPLETA, CB QUEDA OPERATIVO. USUARIO SOMOS BANCOLOMBIA ACTIVO. SE INSTALAN 15 MT DE CABLE UTP | T3: VISITA _TECNICA | U3: VAZZZ393 | V3: TIPO I | W3: TERRESTRE | X3: PAREJA ECHAVARRIA JHON DAVID | Y3: 15 | Z3: 0 | AA3: 0 | AB3: 0 | AC3: 0 | AD3: =IF(V3="TIPO I",'BASE LIQUIDACION'!$D$3,IF(V3="TIPO II",'BASE LIQUIDACION'!$D$4,IF(V3="TIPO III",'BASE LIQUIDACION'!$D$5,'BASE LIQUIDACION'!$D$7))) -> 44559.985 | AE3: =Y3*'BASE LIQUIDACION'!$B$12+Z3*'BASE LIQUIDACION'!$B$11+AA3*'BASE LIQUIDACION'!$B$13+AB3*'BASE LIQUIDACION'!$B$14+AC3*AD3 -> 243520.43
A4: BOGOTA | B4: =VLOOKUP(A4,'CENTRO DE COSTOS'!A:D,4,FALSE) -> WILLIAM ASDRUBAL ROZO ROZO | C4: =VLOOKUP(A4,'CENTRO DE COSTOS'!A:C,2,FALSE) -> 0004-0004 | D4: 11001 | E4: TA-25-915468 | F4: 80772 | G4: APERTURA | H4: CB CRECIMIENTO - NUEVO | I4: CUNDINAMARCA | J4: BOGOTA | K4: BARRIO LA ISABELLA BOGOTA | L4: REDEBAN | M4: FO-25-1328346 | N4: 45870 | O4: 45874 | P4: UNO A UNO | Q4: UNO A UNO | R4: EJECUTADO | S4: 01-08-2025 SE REALIZA LLAMADA AL CLIENTE, SE HABLA CON EL SR JOHN ALEXANDER CUERVO RUBIANO SE VALIDA DIRECCIÓN OK, CANAL OK, DISPONIBILIDAD TOTAL, LLAMAR EL DÍA LA INSTALACIÓN PARA CONFIRMAR VISITA, AVISO EXTERIOR ALTURA APROX 2 METROS; TOMACORRIENTE CERCANO: SI; TIENE CABINA DE SEGURIDAD: NO // CONTACTO REALIZADO POR LA APP 4/08/2025 SE DEBE REPROGRAMAR ACTIVIDAD, EL COMERCIO ES AL INTERIOR DE UN CONJUNTO RESIDENCIAL, SE REQUIEREN PERMISOS DE ADMINISTRACIÓN PARA LA INSTALACIÓN DE LA PUBLICIDAD, SE INFORMA NOVEDAD A COORDINACIÓN QUIEN INDICA REPROGRAMAR PARA MAÑANA 05-08-2025, SE RETORNA PUBLICIDAD A BODEGA. 05-08 SE REALIZA INSTALACIÓN DE CORRESPONSAL, SE INSTALAN EQUIPOS CON PRUEBAS EXITOSAS, SE CAPACITA Y SE EVALÚA AL CLIENTE, SE INSTALA PUBLICIDAD COMPLETA, CB QUEDA OPERATIVO. USUARIO SOMOS BANCOLOMBIA ACTIVO. SE INSTALAN 8 MT DE CABLE UTP | T4: VISITA _TECNICA | U4: F8ZZZ008 | V4: TIPO I | W4: TERRESTRE | X4: GALINDO ROJAS LUIS FELIPE | Y4: 8 | Z4: 0 | AA4: 0 | AB4: 0 | AC4: 1 | AD4: =IF(V4="TIPO I",'BASE LIQUIDACION'!$D$3,IF(V4="TIPO II",'BASE LIQUIDACION'!$D$4,IF(V4="TIPO III",'BASE LIQUIDACION'!$D$5,'BASE LIQUIDACION'!$D$7))) -> 44559.985 | AE4: =Y4*'BASE LIQUIDACION'!$B$12+Z4*'BASE LIQUIDACION'!$B$11+AA4*'BASE LIQUIDACION'!$B$13+AB4*'BASE LIQUIDACION'!$B$14+AC4*AD4 -> 174437.55
A5: PEREIRA | B5: =VLOOKUP(A5,'CENTRO DE COSTOS'!A:D,4,FALSE) -> DIEGO FERNANDO HENAO CARDONA | C5: =VLOOKUP(A5,'CENTRO DE COSTOS'!A:C,2,FALSE) -> 0004-0002 | D5: 66001 | E5: TA-25-915501 | F5: 80798 | G5: APERTURA | H5: CB CRECIMIENTO - NUEVO | I5: RISARALDA | J5: PEREIRA | K5: BARRIO EL JARDIN ETAPA 3 PEREIRA | L5: REDEBAN | M5: FO-25-1316441 | N5: 45870 | O5: 45873 | P5: UNO A UNO | Q5: UNO A UNO | R5: EJECUTADO | S5: 01-08-2025 SE REALIZA LLAMADA AL CLIENTE, SE HABLA CON LA SRA ANDREA TORRES PAREJA DEL SR RONAL ALEXANDER RODRIGUEZ MUR, SE VALIDA DIRECCIÓN OK, CANAL OK, DISPONIBILIDAD TOTAL, LLAMAR EL DÍA LA INSTALACIÓN PARA CONFIRMAR VISITA, AVISO EXTERIOR ALTURA APROX 2 METROS; TOMACORRIENTE CERCANO: SI; TIENE CABINA DE SEGURIDAD: SI 4/08/2025 SE REALIZA INSTALACIÓN DE CORRESPONSAL, SE INSTALAN EQUIPOS CON PRUEBAS EXITOSAS, SE CAPACITA Y SE EVALÚA AL CLIENTE, SE INSTALA PUBLICIDAD COMPLETA, CB QUEDA OPERATIVO. USUARIO SOMOS BANCOLOMBIA ACTIVO. SE INSTALAN 8 MT DE CABLE UTP | T5: VISITA _TECNICA | U5: F8ZZZ033 | V5: TIPO I | W5: TERRESTRE | X5: FRANCO CAÑAVERAL YAMID RAUL | Y5: 8 | Z5: 0 | AA5: 0 | AB5: 0 | AC5: 0 | AD5: =IF(V5="TIPO I",'BASE LIQUIDACION'!$D$3,IF(V5="TIPO II",'BASE LIQUIDACION'!$D$4,IF(V5="TIPO III",'BASE LIQUIDACION'!$D$5,'BASE LIQUIDACION'!$D$7))) -> 44559.985 | AE5: =Y5*'BASE LIQUIDACION'!$B$12+Z5*'BASE LIQUIDACION'!$B$11+AA5*'BASE LIQUIDACION'!$B$13+AB5*'BASE LIQUIDACION'!$B$14+AC5*AD5 -> 129877.56
A6: CALI | B6: =VLOOKUP(A6,'CENTRO DE COSTOS'!A:D,4,FALSE) -> DIEGO FERNANDO HENAO CARDONA | C6: =VLOOKUP(A6,'CENTRO DE COSTOS'!A:C,2,FALSE) -> 0004-0003 | D6: 76001 | E6: TA-25-929470 | F6: 80871 | G6: APERTURA | H6: CB CRECIMIENTO - NUEVO | I6: VALLE DEL CAUCA | J6: CALI | K6: BARRIO TERRON COLORADO CALI 2 | L6: REDEBAN | M6: FO-25-1337707 | N6: 45875 | O6: 45877 | P6: UNO A UNO | Q6: UNO A UNO | R6: EJECUTADO | S6: 06-08 SE REALIZA LLAMADA AL CLIENTE, SE HABLA CON LA SRA JHENIFER CAROLINA VANEGAS RODRIGUEZ SE VALIDA DIRECCIÓN OK, CANAL OK, DISPONIBILIDAD TOTAL, LLAMAR EL DÍA LA INSTALACIÓN PARA CONFIRMAR VISITA, AVISO EXTERIOR ALTURA: NO INDICA ALTURA; TOMACORRIENTE CERCANO: SI; TIENE CABINA DE SEGURIDAD: SI 08-08 SE REALIZA INSTALACIÓN DE CORRESPONSAL, SE INSTALAN EQUIPOS CON PRUEBAS EXITOSAS, SE CAPACITA Y SE EVALÚA AL CLIENTE, SE INSTALA PUBLICIDAD COMPLETA, CB QUEDA OPERATIVO. USUARIO SOMOS BANCOLOMBIA ACTIVO. SE INSTALAN 5 MT DE CABLE UTP | T6: VISITA _TECNICA | U6: FGZZZ906 | V6: TIPO I | W6: TERRESTRE | X6: BOLAÑOS TABORDA JORGE ENRIQUE | Y6: 5 | Z6: 0 | AA6: 0 | AB6: 0 | AC6: 0 | AD6: =IF(V6="TIPO I",'BASE LIQUIDACION'!$D$3,IF(V6="TIPO II",'BASE LIQUIDACION'!$D$4,IF(V6="TIPO III",'BASE LIQUIDACION'!$D$5,'BASE LIQUIDACION'!$D$7))) -> 44559.985 | AE6: =Y6*'BASE LIQUIDACION'!$B$12+Z6*'BASE LIQUIDACION'!$B$11+AA6*'BASE LIQUIDACION'!$B$13+AB6*'BASE LIQUIDACION'!$B$14+AC6*AD6 -> 81173.477
A7: TUNJA | B7: =VLOOKUP(A7,'CENTRO DE COSTOS'!A:D,4,FALSE) -> MIGUEL JULIÁN HERNÁNDEZ GUARÍN | C7: =VLOOKUP(A7,'CENTRO DE COSTOS'!A:C,2,FALSE) -> 0004-0008 | D7: 15776 | E7: TA-25-929577 | F7: 80912 | G7: APERTURA | H7: CB CRECIMIENTO - NUEVO | I7: BOYACA | J7: SUTAMARCHAN | K7: BARRIO CENTRO SUTAMARCHAN 4 | L7: REDEBAN | M7: FO-25-1337775 | N7: 45875 | O7: 45881 | P7: UNO A UNO | Q7: UNO A UNO | R7: EJECUTADO | S7: 06-08-2025 SE REALIZA LLAMADA AL CLIENTE, SE HABLA CON LA SRA DIANA MARCELA GALVIS RODRÍGUEZ, SE VALIDA DIRECCIÓN OK, CANAL OK, DISPONIBILIDAD TOTAL, LLAMAR EL DÍA LA INSTALACIÓN PARA CONFIRMAR VISITA, AVISO EXTERIOR ALTURA APROX DONDE EL TECNICO LO VEA CONVENIENTE; TOMACORRIENTE CERCANO: SI; TIENE CABINA DE SEGURIDAD: SI 11-08 POR TEMAS RELACIONADO AL PARO DE MINEROS PRESENTADO EN EL DEPARTAMENTO LA ORDEN SE REPROGRAMA HASTA NUEVA ORDEN 12/08/2025 SE REALIZA INSTALACIÓN DE CORRESPONSAL, SE INSTALAN EQUIPOS CON PRUEBAS EXITOSAS, SE CAPACITA Y SE EVALÚA AL CLIENTE, SE INSTALA PUBLICIDAD COMPLETA, CB QUEDA OPERATIVO. USUARIO SOMOS BANCOLOMBIA ACTIVO | T7: VISITA _TECNICA | U7: FGZZZ909 | V7: TIPO II | W7: TERRESTRE | X7: RODRIGUEZ MURCIA YERSON IVAN | Y7: 20 | Z7: 0 | AA7: 0 | AB7: 0 | AC7: 0 | AD7: =IF(V7="TIPO I",'BASE LIQUIDACION'!$D$3,IF(V7="TIPO II",'BASE LIQUIDACION'!$D$4,IF(V7="TIPO III",'BASE LIQUIDACION'!$D$5,'BASE LIQUIDACION'!$D$7))) -> 134410.39 | AE7: =Y7*'BASE LIQUIDACION'!$B$12+Z7*'BASE LIQUIDACION'!$B$11+AA7*'BASE LIQUIDACION'!$B$13+AB7*'BASE LIQUIDACION'!$B$14+AC7*AD7 -> 324693.91
A8: TUNJA | B8: =VLOOKUP(A8,'CENTRO DE COSTOS'!A:D,4,FALSE) -> MIGUEL JULIÁN HERNÁNDEZ GUARÍN | C8: =VLOOKUP(A8,'CENTRO DE COSTOS'!A:C,2,FALSE) -> 0004-0008 | D8: 15367 | E8: TA-25-931159 | F8: 80894 | G8: APERTURA | H8: CB CRECIMIENTO - NUEVO | I8: BOYACA | J8: JENESANO | K8: BARRIO CENTRO JENESANO 7 | L8: REDEBAN | M8: FO-25-1339047 | N8: 45875 | O8: 45880 | P8: UNO A UNO | Q8: UNO A UNO | R8: EJECUTADO | S8: 06-08-2025 SE REALIZA LLAMADA AL CLIENTE, SE HABLA CON LA SRA YURY ROCIO PARRA APONTE, SE VALIDA DIRECCIÓN OK, CANAL OK, DISPONIBILIDAD TOTAL, LLAMAR EL DÍA LA INSTALACIÓN PARA CONFIRMAR VISITA, AVISO EXTERIOR ALTURA APROX 3 METROS; TOMACORRIENTE CERCANO: SI; TIENE CABINA DE SEGURIDAD: NO 11/08/2025 SE REALIZA INSTALACIÓN DE CORRESPONSAL, SE INSTALAN EQUIPOS CON PRUEBAS EXITOSAS, SE CAPACITA Y SE EVALÚA AL CLIENTE, SE INSTALA PUBLICIDAD COMPLETA, CB QUEDA OPERATIVO. USUARIO SOMOS BANCOLOMBIA ACTIVO. SE INSTALAN 10 MT DE CABLE UTP | T8: VISITA _TECNICA | U8: FGZZZ912 | V8: TIPO II | W8: TERRESTRE | X8: SOLER HOYOS CRISTIAN LEONARDO | Y8: 10 | Z8: 0 | AA8: 0 | AB8: 0 | AC8: 0 | AD8: =IF(V8="TIPO I",'BASE LIQUIDACION'!$D$3,IF(V8="TIPO II",'BASE LIQUIDACION'!$D$4,IF(V8="TIPO III",'BASE LIQUIDACION'!$D$5,'BASE LIQUIDACION'!$D$7))) -> 134410.39 | AE8: =Y8*'BASE LIQUIDACION'!$B$12+Z8*'BASE LIQUIDACION'!$B$11+AA8*'BASE LIQUIDACION'!$B$13+AB8*'BASE LIQUIDACION'!$B$14+AC8*AD8 -> 162346.95
A9: IBAGUE | B9: =VLOOKUP(A9,'CENTRO DE COSTOS'!A:D,4,FALSE) -> KEVIN ALEXIS CORZO BUSTOS | C9: =VLOOKUP(A9,'CENTRO DE COSTOS'!A:C,2,FALSE) -> 0004-0007 | D9: 73001 | E9: TA-25-931161 | F9: 80888 | G9: APERTURA | H9: CB CRECIMIENTO - NUEVO | I9: TOLIMA | J9: IBAGUE | K9: BARRIO GAITAN IBAGUE | L9: REDEBAN | M9: FO-25-1339064 | N9: 45875 | O9: 45880 | P9: UNO A UNO | Q9: UNO A UNO | R9: EJECUTADO | S9: 06-08-2025 SE REALIZA LLAMADA AL CLIENTE, SE HABLA CON EL SR DEIBY BRAVO BRAVO, SE VALIDA DIRECCIÓN OK, CANAL OK, DISPONIBILIDAD TOTAL, LLAMAR EL DÍA LA INSTALACIÓN PARA CONFIRMAR VISITA, AVISO EXTERIOR ALTURA APROX DONDE EL TECNICO LO VEA CONVENIENTE; TOMACORRIENTE CERCANO: SI; TIENE CABINA DE SEGURIDAD: NO 08-08 SE COMUNICA TELEFÓNICAMENTE CON EL SEÑOR DEIBY BRAVO BRAVO AL NÚMERO TELEFÓNICO # 3133548286 PARA REALIZAR LA INSTALACIÓN DE CORRESPONSAL INFORMA QUE NO ES POSIBLE RECIBIR LA INSTALACIÓN DEL CB EL DÍA DE HOY SOLICITA QUE SE REALICE EL DÍA LUNES 11 AGOSTO 11-08 SE REALIZA INSTALACIÓN DE CORRESPONSAL, SE INSTALAN EQUIPOS CON PRUEBAS EXITOSAS, SE CAPACITA Y SE EVALÚA AL CLIENTE, SE INSTALA PUBLICIDAD COMPLETA, CB QUEDA OPERATIVO. USUARIO SOMOS BANCOLOMBIA ACTIVO. SE INSTALAN 10 MT DE CABLE UTP | T9: VISITA _TECNICA | U9: FGZZZ914 | V9: TIPO I | W9: TERRESTRE | X9: GUTIERREZ CAMILO ANDRES | Y9: 10 | Z9: 0 | AA9: 0 | AB9: 0 | AC9: 0 | AD9: =IF(V9="TIPO I",'BASE LIQUIDACION'!$D$3,IF(V9="TIPO II",'BASE LIQUIDACION'!$D$4,IF(V9="TIPO III",'BASE LIQUIDACION'!$D$5,'BASE LIQUIDACION'!$D$7))) -> 44559.985 | AE9: =Y9*'BASE LIQUIDACION'!$B$12+Z9*'BASE LIQUIDACION'!$B$11+AA9*'BASE LIQUIDACION'!$B$13+AB9*'BASE LIQUIDACION'!$B$14+AC9*AD9 -> 162346.95
A10: IBAGUE | B10: =VLOOKUP(A10,'CENTRO DE COSTOS'!A:D,4,FALSE) -> KEVIN ALEXIS CORZO BUSTOS | C10: =VLOOKUP(A10,'CENTRO DE COSTOS'!A:C,2,FALSE) -> 0004-0007 | D10: 73001 | E10: TA-25-931163 | F10: 80889 | G10: APERTURA | H10: CB CRECIMIENTO - NUEVO | I10: TOLIMA | J10: IBAGUE | K10: BARRIO SAN REMO IBAGUE | L10: REDEBAN | M10: FO-25-1339083 | N10: 45875 | O10: 45880 | P10: UNO A UNO | Q10: UNO A UNO | R10: EJECUTADO | S10: 06-08-2025 SE REALIZA LLAMADA AL CLIENTE, SE HABLA CON LA SRA DIANA MARCELA PATIÑO HERNANDEZ, SE VALIDA DIRECCIÓN OK, CANAL OK, DISPONIBILIDAD TOTAL, LLAMAR EL DÍA LA INSTALACIÓN PARA CONFIRMAR VISITA, AVISO EXTERIOR ALTURA APROX 2,50 METROS; TOMACORRIENTE CERCANO: SI; TIENE CABINA DE SEGURIDAD: NO// MODEM A 5 METROS 11/08/2025 SE REALIZA INSTALACIÓN DE CORRESPONSAL, SE INSTALAN EQUIPOS CON PRUEBAS EXITOSAS, SE CAPACITA Y SE EVALÚA AL CLIENTE, SE INSTALA PUBLICIDAD COMPLETA, CB QUEDA OPERATIVO. USUARIO SOMOS BANCOLOMBIA ACTIVO. SE INSTALAN 15 MT DE CABLE UTP | T10: VISITA _TECNICA | U10: FGZZZ916 | V10: TIPO I | W10: TERRESTRE | X10: BARRAGAN TAFUR EDWIN ESTEBAN | Y10: 15 | Z10: 0 | AA10: 0 | AB10: 0 | AC10: 0 | AD10: =IF(V10="TIPO I",'BASE LIQUIDACION'!$D$3,IF(V10="TIPO II",'BASE LIQUIDACION'!$D$4,IF(V10="TIPO III",'BASE LIQUIDACION'!$D$5,'BASE LIQUIDACION'!$D$7))) -> 44559.985 | AE10: =Y10*'BASE LIQUIDACION'!$B$12+Z10*'BASE LIQUIDACION'!$B$11+AA10*'BASE LIQUIDACION'!$B$13+AB10*'BASE LIQUIDACION'!$B$14+AC10*AD10 -> 243520.43
A11: BUCARAMANGA | B11: =VLOOKUP(A11,'CENTRO DE COSTOS'!A:D,4,FALSE) -> MIGUEL JULIÁN HERNÁNDEZ GUARÍN | C11: =VLOOKUP(A11,'CENTRO DE COSTOS'!A:C,2,FALSE) -> 0004-0008 | D11: 68169 | E11: TA-25-931184 | F11: 80877 | G11: APERTURA | H11: CB CRECIMIENTO - NUEVO | I11: SANTANDER | J11: CHARTA | K11: BARRIO EL CARMEN CHARTA | L11: REDEBAN | M11: FO-25-1339209 | N11: 45875 | O11: 45880 | P11: UNO A UNO | Q11: UNO A UNO | R11: EJECUTADO | S11: 06-08 SE REALIZA LLAMADA AL CLIENTE, SE HABLA CON LA SRA ALICIA PABON DE VILLABONA SE VALIDA DIRECCIÓN OK, CANAL OK, DISPONIBILIDAD TOTAL, LLAMAR EL DÍA LA INSTALACIÓN PARA CONFIRMAR VISITA, AVISO EXTERIOR ALTURA APROX 2 METROS; TOMACORRIENTE CERCANO: SI; TIENE CABINA DE SEGURIDAD: NO - EL MODEM ESTA A 5 MT 11/08/2025 SE REALIZA INSTALACIÓN DE CORRESPONSAL, SE INSTALAN EQUIPOS CON PRUEBAS EXITOSAS, SE CAPACITA Y SE EVALÚA AL CLIENTE, SE INSTALA PUBLICIDAD COMPLETA, CB QUEDA OPERATIVO. USUARIO SOMOS BANCOLOMBIA ACTIVO. SE INSTALAN 10 MT DE CABLE UTP | T11: VISITA _TECNICA | U11: FGZZZ936 | V11: TIPO II | W11: TERRESTRE | X11: SANTOS GONZALEZ JOHAN FABIAN | Y11: 10 | Z11: 0 | AA11: 0 | AB11: 0 | AC11: 0 | AD11: =IF(V11="TIPO I",'BASE LIQUIDACION'!$D$3,IF(V11="TIPO II",'BASE LIQUIDACION'!$D$4,IF(V11="TIPO III",'BASE LIQUIDACION'!$D$5,'BASE LIQUIDACION'!$D$7))) -> 134410.39 | AE11: =Y11*'BASE LIQUIDACION'!$B$12+Z11*'BASE LIQUIDACION'!$B$11+AA11*'BASE LIQUIDACION'!$B$13+AB11*'BASE LIQUIDACION'!$B$14+AC11*AD11 -> 162346.95
A12: YOPAL | B12: =VLOOKUP(A12,'CENTRO DE COSTOS'!A:D,4,FALSE) -> KEVIN ALEXIS CORZO BUSTOS | C12: =VLOOKUP(A12,'CENTRO DE COSTOS'!A:C,2,FALSE) -> 0004-0007 | D12: 85010 | E12: TA-25-931186 | F12: 80862 | G12: APERTURA | H12: CB CRECIMIENTO - NUEVO | I12: CASANARE | J12: AGUAZUL | K12: BARRIO LA ESPIGA AGUAZUL | L12: REDEBAN | M12: FO-25-1339221 | N12: 45875 | O12: 45881 | P12: UNO A UNO | Q12: UNO A UNO | R12: EJECUTADO | S12: 06-08 SE REALIZA LLAMADA AL CLIENTE, SE HABLA CON LA SR RAFAEL SE VALIDA DIRECCIÓN OK, CANAL OK, DISPONIBILIDAD TOTAL, LLAMAR EL DÍA LA INSTALACIÓN PARA CONFIRMAR VISITA, AVISO EXTERIOR ALTURA APROX 2 METROS; TOMACORRIENTE CERCANO: SI; TIENE CABINA DE SEGURIDAD: SI - EL MODEM ESTA A 6 MT 09-08 EN COMUNICACIÓN CON EL SEÑOR RAFAEL CORONEL AL NUMERO 3209171697, INDICA POR TEMAS PERSONALES Y DISPOSICION NO PUEDE RECIBIRNOS HOY. INDICA NOS ATIENDE EL DIA 12-8-2025. 12/08/2025 SE REALIZA INSTALACIÓN DE CORRESPONSAL, SE INSTALAN EQUIPOS CON PRUEBAS EXITOSAS, SE CAPACITA Y SE EVALÚA AL CLIENTE, SE INSTALA PUBLICIDAD COMPLETA, CB QUEDA OPERATIVO. USUARIO SOMOS BANCOLOMBIA ACTIVO. SE INSTALAN 15 MT DE CABLE UTP | T12: VISITA _TECNICA | U12: FGZZZ940 | V12: TIPO II | W12: TERRESTRE | X12: BERNAL ELAICA EDGAR ALEXIS | Y12: 15 | Z12: 0 | AA12: 0 | AB12: 0 | AC12: 0 | AD12: =IF(V12="TIPO I",'BASE LIQUIDACION'!$D$3,IF(V12="TIPO II",'BASE LIQUIDACION'!$D$4,IF(V12="TIPO III",'BASE LIQUIDACION'!$D$5,'BASE LIQUIDACION'!$D$7))) -> 134410.39 | AE12: =Y12*'BASE LIQUIDACION'!$B$12+Z12*'BASE LIQUIDACION'!$B$11+AA12*'BASE LIQUIDACION'!$B$13+AB12*'BASE LIQUIDACION'!$B$14+AC12*AD12 -> 243520.43
A13: TUNJA | B13: =VLOOKUP(A13,'CENTRO DE COSTOS'!A:D,4,FALSE) -> MIGUEL JULIÁN HERNÁNDEZ GUARÍN | C13: =VLOOKUP(A13,'CENTRO DE COSTOS'!A:C,2,FALSE) -> 0004-0008 | D13: 15238 | E13: TA-25-931187 | F13: 80882 | G13: APERTURA | H13: CB CRECIMIENTO - NUEVO | I13: BOYACA | J13: DUITAMA | K13: BARRIO ALAMOS DUITAMA | L13: REDEBAN | M13: FO-25-1339227 | N13: 45875 | O13: 45883 | P13: UNO A UNO | Q13: UNO A UNO | R13: EJECUTADO | S13: 06-08 SE REALIZA LLAMADA AL CLIENTE, SE HABLA CON LA SR JHON JAIRO ESTUPIÑAN DIAZ SE VALIDA DIRECCIÓN OK, CANAL OK, DISPONIBILIDAD TOTAL, LLAMAR EL DÍA LA INSTALACIÓN PARA CONFIRMAR VISITA, AVISO EXTERIOR ALTURA APROX 2.5 METROS; TOMACORRIENTE CERCANO: SI; TIENE CABINA DE SEGURIDAD: NO - EL MODEM ESTA A 4 MT 08-08 POR TEMAS RELACIONADOS AL PARO DE MINEROS PRESENTADO EN EL DEPARTAMENTO LA ORDEN SE REPROGRAMA HASTA NUEVA ORDEN 14/08/2025 SE REALIZA INSTALACIÓN DE CORRESPONSAL, SE INSTALAN EQUIPOS CON PRUEBAS EXITOSAS, SE CAPACITA Y SE EVALÚA AL CLIENTE, SE INSTALA PUBLICIDAD COMPLETA, CB QUEDA OPERATIVO. USUARIO SOMOS BANCOLOMBIA ACTIVO. SE INSTALAN 10 MT DE CABLE UTP | T13: VISITA _TECNICA | U13: FGZZZ941 | V13: TIPO II | W13: TERRESTRE | X13: MARTINEZ FLOREZ DONIS ALBERTO | Y13: 10 | Z13: 0 | AA13: 0 | AB13: 0 | AC13: 0 | AD13: =IF(V13="TIPO I",'BASE LIQUIDACION'!$D$3,IF(V13="TIPO II",'BASE LIQUIDACION'!$D$4,IF(V13="TIPO III",'BASE LIQUIDACION'!$D$5,'BASE LIQUIDACION'!$D$7))) -> 134410.39 | AE13: =Y13*'BASE LIQUIDACION'!$B$12+Z13*'BASE LIQUIDACION'!$B$11+AA13*'BASE LIQUIDACION'!$B$13+AB13*'BASE LIQUIDACION'!$B$14+AC13*AD13 -> 162346.95
A14: TUNJA | B14: =VLOOKUP(A14,'CENTRO DE COSTOS'!A:D,4,FALSE) -> MIGUEL JULIÁN HERNÁNDEZ GUARÍN | C14: =VLOOKUP(A14,'CENTRO DE COSTOS'!A:C,2,FALSE) -> 0004-0008 | D14: 15723 | E14: TA-25-951739 | F14: 80975 | G14: APERTURA | H14: CB CRECIMIENTO - NUEVO | I14: BOYACA | J14: SATIVASUR | K14: BARRIO CENTRO SATIVASUR | L14: REDEBAN | M14: FO-25-1359836 | N14: 45880 | O14: 45883 | P14: UNO A UNO | Q14: UNO A UNO | R14: EJECUTADO | S14: 11-08-2025 SE REALIZA LLAMADA AL CLIENTE, SE HABLA CON LA SRA LINA LEONOR PATIÑO DURAN SE VALIDA DIRECCIÓN OK, CANAL OK, DISPONIBILIDAD TOTAL, LLAMAR EL DÍA LA INSTALACIÓN PARA CONFIRMAR VISITA, AVISO EXTERIOR ALTURA APROX 2,50 METROS; TOMACORRIENTE CERCANO: SI; TIENE CABINA DE SEGURIDAD: SI // CONTACTO REALIZADO POR LA APP // CLIENTE INDICA QUE PARA EL DIA DE MIERCOLES TIENE CITA MEDICA FUERA DE LA CIUDAD, SOLICITA VISITAR EL 14/08 14-08 SE REALIZA INSTALACIÓN DE CORRESPONSAL, SE INSTALAN EQUIPOS CON PRUEBAS EXITOSAS, SE CAPACITA Y SE EVALÚA AL CLIENTE, SE INSTALA PUBLICIDAD COMPLETA, CB QUEDA OPERATIVO. USUARIO SOMOS BANCOLOMBIA ACTIVO. SE INSTALAN 10 MT DE CABLE UTP | T14: VISITA _TECNICA | U14: FIZZZ273 | V14: TIPO III | W14: TERRESTRE | X14: SOLER HOYOS CRISTIAN LEONARDO | Y14: 10 | Z14: 0 | AA14: 0 | AB14: 0 | AC14: 0 | AD14: =IF(V14="TIPO I",'BASE LIQUIDACION'!$D$3,IF(V14="TIPO II",'BASE LIQUIDACION'!$D$4,IF(V14="TIPO III",'BASE LIQUIDACION'!$D$5,'BASE LIQUIDACION'!$D$7))) -> 222904.27 | AE14: =Y14*'BASE LIQUIDACION'!$B$12+Z14*'BASE LIQUIDACION'!$B$11+AA14*'BASE LIQUIDACION'!$B$13+AB14*'BASE LIQUIDACION'!$B$14+AC14*AD14 -> 162346.95
... A24: CALI | B24: =VLOOKUP(A24,'CENTRO DE COSTOS'!A:D,4,FALSE) -> DIEGO FERNANDO HENAO CARDONA | C24: =VLOOKUP(A24,'CENTRO DE COSTOS'!A:C,2,FALSE) -> 0004-0003 | D24: 76606 | E24: TA-25-1034028 | F24: 81244 | G24: APERTURA | H24: CB CRECIMIENTO - NUEVO | I24: VALLE DEL CAUCA | J24: RESTREPO | K24: BARRIO CENTRO RESTREPO 8 | L24: REDEBAN | M24: FO-25-1433218 | N24: 45896 | O24: 45898 | P24: UNO A UNO | Q24: UNO A UNO | R24: EJECUTADO | S24: 27-08 SE REALIZA LLAMADA AL CLIENTE, SE HABLA CON LA SRA JULIO ERNESTO SALAZAR SALAZAR SE VALIDA DIRECCIÓN OK, CANAL OK, DISPONIBILIDAD TOTAL, LLAMAR EL DÍA LA INSTALACIÓN PARA CONFIRMAR VISITA, AVISO EXTERIOR ALTURA APROX 2.5 METROS; TOMACORRIENTE CERCANO: SI; TIENE CABINA DE SEGURIDAD: NO - EL MODEM ESTA A 5 MT 29-08 SE REALIZA INSTALACIÓN DE CORRESPONSAL, SE INSTALAN EQUIPOS CON PRUEBAS EXITOSAS, SE CAPACITA Y SE EVALÚA AL CLIENTE, SE INSTALA PUBLICIDAD COMPLETA, CB QUEDA OPERATIVO. USUARIO SOMOS BANCOLOMBIA ACTIVO. SE INSTALAN 7 MT DE CABLE UTP | T24: VISITA _TECNICA | U24: FKZZZ674 | V24: TIPO II | W24: TERRESTRE | X24: MONTERO MUESES GIAN CARLO | Y24: 9 | Z24: 0 | AA24: 0 | AB24: 0 | AC24: 0 | AD24: =IF(V24="TIPO I",'BASE LIQUIDACION'!$D$3,IF(V24="TIPO II",'BASE LIQUIDACION'!$D$4,IF(V24="TIPO III",'BASE LIQUIDACION'!$D$5,'BASE LIQUIDACION'!$D$7))) -> 134410.39 | AE24: =Y24*'BASE LIQUIDACION'!$B$12+Z24*'BASE LIQUIDACION'!$B$11+AA24*'BASE LIQUIDACION'!$B$13+AB24*'BASE LIQUIDACION'!$B$14+AC24*AD24 -> 146112.26
A25: CALI | B25: =VLOOKUP(A25,'CENTRO DE COSTOS'!A:D,4,FALSE) -> DIEGO FERNANDO HENAO CARDONA | C25: =VLOOKUP(A25,'CENTRO DE COSTOS'!A:C,2,FALSE) -> 0004-0003 | D25: 76001 | E25: TA-25-915476 | F25: 80778 | G25: APERTURA | H25: CB CRECIMIENTO - NUEVO | I25: VALLE DEL CAUCA | J25: CALI | K25: BARRIO FELIDIA CALI | M25: FO-25-1316363 | N25: 45870 | O25: 45873 | P25: UNO A UNO | Q25: UNO A UNO | R25: EJECUTADO | S25: 01-08-2025 SE REALIZA LLAMADA AL CLIENTE, SE HABLA CON EL ESPOSO DE LA SRA MARITZA DEL CARMEN MEDINA PEREIRA, SE VALIDA DIRECCIÓN OK, CANAL OK, DISPONIBILIDAD TOTAL, LLAMAR EL DÍA LA INSTALACIÓN PARA CONFIRMAR VISITA, AVISO EXTERIOR ALTURA APROX DONDE EL TECNICO LO VEA CONVENIENTE; TOMACORRIENTE CERCANO: SI; TIENE CABINA DE SEGURIDAD: SI 4/08/2025 SE REALIZA INSTALACIÓN DE CORRESPONSAL, SE INSTALAN EQUIPOS CON PRUEBAS EXITOSAS, SE CAPACITA Y SE EVALÚA AL CLIENTE, SE INSTALA PUBLICIDAD COMPLETA, CB QUEDA OPERATIVO. USUARIO SOMOS BANCOLOMBIA ACTIVO | U25: F8ZZZ017 | V25: TIPO I | W25: TERRESTRE | X25: BOLAÑOS TABORDA JORGE ENRIQUE | Y25: 10 | Z25: 0 | AA25: 0 | AB25: 0 | AC25: 0 | AD25: =IF(V25="TIPO I",'BASE LIQUIDACION'!$D$3,IF(V25="TIPO II",'BASE LIQUIDACION'!$D$4,IF(V25="TIPO III",'BASE LIQUIDACION'!$D$5,'BASE LIQUIDACION'!$D$7))) -> 44559.985 | AE25: =Y25*'BASE LIQUIDACION'!$B$12+Z25*'BASE LIQUIDACION'!$B$11+AA25*'BASE LIQUIDACION'!$B$13+AB25*'BASE LIQUIDACION'!$B$14+AC25*AD25 -> 162346.95
A26: CALI | B26: =VLOOKUP(A26,'CENTRO DE COSTOS'!A:D,4,FALSE) -> DIEGO FERNANDO HENAO CARDONA | C26: =VLOOKUP(A26,'CENTRO DE COSTOS'!A:C,2,FALSE) -> 0004-0003 | D26: 76520 | E26: TA-25-952397 | F26: 80952 | G26: APERTURA | H26: CB CRECIMIENTO - NUEVO | I26: VALLE DEL CAUCA | J26: PALMIRA | K26: BARRIO ALTAMIRA PALMIRA 3 | M26: FO-25-1360278 | N26: 45880 | O26: 45881 | P26: UNO A UNO | Q26: UNO A UNO | R26: EJECUTADO | S26: 11-08 SE REALIZA LLAMADA AL CLIENTE, SE HABLA CON LA SR EDUARD ALEJANDRO ORTEGA SANCHEZ SE VALIDA DIRECCIÓN OK, CANAL OK, DISPONIBILIDAD TOTAL, LLAMAR EL DÍA LA INSTALACIÓN PARA CONFIRMAR VISITA, AVISO EXTERIOR ALTURA : NO INDICA ALTURA; TOMACORRIENTE CERCANO: SI; TIENE CABINA DE SEGURIDAD: SI - EL MODEM ESTA A 4 MT 12-08 SE REALIZA INSTALACIÓN DE CORRESPONSAL, SE INSTALAN EQUIPOS CON PRUEBAS EXITOSAS, SE CAPACITA Y SE EVALÚA AL CLIENTE, SE INSTALA PUBLICIDAD COMPLETA, CB QUEDA OPERATIVO. USUARIO SOMOS BANCOLOMBIA ACTIVO | U26: FIZZZ297 | V26: TIPO I | W26: TERRESTRE | X26: SANCHEZ URREGO ROBINSON DAVID | Y26: 7 | Z26: 0 | AA26: 0 | AB26: 0 | AC26: 0 | AD26: =IF(V26="TIPO I",'BASE LIQUIDACION'!$D$3,IF(V26="TIPO II",'BASE LIQUIDACION'!$D$4,IF(V26="TIPO III",'BASE LIQUIDACION'!$D$5,'BASE LIQUIDACION'!$D$7))) -> 44559.985 | AE26: =Y26*'BASE LIQUIDACION'!$B$12+Z26*'BASE LIQUIDACION'!$B$11+AA26*'BASE LIQUIDACION'!$B$13+AB26*'BASE LIQUIDACION'!$B$14+AC26*AD26 -> 113642.87
A27: BUCARAMANGA | B27: =VLOOKUP(A27,'CENTRO DE COSTOS'!A:D,4,FALSE) -> MIGUEL JULIÁN HERNÁNDEZ GUARÍN | C27: =VLOOKUP(A27,'CENTRO DE COSTOS'!A:C,2,FALSE) -> 0004-0008 | D27: 68547 | E27: TA-25-1005062 | F27: 81172 | G27: APERTURA | H27: CB CRECIMIENTO - NUEVO | I27: SANTANDER | J27: PIEDECUESTA | K27: BARRIO VILLANUEVA PIEDECUESTA 1 | L27: REDEBAN | M27: FO-25-1418990 | N27: 45894 | O27: 45895 | P27: UNO A UNO | Q27: UNO A UNO | R27: EJECUTADO | S27: 25-08 SE REALIZA LLAMADA AL CLIENTE, SE HABLA CON EL SR CAMILO ESTEBAN JAIMES VILLAMIZAR SE VALIDA DIRECCIÓN OK, CANAL OK, DISPONIBILIDAD TOTAL, LLAMAR EL DÍA DE LA INSTALACIÓN PARA CONFIRMAR VISITA, AVISO EXTERIOR 2,5 METROS APROX; TOMACORRIENTE CERCANO: SI; TIENE CABINA DE SEGURIDAD: NO 26/08/2025 SE REALIZA INSTALACIÓN DE CORRESPONSAL, SE INSTALAN EQUIPOS CON PRUEBAS EXITOSAS, SE CAPACITA Y SE EVALÚA AL CLIENTE, SE INSTALA PUBLICIDAD COMPLETA, CB QUEDA OPERATIVO. USUARIO SOMOS BANCOLOMBIA ACTIVO. SE INSTALA SWITCH 223C4S6013230 | T27: VISITA _TECNICA | U27: VBZZZ276 | V27: TIPO II | W27: TERRESTRE | X27: ORTEBARRERAGA MARLON STWAR | Y27: 0 | Z27: 0 | AA27: 1 | AB27: 0 | AC27: 0 | AD27: =IF(V27="TIPO I",'BASE LIQUIDACION'!$D$3,IF(V27="TIPO II",'BASE LIQUIDACION'!$D$4,IF(V27="TIPO III",'BASE LIQUIDACION'!$D$5,'BASE LIQUIDACION'!$D$7))) -> 134410.39 | AE27: =Y27*'BASE LIQUIDACION'!$B$12+Z27*'BASE LIQUIDACION'!$B$11+AA27*'BASE LIQUIDACION'!$B$13+AB27*'BASE LIQUIDACION'!$B$14+AC27*AD27 -> 257391.82
A28: CALI | B28: =VLOOKUP(A28,'CENTRO DE COSTOS'!A:D,4,FALSE) -> DIEGO FERNANDO HENAO CARDONA | C28: =VLOOKUP(A28,'CENTRO DE COSTOS'!A:C,2,FALSE) -> 0004-0003 | D28: 76001 | E28: TA-25-1005079 | F28: 81060 | G28: APERTURA | H28: CB CRECIMIENTO - OTRAS LISTAS | I28: VALLE DEL CAUCA | J28: CALI | K28: BARRIO SANTA ISABEL CALI 3 | L28: REDEBAN | M28: FO-25-1419047 | N28: 45894 | O28: 45895 | P28: UNO A UNO | Q28: UNO A UNO | R28: EJECUTADO | S28: 25-08 SE REALIZA LLAMADA AL CLIENTE, SE HABLA CON LA SRA VALENTINA LOPEZ MONDOL SE VALIDA DIRECCIÓN OK, CANAL OK, DISPONIBILIDAD TOTAL, LLAMAR EL DÍA DE LA INSTALACIÓN PARA CONFIRMAR VISITA, AVISO EXTERIOR APROX 3 METROS; TOMACORRIENTE CERCANO: SI; TIENE CABINA DE SEGURIDAD: SI 26/08/2025 SE REALIZA INSTALACIÓN DE CORRESPONSAL, SE INSTALAN EQUIPOS CON PRUEBAS EXITOSAS, SE CAPACITA Y SE EVALÚA AL CLIENTE, SE INSTALA PUBLICIDAD COMPLETA, CB QUEDA OPERATIVO. USUARIO SOMOS BANCOLOMBIA ACTIVO. SE INSTALAN SWITCCHH 221C1Q3006448 | T28: VISITA _TECNICA | U28: VBZZZ286 | V28: TIPO I | W28: TERRESTRE | X28: MONTERO MUESES GIAN CARLO | Y28: 0 | Z28: 0 | AA28: 1 | AB28: 0 | AC28: 0 | AD28: =IF(V28="TIPO I",'BASE LIQUIDACION'!$D$3,IF(V28="TIPO II",'BASE LIQUIDACION'!$D$4,IF(V28="TIPO III",'BASE LIQUIDACION'!$D$5,'BASE LIQUIDACION'!$D$7))) -> 44559.985 | AE28: =Y28*'BASE LIQUIDACION'!$B$12+Z28*'BASE LIQUIDACION'!$B$11+AA28*'BASE LIQUIDACION'!$B$13+AB28*'BASE LIQUIDACION'!$B$14+AC28*AD28 -> 257391.82
A29: BOGOTA | B29: =VLOOKUP(A29,'CENTRO DE COSTOS'!A:D,4,FALSE) -> WILLIAM ASDRUBAL ROZO ROZO | C29: =VLOOKUP(A29,'CENTRO DE COSTOS'!A:C,2,FALSE) -> 0004-0004 | D29: 25899 | E29: TA-25-915496 | F29: 80823 | G29: APERTURA | H29: CB CRECIMIENTO - NUEVO | I29: CUNDINAMARCA | J29: ZIPAQUIRA | K29: BARRIO SAN PABLO ZIPAQUIRA 3 | L29: REDEBAN | M29: FO-25-1316424 | N29: 45870 | O29: 45874 | P29: UNO A UNO | Q29: UNO A UNO | R29: EJECUTADO/CANCELADO | S29: 01-08-2025 SE REALIZA LLAMADA AL CLIENTE, SE HABLA CON EL SR JHONNATAN SAMUEL GONZALEZ MARTINEZ SE VALIDA DIRECCIÓN OK, CANAL OK, DISPONIBILIDAD TOTAL, LLAMAR EL DÍA LA INSTALACIÓN PARA CONFIRMAR VISITA, AVISO EXTERIOR ALTURA APROX 3 METROS; TOMACORRIENTE CERCANO: SI; TIENE CABINA DE SEGURIDAD: SI// MODEM A 6 METROS 5/08/2025 SE REALIZA VISITA PARA EJECUTAR LA IMPLEMENTACIÓN DE CORRESPONSAL BANCARIO PERO AL LLEGAR NO ES POSIBLE REALIZAR YA QUE EL SR JHONATAN SE LE PRESENTÓ UNA CALAMIDAD POR EL CUAL NO LE ES POSIBLE ATENDER SE BRINDA INFORMACIÓN PARA REALIZA LA NUEVA SOLICITUD DE INSTALACIÓN | T29: VISITA _TECNICA | U29: F8ZZZ027 | V29: TIPO II | W29: TERRESTRE | X29: GALEANO SORIANO JUAN DAVID | Y29: 0 | Z29: 0 | AA29: 0 | AB29: 0 | AC29: 1 | AD29: =IF(V29="TIPO I",'BASE LIQUIDACION'!$D$3,IF(V29="TIPO II",'BASE LIQUIDACION'!$D$4,IF(V29="TIPO III",'BASE LIQUIDACION'!$D$5,'BASE LIQUIDACION'!$D$7))) -> 134410.39 | AE29: =Y29*'BASE LIQUIDACION'!$B$12+Z29*'BASE LIQUIDACION'!$B$11+AA29*'BASE LIQUIDACION'!$B$13+AB29*'BASE LIQUIDACION'!$B$14+AC29*AD29 -> 134410.39
A30: CARTAGENA | B30: =VLOOKUP(A30,'CENTRO DE COSTOS'!A:D,4,FALSE) -> JOSE MAURICIO HERNANDEZ ROJAS | C30: =VLOOKUP(A30,'CENTRO DE COSTOS'!A:C,2,FALSE) -> 0004-0001 | D30: 13001 | E30: TA-25-915508 | F30: 80781 | G30: APERTURA | H30: CB CRECIMIENTO - NUEVO | I30: BOLIVAR | J30: CARTAGENA | K30: BARRIO VILLA ESTRELLA CARTAGENA 3 | L30: REDEBAN | M30: FO-25-1316456 | N30: 45870 | O30: 45873 | P30: UNO A UNO | Q30: UNO A UNO | R30: EJECUTADO/CANCELADO | S30: 01-08 SE REALIZA LLAMADA AL CLIENTE, SE HABLA CON LA SRA ALEXANDRA ANGULO ANDRADE SE VALIDA DIRECCIÓN OK, CANAL OK, DISPONIBILIDAD TOTAL, LLAMAR EL DÍA LA INSTALACIÓN PARA CONFIRMAR VISITA, AVISO EXTERIOR ALTURA APROX 2 METROS; TOMACORRIENTE CERCANO: SI; TIENE CABINA DE SEGURIDAD: NO 4/08/2025 SE ESCALA EL SIGUIENTE CASO, DONDE SE VA INSTALAR EN UN APARTAMENTO DEL SEGUNDO PISO, TORRE 2 DEL CONJUNTO RESIDENCIAL “CONDOMIO IPANEMA”, INDICAN QUE EL AVISO SE PUEDE INSTALAR EN EL PASILLO DEL EDIFICIO, A LA ENTRADA DEL APARTAMENTO. SE EVIDENCIA TAMBIÉN QUE EL COMERCIO ES UNA VIVIENDA CON UNA VITRINA PEQUEÑA CON ACCESORIOS DE CELULARES. / PROCEDEMOS A ESCALAR A ENTIDAD LA SITUACIÓN, YA QUE SE TIENE PREVISTA LA INSTALACIÓN EN UN APARTAMENTO QUE NO CUENTA CON AVISO PUBLICITARIO, LO CUAL PUEDE GENERAR DIFICULTADES EN LA IDENTIFICACIÓN DEL PUNTO. // ENTIDAD SOLICITA CANCELAR LA ACTIVIDAD | T30: VISITA _TECNICA | U30: F8ZZZ036 | V30: TIPO I | W30: TERRESTRE | X30: CANEDO HERRERA ALEXANDER | Y30: 0 | Z30: 0 | AA30: 0 | AB30: 0 | AC30: 1 | AD30: =IF(V30="TIPO I",'BASE LIQUIDACION'!$D$3,IF(V30="TIPO II",'BASE LIQUIDACION'!$D$4,IF(V30="TIPO III",'BASE LIQUIDACION'!$D$5,'BASE LIQUIDACION'!$D$7))) -> 44559.985 | AE30: =Y30*'BASE LIQUIDACION'!$B$12+Z30*'BASE LIQUIDACION'!$B$11+AA30*'BASE LIQUIDACION'!$B$13+AB30*'BASE LIQUIDACION'!$B$14+AC30*AD30 -> 44559.985
A31: CUCUTA | B31: =VLOOKUP(A31,'CENTRO DE COSTOS'!A:D,4,FALSE) -> MIGUEL JULIÁN HERNÁNDEZ GUARÍN | C31: =VLOOKUP(A31,'CENTRO DE COSTOS'!A:C,2,FALSE) -> 0004-0008 | D31: 54874 | E31: TA-25-915525 | F31: 80816 | G31: APERTURA | H31: CB CRECIMIENTO - NUEVO | I31: NORTE DE SANTANDER | J31: VILLA DEL ROSARIO | K31: BARRIO LA PARADA VILLA DEL ROSARIO 11 | L31: REDEBAN | M31: FO-25-1316487 | N31: 45870 | O31: 45873 | P31: UNO A UNO | Q31: UNO A UNO | R31: EJECUTADO/CANCELADO | S31: 01-08 SE REALIZA LLAMADA AL CLIENTE, SE HABLA CON LA SRA LEDYS ANDREA ESCALANTE BERBESI SE VALIDA DIRECCIÓN OK, CANAL OK, DISPONIBILIDAD TOTAL, LLAMAR EL DÍA LA INSTALACIÓN PARA CONFIRMAR VISITA, AVISO EXTERIOR ALTURA: NO INDICA ALTURA; TOMACORRIENTE CERCANO: SI; TIENE CABINA DE SEGURIDAD: NO 4/08/2025 SE REALIZÓ VISITA AL COMERCIO Y CLIENTE NO ACEPTA LA ACTIVIDAD DE IMPLEMENTACIÓN DE CORRESPONSAL, QUE EN OTRO MOMENTO SE COMUNICARA CON EL BANCO PARA SOLICITARLO EN CASO QUE LO LLEGARA A NECESITAR. | T31: VISITA _TECNICA | U31: F8ZZZ043 | V31: TIPO I | W31: TERRESTRE | X31: MORA VEGA JEAMPIER | Y31: 0 | Z31: 0 | AA31: 0 | AB31: 0 | AC31: 1 | AD31: =IF(V31="TIPO I",'BASE LIQUIDACION'!$D$3,IF(V31="TIPO II",'BASE LIQUIDACION'!$D$4,IF(V31="TIPO III",'BASE LIQUIDACION'!$D$5,'BASE LIQUIDACION'!$D$7))) -> 44559.985 | AE31: =Y31*'BASE LIQUIDACION'!$B$12+Z31*'BASE LIQUIDACION'!$B$11+AA31*'BASE LIQUIDACION'!$B$13+AB31*'BASE LIQUIDACION'!$B$14+AC31*AD31 -> 44559.985
A32: MEDELLIN | B32: =VLOOKUP(A32,'CENTRO DE COSTOS'!A:D,4,FALSE) -> JUAN SEBASTIÁN RÍOS CASTRILLÓN | C32: =VLOOKUP(A32,'CENTRO DE COSTOS'!A:C,2,FALSE) -> 0004-0005 | D32: 5642 | E32: TA-25-930981 | F32: 80842 | G32: APERTURA | H32: CB CRECIMIENTO ALIANZA - NUEVO | I32: ANTIOQUIA | J32: SALGAR | K32: PTM SALGAR NATULIGHT TIENDA NA | L32: REDEBAN | M32: FO-25-1338801 | N32: 45875 | O32: 45880 | P32: AGREGADOR | Q32: COMCARD - PTM | R32: EJECUTADO/CANCELADO | S32: 06-08 PROGRAMACIÓN REALIZADA POR LA ALIANZA 11/08/2025 REPORTAMOS NOVEDAD DE INSTALACIÓN.VISITAMOS COMERCIO ENCONTRANDO CERCANÍA CON 2 PUNTOS: PUNTO EXISTENTE 1: 3007029991 BARRIO PARQUE 2 SALGAR. COORDENADAS 5.963714 -75.979253 PUNTO EXISTENTE 2: 3007037617 DISTRICOL CELULARES JU. COORDENADAS 5.963669 -75.979412 COORDENADAS PUNTO A INSTALAR HOY: 5.963799 -75.979332 / ENTIDAD SOLICITA CANCELAR ACTIVIDAD | T32: VISITA _TECNICA | U32: FHZZZ002 | V32: TIPO II | W32: TERRESTRE | X32: CASTAÑEDA PALACIO CARLOS FELIPE | Y32: 0 | Z32: 0 | AA32: 0 | AB32: 0 | AC32: 1 | AD32: =IF(V32="TIPO I",'BASE LIQUIDACION'!$D$3,IF(V32="TIPO II",'BASE LIQUIDACION'!$D$4,IF(V32="TIPO III",'BASE LIQUIDACION'!$D$5,'BASE LIQUIDACION'!$D$7))) -> 134410.39 | AE32: =Y32*'BASE LIQUIDACION'!$B$12+Z32*'BASE LIQUIDACION'!$B$11+AA32*'BASE LIQUIDACION'!$B$13+AB32*'BASE LIQUIDACION'!$B$14+AC32*AD32 -> 134410.39
A33: VILLAVICENCIO | B33: =VLOOKUP(A33,'CENTRO DE COSTOS'!A:D,4,FALSE) -> KEVIN ALEXIS CORZO BUSTOS | C33: =VLOOKUP(A33,'CENTRO DE COSTOS'!A:C,2,FALSE) -> 0004-0007 | D33: 50006 | E33: TA-25-929391 | F33: 80861 | G33: APERTURA | H33: CB CRECIMIENTO - NUEVO | I33: META | J33: ACACIAS | K33: BARRIO INDEPENDENCIA ACACIAS 1 | L33: REDEBAN | M33: FO-25-1367708 | N33: 45875 | O33: 45884 | P33: UNO A UNO | Q33: UNO A UNO | R33: EJECUTADO | S33: 06-08-2025 SE REALIZA LLAMADA AL CLIENTE, SE HABLA CON LA SRA LEIDY VIVIANA CICUA JIMENEZ SE VALIDA DIRECCIÓN OK, CANAL OK, DISPONIBILIDAD TOTAL, LLAMAR EL DÍA LA INSTALACIÓN PARA CONFIRMAR VISITA, AVISO EXTERIOR ALTURA APROX 1,70 METROS; TOMACORRIENTE CERCANO: SI; TIENE CABINA DE SEGURIDAD: SI // CONTACTO REALIZADO POR WHATSAPP 8/08/2025SE REALIZA VISITA PARA IMPLEMENTACIÓN DEL CB “80861” A LA DIRECCIÓN RELACIONADA EN LA LISTA DE CHEQUEO, PERO AL CONSULTAR LA PLACA EN LA WEB DE INICIALIZACIONES EL CÓDIGO ÚNICO 3007080861 Y TERMINAL FGZZZ886 COINCIDEN CON EL CB RELACIONADO EN LISTA DE CHEQUEO, SIN EMBARGO LA DIRECCIÓN Y NOMBRE NO; ESTOS SON DE OTRO CB “80925” DE OTRA ZONA. @HDMURCIA SEGÚN LO CONVERSADO SE CANCELA INSTALACIÓN PARA EL CB 80861. 12/08/2025 A PETICIÓN DE LA ENTIDAD, POR FAVOR REALICEMOS NUEVAMENTE LA VISITA AL PUNTO E IMPLEMENTEMOS, YA QUE LA DIRECCIÓN HA SIDO ACTUALIZADA CORRECTAMENTE. 15/08/2025 SE REALIZA INSTALACIÓN DE CORRESPONSAL, SE INSTALAN EQUIPOS CON PRUEBAS EXITOSAS, SE CAPACITA Y SE EVALÚA AL CLIENTE, SE INSTALA PUBLICIDAD COMPLETA, CB QUEDA OPERATIVO. USUARIO SOMOS BANCOLOMBIA ACTIVO | T33: VISITA _TECNICA | U33: FGZZZ886 | V33: TIPO II | W33: TERRESTRE | X33: CASTRILLON URREA LONDIER LEANDRO | Y33: 0 | Z33: 0 | AA33: 0 | AB33: 0 | AC33: 1 | AD33: =IF(V33="TIPO I",'BASE LIQUIDACION'!$D$3,IF(V33="TIPO II",'BASE LIQUIDACION'!$D$4,IF(V33="TIPO III",'BASE LIQUIDACION'!$D$5,'BASE LIQUIDACION'!$D$7))) -> 134410.39 | AE33: =Y33*'BASE LIQUIDACION'!$B$12+Z33*'BASE LIQUIDACION'!$B$11+AA33*'BASE LIQUIDACION'!$B$13+AB33*'BASE LIQUIDACION'!$B$14+AC33*AD33 -> 134410.39
A34: YOPAL | B34: =VLOOKUP(A34,'CENTRO DE COSTOS'!A:D,4,FALSE) -> KEVIN ALEXIS CORZO BUSTOS | C34: =VLOOKUP(A34,'CENTRO DE COSTOS'!A:C,2,FALSE) -> 0004-0007 | D34: 85250 | E34: TA-25-931177 | F34: 80906 | G34: APERTURA | H34: CB CRECIMIENTO - NUEVO | I34: CASANARE | J34: PAZ DE ARIPORO | K34: BARRIO EL PALMAR PAZ DE ARIPORO 2 | L34: REDEBAN | M34: FO-25-1339174 | N34: 45875 | O34: 45880 | P34: UNO A UNO | Q34: UNO A UNO | R34: EJECUTADO/CANCELADO | S34: 06-08 SE REALIZA LLAMADA AL CLIENTE, SE HABLA CON LA SRA DIANA YULIETH SARAVIA MARTINEZ SE VALIDA DIRECCIÓN OK, CANAL OK, DISPONIBILIDAD TOTAL, LLAMAR EL DÍA LA INSTALACIÓN PARA CONFIRMAR VISITA, AVISO EXTERIOR ALTURA: NO INDICA ALTURA TOMACORRIENTE CERCANO: SI; TIENE CABINA DE SEGURIDAD: NO 11/08/2025 SE VISITA COMERCIO, LA SEÑORA DIANA SARAVIA INDICA QUE POR TEMAS DE REMODELACION DEL LOCAL, ESTE ESTARÁ LISTO HASTA LA PROXIMA SEMANA, POR TAL MOTIVO SE ESCALA A COORDINADOR Y SE CANCELA, SE LE INDICA AL USUARIO QUE UNA VEZ ESTE EL LOCAL LISTO LLAME A LA ENTIDAD. | T34: VISITA _TECNICA | U34: FGZZZ928 | V34: TIPO II | W34: TERRESTRE | X34: BERNAL ELAICA EDGAR ALEXIS | Y34: 0 | Z34: 0 | AA34: 0 | AB34: 0 | AC34: 1 | AD34: =IF(V34="TIPO I",'BASE LIQUIDACION'!$D$3,IF(V34="TIPO II",'BASE LIQUIDACION'!$D$4,IF(V34="TIPO III",'BASE LIQUIDACION'!$D$5,'BASE LIQUIDACION'!$D$7))) -> 134410.39 | AE34: =Y34*'BASE LIQUIDACION'!$B$12+Z34*'BASE LIQUIDACION'!$B$11+AA34*'BASE LIQUIDACION'!$B$13+AB34*'BASE LIQUIDACION'!$B$14+AC34*AD34 -> 134410.39
A35: CALI | B35: =VLOOKUP(A35,'CENTRO DE COSTOS'!A:D,4,FALSE) -> DIEGO FERNANDO HENAO CARDONA | C35: =VLOOKUP(A35,'CENTRO DE COSTOS'!A:C,2,FALSE) -> 0004-0003 | D35: 19845 | E35: TA-25-931178 | F35: 80922 | G35: APERTURA | H35: CB CRECIMIENTO - NUEVO | I35: CAUCA | J35: VILLA RICA | K35: BARRIO CENTRO VILLA RICA 5 | L35: REDEBAN | M35: FO-25-1350933 | N35: 45875 | O35: 45882 | P35: UNO A UNO | Q35: UNO A UNO | R35: EJECUTADO | S35: 06-08 SE REALIZA LLAMADA AL CLIENTE, SE HABLA CON LA SR JANIER JULIAN VALENCIA ESCOBAR SE VALIDA DIRECCIÓN OK, CANAL OK, DISPONIBILIDAD TOTAL, LLAMAR EL DÍA LA INSTALACIÓN PARA CONFIRMAR VISITA, AVISO EXTERIOR ALTURA: NO INDICA ALTURA; TOMACORRIENTE CERCANO: SI; TIENE CABINA DE SEGURIDAD: SI 8/08/2025SE LLEGA A SITIO PARA REALIZA LA INSTALACIÓN CB Y LA ENERGIA SE FUE HACE APROXIMADAMENTE 90 MINUTOS. EL DATÁFONO QUEDA CONFIGURADO SIN HABER REALIZADO NINGUNA TRANSACCIÓN DE PRUEBA. 13/08/2025 SE REALIZA INSTALACIÓN DE CORRESPONSAL, SE INSTALAN EQUIPOS CON PRUEBAS EXITOSAS, SE CAPACITA Y SE EVALÚA AL CLIENTE, SE INSTALA PUBLICIDAD COMPLETA, CB QUEDA OPERATIVO. USUARIO SOMOS BANCOLOMBIA ACTIVO | T35: VISITA _TECNICA | U35: FGZZZ929 | V35: TIPO IV | W35: TERRESTRE | X35: TORRES GARCIA JENDRY JOSE | Y35: 0 | Z35: 0 | AA35: 0 | AB35: 0 | AC35: 1 | AD35: =IF(V35="TIPO I",'BASE LIQUIDACION'!$D$3,IF(V35="TIPO II",'BASE LIQUIDACION'!$D$4,IF(V35="TIPO III",'BASE LIQUIDACION'!$D$5,'BASE LIQUIDACION'!$D$7))) -> 464809.03 | AE35: =Y35*'BASE LIQUIDACION'!$B$12+Z35*'BASE LIQUIDACION'!$B$11+AA35*'BASE LIQUIDACION'!$B$13+AB35*'BASE LIQUIDACION'!$B$14+AC35*AD35 -> 464809.03
A36: TUNJA | B36: =VLOOKUP(A36,'CENTRO DE COSTOS'!A:D,4,FALSE) -> MIGUEL JULIÁN HERNÁNDEZ GUARÍN | C36: =VLOOKUP(A36,'CENTRO DE COSTOS'!A:C,2,FALSE) -> 0004-0008 | D36: 15272 | E36: TA-25-931181 | F36: 80893 | G36: APERTURA | H36: CB CRECIMIENTO - NUEVO | I36: BOYACA | J36: FIRAVITOBA | K36: BARRIO CENTRO FIRAVITOBA 2 | L36: REDEBAN | M36: FO-25-1339192 | N36: 45875 | O36: 45881 | P36: UNO A UNO | Q36: UNO A UNO | R36: EJECUTADO/CANCELADO | S36: 06-08 SE REALIZA LLAMADA AL CLIENTE, SE HABLA CON LA SR RONALD MANUEL SUAREZ CORREA SE VALIDA DIRECCIÓN OK, CANAL OK, DISPONIBILIDAD TOTAL, LLAMAR EL DÍA LA INSTALACIÓN PARA CONFIRMAR VISITA, AVISO EXTERIOR ALTURA APROX 2.5 METROS; TOMACORRIENTE CERCANO: SI; TIENE CABINA DE SEGURIDAD: SI 08-08 POR TEMAS RELACIONADOS AL PARO DE MINEROS PRESENTADO EN EL DEPARTAMENTO, LA ORDEN SE REPROGRAMA HASTA NUEVA ORDEN 12/08/2025 SE VISITA DIRECCIÓN COMERCIO , NO SE PROCEDE A EJECUTAR INSTALACIÓN POR DIRECCIÓN ERRADA ,SE VALIDA CÁMARA DE COMERCIO DIRECCIÓN COINCIDE CON LA ORDEN DE TRABAJO PERO SE VÁLIDA QUE LA DIRECCIÓN LE CORRESPONDE A OTRO PREDIO QUE ESTA UBICADO EN LA CASA DE AL LADO DE DONDE SE INSTALARÍA, SE LE INDICA AL CLIENTE QUE DEBE ACTUALIZAR CAMARA DE COMERCIO | T36: VISITA _TECNICA | U36: FGZZZ933 | V36: TIPO II | W36: TERRESTRE | X36: ALVARADO MORENO CRISTHIAN | Y36: 0 | Z36: 0 | AA36: 0 | AB36: 0 | AC36: 1 | AD36: =IF(V36="TIPO I",'BASE LIQUIDACION'!$D$3,IF(V36="TIPO II",'BASE LIQUIDACION'!$D$4,IF(V36="TIPO III",'BASE LIQUIDACION'!$D$5,'BASE LIQUIDACION'!$D$7))) -> 134410.39 | AE36: =Y36*'BASE LIQUIDACION'!$B$12+Z36*'BASE LIQUIDACION'!$B$11+AA36*'BASE LIQUIDACION'!$B$13+AB36*'BASE LIQUIDACION'!$B$14+AC36*AD36 -> 134410.39
A37: BOGOTA | B37: =VLOOKUP(A37,'CENTRO DE COSTOS'!A:D,4,FALSE) -> WILLIAM ASDRUBAL ROZO ROZO | C37: =VLOOKUP(A37,'CENTRO DE COSTOS'!A:C,2,FALSE) -> 0004-0004 | D37: 11001 | E37: TA-25-952495 | F37: 80934 | G37: APERTURA | H37: CB CRECIMIENTO - NUEVO | I37: CUNDINAMARCA | J37: BOGOTA | K37: BARRIO BOSA CARBONEL BOGOTA 1 | L37: REDEBAN | M37: FO-25-1374679 | N37: 45880 | O37: 45883 | P37: UNO A UNO | Q37: UNO A UNO | R37: EJECUTADO | S37: 11-08 SE REALIZA LLAMADA AL CLIENTE, SE HABLA CON EL SRA JOHANNA PAOLA CASTAÑO MARTINEZ SE VALIDA DIRECCIÓN OK, CANAL OK, DISPONIBILIDAD TOTAL, LLAMAR EL DÍA LA INSTALACIÓN PARA CONFIRMAR VISITA, AVISO EXTERIOR ALTURA APROX 3 METROS; TOMACORRIENTE CERCANO: SI; TIENE CABINA DE SEGURIDAD: NO - COMUNICACIÓN POR WPP / EL MODEM ESTA A 4 MT 12/08/2025 SE ESCALA NOVEDAD EN APERTURA REDEBAN 3007080934 BARRIO BOSA CARBONEL BOGOTA 1, LA CUAL AL LLEGAR AL SITIO, SE ENCUENTRA UN CORRESPONSAL INSTALADO A 34 METROS SEGÚN MAPS. ADJUNTO REGISTRO FOTOGRÁFICO DATOS DE CB EXISTENTE (ADJUNTO COPIA TIRILA) NOMBRE: PTM BOGOTA DROGUERIA A CÓDIGO ÚNICO: 3007058171 DIRECCIÓN: CR 78C 71C SUR 40 COORDENADAS: 4.603577 -74.196202 14/08/2025 ENTIDAD APRUEBA INSTALACION 14/08/2025 SE REALIZA INSTALACIÓN DE CORRESPONSAL, SE INSTALAN EQUIPOS CON PRUEBAS EXITOSAS, SE CAPACITA Y SE EVALÚA AL CLIENTE, SE INSTALA PUBLICIDAD COMPLETA, CB QUEDA OPERATIVO. USUARIO SOMOS BANCOLOMBIA ACTIVO | T37: VISITA _TECNICA | U37: FIZZZ320 | V37: TIPO I | W37: TERRESTRE | X37: LOZADA ROJAS CHRISTIAN ANDRES | Y37: 0 | Z37: 0 | AA37: 0 | AB37: 0 | AC37: 1 | AD37: =IF(V37="TIPO I",'BASE LIQUIDACION'!$D$3,IF(V37="TIPO II",'BASE LIQUIDACION'!$D$4,IF(V37="TIPO III",'BASE LIQUIDACION'!$D$5,'BASE LIQUIDACION'!$D$7))) -> 44559.985 | AE37: =Y37*'BASE LIQUIDACION'!$B$12+Z37*'BASE LIQUIDACION'!$B$11+AA37*'BASE LIQUIDACION'!$B$13+AB37*'BASE LIQUIDACION'!$B$14+AC37*AD37 -> 44559.985
A38: MEDELLIN | B38: =VLOOKUP(A38,'CENTRO DE COSTOS'!A:D,4,FALSE) -> JUAN SEBASTIÁN RÍOS CASTRILLÓN | C38: =VLOOKUP(A38,'CENTRO DE COSTOS'!A:C,2,FALSE) -> 0004-0005 | D38: 5790 | E38: TA-25-952496 | F38: 80964 | G38: APERTURA | H38: CB CRECIMIENTO - NUEVO | I38: ANTIOQUIA | J38: TARAZA | K38: BARRIO SAN NICOLAS TARAZA 1 | L38: REDEBAN | M38: FO-25-1360406 | N38: 45880 | O38: 45883 | P38: UNO A UNO | Q38: UNO A UNO | R38: EJECUTADO/CANCELADO | S38: 10-08 SE REALIZA LLAMADA AL CLIENTE, SE HABLA CON LA SR FERNEY ANTONIO CASTILLO PASTRANA SE VALIDA DIRECCIÓN OK, CANAL OK, DISPONIBILIDAD TOTAL, LLAMAR EL DÍA LA INSTALACIÓN PARA CONFIRMAR VISITA, AVISO EXTERIOR ALTURA APROX 2 METROS; TOMACORRIENTE CERCANO: SI; TIENE CABINA DE SEGURIDAD: NO 12/08/2025 VISITAMOS PUNTO PARA INSTALACIÓN ENCONTRANDO QUE YA HAY OTRO EXISTENTE A MEDIA CUADRA CON CODIGO 3007077869 PTM SAN NICOLAS TARAZA. ESTE PUNTO FUE TRASLADADO HACE UN MES A ESTA NUEVA DIRECCIÓN. USUARIO DE INSTALACIÓN DE HOY COMENTA QUE CUANDO PASÓ LOS PAPELES PARA SOLICITAR EL CORRESPONSAL NO EXISTÍA ESE OTRO CB EN ESTA DIRECCIÓN SINO QUE SE TRASLADÓ COMO COMENTAMOS ANTERIORMENTE. COORDENADAS PUNTO EXISTENTE: 7.584959 -75.400686 COORDENADAS PUNTO NUEVO: 7.584725 -75.400914 14/08/2025 ENTIDAD SOLICITA CANCELAR | T38: VISITA _TECNICA | U38: FIZZZ321 | V38: TIPO IV | W38: TERRESTRE | X38: BADEL ACUÑA LUIS ALBERTO | Y38: 0 | Z38: 0 | AA38: 0 | AB38: 0 | AC38: 1 | AD38: =IF(V38="TIPO I",'BASE LIQUIDACION'!$D$3,IF(V38="TIPO II",'BASE LIQUIDACION'!$D$4,IF(V38="TIPO III",'BASE LIQUIDACION'!$D$5,'BASE LIQUIDACION'!$D$7))) -> 464809.03 | AE38: =Y38*'BASE LIQUIDACION'!$B$12+Z38*'BASE LIQUIDACION'!$B$11+AA38*'BASE LIQUIDACION'!$B$13+AB38*'BASE LIQUIDACION'!$B$14+AC38*AD38 -> 464809.03
... A50: MEDELLIN | B50: =VLOOKUP(A50,'CENTRO DE COSTOS'!A:D,4,FALSE) -> JUAN SEBASTIÁN RÍOS CASTRILLÓN | C50: =VLOOKUP(A50,'CENTRO DE COSTOS'!A:C,2,FALSE) -> 0004-0005 | D50: 5031 | E50: TA-25-1034477 | F50: 81225 | G50: APERTURA | H50: CB CRECIMIENTO ALIANZA - NUEVO | I50: ANTIOQUIA | J50: AMALFI | K50: DISTRICOL TIENDA A MAR | L50: REDEBAN | M50: FO-25-1433936 | N50: 45896 | O50: 45897 | P50: AGREGADOR | Q50: DISTRICOL | R50: EJECUTADO/CANCELADO | S50: 27-08 PROGRAMACIÓN REALIZADA POR LA ALIANZA 28/08/2025 VISITAMOS PUNTO ENCONTRANDO OTRO CB EN EL LOCAL CONTIGUO. CODIGO EXISTENTE 71566 BARRIO EL CAMELLON AMALFI. ADICIONALMENTE HAY UNA NOVEDAD CON LA DIRECCIÓN. COMERCIO ESTÁ UBICADO EN CALLE 20 PERO CON CARRERA 17. | T50: VISITA _TECNICA | U50: FKZZZ696 | V50: TIPO IV | W50: TERRESTRE | X50: QUINTERO SANCHEZ JUAN SEBASTIAN | Y50: 0 | Z50: 0 | AA50: 0 | AB50: 0 | AC50: 1 | AD50: =IF(V50="TIPO I",'BASE LIQUIDACION'!$D$3,IF(V50="TIPO II",'BASE LIQUIDACION'!$D$4,IF(V50="TIPO III",'BASE LIQUIDACION'!$D$5,'BASE LIQUIDACION'!$D$7))) -> 464809.03 | AE50: =Y50*'BASE LIQUIDACION'!$B$12+Z50*'BASE LIQUIDACION'!$B$11+AA50*'BASE LIQUIDACION'!$B$13+AB50*'BASE LIQUIDACION'!$B$14+AC50*AD50 -> 464809.03
A51: CUCUTA | B51: =VLOOKUP(A51,'CENTRO DE COSTOS'!A:D,4,FALSE) -> MIGUEL JULIÁN HERNÁNDEZ GUARÍN | C51: =VLOOKUP(A51,'CENTRO DE COSTOS'!A:C,2,FALSE) -> 0004-0008 | D51: 54498 | E51: TA-25-904094 | F51: 80745 | G51: APERTURA | H51: CB CRECIMIENTO - NUEVO | I51: NORTE DE SANTANDER | J51: OCAÑA | K51: BARRIO JUAN 23 OCAÑA | M51: FO-25-1305075 | N51: 45868 | O51: 45870 | P51: UNO A UNO | Q51: UNO A UNO | R51: EJECUTADO | S51: 30-07-2025 SE REALIZA LLAMADA AL CLIENTE, SE HABLA CON LA SRA ERIKA CAROLINA RAMIREZ QUINTERO, VALIDA DIRECCIÓN OK, CANAL OK, DISPONIBILIDAD TOTAL, LLAMAR EL DÍA LA INSTALACIÓN PARA CONFIRMAR VISITA, AVISO EXTERIOR ALTURA APROX DONDE EL TECNICO LO VEA CONVENIENTE; TOMACORRIENTE CERCANO: SI; TIENE CABINA DE SEGURIDAD: SI 1/08/2025 SE REALIZA INSTALACIÓN DE CORRESPONSAL, SE INSTALAN EQUIPOS CON PRUEBAS EXITOSAS, SE CAPACITA Y SE EVALÚA AL CLIENTE, SE INSTALA PUBLICIDAD COMPLETA, CB QUEDA OPERATIVO. USUARIO SOMOS BANCOLOMBIA ACTIVO. SE INSTALA SWITCH 223C4S6013109 | T51: VISITA _TECNICA | U51: VAZZZ384 | V51: TIPO IV | W51: TERRESTRE | X51: GELVEZ MOGOLLON JOSE ELISEO | Y51: 0 | Z51: 0 | AA51: 1 | AB51: 0 | AC51: 0 | AD51: =IF(V51="TIPO I",'BASE LIQUIDACION'!$D$3,IF(V51="TIPO II",'BASE LIQUIDACION'!$D$4,IF(V51="TIPO III",'BASE LIQUIDACION'!$D$5,'BASE LIQUIDACION'!$D$7))) -> 464809.03 | AE51: =Y51*'BASE LIQUIDACION'!$B$12+Z51*'BASE LIQUIDACION'!$B$11+AA51*'BASE LIQUIDACION'!$B$13+AB51*'BASE LIQUIDACION'!$B$14+AC51*AD51 -> 257391.82
AE52: =SUM(AE3:AE51) -> 9390985.8

Sheet Hoja1
A1: CIUDAD SEDE | B1: COORDINADOR | C1: CENTRO DE COSTOS LÍNEACOM | D1: CÓDIGO DANE | E1: TA/CODIGO ACTIVIDAD | F1: CODIGO CB | G1: ACTIVIDAD | H1: TIPO DE APERTURA | I1: DEPARTAMENTO | J1: CIUDAD | K1: NOMBRE DEL CB | L1: RED | M1: FO | N1: FECHA LISTA | O1: FECHA ULTIMA ACTUALIZACION | P1: FORMATO | Q1: CADENA | R1: ESTADO | S1: OBSERVACIONES CLIENTE | T1: FORMA DE ATENCIÓN | U1: TERMINALES | V1: TIPIFICACION | W1: TIPO DE TRAYECTO | X1: NOMBRE DEL TECNICO | Y1: ACOMETIDA DATOS | Z1: ACOMETIDA ELECTRICA | AA1: SWITCH | AB1: ROUTER | AC1: VALOR DIAS ACTIVIDAD FACTURABLES | AD1: DIAS ACTIVIDAD FACTURABLES | AE1: VALOR TOTAL INSTALACION DE PUBLICIDAD
A2: MEDELLIN | C2: 0004-0005 | D2: 5360 | E2: TA-25-1165179 | F2: 3007081728 | G2: APERTURA | H2: CB CRECIMIENTO ALIANZA - NUEVO | I2: ANTIOQUIA | J2: ITAGUI | K2: DISTRICOL RG | L2: BANCOLOMBIA | M2: FO-25-1624400 | FO-25-1611140 | P2: AGREGADOR | Q2: DISTRICOL | R2: EJECUTADO | EJECUTADO/CANCELADO | S2: 06/10/2025 SE INSTALA CORRESPONSAL OK | T2: VISITA TECNICA | V2: TIPO I | W2: TERRESTRE | X2: RUA ALVAREZ RICHARD ANDRES | Y2: 0 | Z2: 0 | AA2: 0 | AB2: 0 | AC2: 1 | AD2: 44560 | AE2: 44560
A5: MEDELLIN | C5: 0004-0005 | D5: 5360 | E5: TA-25-1165179 | F5: 3007081728 | G5: APERTURA | H5: CB CRECIMIENTO ALIANZA - NUEVO | I5: ANTIOQUIA | J5: ITAGUI | K5: DISTRICOL RG | L5: BANCOLOMBIA | M5: FO-25-1624400 | FO-25-1611140 | P5: AGREGADOR | Q5: DISTRICOL | R5: EJECUTADO | EJECUTADO/CANCELADO | S5: 06/10/2025 SE INSTALA CORRESPONSAL OK | T5: VISITA TECNICA | V5: TIPO I | W5: TERRESTRE | X5: RUA ALVAREZ RICHARD ANDRES | Y5: 200000 | Z5: 0 | AA5: 0 | AB5: 0 | AC5: 2 | AD5: 0 | AE5: 244560

Sheet TIPOLOGIAS
A1: COD. CIUDAD | B1: CIUDAD | C1: DEPARTAMENTO | D1: DESDE DONDE SE ATIENDE | E1: TIPO DE TRAYECTO NUEVO | F1: TIPOLOGIA NUEVA
A2: 91430 | B2: LA VICTORIA | C2: AMAZONAS | D2: BOGOTA | E2: AEREO | F2: TIPO IV ESPECIAL
A3: 91669 | B3: PUERTO SANTANDER | C3: AMAZONAS | D3: BOGOTA | E3: AEREO | F3: TIPO IV ESPECIAL
A4: 91263 | B4: EL ENCANTO | C4: AMAZONAS | D4: BOGOTA | E4: AEREO | F4: TIPO IV ESPECIAL
A5: 91405 | B5: LA CHORRERA | C5: AMAZONAS | D5: BOGOTA | E5: AEREO | F5: TIPO IV ESPECIAL
A6: 91407 | B6: LA PEDRERA | C6: AMAZONAS | D6: BOGOTA | E6: AEREO | F6: TIPO IV ESPECIAL
A7: 91001 | B7: LETICIA | C7: AMAZONAS | D7: BOGOTA | E7: AEREO | F7: TIPO IV ESPECIAL
A8: 91460 | B8: MIRITI - PARANA | C8: AMAZONAS | D8: BOGOTA | E8: AEREO | F8: TIPO IV ESPECIAL
A9: 91530 | B9: PUERTO ALEGRIA | C9: AMAZONAS | D9: BOGOTA | E9: AEREO | F9: TIPO IV ESPECIAL
A10: 91536 | B10: PUERTO ARICA | C10: AMAZONAS | D10: BOGOTA | E10: AEREO | F10: TIPO IV ESPECIAL
A11: 91540 | B11: PUERTO NARIÑO | C11: AMAZONAS | D11: BOGOTA | E11: AEREO | F11: TIPO IV ESPECIAL
A12: 91798 | B12: TARAPACA | C12: AMAZONAS | D12: BOGOTA | E12: AEREO | F12: TIPO IV ESPECIAL
A13: 5055 | B13: ARGELIA | C13: ANTIOQUIA | D13: MEDELLIN | E13: TERRESTRE | F13: TIPO IV
... A1124: 23682 | B1124: SAN JOSE DE URE | C1124: CORDOBA | D1124: MONTERIA | E1124: TERRESTRE | F1124: TIPO III

Sheet INCIDENTES
A1: CIUDAD SEDE | B1: COORDINADOR | C1: CENTRO DE COSTOS LÍNEACOM | D1: CÓDIGO DANE | E1: TA/CODIGO ACTIVIDAD | F1: CODIGO CB | G1: ACTIVIDAD | H1: DEPARTAMENTO | I1: CIUDAD | J1: NOMBRE DEL CB | K1: RED | L1: FO | M1: FECHA ASIGNACIÓN A LÍNEA COMUNICACIONES (DD/MM/AAAA HH:MM) | N1: FECHA CIERRE DEL TICKET (DD/MM/AAAA HH:MM) | O1: ACOMETIDA | P1: GRUPO_FALLA | Q1: CATEGORÍA | R1: FALLA | S1: FORMATO | T1: CADENA | U1: ESTADO | V1: OBSERVACION | W1: FORMA DE ATENCIÓN | X1: TERMINAL | Y1: TIPIFICACION | Z1: TIPO DE TRAYECTO | AA1: NOMBRE DEL TECNICO | AB1: DIAS DE VISITA | AC1: ACOMETIDA DATOS | AD1: ACOMETIDA ELÉCTRICA | AE1: SWITCH | AF1: VALOR DIAS ACTIVIDAD FACTURABLES | AG1: VALOR DIAS ACOMPAÑAMIENTO FACTURABLES
AF2: VALOR DIAS ACTIVIDAD FACTURABLES TC | AG2: VALOR DIAS ACOMPAÑAMIENTO FACTURABLES TC
A3: CIUDAD SEDE | B3: COORDINADOR | C3: CENTRO DE COSTOS LINEACOM | D3: CODIGO DANE | E3: TA/CODIGO ACTIVIDAD | F3: CODIGO CB | G3: ACTIVIDAD | H3: DEPARTAMENTO | I3: CIUDAD | J3: NOMBRE DEL CB | K3: RED | L3: FO | M3: FECHA ASIGNACION A LINEA COMUNICACIONES | N3: FECHA CIERRE DEL TICKET (DD/MM/AAAA HH:MM) | O3: ACOMETIDA DATOS | P3: GRUPO_FALLA | Q3: CATEGORIA | R3: FALLA | S3: FORMATO | T3: CADENA | U3: ESTADO | V3: OBSERVACIONES CLIENTE | W3: FORMA DE ATENCION | X3: TERMINAL(ES) | Y3: TIPIFICACION | Z3: TIPO DE TRAYECTO | AA3: NOMBRE DEL TECNICO | AB3: DIAS DE VISITA | AC3: ACOMETIDA DATOS | AD3: ACOMETIDA ELECTRICA | AE3: SWITCH | AF3: VALOR DIAS ACTIVIDAD FACTURABLES TE | AG3: VALOR DIAS ACOMPAÑAMIENTO FACTURABLES TE
A4: MEDELLIN | B4: =VLOOKUP(A4,'CENTRO DE COSTOS'!A:D,4,FALSE) -> JUAN SEBASTIÁN RÍOS CASTRILLÓN | C4: =VLOOKUP(A4,'CENTRO DE COSTOS'!A:D,2,FALSE) -> 0004-0005 | D4: 5001 | E4: 2538428 | F4: 75951 | G4: INCIDENTE | H4: ANTIOQUIA | I4: MEDELLIN | J4: BARRIO BELENCITO MEDELLIN | K4: REDEBAN | L4: FO-25-1315516 | M4: 45870.409 | N4: 45870.467 | O4: NO | P4: USUARIO | Q4: MANTENIMIENTO | R4: MANTENIMIENTO GENERAL | S4: CB UNO A UNO | T4: CB UNO A UNO | U4: CERRADO | V4: 01/08/2025 01-08 SE ESCALA PARA VISITA. LLAMAR ANTES DE VISITAR, CONFIRMAR FALLA Y DATOS | 01/08/2025 SE HACE MANTENIMIENTO DE EQUIPO | W4: VISITA_TÉCNICA | X4: FA09Z480 | Y4: TIPO I | Z4: TERRESTRE | AA4: MORENO MEDINA JUAN PABLO | AB4: 1 | AC4: 0 | AD4: 0 | AE4: 0 | AF4: =IF(W4="SOPORTE_TELEFÓNICO",'BASE LIQUIDACION'!$B$10,IF(Y4="TIPO I",'BASE LIQUIDACION'!$C$3,IF(Y4="TIPO II",'BASE LIQUIDACION'!$C$4,IF(Y4="TIPO III",'BASE LIQUIDACION'!$C$5,'BASE LIQUIDACION'!$C$7)))) -> 65960.474 | AG4: =IF(W4="SOPORTE_TELEFÓNICO",'BASE LIQUIDACION'!$B$10,(AB4*AF4+AC4*'BASE LIQUIDACION'!$B$12+AD4*'BASE LIQUIDACION'!$B$11+INCIDENTES!AE4*'BASE LIQUIDACION'!$B$13)) -> 65960.474
