Workbook
Name ACTIVIDAD: [1]Hoja2!$P$2:$P$30
Name Clientes: [2]Clientes!$A$2:$A$100
Name COORDINADOR: [1]Hoja2!$D$2:$D$30
Name Coordinadores: [3]Coordinadores!$A$2:$A$1000
Name DOCUMENTADOR: [1]Hoja2!$A$2:$A$30
Name ES: [1]Hoja2!$K$2:$K$30
Name ESS: [1]Hoja2!$K$2:$K$30
Name Estado: [2]Formulas!$K$2:$K$5000
Name ESTADOACTIVIDAD: [1]Hoja2!$M$2:$M$30
Name ESTADOSCIERRES: '[4]lista desplegable'!$CX$1:$DA$1
Name Facturacion: '[5]Listas desplegables'!$AO$1:$AR$1
Name solicitudes: '[5]Listas desplegables'!$U$1:$AF$1
Name Tecnicos: [2]Tecnicos!$A$2:$A$1000

Sheet RESUMEN
A1: LÍNEA COMUNICACIONES S.A.S | F1: FACTURACIÓN CORRESPONSALES BANCARIOS TIQUIETES AÉREOS
A2: FACTURACIÓN VISITAS FALLIDAS CORRESPONSALES BANCARIOS | F2: =A3 -> AGOSTO 2025
A3: AGOSTO 2025
F4: CONCEPTOS | G4: TRAYECTOS | H4: TOTAL | I4: % ADMINISTRACIÓN | J4: TOTAL
A5: CONCEPTOS | B5: CANT | D5: TOTAL | F5: ORDEN DE CAMBIO TA-25-941590 | G5: PASTO-MOGUI-PASTO | H5: 300000 | I5: =H5*0.12 -> 36000 | J5: =H5+I5 -> 336000
A6: =CONCATENATE("CIERRES NO EXITOSOS ",A3) -> CIERRES NO EXITOSOS AGOSTO 2025 | B6: =COUNTA(CIERRES!A:A)-1 -> 105 | D6: =CIERRES!AD107 -> 11052804 | I6: =H6*0.12 -> 0 | J6: =H6+I6 -> 0
A7: TIQUETES | B7: 1 | D7: =J10 -> 336000 | I7: =H7*0.12 -> 0 | J7: =H7+I7 -> 0
A8: SUBTOTAL | D8: =SUM(D6:D7) -> 11388804
A9: IVA | D9: =D8*0.19 -> 2163872.8
A10: TOTAL | D10: =SUM(D8:D9) -> 13552677 | F10: TOTAL | H10: =SUM(H5:H7) -> 300000 | I10: =SUM(I5:I7) -> 36000 | J10: =SUM(J5:J7) -> 336000

Sheet BASE DE LIQUIDACION 2025
A1: CIERRE CB - VISITAS FALLIDAS O CIERRES NO EXITOSOS TARIFAS 2024 | D1: Incremento 2025
A2: Tipificación | B2: Descripción | C2: Tarifa | D2: 0.052
A3: Tipo I | B3: Metropolitano | C3: =42357*(1+$D$2) -> 44559.564
A4: Tipo II | B4: Hasta 3 horas | C4: =127767*(1+$D$2) -> 134410.88
A5: Tipo III | B5: De 3 a 5 horas | C5: =211886*(1+$D$2) -> 222904.07
A6: Tipo IV | B6: Más de 5 horas | C6: =441834*(1+$D$2) -> 464809.37
A7: Trayecto Especial | B7: No incluye valor del Tiquete | C7: Valor de actividad Tipo IV + Valor tiquete aéreo (o fluvial) + 12% administración)
A9: Gestión telefonica | B9: =36031*(1+$D$2) -> 37904.612

Sheet Tabla Dinámica
A3: COORDINADOR | B3: CENTRO DE COSTOS LÍNEACOM | C3: % | D3: Suma de VALOR TOTAL2 | E3: NOMBRE CC
A4: DIEGO FERNANDO HENAO CARDONA | B4: 0004-0002 | C4: 0.024321589 | D4: 268821.77 | E4: =VLOOKUP(B4,'CENTRO DE COSTOS'!B:C,2,0) -> Redeban Eje Cafetero (Pereira)
B5: 0004-0003 | C5: 0.26918057 | D5: 2975200.1 | E5: =VLOOKUP(B5,'CENTRO DE COSTOS'!B:C,2,0) -> Redeban Suroccidente (Cali)
A6: JOSE MAURICIO HERNANDEZ ROJAS | B6: 0004-0001 | C6: 0.11350208 | D6: 1254516.3 | E6: =VLOOKUP(B6,'CENTRO DE COSTOS'!B:C,2,0) -> Redeban Costa (Barranqullla)
A7: JUAN SEBASTIÁN RÍOS CASTRILLÓN | B7: 0004-0005 | C7: 0.20171451 | D7: 2229511 | E7: =VLOOKUP(B7,'CENTRO DE COSTOS'!B:C,2,0) -> Redeban Noroccidente (Medellín)
A8: KEVIN ALEXIS CORZO BUSTOS | B8: 0004-0007 | C8: 0.14918363 | D8: 1648897.4 | E8: =VLOOKUP(B8,'CENTRO DE COSTOS'!B:C,2,0) -> Redeban Oriente (Otros)
A9: MIGUEL JULIÁN HERNÁNDEZ GUARÍN | B9: 0004-0008 | C9: 0.10481772 | D9: 1158529.7 | E9: =VLOOKUP(B9,'CENTRO DE COSTOS'!B:C,2,0) -> Redeban Santander
A10: WILLIAM ASDRUBAL ROZO ROZO | B10: 0004-0004 | C10: 0.13727991 | D10: 1517328 | E10: =VLOOKUP(B10,'CENTRO DE COSTOS'!B:C,2,0) -> Redeban Centro ( Bogotá)
A11: Total general | C11: 1 | D11: 11052804

Sheet CIERRES
A1: CIUDAD SEDE | B1: COORDINADOR | C1: CENTRO DE COSTOS LÍNEACOM | D1: CÓDIGO DANE | E1: TA/CODIGO ACTIVIDAD | F1: CODIGO CB | G1: ACTIVIDAD | H1: DEPARTAMENTO | I1: CIUDAD | J1: NOMBRE DEL CB | K1: RED | L1: FO | M1: FECHA ASIGNACION A LINEA COMUNICACIONES | N1: FECHA DEL CIERRE DEL TICKET (DD/MM/AAAA) | O1: ACOMETIDA | P1: SOLICITUD | Q1: DESCRIPCIÓN | R1: FORMATO | S1: CADENA | T1: ESTADO | U1: CAUSAL ESTADO | V1: OBSERVACION | W1: FORMA DE ATENCIÓN | X1: TERMINAL | Y1: TIPIFICACION | Z1: TIPO DE TRAYECTO | AA1: NOMBRE DEL TECNICO | AB1: DIAS DE VISITA | AC1: VALOR ACTIVIDAD | AD1: VALOR TOTAL
A2: APARTADO | B2: =VLOOKUP(A2,'CENTRO DE COSTOS'!A:D,4,FALSE) -> JUAN SEBASTIÁN RÍOS CASTRILLÓN | C2: =VLOOKUP(A2,'CENTRO DE COSTOS'!A:C,2,FALSE) -> 0004-0005 | D2: 27615 | E2: TA-25-899476 | F2: 58825 | G2: ORDEN DE CAMBIO | H2: CHOCO | I2: RIOSUCIO | J2: DISTRICOL MAYORISTA LA BODEGA | K2: REDEBAN | L2: FO-25-1297516 | M2: 45867.333 | N2: 45870.398 | P2: CIERRE | Q2: CIERRE | R2: AGREGADOR | S2: DISTRICOL | T2: NO_EXITOSO | U2: CB NO ENTREGA EQUIPO | V2: 0 0 01-08-2025 SE LLAMA AL CLIENTE PARA AVISAR QUE VAMOS HACER LA VISITA Y NOS INFORMA QUE EN LA VEREDA A LLOVIDO MUCHO Y QUE ESTA DIFICIL EL ACCESO HASTA EL CASERIO DE IGUAL FORMA NOS MANIFESTO QUE EL NO A SOLICITADO EL CIERRE Y QUE NO SE ENCUENTRA EN LA VDA. SE LE INFORMA QUE SE COMUNIQUE AL BANCO. EL USUARIO NO ENTREGARA EQUIPOS HASTA QUE EL HABLE CON EL BANCO PARA ACLARAR EL PORQUE LE ESTAN CERRANDO EL CB | W2: SOPORTE_TELEFÓNICO | X2: 0 | Y2: TIPO IV ESPECIAL | Z2: =VLOOKUP(D2,TIPOLOGIAS!A:F,5,0) -> TERRESTRE/FLUVIAL | AA2: SALDARRIAGA MIRANDA SANTIAGO | AB2: 0 | AC2: =IF(AND(W2="SOPORTE_TELEFÓNICO",OR(U2="SIN CONTACTO CON EL CB",U2="NÚMEROS DE CONTACTO ERRADOS")),0,IF(W2="SOPORTE_TELEFÓNICO",'BASE DE LIQUIDACION 2025'!$B$9,IF(Y2="TIPO I",'BASE DE LIQUIDACION 2025'!$C$3,IF(Y2="TIPO II",'BASE DE LIQUIDACION 2025'!$C$4,IF(Y2="TIPO III",'BASE DE LIQUIDACION 2025'!$C$5,'BASE DE LIQUIDACION 2025'!$C$6))))) -> 37904.612 | AD2: =IF(W2="SOPORTE_TELEFÓNICO",AC2,CIERRES!AB2*CIERRES!AC2) -> 37904.612
A3: CALI | B3: =VLOOKUP(A3,'CENTRO DE COSTOS'!A:D,4,FALSE) -> DIEGO FERNANDO HENAO CARDONA | C3: =VLOOKUP(A3,'CENTRO DE COSTOS'!A:C,2,FALSE) -> 0004-0003 | D3: 76001 | E3: TA-25-906330 | F3: 69764 | G3: ORDEN DE CAMBIO | H3: VALLE DEL CAUCA | I3: CALI | J3: BARRIO ALCAZAREZ CALI | K3: REDEBAN | L3: FO-25-1308290 | M3: 45868.666 | N3: 45870.415 | P3: CIERRE | Q3: CIERRE | R3: CB UNO A UNO | S3: CB UNO A UNO | T3: NO_EXITOSO | U3: CB NO ENTREGA EQUIPO | V3: 0 0 01-08-2025 SE LLEGA AL COMERCIO SE HABLA CON EL CLIENTE E INDICA QUE EL NO A SOLICITADO EL CIERRE Y QUE NO SE LE A NOTIFICADO QUE VA HABLAR CON EL BANCO PARA VALIDAR | W3: VISITA_TÉCNICA | X3: NN000790 | Y3: TIPO I | Z3: =VLOOKUP(D3,TIPOLOGIAS!A:F,5,0) -> TERRESTRE | AA3: CUERO RUIZ JHONNY | AB3: 1 | AC3: =IF(AND(W3="SOPORTE_TELEFÓNICO",OR(U3="SIN CONTACTO CON EL CB",U3="NÚMEROS DE CONTACTO ERRADOS")),0,IF(W3="SOPORTE_TELEFÓNICO",'BASE DE LIQUIDACION 2025'!$B$9,IF(Y3="TIPO I",'BASE DE LIQUIDACION 2025'!$C$3,IF(Y3="TIPO II",'BASE DE LIQUIDACION 2025'!$C$4,IF(Y3="TIPO III",'BASE DE LIQUIDACION 2025'!$C$5,'BASE DE LIQUIDACION 2025'!$C$6))))) -> 44559.564 | AD3: =IF(W3="SOPORTE_TELEFÓNICO",AC3,CIERRES!AB3*CIERRES!AC3) -> 44559.564
A4: VILLAVICENCIO | B4: =VLOOKUP(A4,'CENTRO DE COSTOS'!A:D,4,FALSE) -> KEVIN ALEXIS CORZO BUSTOS | C4: =VLOOKUP(A4,'CENTRO DE COSTOS'!A:C,2,FALSE) -> 0004-0007 | D4: 50568 | E4: TA-25-903370 | F4: 72483 | G4: ORDEN DE CAMBIO | H4: META | I4: PUERTO GAITAN | J4: BARRIO PUERTO GAITAN BATEAS | K4: REDEBAN | L4: FO-25-1303399 | M4: 45868.333 | N4: 45870.417 | P4: CIERRE | Q4: RECUPERACION DE EQUIPOS | R4: CB UNO A UNO | S4: CB UNO A UNO | T4: ILOCALIZADO | U4: CB CERRADO - DESOCUPADO | V4: 0 0 01-08-2025 SE REALIZA VISITA A COMERCIO CB NO EXISTE NO ES POSIBLE COMUNICACIÓN CON TITULAR ILOCALIZABLE | W4: VISITA_TÉCNICA | X4: 0 | Y4: TIPO III | Z4: =VLOOKUP(D4,TIPOLOGIAS!A:F,5,0) -> TERRESTRE | AA4: CASTRILLON URREA LONDIER LEANDRO | AB4: 1 | AC4: =IF(AND(W4="SOPORTE_TELEFÓNICO",OR(U4="SIN CONTACTO CON EL CB",U4="NÚMEROS DE CONTACTO ERRADOS")),0,IF(W4="SOPORTE_TELEFÓNICO",'BASE DE LIQUIDACION 2025'!$B$9,IF(Y4="TIPO I",'BASE DE LIQUIDACION 2025'!$C$3,IF(Y4="TIPO II",'BASE DE LIQUIDACION 2025'!$C$4,IF(Y4="TIPO III",'BASE DE LIQUIDACION 2025'!$C$5,'BASE DE LIQUIDACION 2025'!$C$6))))) -> 222904.07 | AD4: =IF(W4="SOPORTE_TELEFÓNICO",AC4,CIERRES!AB4*CIERRES!AC4) -> 222904.07
A5: IBAGUE | B5: =VLOOKUP(A5,'CENTRO DE COSTOS'!A:D,4,FALSE) -> KEVIN ALEXIS CORZO BUSTOS | C5: =VLOOKUP(A5,'CENTRO DE COSTOS'!A:C,2,FALSE) -> 0004-0007 | D5: 73671 | E5: TA-25-906329 | F5: 62416 | G5: ORDEN DE CAMBIO | H5: TOLIMA | I5: SALDAÑA | J5: BARRIO VIA SALDANA GUAMO SALDA | K5: REDEBAN | L5: FO-25-1308287 | M5: 45868.666 | N5: 45870.463 | P5: CIERRE | Q5: CIERRE | R5: CB UNO A UNO | S5: CB UNO A UNO | T5: NO_EXITOSO | U5: CB NO ENTREGA EQUIPO | V5: 0 0 01-08-2025 SE LLAMA A LA SEÑORA BIBIANA GOMEZ AL NÚMERO DE TELÉFONO 3124662530, ME INDICA QUE ELLA NO VA A ENTREGAR EQUIPOS PORQUE ESTÁ ESPERANDO LA CARTA DE RETIRO DE EFECTY PARA CONTINUAR CON EL CORRESPONSAL. QUE ELLA ESTÁ EN CONTACTO CON LA ASESORA DE BANCOLOMBIA PARA SEGUIR CON EL CORRESPONSAL. | W5: SOPORTE_TELEFÓNICO | X5: 0 | Y5: TIPO II | Z5: =VLOOKUP(D5,TIPOLOGIAS!A:F,5,0) -> TERRESTRE | AA5: VARGAS HERRERA JHON JAIRO | AB5: 0 | AC5: =IF(AND(W5="SOPORTE_TELEFÓNICO",OR(U5="SIN CONTACTO CON EL CB",U5="NÚMEROS DE CONTACTO ERRADOS")),0,IF(W5="SOPORTE_TELEFÓNICO",'BASE DE LIQUIDACION 2025'!$B$9,IF(Y5="TIPO I",'BASE DE LIQUIDACION 2025'!$C$3,IF(Y5="TIPO II",'BASE DE LIQUIDACION 2025'!$C$4,IF(Y5="TIPO III",'BASE DE LIQUIDACION 2025'!$C$5,'BASE DE LIQUIDACION 2025'!$C$6))))) -> 37904.612 | AD5: =IF(W5="SOPORTE_TELEFÓNICO",AC5,CIERRES!AB5*CIERRES!AC5) -> 37904.612
A6: MEDELLIN | B6: =VLOOKUP(A6,'CENTRO DE COSTOS'!A:D,4,FALSE) -> JUAN SEBASTIÁN RÍOS CASTRILLÓN | C6: =VLOOKUP(A6,'CENTRO DE COSTOS'!A:C,2,FALSE) -> 0004-0005 | D6: 5059 | E6: TA-25-917392 | F6: 16613 | G6: ORDEN DE CAMBIO | H6: ANTIOQUIA | I6: ARMENIA | J6: 366 SAN DIEGO PLAZA OLIMPICA | K6: REDEBAN | L6: FO-25-1322151 | M6: 45868.666 | N6: 45870.497 | P6: CIERRE | Q6: RECUPERACION DE EQUIPOS | R6: RETAIL | S6: OLIMPICA | T6: EJECUTADO_EXITOSO | U6: CIERRE EXITOSO | V6: SE REALIZA COMUNICACIÓN CON USUARIO. SE HABLA CON LILIANA GUIZA AL NÚMERO 3203261426. INDICA QUE LA SEMANA PASADA YA LE REALIZARON RETIRO DE EQUIPOS Y QUE YA NO TIENE MAS POR ENTREGAR DEL PUNTO 16613.SE ESCALA A LA RED //1/08 11:55 RESPUESTA DE LA RED: SE DOCUMENTA CASO: EJECUTADO EXITOSO. LA RECUPERACIÓN DE EQUIPOS FUE REALIZADA POR MEDIO DE LA GESTORÍA DE REDEBAN** RESPUESTA DE LA RED 0 | W6: SOPORTE_TELEFÓNICO | X6: 0 | Y6: TIPO II | Z6: =VLOOKUP(D6,TIPOLOGIAS!A:F,5,0) -> TERRESTRE | AA6: 0 | AB6: 0 | AC6: =IF(AND(W6="SOPORTE_TELEFÓNICO",OR(U6="SIN CONTACTO CON EL CB",U6="NÚMEROS DE CONTACTO ERRADOS")),0,IF(W6="SOPORTE_TELEFÓNICO",'BASE DE LIQUIDACION 2025'!$B$9,IF(Y6="TIPO I",'BASE DE LIQUIDACION 2025'!$C$3,IF(Y6="TIPO II",'BASE DE LIQUIDACION 2025'!$C$4,IF(Y6="TIPO III",'BASE DE LIQUIDACION 2025'!$C$5,'BASE DE LIQUIDACION 2025'!$C$6))))) -> 37904.612 | AD6: =IF(W6="SOPORTE_TELEFÓNICO",AC6,CIERRES!AB6*CIERRES!AC6) -> 37904.612
A7: BOGOTA | B7: =VLOOKUP(A7,'CENTRO DE COSTOS'!A:D,4,FALSE) -> WILLIAM ASDRUBAL ROZO ROZO | C7: =VLOOKUP(A7,'CENTRO DE COSTOS'!A:C,2,FALSE) -> 0004-0004 | D7: 11001 | E7: TA-25-906294 | F7: 56731 | G7: ORDEN DE CAMBIO | H7: CUNDINAMARCA | I7: BOGOTA | J7: DISTRICOL VARIEDADES TIN | K7: REDEBAN | L7: FO-25-1308178 | M7: 45868.666 | N7: 45870.582 | P7: CIERRE | Q7: CIERRE | R7: AGREGADOR | S7: DISTRICOL | T7: ILOCALIZADO | U7: CB CERRADO - DESOCUPADO | V7: 0 0 01-08-2025 DURANTE LA VISITA DE TECNICA PARA ATENDER CIERRE DE CORRESPONSAL BANCARIO LO CUAL NO ES POSIBLE PORQUE COMERCIO SE ENCUENTRA CERRADO Y NO SE EVIDENCIA LA EXISTENCIA DEL CB SE LLAMA AL CELULAR 3505304343 EL CUAL SE ENCUENTRA APAGADO SE PROCEDE AL CIERRE DE LA ACTIVIDAD | W7: VISITA_TÉCNICA | X7: 0 | Y7: TIPO I | Z7: =VLOOKUP(D7,TIPOLOGIAS!A:F,5,0) -> TERRESTRE | AA7: GALEANO SORIANO JUAN DAVID | AB7: 1 | AC7: =IF(AND(W7="SOPORTE_TELEFÓNICO",OR(U7="SIN CONTACTO CON EL CB",U7="NÚMEROS DE CONTACTO ERRADOS")),0,IF(W7="SOPORTE_TELEFÓNICO",'BASE DE LIQUIDACION 2025'!$B$9,IF(Y7="TIPO I",'BASE DE LIQUIDACION 2025'!$C$3,IF(Y7="TIPO II",'BASE DE LIQUIDACION 2025'!$C$4,IF(Y7="TIPO III",'BASE DE LIQUIDACION 2025'!$C$5,'BASE DE LIQUIDACION 2025'!$C$6))))) -> 44559.564 | AD7: =IF(W7="SOPORTE_TELEFÓNICO",AC7,CIERRES!AB7*CIERRES!AC7) -> 44559.564
A8: BOGOTA | B8: =VLOOKUP(A8,'CENTRO DE COSTOS'!A:D,4,FALSE) -> WILLIAM ASDRUBAL ROZO ROZO | C8: =VLOOKUP(A8,'CENTRO DE COSTOS'!A:C,2,FALSE) -> 0004-0004 | D8: 25817 | E8: TA-25-906311 | F8: 15820 | G8: ORDEN DE CAMBIO | H8: CUNDINAMARCA | I8: TOCANCIPA | J8: BARRIO VD LA FUENTE TOCANCIPA | K8: REDEBAN | L8: FO-25-1308234 | M8: 45868.666 | N8: 45870.607 | P8: CIERRE | Q8: CIERRE | R8: CB UNO A UNO | S8: CB UNO A UNO | T8: NO_EXITOSO | U8: CB NO ENTREGA EQUIPO | V8: 0 0 01-08-2025 CIERRE FALLIDO CLIENTE NO REALIZA ENTREGA DE LOS. EQUIPOS POR QUÉ NO LE HABÍA. AVISADO DEL CIERRE. DEL CB Y APARTE MANIFIESTA ESTAR EN UN PROCESO DE CONCILIACIÓN CON EL BANCO | W8: VISITA_TÉCNICA | X8: 7ZZZZ964 | Y8: TIPO II | Z8: =VLOOKUP(D8,TIPOLOGIAS!A:F,5,0) -> TERRESTRE | AA8: HERNANDEZ NARANJO OSCAR EDUARDO | AB8: 1 | AC8: =IF(AND(W8="SOPORTE_TELEFÓNICO",OR(U8="SIN CONTACTO CON EL CB",U8="NÚMEROS DE CONTACTO ERRADOS")),0,IF(W8="SOPORTE_TELEFÓNICO",'BASE DE LIQUIDACION 2025'!$B$9,IF(Y8="TIPO I",'BASE DE LIQUIDACION 2025'!$C$3,IF(Y8="TIPO II",'BASE DE LIQUIDACION 2025'!$C$4,IF(Y8="TIPO III",'BASE DE LIQUIDACION 2025'!$C$5,'BASE DE LIQUIDACION 2025'!$C$6))))) -> 134410.88 | AD8: =IF(W8="SOPORTE_TELEFÓNICO",AC8,CIERRES!AB8*CIERRES!AC8) -> 134410.88
A9: TUNJA | B9: =VLOOKUP(A9,'CENTRO DE COSTOS'!A:D,4,FALSE) -> MIGUEL JULIÁN HERNÁNDEZ GUARÍN | C9: =VLOOKUP(A9,'CENTRO DE COSTOS'!A:C,2,FALSE) -> 0004-0008 | D9: 15001 | E9: TA-25-906307 | F9: 62298 | G9: ORDEN DE CAMBIO | H9: BOYACA | I9: TUNJA | J9: BARRIO COEDUCADORES TUNJA 1 | K9: REDEBAN | L9: FO-25-1317256 | M9: 45868.666 | N9: 45870.695 | P9: CIERRE | Q9: CIERRE | R9: CB UNO A UNO | S9: CB UNO A UNO | T9: NO_EXITOSO | U9: CB NO ENTREGA EQUIPO | V9: 0 0 01-08-2025 SE VISITA PUNTO ENCONTRANDO EL COMERCIO CERRADO NÚMERO DE CONTACTO REGISTRADO FUERA DE SERVICIO SE GESTIONAN NÚMEROS EN VISITAS ANTERIORES SE LOGRA CONTACTO CON LA SEÑORA MARGARITA SUÁREZ QUIEN INDICA QUE SE ENCUENTRA REALIZANDO UNAS DILIGENCIAS PERSONALES INFORMA POSIBLE HORA DE ENTREGA EN HORAS PM EL DÍA DE HOY. 0 01-08-2025 SE VISITA PUNTO CLIENTE NO AUTORIZA EL RETIRO DE LOS EQUIPOS INDICAN QUE EL ASESOR DE LA ENTIDAD ESCALÓ EL CASO PARA QUE HABILITEN NUEVAMENTE EL CORRESPONSAL BANCARIO. | W9: VISITA_TÉCNICA | X9: OA00C217 | Y9: TIPO I | Z9: =VLOOKUP(D9,TIPOLOGIAS!A:F,5,0) -> TERRESTRE | AA9: RODRIGUEZ MURCIA YERSON IVAN | AB9: 1 | AC9: =IF(AND(W9="SOPORTE_TELEFÓNICO",OR(U9="SIN CONTACTO CON EL CB",U9="NÚMEROS DE CONTACTO ERRADOS")),0,IF(W9="SOPORTE_TELEFÓNICO",'BASE DE LIQUIDACION 2025'!$B$9,IF(Y9="TIPO I",'BASE DE LIQUIDACION 2025'!$C$3,IF(Y9="TIPO II",'BASE DE LIQUIDACION 2025'!$C$4,IF(Y9="TIPO III",'BASE DE LIQUIDACION 2025'!$C$5,'BASE DE LIQUIDACION 2025'!$C$6))))) -> 44559.564 | AD9: =IF(W9="SOPORTE_TELEFÓNICO",AC9,CIERRES!AB9*CIERRES!AC9) -> 44559.564
A10: BOGOTA | B10: =VLOOKUP(A10,'CENTRO DE COSTOS'!A:D,4,FALSE) -> WILLIAM ASDRUBAL ROZO ROZO | C10: =VLOOKUP(A10,'CENTRO DE COSTOS'!A:C,2,FALSE) -> 0004-0004 | D10: 11001 | E10: TA-25-906335 | F10: 58581 | G10: ORDEN DE CAMBIO | H10: CUNDINAMARCA | I10: BOGOTA | J10: BARRIO QUIRIGUA BOGOTQA | K10: REDEBAN | L10: FO-25-1308309 | M10: 45868.666 | N10: 45870.762 | P10: CIERRE | Q10: CIERRE | R10: CB UNO A UNO | S10: CB UNO A UNO | T10: NO_EXITOSO | U10: CB NO ENTREGA EQUIPO | V10: 0 0 01-08-2025 SE REALIZA VISITA A DIRECCIÓN DE COMERCIO, PERSONA QUE ATIENDE INDICA QUE LA SRA. YOVANA ANDREA GALLEGO LE VENDIÓ EL NEGOCIO, SE REALIZA LLAMADA TELEFÓNICA SE HABLA CON LA CLIENTE Y SE LE INDICA QUE DEBE COMUNICARSE A LA LÍNEA DE CORRESPONSAL BANCOLOMBIA Y SOLICITAR CITA PARA LA ENTREGA DE LOS EQUIPOS EN LA DIRECCIÓN DONDE LOS TENGA. | W10: VISITA_TÉCNICA | X10: 0 | Y10: TIPO I | Z10: =VLOOKUP(D10,TIPOLOGIAS!A:F,5,0) -> TERRESTRE | AA10: MURCIA HERNANDEZ HARVEY IGNACIO | AB10: 1 | AC10: =IF(AND(W10="SOPORTE_TELEFÓNICO",OR(U10="SIN CONTACTO CON EL CB",U10="NÚMEROS DE CONTACTO ERRADOS")),0,IF(W10="SOPORTE_TELEFÓNICO",'BASE DE LIQUIDACION 2025'!$B$9,IF(Y10="TIPO I",'BASE DE LIQUIDACION 2025'!$C$3,IF(Y10="TIPO II",'BASE DE LIQUIDACION 2025'!$C$4,IF(Y10="TIPO III",'BASE DE LIQUIDACION 2025'!$C$5,'BASE DE LIQUIDACION 2025'!$C$6))))) -> 44559.564 | AD10: =IF(W10="SOPORTE_TELEFÓNICO",AC10,CIERRES!AB10*CIERRES!AC10) -> 44559.564
A11: BOGOTA | B11: =VLOOKUP(A11,'CENTRO DE COSTOS'!A:D,4,FALSE) -> WILLIAM ASDRUBAL ROZO ROZO | C11: =VLOOKUP(A11,'CENTRO DE COSTOS'!A:C,2,FALSE) -> 0004-0004 | D11: 11001 | E11: TA-25-906337 | F11: 74001 | G11: ORDEN DE CAMBIO | H11: CUNDINAMARCA | I11: BOGOTA | J11: BARRIO ALAMOS BOGOTA 9 | K11: REDEBAN | L11: FO-25-1308315 | M11: 45868.666 | N11: 45870.772 | P11: CIERRE | Q11: CIERRE | R11: CB UNO A UNO | S11: CB UNO A UNO | T11: ILOCALIZADO | U11: CB CERRADO - DESOCUPADO | V11: 0 0 01-08-2025 SE REALIZA DESPLAZAMIENTO A DIRECCIÓN DE COMERCIO, COMERCIO NO EXISTE, TELÉFONO DE CONTACTO NO FUNCIONA. | W11: VISITA_TÉCNICA | X11: 0 | Y11: TIPO I | Z11: =VLOOKUP(D11,TIPOLOGIAS!A:F,5,0) -> TERRESTRE | AA11: MURCIA HERNANDEZ HARVEY IGNACIO | AB11: 1 | AC11: =IF(AND(W11="SOPORTE_TELEFÓNICO",OR(U11="SIN CONTACTO CON EL CB",U11="NÚMEROS DE CONTACTO ERRADOS")),0,IF(W11="SOPORTE_TELEFÓNICO",'BASE DE LIQUIDACION 2025'!$B$9,IF(Y11="TIPO I",'BASE DE LIQUIDACION 2025'!$C$3,IF(Y11="TIPO II",'BASE DE LIQUIDACION 2025'!$C$4,IF(Y11="TIPO III",'BASE DE LIQUIDACION 2025'!$C$5,'BASE DE LIQUIDACION 2025'!$C$6))))) -> 44559.564 | AD11: =IF(W11="SOPORTE_TELEFÓNICO",AC11,CIERRES!AB11*CIERRES!AC11) -> 44559.564
A12: BUCARAMANGA | B12: =VLOOKUP(A12,'CENTRO DE COSTOS'!A:D,4,FALSE) -> MIGUEL JULIÁN HERNÁNDEZ GUARÍN | C12: =VLOOKUP(A12,'CENTRO DE COSTOS'!A:C,2,FALSE) -> 0004-0008 | D12: 68235 | E12: TA-25-906324 | F12: 78424 | G12: ORDEN DE CAMBIO | H12: SANTANDER | I12: EL CARMEN DE CHUCURI | J12: BARRIO CENTRO EL CARMEN DE CHUCURI 2 | K12: REDEBAN | L12: FO-25-1308273 | M12: 45868.666 | N12: 45871.381 | P12: CIERRE | Q12: CIERRE | R12: CB UNO A UNO | S12: CB UNO A UNO | T12: NO_EXITOSO | U12: CB NO ENTREGA EQUIPO | V12: 0 01/08/2025 NO SE LOGRA COMUNICACIÓN CON LA LÍNEA SUMINISTRADA 3125576328, SE TRATA DE REALIZAR LLAMADA Y NO CONTESTA, SE DEJA MENSAJE VÍA CHAT SIN RESPUESTA POR PARTE DEL CLIENTE, SE LE INFORMA A COORDINADOR. 01/08/2025 NO SE LOGRA COMUNICACIÓN CON LA LÍNEA SUMINISTRADA 3125576328-3125249927 , SE TRATA DE REALIZAR LLAMADA Y NO CONTESTA, SE DEJA MENSAJE VÍA CHAT SIN RESPUESTA POR PARTE DEL CLIENTE, SE LE INFORMA A COORDINADOR. 02-08-2025 EN COMUNICACIÓN CON LA SEÑORA YEIMI VÍA CHAT A LA LINEA 3125576328, INDICA QUE VA HABLAR CON EL ASESOR PARA PODER GESTIONAR LA REACTIVACION DEL SERVICIO,SE LE INFORMA QUE TENDRÁ QUE GESTIONAR UNA NUEVA VISITA PARA RECOGER LOS EQUIPOS EN DADO CASO NO SE PUEDA REACTIVAR EL CB. | W12: SOPORTE_TELEFÓNICO | X12: 0 | Y12: TIPO IV | Z12: =VLOOKUP(D12,TIPOLOGIAS!A:F,5,0) -> TERRESTRE | AA12: SANTOS GONZALEZ JOHAN FABIAN | AB12: 0 | AC12: =IF(AND(W12="SOPORTE_TELEFÓNICO",OR(U12="SIN CONTACTO CON EL CB",U12="NÚMEROS DE CONTACTO ERRADOS")),0,IF(W12="SOPORTE_TELEFÓNICO",'BASE DE LIQUIDACION 2025'!$B$9,IF(Y12="TIPO I",'BASE DE LIQUIDACION 2025'!$C$3,IF(Y12="TIPO II",'BASE DE LIQUIDACION 2025'!$C$4,IF(Y12="TIPO III",'BASE DE LIQUIDACION 2025'!$C$5,'BASE DE LIQUIDACION 2025'!$C$6))))) -> 37904.612 | AD12: =IF(W12="SOPORTE_TELEFÓNICO",AC12,CIERRES!AB12*CIERRES!AC12) -> 37904.612
A13: BOGOTA | B13: =VLOOKUP(A13,'CENTRO DE COSTOS'!A:D,4,FALSE) -> WILLIAM ASDRUBAL ROZO ROZO | C13: =VLOOKUP(A13,'CENTRO DE COSTOS'!A:C,2,FALSE) -> 0004-0004 | D13: 11001 | E13: TA-25-906334 | F13: 57327 | G13: ORDEN DE CAMBIO | H13: CUNDINAMARCA | I13: BOGOTA | J13: BARRIO PINAR BOGOTA | K13: REDEBAN | L13: FO-25-1308307 | M13: 45868.666 | N13: 45871.485 | P13: CIERRE | Q13: CIERRE | R13: CB UNO A UNO | S13: CB UNO A UNO | T13: NO_EXITOSO | U13: CB NO ENTREGA EQUIPO | V13: 0 02/08/2025 SE LLAGA A LA DIRECCIÓN CLIENTE MANIFIESTA QUE BANCOLOMBIA TIENE UN SALDO DE EL Y QUE CON BANCOLOMBIA SE HABIA LLEGADO AL ACUERDO QUE CUANDO LE RETORNARAN EL SALDO SE RECOJIAN LOS EQUIPOS ENTONCES NO ENTREGA EQUIPOS 02-08-2025 SE LLAGA A LA DIRECCIÓN CLIENTE MANIFIESTA QUE BANCOLOMBIA TIENE UN SALDO DE EL Y QUE CON BANCOLOMBIA SE HABIA LLEGADO AL ACUERDO QUE CUANDO LE RETORNARAN EL SALDO SE RECOJIAN LOS EQUIPOS ENTONCES NO ENTREGA EQUIPOS. NO DA MAS INFORMACIÓN. | W13: VISITA_TÉCNICA | X13: 0 | Y13: TIPO I | Z13: =VLOOKUP(D13,TIPOLOGIAS!A:F,5,0) -> TERRESTRE | AA13: SOTO MUNAR DYLAN DAVID | AB13: 1 | AC13: =IF(AND(W13="SOPORTE_TELEFÓNICO",OR(U13="SIN CONTACTO CON EL CB",U13="NÚMEROS DE CONTACTO ERRADOS")),0,IF(W13="SOPORTE_TELEFÓNICO",'BASE DE LIQUIDACION 2025'!$B$9,IF(Y13="TIPO I",'BASE DE LIQUIDACION 2025'!$C$3,IF(Y13="TIPO II",'BASE DE LIQUIDACION 2025'!$C$4,IF(Y13="TIPO III",'BASE DE LIQUIDACION 2025'!$C$5,'BASE DE LIQUIDACION 2025'!$C$6))))) -> 44559.564 | AD13: =IF(W13="SOPORTE_TELEFÓNICO",AC13,CIERRES!AB13*CIERRES!AC13) -> 44559.564
A14: BOGOTA | B14: =VLOOKUP(A14,'CENTRO DE COSTOS'!A:D,4,FALSE) -> WILLIAM ASDRUBAL ROZO ROZO | C14: =VLOOKUP(A14,'CENTRO DE COSTOS'!A:C,2,FALSE) -> 0004-0004 | D14: 11001 | E14: TA-25-899547 | F14: 70302 | G14: ORDEN DE CAMBIO | H14: CUNDINAMARCA | I14: BOGOTA | J14: PTM BOGOTA DISTRI CASTEL SAS | K14: REDEBAN | L14: FO-25-1297618 | M14: 45867.333 | N14: 45871.511 | P14: CIERRE | Q14: RECUPERACION DE EQUIPOS | R14: AGREGADOR | S14: COMCARD - PTM | T14: ILOCALIZADO | U14: CB CERRADO - DESOCUPADO | V14: 0 02/08/2025 SE INTENTA LLAMAR AL CLIENTE Y NO CONTESTA, DE ESCRIBE POR WHATSAPP Y TAMPCO AHI RESPUESTA , AL LLEGAR AL PUNTO SE ENCUENTRA CERRADO 02-08-2025 SE INTENTA LLAMAR AL CLIENTE Y NO CONTESTA, DE ESCRIBE POR WHATSAPP Y TAMPCO AHI RESPUESTA , AL LLEGAR AL PUNTO SE ENCUENTRA CERRADO | W14: VISITA_TÉCNICA | X14: O | Y14: TIPO I | Z14: =VLOOKUP(D14,TIPOLOGIAS!A:F,5,0) -> TERRESTRE | AA14: SOTO MUNAR DYLAN DAVID | AB14: 1 | AC14: =IF(AND(W14="SOPORTE_TELEFÓNICO",OR(U14="SIN CONTACTO CON EL CB",U14="NÚMEROS DE CONTACTO ERRADOS")),0,IF(W14="SOPORTE_TELEFÓNICO",'BASE DE LIQUIDACION 2025'!$B$9,IF(Y14="TIPO I",'BASE DE LIQUIDACION 2025'!$C$3,IF(Y14="TIPO II",'BASE DE LIQUIDACION 2025'!$C$4,IF(Y14="TIPO III",'BASE DE LIQUIDACION 2025'!$C$5,'BASE DE LIQUIDACION 2025'!$C$6))))) -> 44559.564 | AD14: =IF(W14="SOPORTE_TELEFÓNICO",AC14,CIERRES!AB14*CIERRES!AC14) -> 44559.564
A15: NEIVA | B15: =VLOOKUP(A15,'CENTRO DE COSTOS'!A:D,4,FALSE) -> KEVIN ALEXIS CORZO BUSTOS | C15: =VLOOKUP(A15,'CENTRO DE COSTOS'!A:C,2,FALSE) -> 0004-0007 | D15: 41615 | E15: TA-25-906315 | F15: 78964 | G15: ORDEN DE CAMBIO | H15: HUILA | I15: RIVERA | J15: BARRIO CENTRO BAJO RIVERA 1 | K15: REDEBAN | L15: FO-25-1308245 | M15: 45868.666 | N15: 45871.569 | P15: CIERRE | Q15: CIERRE | R15: CB UNO A UNO | S15: CB UNO A UNO | T15: SOLICITUD_CANCELADA | U15: CANCELADO POR LA ENTIDAD | V15: 0 0 02-08-2025 SE LLEGA A SITIO, NO SE ENCUENTRA NADIE EN LA CASA, SE LLAMA A NÚMERO DE CONTACTO 3207128409 PERO NO RESPONDEN. | W15: VISITA_TÉCNICA | X15: 0 | Y15: TIPO I | Z15: =VLOOKUP(D15,TIPOLOGIAS!A:F,5,0) -> TERRESTRE | AA15: DIAZ VARGAS JONATHAN MIGUEL | AB15: 1 | AC15: =IF(AND(W15="SOPORTE_TELEFÓNICO",OR(U15="SIN CONTACTO CON EL CB",U15="NÚMEROS DE CONTACTO ERRADOS")),0,IF(W15="SOPORTE_TELEFÓNICO",'BASE DE LIQUIDACION 2025'!$B$9,IF(Y15="TIPO I",'BASE DE LIQUIDACION 2025'!$C$3,IF(Y15="TIPO II",'BASE DE LIQUIDACION 2025'!$C$4,IF(Y15="TIPO III",'BASE DE LIQUIDACION 2025'!$C$5,'BASE DE LIQUIDACION 2025'!$C$6))))) -> 44559.564 | AD15: =IF(W15="SOPORTE_TELEFÓNICO",AC15,CIERRES!AB15*CIERRES!AC15) -> 44559.564
A16: VILLAVICENCIO | B16: =VLOOKUP(A16,'CENTRO DE COSTOS'!A:D,4,FALSE) -> KEVIN ALEXIS CORZO BUSTOS | C16: =VLOOKUP(A16,'CENTRO DE COSTOS'!A:C,2,FALSE) -> 0004-0007 | D16: 50001 | E16: TA-25-906316 | F16: 63562 | G16: ORDEN DE CAMBIO | H16: META | I16: VILLAVICENCIO | J16: BARRIO RECREO VILLAVICENCIO 2 | K16: REDEBAN | L16: FO-25-1308249 | M16: 45868.666 | N16: 45873.344 | P16: CIERRE | Q16: CIERRE | R16: CB UNO A UNO | S16: CB UNO A UNO | T16: NO_EXITOSO | U16: CB NO ENTREGA EQUIPO | V16: 0 0 04-08-2025 SE REALIZA VISITA Y ENCARGADO INFORMA QUE NO TIENE CONOCIMIENTO QUE TOCA COMUNICARSE CON LOS DUEÑOS YA QUE ELLOS VENDIERON EL.NEGOCIO | W16: VISITA_TÉCNICA | X16: 0 | Y16: TIPO I | Z16: =VLOOKUP(D16,TIPOLOGIAS!A:F,5,0) -> TERRESTRE | AA16: PEDREROS CONTRERAS MICHAEL STEVENS | AB16: 1 | AC16: =IF(AND(W16="SOPORTE_TELEFÓNICO",OR(U16="SIN CONTACTO CON EL CB",U16="NÚMEROS DE CONTACTO ERRADOS")),0,IF(W16="SOPORTE_TELEFÓNICO",'BASE DE LIQUIDACION 2025'!$B$9,IF(Y16="TIPO I",'BASE DE LIQUIDACION 2025'!$C$3,IF(Y16="TIPO II",'BASE DE LIQUIDACION 2025'!$C$4,IF(Y16="TIPO III",'BASE DE LIQUIDACION 2025'!$C$5,'BASE DE LIQUIDACION 2025'!$C$6))))) -> 44559.564 | AD16: =IF(W16="SOPORTE_TELEFÓNICO",AC16,CIERRES!AB16*CIERRES!AC16) -> 44559.564
A17: APARTADO | B17: =VLOOKUP(A17,'CENTRO DE COSTOS'!A:D,4,FALSE) -> JUAN SEBASTIÁN RÍOS CASTRILLÓN | C17: =VLOOKUP(A17,'CENTRO DE COSTOS'!A:C,2,FALSE) -> 0004-0005 | D17: 5490 | E17: TA-25-899458 | F17: 71512 | G17: ORDEN DE CAMBIO | H17: ANTIOQUIA | I17: NECOCLI | J17: DISTRICOL LA 44 DE DORKI | K17: REDEBAN | L17: FO-25-1297487 | M17: 45867.333 | N17: 45873.353 | P17: CIERRE | Q17: CIERRE | R17: AGREGADOR | S17: DISTRICOL | T17: NO_EXITOSO | U17: CB NO ENTREGA EQUIPO | V17: 0 0 04-08-2025 SE LLAMA AL USUARIO PARA PROGRAMAR LA VISITA, EL USUARIO NOS MANIFIESTA QUE NO NOS PUEDE ANTENDER Y QUE VA A COMUNICARCE CON LA ALIANZA DISTRICOL PARA CAMBIAR EL MODO DEL CORRESPONSAL A PREPAGO. | W17: SOPORTE_TELEFÓNICO | X17: 0 | Y17: TIPO II | Z17: =VLOOKUP(D17,TIPOLOGIAS!A:F,5,0) -> TERRESTRE | AA17: SALDARRIAGA MIRANDA SANTIAGO | AB17: 0 | AC17: =IF(AND(W17="SOPORTE_TELEFÓNICO",OR(U17="SIN CONTACTO CON EL CB",U17="NÚMEROS DE CONTACTO ERRADOS")),0,IF(W17="SOPORTE_TELEFÓNICO",'BASE DE LIQUIDACION 2025'!$B$9,IF(Y17="TIPO I",'BASE DE LIQUIDACION 2025'!$C$3,IF(Y17="TIPO II",'BASE DE LIQUIDACION 2025'!$C$4,IF(Y17="TIPO III",'BASE DE LIQUIDACION 2025'!$C$5,'BASE DE LIQUIDACION 2025'!$C$6))))) -> 37904.612 | AD17: =IF(W17="SOPORTE_TELEFÓNICO",AC17,CIERRES!AB17*CIERRES!AC17) -> 37904.612
A18: APARTADO | B18: =VLOOKUP(A18,'CENTRO DE COSTOS'!A:D,4,FALSE) -> JUAN SEBASTIÁN RÍOS CASTRILLÓN | C18: =VLOOKUP(A18,'CENTRO DE COSTOS'!A:C,2,FALSE) -> 0004-0005 | D18: 5837 | E18: TA-25-899462 | F18: 37620 | G18: ORDEN DE CAMBIO | H18: ANTIOQUIA | I18: TURBO | J18: DISTRICOL PAPELERIA BEERM | K18: REDEBAN | L18: FO-25-1297489 | M18: 45867.333 | N18: 45873.36 | P18: CIERRE | Q18: CIERRE | R18: AGREGADOR | S18: DISTRICOL | T18: NO_EXITOSO | U18: CB NO ENTREGA EQUIPO | V18: 0 0 04-08-2025 USUARIO MANIFIESTA QUE YA HIZO LA ENTREGA DEL COMERCIO Y ENVIO LOS EQUIPOS A DISTRICOL MEDELLIN. NOS COMPARTE EVIDENCIA DE LOS EQUIPOS Y GUIA DEL ENVIO | W18: SOPORTE_TELEFÓNICO | X18: 0 | Y18: TIPO II | Z18: =VLOOKUP(D18,TIPOLOGIAS!A:F,5,0) -> TERRESTRE | AA18: SALDARRIAGA MIRANDA SANTIAGO | AB18: 0 | AC18: =IF(AND(W18="SOPORTE_TELEFÓNICO",OR(U18="SIN CONTACTO CON EL CB",U18="NÚMEROS DE CONTACTO ERRADOS")),0,IF(W18="SOPORTE_TELEFÓNICO",'BASE DE LIQUIDACION 2025'!$B$9,IF(Y18="TIPO I",'BASE DE LIQUIDACION 2025'!$C$3,IF(Y18="TIPO II",'BASE DE LIQUIDACION 2025'!$C$4,IF(Y18="TIPO III",'BASE DE LIQUIDACION 2025'!$C$5,'BASE DE LIQUIDACION 2025'!$C$6))))) -> 37904.612 | AD18: =IF(W18="SOPORTE_TELEFÓNICO",AC18,CIERRES!AB18*CIERRES!AC18) -> 37904.612
A19: MEDELLIN | B19: =VLOOKUP(A19,'CENTRO DE COSTOS'!A:D,4,FALSE) -> JUAN SEBASTIÁN RÍOS CASTRILLÓN | C19: =VLOOKUP(A19,'CENTRO DE COSTOS'!A:C,2,FALSE) -> 0004-0005 | D19: 5197 | E19: TA-25-899457 | F19: 59566 | G19: ORDEN DE CAMBIO | H19: ANTIOQUIA | I19: COCORNA | J19: DISTRICOL VARIEDADES ARCO IRIS | K19: REDEBAN | L19: FO-25-1297476 | M19: 45867.333 | N19: 45873.469 | P19: CIERRE | Q19: CIERRE | R19: AGREGADOR | S19: DISTRICOL | T19: NO_EXITOSO | U19: CB NO ENTREGA EQUIPO | V19: 0 04-08-2025 SE VISITA COMERCIO PERO ESTA DESOCUPADO, SE LLAMA AL NÚMERO INDICADO PERO LA SEÑORA VERÓNICA CANO INDICA QUE ELLA VA A ENTREGAR ELLA MISMA EL DATAFONO EN LAS OFICINAS DE DISTRICOL | W19: VISITA_TÉCNICA | X19: 0 | Y19: TIPO II | Z19: =VLOOKUP(D19,TIPOLOGIAS!A:F,5,0) -> TERRESTRE | AA19: RUA ALVAREZ RICHARD ANDRES | AB19: 1 | AC19: =IF(AND(W19="SOPORTE_TELEFÓNICO",OR(U19="SIN CONTACTO CON EL CB",U19="NÚMEROS DE CONTACTO ERRADOS")),0,IF(W19="SOPORTE_TELEFÓNICO",'BASE DE LIQUIDACION 2025'!$B$9,IF(Y19="TIPO I",'BASE DE LIQUIDACION 2025'!$C$3,IF(Y19="TIPO II",'BASE DE LIQUIDACION 2025'!$C$4,IF(Y19="TIPO III",'BASE DE LIQUIDACION 2025'!$C$5,'BASE DE LIQUIDACION 2025'!$C$6))))) -> 134410.88 | AD19: =IF(W19="SOPORTE_TELEFÓNICO",AC19,CIERRES!AB19*CIERRES!AC19) -> 134410.88
A20: BOGOTA | B20: =VLOOKUP(A20,'CENTRO DE COSTOS'!A:D,4,FALSE) -> WILLIAM ASDRUBAL ROZO ROZO | C20: =VLOOKUP(A20,'CENTRO DE COSTOS'!A:C,2,FALSE) -> 0004-0004 | D20: 25200 | E20: TA-25-906341 | F20: 37315 | G20: ORDEN DE CAMBIO | H20: CUNDINAMARCA | I20: COGUA | J20: BARRIO CENTRO COGUA 2 | K20: REDEBAN | L20: FO-25-1308339 | M20: 45868.666 | N20: 45873.635 | P20: CIERRE | Q20: RECUPERACION DE EQUIPOS | R20: CB UNO A UNO | S20: CB UNO A UNO | T20: NO_EXITOSO | U20: CB NO ENTREGA EQUIPO | V20: 0 04-08-2025 SE LLEGA A DIRECCIÓN REFERENCIADA EN ORDEN DE TRABAJO CL 1 B # 14 A - 2 SE GOLPEA. Y SE TIMBRA NADIE SALE, SE REALIZA INTENTOS DE COMUNICACIÓN CON CLIENTE RAFAEL RAMOS A NI.E REGISTRADO 3144520647 EL CUAL INFORMA QUE EN EL MOMENTO NO SE ENCUENTRA NADIE Y DAMAS . INFORMA QUE PARA PRÓXIMA VISITA QUE POR FAVOR PASAR DESPUÉS DE 2 DE LA TARDE Y LLAMAR CON ANTICIPACIÓN SE ESCALA Y SE CIERRA | W20: VISITA_TÉCNICA | X20: 0 | Y20: TIPO II | Z20: =VLOOKUP(D20,TIPOLOGIAS!A:F,5,0) -> TERRESTRE | AA20: ORTIZ MARTINEZ STIVEN | AB20: 1 | AC20: =IF(AND(W20="SOPORTE_TELEFÓNICO",OR(U20="SIN CONTACTO CON EL CB",U20="NÚMEROS DE CONTACTO ERRADOS")),0,IF(W20="SOPORTE_TELEFÓNICO",'BASE DE LIQUIDACION 2025'!$B$9,IF(Y20="TIPO I",'BASE DE LIQUIDACION 2025'!$C$3,IF(Y20="TIPO II",'BASE DE LIQUIDACION 2025'!$C$4,IF(Y20="TIPO III",'BASE DE LIQUIDACION 2025'!$C$5,'BASE DE LIQUIDACION 2025'!$C$6))))) -> 134410.88 | AD20: =IF(W20="SOPORTE_TELEFÓNICO",AC20,CIERRES!AB20*CIERRES!AC20) -> 134410.88
A21: CARTAGENA | B21: =VLOOKUP(A21,'CENTRO DE COSTOS'!A:D,4,FALSE) -> JOSE MAURICIO HERNANDEZ ROJAS | C21: =VLOOKUP(A21,'CENTRO DE COSTOS'!A:C,2,FALSE) -> 0004-0001 | D21: 13001 | E21: TA-25-904648 | F21: 43018 | G21: ORDEN DE CAMBIO | H21: BOLIVAR | I21: CARTAGENA | J21: BARRIO LA CORDIALIDAD CARTAGEN | K21: REDEBAN | L21: FO-25-1305901 | M21: 45868.523 | N21: 45873.674 | P21: CIERRE | Q21: RECUPERACION DE EQUIPOS | R21: CB UNO A UNO | S21: CB UNO A UNO | T21: NO_EXITOSO | U21: PARCIAL EXITOSO PTE. DATAFONO | V21: 30-07 DE ACUERDO A COMUNICACIÓN DE CONTACTO DE CB 43018 SR JAVIER DIAZ, CON COLABORADOR DE LINEA, INDICA QUE YA CUENTA CON LOS EQUIPOS PARA REALIZAR LOS CIERRES, ÉSTOS TENÍAN ORDEN DE CIERRE DESDE EL PASADO MES DE ABRIL, PERO NO ENTREGARON LOS EQUIPOS EN ESA FECHA 0 30-07-2025 SE REALIZA CIERRE DEL CB CLIENTE ENTREGA EQUIPO LECTORA HUB NO ENTREGA PUBLICIDAD HACE FALTA UNOS EQUIPOS LOS VAN A BUSCAR Y AVISAN CUANDO YA LOS TENGA PARA VENIRLOS A RECOGER | W21: VISITA_TÉCNICA | X21: AB9ZZ980 | Y21: TIPO I | Z21: =VLOOKUP(D21,TIPOLOGIAS!A:F,5,0) -> TERRESTRE | AA21: CANEDO HERRERA ALEXANDER | AB21: 1 | AC21: =IF(AND(W21="SOPORTE_TELEFÓNICO",OR(U21="SIN CONTACTO CON EL CB",U21="NÚMEROS DE CONTACTO ERRADOS")),0,IF(W21="SOPORTE_TELEFÓNICO",'BASE DE LIQUIDACION 2025'!$B$9,IF(Y21="TIPO I",'BASE DE LIQUIDACION 2025'!$C$3,IF(Y21="TIPO II",'BASE DE LIQUIDACION 2025'!$C$4,IF(Y21="TIPO III",'BASE DE LIQUIDACION 2025'!$C$5,'BASE DE LIQUIDACION 2025'!$C$6))))) -> 44559.564 | AD21: =IF(W21="SOPORTE_TELEFÓNICO",AC21,CIERRES!AB21*CIERRES!AC21) -> 44559.564
A22: VILLAVICENCIO | B22: =VLOOKUP(A22,'CENTRO DE COSTOS'!A:D,4,FALSE) -> KEVIN ALEXIS CORZO BUSTOS | C22: =VLOOKUP(A22,'CENTRO DE COSTOS'!A:C,2,FALSE) -> 0004-0007 | D22: 50001 | E22: TA-25-906338 | F22: 60579 | G22: ORDEN DE CAMBIO | H22: META | I22: VILLAVICENCIO | J22: BARRIO LA MADRID VILLAVICENCIO | K22: REDEBAN | L22: FO-25-1308322 | M22: 45868.666 | N22: 45874.359 | P22: CIERRE | Q22: CIERRE | R22: CB UNO A UNO | S22: CB UNO A UNO | T22: NO_EXITOSO | U22: CB NO ENTREGA EQUIPO | V22: 05/08/2025 SE REALIZA GESTIÓN TELEFÓNICA AL NÚMERO 6044619700 EL CUAL CONTESTA EL SEÑOR CARLOS OCAMPO CON CÉDULA 70326497 HIJO DE LA SEÑORA ROCÍO ARENAS DE OCAMPO Y MANIFIESTA QUE POR FAVOR REALIZAR LA RECOGIDA EL DÍA DE MAÑANA EN MEDELLÍN EN LA DIRECCIÓN CL.53 # 78-121 EN LOS EDIFICIOS PALMAR DE LOS COLORES, EL VIGILANTE ENTREGA LOS EQUIPOS. 05-08-2025 SE REALIZA GESTIÓN TELEFÓNICA AL NÚMERO 6044619700 EL CUAL CONTESTA EL SEÑOR CARLOS OCAMPO CON CÉDULA 70326497 HIJO DE LA SEÑORA ROCÍO ARENAS DE OCAMPO Y MANIFIESTA QUE POR FAVOR REALIZAR LA RECOGIDA EL DÍA DE MAÑANA EN MEDELLÍN EN LA DIRECCIÓN CL.53 # 78-121 EN LOS EDIFICIOS PALMAR DE LOS COLORES, EL VIGILANTE ENTREGA LOS EQUIPOS. | W22: SOPORTE_TELEFÓNICO | X22: 0 | Y22: TIPO I | Z22: =VLOOKUP(D22,TIPOLOGIAS!A:F,5,0) -> TERRESTRE | AA22: PEDREROS CONTRERAS MICHAEL STEVENS | AB22: 0 | AC22: =IF(AND(W22="SOPORTE_TELEFÓNICO",OR(U22="SIN CONTACTO CON EL CB",U22="NÚMEROS DE CONTACTO ERRADOS")),0,IF(W22="SOPORTE_TELEFÓNICO",'BASE DE LIQUIDACION 2025'!$B$9,IF(Y22="TIPO I",'BASE DE LIQUIDACION 2025'!$C$3,IF(Y22="TIPO II",'BASE DE LIQUIDACION 2025'!$C$4,IF(Y22="TIPO III",'BASE DE LIQUIDACION 2025'!$C$5,'BASE DE LIQUIDACION 2025'!$C$6))))) -> 37904.612 | AD22: =IF(W22="SOPORTE_TELEFÓNICO",AC22,CIERRES!AB22*CIERRES!AC22) -> 37904.612
A23: PASTO | B23: =VLOOKUP(A23,'CENTRO DE COSTOS'!A:D,4,FALSE) -> DIEGO FERNANDO HENAO CARDONA | C23: =VLOOKUP(A23,'CENTRO DE COSTOS'!A:C,2,FALSE) -> 0004-0003 | D23: 52083 | E23: TA-25-906320 | F23: 64590 | G23: ORDEN DE CAMBIO | H23: NARIÑO | I23: BELEN | J23: BARRIO AV LOS ESTUDIANTES BELE | K23: REDEBAN | L23: FO-25-1308262 | M23: 45868.666 | N23: 45875.408 | P23: CIERRE | Q23: CIERRE | R23: CB UNO A UNO | S23: CB UNO A UNO | T23: NO_EXITOSO | U23: CB NO ENTREGA EQUIPO | V23: 0 0 06-08-2025 SE HABLA CON EL SEÑOR MILCIADES QUIEN INDICA QUE SE ENCUENTRA EN UN PROCESO DE VALIDACION CON LA ENTIDAD PARA LA CONTINUIDAD DEL CORRESPONAL, POR TANTO POR AHORA NO DESEA LA ENTREGA DEL LOS EQUIPOS PUES ESTA EN ESPERA DE VALIDACIONES Y RESPUESTA DE LA ENTIDAD ANTE LA PETICION. | W23: SOPORTE_TELEFÓNICO | X23: 0 | Y23: TIPO III | Z23: =VLOOKUP(D23,TIPOLOGIAS!A:F,5,0) -> TERRESTRE | AA23: HENAO CARDONA DIEGO FERNANDO | AB23: 0 | AC23: =IF(AND(W23="SOPORTE_TELEFÓNICO",OR(U23="SIN CONTACTO CON EL CB",U23="NÚMEROS DE CONTACTO ERRADOS")),0,IF(W23="SOPORTE_TELEFÓNICO",'BASE DE LIQUIDACION 2025'!$B$9,IF(Y23="TIPO I",'BASE DE LIQUIDACION 2025'!$C$3,IF(Y23="TIPO II",'BASE DE LIQUIDACION 2025'!$C$4,IF(Y23="TIPO III",'BASE DE LIQUIDACION 2025'!$C$5,'BASE DE LIQUIDACION 2025'!$C$6))))) -> 37904.612 | AD23: =IF(W23="SOPORTE_TELEFÓNICO",AC23,CIERRES!AB23*CIERRES!AC23) -> 37904.612
A24: CUCUTA | B24: =VLOOKUP(A24,'CENTRO DE COSTOS'!A:D,4,FALSE) -> MIGUEL JULIÁN HERNÁNDEZ GUARÍN | C24: =VLOOKUP(A24,'CENTRO DE COSTOS'!A:C,2,FALSE) -> 0004-0008 | D24: 54001 | E24: TA-25-924046 | F24: 71022 | G24: ORDEN DE CAMBIO | H24: NORTE DE SANTANDER | I24: CUCUTA | J24: DISTRICOL CENTROPAG | K24: REDEBAN | L24: FO-25-1332781 | M24: 45874.597 | N24: 45875.671 | P24: CIERRE | Q24: RECUPERACION DE EQUIPOS | R24: AGREGADOR | S24: DISTRICOL | T24: NO_EXITOSO | U24: CB NO ENTREGA EQUIPO | V24: 0 06-08-2025 SE VISITA COMERCIO, PERSONA EN SITIO DICE QUE NO ESTA AUTORIZADA PARA ATENDER VISITA YA QUE NO ES LA DUEÑA, SE COMUNICA CON EL CLIENTE A LOS NUMEROS INDICADOS NO SE RESIVE RESPUESTA, SIN COMUNICACION. | W24: VISITA_TÉCNICA | X24: MN00C096 | Y24: TIPO I | Z24: =VLOOKUP(D24,TIPOLOGIAS!A:F,5,0) -> TERRESTRE | AA24: NARANJO AFANADOR RUBEN JESUS | AB24: 1 | AC24: =IF(AND(W24="SOPORTE_TELEFÓNICO",OR(U24="SIN CONTACTO CON EL CB",U24="NÚMEROS DE CONTACTO ERRADOS")),0,IF(W24="SOPORTE_TELEFÓNICO",'BASE DE LIQUIDACION 2025'!$B$9,IF(Y24="TIPO I",'BASE DE LIQUIDACION 2025'!$C$3,IF(Y24="TIPO II",'BASE DE LIQUIDACION 2025'!$C$4,IF(Y24="TIPO III",'BASE DE LIQUIDACION 2025'!$C$5,'BASE DE LIQUIDACION 2025'!$C$6))))) -> 44559.564 | AD24: =IF(W24="SOPORTE_TELEFÓNICO",AC24,CIERRES!AB24*CIERRES!AC24) -> 44559.564
A25: NEIVA | B25: =VLOOKUP(A25,'CENTRO DE COSTOS'!A:D,4,FALSE) -> KEVIN ALEXIS CORZO BUSTOS | C25: =VLOOKUP(A25,'CENTRO DE COSTOS'!A:C,2,FALSE) -> 0004-0007 | D25: 41001 | E25: TA-25-924053 | F25: 64929 | G25: ORDEN DE CAMBIO | H25: HUILA | I25: NEIVA | J25: DISTRICOL BEATIFUL NAILS | K25: REDEBAN | L25: FO-25-1332800 | M25: 45874.597 | N25: 45875.853 | P25: CIERRE | Q25: CIERRE | R25: AGREGADOR | S25: DISTRICOL | T25: NO_EXITOSO | U25: CB NO ENTREGA EQUIPO | V25: 0 06-08-2025 SE REALIZA VISITA AL PUNTO SE EVIDENCIA COEMECIO CERRADO, EN COMUNICACIÓN CON EL CLIENTE LA SEÑORA DANIELA RUBIANO, AL NÚMERO +57 322 3100611, INDICA QUE NO CUENTA CON LOS EQUIPOS, YA QUE LOS ENVIARON A LAS OFICINAS DE DISTRICOL EN MEDELLÍN, | W25: VISITA_TÉCNICA | X25: 0 | Y25: TIPO I | Z25: =VLOOKUP(D25,TIPOLOGIAS!A:F,5,0) -> TERRESTRE | AA25: DEVIA REINOSO JUAN CARLOS | AB25: 1 | AC25: =IF(AND(W25="SOPORTE_TELEFÓNICO",OR(U25="SIN CONTACTO CON EL CB",U25="NÚMEROS DE CONTACTO ERRADOS")),0,IF(W25="SOPORTE_TELEFÓNICO",'BASE DE LIQUIDACION 2025'!$B$9,IF(Y25="TIPO I",'BASE DE LIQUIDACION 2025'!$C$3,IF(Y25="TIPO II",'BASE DE LIQUIDACION 2025'!$C$4,IF(Y25="TIPO III",'BASE DE LIQUIDACION 2025'!$C$5,'BASE DE LIQUIDACION 2025'!$C$6))))) -> 44559.564 | AD25: =IF(W25="SOPORTE_TELEFÓNICO",AC25,CIERRES!AB25*CIERRES!AC25) -> 44559.564
A26: SANTA MARTA | B26: =VLOOKUP(A26,'CENTRO DE COSTOS'!A:D,4,FALSE) -> JOSE MAURICIO HERNANDEZ ROJAS | C26: =VLOOKUP(A26,'CENTRO DE COSTOS'!A:C,2,FALSE) -> 0004-0001 | D26: 47268 | E26: TA-25-941588 | F26: 53238 | G26: ORDEN DE CAMBIO | H26: MAGDALENA | I26: EL RETEN | J26: PTM EL RETEN SERVIFRIOMAR | K26: REDEBAN | L26: FO-25-1345215 | M26: 45875.721 | N26: 45877.719 | P26: CIERRE | Q26: CIERRE | R26: AGREGADOR | S26: COMCARD - PTM | T26: ILOCALIZADO | U26: CB CERRADO - DESOCUPADO | V26: 0 0 08-08-2025 SE HACE GESTIÓN TELEFÓNICA, EL USUARIO NO RESPONDE LAS.LLAMDAS, SE REALIZA LA VISITA, NO SE HAYA EL CORRESPONSAL EN EL PUNTO SE VALIDA LA UBICACIÓN DEL SITIO CON EL COORDINADOR PERO EN EL SITIO NO HAY CORRESPONSAL INSTALADO Y NADIE DA RAZÓN DEL USUARIO NI DEL CORRESPONSAL | W26: VISITA_TÉCNICA | X26: 0 | Y26: TIPO III | Z26: =VLOOKUP(D26,TIPOLOGIAS!A:F,5,0) -> TERRESTRE | AA26: THOMAS CAMPO SIGIFREDO SEGUNDO | AB26: 1 | AC26: =IF(AND(W26="SOPORTE_TELEFÓNICO",OR(U26="SIN CONTACTO CON EL CB",U26="NÚMEROS DE CONTACTO ERRADOS")),0,IF(W26="SOPORTE_TELEFÓNICO",'BASE DE LIQUIDACION 2025'!$B$9,IF(Y26="TIPO I",'BASE DE LIQUIDACION 2025'!$C$3,IF(Y26="TIPO II",'BASE DE LIQUIDACION 2025'!$C$4,IF(Y26="TIPO III",'BASE DE LIQUIDACION 2025'!$C$5,'BASE DE LIQUIDACION 2025'!$C$6))))) -> 222904.07 | AD26: =IF(W26="SOPORTE_TELEFÓNICO",AC26,CIERRES!AB26*CIERRES!AC26) -> 222904.07
A27: CALI | B27: =VLOOKUP(A27,'CENTRO DE COSTOS'!A:D,4,FALSE) -> DIEGO FERNANDO HENAO CARDONA | C27: =VLOOKUP(A27,'CENTRO DE COSTOS'!A:C,2,FALSE) -> 0004-0003 | D27: 76364 | E27: TA-25-941582 | F27: 36900 | G27: ORDEN DE CAMBIO | H27: VALLE DEL CAUCA | I27: JAMUNDI | J27: BARRIO JAMUNDI VALLE DEL CAUCA | K27: REDEBAN | L27: FO-25-1345200 | M27: 45875.724 | N27: 45878.501 | P27: CIERRE | Q27: RECUPERACION DE EQUIPOS | R27: CB UNO A UNO | S27: CB UNO A UNO | T27: ILOCALIZADO | U27: CB CERRADO - DESOCUPADO | V27: 0 0 09-08-2025 SE VISITA CORRESPONSAL Y SE ENCONTRÓ CERRADO, SE LLAMA AL CONTACTO EN REPETIDAS OCASIONES NO CONTESTA. | W27: VISITA_TÉCNICA | X27: MN0SZ859 | Y27: TIPO II | Z27: =VLOOKUP(D27,TIPOLOGIAS!A:F,5,0) -> TERRESTRE | AA27: BOLAÑOS TABORDA JORGE ENRIQUE | AB27: 1 | AC27: =IF(AND(W27="SOPORTE_TELEFÓNICO",OR(U27="SIN CONTACTO CON EL CB",U27="NÚMEROS DE CONTACTO ERRADOS")),0,IF(W27="SOPORTE_TELEFÓNICO",'BASE DE LIQUIDACION 2025'!$B$9,IF(Y27="TIPO I",'BASE DE LIQUIDACION 2025'!$C$3,IF(Y27="TIPO II",'BASE DE LIQUIDACION 2025'!$C$4,IF(Y27="TIPO III",'BASE DE LIQUIDACION 2025'!$C$5,'BASE DE LIQUIDACION 2025'!$C$6))))) -> 134410.88 | AD27: =IF(W27="SOPORTE_TELEFÓNICO",AC27,CIERRES!AB27*CIERRES!AC27) -> 134410.88
A28: NEIVA | B28: =VLOOKUP(A28,'CENTRO DE COSTOS'!A:D,4,FALSE) -> KEVIN ALEXIS CORZO BUSTOS | C28: =VLOOKUP(A28,'CENTRO DE COSTOS'!A:C,2,FALSE) -> 0004-0007 | D28: 41001 | E28: TA-25-948860 | F28: 33473 | G28: ORDEN DE CAMBIO | H28: HUILA | I28: NEIVA | J28: BARRIO CENTRO NEIVA 3 | K28: REDEBAN | L28: FO-25-1353510 | M28: 45878.7 | N28: 45878.501 | P28: CIERRE | Q28: CIERRE | R28: CB UNO A UNO | S28: CB UNO A UNO | T28: ILOCALIZADO | U28: CB CERRADO - DESOCUPADO | V28: 0 0 09-08-2025 SE LLEGA AL PUNTO , LOCAL VACÍO Y DISPONIBLE , SE PREGUNTA A VIGILANTE DEL EDIFICIO COMENTANDO QUE LLEVA MUCHO TIEMPO VACÍO , SE LLAMA AL NÚMERO NO CONTESTA , SE ESCRIBE POR WHATSAPP NO HAY RESPUESTA | W28: VISITA_TÉCNICA | X28: 17ZZZ823 | Y28: TIPO I | Z28: =VLOOKUP(D28,TIPOLOGIAS!A:F,5,0) -> TERRESTRE | AA28: ANDRADE HERNANDEZ JUAN CARLOS | AB28: 1 | AC28: =IF(AND(W28="SOPORTE_TELEFÓNICO",OR(U28="SIN CONTACTO CON EL CB",U28="NÚMEROS DE CONTACTO ERRADOS")),0,IF(W28="SOPORTE_TELEFÓNICO",'BASE DE LIQUIDACION 2025'!$B$9,IF(Y28="TIPO I",'BASE DE LIQUIDACION 2025'!$C$3,IF(Y28="TIPO II",'BASE DE LIQUIDACION 2025'!$C$4,IF(Y28="TIPO III",'BASE DE LIQUIDACION 2025'!$C$5,'BASE DE LIQUIDACION 2025'!$C$6))))) -> 44559.564 | AD28: =IF(W28="SOPORTE_TELEFÓNICO",AC28,CIERRES!AB28*CIERRES!AC28) -> 44559.564
A29: NEIVA | B29: =VLOOKUP(A29,'CENTRO DE COSTOS'!A:D,4,FALSE) -> KEVIN ALEXIS CORZO BUSTOS | C29: =VLOOKUP(A29,'CENTRO DE COSTOS'!A:C,2,FALSE) -> 0004-0007 | D29: 41001 | E29: TA-25-948862 | F29: 33475 | G29: ORDEN DE CAMBIO | H29: HUILA | I29: NEIVA | J29: BARRIO CENTRO NEIVA 5 | K29: REDEBAN | L29: FO-25-1353516 | M29: 45878.7 | N29: 45878.508 | P29: CIERRE | Q29: CIERRE | R29: CB UNO A UNO | S29: CB UNO A UNO | T29: ILOCALIZADO | U29: CB CERRADO - DESOCUPADO | V29: 0 0 09-08-2025 SE REALIZA VISITA A LA DIRECCIÓN INDICADA EN LA ORDEN, SE EVIDENCIARÁ COMERCIO ESTÁ CERRADO , SE INTENTA COMUNICACIÓN A NÚMERO INDICADO EN LA ORDEN PERO NO HAY REPSUESTA. | W29: VISITA_TÉCNICA | X29: 0 | Y29: TIPO I | Z29: =VLOOKUP(D29,TIPOLOGIAS!A:F,5,0) -> TERRESTRE | AA29: DEVIA REINOSO JUAN CARLOS | AB29: 1 | AC29: =IF(AND(W29="SOPORTE_TELEFÓNICO",OR(U29="SIN CONTACTO CON EL CB",U29="NÚMEROS DE CONTACTO ERRADOS")),0,IF(W29="SOPORTE_TELEFÓNICO",'BASE DE LIQUIDACION 2025'!$B$9,IF(Y29="TIPO I",'BASE DE LIQUIDACION 2025'!$C$3,IF(Y29="TIPO II",'BASE DE LIQUIDACION 2025'!$C$4,IF(Y29="TIPO III",'BASE DE LIQUIDACION 2025'!$C$5,'BASE DE LIQUIDACION 2025'!$C$6))))) -> 44559.564 | AD29: =IF(W29="SOPORTE_TELEFÓNICO",AC29,CIERRES!AB29*CIERRES!AC29) -> 44559.564
A30: NEIVA | B30: =VLOOKUP(A30,'CENTRO DE COSTOS'!A:D,4,FALSE) -> KEVIN ALEXIS CORZO BUSTOS | C30: =VLOOKUP(A30,'CENTRO DE COSTOS'!A:C,2,FALSE) -> 0004-0007 | D30: 41001 | E30: TA-25-948861 | F30: 33474 | G30: ORDEN DE CAMBIO | H30: HUILA | I30: NEIVA | J30: BARRIO CENTRO NEIVA 4 | K30: REDEBAN | L30: FO-25-1353513 | M30: 45878.7 | N30: 45878.51 | P30: CIERRE | Q30: CIERRE | R30: CB UNO A UNO | S30: CB UNO A UNO | T30: ILOCALIZADO | U30: CB CERRADO - DESOCUPADO | V30: 0 0 09-08-2025 SE REALIZA VISITA A LA DIRECCIÓN INDICADA EN LA ORDEN, SE EVIDENCIARÁ COMERCIO ESTÁ CERRADO , SE INTENTA COMUNICACIÓN A NÚMERO INDICADO EN LA ORDEN PERO NO HAY REPSUESTA. | W30: VISITA_TÉCNICA | X30: 0 | Y30: TIPO I | Z30: =VLOOKUP(D30,TIPOLOGIAS!A:F,5,0) -> TERRESTRE | AA30: DEVIA REINOSO JUAN CARLOS | AB30: 1 | AC30: =IF(AND(W30="SOPORTE_TELEFÓNICO",OR(U30="SIN CONTACTO CON EL CB",U30="NÚMEROS DE CONTACTO ERRADOS")),0,IF(W30="SOPORTE_TELEFÓNICO",'BASE DE LIQUIDACION 2025'!$B$9,IF(Y30="TIPO I",'BASE DE LIQUIDACION 2025'!$C$3,IF(Y30="TIPO II",'BASE DE LIQUIDACION 2025'!$C$4,IF(Y30="TIPO III",'BASE DE LIQUIDACION 2025'!$C$5,'BASE DE LIQUIDACION 2025'!$C$6))))) -> 44559.564 | AD30: =IF(W30="SOPORTE_TELEFÓNICO",AC30,CIERRES!AB30*CIERRES!AC30) -> 44559.564
A31: NEIVA | B31: =VLOOKUP(A31,'CENTRO DE COSTOS'!A:D,4,FALSE) -> KEVIN ALEXIS CORZO BUSTOS | C31: =VLOOKUP(A31,'CENTRO DE COSTOS'!A:C,2,FALSE) -> 0004-0007 | D31: 18592 | E31: TA-25-924060 | F31: 77695 | G31: ORDEN DE CAMBIO | H31: CAQUETA | I31: PUERTO RICO | J31: BARRIO SIETE DE AGOSTO PUERTO RICO | K31: REDEBAN | L31: FO-25-1332827 | M31: 45874.597 | N31: 45880.535 | P31: CIERRE | Q31: CIERRE | R31: CB UNO A UNO | S31: CB UNO A UNO | T31: ILOCALIZADO | U31: CB CERRADO - DESOCUPADO | V31: 0 0 11-08-2025 SE LLEGA AL ESTABLECIMIENTO PERO SE ENCUENTRA CERRADO Y DESOCUPADO, SE PREGUNTA A LAS PERSONAS DEL SECTOR Y MANIFIESTA QUE SE FUERON DE AHÍ DEL LUGAR, SE LLAMA Y SE ESCRIBE AL NÚMERO DE LA TA PERO NADIE RESPONDE, CIERRE FALLIDO. | W31: VISITA_TÉCNICA | X31: 10LZZ966 | Y31: TIPO IV ESPECIAL | Z31: =VLOOKUP(D31,TIPOLOGIAS!A:F,5,0) -> TERRESTRE | AA31: BERMUDEZ SANCHEZ JOSE NEYBER | AB31: 1 | AC31: =IF(AND(W31="SOPORTE_TELEFÓNICO",OR(U31="SIN CONTACTO CON EL CB",U31="NÚMEROS DE CONTACTO ERRADOS")),0,IF(W31="SOPORTE_TELEFÓNICO",'BASE DE LIQUIDACION 2025'!$B$9,IF(Y31="TIPO I",'BASE DE LIQUIDACION 2025'!$C$3,IF(Y31="TIPO II",'BASE DE LIQUIDACION 2025'!$C$4,IF(Y31="TIPO III",'BASE DE LIQUIDACION 2025'!$C$5,'BASE DE LIQUIDACION 2025'!$C$6))))) -> 464809.37 | AD31: =IF(W31="SOPORTE_TELEFÓNICO",AC31,CIERRES!AB31*CIERRES!AC31) -> 464809.37
A32: NEIVA | B32: =VLOOKUP(A32,'CENTRO DE COSTOS'!A:D,4,FALSE) -> KEVIN ALEXIS CORZO BUSTOS | C32: =VLOOKUP(A32,'CENTRO DE COSTOS'!A:C,2,FALSE) -> 0004-0007 | D32: 73483 | E32: TA-25-948868 | F32: 75471 | G32: ORDEN DE CAMBIO | H32: TOLIMA | I32: NATAGAIMA | J32: BARRIO CENTRO NATAGAIMA | K32: REDEBAN | L32: FO-25-1361975 | M32: 45878.7 | N32: 45880.698 | P32: CIERRE | Q32: CIERRE | R32: CB UNO A UNO | S32: CB UNO A UNO | T32: EJECUTADO_EXITOSO | U32: CIERRE EXITOSO | V32: 0 0 11-08-2025 SE LLEGA AL SITIO COMERCIO CERRADO , VECINOS MANIFIESTA QUE EL ALMACÉN FUE RECOGIDO Y LLEVADO A IBAGUÉ, SE MARCA AL CELULAR NO CONTESTA, SE ESCRIBE POR WHATSAPP NO HAY RESPUESTA , CLIENTE EN EL ÚLTIMO MINUTO DA RESPUESTA COMENTANDO QUE LOS EQUIPOS ESTÁN EN EL MUNICIPIO DE SALDAÑA , QUE SI PODEMOS RECOGERLOS ALLÍ SE ESCALA AL JEFE INMEDIATO DONDE AUTORIZA DESPLAZARNOS HASTA SALDAÑA. 0 11-08-2025 CLIENTE ENTREGA DATAFONO , LECTOR DE BARRAS,CABLE MAGIC BOX, FUENTE DE PODER DATÁFONO Y CABLE DE RED , PUBLICIDAD Y ROLLOS NO HAY | W32: VISITA_TÉCNICA | X32: V100C094-A406Z663 | Y32: TIPO II | Z32: =VLOOKUP(D32,TIPOLOGIAS!A:F,5,0) -> TERRESTRE | AA32: ANDRADE HERNANDEZ JUAN CARLOS | AB32: 1 | AC32: =IF(AND(W32="SOPORTE_TELEFÓNICO",OR(U32="SIN CONTACTO CON EL CB",U32="NÚMEROS DE CONTACTO ERRADOS")),0,IF(W32="SOPORTE_TELEFÓNICO",'BASE DE LIQUIDACION 2025'!$B$9,IF(Y32="TIPO I",'BASE DE LIQUIDACION 2025'!$C$3,IF(Y32="TIPO II",'BASE DE LIQUIDACION 2025'!$C$4,IF(Y32="TIPO III",'BASE DE LIQUIDACION 2025'!$C$5,'BASE DE LIQUIDACION 2025'!$C$6))))) -> 134410.88 | AD32: =IF(W32="SOPORTE_TELEFÓNICO",AC32,CIERRES!AB32*CIERRES!AC32) -> 134410.88
A33: VILLAVICENCIO | B33: =VLOOKUP(A33,'CENTRO DE COSTOS'!A:D,4,FALSE) -> KEVIN ALEXIS CORZO BUSTOS | C33: =VLOOKUP(A33,'CENTRO DE COSTOS'!A:C,2,FALSE) -> 0004-0007 | D33: 50001 | E33: TA-25-948865 | F33: 74538 | G33: ORDEN DE CAMBIO | H33: META | I33: VILLAVICENCIO | J33: BARRIO DOCE DE OCTUBRE VILLAVI | K33: REDEBAN | L33: FO-25-1353528 | M33: 45878.7 | N33: 45881.365 | P33: CIERRE | Q33: CIERRE | R33: CB UNO A UNO | S33: CB UNO A UNO | T33: ILOCALIZADO | U33: CB CERRADO - DESOCUPADO | V33: 0 0 12-08-2025 SE REALIZA VISITA A LA DIRECCIÓN DE CB Y COMERCIO NO EXISTE, SE PREGUNTA EN LA DIRECCION Y NOS INFORMAN NO CONOCER AL SEÑOR OSCAR VARGAS | W33: VISITA_TÉCNICA | X33: 0 | Y33: TIPO I | Z33: =VLOOKUP(D33,TIPOLOGIAS!A:F,5,0) -> TERRESTRE | AA33: PEDREROS CONTRERAS MICHAEL STEVENS | AB33: 1 | AC33: =IF(AND(W33="SOPORTE_TELEFÓNICO",OR(U33="SIN CONTACTO CON EL CB",U33="NÚMEROS DE CONTACTO ERRADOS")),0,IF(W33="SOPORTE_TELEFÓNICO",'BASE DE LIQUIDACION 2025'!$B$9,IF(Y33="TIPO I",'BASE DE LIQUIDACION 2025'!$C$3,IF(Y33="TIPO II",'BASE DE LIQUIDACION 2025'!$C$4,IF(Y33="TIPO III",'BASE DE LIQUIDACION 2025'!$C$5,'BASE DE LIQUIDACION 2025'!$C$6))))) -> 44559.564 | AD33: =IF(W33="SOPORTE_TELEFÓNICO",AC33,CIERRES!AB33*CIERRES!AC33) -> 44559.564
A34: CALI | B34: =VLOOKUP(A34,'CENTRO DE COSTOS'!A:D,4,FALSE) -> DIEGO FERNANDO HENAO CARDONA | C34: =VLOOKUP(A34,'CENTRO DE COSTOS'!A:C,2,FALSE) -> 0004-0003 | D34: 76520 | E34: TA-25-948870 | F34: 59729 | G34: ORDEN DE CAMBIO | H34: VALLE DEL CAUCA | I34: PALMIRA | J34: BARRIO EL CENTRO PALMIRA | K34: REDEBAN | L34: FO-25-1353541 | M34: 45878.7 | N34: 45881.369 | P34: CIERRE | Q34: CIERRE | R34: CB UNO A UNO | S34: CB UNO A UNO | T34: NO_EXITOSO | U34: CB NO ENTREGA EQUIPO | V34: 0 0 11-08-2025 EN LA VISITA TÉCNICA SE ENCONTRÓ EL LUGAR CERRADO, SE REALIZÓ GESTIÓN TELEFÓNICA Y LA USUARIA INFORMA QUE ÉL CB YA NO EXISTE EN ESTE LUGAR INFORMA QUE ELLA PIDIÓ UN TRASLADO, NO UN CIERRE, ADICIONAL NO PUEDE ATENDER PORQUE NO SE ENCUENTRA | W34: VISITA_TÉCNICA | X34: 0 | Y34: TIPO I | Z34: =VLOOKUP(D34,TIPOLOGIAS!A:F,5,0) -> TERRESTRE | AA34: SANCHEZ URREGO ROBINSON DAVID | AB34: 1 | AC34: =IF(AND(W34="SOPORTE_TELEFÓNICO",OR(U34="SIN CONTACTO CON EL CB",U34="NÚMEROS DE CONTACTO ERRADOS")),0,IF(W34="SOPORTE_TELEFÓNICO",'BASE DE LIQUIDACION 2025'!$B$9,IF(Y34="TIPO I",'BASE DE LIQUIDACION 2025'!$C$3,IF(Y34="TIPO II",'BASE DE LIQUIDACION 2025'!$C$4,IF(Y34="TIPO III",'BASE DE LIQUIDACION 2025'!$C$5,'BASE DE LIQUIDACION 2025'!$C$6))))) -> 44559.564 | AD34: =IF(W34="SOPORTE_TELEFÓNICO",AC34,CIERRES!AB34*CIERRES!AC34) -> 44559.564
A35: CALI | B35: =VLOOKUP(A35,'CENTRO DE COSTOS'!A:D,4,FALSE) -> DIEGO FERNANDO HENAO CARDONA | C35: =VLOOKUP(A35,'CENTRO DE COSTOS'!A:C,2,FALSE) -> 0004-0003 | D35: 76109 | E35: TA-25-941581 | F35: 76884 | G35: ORDEN DE CAMBIO | H35: VALLE DEL CAUCA | I35: BUENAVENTURA | J35: BARRIO BAHIA MALAGA | K35: REDEBAN | L35: FO-25-1345197 | M35: 45875.724 | N35: 45881.387 | P35: CIERRE | Q35: RECUPERACION DE EQUIPOS | R35: CB UNO A UNO | S35: CB UNO A UNO | T35: NO_EXITOSO | U35: CB NO ENTREGA EQUIPO | V35: 0 0 12-08-2025 SE REALIZA LLAMADA A LOS NUMEROS A LA SEÑORA LIZETH , CONTESTA PERO INDICA NO TENER CONOCIMIENTO DE QUE LE HABLAMOS NI DE NINGUN CORRESPONSAL BANCARIA EN BAHIA MALAGA, SE BUSCAN MAS NUMEROS DE CONTACTO , SE ENCUENTRA EL NUMERO 3153841106, LA PERSONA QUE CONTESTA NO DA EL NOMBRE INDICA QUE ELLA YA NO TRABAJA CON EL SEÑOR EDWIN MANZUERA QUIEN ERA EL ENCARGADO DEL CORRESPONSAL INDCIA QUE ELLOS SE FUERON DE LA ISLA SIN DAR RAZON Y SIN PAGARLES , NO TIENE CONOCIMIENTO DE DONDE ESTAN LOS EQUIPOS PUES ALLA EN LA ISLA YA NO HAY NADA, NOS DA EL NUMERO DE CONTACTO DEL SEÑOR EDWIN PERO NO HA SIDO POSIBLE ENTABLAR COMUNICACION. | W35: SOPORTE_TELEFÓNICO | X35: 0 | Y35: TIPO III | Z35: =VLOOKUP(D35,TIPOLOGIAS!A:F,5,0) -> TERRESTRE | AA35: HENAO CARDONA DIEGO FERNANDO | AB35: 0 | AC35: =IF(AND(W35="SOPORTE_TELEFÓNICO",OR(U35="SIN CONTACTO CON EL CB",U35="NÚMEROS DE CONTACTO ERRADOS")),0,IF(W35="SOPORTE_TELEFÓNICO",'BASE DE LIQUIDACION 2025'!$B$9,IF(Y35="TIPO I",'BASE DE LIQUIDACION 2025'!$C$3,IF(Y35="TIPO II",'BASE DE LIQUIDACION 2025'!$C$4,IF(Y35="TIPO III",'BASE DE LIQUIDACION 2025'!$C$5,'BASE DE LIQUIDACION 2025'!$C$6))))) -> 37904.612 | AD35: =IF(W35="SOPORTE_TELEFÓNICO",AC35,CIERRES!AB35*CIERRES!AC35) -> 37904.612
A36: IBAGUE | B36: =VLOOKUP(A36,'CENTRO DE COSTOS'!A:D,4,FALSE) -> KEVIN ALEXIS CORZO BUSTOS | C36: =VLOOKUP(A36,'CENTRO DE COSTOS'!A:C,2,FALSE) -> 0004-0007 | D36: 73001 | E36: TA-25-948867 | F36: 67287 | G36: ORDEN DE CAMBIO | H36: TOLIMA | I36: IBAGUE | J36: BARRIO PRADERAS DE SANTA RITA | K36: REDEBAN | L36: FO-25-1353534 | M36: 45878.7 | N36: 45881.409 | P36: CIERRE | Q36: CIERRE | R36: CB UNO A UNO | S36: CB UNO A UNO | T36: NO_EXITOSO | U36: CB NO ENTREGA EQUIPO | V36: 0 0 12-08-2025 SE LLEGA ALA DIRECCIÓN INDICADA EVIDENCIA QUE ESTÁ CERRADO SE COMUNICA TELEFÓNICAMENTE,CON LA SEÑORITA MARIA DE LOS MILAGROS LOZANO AL TELÉFONO 3154255999 QUIEN MANIFIESTA QUE NO SOLICITO CIERRE ELLA SOLICITO ES UN TRASLADO,SE ESTARÁ COMUNICANDO CON LA ASERSOR(A)DE LA ENTIDAD ,PARA VALIDAR EL POR QUÉ DEL CIERRE USUARIO NO PERMITE EL CIERRE | W36: VISITA_TÉCNICA | X36: 0 | Y36: TIPO I | Z36: =VLOOKUP(D36,TIPOLOGIAS!A:F,5,0) -> TERRESTRE | AA36: GUTIERREZ CAMILO ANDRES | AB36: 1 | AC36: =IF(AND(W36="SOPORTE_TELEFÓNICO",OR(U36="SIN CONTACTO CON EL CB",U36="NÚMEROS DE CONTACTO ERRADOS")),0,IF(W36="SOPORTE_TELEFÓNICO",'BASE DE LIQUIDACION 2025'!$B$9,IF(Y36="TIPO I",'BASE DE LIQUIDACION 2025'!$C$3,IF(Y36="TIPO II",'BASE DE LIQUIDACION 2025'!$C$4,IF(Y36="TIPO III",'BASE DE LIQUIDACION 2025'!$C$5,'BASE DE LIQUIDACION 2025'!$C$6))))) -> 44559.564 | AD36: =IF(W36="SOPORTE_TELEFÓNICO",AC36,CIERRES!AB36*CIERRES!AC36) -> 44559.564
A37: PASTO | B37: =VLOOKUP(A37,'CENTRO DE COSTOS'!A:D,4,FALSE) -> DIEGO FERNANDO HENAO CARDONA | C37: =VLOOKUP(A37,'CENTRO DE COSTOS'!A:C,2,FALSE) -> 0004-0003 | D37: 52203 | E37: TA-25-941578 | F37: 49060 | G37: ORDEN DE CAMBIO | H37: NARIÑO | I37: COLON | J37: BARRIO LA MILAGROSA CORR DE VI | K37: REDEBAN | L37: FO-25-1345190 | M37: 45875.724 | N37: 45881.423 | P37: CIERRE | Q37: CIERRE | R37: CB UNO A UNO | S37: CB UNO A UNO | T37: NO_EXITOSO | U37: CB NO ENTREGA EQUIPO | V37: 0 0 12-08-2025 SE HABLA CON LA SEÑORA MARIA, QUIEN INDICA QUE ELLA TIENE LOS EQUIPOS PAR ENTREGAR PERO NO ESTA EN LA VEREDA, INDICA QUE ELLA ESTARA LA PROXIMA SEMANA EN LA CIUDAD DE PASTO Y SE CONTACTARA CON NOSOTROS PARA LA ENTREGA, SE PROCEDE A CERRAR VISITA POR VENCIMIENTO A LA ESPERA DE CONTACTO DEL CLIENTE PARA GESTIONAR NUEVO CIERRE. | W37: SOPORTE_TELEFÓNICO | X37: 0 | Y37: TIPO IV | Z37: =VLOOKUP(D37,TIPOLOGIAS!A:F,5,0) -> TERRESTRE | AA37: HENAO CARDONA DIEGO FERNANDO | AB37: 0 | AC37: =IF(AND(W37="SOPORTE_TELEFÓNICO",OR(U37="SIN CONTACTO CON EL CB",U37="NÚMEROS DE CONTACTO ERRADOS")),0,IF(W37="SOPORTE_TELEFÓNICO",'BASE DE LIQUIDACION 2025'!$B$9,IF(Y37="TIPO I",'BASE DE LIQUIDACION 2025'!$C$3,IF(Y37="TIPO II",'BASE DE LIQUIDACION 2025'!$C$4,IF(Y37="TIPO III",'BASE DE LIQUIDACION 2025'!$C$5,'BASE DE LIQUIDACION 2025'!$C$6))))) -> 37904.612 | AD37: =IF(W37="SOPORTE_TELEFÓNICO",AC37,CIERRES!AB37*CIERRES!AC37) -> 37904.612
A38: PASTO | B38: =VLOOKUP(A38,'CENTRO DE COSTOS'!A:D,4,FALSE) -> DIEGO FERNANDO HENAO CARDONA | C38: =VLOOKUP(A38,'CENTRO DE COSTOS'!A:C,2,FALSE) -> 0004-0003 | D38: 52323 | E38: TA-25-941591 | F38: 45928 | G38: ORDEN DE CAMBIO | H38: NARIÑO | I38: GUALMATAN | J38: PTM GUALMATAN PUNTOSERVIS GU | K38: REDEBAN | L38: FO-25-1345223 | M38: 45875.721 | N38: 45881.428 | P38: CIERRE | Q38: CIERRE | R38: AGREGADOR | S38: COMCARD - PTM | T38: NO_EXITOSO | U38: CB NO ENTREGA EQUIPO | V38: 0 0 12-08-2025 SE REALIZA LLAMADA CONTESTA UNA PERSONA QUE SE NIEGA A DAR EL NOMBRE, SE LE INDICA QUE ES PARA EL CIERRE DEL CORRESPONSAL , INDICA QUE YA NO TIENE CONTACTO NI NADA QUE VER CON EL, QUE ESO SE CERRO HACE MUCHO, Y SEGUN ELLA TODO FUE DEVUELTO, NO NOS ENTREGA MAS INFORMACION, SE LE SOLICITA OTRO NUMERO DE CONTACTO NO NOS LO SUMINISTRA, SE LE PREGUNTA SI HAY EXISTE EL LOCAL EN EL MUNICIPIO INDICA QUE NO, SE CIERRE EL CASO. | W38: SOPORTE_TELEFÓNICO | X38: 0 | Y38: TIPO II | Z38: =VLOOKUP(D38,TIPOLOGIAS!A:F,5,0) -> TERRESTRE | AA38: HENAO CARDONA DIEGO FERNANDO | AB38: 0 | AC38: =IF(AND(W38="SOPORTE_TELEFÓNICO",OR(U38="SIN CONTACTO CON EL CB",U38="NÚMEROS DE CONTACTO ERRADOS")),0,IF(W38="SOPORTE_TELEFÓNICO",'BASE DE LIQUIDACION 2025'!$B$9,IF(Y38="TIPO I",'BASE DE LIQUIDACION 2025'!$C$3,IF(Y38="TIPO II",'BASE DE LIQUIDACION 2025'!$C$4,IF(Y38="TIPO III",'BASE DE LIQUIDACION 2025'!$C$5,'BASE DE LIQUIDACION 2025'!$C$6))))) -> 37904.612 | AD38: =IF(W38="SOPORTE_TELEFÓNICO",AC38,CIERRES!AB38*CIERRES!AC38) -> 37904.612
A39: CALI | B39: =VLOOKUP(A39,'CENTRO DE COSTOS'!A:D,4,FALSE) -> DIEGO FERNANDO HENAO CARDONA | C39: =VLOOKUP(A39,'CENTRO DE COSTOS'!A:C,2,FALSE) -> 0004-0003 | D39: 76834 | E39: TA-25-948872 | F39: 76243 | G39: ORDEN DE CAMBIO | H39: VALLE DEL CAUCA | I39: TULUA | J39: BARRIO EL CENTRO TULUA 1 | K39: REDEBAN | L39: FO-25-1353543 | M39: 45878.7 | N39: 45881.469 | P39: CIERRE | Q39: CIERRE | R39: CB UNO A UNO | S39: CB UNO A UNO | T39: ILOCALIZADO | U39: CB CERRADO - DESOCUPADO | V39: 0 0 12-08-2025 SE VISITÓ Y SE ENCONTRÓ LOCAL CERRADO. SE LLAMA AL CONTACTO EN REPETIDAS OCASIONES Y NO CONTESTA. | W39: VISITA_TÉCNICA | X39: A40NZ752 | Y39: TIPO II | Z39: =VLOOKUP(D39,TIPOLOGIAS!A:F,5,0) -> TERRESTRE | AA39: BOLAÑOS TABORDA JORGE ENRIQUE | AB39: 1 | AC39: =IF(AND(W39="SOPORTE_TELEFÓNICO",OR(U39="SIN CONTACTO CON EL CB",U39="NÚMEROS DE CONTACTO ERRADOS")),0,IF(W39="SOPORTE_TELEFÓNICO",'BASE DE LIQUIDACION 2025'!$B$9,IF(Y39="TIPO I",'BASE DE LIQUIDACION 2025'!$C$3,IF(Y39="TIPO II",'BASE DE LIQUIDACION 2025'!$C$4,IF(Y39="TIPO III",'BASE DE LIQUIDACION 2025'!$C$5,'BASE DE LIQUIDACION 2025'!$C$6))))) -> 134410.88 | AD39: =IF(W39="SOPORTE_TELEFÓNICO",AC39,CIERRES!AB39*CIERRES!AC39) -> 134410.88
A40: MONTERIA | B40: =VLOOKUP(A40,'CENTRO DE COSTOS'!A:D,4,FALSE) -> JOSE MAURICIO HERNANDEZ ROJAS | C40: =VLOOKUP(A40,'CENTRO DE COSTOS'!A:C,2,FALSE) -> 0004-0001 | D40: 23001 | E40: TA-25-948859 | F40: 78090 | G40: ORDEN DE CAMBIO | H40: CORDOBA | I40: MONTERIA | J40: BARRIO URBANIZACION VALLEJO MONTERIA 8 | K40: REDEBAN | L40: FO-25-1353504 | M40: 45878.7 | N40: 45881.503 | P40: CIERRE | Q40: CIERRE | R40: CB UNO A UNO | S40: CB UNO A UNO | T40: NO_EXITOSO | U40: CB NO ENTREGA EQUIPO | V40: 0 0 12-08-2025 VISITA FALLIDA, LA PERSONA EN SITIO NO TIENE AUTORIZACIÓN DE ENTREGAR LOS EQUIPOS.CLIENTE NO LOGRA COMUNICARSE CON EL PROPIETARIO PARA LE DE EL AVAL DEL CIERRE | W40: VISITA_TÉCNICA | X40: 0 | Y40: TIPO I | Z40: =VLOOKUP(D40,TIPOLOGIAS!A:F,5,0) -> TERRESTRE | AA40: CALDERA SALCEDO CARLOS JULIO | AB40: 1 | AC40: =IF(AND(W40="SOPORTE_TELEFÓNICO",OR(U40="SIN CONTACTO CON EL CB",U40="NÚMEROS DE CONTACTO ERRADOS")),0,IF(W40="SOPORTE_TELEFÓNICO",'BASE DE LIQUIDACION 2025'!$B$9,IF(Y40="TIPO I",'BASE DE LIQUIDACION 2025'!$C$3,IF(Y40="TIPO II",'BASE DE LIQUIDACION 2025'!$C$4,IF(Y40="TIPO III",'BASE DE LIQUIDACION 2025'!$C$5,'BASE DE LIQUIDACION 2025'!$C$6))))) -> 44559.564 | AD40: =IF(W40="SOPORTE_TELEFÓNICO",AC40,CIERRES!AB40*CIERRES!AC40) -> 44559.564
...

Sheet TIPOLOGIAS
A1: COD. CIUDAD | B1: CIUDAD | C1: DEPARTAMENTO | D1: DESDE DONDE SE ATIENDE | E1: TIPO DE TRAYECTO NUEVO | F1: TIPOLOGIA NUEVA
A2: 91430 | B2: LA VICTORIA | C2: AMAZONAS | D2: BOGOTA | E2: AEREO | F2: TIPO IV ESPECIAL
A3: 91669 | B3: PUERTO SANTANDER | C3: AMAZONAS | D3: BOGOTA | E3: AEREO | F3: TIPO IV ESPECIAL
A4: 91263 | B4: EL ENCANTO | C4: AMAZONAS | D4: BOGOTA | E4: AEREO | F4: TIPO IV ESPECIAL
A5: 91405 | B5: LA CHORRERA | C5: AMAZONAS | D5: BOGOTA | E5: AEREO | F5: TIPO IV ESPECIAL
A6: 91407 | B6: LA PEDRERA | C6: AMAZONAS | D6: BOGOTA | E6: AEREO | F6: TIPO IV ESPECIAL
A7: 91001 | B7: LETICIA | C7: AMAZONAS | D7: BOGOTA | E7: AEREO | F7: TIPO IV ESPECIAL
A8: 91460 | B8: MIRITI - PARANA | C8: AMAZONAS | D8: BOGOTA | E8: AEREO | F8: TIPO IV ESPECIAL
A9: 91530 | B9: PUERTO ALEGRIA | C9: AMAZONAS | D9: BOGOTA | E9: AEREO | F9: TIPO IV ESPECIAL
A10: 91536 | B10: PUERTO ARICA | C10: AMAZONAS | D10: BOGOTA | E10: AEREO | F10: TIPO IV ESPECIAL
A11: 91540 | B11: PUERTO NARIÑO | C11: AMAZONAS | D11: BOGOTA | E11: AEREO | F11: TIPO IV ESPECIAL
A12: 91798 | B12: TARAPACA | C12: AMAZONAS | D12: BOGOTA | E12: AEREO | F12: TIPO IV ESPECIAL
A13: 5055 | B13: ARGELIA | C13: ANTIOQUIA | D13: MEDELLIN | E13: TERRESTRE | F13: TIPO IV
... A1124: 23682 | B1124: SAN JOSE DE URE | C1124: CORDOBA | D1124: MONTERIA | E1124: TERRESTRE | F1124: TIPO III

Sheet CENTRO DE COSTOS
A1: CIUDAD | B1: CENTRO_COSTO | C1: DESCRIPCION | D1: COORDINADOR
A2: APARTADO | B2: 0004-0005 | C2: Redeban Noroccidente (Medellín) | D2: JUAN SEBASTIÁN RÍOS CASTRILLÓN
A3: BARRANQUILLA | B3: 0004-0001 | C3: Redeban Costa (Barranqullla) | D3: JOSE MAURICIO HERNANDEZ ROJAS
A4: BOGOTA | B4: 0004-0004 | C4: Redeban Centro ( Bogotá) | D4: WILLIAM ASDRUBAL ROZO ROZO
A5: BUCARAMANGA | B5: 0004-0008 | C5: Redeban Santander | D5: MIGUEL JULIÁN HERNÁNDEZ GUARÍN
A6: CALI | B6: 0004-0003 | C6: Redeban Suroccidente (Cali) | D6: DIEGO FERNANDO HENAO CARDONA
A7: CARTAGENA | B7: 0004-0001 | C7: Redeban Costa (Barranqullla) | D7: JOSE MAURICIO HERNANDEZ ROJAS
