Workbook
Name A: #REF!
Name A: #REF!
Name ACTIVIDAD: [1]Hoja2!$P$2:$P$30
Name Actividad: [2]Formulas!$H$2:$H$5000
Name Analistas: '[3]Listas Desplegables'!$T$2:$T$7
Name arearesponsable: '[4]Listas desplegables'!$BB$2:$BB$100
Name CCO: [5]Tecnicos!$A$2:$A$1000
Name Clientes: [6]Clientes!$A$2:$A$100
Name Clientes: [2]Clientes!$A$2:$A$100
Name COORDINADOR: [1]Hoja2!$D$2:$D$30
Name Coordinadores: [7]Coordinadores!$A$2:$A$1000
Name Coordinadores: [2]Coordinadores!$A$2:$A$1000
Name DOCUMENTADOR: [1]Hoja2!$A$2:$A$30
Name ES: [1]Hoja2!$K$2:$K$30
Name ESS: [1]Hoja2!$K$2:$K$30
Name Estado: [6]Formulas!$K$2:$K$5000
Name Estado: [2]Formulas!$K$2:$K$5000
Name ESTADOACTIVIDAD: [1]Hoja2!$M$2:$M$30
Name ESTADOS: '[8]Listas desplegables'!$B$1:$D$1
Name ESTADOS: '[9]Listas desplegables'!$B$1:$D$1
Name ESTADOSCIERRES: '[10]lista desplegable'!$CX$1:$DA$1
Name Facturacion: '[11]Listas desplegables'!$AO$1:$AR$1
Name FACTURACIÓN: '[8]Listas desplegables'!$Y$1:$AB$1
Name FACTURACIÓN: '[9]Listas desplegables'!$Y$1:$AB$1
Name falla: #REF!
Name Fallas: '[12]Listas desplegables'!$F$2:$L$2
Name Fallas: '[13]Listas desplegables'!$F$2:$L$2
Name Grupo_Falla: '[14]Listas Desplegables'!$CH$2:$CH$5
Name Grupo_Falla: '[15]Listas Desplegables'!$CH$2:$CH$5
Name inconservmanager: '[16]Listas desplegables'!$BC$2:$BC$100
Name inconservmanager: '[4]Listas desplegables'!$BC$2:$BC$100
Name INCUMPLIMIENTO: '[4]Listas desplegables'!$AK$1:$AN$1
Name INCUMPLIMIENTO: '[17]Listas desplegables'!$AT$1:$AX$1
Name LISTA: [18]Dptos!$A$1139:$A$1171
Name LISTA: [19]Dptos!$A$1139:$A$1171
Name LISTA2: #REF!
Name LISTA2: #REF!
Name LOLO: [20]Coordinadores!$A$2:$A$1000
Name solicitudes: '[11]Listas desplegables'!$U$1:$AF$1
Name solicitudes: '[21]Listas desplegables'!$AF$1:$AQ$1
Name Tecnicos: [6]Tecnicos!$A$2:$A$1000
Name Tecnicos: [2]Tecnicos!$A$2:$A$1000
Name Version: [22]Formulas!$I$2:$I$3
Name Version: [2]Formulas!$I$2:$I$3

Sheet Detalle REDEBAN
A1: FACTURACIÓN ACTIVIDADES REDEBAN CB BANCOLOMBIA Y AVAL
A2: 1 AL 30 DE AGOSTO 2025
A4: CONCEPTOS | B4: CANTIDAD | C4: TOTAL
A5: Aperturas Bancolombia | B5: =COUNTA('APERTURAS BANCOLOMBIA'!$A:$A)-1 -> 508 | C5: ='APERTURAS BANCOLOMBIA'!AC510 -> 94349557
A6: Incidentes Bancolombia | B6: =COUNTA('INCIDENTES BANCOLOMBIA'!A:A)-1 -> 1268 | C6: ='INCIDENTES BANCOLOMBIA'!AF1270 -> 1.9300888e+08
A7: Gestión de Campo Bancolombia | B7: =COUNTA('OC BANCOLOMBIA'!A:A)-1 -> 449 | C7: ='OC BANCOLOMBIA'!AF451 -> 72797755
A8: Soporte Papelería Bancolombia | B8: =COUNTA(PAPELERIA!A:A)-1 -> 2113 | C8: =PAPELERIA!AE2115 -> 88607824
A9: Aperturas Aval | B9: =COUNTA('APERTURAS AVAL'!A:A)-1 -> 151 | C9: ='APERTURAS AVAL'!AB153 -> 23187291
A10: Incidentes Aval | B10: =COUNTA('INCIDENTES AVAL'!A:A)-1 -> 303 | C10: ='INCIDENTES AVAL'!AD305 -> 35001862
A11: Gestión de Campo Aval | B11: =COUNTA('OC AVAL'!A:A)-1 -> 92 | C11: ='OC AVAL'!AF94 -> 12141358
A12: Aperturas BBVA | B12: =COUNTA('APERTURAS BBVA'!A:A)-1 -> 0 | C12: ='APERTURAS BBVA'!AH3 -> 0
A13: Gestión de Campo BBVA | B13: =COUNTA('OC BBVA'!A:A)-1 -> 2 | C13: ='OC BBVA'!AF4 -> 289935.74
A14: Incidentes BBVA | B14: =COUNTA('INCIDENTES BBVA'!A:A)-1 -> 0 | C14: ='INCIDENTES BBVA'!AD5 -> 0
A15: SUBTOTAL | C15: =SUM(C5:C14) -> 5.1938446e+08
A16: Iva | C16: =C15*0.19 -> 98683047
A17: TOTAL | B17: TOTAL | C17: =C15+C16 -> 6.1806751e+08

Sheet BASE LIQUIDACION REDEBAN 2025
A1: Tipificación | B1: Implementaciones | C1: Incidentes – Ordenes de Cambio | D1: Fallida | G1: Tipificación | H1: Actividad sin cambio de datafono | J1: Actividad + adicional cambio de datafono | L1: Visita Fallida | N1: Incremento 2025
A2: TIPO I | B2: =71384.4052*(1+$N$2) -> 75096.394 | C2: =62699.6885*(1+$N$2) -> 65960.072 | D2: =35693.4343*(1+$N$2) -> 37549.493 | H2: Instalación Pinpad + HUB | I2: Segunda actividad en mismo comercio, misma visita | J2: Instalación Pinpad + HUB | K2: Segunda actividad en mismo comercio, misma visita | N2: 0.052
A3: TIPO II | B3: =155716.4408*(1+$N$2) -> 163813.7 | C3: =137802.16*(1+$N$2) -> 144967.87 | D3: =117879.8485*(1+$N$2) -> 124009.6 | G3: Tipo I | H3: =31819.23994686*(1+$N$2) -> 33473.84 | I3: =26222.67548178*(1+$N$2) -> 27586.255 | J3: =51196.46628516*(1+$N$2) -> 53858.683 | K3: =42157.66342524*(1+$N$2) -> 44349.862 | L3: =28948.10610808*(1+$N$2) -> 30453.408
A4: TIPO III | B4: =262099.6015*(1+$N$2) -> 275728.78 | C4: =262099.6015*(1+$N$2) -> 275728.78 | D4: =262099.6015*(1+$N$2) -> 275728.78 | G4: Tipo II | H4: =98014.03066668*(1+$N$2) -> 103110.76 | I4: =26222.67548178*(1+$N$2) -> 27586.255 | J4: =119562.49505524*(1+$N$2) -> 125779.74 | K4: =42157.66342524*(1+$N$2) -> 44349.862 | L4: =94765.6295813*(1+$N$2) -> 99693.442
A5: TIPO IV | B5: =479878.9419*(1+$N$2) -> 504832.65 | C5: =455882.9625*(1+$N$2) -> 479588.88 | D5: =370911.6746*(1+$N$2) -> 390199.08 | G5: Tipo III | H5: =189140.9827006*(1+$N$2) -> 198976.31 | I5: =26222.67548178*(1+$N$2) -> 27586.255 | J5: =200461.60194168*(1+$N$2) -> 210885.61 | K5: =42157.66342524*(1+$N$2) -> 44349.862 | L5: =171492.68108896*(1+$N$2) -> 180410.3
A6: Destino Aéreo | B6: =939603.5767*(1+$N$2) -> 988462.96 | C6: a partir del 5to servicio | G6: Tipo IV | H6: =461621.60109668*(1+$N$2) -> 485625.92 | I6: =26222.67548178*(1+$N$2) -> 27586.255 | J6: =461621.60109668*(1+$N$2) -> 485625.92 | K6: =42157.66342524*(1+$N$2) -> 44349.862 | L6: =461621.60109668*(1+$N$2) -> 485625.92
G7: * Tipo IV Especial Donde se requiera desplazamiento aéreo o fluvial será facturado el valor de la actividad y adicional el valor de $988.463 por cada 5 actividades de esta tipología
A8: Tarifas para día adicional de actividades:
A9: Tipificación | B9: Día adicional- menos de dos horas | C9: Medio día adicional | D9: Día adicional- más de 4 horas
A10: Tipo I | B10: =71384.4052*(1+$N$2) -> 75096.394 | C10: =133455.9267*(1+$N$2) -> 140395.63 | D10: =191225.1201*(1+$N$2) -> 201168.83 | G10: Actividad | H10: Unidad | I10: Valor Unitario
A11: Tipo II | B11: =133455.9267*(1+$N$2) -> 140395.63 | C11: =191225.1201*(1+$N$2) -> 201168.83 | D11: =257740.6152*(1+$N$2) -> 271143.13 | G11: Gestión telefónica y cierre de incidente de bloqueo | H11: Unidad | I11: =17639.19516086*(1+$N$2) -> 18556.433
A12: Tipo III | B12: =186821.7926*(1+$N$2) -> 196536.53 | C12: =248892.0824*(1+$N$2) -> 261834.47 | D12: =306662.5075*(1+$N$2) -> 322608.96 | G12: Servicio de cierre de incidente de bloqueo | H12: Unidad | I12: =4810.80785492*(1+$N$2) -> 5060.9699
A13: Tipo IV | B13: =186821.7926*(1+$N$2) -> 196536.53 | C13: =248892.0824*(1+$N$2) -> 261834.47 | D13: =306662.5075*(1+$N$2) -> 322608.96
A16: Servicio | B16: Tarifa actividad | D16: VALOR DE LA TERMINAL ADICIONAL | E16: VALOR DE INSTALACIÓN DE BASE EN "Y"
A17: Papelería – Tarifa única | B17: =34010.9321*(1+$N$2) -> 35779.501 | D17: =20537.3658*(1+$N$2) -> 21605.309 | E17: =10737.9606*(1+$N$2) -> 11296.335
A18: Papelería Tipo II - Visita técnica | B18: =64310*(1+$N$2) -> 67654.12
A19: Solución telefónica | B19: =39202.5476*(1+$N$2) -> 41241.08
A22: Traifas 2024
A23: Tipificación | B23: Implementaciones | C23: Incidentes – Ordenes de Cambio | D23: Fallida | G23: Tipificación | H23: Actividad sin cambio de datafono | J23: Actividad + adicional cambio de datafono | L23: Visita Fallida
A24: TIPO I | B24: 71384.405 | C24: 62699.689 | D24: 35693.434 | H24: Instalación Pinpad + HUB | I24: Segunda actividad en mismo comercio, misma visita | J24: Instalación Pinpad + HUB | K24: Segunda actividad en mismo comercio, misma visita
A25: TIPO II | B25: 155716.44 | C25: 137802.16 | D25: 117879.85 | G25: Tipo I | H25: 31819.24 | I25: 26222.675 | J25: 51196.466 | K25: 42157.663 | L25: 28948.106
A26: TIPO III | B26: 262099.6 | C26: 262099.6 | D26: 262099.6 | G26: Tipo II | H26: 98014.031 | I26: 26222.675 | J26: 119562.5 | K26: 42157.663 | L26: 94765.63
A27: TIPO IV | B27: 479878.94 | C27: 455882.96 | D27: 370911.67 | G27: Tipo III | H27: 189140.98 | I27: 26222.675 | J27: 200461.6 | K27: 42157.663 | L27: 171492.68
A28: Destino Aéreo | B28: 939603.58 | C28: a partir del 5to servicio | G28: Tipo IV | H28: 461621.6 | I28: 26222.675 | J28: 461621.6 | K28: 42157.663 | L28: 461621.6
G29: * Tipo IV Especial Donde se requiera desplazamiento aéreo o fluvial será facturado el valor de la actividad y adicional el valor de $939,604 por cada 5 actividades de esta tipología
A30: Tarifas para día adicional de actividades:
A31: Tipificación | B31: Día adicional- menos de dos horas | C31: Medio día adicional | D31: Día adicional- más de 4 horas
A32: Tipo I | B32: 71384.405 | C32: 133455.93 | D32: 191225.12 | G32: Actividad | H32: Unidad | I32: Valor Unitario
A33: Tipo II | B33: 133455.93 | C33: 191225.12 | D33: 257740.62 | G33: Gestión telefónica y cierre de incidente de bloqueo | H33: Unidad | I33: 17639.195
A34: Tipo III | B34: 186821.79 | C34: 248892.08 | D34: 306662.51 | G34: Servicio de cierre de incidente de bloqueo | H34: Unidad | I34: 4810.8079
A35: Tipo IV | B35: 186821.79 | C35: 248892.08 | D35: 306662.51
A38: Servicio | B38: Tarifa actividad | D38: VALOR DE LA TERMINAL ADICIONAL | E38: VALOR DE INSTALACIÓN DE BASE EN "Y"
A39: Papelería – Tarifa única | B39: 34010.932 | D39: 20537.366 | E39: 10737.961
A40: Papelería Tipo II - Visita técnica | B40: 64310
A41: Solución telefónica | B41: 39202.548

Sheet CENTRO DE COSTOS
A1: CIUDAD | B1: CENTRO_COSTO | C1: DESCRIPCION | D1: COORDINADOR
A2: APARTADO | B2: 0004-0005 | C2: Redeban Noroccidente (Medellín) | D2: JUAN SEBASTIÁN RÍOS CASTRILLÓN
A3: BARRANQUILLA | B3: 0004-0001 | C3: Redeban Costa (Barranqullla) | D3: JOSE MAURICIO HERNANDEZ ROJAS
A4: BOGOTA | B4: 0004-0004 | C4: Redeban Centro ( Bogotá) | D4: WILLIAM ASDRUBAL ROZO ROZO
A5: BUCARAMANGA | B5: 0004-0008 | C5: Redeban Santander | D5: MIGUEL JULIÁN HERNÁNDEZ GUARÍN
A6: CALI | B6: 0004-0003 | C6: Redeban Suroccidente (Cali) | D6: DIEGO FERNANDO HENAO CARDONA
A7: CARTAGENA | B7: 0004-0001 | C7: Redeban Costa (Barranqullla) | D7: JOSE MAURICIO HERNANDEZ ROJAS
A8: CUCUTA | B8: 0004-0008 | C8: Redeban Santander | D8: MIGUEL JULIÁN HERNÁNDEZ GUARÍN
A9: FLORENCIA | B9: 0004-0007 | C9: Redeban Oriente (Otros) | D9: KEVIN ALEXIS CORZO BUSTOS
A10: IBAGUE | B10: 0004-0007 | C10: Redeban Oriente (Otros) | D10: KEVIN ALEXIS CORZO BUSTOS
A11: MANIZALES | B11: 0004-0002 | C11: Redeban Eje Cafetero (Pereira) | D11: DIEGO FERNANDO HENAO CARDONA
A12: MEDELLIN | B12: 0004-0005 | C12: Redeban Noroccidente (Medellín) | D12: JUAN SEBASTIÁN RÍOS CASTRILLÓN
... A23: YOPAL | B23: 0004-0007 | C23: Redeban Oriente (Otros) | D23: KEVIN ALEXIS CORZO BUSTOS

Sheet Tablas dinámicas
A1: APERTURAS BANCOLOMBIA | G1: NOMBRE DE CC | H1: Suma de VALOR CC | I1: Suma de VALOR CC2
A2: COORDINADOR | B2: CENTRO DE COSTOS LÍNEACOM | C2: Suma de VALOR FACTURABLE A LA RED | D2: NOMBRE DE CC | E2: VALOR CC | G2: Redeban Centro ( Bogotá) | H2: 58483522 | I2: 0.1126016
A3: DIEGO FERNANDO HENAO CARDONA | B3: 0004-0002 | C3: 5822339.2 | D3: =VLOOKUP(B3,'CENTRO DE COSTOS'!B:C,2,0) -> Redeban Eje Cafetero (Pereira) | E3: =C3 -> 5822339.2 | G3: Redeban Costa (Barranqullla) | H3: 87388554 | I3: 0.16825408
B4: 0004-0003 | C4: 16230338 | D4: =VLOOKUP(B4,'CENTRO DE COSTOS'!B:C,2,0) -> Redeban Suroccidente (Cali) | E4: =C4 -> 16230338 | G4: Redeban Eje Cafetero (Pereira) | H4: 22430644 | I4: 0.043186976
A5: JOSE MAURICIO HERNANDEZ ROJAS | B5: 0004-0001 | C5: 16690174 | D5: =VLOOKUP(B5,'CENTRO DE COSTOS'!B:C,2,0) -> Redeban Costa (Barranqullla) | E5: =C5 -> 16690174 | G5: Redeban Noroccidente (Medellín) | H5: 1.0264108e+08 | I5: 0.19762062
A6: JUAN SEBASTIÁN RÍOS CASTRILLÓN | B6: 0004-0005 | C6: 15826985 | D6: =VLOOKUP(B6,'CENTRO DE COSTOS'!B:C,2,0) -> Redeban Noroccidente (Medellín) | E6: =C6 -> 15826985 | G6: Redeban Oriente (Otros) | H6: 76399104 | I6: 0.14709548
A7: KEVIN ALEXIS CORZO BUSTOS | B7: 0004-0007 | C7: 12991593 | D7: =VLOOKUP(B7,'CENTRO DE COSTOS'!B:C,2,0) -> Redeban Oriente (Otros) | E7: =C7 -> 12991593 | G7: Redeban Santander | H7: 96753187 | I7: 0.18628433
A8: MIGUEL JULIÁN HERNÁNDEZ GUARÍN | B8: 0004-0008 | C8: 19062375 | D8: =VLOOKUP(B8,'CENTRO DE COSTOS'!B:C,2,0) -> Redeban Santander | E8: =C8 -> 19062375 | G8: Redeban Suroccidente (Cali) | H8: 75288369 | I8: 0.14495691
A9: WILLIAM ASDRUBAL ROZO ROZO | B9: 0004-0004 | C9: 7725752.1 | D9: =VLOOKUP(B9,'CENTRO DE COSTOS'!B:C,2,0) -> Redeban Centro ( Bogotá) | E9: =C9 -> 7725752.1 | G9: Total general | H9: 5.1938446e+08 | I9: 1
A10: Total general | C10: 94349557
A15: INCIDENTES BANCOLOMBIA
A16: COORDINADOR | B16: CENTRO DE COSTOS LÍNEACOM | C16: Suma de VALOR FACTURABLE A LA RED | D16: NOMBRE DE CC | E16: VALOR CC
A17: DIEGO FERNANDO HENAO CARDONA | B17: 0004-0002 | C17: 7597782.2 | D17: =VLOOKUP(B17,'CENTRO DE COSTOS'!B:C,2,0) -> Redeban Eje Cafetero (Pereira) | E17: =C17 -> 7597782.2
B18: 0004-0003 | C18: 25923885 | D18: =VLOOKUP(B18,'CENTRO DE COSTOS'!B:C,2,0) -> Redeban Suroccidente (Cali) | E18: =C18 -> 25923885
A19: JOSE MAURICIO HERNANDEZ ROJAS | B19: 0004-0001 | C19: 38090363 | D19: =VLOOKUP(B19,'CENTRO DE COSTOS'!B:C,2,0) -> Redeban Costa (Barranqullla) | E19: =C19 -> 38090363
A20: JUAN SEBASTIÁN RÍOS CASTRILLÓN | B20: 0004-0005 | C20: 44541702 | D20: =VLOOKUP(B20,'CENTRO DE COSTOS'!B:C,2,0) -> Redeban Noroccidente (Medellín) | E20: =C20 -> 44541702
A21: KEVIN ALEXIS CORZO BUSTOS | B21: 0004-0007 | C21: 27986392 | D21: =VLOOKUP(B21,'CENTRO DE COSTOS'!B:C,2,0) -> Redeban Oriente (Otros) | E21: =C21 -> 27986392
A22: MIGUEL JULIÁN HERNÁNDEZ GUARÍN | B22: 0004-0008 | C22: 32605647 | D22: =VLOOKUP(B22,'CENTRO DE COSTOS'!B:C,2,0) -> Redeban Santander | E22: =C22 -> 32605647
A23: WILLIAM ASDRUBAL ROZO ROZO | B23: 0004-0004 | C23: 16263108 | D23: =VLOOKUP(B23,'CENTRO DE COSTOS'!B:C,2,0) -> Redeban Centro ( Bogotá) | E23: =C23 -> 16263108
A24: Total general | C24: 1.9300888e+08
A30: ORDENES DE CAMBIO BANCOLOMBIA
A31: COORDINADOR | B31: CENTRO DE COSTOS LÍNEACOM | C31: Suma de VALOR TOTAL | D31: NOMBRE DE CC | E31: VALOR CC
A32: DIEGO FERNANDO HENAO CARDONA | B32: 0004-0002 | C32: 2817155.6 | D32: =VLOOKUP(B32,'CENTRO DE COSTOS'!B:C,2,0) -> Redeban Eje Cafetero (Pereira) | E32: =C32 -> 2817155.6
B33: 0004-0003 | C33: 9402777.1 | D33: =VLOOKUP(B33,'CENTRO DE COSTOS'!B:C,2,0) -> Redeban Suroccidente (Cali) | E33: =C33 -> 9402777.1
A34: JOSE MAURICIO HERNANDEZ ROJAS | B34: 0004-0001 | C34: 9215551.5 | D34: =VLOOKUP(B34,'CENTRO DE COSTOS'!B:C,2,0) -> Redeban Costa (Barranqullla) | E34: =C34 -> 9215551.5
A35: JUAN SEBASTIÁN RÍOS CASTRILLÓN | B35: 0004-0005 | C35: 15480396 | D35: =VLOOKUP(B35,'CENTRO DE COSTOS'!B:C,2,0) -> Redeban Noroccidente (Medellín) | E35: =C35 -> 15480396
A36: KEVIN ALEXIS CORZO BUSTOS | B36: 0004-0007 | C36: 11899557 | D36: =VLOOKUP(B36,'CENTRO DE COSTOS'!B:C,2,0) -> Redeban Oriente (Otros) | E36: =C36 -> 11899557
A37: MIGUEL JULIÁN HERNÁNDEZ GUARÍN | B37: 0004-0008 | C37: 16002255 | D37: =VLOOKUP(B37,'CENTRO DE COSTOS'!B:C,2,0) -> Redeban Santander | E37: =C37 -> 16002255
A38: WILLIAM ASDRUBAL ROZO ROZO | B38: 0004-0004 | C38: 7980063.8 | D38: =VLOOKUP(B38,'CENTRO DE COSTOS'!B:C,2,0) -> Redeban Centro ( Bogotá) | E38: =C38 -> 7980063.8
A39: Total general | C39: 72797755
A45: PAPELERIA BANCOLOMBIA
A46: COORDINADOR | B46: CENTRO DE COSTOS LÍNEACOM | C46: Suma de VALOR TOTAL | D46: NOMBRE DE CC | E46: VALOR CC
A47: DIEGO FERNANDO HENAO CARDONA | B47: 0004-0002 | C47: 4394975.5 | D47: =VLOOKUP(B47,'CENTRO DE COSTOS'!B:C,2,0) -> Redeban Eje Cafetero (Pereira) | E47: =C47 -> 4394975.5
B48: 0004-0003 | C48: 12183386 | D48: =VLOOKUP(B48,'CENTRO DE COSTOS'!B:C,2,0) -> Redeban Suroccidente (Cali) | E48: =C48 -> 12183386
A49: JOSE MAURICIO HERNANDEZ ROJAS | B49: 0004-0001 | C49: 17391768 | D49: =VLOOKUP(B49,'CENTRO DE COSTOS'!B:C,2,0) -> Redeban Costa (Barranqullla) | E49: =C49 -> 17391768
A50: JUAN SEBASTIÁN RÍOS CASTRILLÓN | B50: 0004-0005 | C50: 20563599 | D50: =VLOOKUP(B50,'CENTRO DE COSTOS'!B:C,2,0) -> Redeban Noroccidente (Medellín) | E50: =C50 -> 20563599
A51: KEVIN ALEXIS CORZO BUSTOS | B51: 0004-0007 | C51: 9461601.8 | D51: =VLOOKUP(B51,'CENTRO DE COSTOS'!B:C,2,0) -> Redeban Oriente (Otros) | E51: =C51 -> 9461601.8
A52: MIGUEL JULIÁN HERNÁNDEZ GUARÍN | B52: 0004-0008 | C52: 13964993 | D52: =VLOOKUP(B52,'CENTRO DE COSTOS'!B:C,2,0) -> Redeban Santander | E52: =C52 -> 13964993
A53: WILLIAM ASDRUBAL ROZO ROZO | B53: 0004-0004 | C53: 10647501 | D53: =VLOOKUP(B53,'CENTRO DE COSTOS'!B:C,2,0) -> Redeban Centro ( Bogotá) | E53: =C53 -> 10647501
A54: Total general | C54: 88607824
...

Sheet APERTURAS BANCOLOMBIA
A1: CIUDAD SEDE | B1: COORDINADOR | C1: CENTRO DE COSTOS LÍNEACOM | D1: CÓDIGO DANE | E1: TA/CODIGO ACTIVIDAD | F1: CODIGO CB | G1: ACTIVIDAD | H1: TIPO DE APERTURA | I1: DEPARTAMENTO | J1: CIUDAD | K1: NOMBRE DEL CB | L1: RED | M1: FO | N1: FECHA LISTA | O1: FECHA ULTIMA ACTUALIZACION | P1: FORMATO | Q1: CADENA | R1: ESTADO | S1: OBSERVACIONES CLIENTE | T1: FORMA DE ATENCIÓN | U1: TERMINALES | V1: TIPO DE ATENCION | W1: TIPO DE TRAYECTO | X1: NOMBRE DEL TECNICO | Y1: DIAS DE VISITA | Z1: DIA ADICIONAL | AA1: VALOR DIAS ACTIVIDAD FACTURABLES A LA RED | AB1: VALOR DIAS ACOMPAÑAMIENTO FACTURABLES | AC1: VALOR FACTURABLE A LA RED | AD1: CU CB | AE1: COBRO ENTIDAD | AF1: ESTADO | AG1: TIPO | AH1: VAL TIPO | AI1: VAL COSTO | AJ1: OBSERVACIONES | AK1: OBSERVACIONES LINEA
A2: NEIVA | B2: =VLOOKUP(A2,'CENTRO DE COSTOS'!A:D,4,FALSE) -> KEVIN ALEXIS CORZO BUSTOS | C2: =VLOOKUP(A2,'CENTRO DE COSTOS'!A:D,2,FALSE) -> 0004-0007 | D2: 18001 | E2: TA-25-897275 | F2: 80665 | G2: APERTURA | H2: CB CRECIMIENTO - NUEVO | I2: CAQUETA | J2: FLORENCIA | K2: BARRIO BUENOS AIRES FLORENCIA 1 | L2: REDEBAN | M2: FO-25-1293630 | N2: 45866 | O2: 45870 | P2: UNO A UNO | Q2: UNO A UNO | R2: EJECUTADO | S2: 28-07-2025 SE REALIZA LLAMADA AL CLIENTE, SE HABLA CON CON EL ESPOSO DE LA SRA LEIDY VERONICA CARVAJAL BARRETO SE VALIDA DIRECCIÓN OK, CANAL OK, DISPONIBILIDAD TOTAL, LLAMAR EL DÍA LA INSTALACIÓN PARA CONFIRMAR VISITA, AVISO EXTERIOR ALTURA APROX 3,30 METROS; TOMACORRIENTE CERCANO: SI; TIENE CABINA DE SEGURIDAD: NO // CONTACTO REALIZADO POR LA APP 01-0 SE REALIZA INSTALACIÓN DE CORRESPONSAL, SE INSTALAN EQUIPOS CON PRUEBAS EXITOSAS, SE CAPACITA Y SE EVALÚA AL CLIENTE, SE INSTALA PUBLICIDAD COMPLETA, CB QUEDA OPERATIVO. USUARIO SOMOS BANCOLOMBIA ACTIVO | T2: VISITA_TECNICA | U2: V8ZZZ345 | V2: TIPO IV | W2: TERRESTRE | X2: DEVIA REINOSO JUAN CARLOS | Y2: 1 | Z2: 0 | AA2: =IF(V2="TIPO I",'BASE LIQUIDACION REDEBAN 2025'!$B$2,IF(V2="TIPO II",'BASE LIQUIDACION REDEBAN 2025'!$B$3,IF(V2="TIPO III",'BASE LIQUIDACION REDEBAN 2025'!$B$4,IF(V2="TIPO IV",'BASE LIQUIDACION REDEBAN 2025'!$B$5,IF(W2="AEREO",'BASE LIQUIDACION REDEBAN 2025'!$B$6,'BASE LIQUIDACION REDEBAN 2025'!$B$5))))) -> 504832.65 | AB2: =IF(V2="TIPO I",'BASE LIQUIDACION REDEBAN 2025'!$B$10,IF(V2="TIPO II",'BASE LIQUIDACION REDEBAN 2025'!$B$11,IF(V2="TIPO III",'BASE LIQUIDACION REDEBAN 2025'!$B$12,'BASE LIQUIDACION REDEBAN 2025'!$B$13))) -> 196536.53 | AC2: =Y2*AA2+Z2*AB2 -> 504832.65
A3: NEIVA | B3: =VLOOKUP(A3,'CENTRO DE COSTOS'!A:D,4,FALSE) -> KEVIN ALEXIS CORZO BUSTOS | C3: =VLOOKUP(A3,'CENTRO DE COSTOS'!A:D,2,FALSE) -> 0004-0007 | D3: 18001 | E3: TA-25-897283 | F3: 80664 | G3: APERTURA | H3: CB CRECIMIENTO - NUEVO | I3: CAQUETA | J3: FLORENCIA | K3: BARRIO SIETE DE AGOSTO FLORENCIA 7 | L3: REDEBAN | M3: FO-25-1293646 | N3: 45866 | O3: 45870 | P3: UNO A UNO | Q3: UNO A UNO | R3: EJECUTADO | S3: 28-07-2025 SE REALIZA LLAMADA AL CLIENTE, SE HABLA CON CON EL SR LUIS MIGUEL BAHAMON ROJAS SE VALIDA DIRECCIÓN OK, CANAL OK, DISPONIBILIDAD TOTAL, LLAMAR EL DÍA LA INSTALACIÓN PARA CONFIRMAR VISITA, AVISO EXTERIOR ALTURA APROX 2 METROS; TOMACORRIENTE CERCANO: SI; TIENE CABINA DE SEGURIDAD: SI // CONTACTO REALIZADO POR LA APP 1/08/2025 SE REALIZA INSTALACIÓN DE CORRESPONSAL, SE INSTALAN EQUIPOS CON PRUEBAS EXITOSAS, SE CAPACITA Y SE EVALÚA AL CLIENTE, SE INSTALA PUBLICIDAD COMPLETA, CB QUEDA OPERATIVO. USUARIO SOMOS BANCOLOMBIA ACTIVO | T3: VISITA_TECNICA | U3: V8ZZZ349 | V3: TIPO IV | W3: TERRESTRE | X3: DEVIA REINOSO JUAN CARLOS | Y3: 1 | Z3: 0 | AA3: =IF(V3="TIPO I",'BASE LIQUIDACION REDEBAN 2025'!$B$2,IF(V3="TIPO II",'BASE LIQUIDACION REDEBAN 2025'!$B$3,IF(V3="TIPO III",'BASE LIQUIDACION REDEBAN 2025'!$B$4,IF(V3="TIPO IV",'BASE LIQUIDACION REDEBAN 2025'!$B$5,IF(W3="AEREO",'BASE LIQUIDACION REDEBAN 2025'!$B$6,'BASE LIQUIDACION REDEBAN 2025'!$B$5))))) -> 504832.65 | AB3: =IF(V3="TIPO I",'BASE LIQUIDACION REDEBAN 2025'!$B$10,IF(V3="TIPO II",'BASE LIQUIDACION REDEBAN 2025'!$B$11,IF(V3="TIPO III",'BASE LIQUIDACION REDEBAN 2025'!$B$12,'BASE LIQUIDACION REDEBAN 2025'!$B$13))) -> 196536.53 | AC3: =Y3*AA3+Z3*AB3 -> 504832.65
A4: PASTO | B4: =VLOOKUP(A4,'CENTRO DE COSTOS'!A:D,4,FALSE) -> DIEGO FERNANDO HENAO CARDONA | C4: =VLOOKUP(A4,'CENTRO DE COSTOS'!A:D,2,FALSE) -> 0004-0003 | D4: 52427 | E4: TA-25-897342 | F4: 80676 | G4: APERTURA | H4: CB CRECIMIENTO - NUEVO | I4: NARIÑO | J4: MAGUI | K4: BARRIO CRR BRISAS DE HAMBURGO MAGUI | L4: REDEBAN | M4: FO-25-1293775 | N4: 45866 | O4: 45883 | P4: UNO A UNO | Q4: UNO A UNO | R4: EJECUTADO | S4: 28-07 SE REALIZA LLAMADA AL CLIENTE, SE HABLA CON LA SRA KAROL NATALIA ANGULO CORTES SE VALIDA DIRECCIÓN OK, CANAL OK, DISPONIBILIDAD TOTAL, LLAMAR EL DÍA LA INSTALACIÓN PARA CONFIRMAR VISITA, AVISO EXTERIOR ALTURA APROX 4 METROS; TOMACORRIENTE CERCANO: SI; TIENE CABINA DE SEGURIDAD: SI 06-08 DADO QUE EL SITIO SE DEBE REALIZAR DESPLAZAMIENTO MARITIMO, SE REALIZARA EL DIA LUNES 11 POR DISPONIBILIDAD DE TRANSPORTE. 11-08 SÉ ALCANZO A LLEGAR HASTA POR DEMORAS EN EL TRANSPORTE (LANCHA) 12-08 SE ESTA PENDIENTE DEL TRANSPORTE EN LANCHA PARA LLEGAR AL SITIO, NOS ENCONTRAMOS EN LA ZONA EN DESPLAZAMIENTO 13-08 SE LLEGA TARDE AL MUNICIPIO Y POR ENDE NO SE ALCANCANZA A REALIZAR LA INSTALACIÓN, SE PROGRAMA PARA EL DIA SIGUIENTE 14/08/2025 SE REALIZA INSTALACIÓN DE CORRESPONSAL, SE INSTALAN EQUIPOS CON PRUEBAS EXITOSAS, SE CAPACITA Y SE EVALÚA AL CLIENTE, SE INSTALA PUBLICIDAD COMPLETA, CB QUEDA OPERATIVO. USUARIO SOMOS BANCOLOMBIA ACTIVO | T4: VISITA_TECNICA | U4: V8ZZZ380 | V4: TIPO IV ESPECIAL | W4: FLUVIAL | X4: PAZ MARTINEZ RICHARD HUMBERTO | Y4: 1 | Z4: 0 | AA4: =IF(V4="TIPO I",'BASE LIQUIDACION REDEBAN 2025'!$B$2,IF(V4="TIPO II",'BASE LIQUIDACION REDEBAN 2025'!$B$3,IF(V4="TIPO III",'BASE LIQUIDACION REDEBAN 2025'!$B$4,IF(V4="TIPO IV",'BASE LIQUIDACION REDEBAN 2025'!$B$5,IF(W4="AEREO",'BASE LIQUIDACION REDEBAN 2025'!$B$6,'BASE LIQUIDACION REDEBAN 2025'!$B$5))))) -> 504832.65 | AB4: =IF(V4="TIPO I",'BASE LIQUIDACION REDEBAN 2025'!$B$10,IF(V4="TIPO II",'BASE LIQUIDACION REDEBAN 2025'!$B$11,IF(V4="TIPO III",'BASE LIQUIDACION REDEBAN 2025'!$B$12,'BASE LIQUIDACION REDEBAN 2025'!$B$13))) -> 196536.53 | AC4: =Y4*AA4+Z4*AB4 -> 504832.65
A5: PASTO | B5: =VLOOKUP(A5,'CENTRO DE COSTOS'!A:D,4,FALSE) -> DIEGO FERNANDO HENAO CARDONA | C5: =VLOOKUP(A5,'CENTRO DE COSTOS'!A:D,2,FALSE) -> 0004-0003 | D5: 52427 | E5: TA-25-897364 | F5: 80675 | G5: APERTURA | H5: CB CRECIMIENTO - NUEVO | I5: NARIÑO | J5: MAGUI | K5: BARRIO LA PISTA MAGUI | L5: REDEBAN | M5: FO-25-1293834 | N5: 45866 | O5: 45883 | P5: UNO A UNO | Q5: UNO A UNO | R5: EJECUTADO | S5: 28-07 SE REALIZA LLAMADA AL CLIENTE, SE HABLA CON LA SRA DAYAN YORELY ANGULO CORTES SE VALIDA DIRECCIÓN OK, CANAL OK, DISPONIBILIDAD TOTAL, LLAMAR EL DÍA LA INSTALACIÓN PARA CONFIRMAR VISITA, AVISO EXTERIOR ALTURA APROX 4 METROS; TOMACORRIENTE CERCANO: SI; TIENE CABINA DE SEGURIDAD: SI - COMUNICACIÓN POR WPP 06-08 DEBIDO A QUE EL DESPLAZAMIENTO ES VIA MARITIMA, DADO DISPONIBILIDAD DE TRANSPORTE SE REALIZARA EL DIA LUNES 11-08 SÉ ALCANZO A LLEGAR HASTA POR DEMORAS EN EL TRANSPORTE (LANCHA) 12-08 SE ESTA PENDIENTE DEL TRANSPORTE EN LANCHA PARA LLEGAR AL SITIO, NOS ENCONTRAMOS EN LA ZONA EN DESPLAZAMIENTO 13-08 SE LLEGA TARDE AL MUNICIPIO Y POR ENDE NO SE ALCANCANZA A REALIZAR LA INSTALACIÓN, SE PROGRAMA PARA EL DIA SIGUIENTE 14/08/2025 SE REALIZA INSTALACIÓN DE CORRESPONSAL, SE INSTALAN EQUIPOS CON PRUEBAS EXITOSAS, SE CAPACITA Y SE EVALÚA AL CLIENTE, SE INSTALA PUBLICIDAD COMPLETA, CB QUEDA OPERATIVO. USUARIO SOMOS BANCOLOMBIA ACTIVO | T5: VISITA_TECNICA | U5: V8ZZZ393 | V5: TIPO IV ESPECIAL | W5: FLUVIAL | X5: PAZ MARTINEZ RICHARD HUMBERTO | Y5: 1 | Z5: 0 | AA5: =IF(V5="TIPO I",'BASE LIQUIDACION REDEBAN 2025'!$B$2,IF(V5="TIPO II",'BASE LIQUIDACION REDEBAN 2025'!$B$3,IF(V5="TIPO III",'BASE LIQUIDACION REDEBAN 2025'!$B$4,IF(V5="TIPO IV",'BASE LIQUIDACION REDEBAN 2025'!$B$5,IF(W5="AEREO",'BASE LIQUIDACION REDEBAN 2025'!$B$6,'BASE LIQUIDACION REDEBAN 2025'!$B$5))))) -> 504832.65 | AB5: =IF(V5="TIPO I",'BASE LIQUIDACION REDEBAN 2025'!$B$10,IF(V5="TIPO II",'BASE LIQUIDACION REDEBAN 2025'!$B$11,IF(V5="TIPO III",'BASE LIQUIDACION REDEBAN 2025'!$B$12,'BASE LIQUIDACION REDEBAN 2025'!$B$13))) -> 196536.53 | AC5: =Y5*AA5+Z5*AB5 -> 504832.65
A6: YOPAL | B6: =VLOOKUP(A6,'CENTRO DE COSTOS'!A:D,4,FALSE) -> KEVIN ALEXIS CORZO BUSTOS | C6: =VLOOKUP(A6,'CENTRO DE COSTOS'!A:D,2,FALSE) -> 0004-0007 | D6: 85001 | E6: TA-25-897375 | F6: 80709 | G6: APERTURA | H6: CB CRECIMIENTO - NUEVO | I6: CASANARE | J6: YOPAL | K6: BARRIO LA ESPERANZA YOPAL 6 | L6: REDEBAN | M6: FO-25-1293877 | N6: 45866 | O6: 45870 | P6: UNO A UNO | Q6: UNO A UNO | R6: EJECUTADO | S6: 28-07 SE REALIZA COMUNICACION CON LA SRA ZULEIMA SIERRA ZAPATA, SE VALIDA DIRECCIÓN OK, CANAL OK, DISPONIBILIDAD TOTAL, LLAMAR EL DÍA LA INSTALACIÓN PARA CONFIRMAR VISITA, AVISO EXTERIOR ALTURA APROX DONDE EL TECNICO LO VEA CONVENIENTE; TOMACORRIENTE CERCANO: SI; TIENE CABINA DE SEGURIDAD: SI// MODEM A 5 METROS 29-07 EN COMUNICACIÓN CON LA SEÑORA ZULEIMA SIERRA AL NUMERO 3228924900, INDICA QUE POR TEMAS PERSONALES NO PUEDE ATENDER HOY LA INSTALACIÓN, INDICA NOS ATIENDE EL DIA 31-7-2025 31-07 EN COMUNICACIÓN CON LA SEÑORA ZULEIMA SIERRA AL NÚMERO 3228924900, INDICA NOS ATIENDE EL DIA 2-8-2025 1/08/2025 SE REALIZA INSTALACIÓN DE CORRESPONSAL, SE INSTALAN EQUIPOS CON PRUEBAS EXITOSAS, SE CAPACITA Y SE EVALÚA AL CLIENTE, SE INSTALA PUBLICIDAD COMPLETA, CB QUEDA OPERATIVO. USUARIO SOMOS BANCOLOMBIA ACTIVO | T6: VISITA_TECNICA | U6: V8ZZZ402 | V6: TIPO I | W6: TERRESTRE | X6: BERNAL ELAICA EDGAR ALEXIS | Y6: 1 | Z6: 0 | AA6: =IF(V6="TIPO I",'BASE LIQUIDACION REDEBAN 2025'!$B$2,IF(V6="TIPO II",'BASE LIQUIDACION REDEBAN 2025'!$B$3,IF(V6="TIPO III",'BASE LIQUIDACION REDEBAN 2025'!$B$4,IF(V6="TIPO IV",'BASE LIQUIDACION REDEBAN 2025'!$B$5,IF(W6="AEREO",'BASE LIQUIDACION REDEBAN 2025'!$B$6,'BASE LIQUIDACION REDEBAN 2025'!$B$5))))) -> 75096.394 | AB6: =IF(V6="TIPO I",'BASE LIQUIDACION REDEBAN 2025'!$B$10,IF(V6="TIPO II",'BASE LIQUIDACION REDEBAN 2025'!$B$11,IF(V6="TIPO III",'BASE LIQUIDACION REDEBAN 2025'!$B$12,'BASE LIQUIDACION REDEBAN 2025'!$B$13))) -> 75096.394 | AC6: =Y6*AA6+Z6*AB6 -> 75096.394
A7: MEDELLIN | B7: =VLOOKUP(A7,'CENTRO DE COSTOS'!A:D,4,FALSE) -> JUAN SEBASTIÁN RÍOS CASTRILLÓN | C7: =VLOOKUP(A7,'CENTRO DE COSTOS'!A:D,2,FALSE) -> 0004-0005 | D7: 5001 | E7: TA-25-904686 | F7: 80717 | G7: APERTURA | H7: CB CRECIMIENTO ALIANZA - NUEVO | I7: ANTIOQUIA | J7: MEDELLIN | K7: DISTRICOL VARIEDADES Y DETALLE | L7: REDEBAN | M7: FO-25-1306012 | N7: 45868 | O7: 45870 | P7: AGREGADOR | Q7: DISTRICOL | R7: EJECUTADO | S7: 30/07/2025 PROGRAMACIÓN REALIZADA POR LA ALIANZA 1/08/2025 SE REALIZA INSTALACIÓN DE CORRESPONSAL, SE INSTALAN EQUIPOS CON PRUEBAS EXITOSAS, SE CAPACITA Y SE EVALÚA AL CLIENTE, SE INSTALA PUBLICIDAD COMPLETA, CB QUEDA OPERATIVO. USUARIO SOMOS BANCOLOMBIA ACTIVO | T7: VISITA_TECNICA | U7: VAZZZ340 | V7: TIPO I | W7: TERRESTRE | X7: BARRIENTOS HERNANDEZ CRISTIAN HORACIO | Y7: 1 | Z7: 0 | AA7: =IF(V7="TIPO I",'BASE LIQUIDACION REDEBAN 2025'!$B$2,IF(V7="TIPO II",'BASE LIQUIDACION REDEBAN 2025'!$B$3,IF(V7="TIPO III",'BASE LIQUIDACION REDEBAN 2025'!$B$4,IF(V7="TIPO IV",'BASE LIQUIDACION REDEBAN 2025'!$B$5,IF(W7="AEREO",'BASE LIQUIDACION REDEBAN 2025'!$B$6,'BASE LIQUIDACION REDEBAN 2025'!$B$5))))) -> 75096.394 | AB7: =IF(V7="TIPO I",'BASE LIQUIDACION REDEBAN 2025'!$B$10,IF(V7="TIPO II",'BASE LIQUIDACION REDEBAN 2025'!$B$11,IF(V7="TIPO III",'BASE LIQUIDACION REDEBAN 2025'!$B$12,'BASE LIQUIDACION REDEBAN 2025'!$B$13))) -> 75096.394 | AC7: =Y7*AA7+Z7*AB7 -> 75096.394
A8: MEDELLIN | B8: =VLOOKUP(A8,'CENTRO DE COSTOS'!A:D,4,FALSE) -> JUAN SEBASTIÁN RÍOS CASTRILLÓN | C8: =VLOOKUP(A8,'CENTRO DE COSTOS'!A:D,2,FALSE) -> 0004-0005 | D8: 5001 | E8: TA-25-904688 | F8: 80718 | G8: APERTURA | H8: CB CRECIMIENTO ALIANZA - NUEVO | I8: ANTIOQUIA | J8: MEDELLIN | K8: DISTRICOL PAPELERIA LA PIZARRA | L8: REDEBAN | M8: FO-25-1306018 | N8: 45868 | O8: 45870 | P8: AGREGADOR | Q8: DISTRICOL | R8: EJECUTADO | S8: 30/07/2025 PROGRAMACIÓN REALIZADA POR LA ALIANZA 1/08/2025 SE REALIZA INSTALACIÓN DE CORRESPONSAL, SE INSTALAN EQUIPOS CON PRUEBAS EXITOSAS, SE CAPACITA Y SE EVALÚA AL CLIENTE, SE INSTALA PUBLICIDAD COMPLETA, CB QUEDA OPERATIVO. USUARIO SOMOS BANCOLOMBIA ACTIVO | T8: VISITA_TECNICA | U8: VAZZZ341 | V8: TIPO I | W8: TERRESTRE | X8: PAREJA ECHAVARRIA JHON DAVID | Y8: 1 | Z8: 0 | AA8: =IF(V8="TIPO I",'BASE LIQUIDACION REDEBAN 2025'!$B$2,IF(V8="TIPO II",'BASE LIQUIDACION REDEBAN 2025'!$B$3,IF(V8="TIPO III",'BASE LIQUIDACION REDEBAN 2025'!$B$4,IF(V8="TIPO IV",'BASE LIQUIDACION REDEBAN 2025'!$B$5,IF(W8="AEREO",'BASE LIQUIDACION REDEBAN 2025'!$B$6,'BASE LIQUIDACION REDEBAN 2025'!$B$5))))) -> 75096.394 | AB8: =IF(V8="TIPO I",'BASE LIQUIDACION REDEBAN 2025'!$B$10,IF(V8="TIPO II",'BASE LIQUIDACION REDEBAN 2025'!$B$11,IF(V8="TIPO III",'BASE LIQUIDACION REDEBAN 2025'!$B$12,'BASE LIQUIDACION REDEBAN 2025'!$B$13))) -> 75096.394 | AC8: =Y8*AA8+Z8*AB8 -> 75096.394
A9: MEDELLIN | B9: =VLOOKUP(A9,'CENTRO DE COSTOS'!A:D,4,FALSE) -> JUAN SEBASTIÁN RÍOS CASTRILLÓN | C9: =VLOOKUP(A9,'CENTRO DE COSTOS'!A:D,2,FALSE) -> 0004-0005 | D9: 5088 | E9: TA-25-904689 | F9: 80715 | G9: APERTURA | H9: CB CRECIMIENTO ALIANZA - NUEVO | I9: ANTIOQUIA | J9: BELLO | K9: DISTRICOL ABARROTES EL PUERTO | L9: REDEBAN | M9: FO-25-1306022 | N9: 45868 | O9: 45870 | P9: AGREGADOR | Q9: DISTRICOL | R9: EJECUTADO | S9: 30/07/2025 PROGRAMACIÓN REALIZADA POR LA ALIANZA 1/08/2025 SE REALIZA INSTALACIÓN DE CORRESPONSAL, SE INSTALAN EQUIPOS CON PRUEBAS EXITOSAS, SE CAPACITA Y SE EVALÚA AL CLIENTE, SE INSTALA PUBLICIDAD COMPLETA, CB QUEDA OPERATIVO. USUARIO SOMOS BANCOLOMBIA ACTIVO | T9: VISITA_TECNICA | U9: VAZZZ342 | V9: TIPO I | W9: TERRESTRE | X9: BARRIENTOS HERNANDEZ CRISTIAN HORACIO | Y9: 1 | Z9: 0 | AA9: =IF(V9="TIPO I",'BASE LIQUIDACION REDEBAN 2025'!$B$2,IF(V9="TIPO II",'BASE LIQUIDACION REDEBAN 2025'!$B$3,IF(V9="TIPO III",'BASE LIQUIDACION REDEBAN 2025'!$B$4,IF(V9="TIPO IV",'BASE LIQUIDACION REDEBAN 2025'!$B$5,IF(W9="AEREO",'BASE LIQUIDACION REDEBAN 2025'!$B$6,'BASE LIQUIDACION REDEBAN 2025'!$B$5))))) -> 75096.394 | AB9: =IF(V9="TIPO I",'BASE LIQUIDACION REDEBAN 2025'!$B$10,IF(V9="TIPO II",'BASE LIQUIDACION REDEBAN 2025'!$B$11,IF(V9="TIPO III",'BASE LIQUIDACION REDEBAN 2025'!$B$12,'BASE LIQUIDACION REDEBAN 2025'!$B$13))) -> 75096.394 | AC9: =Y9*AA9+Z9*AB9 -> 75096.394
A10: NEIVA | B10: =VLOOKUP(A10,'CENTRO DE COSTOS'!A:D,4,FALSE) -> KEVIN ALEXIS CORZO BUSTOS | C10: =VLOOKUP(A10,'CENTRO DE COSTOS'!A:D,2,FALSE) -> 0004-0007 | D10: 18753 | E10: TA-25-904057 | F10: 31694 | G10: APERTURA | H10: DATAFONO ADICIONAL - ALIANZA | I10: CAQUETA | J10: SAN VICENTE DEL CAGUAN | K10: Multipagas - San Vicente del Caguan | L10: REDEBAN | M10: FO-25-1304946 | N10: 45868 | O10: 45875 | P10: ROBUSTO | Q10: MULTIPAGAS | R10: EJECUTADO | S10: 30-07-2025 SE REALIZA LLAMADA AL CLIENTE, SE HABLA CON LA SRA Tatiana Penagos SE VALIDA DIRECCIÓN OK, CANAL OK, DISPONIBILIDAD TOTAL, LLAMAR EL DÍA LA INSTALACIÓN PARA CONFIRMAR VISITA 6/08/2025 SE REALIZA INSTALACIÓN DE DAT ADICIONAL, PRUEBAS EXITOSAS, CB QUEDA OPERATIVO | T10: VISITA_TECNICA | U10: VAZZZ348 VAZZZ349 | V10: TIPO IV ESPECIAL | W10: TERRESTRE / AEREO | X10: BERMUDEZ SANCHEZ JOSE NEYBER | Y10: 1 | Z10: 0 | AA10: =IF(V10="TIPO I",'BASE LIQUIDACION REDEBAN 2025'!$B$2,IF(V10="TIPO II",'BASE LIQUIDACION REDEBAN 2025'!$B$3,IF(V10="TIPO III",'BASE LIQUIDACION REDEBAN 2025'!$B$4,IF(V10="TIPO IV",'BASE LIQUIDACION REDEBAN 2025'!$B$5,IF(W10="AEREO",'BASE LIQUIDACION REDEBAN 2025'!$B$6,'BASE LIQUIDACION REDEBAN 2025'!$B$5))))) -> 504832.65 | AB10: =IF(V10="TIPO I",'BASE LIQUIDACION REDEBAN 2025'!$B$10,IF(V10="TIPO II",'BASE LIQUIDACION REDEBAN 2025'!$B$11,IF(V10="TIPO III",'BASE LIQUIDACION REDEBAN 2025'!$B$12,'BASE LIQUIDACION REDEBAN 2025'!$B$13))) -> 196536.53 | AC10: =Y10*AA10+Z10*AB10 -> 504832.65
A11: CALI | B11: =VLOOKUP(A11,'CENTRO DE COSTOS'!A:D,4,FALSE) -> DIEGO FERNANDO HENAO CARDONA | C11: =VLOOKUP(A11,'CENTRO DE COSTOS'!A:D,2,FALSE) -> 0004-0003 | D11: 76892 | E11: TA-25-904699 | F11: 66067 | G11: APERTURA | H11: DATAFONO ADICIONAL - ALIANZA | I11: VALLE DEL CAUCA | J11: YUMBO | K11: DISTRICOL DIST MISC THOVAJU | L11: REDEBAN | M11: FO-25-1306040 | N11: 45868 | O11: 45870 | P11: AGREGADOR | Q11: DISTRICOL | R11: EJECUTADO | S11: 30/07/2025 PROGRAMACIÓN REALIZADA POR LA ALIANZA 1/08/2025 SE REALIZA INSTALACIÓN DE DAT ADICIONAL, PRUEBAS EXITOSAS, CB QUEDA OPERATIVO | T11: VISITA_TECNICA | U11: VAZZZ351 | V11: TIPO I | W11: TERRESTRE | X11: MONTERO MUESES GIAN CARLO | Y11: 1 | Z11: 0 | AA11: =IF(V11="TIPO I",'BASE LIQUIDACION REDEBAN 2025'!$B$2,IF(V11="TIPO II",'BASE LIQUIDACION REDEBAN 2025'!$B$3,IF(V11="TIPO III",'BASE LIQUIDACION REDEBAN 2025'!$B$4,IF(V11="TIPO IV",'BASE LIQUIDACION REDEBAN 2025'!$B$5,IF(W11="AEREO",'BASE LIQUIDACION REDEBAN 2025'!$B$6,'BASE LIQUIDACION REDEBAN 2025'!$B$5))))) -> 75096.394 | AB11: =IF(V11="TIPO I",'BASE LIQUIDACION REDEBAN 2025'!$B$10,IF(V11="TIPO II",'BASE LIQUIDACION REDEBAN 2025'!$B$11,IF(V11="TIPO III",'BASE LIQUIDACION REDEBAN 2025'!$B$12,'BASE LIQUIDACION REDEBAN 2025'!$B$13))) -> 75096.394 | AC11: =Y11*AA11+Z11*AB11 -> 75096.394
A12: YOPAL | B12: =VLOOKUP(A12,'CENTRO DE COSTOS'!A:D,4,FALSE) -> KEVIN ALEXIS CORZO BUSTOS | C12: =VLOOKUP(A12,'CENTRO DE COSTOS'!A:D,2,FALSE) -> 0004-0007 | D12: 85162 | E12: TA-25-904063 | F12: 80742 | G12: APERTURA | H12: CB CRECIMIENTO - NUEVO | I12: CASANARE | J12: MONTERREY | K12: BARRIO ALCARAVANES MONTERREY 1 | L12: REDEBAN | M12: FO-25-1304972 | N12: 45868 | O12: 45874 | P12: UNO A UNO | Q12: UNO A UNO | R12: EJECUTADO | S12: 30-07-2025 SE REALIZA LLAMADA AL CLIENTE, SE HABLA CON EL SR EDWIN YESID SOSA BUITRAGO SE VALIDA DIRECCIÓN OK, CANAL OK, DISPONIBILIDAD TOTAL, LLAMAR EL DÍA LA INSTALACIÓN PARA CONFIRMAR VISITA, AVISO EXTERIOR ALTURA APROX SE VALIDA EL DIA DE LA APERTURA HAY ESPACIO SUFICIENTE; TOMACORRIENTE CERCANO: SI; TIENE CABINA DE SEGURIDAD: SI // CONTACTO REALIZADO POR LA APP 01-08 EN COMUNICACIÓN CON EL SEÑOR EDWIN SOSA AL NUMERO 3114659005, SE INFORMA QUE NO SE PUEDE REALIZAR LA APERTURA, MOTIVO CIERRE DE LA MARGINAL, CICLISMO VUELTA COLOMBIA. INDICA NOS ATIENDE EL 5-8-2025 5/08/2025 SE REALIZA INSTALACIÓN DE CORRESPONSAL, SE INSTALAN EQUIPOS CON PRUEBAS EXITOSAS, SE CAPACITA Y SE EVALÚA AL CLIENTE, SE INSTALA PUBLICIDAD COMPLETA, CB QUEDA OPERATIVO. USUARIO SOMOS BANCOLOMBIA ACTIVO | T12: VISITA_TECNICA | U12: VAZZZ361 | V12: TIPO II | W12: TERRESTRE | X12: BERNAL ELAICA EDGAR ALEXIS | Y12: 1 | Z12: 0 | AA12: =IF(V12="TIPO I",'BASE LIQUIDACION REDEBAN 2025'!$B$2,IF(V12="TIPO II",'BASE LIQUIDACION REDEBAN 2025'!$B$3,IF(V12="TIPO III",'BASE LIQUIDACION REDEBAN 2025'!$B$4,IF(V12="TIPO IV",'BASE LIQUIDACION REDEBAN 2025'!$B$5,IF(W12="AEREO",'BASE LIQUIDACION REDEBAN 2025'!$B$6,'BASE LIQUIDACION REDEBAN 2025'!$B$5))))) -> 163813.7 | AB12: =IF(V12="TIPO I",'BASE LIQUIDACION REDEBAN 2025'!$B$10,IF(V12="TIPO II",'BASE LIQUIDACION REDEBAN 2025'!$B$11,IF(V12="TIPO III",'BASE LIQUIDACION REDEBAN 2025'!$B$12,'BASE LIQUIDACION REDEBAN 2025'!$B$13))) -> 140395.63 | AC12: =Y12*AA12+Z12*AB12 -> 163813.7
A13: TUNJA | B13: =VLOOKUP(A13,'CENTRO DE COSTOS'!A:D,4,FALSE) -> MIGUEL JULIÁN HERNÁNDEZ GUARÍN | C13: =VLOOKUP(A13,'CENTRO DE COSTOS'!A:D,2,FALSE) -> 0004-0008 | D13: 15464 | E13: TA-25-904065 | F13: 80720 | G13: APERTURA | H13: CB CRECIMIENTO - NUEVO | I13: BOYACA | J13: MONGUA | K13: BARRIO CENTRO MONGUA 1 | L13: REDEBAN | M13: FO-25-1304982 | N13: 45868 | O13: 45870 | P13: UNO A UNO | Q13: UNO A UNO | R13: EJECUTADO | S13: 30-07-2025 SE REALIZA LLAMADA AL CLIENTE, SE HABLA CON LA SRA YESICA PAOLA MERCHAN CASTAÑEDA SE VALIDA DIRECCIÓN OK, CANAL OK, DISPONIBILIDAD TOTAL, LLAMAR EL DÍA LA INSTALACIÓN PARA CONFIRMAR VISITA, AVISO EXTERIOR ALTURA APROX 2,50 METROS; TOMACORRIENTE CERCANO: SI; TIENE CABINA DE SEGURIDAD: SI // CONTACTO REALIZADO POR LA APP 01-08 SE REALIZA INSTALACIÓN DE CORRESPONSAL, SE INSTALAN EQUIPOS CON PRUEBAS EXITOSAS, SE CAPACITA Y SE EVALÚA AL CLIENTE, SE INSTALA PUBLICIDAD COMPLETA, CB QUEDA OPERATIVO. USUARIO SOMOS BANCOLOMBIA ACTIVO | T13: VISITA_TECNICA | U13: VAZZZ363 | V13: TIPO II | W13: TERRESTRE | X13: SOLER HOYOS CRISTIAN LEONARDO | Y13: 1 | Z13: 0 | AA13: =IF(V13="TIPO I",'BASE LIQUIDACION REDEBAN 2025'!$B$2,IF(V13="TIPO II",'BASE LIQUIDACION REDEBAN 2025'!$B$3,IF(V13="TIPO III",'BASE LIQUIDACION REDEBAN 2025'!$B$4,IF(V13="TIPO IV",'BASE LIQUIDACION REDEBAN 2025'!$B$5,IF(W13="AEREO",'BASE LIQUIDACION REDEBAN 2025'!$B$6,'BASE LIQUIDACION REDEBAN 2025'!$B$5))))) -> 163813.7 | AB13: =IF(V13="TIPO I",'BASE LIQUIDACION REDEBAN 2025'!$B$10,IF(V13="TIPO II",'BASE LIQUIDACION REDEBAN 2025'!$B$11,IF(V13="TIPO III",'BASE LIQUIDACION REDEBAN 2025'!$B$12,'BASE LIQUIDACION REDEBAN 2025'!$B$13))) -> 140395.63 | AC13: =Y13*AA13+Z13*AB13 -> 163813.7
... A509: PEREIRA | B509: =VLOOKUP(A509,'CENTRO DE COSTOS'!A:D,4,FALSE) -> DIEGO FERNANDO HENAO CARDONA | C509: =VLOOKUP(A509,'CENTRO DE COSTOS'!A:D,2,FALSE) -> 0004-0002 | D509: 76147 | E509: TA-25-1034508 | F509: 67249 | G509: APERTURA | H509: DATAFONO ADICIONAL - ALIANZA | I509: VALLE DEL CAUCA | J509: CARTAGO | K509: DISTRICOL MISCELANEA Y PANADER | L509: REDEBAN | M509: FO-25-1433980 | N509: 45896 | O509: 45898 | P509: AGREGADOR | Q509: DISTRICOL | R509: EJECUTADO | S509: 27-08 PROGRAMACIÓN REALIZADA POR LA ALIANZA 29/08/2025 SE REALIZA INSTALACIÓN DE DAT ADICIONAL, PRUEBAS EXITOSAS, CB QUEDA OPERATIVO | T509: VISITA_TECNICA | U509: FKZZZ702 | V509: TIPO I | W509: TERRESTRE | X509: LOAIZA LOPEZ JHON FREDDY | Y509: 1 | Z509: 0 | AA509: =IF(V509="TIPO I",'BASE LIQUIDACION REDEBAN 2025'!$B$2,IF(V509="TIPO II",'BASE LIQUIDACION REDEBAN 2025'!$B$3,IF(V509="TIPO III",'BASE LIQUIDACION REDEBAN 2025'!$B$4,IF(V509="TIPO IV",'BASE LIQUIDACION REDEBAN 2025'!$B$5,IF(W509="AEREO",'BASE LIQUIDACION REDEBAN 2025'!$B$6,'BASE LIQUIDACION REDEBAN 2025'!$B$5))))) -> 75096.394 | AB509: =IF(V509="TIPO I",'BASE LIQUIDACION REDEBAN 2025'!$B$10,IF(V509="TIPO II",'BASE LIQUIDACION REDEBAN 2025'!$B$11,IF(V509="TIPO III",'BASE LIQUIDACION REDEBAN 2025'!$B$12,'BASE LIQUIDACION REDEBAN 2025'!$B$13))) -> 75096.394 | AC509: =Y509*AA509+Z509*AB509 -> 75096.394
AC510: =SUM(AC2:AC509) -> 94349557

Sheet INCIDENTES BANCOLOMBIA
A1: CIUDAD SEDE | B1: COORDINADOR | C1: CENTRO DE COSTOS LÍNEACOM | D1: CÓDIGO DANE | E1: TA/CODIGO ACTIVIDAD | F1: CODIGO CB | G1: ACTIVIDAD | H1: DEPARTAMENTO | I1: CIUDAD | J1: NOMBRE DEL CB | K1: RED | L1: FO | M1: FECHA ASIGNACIÓN A LÍNEA COMUNICACIONES (DD/MM/AAAA HH:MM) | N1: FECHA CIERRE DEL TICKET (DD/MM/AAAA HH:MM) | O1: ACOMETIDA | P1: GRUPO_FALLA | Q1: CATEGORÍA | R1: FALLA | S1: FORMATO | T1: CADENA | U1: ESTADO | V1: OBSERVACION | W1: FORMA DE ATENCIÓN | X1: TERMINAL | Y1: TIPIFICACION | Z1: TIPO DE TRAYECTO | AA1: NOMBRE DEL TECNICO | AB1: DIAS DE VISITA | AC1: DIA ADICIONAL | AD1: VALOR DIAS ACTIVIDAD FACTURABLES A LA RED | AE1: VALOR DIAS ACOMPAÑAMIENTO FACTURABLES A RED | AF1: VALOR FACTURABLE A LA RED | AG1: CU CB | AH1: COBRO ENTIDAD | AI1: ESTADO | AJ1: TIPO | AK1: VAL TIPO | AL1: VAL COSTO | AM1: OBSERVACIONES | AN1: Observaciones LINEA
A2: BUCARAMANGA | B2: =VLOOKUP(A2,'CENTRO DE COSTOS'!A:D,4,FALSE) -> MIGUEL JULIÁN HERNÁNDEZ GUARÍN | C2: =VLOOKUP(A2,'CENTRO DE COSTOS'!A:D,2,FALSE) -> 0004-0008 | D2: 68679 | E2: 2535859 | F2: 48929 | G2: INCIDENTE | H2: SANTANDER | I2: SAN GIL | J2: DISTRICOL COMUNICACIONES JIRET | K2: REDEBAN | L2: FO-25-1313905 | M2: 45869.72 | N2: 45870.369 | O2: NO | P2: HARDWARE | Q2: ACTUALIZACION | R2: VERSION CAMBIO POS | S2: AGREGADOR | U2: CERRADO | V2: 01/08/2025 SE REALIZA VISITA AL COMERCIO SE ACTUALIZA DATAFONO A LA VERSIÓN 9.90 SE REALIZAN PRUEBAS OK | W2: VISITA_TÉCNICA | X2: AD00M861 | Y2: TIPO II | Z2: TERRESTRE | AA2: MARIÑO PABON JORGE ENRIQUE | AB2: 1 | AC2: 0 | AD2: =IF(W2="SOPORTE_TELEFÓNICO",'BASE LIQUIDACION REDEBAN 2025'!$B$19,IF(W2="ENVÍO",'BASE LIQUIDACION REDEBAN 2025'!$C$2,IF(Y2="TIPO I",'BASE LIQUIDACION REDEBAN 2025'!$C$2,IF(Y2="TIPO II",'BASE LIQUIDACION REDEBAN 2025'!$C$3,IF(Y2="TIPO III",'BASE LIQUIDACION REDEBAN 2025'!$C$4,IF(Y2="TIPO IV",'BASE LIQUIDACION REDEBAN 2025'!$C$5,IF(Z2="AEREO",'BASE LIQUIDACION REDEBAN 2025'!$B$6,'BASE LIQUIDACION REDEBAN 2025'!$C$5))))))) -> 144967.87 | AE2: =IF(OR(W2="SOPORTE_TELEFÓNICO",W2="ENVÍO"),0,IF(Y2="TIPO I",'BASE LIQUIDACION REDEBAN 2025'!$B$10,IF(Y2="TIPO II",'BASE LIQUIDACION REDEBAN 2025'!$B$11,IF(Y2="TIPO III",'BASE LIQUIDACION REDEBAN 2025'!$B$12,'BASE LIQUIDACION REDEBAN 2025'!$B$13)))) -> 140395.63 | AF2: =IF(OR(W2="SOPORTE_TELEFÓNICO",W2="ENVÍO"),AD2,(AD2*AB2+AE2*AC2)) -> 144967.87
A3: CUCUTA | B3: =VLOOKUP(A3,'CENTRO DE COSTOS'!A:D,4,FALSE) -> MIGUEL JULIÁN HERNÁNDEZ GUARÍN | C3: =VLOOKUP(A3,'CENTRO DE COSTOS'!A:D,2,FALSE) -> 0004-0008 | D3: 54405 | E3: 2535436 | F3: 53530 | G3: INCIDENTE | H3: NORTE DE SANTANDER | I3: LOS PATIOS | J3: BARRIO SANTA ROSA DE LIMA LOS | K3: REDEBAN | L3: FO-25-1313417 | M3: 45869.669 | N3: 45870.374 | O3: NO | P3: HARDWARE | Q3: LECTOR DE BARRAS | R3: DAÑO POS | S3: CB UNO A UNO | U3: CERRADO | V3: 31/07/2025 31-07 SE ESCALA PARA VISITA. LLAMAR ANTES DE VISITAR, CONFIRMAR FALLA Y DATOS | 01/08/2025 SE REALIZÓ VISITA AL COMERCIO Y SE ENCUENTRA LECTORA DAÑADA, SE REALIZA CAMBIO DE EQUIPO PRUEBAS EXITOSAS | W3: VISITA_TÉCNICA | X3: TR0VZ607 | Y3: TIPO I | Z3: TERRESTRE | AA3: MORA VEGA JEAMPIER | AB3: 1 | AC3: 0 | AD3: =IF(W3="SOPORTE_TELEFÓNICO",'BASE LIQUIDACION REDEBAN 2025'!$B$19,IF(W3="ENVÍO",'BASE LIQUIDACION REDEBAN 2025'!$C$2,IF(Y3="TIPO I",'BASE LIQUIDACION REDEBAN 2025'!$C$2,IF(Y3="TIPO II",'BASE LIQUIDACION REDEBAN 2025'!$C$3,IF(Y3="TIPO III",'BASE LIQUIDACION REDEBAN 2025'!$C$4,IF(Y3="TIPO IV",'BASE LIQUIDACION REDEBAN 2025'!$C$5,IF(Z3="AEREO",'BASE LIQUIDACION REDEBAN 2025'!$B$6,'BASE LIQUIDACION REDEBAN 2025'!$C$5))))))) -> 65960.072 | AE3: =IF(OR(W3="SOPORTE_TELEFÓNICO",W3="ENVÍO"),0,IF(Y3="TIPO I",'BASE LIQUIDACION REDEBAN 2025'!$B$10,IF(Y3="TIPO II",'BASE LIQUIDACION REDEBAN 2025'!$B$11,IF(Y3="TIPO III",'BASE LIQUIDACION REDEBAN 2025'!$B$12,'BASE LIQUIDACION REDEBAN 2025'!$B$13)))) -> 75096.394 | AF3: =IF(OR(W3="SOPORTE_TELEFÓNICO",W3="ENVÍO"),AD3,(AD3*AB3+AE3*AC3)) -> 65960.072
A4: MEDELLIN | B4: =VLOOKUP(A4,'CENTRO DE COSTOS'!A:D,4,FALSE) -> JUAN SEBASTIÁN RÍOS CASTRILLÓN | C4: =VLOOKUP(A4,'CENTRO DE COSTOS'!A:D,2,FALSE) -> 0004-0005 | D4: 5890 | E4: 2531780 | F4: 76392 | G4: INCIDENTE | H4: ANTIOQUIA | I4: YOLOMBO | J4: PTM YOLOMBO DROGUERIA EL RUBI | K4: REDEBAN | L4: FO-25-1310322 | M4: 45869.403 | N4: 45870.382 | O4: NO | P4: HARDWARE | Q4: COMUNICACION | R4: DAÑO POS | S4: AGREGADOR | U4: CERRADO | V4: 31/07/2025 31-07 SE ESCALA PARA VISITA. LLAMAR ANTES DE VISITAR, CONFIRMAR FALLA Y DATOS | 31/07/2025 SE CAMBIA EQUIPO POR PUERTO DE RED MALO | W4: VISITA_TÉCNICA | X4: A10RZ489 - A10SZ735 | Y4: TIPO II | Z4: TERRESTRE | AA4: BADEL ACUÑA LUIS ALBERTO | AB4: 1 | AC4: 0 | AD4: =IF(W4="SOPORTE_TELEFÓNICO",'BASE LIQUIDACION REDEBAN 2025'!$B$19,IF(W4="ENVÍO",'BASE LIQUIDACION REDEBAN 2025'!$C$2,IF(Y4="TIPO I",'BASE LIQUIDACION REDEBAN 2025'!$C$2,IF(Y4="TIPO II",'BASE LIQUIDACION REDEBAN 2025'!$C$3,IF(Y4="TIPO III",'BASE LIQUIDACION REDEBAN 2025'!$C$4,IF(Y4="TIPO IV",'BASE LIQUIDACION REDEBAN 2025'!$C$5,IF(Z4="AEREO",'BASE LIQUIDACION REDEBAN 2025'!$B$6,'BASE LIQUIDACION REDEBAN 2025'!$C$5))))))) -> 144967.87 | AE4: =IF(OR(W4="SOPORTE_TELEFÓNICO",W4="ENVÍO"),0,IF(Y4="TIPO I",'BASE LIQUIDACION REDEBAN 2025'!$B$10,IF(Y4="TIPO II",'BASE LIQUIDACION REDEBAN 2025'!$B$11,IF(Y4="TIPO III",'BASE LIQUIDACION REDEBAN 2025'!$B$12,'BASE LIQUIDACION REDEBAN 2025'!$B$13)))) -> 140395.63 | AF4: =IF(OR(W4="SOPORTE_TELEFÓNICO",W4="ENVÍO"),AD4,(AD4*AB4+AE4*AC4)) -> 144967.87
A5: MEDELLIN | B5: =VLOOKUP(A5,'CENTRO DE COSTOS'!A:D,4,FALSE) -> JUAN SEBASTIÁN RÍOS CASTRILLÓN | C5: =VLOOKUP(A5,'CENTRO DE COSTOS'!A:D,2,FALSE) -> 0004-0005 | D5: 5088 | E5: 2534410 | F5: 30086 | G5: INCIDENTE | H5: ANTIOQUIA | I5: BELLO | J5: COMCARD BELLO MERCADOS LA CRUZ | K5: REDEBAN | L5: FO-25-1312972 | M5: 45869.602 | N5: 45870.401 | O5: NO | P5: HARDWARE | Q5: COMUNICACION | R5: MENSAJE CABLE DE RED DESCONECTADO | S5: AGREGADOR | U5: CERRADO | V5: 01/08/2025 SE REVISA EL CABLE DE RED Y SE ENCUENTRA EL MAL ESTADO SE REPONCHA EL CABLE DE RED REALIZAN PRUEBAS EXITOSAS SERVICIO OPERATIVO OK | W5: VISITA_TÉCNICA | X5: BBTZZ891 | Y5: TIPO I | Z5: TERRESTRE | AA5: ZAPATA LOPEZ EDWARD ASDRUBAL | AB5: 1 | AC5: 0 | AD5: =IF(W5="SOPORTE_TELEFÓNICO",'BASE LIQUIDACION REDEBAN 2025'!$B$19,IF(W5="ENVÍO",'BASE LIQUIDACION REDEBAN 2025'!$C$2,IF(Y5="TIPO I",'BASE LIQUIDACION REDEBAN 2025'!$C$2,IF(Y5="TIPO II",'BASE LIQUIDACION REDEBAN 2025'!$C$3,IF(Y5="TIPO III",'BASE LIQUIDACION REDEBAN 2025'!$C$4,IF(Y5="TIPO IV",'BASE LIQUIDACION REDEBAN 2025'!$C$5,IF(Z5="AEREO",'BASE LIQUIDACION REDEBAN 2025'!$B$6,'BASE LIQUIDACION REDEBAN 2025'!$C$5))))))) -> 65960.072 | AE5: =IF(OR(W5="SOPORTE_TELEFÓNICO",W5="ENVÍO"),0,IF(Y5="TIPO I",'BASE LIQUIDACION REDEBAN 2025'!$B$10,IF(Y5="TIPO II",'BASE LIQUIDACION REDEBAN 2025'!$B$11,IF(Y5="TIPO III",'BASE LIQUIDACION REDEBAN 2025'!$B$12,'BASE LIQUIDACION REDEBAN 2025'!$B$13)))) -> 75096.394 | AF5: =IF(OR(W5="SOPORTE_TELEFÓNICO",W5="ENVÍO"),AD5,(AD5*AB5+AE5*AC5)) -> 65960.072
A6: CARTAGENA | B6: =VLOOKUP(A6,'CENTRO DE COSTOS'!A:D,4,FALSE) -> JOSE MAURICIO HERNANDEZ ROJAS | C6: =VLOOKUP(A6,'CENTRO DE COSTOS'!A:D,2,FALSE) -> 0004-0001 | D6: 13001 | E6: 2534555 | F6: 33382 | G6: INCIDENTE | H6: BOLIVAR | I6: CARTAGENA | J6: PAGAFACIL BAZURTO | K6: REDEBAN | L6: FO-25-1313041 | M6: 45869.624 | N6: 45870.431 | O6: NO | P6: SOFTWARE | Q6: FLASH FULL | R6: ACTUALIZACION VERSION | S6: ROBUSTO | U6: CERRADO | V6: 01/08/2025 EN SITIO ESPERANDO AUTORIZACIÓN DE INGRESO | 01/08/2025 SE CAMBIA EQUIPO POR PROBLEMAS DE IMPRESORA SE CAMBIA PIN PAD POR TECNOLOGÍA | W6: VISITA_TÉCNICA | X6: 18ZZZ921 | Y6: TIPO I | Z6: TERRESTRE | AA6: MARTINEZ SALGUEDO ANDRES AUGUSTO | AB6: 1 | AC6: 0 | AD6: =IF(W6="SOPORTE_TELEFÓNICO",'BASE LIQUIDACION REDEBAN 2025'!$B$19,IF(W6="ENVÍO",'BASE LIQUIDACION REDEBAN 2025'!$C$2,IF(Y6="TIPO I",'BASE LIQUIDACION REDEBAN 2025'!$C$2,IF(Y6="TIPO II",'BASE LIQUIDACION REDEBAN 2025'!$C$3,IF(Y6="TIPO III",'BASE LIQUIDACION REDEBAN 2025'!$C$4,IF(Y6="TIPO IV",'BASE LIQUIDACION REDEBAN 2025'!$C$5,IF(Z6="AEREO",'BASE LIQUIDACION REDEBAN 2025'!$B$6,'BASE LIQUIDACION REDEBAN 2025'!$C$5))))))) -> 65960.072 | AE6: =IF(OR(W6="SOPORTE_TELEFÓNICO",W6="ENVÍO"),0,IF(Y6="TIPO I",'BASE LIQUIDACION REDEBAN 2025'!$B$10,IF(Y6="TIPO II",'BASE LIQUIDACION REDEBAN 2025'!$B$11,IF(Y6="TIPO III",'BASE LIQUIDACION REDEBAN 2025'!$B$12,'BASE LIQUIDACION REDEBAN 2025'!$B$13)))) -> 75096.394 | AF6: =IF(OR(W6="SOPORTE_TELEFÓNICO",W6="ENVÍO"),AD6,(AD6*AB6+AE6*AC6)) -> 65960.072
A7: VILLAVICENCIO | B7: =VLOOKUP(A7,'CENTRO DE COSTOS'!A:D,4,FALSE) -> KEVIN ALEXIS CORZO BUSTOS | C7: =VLOOKUP(A7,'CENTRO DE COSTOS'!A:D,2,FALSE) -> 0004-0007 | D7: 50568 | E7: 2525574 | F7: 58542 | G7: INCIDENTE | H7: META | I7: PUERTO GAITAN | J7: BARRIO CENTRO PUERTO GAITAN 9 | K7: REDEBAN | L7: FO-25-1304845 | M7: 45868.416 | N7: 45870.44 | O7: NO | P7: HARDWARE | Q7: NO ENCIENDE | R7: DAÑO POS | S7: CB UNO A UNO | U7: CERRADO | V7: 30/07/2025 30-07 EN COMUNICACION CON LA SEÑORA ANGIE ALVARADO AL NUMERO 3187565278, CONFIRMA FALLA, DATOS CORRECTOS. SE ESCALA PARA VISITA | 01/08/2025 SE REALIZA CAMBIO DE EQUIPO PRUEBAS OK SIN NOVEDADES | W7: VISITA_TÉCNICA | X7: TYZZZ661 | Y7: TIPO III | Z7: TERRESTRE | AA7: CASTRILLON URREA LONDIER LEANDRO | AB7: 1 | AC7: 0 | AD7: =IF(W7="SOPORTE_TELEFÓNICO",'BASE LIQUIDACION REDEBAN 2025'!$B$19,IF(W7="ENVÍO",'BASE LIQUIDACION REDEBAN 2025'!$C$2,IF(Y7="TIPO I",'BASE LIQUIDACION REDEBAN 2025'!$C$2,IF(Y7="TIPO II",'BASE LIQUIDACION REDEBAN 2025'!$C$3,IF(Y7="TIPO III",'BASE LIQUIDACION REDEBAN 2025'!$C$4,IF(Y7="TIPO IV",'BASE LIQUIDACION REDEBAN 2025'!$C$5,IF(Z7="AEREO",'BASE LIQUIDACION REDEBAN 2025'!$B$6,'BASE LIQUIDACION REDEBAN 2025'!$C$5))))))) -> 275728.78 | AE7: =IF(OR(W7="SOPORTE_TELEFÓNICO",W7="ENVÍO"),0,IF(Y7="TIPO I",'BASE LIQUIDACION REDEBAN 2025'!$B$10,IF(Y7="TIPO II",'BASE LIQUIDACION REDEBAN 2025'!$B$11,IF(Y7="TIPO III",'BASE LIQUIDACION REDEBAN 2025'!$B$12,'BASE LIQUIDACION REDEBAN 2025'!$B$13)))) -> 196536.53 | AF7: =IF(OR(W7="SOPORTE_TELEFÓNICO",W7="ENVÍO"),AD7,(AD7*AB7+AE7*AC7)) -> 275728.78
A8: BUCARAMANGA | B8: =VLOOKUP(A8,'CENTRO DE COSTOS'!A:D,4,FALSE) -> MIGUEL JULIÁN HERNÁNDEZ GUARÍN | C8: =VLOOKUP(A8,'CENTRO DE COSTOS'!A:D,2,FALSE) -> 0004-0008 | D8: 68615 | E8: 2530689 | F8: 69616 | G8: INCIDENTE | H8: SANTANDER | I8: RIONEGRO | J8: BARRIO UNIDO RIONEGRO | K8: REDEBAN | L8: FO-25-1309852 | M8: 45869.333 | N8: 45870.449 | O8: NO | P8: HARDWARE | Q8: LECTOR DE BARRAS | R8: FORMATO INVALIDO LECTOR DAÑADO | S8: CB UNO A UNO | U8: CERRADO | V8: 31/07/2025 31-07 SE ESCALA PARA VISITA. LLAMAR ANTES DE VISITAR, CONFIRMAR FALLA Y DATOS | 01/08/2025 SE REALIZA VISITA AL COMERCIO CB, SE VALIDA Y SE ENCUENTRA LECTOR DE BARRAS EN DAÑO SE REINICIA CONSTANTEMENTE, SE PROCEDE A HACER CAMBIO SE HACEN PRUEBAS DEJANDO TODO OK | W8: VISITA_TÉCNICA | X8: EG004608 | Y8: TIPO II | Z8: TERRESTRE | AA8: GONZALEZ ESTUPIÑAN YEISON WALTER ANTONIO | AB8: 1 | AC8: 0 | AD8: =IF(W8="SOPORTE_TELEFÓNICO",'BASE LIQUIDACION REDEBAN 2025'!$B$19,IF(W8="ENVÍO",'BASE LIQUIDACION REDEBAN 2025'!$C$2,IF(Y8="TIPO I",'BASE LIQUIDACION REDEBAN 2025'!$C$2,IF(Y8="TIPO II",'BASE LIQUIDACION REDEBAN 2025'!$C$3,IF(Y8="TIPO III",'BASE LIQUIDACION REDEBAN 2025'!$C$4,IF(Y8="TIPO IV",'BASE LIQUIDACION REDEBAN 2025'!$C$5,IF(Z8="AEREO",'BASE LIQUIDACION REDEBAN 2025'!$B$6,'BASE LIQUIDACION REDEBAN 2025'!$C$5))))))) -> 144967.87 | AE8: =IF(OR(W8="SOPORTE_TELEFÓNICO",W8="ENVÍO"),0,IF(Y8="TIPO I",'BASE LIQUIDACION REDEBAN 2025'!$B$10,IF(Y8="TIPO II",'BASE LIQUIDACION REDEBAN 2025'!$B$11,IF(Y8="TIPO III",'BASE LIQUIDACION REDEBAN 2025'!$B$12,'BASE LIQUIDACION REDEBAN 2025'!$B$13)))) -> 140395.63 | AF8: =IF(OR(W8="SOPORTE_TELEFÓNICO",W8="ENVÍO"),AD8,(AD8*AB8+AE8*AC8)) -> 144967.87
A9: VALLEDUPAR | B9: =VLOOKUP(A9,'CENTRO DE COSTOS'!A:D,4,FALSE) -> JOSE MAURICIO HERNANDEZ ROJAS | C9: =VLOOKUP(A9,'CENTRO DE COSTOS'!A:D,2,FALSE) -> 0004-0001 | D9: 20001 | E9: 2534424 | F9: 65049 | G9: INCIDENTE | H9: CESAR | I9: VALLEDUPAR | J9: BARRIO BELLA VISTA VALLEDUPAR | K9: REDEBAN | L9: FO-25-1312961 | M9: 45869.603 | N9: 45870.455 | O9: NO | P9: HARDWARE | Q9: CABLEADO | R9: DAÑO POS | S9: CB UNO A UNO | U9: CERRADO | V9: 31/07/2025 31-07 SE ESCALA PARA VISITA. LLAMAR ANTES DE VISITAR, CONFIRMAR FALLA Y DATOS | 01/08/2025 BUENOS DIAS SE HACE VISITA AL CB Y SE EVIDENCIA QUE EL CABLE DEL LECTOR ESTÁ AVERIADO POR QUE SE CAMBIA Y TAMBIÉN EL CABLE DEL PINPAD TIENE EL CONECTOR FLOJO, SE PROCEDE A HACER EL CAMBIO | W9: VISITA_TÉCNICA | X9: 6Z005717 | Y9: TIPO I | Z9: TERRESTRE | AA9: BENITEZ CARVAJAL ALVARO JAVIER | AB9: 1 | AC9: 0 | AD9: =IF(W9="SOPORTE_TELEFÓNICO",'BASE LIQUIDACION REDEBAN 2025'!$B$19,IF(W9="ENVÍO",'BASE LIQUIDACION REDEBAN 2025'!$C$2,IF(Y9="TIPO I",'BASE LIQUIDACION REDEBAN 2025'!$C$2,IF(Y9="TIPO II",'BASE LIQUIDACION REDEBAN 2025'!$C$3,IF(Y9="TIPO III",'BASE LIQUIDACION REDEBAN 2025'!$C$4,IF(Y9="TIPO IV",'BASE LIQUIDACION REDEBAN 2025'!$C$5,IF(Z9="AEREO",'BASE LIQUIDACION REDEBAN 2025'!$B$6,'BASE LIQUIDACION REDEBAN 2025'!$C$5))))))) -> 65960.072 | AE9: =IF(OR(W9="SOPORTE_TELEFÓNICO",W9="ENVÍO"),0,IF(Y9="TIPO I",'BASE LIQUIDACION REDEBAN 2025'!$B$10,IF(Y9="TIPO II",'BASE LIQUIDACION REDEBAN 2025'!$B$11,IF(Y9="TIPO III",'BASE LIQUIDACION REDEBAN 2025'!$B$12,'BASE LIQUIDACION REDEBAN 2025'!$B$13)))) -> 75096.394 | AF9: =IF(OR(W9="SOPORTE_TELEFÓNICO",W9="ENVÍO"),AD9,(AD9*AB9+AE9*AC9)) -> 65960.072
A10: VALLEDUPAR | B10: =VLOOKUP(A10,'CENTRO DE COSTOS'!A:D,4,FALSE) -> JOSE MAURICIO HERNANDEZ ROJAS | C10: =VLOOKUP(A10,'CENTRO DE COSTOS'!A:D,2,FALSE) -> 0004-0001 | D10: 20383 | E10: 2528990 | F10: 11416 | G10: INCIDENTE | H10: CESAR | I10: LA GLORIA | J10: LA GLORIA CESAR | K10: REDEBAN | L10: FO-25-1307791 | M10: 45868.663 | N10: 45870.462 | O10: NO | P10: HARDWARE | Q10: LECTOR DE BARRAS | R10: DAÑO POS | S10: CB UNO A UNO | U10: CERRADO | V10: 30/07/2025 30-07 EN COMUNICACION CON EL SEÑOR GUSTAVO PINO AL NUMERO 3175576521, CONFIRMA FALLA, DATOS CORRECTOS. SE ESCALA PARA VISITA | 01/08/2025 SE REALIZA VISITA POR SOLICITUD DE CLIENTE, SE LLEGA A SITIO SE VALIDA LECTOR DE BARRAS LA CUAL NO LLE LAS FACTURAS, SE REALIZA CAMBIÓ DE LECTOR QUEDANDO SERVICIO OPERÁTIVO AL 100% | W10: VISITA_TÉCNICA | X10: A00FZ861 | Y10: TIPO IV | Z10: TERRESTRE | AA10: MAESTRE MENGUAL EDGAR ENRIQUE | AB10: 1 | AC10: 0 | AD10: =IF(W10="SOPORTE_TELEFÓNICO",'BASE LIQUIDACION REDEBAN 2025'!$B$19,IF(W10="ENVÍO",'BASE LIQUIDACION REDEBAN 2025'!$C$2,IF(Y10="TIPO I",'BASE LIQUIDACION REDEBAN 2025'!$C$2,IF(Y10="TIPO II",'BASE LIQUIDACION REDEBAN 2025'!$C$3,IF(Y10="TIPO III",'BASE LIQUIDACION REDEBAN 2025'!$C$4,IF(Y10="TIPO IV",'BASE LIQUIDACION REDEBAN 2025'!$C$5,IF(Z10="AEREO",'BASE LIQUIDACION REDEBAN 2025'!$B$6,'BASE LIQUIDACION REDEBAN 2025'!$C$5))))))) -> 479588.88 | AE10: =IF(OR(W10="SOPORTE_TELEFÓNICO",W10="ENVÍO"),0,IF(Y10="TIPO I",'BASE LIQUIDACION REDEBAN 2025'!$B$10,IF(Y10="TIPO II",'BASE LIQUIDACION REDEBAN 2025'!$B$11,IF(Y10="TIPO III",'BASE LIQUIDACION REDEBAN 2025'!$B$12,'BASE LIQUIDACION REDEBAN 2025'!$B$13)))) -> 196536.53 | AF10: =IF(OR(W10="SOPORTE_TELEFÓNICO",W10="ENVÍO"),AD10,(AD10*AB10+AE10*AC10)) -> 479588.88
A11: CUCUTA | B11: =VLOOKUP(A11,'CENTRO DE COSTOS'!A:D,4,FALSE) -> MIGUEL JULIÁN HERNÁNDEZ GUARÍN | C11: =VLOOKUP(A11,'CENTRO DE COSTOS'!A:D,2,FALSE) -> 0004-0008 | D11: 54720 | E11: 2531280 | F11: 39109 | G11: INCIDENTE | H11: NORTE DE SANTANDER | I11: SARDINATA | J11: BARRIO SAN FRANCISCO SARDINATA | K11: REDEBAN | L11: FO-25-1310134 | M11: 45869.383 | N11: 45870.465 | O11: NO | P11: HARDWARE | Q11: PANTALLA | R11: DAÑO POS | S11: CB UNO A UNO | U11: CERRADO | V11: 31/07/2025 31-07 SE ESCALA PARA VISITA. LLAMAR ANTES DE VISITAR, CONFIRMAR FALLA Y DATOS | 01/08/2025 SE CAMBIO DATAFONO POR DAÑO EN LA PANTALLA SE INSTALA NUEVA VERSIÓN CIERRES Y PRUEBAS OK | W11: VISITA_TÉCNICA | X11: AA07Z118 | Y11: TIPO II | Z11: TERRESTRE | AA11: DURAN ACOSTA FRANK YONNY | AB11: 1 | AC11: 0 | AD11: =IF(W11="SOPORTE_TELEFÓNICO",'BASE LIQUIDACION REDEBAN 2025'!$B$19,IF(W11="ENVÍO",'BASE LIQUIDACION REDEBAN 2025'!$C$2,IF(Y11="TIPO I",'BASE LIQUIDACION REDEBAN 2025'!$C$2,IF(Y11="TIPO II",'BASE LIQUIDACION REDEBAN 2025'!$C$3,IF(Y11="TIPO III",'BASE LIQUIDACION REDEBAN 2025'!$C$4,IF(Y11="TIPO IV",'BASE LIQUIDACION REDEBAN 2025'!$C$5,IF(Z11="AEREO",'BASE LIQUIDACION REDEBAN 2025'!$B$6,'BASE LIQUIDACION REDEBAN 2025'!$C$5))))))) -> 144967.87 | AE11: =IF(OR(W11="SOPORTE_TELEFÓNICO",W11="ENVÍO"),0,IF(Y11="TIPO I",'BASE LIQUIDACION REDEBAN 2025'!$B$10,IF(Y11="TIPO II",'BASE LIQUIDACION REDEBAN 2025'!$B$11,IF(Y11="TIPO III",'BASE LIQUIDACION REDEBAN 2025'!$B$12,'BASE LIQUIDACION REDEBAN 2025'!$B$13)))) -> 140395.63 | AF11: =IF(OR(W11="SOPORTE_TELEFÓNICO",W11="ENVÍO"),AD11,(AD11*AB11+AE11*AC11)) -> 144967.87
A12: VALLEDUPAR | B12: =VLOOKUP(A12,'CENTRO DE COSTOS'!A:D,4,FALSE) -> JOSE MAURICIO HERNANDEZ ROJAS | C12: =VLOOKUP(A12,'CENTRO DE COSTOS'!A:D,2,FALSE) -> 0004-0001 | D12: 20001 | E12: 2534486 | F12: 60632 | G12: INCIDENTE | H12: CESAR | I12: VALLEDUPAR | J12: DISTRICOL VARIEDADES LA NENAYD | K12: REDEBAN | L12: FO-25-1312955 | M12: 45869.618 | N12: 45870.474 | O12: NO | P12: HARDWARE | Q12: CABLEADO | R12: DAÑO POS | S12: AGREGADOR | U12: CERRADO | V12: 31/07/2025 31-07 SE ESCALA PARA VISITA. LLAMAR ANTES DE VISITAR, CONFIRMAR FALLA Y DATOS | 01/08/2025 BUENOS DÍAS SE VISITA CB Y SE ENCUENTRA CABLE DEL LECTOR AVERIADO SE HACE CAMBIO DE ACCESORIO Y SE HACEN PRUEBAS | W12: VISITA_TÉCNICA | X12: MA00C921 | Y12: TIPO I | Z12: TERRESTRE | AA12: BENITEZ CARVAJAL ALVARO JAVIER | AB12: 1 | AC12: 0 | AD12: =IF(W12="SOPORTE_TELEFÓNICO",'BASE LIQUIDACION REDEBAN 2025'!$B$19,IF(W12="ENVÍO",'BASE LIQUIDACION REDEBAN 2025'!$C$2,IF(Y12="TIPO I",'BASE LIQUIDACION REDEBAN 2025'!$C$2,IF(Y12="TIPO II",'BASE LIQUIDACION REDEBAN 2025'!$C$3,IF(Y12="TIPO III",'BASE LIQUIDACION REDEBAN 2025'!$C$4,IF(Y12="TIPO IV",'BASE LIQUIDACION REDEBAN 2025'!$C$5,IF(Z12="AEREO",'BASE LIQUIDACION REDEBAN 2025'!$B$6,'BASE LIQUIDACION REDEBAN 2025'!$C$5))))))) -> 65960.072 | AE12: =IF(OR(W12="SOPORTE_TELEFÓNICO",W12="ENVÍO"),0,IF(Y12="TIPO I",'BASE LIQUIDACION REDEBAN 2025'!$B$10,IF(Y12="TIPO II",'BASE LIQUIDACION REDEBAN 2025'!$B$11,IF(Y12="TIPO III",'BASE LIQUIDACION REDEBAN 2025'!$B$12,'BASE LIQUIDACION REDEBAN 2025'!$B$13)))) -> 75096.394 | AF12: =IF(OR(W12="SOPORTE_TELEFÓNICO",W12="ENVÍO"),AD12,(AD12*AB12+AE12*AC12)) -> 65960.072
A13: MEDELLIN | B13: =VLOOKUP(A13,'CENTRO DE COSTOS'!A:D,4,FALSE) -> JUAN SEBASTIÁN RÍOS CASTRILLÓN | C13: =VLOOKUP(A13,'CENTRO DE COSTOS'!A:D,2,FALSE) -> 0004-0005 | D13: 5264 | E13: 2535903 | F13: 62252 | G13: INCIDENTE | H13: ANTIOQUIA | I13: ENTRERRIOS | J13: BARRIO LA TERMINAL ENTRERRIOS | K13: REDEBAN | L13: FO-25-1313778 | M13: 45869.701 | N13: 45870.486 | O13: NO | P13: HARDWARE | Q13: LECTOR DE BARRAS | R13: CABLE LECTORA AVERIADO | S13: CB UNO A UNO | U13: CERRADO | V13: 31/07/2025 31-07 SE ESCALA PARA VISITA. LLAMAR ANTES DE VISITAR, CONFIRMAR FALLA Y DATOS | 01/08/2025 SE CAMBIA CABLE DE LECTOR DE BARRAS | W13: VISITA_TÉCNICA | X13: NA00K026 | Y13: TIPO II | Z13: TERRESTRE | AA13: CASTAÑEDA PALACIO CARLOS FELIPE | AB13: 1 | AC13: 0 | AD13: =IF(W13="SOPORTE_TELEFÓNICO",'BASE LIQUIDACION REDEBAN 2025'!$B$19,IF(W13="ENVÍO",'BASE LIQUIDACION REDEBAN 2025'!$C$2,IF(Y13="TIPO I",'BASE LIQUIDACION REDEBAN 2025'!$C$2,IF(Y13="TIPO II",'BASE LIQUIDACION REDEBAN 2025'!$C$3,IF(Y13="TIPO III",'BASE LIQUIDACION REDEBAN 2025'!$C$4,IF(Y13="TIPO IV",'BASE LIQUIDACION REDEBAN 2025'!$C$5,IF(Z13="AEREO",'BASE LIQUIDACION REDEBAN 2025'!$B$6,'BASE LIQUIDACION REDEBAN 2025'!$C$5))))))) -> 144967.87 | AE13: =IF(OR(W13="SOPORTE_TELEFÓNICO",W13="ENVÍO"),0,IF(Y13="TIPO I",'BASE LIQUIDACION REDEBAN 2025'!$B$10,IF(Y13="TIPO II",'BASE LIQUIDACION REDEBAN 2025'!$B$11,IF(Y13="TIPO III",'BASE LIQUIDACION REDEBAN 2025'!$B$12,'BASE LIQUIDACION REDEBAN 2025'!$B$13)))) -> 140395.63 | AF13: =IF(OR(W13="SOPORTE_TELEFÓNICO",W13="ENVÍO"),AD13,(AD13*AB13+AE13*AC13)) -> 144967.87
