Workbook

Sheet RESUMEN
A1: FACTURACIÓN ACTIVIDADES CORRESPONSAL BANCARIO WOMPI | E1: FACTURACIÓN SERVICIOS ADICIONALES
A2: 1 AL 30 DE NOVIEMBRE 2025 | E2: 1 AL 30 DE NOVIEMBRE 2025
A4: CONCEPTOS | B4: CANTIDAD | C4: TOTAL | E4: CONCEPTOS | F4: CANTIDAD | G4: VALOR UNITARIO | H4: TOTAL
A5: Aperturas | B5: =COUNTA(APERTURAS!A:A)-1 -> 133 | C5: =APERTURAS!Z135 -> 63463121
A6: Incidentes | B6: =COUNTA(INCIDENTES!A:A)-1 -> 655 | C6: =INCIDENTES!AA657 -> 44909577
A7: OC Papelería | B7: =COUNTA('OC PAPALERÍA'!A:A)-1 -> 2292 | C7: ='OC PAPALERÍA'!AA2294 -> 77876087
A8: OC Cierres | B8: =COUNTA('OC CIERRES'!A:A)-1 -> 58 | C8: ='OC CIERRES'!AA60 -> 13482704
A9: OC Publicidad | B9: =COUNTA('OC PUBLICIDAD'!A:A)-1 -> 58 | C9: ='OC PUBLICIDAD'!AA60 -> 10061454
A10: OC Traslados | B10: =COUNTA('OC TRASLADOS'!A:A)-1 -> 11 | C10: ='OC TRASLADOS'!AA13 -> 899975 | H10: =SUM(H5:H9) -> 0
A11: Servicios Adicionales | C11: =H10 -> 0
A12: SUBTOTAL | C12: =SUM(C5:C11) -> 210692918
A13: Iva | C13: =C12*0.19 -> 40031654
A14: TOTAL | C14: =SUM(C12:C13) -> 2.5072457e+08

Sheet TD
A1: ACTIVIDAD | B1: APERTURA
A3: DESCRIPCION CENTRO DE COSTOS | B3: Suma de VALOR TOTAL | C3: CENTRO DE COSTOS | D3: VALOR
A4: Wompi Centro | B4: 14539661 | C4: =A4 -> Wompi Centro | D4: =B4 -> 14539661 | H4: CENTRO DE COSTOS | I4: Suma de VALOR
A5: Wompi Costa | B5: 9031931 | C5: =A5 -> Wompi Costa | D5: =B5 -> 9031931 | H5: Wompi Centro | I5: 36483158
A6: Wompi Eje Cafetero | B6: 7686309 | C6: =A6 -> Wompi Eje Cafetero | D6: =B6 -> 7686309 | H6: Wompi Costa | I6: 26943227
A7: Wompi Noroccidente | B7: 5835873 | C7: =A7 -> Wompi Noroccidente | D7: =B7 -> 5835873 | H7: Wompi Eje Cafetero | I7: 15752402
A8: Wompi Oriente | B8: 8678589 | C8: =A8 -> Wompi Oriente | D8: =B8 -> 8678589 | H8: Wompi Noroccidente | I8: 32205102
A9: Wompi Santander | B9: 14025509 | C9: =A9 -> Wompi Santander | D9: =B9 -> 14025509 | H9: Wompi Oriente | I9: 26764391
A10: Wompi Suroccidente | B10: 15031132 | C10: =A10 -> Wompi Suroccidente | D10: =B10 -> 15031132 | H10: Wompi Santander | I10: 34579886
A11: Total general | B11: 74829004 | H11: Wompi Suroccidente | I11: 38215689
H12: Total general | I12: 210943855
A15: ACTIVIDAD | B15: INCIDENTE
A17: DESCRIPCION CENTRO DE COSTOS | B17: Suma de VALOR TOTAL
A18: Wompi Centro | B18: 7149102 | C18: =A18 -> Wompi Centro | D18: =B18 -> 7149102
A19: Wompi Costa | B19: 6553224 | C19: =A19 -> Wompi Costa | D19: =B19 -> 6553224
A20: Wompi Eje Cafetero | B20: 2103611 | C20: =A20 -> Wompi Eje Cafetero | D20: =B20 -> 2103611
A21: Wompi Noroccidente | B21: 5966201 | C21: =A21 -> Wompi Noroccidente | D21: =B21 -> 5966201
A22: Wompi Oriente | B22: 5627328 | C22: =A22 -> Wompi Oriente | D22: =B22 -> 5627328
A23: Wompi Santander | B23: 5997673 | C23: =A23 -> Wompi Santander | D23: =B23 -> 5997673
A24: Wompi Suroccidente | B24: 8193714 | C24: =A24 -> Wompi Suroccidente | D24: =B24 -> 8193714
A25: Total general | B25: 41590853
A29: ACTIVIDAD | B29: ORDEN DE CAMBIO
A30: SOLICITUD | B30: ROLLOS
A32: DESCRIPCION CENTRO DE COSTOS | B32: Suma de VALOR TOTAL
A33: Wompi Centro | B33: 12738595 | C33: =A33 -> Wompi Centro | D33: =B33 -> 12738595
A34: Wompi Costa | B34: 10005932 | C34: =A34 -> Wompi Costa | D34: =B34 -> 10005932
A35: Wompi Eje Cafetero | B35: 5184656 | C35: =A35 -> Wompi Eje Cafetero | D35: =B35 -> 5184656
A36: Wompi Noroccidente | B36: 16237033 | C36: =A36 -> Wompi Noroccidente | D36: =B36 -> 16237033
A37: Wompi Oriente | B37: 9499872 | C37: =A37 -> Wompi Oriente | D37: =B37 -> 9499872
A38: Wompi Santander | B38: 12610038 | C38: =A38 -> Wompi Santander | D38: =B38 -> 12610038
A39: Wompi Suroccidente | B39: 11965127 | C39: =A39 -> Wompi Suroccidente | D39: =B39 -> 11965127
A40: Total general | B40: 78241253
A44: ACTIVIDAD | B44: ORDEN DE CAMBIO
A45: SOLICITUD | B45: CIERRE
A47: DESCRIPCION CENTRO DE COSTOS | B47: Suma de VALOR TOTAL
A48: Wompi Centro | B48: 1362264 | C48: =A48 -> Wompi Centro | D48: =B48 -> 1362264
A49: Wompi Costa | B49: 203532 | C49: =A49 -> Wompi Costa | D49: =B49 -> 203532
A50: Wompi Noroccidente | B50: 2914958 | C50: =A50 -> Wompi Noroccidente | D50: =B50 -> 2914958
A51: Wompi Oriente | B51: 2228348 | C51: =A51 -> Wompi Oriente | D51: =B51 -> 2228348
A52: Wompi Santander | B52: 1636106 | C52: =A52 -> Wompi Santander | D52: =B52 -> 1636106
...

Sheet TARIFAS 2025
A1: TIPO ACTIVIDAD | B1: PRINCIPAL | C1: INTERMEDIA | D1: LEJANA
A2: ENVIO DATAFONO | B2: 39706 | C2: 49474 | D2: 51412
A3: ENVIO VISITA DATAFONO | B3: 59451 | C3: 182458 | D3: 462012
A4: INSTALACIÓN DATAFONO | B4: 130010 | C4: 222882 | D4: 474719
A5: INSTALACIÓN DATAFONO Y MATERIAL POP | B5: 367716 | C5: 488953 | D5: 598334
A6: LOGISTICA INVERSA DATAFONO | B6: 49274 | C6: 188826 | D6: 454487
A7: LOGISTICA INVERSA MATERIAL POP | B7: 95829 | C7: 287147 | D7: 551974
A8: SOPORTE TÉCNICO | B8: 51282 | C8: 172989 | D8: 452148
A9: ORDENES DE CAMBIO_CIERRES DESTRUCCIÓN DE POP EN SITIO | B9: 71290 | C9: 206527 | D9: 602411
A10: ORDENES DE CAMBIO_CIERRES RETORNO DE POP A BODEGA | B10: 101766 | C10: 318400 | D10: 707110
A11: ORDENES DE CAMBIO_PAPELERÍA | B11: 31419 | C11: 36351 | D11: 40250
A12: ORDENES DE CAMBIO_PUBLICIDAD | B12: 95829 | C12: 287147 | D12: 551974
A13: ORDENES DE CAMBIO_OTRAS | B13: 59451 | C13: 182458 | D13: 462012
A14: SOPORTE TELEFÓNICO | B14: 22000 | C14: 22000 | D14: 22000
A16: SERVICIOS ADICIONALES EN SITIO | B16: Estos valores aplican en las actividades que se requieran, previa autorización de Wompi.
A17: Acometida eléctrica 3N12 Cu THHN (ml) | B17: 21000 | C17: 21000 | D17: 21000
A18: Acometida de datos (ML) | B18: 16235 | C18: 16235 | D18: 16235
A19: Switch | B19: 257392 | C19: 257392 | D19: 257392
A20: Router | B20: 306552 | C20: 306552 | D20: 306552

Sheet CENTROS DE COSTOS
A1: CIUDAD | B1: CENTRO_COSTO | C1: DESCRIPCION CENTRO DE COSTOS | D1: COORDINADOR DE ZONA
A2: APARTADO | B2: 0036-0005 | C2: Wompi Noroccidente | D2: JUAN SEBASTIÁN RÍOS CASTRILLÓN
A3: BARRANQUILLA | B3: 0036-0001 | C3: Wompi Costa | D3: JOSE MAURICIO HERNANDEZ ROJAS
A4: BOGOTA | B4: 0036-0004 | C4: Wompi Centro | D4: WILLIAM ASDRUBAL ROZO ROZO
A5: BUCARAMANGA | B5: 0036-0007 | C5: Wompi Santander | D5: MIGUEL JULIÁN HERNÁNDEZ GUARÍN
A6: CALI | B6: 0036-0003 | C6: Wompi Suroccidente | D6: DIEGO FERNANDO HENAO CARDONA
A7: CARTAGENA | B7: 0036-0001 | C7: Wompi Costa | D7: JOSE MAURICIO HERNANDEZ ROJAS
A8: CUCUTA | B8: 0036-0007 | C8: Wompi Santander | D8: MIGUEL JULIÁN HERNÁNDEZ GUARÍN
A9: FLORENCIA | B9: 0036-0006 | C9: Wompi Oriente | D9: KEVIN ALEXIS CORZO BUSTOS
A10: IBAGUE | B10: 0036-0006 | C10: Wompi Oriente | D10: KEVIN ALEXIS CORZO BUSTOS
A11: MANIZALES | B11: 0036-0002 | C11: Wompi Eje Cafetero | D11: DIEGO FERNANDO HENAO CARDONA
A12: MEDELLIN | B12: 0036-0005 | C12: Wompi Noroccidente | D12: JUAN SEBASTIÁN RÍOS CASTRILLÓN
... A23: YOPAL | B23: 0036-0006 | C23: Wompi Oriente | D23: KEVIN ALEXIS CORZO BUSTOS

Sheet TIPOLOGIA
A1: COD. CIUDAD | B1: CIUDAD | C1: DEPARTAMENTO | D1: DESDE DONDE SE ATIENDE | E1: TIPOLOGIA WOMPI | F1: TIPO DE TRAYECTO | G1: BODEGA WOMPI
A2: 91430 | B2: LA VICTORIA | C2: AMAZONAS | D2: BOGOTA | E2: LEJANA | F2: AEREO | G2: BOGOTA
A3: 91669 | B3: PUERTO SANTANDER | C3: AMAZONAS | D3: BOGOTA | E3: LEJANA | F3: AEREO | G3: BOGOTA
A4: 91263 | B4: EL ENCANTO | C4: AMAZONAS | D4: BOGOTA | E4: LEJANA | F4: AEREO | G4: BOGOTA
A5: 91405 | B5: LA CHORRERA | C5: AMAZONAS | D5: BOGOTA | E5: LEJANA | F5: AEREO | G5: BOGOTA
A6: 91407 | B6: LA PEDRERA | C6: AMAZONAS | D6: BOGOTA | E6: LEJANA | F6: AEREO | G6: BOGOTA
A7: 91001 | B7: LETICIA | C7: AMAZONAS | D7: BOGOTA | E7: LEJANA | F7: AEREO | G7: BOGOTA
A8: 91460 | B8: MIRITI - PARANA | C8: AMAZONAS | D8: BOGOTA | E8: LEJANA | F8: AEREO | G8: BOGOTA
A9: 91530 | B9: PUERTO ALEGRIA | C9: AMAZONAS | D9: BOGOTA | E9: LEJANA | F9: AEREO | G9: BOGOTA
A10: 91536 | B10: PUERTO ARICA | C10: AMAZONAS | D10: BOGOTA | E10: LEJANA | F10: AEREO | G10: BOGOTA
A11: 91540 | B11: PUERTO NARIÑO | C11: AMAZONAS | D11: BOGOTA | E11: LEJANA | F11: AEREO | G11: BOGOTA
A12: 91798 | B12: TARAPACA | C12: AMAZONAS | D12: BOGOTA | E12: LEJANA | F12: AEREO | G12: BOGOTA
A13: 5055 | B13: ARGELIA | C13: ANTIOQUIA | D13: MEDELLIN | E13: LEJANA | F13: TERRESTRE | G13: MEDELLIN
... A1124: 23682 | B1124: SAN JOSE DE URE | C1124: CORDOBA | D1124: MONTERIA | E1124: LEJANA | F1124: TERRESTRE | G1124: MONTERIA

Sheet APERTURAS
A1: CIUDAD SEDE | B1: CENTRO_COSTO | C1: DESCRIPCION CENTRO DE COSTOS | D1: CÓDIGO DANE | E1: TA/CODIGO ACTIVIDAD | F1: CODIGO CB | G1: ACTIVIDAD | H1: TIPO DE APERTURA | I1: DEPARTAMENTO | J1: CIUDAD | K1: NOMBRE DEL CB | L1: RED | M1: FO | N1: FECHA LISTA | O1: FECHA ULTIMA ACTUALIZACION | P1: ESTADO | Q1: OBSERVACIONES CLIENTE | R1: FORMA DE ATENCIÓN | S1: TERMINALES | T1: TIPOLOGIA | U1: TIPO DE TRAYECTO | V1: NOMBRE DEL TECNICO | W1: DIAS DE VISITA | X1: VALOR DIAS ACTIVIDAD | Y1: % FACTURACIÓN | Z1: VALOR TOTAL
A2: MONTERIA | B2: =VLOOKUP(A2,'CENTROS DE COSTOS'!A:D,2,0) -> 0036-0001 | C2: =VLOOKUP(A2,'CENTROS DE COSTOS'!A:D,3,0) -> Wompi Costa | D2: 23001 | E2: TA-25-1046209 | F2: 81286 | G2: APERTURA | H2: CB CRECIMIENTO - NUEVO | I2: CORDOBA | J2: MONTERIA | K2: BARRIO MONTERIA MODERNO MONTERIA 2 | L2: WOMPI | M2: FO-25-1654602 | N2: 45901 | O2: 45973 | P2: EJECUTADO | Q2: 12-09 SE REALIZA LLAMADA AL CLIENTE, SE HABLA CON BLAS ALFONSO VILLADIEGO DOMINGUEZ EL CUAL INDICA QUE EL CORREO CON LAS CREDENCIALES POR PARTE DE WOMPI AUN NO HA LLEGADO 22-09 SE REALIZA LLAMADA AL CLIENTE, SE HABLA CON EL SR BLAS ALFONSO VILLADIEGO DOMINGUEZ EL CUAL IDNICA QUE EL CORREO ESTA ERRADO, EL CORREO CORRECTO ES ENERGIAINTEGRALDELASABANA@GMAIL.COM 08-10 SE REALIZA LLAMADA AL CLIENTE, SE HABLA CON LA SRA SERY RAMOS. SE VALIDA DIRECCIÓN OK, CANAL OK, DISPONIBILIDAD TOTAL, LLAMAR EL DÍA LA INSTALACIÓN PARA CONFIRMAR VISITA, AVISO EXTERIOR ALTURA APROX 2 METROS; CREDENCIALES: SI 9/10/2025 SE ENVIO ESTE CASO DE APERTURA WOMPI, DONDE EL NOMBRE DE COMERCIO NO ES EL MISMO DEL AVISO PUBLICITARIO, SIN EMBARGO SI ES EL MISMO OBJETIVO COMERCIAL, LA DIRECCION COINCIDE Y LA CÁMARA DE COMERCIO TAMBIEN TIENE EL MISMO NOMBRE DE LISTA DE CHEQUEO. NOMBRE ESTABLECIMIENTO CÁMARA DE COMERCIO: ELECTROREDES DEL SINU NOMBRE AVISO PUBLICITARIO: ENERGIA INTEGRAL DE LA SABANA |RESPUESTA DE WOMPI: LO IMPORTANTE ES GARANTIZAR QUE LA DIRECCIÓN COINCIDA, SI ESTA COINCIDE PODEMOS INSTALAR RECOMENDANDO AL PUNTO QUE REALICE LA ACTUALIZACIÓN EN CÁMARA DE COMERCIO O EN EL AVISO 9/10/2025 SE VISITA COMERCIO, CB INDICA QUE EL CORREO DE REGISTRO SE ENCUENTRA ERRÓNEO POR LO CUAL NO HAN PODIDO CREAR CREDENCIALES DE ACCESO, SE ESCALA A COORDINADOR Y SE LE INDICA AL COMERCIO QUE DEBE HACER ACTUALIZACIÓN EN LÍNEA 018000. | SE ESTABLECE COMUNICACIÓN DE NUEVO CON EL USUARIO EL CUAL INDICA QUE AUN NO TIENE CORREO POR PARTE DE WOMPI - COMUNICACIÓN POR WPP | 11-11 SE REALIZA LLAMADA AL CLIENTE, SE HABLA CON EL SR BLAS ALFONSO VILLADIEGO DOMINGUEZ SE VALIDA DIRECCIÓN OK, CANAL OK, DISPONIBILIDAD TOTAL, USUARIO Y CONTRASEÑA WOMPI OK, LLAMAR EL DÍA LA INSTALACIÓN PARA CONFIRMAR VISITA, AVISO EXTERIOR ALTURA - 2 METROS (COMUNICACION POR WPP) | 12-11 SE REALIZA INSTALACIÓN DE CORRESPONSAL, SE INSTALA EQUIPO CON PRUEBAS EXITOSAS, SE CAPACITA Y SE EVALÚA AL CLIENTE, SE INSTALA PUBLICIDAD COMPLETA, CB QUEDA OPERATIVO. USUARIO SOMOS BANCOLOMBIA ACTIVO | R2: VISITA_TÉCNICA | S2: 254UMD4X8473 | T2: PRINCIPAL | U2: TERRESTRE | V2: CASSIANI PEREZ RAUL RAMIRO | W2: 2 | X2: =IF(T2="PRINCIPAL",'TARIFAS 2025'!$B$5,IF(T2="INTERMEDIA",'TARIFAS 2025'!$C$5,IF(T2="LEJANA",'TARIFAS 2025'!$D$5))) -> 367716 | Y2: 1 | Z2: =X2*W2*Y2 -> 735432
A3: BUCARAMANGA | B3: =VLOOKUP(A3,'CENTROS DE COSTOS'!A:D,2,0) -> 0036-0007 | C3: =VLOOKUP(A3,'CENTROS DE COSTOS'!A:D,3,0) -> Wompi Santander | D3: 81065 | E3: TA-25-1246641 | F3: 81750 | G3: APERTURA | H3: CB CRECIMIENTO - NUEVO | I3: ARAUCA | J3: ARAUQUITA | K3: BARRIO SEIS DE ENERO ARAUQUITA | L3: WOMPI | M3: FO-25-1748405 | N3: 45932 | O3: 45967 | P3: EJECUTADO | Q3: 10-10 SE REALIZA LLAMADA AL CLIENTE, SE HABLA CON LA SRA ALBA ALFONSO NIÑO LA CUAL INDICA QUE AUN NO TIENE EL CORREO POR PARTE DE WOMPI | 28/10/2025 EN NUEVA COMUNICACION CON LA USUARIA INDICA QUE YA TIENE EL CORREO POR PARTE DE WOMPÍ, ALTURA DEL AVISO 1 MT | 06-11 SE REALIZA INSTALACIÓN DE CORRESPONSAL, SE INSTALA EQUIPO CON PRUEBAS EXITOSAS, SE CAPACITA Y SE EVALÚA AL CLIENTE, SE INSTALA PUBLICIDAD COMPLETA, CB QUEDA OPERATIVO. USUARIO SOMOS BANCOLOMBIA ACTIVO | R3: VISITA_TÉCNICA | S3: 254UMD4X8479 | T3: LEJANA | U3: AEREO | V3: SANTOS GONZALEZ JOHAN FABIAN | W3: 1 | X3: =IF(T3="PRINCIPAL",'TARIFAS 2025'!$B$5,IF(T3="INTERMEDIA",'TARIFAS 2025'!$C$5,IF(T3="LEJANA",'TARIFAS 2025'!$D$5))) -> 598334 | Y3: 1 | Z3: =X3*W3*Y3 -> 598334
A4: NEIVA | B4: =VLOOKUP(A4,'CENTROS DE COSTOS'!A:D,2,0) -> 0036-0006 | C4: =VLOOKUP(A4,'CENTROS DE COSTOS'!A:D,3,0) -> Wompi Oriente | D4: 18247 | E4: TA-25-1246642 | F4: 81763 | G4: APERTURA | H4: CB CRECIMIENTO - NUEVO | I4: CAQUETA | J4: EL DONCELLO | K4: BARRIO CENTRO EL DONCELLO 2 | L4: WOMPI | M4: FO-25-1748407 | N4: 45932 | O4: 45968 | P4: EJECUTADO | Q4: 11-10 SE REALIZA LLAMADA AL CLIENTE, SE HABLA CON LA SRA MARIA LUZ ORTIZ BARRAGAN, EL CUAL INDICA QUE AUN NO TIENE EL CORREO POR PARTE DE WOMPI. CORREO CORRECTO | 28/10/2025 SE REALIZA COMUNICACIÓN POR WPP CON EL USUARIO E INDICA QUE YA TIENE EL CORREO, NO INDICA ALTURA DEL AVISO | 07-11 SE REALIZA INSTALACIÓN DE CORRESPONSAL, SE INSTALA EQUIPO CON PRUEBAS EXITOSAS, SE CAPACITA Y SE EVALÚA AL CLIENTE, SE INSTALA PUBLICIDAD COMPLETA, CB QUEDA OPERATIVO. USUARIO SOMOS BANCOLOMBIA ACTIVO | R4: VISITA_TÉCNICA | S4: 254MMD4X0414 | T4: LEJANA | U4: TERRESTRE | V4: BERMUDEZ SANCHEZ JOSE NEYBER | W4: 1 | X4: =IF(T4="PRINCIPAL",'TARIFAS 2025'!$B$5,IF(T4="INTERMEDIA",'TARIFAS 2025'!$C$5,IF(T4="LEJANA",'TARIFAS 2025'!$D$5))) -> 598334 | Y4: 1 | Z4: =X4*W4*Y4 -> 598334
A5: MANIZALES | B5: =VLOOKUP(A5,'CENTROS DE COSTOS'!A:D,2,0) -> 0036-0002 | C5: =VLOOKUP(A5,'CENTROS DE COSTOS'!A:D,3,0) -> Wompi Eje Cafetero | D5: 17777 | E5: TA-25-1246646 | F5: 81788 | G5: APERTURA | H5: CB CRECIMIENTO - NUEVO | I5: CALDAS | J5: SUPIA | K5: BARRIO CODEMAS SUPÍA | L5: WOMPI | M5: FO-25-1748414 | N5: 45932 | O5: 45966 | P5: EJECUTADO | Q5: 10-10 SE REALIZA LLAMADA AL CLIENTE, SE HABLA CON LA SRA SHIRLEY PATRICIA CANTELLON LOPEZ, EL CUAL INDICA QUE AUN NO TIENE EL CORREO POR PARTE DE WOMPI | 28/10/2025 EN NUEVA COMUNICACIÓN CON LA USUARIA INDICA QUE YA TIENE EL CORREO POR PARTE DE WOMPI, 2.5 MT 31-10 DEBIDO A PROBLEMAS DE MOVILIDAD EN LA VIA QUE COMUNICA AL MUNICIPIO DE SUPIA, NO SE PUEDE DESPLAZAR, SE REALIZARA DESPLAZAMIENTO LA PROXIMA SEMANA | 05-11 SE REALIZA INSTALACIÓN DE CORRESPONSAL, SE INSTALA EQUIPO CON PRUEBAS EXITOSAS, SE CAPACITA Y SE EVALÚA AL CLIENTE, SE INSTALA PUBLICIDAD COMPLETA, CB QUEDA OPERATIVO. USUARIO SOMOS BANCOLOMBIA ACTIVO | R5: VISITA_TÉCNICA | S5: 254UMD4X8954 | T5: INTERMEDIA | U5: TERRESTRE | V5: ARROYAVE CANO MANUEL GUILLERMO | W5: 1 | X5: =IF(T5="PRINCIPAL",'TARIFAS 2025'!$B$5,IF(T5="INTERMEDIA",'TARIFAS 2025'!$C$5,IF(T5="LEJANA",'TARIFAS 2025'!$D$5))) -> 488953 | Y5: 1 | Z5: =X5*W5*Y5 -> 488953
A6: MEDELLIN | B6: =VLOOKUP(A6,'CENTROS DE COSTOS'!A:D,2,0) -> 0036-0005 | C6: =VLOOKUP(A6,'CENTROS DE COSTOS'!A:D,3,0) -> Wompi Noroccidente | D6: 5237 | E6: TA-25-1253400 | F6: 81760 | G6: APERTURA | H6: CB CRECIMIENTO - NUEVO | I6: ANTIOQUIA | J6: DON MATIAS | K6: BARRIO PARQUE DON MATIAS DON MATIAS | L6: WOMPI | M6: FO-25-1763460 | N6: 45932 | O6: 45965 | P6: EJECUTADO | Q6: 10-10 SE REALIZA LLAMADA AL CLIENTE, SE HABLA CON LA SRA YESICA PAOLA JIMENEZ CARDENAS, INDICA NO TENER LAS CREDENCIALES DE ACCESO WOMPI. CORREO CORRECTO | 28/10/2025 EN NUEVA COMUNICACIÓN CON LA USUARIA INDICA QUE AUN NO TIENE CORREO POR PARTE DE WOMPI | 31/10/2025 30-10 SE REALIZA LLAMADA AL CLIENTE, SE HABLA CON LA SRA YESICA PAOLA JIMENEZ CARDENAS SE VALIDA DIRECCIÓN OK, CANAL OK, DISPONIBILIDAD TOTAL, USUARIO Y CONTRASEÑA WOMPI OK, LLAMAR EL DÍA LA INSTALACIÓN PARA CONFIRMAR VISITA, AVISO EXTERIOR ALTURA: NO INDICA ALTURA | 04-11 SE REALIZA INSTALACIÓN DE CORRESPONSAL, SE INSTALA EQUIPO CON PRUEBAS EXITOSAS, SE CAPACITA Y SE EVALÚA AL CLIENTE, SE INSTALA PUBLICIDAD COMPLETA, CB QUEDA OPERATIVO. USUARIO SOMOS BANCOLOMBIA ACTIVO | R6: VISITA_TÉCNICA | S6: 254MMD4W7548 | T6: INTERMEDIA | U6: TERRESTRE | V6: ZAPATA LOPEZ EDWARD ASDRUBAL | W6: 1 | X6: =IF(T6="PRINCIPAL",'TARIFAS 2025'!$B$5,IF(T6="INTERMEDIA",'TARIFAS 2025'!$C$5,IF(T6="LEJANA",'TARIFAS 2025'!$D$5))) -> 488953 | Y6: 1 | Z6: =X6*W6*Y6 -> 488953
A7: TUNJA | B7: =VLOOKUP(A7,'CENTROS DE COSTOS'!A:D,2,0) -> 0036-0007 | C7: =VLOOKUP(A7,'CENTROS DE COSTOS'!A:D,3,0) -> Wompi Santander | D7: 15001 | E7: TA-25-1253402 | F7: 81789 | G7: APERTURA | H7: CB CRECIMIENTO - NUEVO | I7: BOYACA | J7: TUNJA | K7: BARRIO LAS QUINTAS TUNJA 5 | L7: WOMPI | M7: FO-25-1763467 | N7: 45932 | O7: 45972 | P7: EJECUTADO | Q7: 10-10 SE REALIZA LLAMADA AL CLIENTE, SE HABLA CON LA SRA YILLIAN YINDEE CARDONA CASTEBLANCO, INDICA NO TENER LAS CREDENCIALES DE ACCESO WOMPI. CORREO CORRECTO // 28-10-2025 SE REALIZA LLAMADA SE HABLA CON LA SEÑORA YILLIAN AL REALIZAR LA BUSQUEDA EN SU CORREO DEL MENSAJE DE WOMPI NO LO ENCUENTRA, SE ESCRIBE EN EL BUSCADOR SIN EXITO, LA SEÑORA CONFIRMA NO HABERLE LLEGADO Y QUEDA ATENDA AL CORREO PARA CONTINUAR CON EL PROCESO | 31/10/2025 SE REALIZA LLAMADA AL CLIENTE, SE HABLA CON LA SRA YILLIAN YINDEE CARDONA CASTEBLANCO SE VALIDA DIRECCIÓN OK, CANAL OK, DISPONIBILIDAD TOTAL, USUARIO Y CONTRASEÑA WOMPI OK, LLAMAR EL DÍA LA INSTALACIÓN PARA CONFIRMAR VISITA, AVISO EXTERIOR ALTURA APROX 4 METROS - SE PROGRAMA PARA ESTA FECHA YA QUE LA SRA INDICA QUE VA A ESTAR POR FUERA DEL PAIS | 11-11 SE REALIZA INSTALACIÓN DE CORRESPONSAL, SE INSTALA EQUIPO CON PRUEBAS EXITOSAS, SE CAPACITA Y SE EVALÚA AL CLIENTE, SE INSTALA PUBLICIDAD COMPLETA, CB QUEDA OPERATIVO. USUARIO SOMOS BANCOLOMBIA ACTIVO | R7: VISITA_TÉCNICA | S7: 254KMD4W6142 | T7: PRINCIPAL | U7: TERRESTRE | V7: GONZALEZ GONZALEZ MARIO ALBERTO | W7: 1 | X7: =IF(T7="PRINCIPAL",'TARIFAS 2025'!$B$5,IF(T7="INTERMEDIA",'TARIFAS 2025'!$C$5,IF(T7="LEJANA",'TARIFAS 2025'!$D$5))) -> 367716 | Y7: 1 | Z7: =X7*W7*Y7 -> 367716
A8: CALI | B8: =VLOOKUP(A8,'CENTROS DE COSTOS'!A:D,2,0) -> 0036-0003 | C8: =VLOOKUP(A8,'CENTROS DE COSTOS'!A:D,3,0) -> Wompi Suroccidente | D8: 19532 | E8: TA-25-1246657 | F8: 81921 | G8: APERTURA | H8: CB CRECIMIENTO - NUEVO | I8: CAUCA | J8: PATIA | K8: BARRIO CENTRO PATIA 4 | L8: WOMPI | M8: FO-25-1748434 | N8: 45950 | O8: 45982 | P8: EJECUTADO | Q8: 21-10 SE REALIZA LLAMADA AL CLIENTE, SE HABLA CON LA SRA YENIFER CAMAYO ANDRADE, EL CUAL INDICA QUE EL CORREO ESTA CORRECTO PERO NO LE HA LLEGADO NADA DE WOMPI -COMUNICACIÓN POR WPP | 28-10 EN NUEVA COMUNICACIÓN CON EL USUARIO INDICA QUE YA TIENE EL CORREO POR PARTE DE WOMPI, SE PROCEDE CON LA PROGRAMACIÓN | 07-11 DADO PROBLEMAS PARA DESPLAZARSE HACIA EL SITIO POR ZONA ROJA, SE ESTARÁ TRATANDO DE VIAJAR LA PRÓXIMA SEMANA | 18-11 DADO PROBLEMAS PARA DESPLAZAR HACIA EL SITIO POR ZONA ROJA, SE ESTARÁ TRATANDO DE VIAJAR LA PRÓXIMA SEMANA. SE REALIZA LLAMADA CON LA SEÑORA YENIFER, SE LE INFORMA QUE DEBIDO A LOS ENFRENTAMIENTOS DE GRUPOS ARMADOS EN LA VÍA SE REPROGRAMA VISITA TÉCNICA | 21-11 SE REALIZA INSTALACIÓN DE CORRESPONSAL, SE INSTALA EQUIPO CON PRUEBAS EXITOSAS, SE CAPACITA Y SE EVALÚA AL CLIENTE, SE INSTALA PUBLICIDAD COMPLETA, CB QUEDA OPERATIVO. USUARIO SOMOS BANCOLOMBIA ACTIVO | R8: VISITA_TÉCNICA | S8: 254MMD4W7882 | T8: LEJANA | U8: TERRESTRE | V8: GIMBUEL LASSO LUIS GERMAN | W8: 1 | X8: =IF(T8="PRINCIPAL",'TARIFAS 2025'!$B$5,IF(T8="INTERMEDIA",'TARIFAS 2025'!$C$5,IF(T8="LEJANA",'TARIFAS 2025'!$D$5))) -> 598334 | Y8: 1 | Z8: =X8*W8*Y8 -> 598334
A9: PEREIRA | B9: =VLOOKUP(A9,'CENTROS DE COSTOS'!A:D,2,0) -> 0036-0002 | C9: =VLOOKUP(A9,'CENTROS DE COSTOS'!A:D,3,0) -> Wompi Eje Cafetero | D9: 76622 | E9: TA-25-1246658 | F9: 81927 | G9: APERTURA | H9: CB CRECIMIENTO - NUEVO | I9: VALLE DEL CAUCA | J9: ROLDANILLO | K9: BARRIO LA ASUNCION ROLDANILLO 2 | L9: WOMPI | M9: FO-25-1748436 | N9: 45950 | O9: 45971 | P9: EJECUTADO | Q9: 21-10 SE REALIZA LLAMADA AL CLIENTE, SE HABLA CON LA SR GERMAN ALONSO MARTINEZ BERMUDEZ EL CUAL INDICA QUE EL CORREO ESTA ERRADO, EL CORREO CORRECTO ES germanalonso0410@gmail.com | 28/10/2025 SE ESTABLECE COMUNICACIÓN CON EL SR GERMAN EL CUAL INDICA QUE YA TIENE EL CORREO POR PARTE DE WOMPI , ALTURA DEL AVISO 2 MT 07-11 DADO PROBLEMAS DE CIERRE EN LA VIA QUE COMUNICA A PEREURA CON CARTAGO NO SE PUDO REALIZAR DESPLAZAMIENTO EL DIA 7 DE NOVIEMBRE | 10-11 SE REALIZA INSTALACIÓN DE CORRESPONSAL, SE INSTALA EQUIPO CON PRUEBAS EXITOSAS, SE CAPACITA Y SE EVALÚA AL CLIENTE, SE INSTALA PUBLICIDAD COMPLETA, CB QUEDA OPERATIVO. USUARIO SOMOS BANCOLOMBIA ACTIVO | R9: VISITA_TÉCNICA | S9: 254MMD4X0180 | T9: LEJANA | U9: TERRESTRE | V9: LOAIZA LOPEZ JHON FREDDY | W9: 1 | X9: =IF(T9="PRINCIPAL",'TARIFAS 2025'!$B$5,IF(T9="INTERMEDIA",'TARIFAS 2025'!$C$5,IF(T9="LEJANA",'TARIFAS 2025'!$D$5))) -> 598334 | Y9: 1 | Z9: =X9*W9*Y9 -> 598334
A10: BOGOTA | B10: =VLOOKUP(A10,'CENTROS DE COSTOS'!A:D,2,0) -> 0036-0004 | C10: =VLOOKUP(A10,'CENTROS DE COSTOS'!A:D,3,0) -> Wompi Centro | D10: 25718 | E10: TA-25-1253410 | F10: 81925 | G10: APERTURA | H10: CB CRECIMIENTO - NUEVO | I10: CUNDINAMARCA | J10: SASAIMA | K10: BARRIO EL CARMEN SASAIMA | L10: WOMPI | M10: FO-25-1763475 | N10: 45950 | O10: 45966 | P10: EJECUTADO | Q10: 21-10 SE REALIZA LLAMADA AL CLIENTE, SE HABLA CON LA SR EDUARDO CRUZ MURCIA EL CUAL INDICA QUE EL CORREO ESTA ERRADO, EL CORREO CORRECTO ES rujacara1@hotmail.com // 28-10-2025 SE REALIZA LLAMADA AL NUMERO DE LA LISTA SE HABLA CON EL CLIENTE QUIEN AL BUSCAR EN SU CORREO NO ENCUENTRA EL MENSAJE DE WOMPI, ME VUELVE A CONFIRMAR SU CORREO: rujacara1@hotmail.com | 31/10/2025 30-10 SE REALIZA LLAMADA AL CLIENTE, SE HABLA CON LA SR EDUARDO CRUZ MURCIA SE VALIDA DIRECCIÓN OK, CANAL OK, DISPONIBILIDAD TOTAL, USUARIO Y CONTRASEÑA WOMPI OK, LLAMAR EL DÍA LA INSTALACIÓN PARA CONFIRMAR VISITA, AVISO EXTERIOR ALTURA APROX 2.50 METROS - COMUNICACIÓN POR WPP | 05-11 SE REALIZA INSTALACIÓN DE CORRESPONSAL, SE INSTALA EQUIPO CON PRUEBAS EXITOSAS, SE CAPACITA Y SE EVALÚA AL CLIENTE, SE INSTALA PUBLICIDAD COMPLETA, CB QUEDA OPERATIVO. USUARIO SOMOS BANCOLOMBIA ACTIVO | R10: VISITA_TÉCNICA | S10: 254MMD4X2531 | T10: INTERMEDIA | U10: TERRESTRE | V10: LOZADA ROJAS CHRISTIAN ANDRES | W10: 1 | X10: =IF(T10="PRINCIPAL",'TARIFAS 2025'!$B$5,IF(T10="INTERMEDIA",'TARIFAS 2025'!$C$5,IF(T10="LEJANA",'TARIFAS 2025'!$D$5))) -> 488953 | Y10: 1 | Z10: =X10*W10*Y10 -> 488953
A11: PASTO | B11: =VLOOKUP(A11,'CENTROS DE COSTOS'!A:D,2,0) -> 0036-0003 | C11: =VLOOKUP(A11,'CENTROS DE COSTOS'!A:D,3,0) -> Wompi Suroccidente | D11: 52427 | E11: TA-25-1246659 | F11: 81913 | G11: APERTURA | H11: CB CRECIMIENTO - NUEVO | I11: NARIÑO | J11: MAGUI | K11: BARRIO PIEDRA VERDE MAGUI | L11: WOMPI | M11: FO-25-1748439 | N11: 45950 | O11: 45973 | P11: EJECUTADO | Q11: 22-10 SE REALIZA LLAMADA AL CLIENTE, SE HABLA CON LA SRA DANIA MADONA BENALCAZAR CASTILLO, INDICA QUE NO TIENE LAS CREDENCIALES DE ACCESO (CORREO CORRECTO) // 28-10-2025 SE REALIZA LLAMADA AL NUMERO DE LA LISTA SE HABLA CON LA MAMA SE LA SEÑORA DANIA, AL CONFIRMAR POR EL CORREO DE WOMPI ME INDICA QUE NO LE HA LLEGADO AUN, QUE ESTA EN ESPERA DE ESE CORREO PERO AUN NO LO TIENE 28-10 EN COMUNICACIÓN CON LA USUARIA INDICA QUE YA TIENE EL CORREO POR PARTE DE WOMPI | 07-10 SE REALIZARA DESPLAZAMIENTO EL DIA 10 DE NOVIEMBRE YA QUE DADO PROBLEMAS EN LA VIA HACIA TUMACO NO SE PUEDE DESPLAZAR ANTES | 12-11 12-11 SE REALIZA INSTALACIÓN DE CORRESPONSAL, SE INSTALA EQUIPO CON PRUEBAS EXITOSAS, SE CAPACITA Y SE EVALÚA AL CLIENTE, SE INSTALA PUBLICIDAD COMPLETA, CB QUEDA OPERATIVO. USUARIO SOMOS BANCOLOMBIA ACTIVO. COMERCIO SIN AVISO PUBLICITARIO. SIN EMBARGO, SI ES EL MISMO OBJETIVO COMERCIAL, LA DIRECCIÓN COINCIDE Y LA CÁMARA DE COMERCIO TAMBIÓN TIENE EL MISMO NOMBRE DE LISTA DE CHEQUEO | R11: VISITA_TÉCNICA | S11: 254MMD4X2338 | T11: LEJANA | U11: FLUVIAL | V11: PAZ MARTINEZ RICHARD HUMBERTO | W11: 1 | X11: =IF(T11="PRINCIPAL",'TARIFAS 2025'!$B$5,IF(T11="INTERMEDIA",'TARIFAS 2025'!$C$5,IF(T11="LEJANA",'TARIFAS 2025'!$D$5))) -> 598334 | Y11: 1 | Z11: =X11*W11*Y11 -> 598334
A12: MANIZALES | B12: =VLOOKUP(A12,'CENTROS DE COSTOS'!A:D,2,0) -> 0036-0002 | C12: =VLOOKUP(A12,'CENTROS DE COSTOS'!A:D,3,0) -> Wompi Eje Cafetero | D12: 17042 | E12: TA-25-1253412 | F12: 81889 | G12: APERTURA | H12: CB CRECIMIENTO - NUEVO | I12: CALDAS | J12: ANSERMA | K12: BARRIO VEREDA EL PARAISO ANSERMA | L12: WOMPI | M12: FO-25-1763478 | N12: 45950 | O12: 45967 | P12: EJECUTADO | Q12: 22-10-2025 SE REALIZA LLAMADA AL NUMERO DE LA LISTA, SE HABLA CON EL SEÑOR HENRRY AL VALIDAR EL CORREO ME INDICA QUE NO LE HA LLEGADO, EL CORREO SE VALIDA LETRA POR LETRA SIN EMBARGO DESPUES DE UNA BUSQUEDA ME INDICA QUE QUE EFECTIVAMENTE NO LO TIENE // 29-10-2025 SE REALIZA CONTACTO POR WHATSAPP CON EL SEÑOR HENRRY ME INDICA QUE NO LE HA LLEGADO EL CORREO Y ME LO RECTIFICA NUEVAMENTE YA QUE ESTA ESPERANDO EL PROCESO DE INSTALACION; CORREO CONFIRMADO POR EL CLIENTE: portillo_serrano@hotmail.com | 6/11/2025 SE REALIZA INSTALACIÓN DE CORRESPONSAL, SE INSTALAN EQUIPOS CON PRUEBAS EXITOSAS, SE CAPACITA Y SE EVALÚA AL CLIENTE, SE INSTALA PUBLICIDAD COMPLETA, CB QUEDA OPERATIVO. USUARIO SOMOS BANCOLOMBIA ACTIVO | R12: VISITA_TÉCNICA | S12: 254UMD4X8655 | T12: INTERMEDIA | U12: TERRESTRE | V12: FRANCO CAÑAVERAL YAMID RAUL | W12: 1 | X12: =IF(T12="PRINCIPAL",'TARIFAS 2025'!$B$5,IF(T12="INTERMEDIA",'TARIFAS 2025'!$C$5,IF(T12="LEJANA",'TARIFAS 2025'!$D$5))) -> 488953 | Y12: 1 | Z12: =X12*W12*Y12 -> 488953
A13: CALI | B13: =VLOOKUP(A13,'CENTROS DE COSTOS'!A:D,2,0) -> 0036-0003 | C13: =VLOOKUP(A13,'CENTROS DE COSTOS'!A:D,3,0) -> Wompi Suroccidente | D13: 19001 | E13: TA-25-1233729 | F13: 81956 | G13: APERTURA | H13: CB CRECIMIENTO - NUEVO | I13: CAUCA | J13: POPAYAN | K13: BARRIO VILLA DEL NORTE EN POPAYAN | L13: WOMPI | M13: FO-25-1724170 | N13: 45952 | O13: 45965 | P13: EJECUTADO | Q13: 23-10 SE REALIZA LLAMADA AL CLIENTE, SE HABLA CON LA SRA EDILMA INES ARANDA MUELAS SE VALIDA DIRECCIÓN OK, CANAL OK, DISPONIBILIDAD TOTAL, USUARIO Y CONTRASEÑA WOMPI OK, LLAMAR EL DÍA LA INSTALACIÓN PARA CONFIRMAR VISITA, AVISO EXTERIOR ALTURA: NO INDICA - COMUICACIÓN POR WPP | 04-11 DADO A INCONVENIENTES CON EL TRANSPORTE EL DIA FESTIVO, LA VISITA SE ESTA ATENDIENDO EL DIA MARTES 4 DE NOVIEMBRE | SE REALIZA INSTALACIÓN DE CORRESPONSAL, SE INSTALA EQUIPO CON PRUEBAS EXITOSAS, SE CAPACITA Y SE EVALÚA AL CLIENTE, SE INSTALA PUBLICIDAD COMPLETA, CB QUEDA OPERATIVO. USUARIO SOMOS BANCOLOMBIA ACTIVO | R13: VISITA_TÉCNICA | S13: 254MMD4W8511 | T13: LEJANA | U13: TERRESTRE | V13: GIMBUEL LASSO LUIS GERMAN | W13: 1 | X13: =IF(T13="PRINCIPAL",'TARIFAS 2025'!$B$5,IF(T13="INTERMEDIA",'TARIFAS 2025'!$C$5,IF(T13="LEJANA",'TARIFAS 2025'!$D$5))) -> 598334 | Y13: 1 | Z13: =X13*W13*Y13 -> 598334
... A134: MEDELLIN | B134: =VLOOKUP(A134,'CENTROS DE COSTOS'!A:D,2,0) -> 0036-0005 | C134: =VLOOKUP(A134,'CENTROS DE COSTOS'!A:D,3,0) -> Wompi Noroccidente | D134: 5001 | E134: TA-25-1334007 | F134: 82402 | G134: APERTURA | H134: CB CRECIMIENTO - NUEVO | I134: ANTIOQUIA | J134: MEDELLIN | K134: BARRIO EL CENTRO LA CANDELARIA MEDELLIN | L134: WOMPI | M134: FO-25-1895899 | N134: 45987 | O134: 45988 | P134: EJECUTADO | Q134: 27-11 SE REALIZA LLAMADA AL CLIENTE, SE HABLA CON LA SR ANGELO EUGENIO PUERTA CORREA SE VALIDA DIRECCIÓN OK, CANAL OK, DISPONIBILIDAD TOTAL, USUARIO Y CONTRASEÑA WOMPI OK, LLAMAR EL DÍA LA INSTALACIÓN PARA CONFIRMAR VISITA, AVISO EXTERIOR ALTURA: 2 METROS (COMUNICACION POR WPP) | 27-11 SE REALIZA INSTALACIÓN DE CORRESPONSAL, SE INSTALA EQUIPO CON PRUEBAS EXITOSAS, SE CAPACITA Y SE EVALÚA AL CLIENTE, SE INSTALA PUBLICIDAD COMPLETA, CB QUEDA OPERATIVO. USUARIO SOMOS BANCOLOMBIA ACTIVO | R134: VISITA_TÉCNICA | S134: 254MMD4W7770 | T134: PRINCIPAL | U134: TERRESTRE | V134: MARTINEZ TOVAR OSCAR DAVID | W134: 1 | X134: =IF(T134="PRINCIPAL",'TARIFAS 2025'!$B$5,IF(T134="INTERMEDIA",'TARIFAS 2025'!$C$5,IF(T134="LEJANA",'TARIFAS 2025'!$D$5))) -> 367716 | Y134: 1 | Z134: =X134*W134*Y134 -> 367716
Z135: =SUM(Z2:Z134) -> 63463121

Sheet INCIDENTES
A1: CIUDAD SEDE | B1: CENTRO_COSTO | C1: DESCRIPCION CENTRO DE COSTOS | D1: CÓDIGO DANE | E1: TA/CODIGO ACTIVIDAD | F1: CODIGO CB | G1: ACTIVIDAD | H1: DEPARTAMENTO | I1: CIUDAD | J1: NOMBRE DEL CB | K1: RED | L1: FO | M1: FECHA ASIGNACION A LINEA COMUNICACIONES | N1: FECHA DEL CIERRE DEL TICKET (DD/MM/AAAA) | O1: SOLICITUD | P1: GRUPO_FALLA | Q1: CATEGORÍA | R1: FALLA | S1: OBSERVACION | T1: FORMA DE ATENCIÓN | U1: INVENTARIO ACTUAL DE ROLLOS | V1: TIPOLOGIA | W1: TIPO DE TRAYECTO | X1: NOMBRE DEL TECNICO | Y1: DIAS DE ACTIVIDAD | Z1: VALOR DIAS ACTIVIDAD | AA1: VALOR TOTAL
A2: MEDELLIN | B2: =VLOOKUP(A2,'CENTROS DE COSTOS'!A:D,2,0) -> 0036-0005 | C2: =VLOOKUP(A2,'CENTROS DE COSTOS'!A:D,3,0) -> Wompi Noroccidente | D2: 5001 | E2: 2960293 | F2: 68652 | G2: INCIDENTE | H2: ANTIOQUIA | I2: MEDELLIN | J2: BARRIO ROBLEDO MIRADOR DEL VALLE MEDELLIN | K2: WOMPI | L2: FO-25-1761835 | M2: 45960.671 | N2: 45962.378 | O2: INCIDENTE | P2: CREDENCIALES DE ACCESO (USUARIO/CONTRASEÑA) | Q2: NO FUNCIONA EL USUARIO O CONTRASEÑA | R2: ERROR INICIO DE SESIÓN | S2: 01/11/2025 SE LLEGA AL PUNTO, CLIENTE NOS INDICA QUE NO PUEDE INICIAR SECCIÓN, SE ELIMINA CACHÉ Y DATOS DE LA APLICACIÓN, SE ACTUALIZA EQUIPO Y SE REINICIA, QUEDA OPERATIVO, TAMBIÉN SE HACEN PRUEBAS DE RED Y SE ENCUENTRAN INTERMITENCIAS, SE LE DICE A CLIENTE, PRUEBAS OK | T2: VISITA_TÉCNICA | U2: 32 | V2: PRINCIPAL | W2: TERRESTRE | X2: CARDONA MOLINA BROLIN STIVEN | Y2: 1 | Z2: =IF(T2="SOPORTE_TELEFÓNICO",'TARIFAS 2025'!$B$14,IF(V2="PRINCIPAL",'TARIFAS 2025'!$B$8,IF(V2="INTERMEDIA",'TARIFAS 2025'!$C$8,IF(V2="LEJANA",'TARIFAS 2025'!$D$8)))) -> 51282 | AA2: =Z2*Y2 -> 51282
A3: CUCUTA | B3: =VLOOKUP(A3,'CENTROS DE COSTOS'!A:D,2,0) -> 0036-0007 | C3: =VLOOKUP(A3,'CENTROS DE COSTOS'!A:D,3,0) -> Wompi Santander | D3: 54001 | E3: 2957899 | F3: 80784 | G3: INCIDENTE | H3: NORTE DE SANTANDER | I3: CUCUTA | J3: BARRIO CALLEJON CUCUTA 22 | K3: WOMPI | L3: FO-25-1766789 | FO-25-1756840 | M3: 45960.444 | N3: 45962.415 | O3: INCIDENTE | P3: EQUIPO | Q3: INTENTO DE MANIPULACION | R3: MALA MANIPULACIÓN DEL DATAFONO | S3: 31/10/2025 SE REALIZA VISITA SE ENCONTRÓ COMERCIO CERRADO NO SE LOGRÓ COMUNICACIÓN CON EL CLIENTE NI POR LLAMADA O WHATSAPP PARA SABER SI IBA A LABORAR EN LAS HORAS DE LA TARDE,SE PROGRAMA VISITA PARA EL DÍA DE MAÑANA 01-11-25 A LA ESPERA DE RESPUESTA POR PARTE DE CLIENTE PARA REALIZAR EL CAMBIO DEL DATAFONO 01/11/2025 SE REALIZA VISITA SE ENCONTRÓ DATAFONO BLOQUEADO NO PERMITE INGRESAR A LA APLICACIÓN WOMPI ARROJA ERROR EN EL SERVIDOR - AUTO INICIALIZACIÓN ,SE PROCEDE A CAMBIAR DATAFONO SE INTERESAN CREDENCIALES PRUEBAS OK | T3: VISITA_TÉCNICA | U3: 0 | V3: PRINCIPAL | W3: TERRESTRE | X3: DURAN ACOSTA FRANK YONNY | Y3: 2 | Z3: =IF(T3="SOPORTE_TELEFÓNICO",'TARIFAS 2025'!$B$14,IF(V3="PRINCIPAL",'TARIFAS 2025'!$B$8,IF(V3="INTERMEDIA",'TARIFAS 2025'!$C$8,IF(V3="LEJANA",'TARIFAS 2025'!$D$8)))) -> 51282 | AA3: =Z3*Y3 -> 102564
A4: TUNJA | B4: =VLOOKUP(A4,'CENTROS DE COSTOS'!A:D,2,0) -> 0036-0007 | C4: =VLOOKUP(A4,'CENTROS DE COSTOS'!A:D,3,0) -> Wompi Santander | D4: 15238 | E4: 2922589 | F4: 18727 | G4: INCIDENTE | H4: BOYACA | I4: DUITAMA | J4: BARRIO EL CARMEN II DUITAMA | K4: WOMPI | L4: FO-25-1721580 | M4: 45953.333 | N4: 45962.476 | O4: INCIDENTE | P4: NAVEGACION LENTA | Q4: USUARIO NO PUEDE NAVEGAR ENTRE PANTALLAS O LA APP NO ABRE SE QUEDA CARGANDO | R4: CACHE | S4: 01/11/2025 SE LOGRA COMUNICACION CON EL SEÑOR CARLOS MESA QUIEN NOS CONFIRMA QUE LOS DATAFONO SE ENCUENTRAN TRABAJANDO CON NORMALIDAD AUNQUE PRESENTA UN DESCUADRE DE GRAN VALOR, CLIENTE MANIFIESTA QUE NO VA A USAR LOS EQUIPOS HASTA QUE SE LE SOLICIONES ESTE INCONVENIENTE, SE LE INDICA AL CLIENTE QUE DICHA SOLICITUD DEBE ESCALARLA CON LA ENTIDAD BANCARIA PARA SU SOLUCION, SE CIERRA LA ORDEN YA QUE EL DATAFONO SE ENCUENTRA TRABAJANDO DE FORMA NORMAL, CLIENTE SE NIEGA A ENVIAR PRUEBAS DE TRANSACCIONES EXITOSAS. | T4: SOPORTE_TELEFÓNICO | U4: 64 | V4: INTERMEDIA | W4: TERRESTRE | X4: SOLER HOYOS CRISTIAN LEONARDO | Y4: 1 | Z4: =IF(T4="SOPORTE_TELEFÓNICO",'TARIFAS 2025'!$B$14,IF(V4="PRINCIPAL",'TARIFAS 2025'!$B$8,IF(V4="INTERMEDIA",'TARIFAS 2025'!$C$8,IF(V4="LEJANA",'TARIFAS 2025'!$D$8)))) -> 22000 | AA4: =Z4*Y4 -> 22000
A5: BOGOTA | B5: =VLOOKUP(A5,'CENTROS DE COSTOS'!A:D,2,0) -> 0036-0004 | C5: =VLOOKUP(A5,'CENTROS DE COSTOS'!A:D,3,0) -> Wompi Centro | D5: 11001 | E5: 2965082 | F5: 31244 | G5: INCIDENTE | H5: CUNDINAMARCA | I5: BOGOTA | J5: BARRIO LA PEPITA 2 | K5: WOMPI | L5: FO-25-1766917 | M5: 45961.662 | N5: 45962.534 | O5: INCIDENTE | P5: CONEXIÓN | Q5: CONEXIÓN DEFICIENTE WIFI | R5: FALLAS EN CANAL DE COMUNICACIÓN DEL CLIENTE (INTERNET) | S5: 01/11/2025 SE REALIZA LLAMADA, LA SEÑORA ADRIANA INDICA QUE ES EL INTERNET ( CLARO HOGAR ) QUE LE ESTA FALLANDO SOLAMENTE AL DATAFONO, YA QUE EN OTROS DISPOSITIVOS FUNCIONA NORMAL. LA SEÑORA ADRIANA LE COMPARTE DATOS DESDE EL CELULAR AL DATAFONO Y FUNCIONA NORMAL, A CONFORMIDAD DEL CLIENTE. | T5: SOPORTE_TELEFÓNICO | U5: 32 | V5: PRINCIPAL | W5: TERRESTRE | X5: ARIAS QUILINDO JULIAN | Y5: 1 | Z5: =IF(T5="SOPORTE_TELEFÓNICO",'TARIFAS 2025'!$B$14,IF(V5="PRINCIPAL",'TARIFAS 2025'!$B$8,IF(V5="INTERMEDIA",'TARIFAS 2025'!$C$8,IF(V5="LEJANA",'TARIFAS 2025'!$D$8)))) -> 22000 | AA5: =Z5*Y5 -> 22000
A6: MEDELLIN | B6: =VLOOKUP(A6,'CENTROS DE COSTOS'!A:D,2,0) -> 0036-0005 | C6: =VLOOKUP(A6,'CENTROS DE COSTOS'!A:D,3,0) -> Wompi Noroccidente | D6: 5607 | E6: 2965759 | F6: 31280 | G6: INCIDENTE | H6: ANTIOQUIA | I6: RETIRO | J6: BARRIO EL PINO | K6: WOMPI | L6: FO-25-1767194 | M6: 45962.375 | N6: 45962.537 | O6: INCIDENTE | P6: CREDENCIALES DE ACCESO (USUARIO/CONTRASEÑA) | Q6: INGRESO DE CREDENCIALES ERRADAS | R6: ERROR INICIO DE SESIÓN | S6: 01/11/2025 SE LLEGA AL PUNTO, SE VERIFICA QUE NO PUEDE INGRESAR EL USUARIO, SE ACTUALIZA, SE BORRA CACHÉ Y SE ENCUENTRA INTERMITENCIA EN LA RED, PRUEBAS OK | T6: VISITA_TÉCNICA | U6: 64 | V6: INTERMEDIA | W6: TERRESTRE | X6: CARDONA MOLINA BROLIN STIVEN | Y6: 1 | Z6: =IF(T6="SOPORTE_TELEFÓNICO",'TARIFAS 2025'!$B$14,IF(V6="PRINCIPAL",'TARIFAS 2025'!$B$8,IF(V6="INTERMEDIA",'TARIFAS 2025'!$C$8,IF(V6="LEJANA",'TARIFAS 2025'!$D$8)))) -> 172989 | AA6: =Z6*Y6 -> 172989
A7: VILLAVICENCIO | B7: =VLOOKUP(A7,'CENTROS DE COSTOS'!A:D,2,0) -> 0036-0006 | C7: =VLOOKUP(A7,'CENTROS DE COSTOS'!A:D,3,0) -> Wompi Oriente | D7: 50001 | E7: 2965265 | F7: 42229 | G7: INCIDENTE | H7: META | I7: VILLAVICENCIO | J7: BARRIO DANUBIO VILLAVICENCIO 1 | K7: WOMPI | L7: FO-25-1767029 | M7: 45961.683 | N7: 45962.54 | O7: INCIDENTE | P7: EQUIPO | Q7: PUERTO USB MALO | R7: FUENTE DE PODER | S7: 01/11/2025 SE REALIZA REVISIÓN FÍSICA DEL DATAFONO, NO SE ENCUENTRA FALLA, EN EL CARGADOR EL CONECTOR QUE LLEGA AL COSTADO DEL DATAFONO PRESENTA JUEGO NO ENCAJA COM AJUSTE, SE REALIZA PRUEBA CON OTRO CABLE TIPO DEL COMERCIO, LA CARGA ES CONSTANTE, SE INDICA A LA SRTA. YEIRA MEZA QUE SE DEBE USAR ESTE CABLE MIENTRAS SE SUMINISTRA CABLE DE CAMBIO PARA EL CARGADOR DEL DATAFONO. | T7: VISITA_TÉCNICA | U7: 64 | V7: PRINCIPAL | W7: TERRESTRE | X7: MURCIA HERNANDEZ HARVEY IGNACIO | Y7: 1 | Z7: =IF(T7="SOPORTE_TELEFÓNICO",'TARIFAS 2025'!$B$14,IF(V7="PRINCIPAL",'TARIFAS 2025'!$B$8,IF(V7="INTERMEDIA",'TARIFAS 2025'!$C$8,IF(V7="LEJANA",'TARIFAS 2025'!$D$8)))) -> 51282 | AA7: =Z7*Y7 -> 51282
A8: MEDELLIN | B8: =VLOOKUP(A8,'CENTROS DE COSTOS'!A:D,2,0) -> 0036-0005 | C8: =VLOOKUP(A8,'CENTROS DE COSTOS'!A:D,3,0) -> Wompi Noroccidente | D8: 5001 | E8: 2964523 | F8: 29381 | G8: INCIDENTE | H8: ANTIOQUIA | I8: MEDELLÍN | J8: COPYRED INSUMOS Y PAPELERIA | K8: WOMPI | L8: FO-25-1766282 | M8: 45961.6 | N8: 45962.578 | O8: INCIDENTE | P8: LECTURA | Q8: ERROR LECTURA CODIGO DE BARRAS | R8: NO LEE CODIGOS DE BARRAS LARGOS | S8: 01/11/2025 SE COMUNICA CON CLIENTE AL 3007795647 SE LE INDICA REALIZAR BORRADO DE CACHE, ACTUALIZACIÓN DEL TEM CALL Y REINICIO DE EQUIPO, TAMBIÉN SE LE DA INDICACIONES PARA LEER CORRECTAMENTE CÓDIGOS DE BARRAS, SE PRUEBA CON FACTURA DE EPM Y TIGO Y LEE CORRECTAMENTE, SE CIERRA | T8: SOPORTE_TELEFÓNICO | U8: 48 | V8: PRINCIPAL | W8: TERRESTRE | X8: QUINTERO SANCHEZ JUAN SEBASTIAN | Y8: 1 | Z8: =IF(T8="SOPORTE_TELEFÓNICO",'TARIFAS 2025'!$B$14,IF(V8="PRINCIPAL",'TARIFAS 2025'!$B$8,IF(V8="INTERMEDIA",'TARIFAS 2025'!$C$8,IF(V8="LEJANA",'TARIFAS 2025'!$D$8)))) -> 22000 | AA8: =Z8*Y8 -> 22000
A9: PASTO | B9: =VLOOKUP(A9,'CENTROS DE COSTOS'!A:D,2,0) -> 0036-0003 | C9: =VLOOKUP(A9,'CENTROS DE COSTOS'!A:D,3,0) -> Wompi Suroccidente | D9: 52683 | E9: 2960758 | F9: 37746 | G9: INCIDENTE | H9: NARIÑO | I9: SANDONA | J9: BARRIO SAN CARLOS SANDONA 1 | K9: WOMPI | L9: FO-25-1761983 | M9: 45960.698 | N9: 45962.582 | O9: INCIDENTE | P9: LECTURA | Q9: ERROR LECTURA CODIGO DE BARRAS | R9: NO LEE CODIGOS DE BARRAS CORTOS | S9: 01/11/2025 SE VALIDA CON EL CLIENTE QUIEN INDICA QUE EL DATAFONO NO LEE ESPECIFICAMENTE LA FACTURA DE CEDENAR, EL RESTO SI LAS LEE PERO LA DE CEDENAR NO, SE LE EXPLICA AL CLIENTE QUE CON ESTA FACTURA HAY UNA NOVEDAD QUE YA HABIA SIDO ESCALADA Y ESTA EN PROCESO DE CORRECCION PERO QUE LA FACTURA PUEDE SER PAGA CON CODIGO DE CONVENIO MANUALMENTE, LA USUARIO INDICA QUE SI PUEDE HACERLO ASI SOLO QUE PENSO QUE ERA LA UNICA QUE NO PODIA REALIZARLO, SE LE INDICA QUE ASI LO PUEDE SEGUIR REALIZANDO. | T9: SOPORTE_TELEFÓNICO | U9: 0 | V9: INTERMEDIA | W9: TERRESTRE | X9: HENAO CARDONA DIEGO FERNANDO | Y9: 1 | Z9: =IF(T9="SOPORTE_TELEFÓNICO",'TARIFAS 2025'!$B$14,IF(V9="PRINCIPAL",'TARIFAS 2025'!$B$8,IF(V9="INTERMEDIA",'TARIFAS 2025'!$C$8,IF(V9="LEJANA",'TARIFAS 2025'!$D$8)))) -> 22000 | AA9: =Z9*Y9 -> 22000
A10: MEDELLIN | B10: =VLOOKUP(A10,'CENTROS DE COSTOS'!A:D,2,0) -> 0036-0005 | C10: =VLOOKUP(A10,'CENTROS DE COSTOS'!A:D,3,0) -> Wompi Noroccidente | D10: 5088 | E10: 2966575 | F10: 71700 | G10: INCIDENTE | H10: ANTIOQUIA | I10: BELLO | J10: BELLO CABAÑAS | K10: WOMPI | L10: FO-25-1768865 | M10: 45962.451 | N10: 45962.585 | O10: INCIDENTE | P10: EQUIPO | Q10: DATAFONO NO ENCIENDE | R10: FUENTE DE PODER | S10: 01/11/2025 SE ESTABLECE COMUNICACIÓN TELEFÓNICA CON EL USUARIO PARA CONFIRMAR EL INCIDENTE PREVIAMENTE REPORTADO RELACIONADO CON EL DATÁFONO WOMPI DEL CORRESPONSAL BANCOLOMBIA. DURANTE LA LLAMADA, EL USUARIO INDICA QUE EL DISPOSITIVO PRESENTA FALLAS DE CARGA Y NO ENCIENDE CORRECTAMENTE. ADEMÁS, ACLARA QUE EN EL MOMENTO NO SE ENCUENTRA EN EL ESTABLECIMIENTO COMERCIAL, YA QUE ESTÁ ATENDIENDO DILIGENCIAS PERSONALES FUERA DEL LUGAR. INFORMA QUE REGRESARÁ AL COMERCIO EL DÍA MARTES | T10: SOPORTE_TELEFÓNICO | U10: 40 | V10: PRINCIPAL | W10: TERRESTRE | X10: MARTINEZ TOVAR OSCAR DAVID | Y10: 1 | Z10: =IF(T10="SOPORTE_TELEFÓNICO",'TARIFAS 2025'!$B$14,IF(V10="PRINCIPAL",'TARIFAS 2025'!$B$8,IF(V10="INTERMEDIA",'TARIFAS 2025'!$C$8,IF(V10="LEJANA",'TARIFAS 2025'!$D$8)))) -> 22000 | AA10: =Z10*Y10 -> 22000
A11: BARRANQUILLA | B11: =VLOOKUP(A11,'CENTROS DE COSTOS'!A:D,2,0) -> 0036-0001 | C11: =VLOOKUP(A11,'CENTROS DE COSTOS'!A:D,3,0) -> Wompi Costa | D11: 8606 | E11: 2965883 | F11: 75354 | G11: INCIDENTE | H11: ATLANTICO | I11: REPELON | J11: BARRIO MARCOS LOPERA REPELON | K11: WOMPI | L11: FO-25-1767944 | M11: 45962.375 | N11: 45963.392 | O11: INCIDENTE | P11: NAVEGACION LENTA | Q11: USUARIO NO PUEDE NAVEGAR ENTRE PANTALLAS O LA APP NO ABRE SE QUEDA CARGANDO | R11: CACHE | S11: 01/11/2025 EN COMUNICACIÓN CON HERLINDA RODRÍGUEZ AL NÚMERO 3007986858 ME MANIFIESTA QUE EL DATÁFONO ESTÁ LENTO LE COMUNICO QUE EL DATÁFONO HAY QUE BORRAR CACHÉ Y BUSCAR LA ÚLTIMA ACTUALIZACIÓN QUE ES 26.0.3 HACES EL PROCEDIMIENTO DE BORRAR CACHÉ Y ACTUALIZARLA LO CUAL QUEDA EN LA ÚLTIMA QUE ES 26.0.3 LE MANIFIESTO QUE REALIZA PRUEBAS LO CUAL ME DICE QUE EL DATÁFONO YA ESTÁ TRABAJANDO BIEN Y EL PROBLEMA DE LENTITUD CAMBIO LO CUAL REALIZA VARIAS PRUEBAS EXITOSAS | T11: SOPORTE_TELEFÓNICO | U11: 0 | V11: INTERMEDIA | W11: TERRESTRE | X11: PEÑALOZA GUTIERREZ RAFAEL GUSTAVO | Y11: 1 | Z11: =IF(T11="SOPORTE_TELEFÓNICO",'TARIFAS 2025'!$B$14,IF(V11="PRINCIPAL",'TARIFAS 2025'!$B$8,IF(V11="INTERMEDIA",'TARIFAS 2025'!$C$8,IF(V11="LEJANA",'TARIFAS 2025'!$D$8)))) -> 22000 | AA11: =Z11*Y11 -> 22000
A12: MEDELLIN | B12: =VLOOKUP(A12,'CENTROS DE COSTOS'!A:D,2,0) -> 0036-0005 | C12: =VLOOKUP(A12,'CENTROS DE COSTOS'!A:D,3,0) -> Wompi Noroccidente | D12: 5001 | E12: 2967212 | F12: 70713 | G12: INCIDENTE | H12: ANTIOQUIA | I12: MEDELLÍN | J12: TIENDA LAS ESCALAS DE AYALA | K12: WOMPI | L12: FO-25-1770556 | M12: 45963.375 | N12: 45963.54 | O12: INCIDENTE | P12: CAPACITACIÓN | Q12: MALA MANIPULACIÓN POS | R12: FALTA CAPACITACIÓN USUARIO CB | S12: 02/11/2025 SE REALIZA GESTIÓN TELEFÓNICA AL NÚMERO 3006488701 Y EN COMUNICACIÓN CON EL SEÑOR JOSÉ AYALA INDICA QUE NO LE DA INGRESO A LA APLICACIÓN DE WOMPI, POR MEDIO DE VIDEO LLAMADA SE BRINDA PRIMEROS AUXILIOS Y SE IDENTIFICA QUE EL USUARIO NO ESTABA METIENDO BIEN LA CLAVE, NO PONÍAN MAYÚSCULAS, SE DA SOLUCIÓN, SERVICIOS OK | T12: SOPORTE_TELEFÓNICO | U12: 32 | V12: PRINCIPAL | W12: TERRESTRE | X12: BARRIENTOS HERNANDEZ CRISTIAN HORACIO | Y12: 1 | Z12: =IF(T12="SOPORTE_TELEFÓNICO",'TARIFAS 2025'!$B$14,IF(V12="PRINCIPAL",'TARIFAS 2025'!$B$8,IF(V12="INTERMEDIA",'TARIFAS 2025'!$C$8,IF(V12="LEJANA",'TARIFAS 2025'!$D$8)))) -> 22000 | AA12: =Z12*Y12 -> 22000
A13: CALI | B13: =VLOOKUP(A13,'CENTROS DE COSTOS'!A:D,2,0) -> 0036-0003 | C13: =VLOOKUP(A13,'CENTROS DE COSTOS'!A:D,3,0) -> Wompi Suroccidente | D13: 19001 | E13: 2957028 | F13: 80291 | G13: INCIDENTE | H13: CAUCA | I13: POPAYAN | J13: BARRIO SAN EDUARDO POPAYAN 6 | K13: WOMPI | L13: FO-25-1755940 | M13: 45960.376 | N13: 45964.365 | O13: INCIDENTE | P13: CREDENCIALES DE ACCESO (USUARIO/CONTRASEÑA) | Q13: NO FUNCIONA EL USUARIO O CONTRASEÑA | R13: ERROR INICIO DE SESIÓN | S13: 03/11/2025 SE HABLA CON EL CLIENTE Y SE LE SOLICITA CREAR UNA NUEVA CONTRASEÑA, EL CLIENTE REALIZA LA CREACIÓN DE UNA NUEVA CONTRASEÑA Y YA PUEDE INGRESAR SIN NOVEDAD | T13: SOPORTE_TELEFÓNICO | U13: 8 | V13: LEJANA | W13: TERRESTRE | X13: HENAO CARDONA DIEGO FERNANDO | Y13: 1 | Z13: =IF(T13="SOPORTE_TELEFÓNICO",'TARIFAS 2025'!$B$14,IF(V13="PRINCIPAL",'TARIFAS 2025'!$B$8,IF(V13="INTERMEDIA",'TARIFAS 2025'!$C$8,IF(V13="LEJANA",'TARIFAS 2025'!$D$8)))) -> 22000 | AA13: =Z13*Y13 -> 22000
... A135: CALI | B135: =VLOOKUP(A135,'CENTROS DE COSTOS'!A:D,2,0) -> 0036-0003 | C135: =VLOOKUP(A135,'CENTROS DE COSTOS'!A:D,3,0) -> Wompi Suroccidente | D135: 76306 | E135: 2986516 | F135: 54283 | G135: INCIDENTE | H135: VALLE DEL CAUCA | I135: GINEBRA | J135: BARRIO SAN JOSE GINEBRA | K135: WOMPI | L135: FO-25-1792949 | M135: 45967.683 | N135: 45968.483 | O135: INCIDENTE | P135: NAVEGACION LENTA | Q135: USUARIO NO PUEDE NAVEGAR ENTRE PANTALLAS O LA APP NO ABRE SE QUEDA CARGANDO | R135: CACHE | S135: 07/11/2025 SE REALIZA ACTUALIZACIÓN DE APLICACION WOMPI Y BORRADO DE CACHÉ DONDE EL DISPOSITIVO EMPIEZA A REALIZAR TRANSACCIONES | T135: VISITA_TÉCNICA | U135: 24 | V135: INTERMEDIA | W135: TERRESTRE | X135: ESCOBAR LENIS JUAN SEBASTIAN | Y135: 1 | Z135: =IF(T135="SOPORTE_TELEFÓNICO",'TARIFAS 2025'!$B$14,IF(V135="PRINCIPAL",'TARIFAS 2025'!$B$8,IF(V135="INTERMEDIA",'TARIFAS 2025'!$C$8,IF(V135="LEJANA",'TARIFAS 2025'!$D$8)))) -> 172989 | AA135: =Z135*Y135 -> 172989
A136: YOPAL | B136: =VLOOKUP(A136,'CENTROS DE COSTOS'!A:D,2,0) -> 0036-0006 | C136: =VLOOKUP(A136,'CENTROS DE COSTOS'!A:D,3,0) -> Wompi Oriente | D136: 85001 | E136: 2988398 | F136: 52651 | G136: INCIDENTE | H136: CASANARE | I136: YOPAL | J136: TECNOMOVILC TECNOLOGÍA MÓVIL CELULAR | K136: WOMPI | L136: FO-25-1794745 | M136: 45968.384 | N136: 45968.487 | O136: INCIDENTE | P136: IMPRESIÓN | Q136: TAPA DE IMPRESORA DESAJUSTADA | R136: MALA MANIPULACIÓN DEL DATAFONO | S136: 07/11/2025 EN COMUNICACIÓN CON LA SEÑORA OLGA DELGADO AL NUMERO 3143371167, INDICA NO REQUIERE LA VISITA, EL SERVICIO SE ENCUENTRA OPERATIVO. | T136: SOPORTE_TELEFÓNICO | U136: 16 | V136: PRINCIPAL | W136: TERRESTRE | X136: BERNAL ELAICA EDGAR ALEXIS | Y136: 1 | Z136: =IF(T136="SOPORTE_TELEFÓNICO",'TARIFAS 2025'!$B$14,IF(V136="PRINCIPAL",'TARIFAS 2025'!$B$8,IF(V136="INTERMEDIA",'TARIFAS 2025'!$C$8,IF(V136="LEJANA",'TARIFAS 2025'!$D$8)))) -> 22000 | AA136: =Z136*Y136 -> 22000
A137: MEDELLIN | B137: =VLOOKUP(A137,'CENTROS DE COSTOS'!A:D,2,0) -> 0036-0005 | C137: =VLOOKUP(A137,'CENTROS DE COSTOS'!A:D,3,0) -> Wompi Noroccidente | D137: 5001 | E137: 2984953 | F137: 38038 | G137: INCIDENTE | H137: ANTIOQUIA | I137: MEDELLIN | J137: BARRIO PICACHO MEDELLIN 1 | K137: WOMPI | L137: FO-25-1791571 | M137: 45967.581 | N137: 45968.512 | O137: INCIDENTE | P137: NAVEGACION LENTA | Q137: USUARIO NO PUEDE NAVEGAR ENTRE PANTALLAS O LA APP NO ABRE SE QUEDA CARGANDO | R137: CACHE | S137: 07/11/2025 SE LLAMA AL CLIENTE Y SE LE INDICA AL CLIENTE COMO LIMPIAR CACHÉ Y SE LE DAN RECOMENDACIONES DE USO DEL EQUIPO COMO USARLO CON LA BATERÍA SUPERIOR AL 40%, ELIMINAR CACHÉ UNA VEZ POR MA MAÑANA Y OTRA POR LA TARDE, NO TENER EL EQUIPO LEJOS DE LA RED WIFI, EQUIPO QUEDA OPERATIVO | T137: SOPORTE_TELEFÓNICO | U137: 56 | V137: PRINCIPAL | W137: TERRESTRE | X137: CARDONA MOLINA BROLIN STIVEN | Y137: 1 | Z137: =IF(T137="SOPORTE_TELEFÓNICO",'TARIFAS 2025'!$B$14,IF(V137="PRINCIPAL",'TARIFAS 2025'!$B$8,IF(V137="INTERMEDIA",'TARIFAS 2025'!$C$8,IF(V137="LEJANA",'TARIFAS 2025'!$D$8)))) -> 22000 | AA137: =Z137*Y137 -> 22000
A138: TUNJA | B138: =VLOOKUP(A138,'CENTROS DE COSTOS'!A:D,2,0) -> 0036-0007 | C138: =VLOOKUP(A138,'CENTROS DE COSTOS'!A:D,3,0) -> Wompi Santander | D138: 15176 | E138: 2986738 | F138: 69859 | G138: INCIDENTE | H138: BOYACA | I138: CHIQUINQUIRA | J138: BARRIO LA ESPERANZA CHIQUINQUIRA 1 | K138: WOMPI | L138: FO-25-1792948 | M138: 45967.692 | N138: 45968.515 | O138: INCIDENTE | P138: NAVEGACION LENTA | Q138: USUARIO NO PUEDE NAVEGAR ENTRE PANTALLAS O LA APP NO ABRE SE QUEDA CARGANDO | R138: CACHE | S138: 07/11/2025 "SE ESTABLECE COMUNICACIÓN CON LA SEÑORA LEIDY PORRAS AL NÚMERO 3107615880 PARA VALIDAR LA FALLA DEL CORRESPONSAL. SE REALIZA GESTIÓN TELEFÓNICA EN VIDEOLLAMADA, DURANTE LA CUAL SE LLEVAN A CABO LAS SIGUIENTES VALIDACIONES CON EL EQUIPO: BORRADO DE CACHÉ, ACTUALIZACIÓN DE LA VERSIÓN 26.2.5 , Y VALIDACIÓN DEL FUNCIONAMIENTO DEL EQUIPO MEDIANTE PRUEBAS EXITOSAS. ESTO DEMUESTRA QUE EL EQUIPO TRABAJA CON UNA COMUNICACIÓN MÁS ESTABLE. SE INFORMA AL CLIENTE QUE LAS FALLAS DE NAVEGACIÓN LENTA PUEDEN DEBERSE A PROBLEMAS DE CONFIGURACIÓN DEL WI-FI O CAÍDAS DE RED. CON LAS VALIDACIONES REALIZADAS, SE OBTIENEN PRUEBA EXITOSA Y EL CLIENTE COMPARTE EL VOUCHERS CORRESPONDIENTE , CONFIRMANDO QUE LA COMUNICACIÓN ES MÁS ESTABLE. DE ESTA MANERA, EL CLIENTE QUEDA CONFORME Y SE PROCEDE A CERRAR LA ACTIVIDAD." | T138: SOPORTE_TELEFÓNICO | U138: 32 | V138: LEJANA | W138: TERRESTRE | X138: ALVARADO MORENO CRISTHIAN | Y138: 1 | Z138: =IF(T138="SOPORTE_TELEFÓNICO",'TARIFAS 2025'!$B$14,IF(V138="PRINCIPAL",'TARIFAS 2025'!$B$8,IF(V138="INTERMEDIA",'TARIFAS 2025'!$C$8,IF(V138="LEJANA",'TARIFAS 2025'!$D$8)))) -> 22000 | AA138: =Z138*Y138 -> 22000
A139: MONTERIA | B139: =VLOOKUP(A139,'CENTROS DE COSTOS'!A:D,2,0) -> 0036-0001 | C139: =VLOOKUP(A139,'CENTROS DE COSTOS'!A:D,3,0) -> Wompi Costa | D139: 23417 | E139: 2981462 | F139: 59132 | G139: INCIDENTE | H139: CORDOBA | I139: LORICA | J139: BARRIO LOS ANDES VIA A COVEÑAS LORICA | K139: WOMPI | L139: FO-25-1786686 | M139: 45967.337 | N139: 45968.52 | O139: INCIDENTE | P139: EQUIPO | Q139: BLOQUEO POR PIN | R139: DAÑO EN LA FUENTE DE PODER | S139: 07/11/2025 NOS COMUNICAMOS CON EL CB, NOS INDICA FALLA EN EL CARGADOR, INFORMANDO QUE NO COJE CARGA EL EQUIPO, SE LE INDICA REALIZAR PRUEBAS CON OTRO CARGADOR INDICANDO QUE EL EQUIPO YA CON OTRO CARGADOR TOMA CARGA Y LO GRAN ESTABILIDAD, POR LO TANTO NO SE VISITA Y SE LE INDICA QUE PUEDE UTILIZAR ESTE CARGADOR HASTA QUE NOS INFORMEN EL CAMBIO DE ESTE ACCESORIO. NOTA: PARA ESTE PROCESÓ NOS COMUNICAMOS CON LA SRA CRISTINA SUÁREZ CON CC 1063180156, EN NO DE CONTACTO 3136096758. | T139: SOPORTE_TELEFÓNICO | U139: 0 | V139: INTERMEDIA | W139: TERRESTRE | X139: CASSIANI PEREZ RAUL RAMIRO | Y139: 1 | Z139: =IF(T139="SOPORTE_TELEFÓNICO",'TARIFAS 2025'!$B$14,IF(V139="PRINCIPAL",'TARIFAS 2025'!$B$8,IF(V139="INTERMEDIA",'TARIFAS 2025'!$C$8,IF(V139="LEJANA",'TARIFAS 2025'!$D$8)))) -> 22000 | AA139: =Z139*Y139 -> 22000
A140: PEREIRA | B140: =VLOOKUP(A140,'CENTROS DE COSTOS'!A:D,2,0) -> 0036-0002 | C140: =VLOOKUP(A140,'CENTROS DE COSTOS'!A:D,3,0) -> Wompi Eje Cafetero | D140: 66001 | E140: 2980856 | F140: 63031 | G140: INCIDENTE | H140: RISARALDA | I140: PEREIRA | J140: TWINS URBAN SHOP | K140: WOMPI | L140: FO-25-1785473 | M140: 45967.333 | N140: 45968.525 | O140: INCIDENTE | P140: SOFTWARE | Q140: APP ELIMINADA | R140: APP ELIMINADA POR EL CB | S140: 07/11/2025 EN COMUNICACIÓN CON EL CLIENTE SE EVIDENCIA QUE LA APP LA ELIMINO, SE LOGRA REALIZAR ACTUALIZACIÓN DE LA VERSIÓN POR TELL CAM Y SE ESCALA CON WOMPI PARA QUE SE REALICE TELECARGA DE LA APP, SE LLAMA NUEVAMENTE AL CLIENTE E INDICA QUE YA ESTÁ FUNCIONANDO CORRECTAMENTE. | T140: SOPORTE_TELEFÓNICO | U140: 32 | V140: PRINCIPAL | W140: TERRESTRE | X140: FRANCO CAÑAVERAL YAMID RAUL | Y140: 1 | Z140: =IF(T140="SOPORTE_TELEFÓNICO",'TARIFAS 2025'!$B$14,IF(V140="PRINCIPAL",'TARIFAS 2025'!$B$8,IF(V140="INTERMEDIA",'TARIFAS 2025'!$C$8,IF(V140="LEJANA",'TARIFAS 2025'!$D$8)))) -> 22000 | AA140: =Z140*Y140 -> 22000
A141: TUNJA | B141: =VLOOKUP(A141,'CENTROS DE COSTOS'!A:D,2,0) -> 0036-0007 | C141: =VLOOKUP(A141,'CENTROS DE COSTOS'!A:D,3,0) -> Wompi Santander | D141: 15176 | E141: 2978928 | F141: 57782 | G141: INCIDENTE | H141: BOYACA | I141: CHIQUINQUIRA | J141: BARRIO LOS SAUCES CHIQUINQUIRA | K141: WOMPI | L141: FO-25-1783644 | M141: 45966.569 | N141: 45968.537 | O141: INCIDENTE | P141: EQUIPO | Q141: DATAFONO NO ENCIENDE | R141: FUENTE DE PODER | S141: 07/11/2025 SE ESTABLECE COMUNICACIÓN CON LA SEÑORA NANCY PACHON AL NÚMERO DE CONTACTO 3202475108, CON EL FIN DE VALIDAR LA FALLA REPORTADA. LA CLIENTE INFORMA QUE EL DATÁFONO SE ENCUENTRA EN PERFECTO FUNCIONAMIENTO, INDICANDO QUE PREVIAMENTE HABÍA PRESENTADO INCONVENIENTES DE CARGA, LOS CUALES FUERON SOLUCIONADOS TRAS REALIZAR UN REINICIO DEL EQUIPO.LA SEÑORA NANCY MANIFIESTA HABER CONTACTADO A LA LÍNEA DE SOPORTE PARA SOLICITAR LA CANCELACIÓN DE LA VISITA TÉCNICA, Y ADJUNTA UN VOUCHER QUE CONFIRMA LA CORRECTA OPERATIVIDAD DEL DISPOSITIVO SE LE INFORMA QUE SE PROCEDERÁ CON EL CIERRE DE LA ORDEN, A LO CUAL LA CLIENTE MANIFIESTA CONFORMIDAD | T141: SOPORTE_TELEFÓNICO | U141: 32 | V141: LEJANA | W141: TERRESTRE | X141: ALVARADO MORENO CRISTHIAN | Y141: 1 | Z141: =IF(T141="SOPORTE_TELEFÓNICO",'TARIFAS 2025'!$B$14,IF(V141="PRINCIPAL",'TARIFAS 2025'!$B$8,IF(V141="INTERMEDIA",'TARIFAS 2025'!$C$8,IF(V141="LEJANA",'TARIFAS 2025'!$D$8)))) -> 22000 | AA141: =Z141*Y141 -> 22000
A142: TUNJA | B142: =VLOOKUP(A142,'CENTROS DE COSTOS'!A:D,2,0) -> 0036-0007 | C142: =VLOOKUP(A142,'CENTROS DE COSTOS'!A:D,3,0) -> Wompi Santander | D142: 15646 | E142: 2978689 | F142: 52924 | G142: INCIDENTE | H142: BOYACA | I142: SAMACA | J142: BARRIO CENTRO SAMACA 3 | K142: WOMPI | L142: FO-25-1783230 | M142: 45966.556 | N142: 45968.54 | O142: INCIDENTE | P142: PANTALLA | Q142: TÁCTIL | R142: NO RESPONDE LA PANTALLA TÁCTIL | S142: 07/11/2025 SE REALIZA VISITA TÉCNICA AL PUNTO PARA ENTREGA DE ROLLOS.CLIENTE CON ORDEN DE INCIDENTE GENERADA SE EVIDENCIA QUE EL EQUIPO PRESENTA BLOQUEO EN LA PANTALLA TÁCTIL. SE PROCEDE A RETIRAR LA BATERÍA Y ENCENDER NUEVAMENTE EL DISPOSITIVO. POSTERIORMENTE, SE REALIZA LIMPIEZA DE CACHÉ Y ACTUALIZACIÓN DEL SISTEMA, LUEGO DE LO CUAL SE REINICIA EL EQUIPO. SE EJECUTAN PRUEBAS DE FUNCIONAMIENTO CON RESULTADOS EXITOSOS. CLIENTE QUEDA CONFORME CON LA GESTIÓN REALIZADA. | T142: VISITA_TÉCNICA | U142: 64 | V142: INTERMEDIA | W142: TERRESTRE | X142: RODRIGUEZ MURCIA YERSON IVAN | Y142: 1 | Z142: =IF(T142="SOPORTE_TELEFÓNICO",'TARIFAS 2025'!$B$14,IF(V142="PRINCIPAL",'TARIFAS 2025'!$B$8,IF(V142="INTERMEDIA",'TARIFAS 2025'!$C$8,IF(V142="LEJANA",'TARIFAS 2025'!$D$8)))) -> 172989 | AA142: =Z142*Y142 -> 172989
A143: MEDELLIN | B143: =VLOOKUP(A143,'CENTROS DE COSTOS'!A:D,2,0) -> 0036-0005 | C143: =VLOOKUP(A143,'CENTROS DE COSTOS'!A:D,3,0) -> Wompi Noroccidente | D143: 5079 | E143: 2863040 | F143: 13055 | G143: INCIDENTE | H143: ANTIOQUIA | I143: BARBOSA | J143: BARBOSA III ANTIOQUIA | K143: WOMPI | L143: FO-25-1700538 | FO-25-1654904 | M143: 45939.468 | N143: 45968.557 | O143: INCIDENTE | P143: CONEXIÓN | Q143: CONEXIÓN DEFICIENTE WIFI | R143: FALLAS EN CANAL DE COMUNICACIÓN DEL CLIENTE (INTERNET) | S143: 17/10/2025 SE REALIZA GESTIÓN TELEFÓNICA Y PERSONA QUE ATIENDE EN EL NÚMERO 3023564578 INDICA QUE ANTES DE LA LLAMADA YA HABÍA BORRADO CACHÉ Y QUE LA FALLA PERSISTE QUE POR FAVOR LE AYUDEN CON ESO 07/11/2025 SE VERIFICA EL CANAL DEL MODEM QUE TIENEN EL CLIENTE Y EST ATRASMITIENDO SOLO POR RED 5G POR LO QUE SE LE EXPLICA AL CLIENTE QUE POR ESO EL DATAFONO NO DETECTA EL MODEM Y DEBE COMUNICARSE CON SU PROVEEDOR PARA QUE LE CAMBIE LA RED POR LA QUE TRASMITE EL NUEVO MODEM | T143: VISITA_TÉCNICA | U143: 64 | V143: INTERMEDIA | W143: TERRESTRE | X143: ALVAREZ ARENAS VICTOR HUGO | Y143: 2 | Z143: =IF(T143="SOPORTE_TELEFÓNICO",'TARIFAS 2025'!$B$14,IF(V143="PRINCIPAL",'TARIFAS 2025'!$B$8,IF(V143="INTERMEDIA",'TARIFAS 2025'!$C$8,IF(V143="LEJANA",'TARIFAS 2025'!$D$8)))) -> 172989 | AA143: =Z143*Y143 -> 345978
A144: VILLAVICENCIO | B144: =VLOOKUP(A144,'CENTROS DE COSTOS'!A:D,2,0) -> 0036-0006 | C144: =VLOOKUP(A144,'CENTROS DE COSTOS'!A:D,3,0) -> Wompi Oriente | D144: 50001 | E144: 2987462 | F144: 81456 | G144: INCIDENTE | H144: META | I144: VILLAVICENCIO | J144: DROGUERÍA FARMACÉUTICA EXPRESS | K144: WOMPI | L144: FO-25-1793851 | M144: 45968.333 | N144: 45968.59 | O144: INCIDENTE | P144: CONEXIÓN | Q144: APARECEN ERRORES EN PANTALLA: HUBO UNA DESCONEXION DE LA RED | R144: WIFI | S144: 07/11/2025 SE REALIZA ACTUALIZACIÓN DE APLICACIONE DE EQUIPO VERSION 26.2.5, SE REALIZAN PRUEBAS Y CB QUEDA OPERANDO OK | T144: VISITA_TÉCNICA | U144: 0 | V144: PRINCIPAL | W144: TERRESTRE | X144: PEDREROS CONTRERAS MICHAEL STEVENS | Y144: 1 | Z144: =IF(T144="SOPORTE_TELEFÓNICO",'TARIFAS 2025'!$B$14,IF(V144="PRINCIPAL",'TARIFAS 2025'!$B$8,IF(V144="INTERMEDIA",'TARIFAS 2025'!$C$8,IF(V144="LEJANA",'TARIFAS 2025'!$D$8)))) -> 51282 | AA144: =Z144*Y144 -> 51282
A145: BOGOTA | B145: =VLOOKUP(A145,'CENTROS DE COSTOS'!A:D,2,0) -> 0036-0004 | C145: =VLOOKUP(A145,'CENTROS DE COSTOS'!A:D,3,0) -> Wompi Centro | D145: 11001 | E145: 2987464 | F145: 45991 | G145: INCIDENTE | H145: CUNDINAMARCA | I145: BOGOTA | J145: BARRIO ENGATIVA CENTRO BOGOTA 3 | K145: WOMPI | L145: FO-25-1793844 | M145: 45968.333 | N145: 45968.595 | O145: INCIDENTE | P145: CONEXIÓN | Q145: CONEXIÓN DEFICIENTE WIFI | R145: WIFI | S145: 07/11/2025 SE REALIZA CONFIRMACIÓN DE WIFI, CB REALIZA PRUEBAS DE FUNCIONAMIENTO OK | T145: VISITA_TÉCNICA | U145: 56 | V145: PRINCIPAL | W145: TERRESTRE | X145: MICHELI LOPEZ MIGUEL ANGEL | Y145: 1 | Z145: =IF(T145="SOPORTE_TELEFÓNICO",'TARIFAS 2025'!$B$14,IF(V145="PRINCIPAL",'TARIFAS 2025'!$B$8,IF(V145="INTERMEDIA",'TARIFAS 2025'!$C$8,IF(V145="LEJANA",'TARIFAS 2025'!$D$8)))) -> 51282 | AA145: =Z145*Y145 -> 51282
A146: MANIZALES | B146: =VLOOKUP(A146,'CENTROS DE COSTOS'!A:D,2,0) -> 0036-0002 | C146: =VLOOKUP(A146,'CENTROS DE COSTOS'!A:D,3,0) -> Wompi Eje Cafetero | D146: 17001 | E146: 2982412 | F146: 68804 | G146: INCIDENTE | H146: CALDAS | I146: MANIZALES | J146: CARNICERIA LAS PALMAS | K146: WOMPI | L146: FO-25-1786642 | M146: 45967.385 | N146: 45968.599 | O146: INCIDENTE | P146: CREDENCIALES DE ACCESO (USUARIO/CONTRASEÑA) | Q146: NO FUNCIONA EL USUARIO O CONTRASEÑA | R146: ERROR INICIO DE SESIÓN | S146: 07/11/2025 SE VALIDA CON EL CLIENTE NO LE PERMITE EL INGRESO ASI CAMBIE CONTRASEÑA, SE ESCALA CON WOMPI Y SE VALIDA BORRADO Y RESINATALACION DE APLICACION Y DESPUES DE ESTO EL CLIENTE YA PUEDDE INGRESAR AL DATAFONO | T146: SOPORTE_TELEFÓNICO | U146: 40 | V146: PRINCIPAL | W146: TERRESTRE | X146: HENAO CARDONA DIEGO FERNANDO | Y146: 1 | Z146: =IF(T146="SOPORTE_TELEFÓNICO",'TARIFAS 2025'!$B$14,IF(V146="PRINCIPAL",'TARIFAS 2025'!$B$8,IF(V146="INTERMEDIA",'TARIFAS 2025'!$C$8,IF(V146="LEJANA",'TARIFAS 2025'!$D$8)))) -> 22000 | AA146: =Z146*Y146 -> 22000
A147: PASTO | B147: =VLOOKUP(A147,'CENTROS DE COSTOS'!A:D,2,0) -> 0036-0003 | C147: =VLOOKUP(A147,'CENTROS DE COSTOS'!A:D,3,0) -> Wompi Suroccidente | D147: 52001 | E147: 2988369 | F147: 79822 | G147: INCIDENTE | H147: NARIÑO | I147: PASTO | J147: A Y E DROGUERIA | K147: WOMPI | L147: FO-25-1794748 | M147: 45968.381 | N147: 45968.616 | O147: INCIDENTE | P147: SOFTWARE | Q147: VERSIÓN DESACTUALIZADA | R147: VERSIÓN NO ACTUALIZADA | S147: 07/11/2025 SE VISITA CB. SE ENCUENTRA DATAFONO CON VERSIÓN DESACTUALIZADA. SE REALIZA ACTUALIZACIÓN DE VERSIÓN Y BORRADO DE CACHE. SE REALIZAN PRUEBAS TX Y DE CÓDIGO DE BARRAS EXITOSAS. QUEDA OPERATIVO | T147: VISITA_TÉCNICA | U147: 16 | V147: PRINCIPAL | W147: TERRESTRE | X147: CASTILLO HERRERA ALEX RICARDO | Y147: 1 | Z147: =IF(T147="SOPORTE_TELEFÓNICO",'TARIFAS 2025'!$B$14,IF(V147="PRINCIPAL",'TARIFAS 2025'!$B$8,IF(V147="INTERMEDIA",'TARIFAS 2025'!$C$8,IF(V147="LEJANA",'TARIFAS 2025'!$D$8)))) -> 51282 | AA147: =Z147*Y147 -> 51282
A148: BUCARAMANGA | B148: =VLOOKUP(A148,'CENTROS DE COSTOS'!A:D,2,0) -> 0036-0007 | C148: =VLOOKUP(A148,'CENTROS DE COSTOS'!A:D,3,0) -> Wompi Santander | D148: 68001 | E148: 2985755 | F148: 71344 | G148: INCIDENTE | H148: SANTANDER | I148: BUCARAMANGA | J148: BARRIO CONCORDIA BUCARAMANGA 3 | K148: WOMPI | L148: FO-25-1791561 | M148: 45967.631 | N148: 45968.626 | O148: INCIDENTE | P148: LECTURA | Q148: NO LEE NINGUNA FACTURA | R148: NO LEE CODIGOS DE BARRAS LARGOS | S148: 07/11/2025 SE ESTABLECE CONTACTO TELEFÓNICO CON LA SEÑORA MARTA AL NÚMERO +57 320 9776185 SE PROCEDE REALIZANDO BORRADO DE CACHÉ ACTUALIZACIÓN DE APLICACIÓN REINICIO DEL EQUIPO SE LE INDICAA LA USUARIA DE CÓMO REALIZAR CORRECTAMENTE EL PAGO DE LAS FACTURAS SE REALIZA PRUEBA CON UNA FACTURA POR UN PESO INDICANDO QUE LA TRANSACCIÓN FUE EXITOSA SE LE INDICA A LA CLIENTE QUE EN CASO QUE SE LE PRESENTE ALGÚN INCONVENIENTE SE VUELVA A COMUNICAR NUEVAMENTE LA LÍNEA DE ATENCIÓN 01 8000 95 3344 SE PROCEDE CON EL CIERRE DE LA ACTIVIDAD | T148: SOPORTE_TELEFÓNICO | U148: 24 | V148: PRINCIPAL | W148: TERRESTRE | X148: REYES RAMIREZ DIEGO ALEXANDER | Y148: 1 | Z148: =IF(T148="SOPORTE_TELEFÓNICO",'TARIFAS 2025'!$B$14,IF(V148="PRINCIPAL",'TARIFAS 2025'!$B$8,IF(V148="INTERMEDIA",'TARIFAS 2025'!$C$8,IF(V148="LEJANA",'TARIFAS 2025'!$D$8)))) -> 22000 | AA148: =Z148*Y148 -> 22000
A149: BOGOTA | B149: =VLOOKUP(A149,'CENTROS DE COSTOS'!A:D,2,0) -> 0036-0004 | C149: =VLOOKUP(A149,'CENTROS DE COSTOS'!A:D,3,0) -> Wompi Centro | D149: 11001 | E149: 2989537 | F149: 14690 | G149: INCIDENTE | H149: CUNDINAMARCA | I149: BOGOTÁ | J149: TELECOMUNICACIONES LA CRECIENTE | K149: WOMPI | L149: FO-25-1795537 | M149: 45968.442 | N149: 45968.655 | O149: INCIDENTE | P149: SOFTWARE | Q149: APP ELIMINADA | R149: APP ELIMINADA POR EL CB | S149: 07/11/2025 SE REALIZA COMUNICACIÓN CON LA SEÑORA KAREN MENESES PARA VALIDAR FALLA CLIENTE INDICA QUE BORRÓ POR EQUIVOCACION LA APP DE WOMPI ,SE REALIZA INSTALACIÓN DE FORMA REMOTA ,SE REALIZAN PRUEBAS OK CLIENTE INDICA DATAFONO YA SE ENCUENTRA OPERATIVO | T149: SOPORTE_TELEFÓNICO | U149: 16 | V149: PRINCIPAL | W149: TERRESTRE | X149: GALINDO ROJAS LUIS FELIPE | Y149: 1 | Z149: =IF(T149="SOPORTE_TELEFÓNICO",'TARIFAS 2025'!$B$14,IF(V149="PRINCIPAL",'TARIFAS 2025'!$B$8,IF(V149="INTERMEDIA",'TARIFAS 2025'!$C$8,IF(V149="LEJANA",'TARIFAS 2025'!$D$8)))) -> 22000 | AA149: =Z149*Y149 -> 22000
