Workbook

Sheet RESUMEN
A1: FACTURACIÓN ENTREGA DE ROLLOS A GESTORES
A2: 1 AL 3O DE NOVIEMBRE 2025
A3: WOMPI
A4: CONCEPTOS | B4: CANTIDAD | C4: TOTAL
A5: ='ENTREGA DE ROLLOS EN BODEGAS'!V1 -> ENTREGA DE ROLLOS EN BODEGAS | B5: =COUNTA('ENTREGA DE ROLLOS EN BODEGAS'!A:A)-1 -> 2410 | C5: ='ENTREGA DE ROLLOS EN BODEGAS'!V2412 -> 50314387
A6: SUBTOTAL | C6: =SUM(C5:C5) -> 50314387
A7: Iva | C7: =C6*0.19 -> 9559733.5
A8: TOTAL | C8: =SUM(C6:C7) -> 59874120

Sheet BASE TARIFA 2025
A1: PROPONENTE | B1: TIPO ACTIVIDAD | C1: BODEGA | D1: CENTRO DE COSTOS | E1: ENTREGA DE DATAFONOS EN BODEGAS | F1: ENTREGA DE ROLLOS EN BODEGAS
A2: WOMPI (SOLICITUD ADICIONAL) | B2: ENTREGA DE DATAFONOS EN BODEGAS UBICADAS EN CIUDADES PRINCIPALES | C2: MEDELLIN | D2: WOMPI NOROCCIDENTE | E2: 37313 | F2: 15709.5
A3: WOMPI (SOLICITUD ADICIONAL) | B3: ENTREGA DE DATAFONOS EN BODEGAS UBICADAS EN CIUDADES PRINCIPALES | C3: BOGOTA | D3: WOMPI CENTRO | E3: 37313 | F3: 15709.5
A4: WOMPI (SOLICITUD ADICIONAL) | B4: ENTREGA DE DATAFONOS EN BODEGAS UBICADAS EN CIUDADES PRINCIPALES | C4: CALI | D4: WOMPI SUROCCIDENTE | E4: 37313 | F4: 15709.5
A5: WOMPI (SOLICITUD ADICIONAL) | B5: ENTREGA DE DATAFONOS EN BODEGAS UBICADAS EN CIUDADES PRINCIPALES | C5: PEREIRA | D5: WOMPI EJE CAFETERO | E5: 37313 | F5: 15709.5
A6: WOMPI (SOLICITUD ADICIONAL) | B6: ENTREGA DE DATAFONOS EN BODEGAS UBICADAS EN CIUDADES PRINCIPALES | C6: BARRANQUILLA | D6: WOMPI COSTA | E6: 37313 | F6: 15709.5
A7: WOMPI (SOLICITUD ADICIONAL) | B7: ENTREGA DE DATAFONOS EN BODEGAS UBICADAS EN CIUDADES PRINCIPALES | C7: BUCARAMANGA | D7: WOMPI SANTANDERES | E7: 37313 | F7: 15709.5
A8: WOMPI (SOLICITUD ADICIONAL) | B8: ENTREGA DE DATAFONOS EN BODEGAS UBICADAS EN CIUDADES PRINCIPALES | C8: MONTERIA | D8: WOMPI COSTA | E8: 37313 | F8: 15709.5
A9: WOMPI (SOLICITUD ADICIONAL) | B9: ENTREGA DE DATAFONOS EN BODEGAS UBICADAS EN CIUDADES REMOTAS CERTIFICADAS | C9: CUCUTA | D9: WOMPI SANTANDERES | E9: 49671.7 | F9: 28277.1
A10: WOMPI (SOLICITUD ADICIONAL) | B10: ENTREGA DE DATAFONOS EN BODEGAS UBICADAS EN CIUDADES REMOTAS CERTIFICADAS | C10: NEIVA | D10: WOMPI ORIENTE | E10: 49671.7 | F10: 28277.1
A11: WOMPI (SOLICITUD ADICIONAL) | B11: ENTREGA DE DATAFONOS EN BODEGAS UBICADAS EN CIUDADES REMOTAS CERTIFICADAS | C11: SANTA MARTA | D11: WOMPI COSTA | E11: 49671.7 | F11: 28277.1
A12: WOMPI (SOLICITUD ADICIONAL) | B12: ENTREGA DE DATAFONOS EN BODEGAS UBICADAS EN CIUDADES REMOTAS CERTIFICADAS | C12: TUNJA | D12: WOMPI SANTANDERES | E12: 49671.7 | F12: 28277.1
A13: WOMPI (SOLICITUD ADICIONAL) | B13: ENTREGA DE DATAFONOS EN BODEGAS UBICADAS EN CIUDADES REMOTAS CERTIFICADAS | C13: VILLAVICENCIO | D13: WOMPI ORIENTE | E13: 49671.7 | F13: 28277.1
... A23: WOMPI (SOLICITUD ADICIONAL) | B23: ENTREGA DE DATAFONOS EN BODEGAS UBICADAS EN CIUDADES REMOTAS NO CERTIFICADAS | C23: YOPAL | D23: WOMPI ORIENTE | E23: 49671.7 | F23: 28277.1

Sheet TD
A1: Centro_de_Costos | B1: Suma de ENTREGA DE ROLLOS EN BODEGAS
A2: WOMPI CENTRO | B2: 11499354
A3: WOMPI COSTA | B3: 10374554
A4: WOMPI EJE CAFETERO | B4: 5674271.4
A5: WOMPI NOROCCIDENTE | B5: 5067884.7
A6: WOMPI ORIENTE | B6: 13516454
A7: WOMPI SANTANDERES | B7: 15920007
A8: WOMPI SUROCCIDENTE | B8: 10399689
A9: Total general | B9: 72452214

Sheet Hoja1
A1: CODIGO PUNTO DE SERVICIO | B1: ROLLOS
A2: 10007 | B2: 16
A3: 10015 | B3: 16
A4: 10016 | B4: 8
A5: 10018 | B5: 16
A6: 10023 | B6: 8
A7: 10024 | B7: 16
A8: 10028 | B8: 8
A9: 10029 | B9: 16
A10: 10030 | B10: 16
A11: 10032 | B11: 16
A12: 10033 | B12: 8
A13: 10035 | B13: 16
... A17890: 81253 | B17890: 8

Sheet Hoja2
A3: Etiquetas de fila | B3: Suma de ENTREGA DE ROLLOS EN BODEGAS
A4: WOMPI CENTRO | B4: 8671644
A5: WOMPI COSTA | B5: 5850217.8
A6: WOMPI EJE CAFETERO | B6: 3415245.3
A7: WOMPI NOROCCIDENTE | B7: 3716867.7
A8: WOMPI ORIENTE | B8: 10688744
A9: WOMPI SANTANDERES | B9: 12536181
A10: WOMPI SUROCCIDENTE | B10: 5435487
A11: Total general | B11: 50314387

Sheet ENTREGA DE ROLLOS EN BODEGAS
A1: Codigo_Punto | B1: Nombre_Punto | C1: Nit_CC_Persona | D1: TelefonoCB | E1: Celular_Contacto1 | F1: Celular_dueno | G1: Dirección_Establecimiento | H1: Latitud | I1: Longitud | J1: Departamento | K1: Municipio | L1: Corregimiento | M1: Codigo_Dane | N1: Fecha_Migracion | O1: Formulario | P1: Forma de atención | Q1: Descripción de la Solución | R1: Estado | S1: Cantidad de Rollos por CB | T1: Bodega | U1: Centro_de_Costos | V1: ENTREGA DE ROLLOS EN BODEGAS
A2: 78455 | B2: BARRIO PARQUE PRINCIPAL GRANADA GRANADA | C2: 900815151 | D2: 3108256807 | E2: 3135853734 | F2: 3135853734 | G2: CR 23 20 36,PARQUE PRINCIPAL GRANADA | H2: 6.1431387 | I2: -75.1851605 | J2: ANTIOQUIA | K2: GRANADA | L2: GRANADA | M2: 5313 | N2: 2025-11-10 | S2: =VLOOKUP(A2,Hoja1!A:B,2,0) -> 8 | T2: =VLOOKUP(M2,[1]TIPOLOGIAS!$A:$F,4,0) -> MEDELLIN | U2: =VLOOKUP(T2,'BASE TARIFA 2025'!C:D,2,0) -> WOMPI NOROCCIDENTE | V2: =VLOOKUP(T2,'BASE TARIFA 2025'!C:F,4,0) -> 15709.5
A3: 76347 | B3: BARRIO JUNIN GRANADA GRANADA | C3: 43645420 | D3: 3235263995 | E3: 3128575628 | F3: 3128575628 | G3: CR 23 22 17,JUNIN GRANADA | H3: 6.1444621 | I3: -75.1860924 | J3: ANTIOQUIA | K3: GRANADA | L3: GRANADA | M3: 5313 | N3: 2025-11-10 | S3: =VLOOKUP(A3,Hoja1!A:B,2,0) -> 8 | T3: =VLOOKUP(M3,[1]TIPOLOGIAS!$A:$F,4,0) -> MEDELLIN | U3: =VLOOKUP(T3,'BASE TARIFA 2025'!C:D,2,0) -> WOMPI NOROCCIDENTE | V3: =VLOOKUP(T3,'BASE TARIFA 2025'!C:F,4,0) -> 15709.5
A4: 42888 | B4: BARRIO CENTRO GRANADA 1 | C4: 1041202120 | D4: 8320396 | E4: 3217742193 | F4: 3217742193 | G4: CR 24 A 21 10,CENTRO | H4: 6.142882 | I4: -75.1851 | J4: ANTIOQUIA | K4: GRANADA | L4: GRANADA | M4: 5313 | N4: 2025-11-10 | S4: =VLOOKUP(A4,Hoja1!A:B,2,0) -> 8 | T4: =VLOOKUP(M4,[1]TIPOLOGIAS!$A:$F,4,0) -> MEDELLIN | U4: =VLOOKUP(T4,'BASE TARIFA 2025'!C:D,2,0) -> WOMPI NOROCCIDENTE | V4: =VLOOKUP(T4,'BASE TARIFA 2025'!C:F,4,0) -> 15709.5
A5: 37971 | B5: BARRIO CENTRO GRANADA | C5: 1041203634 | E5: 3127054455 | F5: 3215029004 | G5: CR 23 21 34 LC 109 CENTRO | H5: 6.14341944 | I5: -75.1856152 | J5: ANTIOQUIA | K5: GRANADA | L5: GRANADA | M5: 5313 | N5: 2025-11-10 | S5: =VLOOKUP(A5,Hoja1!A:B,2,0) -> 8 | T5: =VLOOKUP(M5,[1]TIPOLOGIAS!$A:$F,4,0) -> MEDELLIN | U5: =VLOOKUP(T5,'BASE TARIFA 2025'!C:D,2,0) -> WOMPI NOROCCIDENTE | V5: =VLOOKUP(T5,'BASE TARIFA 2025'!C:F,4,0) -> 15709.5
A6: 13134 | B6: BARRIO UNICO - GRANDA ANTIOQUIA | C6: 70830261 | D6: 2643794 | E6: 3117207058 | F6: 3133559106 | G6: CL 21 21-25 | H6: 6.1439934 | I6: -75.1848529 | J6: ANTIOQUIA | K6: GRANADA | L6: GRANADA | M6: 5313 | N6: 2025-11-10 | S6: =VLOOKUP(A6,Hoja1!A:B,2,0) -> 16 | T6: =VLOOKUP(M6,[1]TIPOLOGIAS!$A:$F,4,0) -> MEDELLIN | U6: =VLOOKUP(T6,'BASE TARIFA 2025'!C:D,2,0) -> WOMPI NOROCCIDENTE | V6: =VLOOKUP(T6,'BASE TARIFA 2025'!C:F,4,0) -> 15709.5
A7: 10254 | B7: HISPANIA - ANTIOQUIA | C7: 21555569 | D7: 8432224 | E7: 3147215403 | F7: 3147215403 | G7: CR 51 FLORENCIA PAR PRINCIPAL DE HISPANIA | H7: 5.7991142 | I7: -75.9077696 | J7: ANTIOQUIA | K7: HISPANIA | L7: HISPANIA | M7: 5353 | N7: 2025-11-12 | S7: =VLOOKUP(A7,Hoja1!A:B,2,0) -> 8 | T7: =VLOOKUP(M7,[1]TIPOLOGIAS!$A:$F,4,0) -> MEDELLIN | U7: =VLOOKUP(T7,'BASE TARIFA 2025'!C:D,2,0) -> WOMPI NOROCCIDENTE | V7: =VLOOKUP(T7,'BASE TARIFA 2025'!C:F,4,0) -> 15709.5
A8: 40400 | B8: BARRIO PARQUE HISPANIA | C8: 1027884461 | D8: 8432045 | E8: 3146379251 | F8: 3146379251 | G8: CL 50 50 12 TOLEDO PORQUE PRINCIPAL,PARQUE | H8: 5.7999259 | I8: -75.9072391 | J8: ANTIOQUIA | K8: HISPANIA | L8: HISPANIA | M8: 5353 | N8: 2025-11-12 | S8: =VLOOKUP(A8,Hoja1!A:B,2,0) -> 16 | T8: =VLOOKUP(M8,[1]TIPOLOGIAS!$A:$F,4,0) -> MEDELLIN | U8: =VLOOKUP(T8,'BASE TARIFA 2025'!C:D,2,0) -> WOMPI NOROCCIDENTE | V8: =VLOOKUP(T8,'BASE TARIFA 2025'!C:F,4,0) -> 15709.5
A9: 73886 | B9: BARRIO CALLE TOLEDO HISPANIA | C9: 1001144624 | D9: 3113503670 | E9: 3113503670 | F9: 3113503670 | G9: CALLE 50 TOLEDO 49 33,CALLE TOLEDO | H9: 5.7998727 | I9: -75.9067541 | J9: ANTIOQUIA | K9: HISPANIA | L9: HISPANIA | M9: 5353 | N9: 2025-11-12 | S9: =VLOOKUP(A9,Hoja1!A:B,2,0) -> 8 | T9: =VLOOKUP(M9,[1]TIPOLOGIAS!$A:$F,4,0) -> MEDELLIN | U9: =VLOOKUP(T9,'BASE TARIFA 2025'!C:D,2,0) -> WOMPI NOROCCIDENTE | V9: =VLOOKUP(T9,'BASE TARIFA 2025'!C:F,4,0) -> 15709.5
A10: 77395 | B10: BARRIO VILLA REPUBLICANA CHIQUINQUIRA | C10: 46680285 | D10: 3133329935 | E10: 3133329935 | F10: 3133329935 | G10: CL 19 17 A 02,VILLA REPUBLICANA | H10: 5.62386426 | I10: -73.81922155 | J10: BOYACÁ | K10: CHIQUINQUIRÁ | L10: CHIQUINQUIRÁ | M10: 15176 | N10: 2025-11-13 | S10: =VLOOKUP(A10,Hoja1!A:B,2,0) -> 8 | T10: =VLOOKUP(M10,[1]TIPOLOGIAS!$A:$F,4,0) -> TUNJA | U10: =VLOOKUP(T10,'BASE TARIFA 2025'!C:D,2,0) -> WOMPI SANTANDERES | V10: =VLOOKUP(T10,'BASE TARIFA 2025'!C:F,4,0) -> 28277.1
A11: 78515 | B11: BARRIO SAN CARLOS CHIQUINQUIRA 1 | C11: 1002522047 | D11: 3142740848 | E11: 3142740848 | F11: 3142740848 | G11: DG 28 7 02 ,SAN CARLOS | H11: 5.6239891 | I11: -73.8077324 | J11: BOYACÁ | K11: CHIQUINQUIRÁ | L11: CHIQUINQUIRÁ | M11: 15176 | N11: 2025-11-14 | S11: =VLOOKUP(A11,Hoja1!A:B,2,0) -> 8 | T11: =VLOOKUP(M11,[1]TIPOLOGIAS!$A:$F,4,0) -> TUNJA | U11: =VLOOKUP(T11,'BASE TARIFA 2025'!C:D,2,0) -> WOMPI SANTANDERES | V11: =VLOOKUP(T11,'BASE TARIFA 2025'!C:F,4,0) -> 28277.1
A12: 76795 | B12: BARRIO VEDERA SUCRE OCCIDENTAL CHIQUINQUIRA | C12: 7316213 | D12: 3152292734 | E12: 3152292734 | F12: 3152292734 | G12: VRD SUCRE OCCIDENTAL,KM 1 SUR VIA BOGOTÁ,VEDERA SUCRE OCCIDENTAL | H12: 5.59722349 | I12: -73.83546531 | J12: BOYACÁ | K12: CHIQUINQUIRÁ | L12: CHIQUINQUIRÁ | M12: 15176 | N12: 2025-11-14 | S12: =VLOOKUP(A12,Hoja1!A:B,2,0) -> 8 | T12: =VLOOKUP(M12,[1]TIPOLOGIAS!$A:$F,4,0) -> TUNJA | U12: =VLOOKUP(T12,'BASE TARIFA 2025'!C:D,2,0) -> WOMPI SANTANDERES | V12: =VLOOKUP(T12,'BASE TARIFA 2025'!C:F,4,0) -> 28277.1
A13: 77224 | B13: BARRIO CENTRO CHIQUINQUIRÁ | C13: 1053327379 | D13: 3142696302 | E13: 3142696302 | F13: 3142696302 | G13: CR 12 16 13 BALCONES DE SAN JOSE ,PISO 2, OFICINA 202,CENTRO | H13: 5.61791145 | I13: -73.81791619 | J13: BOYACÁ | K13: CHIQUINQUIRÁ | L13: CHIQUINQUIRÁ | M13: 15176 | N13: 2025-11-13 | S13: =VLOOKUP(A13,Hoja1!A:B,2,0) -> 8 | T13: =VLOOKUP(M13,[1]TIPOLOGIAS!$A:$F,4,0) -> TUNJA | U13: =VLOOKUP(T13,'BASE TARIFA 2025'!C:D,2,0) -> WOMPI SANTANDERES | V13: =VLOOKUP(T13,'BASE TARIFA 2025'!C:F,4,0) -> 28277.1
A14: 70922 | B14: BARRIO VEREDA SASA CHIQUINQUIRA | C14: 1053343081 | D14: 3108094994 | E14: 3108094994 | F14: 3108094994 | G14: VRD SASA, KILOMETRO 8 VIA TUNJA,VEREDA SASA | H14: 5.6118117 | I14: -73.7395567 | J14: BOYACÁ | K14: CHIQUINQUIRÁ | L14: CHIQUINQUIRÁ | M14: 15176 | N14: 2025-11-14 | S14: =VLOOKUP(A14,Hoja1!A:B,2,0) -> 8 | T14: =VLOOKUP(M14,[1]TIPOLOGIAS!$A:$F,4,0) -> TUNJA | U14: =VLOOKUP(T14,'BASE TARIFA 2025'!C:D,2,0) -> WOMPI SANTANDERES | V14: =VLOOKUP(T14,'BASE TARIFA 2025'!C:F,4,0) -> 28277.1
A15: 67789 | B15: PARQUE PRINCIPAL LA CEJA | C15: 1040049827 | D15: 3217235081 | E15: 3217235081 | F15: 3217235081 | G15: CL 13 AE 7 29 | H15: 6.0221272 | I15: -75.4225021 | J15: ANTIOQUIA | K15: LA CEJA | L15: LA CEJA | M15: 5376 | N15: 2025-11-19 | S15: =VLOOKUP(A15,Hoja1!A:B,2,0) -> 8 | T15: =VLOOKUP(M15,[1]TIPOLOGIAS!$A:$F,4,0) -> MEDELLIN | U15: =VLOOKUP(T15,'BASE TARIFA 2025'!C:D,2,0) -> WOMPI NOROCCIDENTE | V15: =VLOOKUP(T15,'BASE TARIFA 2025'!C:F,4,0) -> 15709.5
A16: 77118 | B16: BARRIO LA CEJA LA CEJA 9 | C16: 901314321 | D16: 3205880628 | E16: 3205880628 | F16: 3137013499 | G16: CL 20 17 A 08,LA CEJA | H16: 6.0305830 | I16: -75.4291404 | J16: ANTIOQUIA | K16: LA CEJA | L16: LA CEJA | M16: 5376 | N16: 2025-11-19 | S16: =VLOOKUP(A16,Hoja1!A:B,2,0) -> 8 | T16: =VLOOKUP(M16,[1]TIPOLOGIAS!$A:$F,4,0) -> MEDELLIN | U16: =VLOOKUP(T16,'BASE TARIFA 2025'!C:D,2,0) -> WOMPI NOROCCIDENTE | V16: =VLOOKUP(T16,'BASE TARIFA 2025'!C:F,4,0) -> 15709.5
A17: 76330 | B17: BARRIO CUIDAD JARDIN LA CEJA LA CEJA | C17: 71527195 | D17: 3024372762 | E17: 3024372762 | F17: 3122417335 | G17: CL 19 10 160 LC 29 | H17: 6.028166 | I17: -75.424026 | J17: ANTIOQUIA | K17: LA CEJA | L17: LA CEJA | M17: 5376 | N17: 2025-11-19 | S17: =VLOOKUP(A17,Hoja1!A:B,2,0) -> 8 | T17: =VLOOKUP(M17,[1]TIPOLOGIAS!$A:$F,4,0) -> MEDELLIN | U17: =VLOOKUP(T17,'BASE TARIFA 2025'!C:D,2,0) -> WOMPI NOROCCIDENTE | V17: =VLOOKUP(T17,'BASE TARIFA 2025'!C:F,4,0) -> 15709.5
... A20: 76146 | B20: BARRIO CALLE DEL COMERCIO NECHI | C20: 21646911 | D20: 3245668267 | E20: 3245668267 | F20: 3245668267 | G20: CALLE DEL COMERCIO BRR CALLE DEL COMERCIO,CALLE DEL COMERCIO | H20: 8.09571846 | I20: -74.7738059 | J20: ANTIOQUIA | K20: NECHÍ | L20: NECHÍ | M20: 5495 | N20: 2025-11-05 | S20: =VLOOKUP(A20,Hoja1!A:B,2,0) -> 8 | T20: =VLOOKUP(M20,[1]TIPOLOGIAS!$A:$F,4,0) -> MONTERIA | U20: =VLOOKUP(T20,'BASE TARIFA 2025'!C:D,2,0) -> WOMPI COSTA | V20: =VLOOKUP(T20,'BASE TARIFA 2025'!C:F,4,0) -> 15709.5
A21: 79812 | B21: BARRIO CENTRO NECHI 2 | C21: 1038484267 | D21: 3127995453 | E21: 3127995453 | G21: CR 28 31 37 ,CENTRO | H21: 8.0964269 | I21: -74.7738804 | J21: ANTIOQUIA | K21: NECHÍ | L21: NECHÍ | M21: 5495 | N21: 2025-11-05 | S21: =VLOOKUP(A21,Hoja1!A:B,2,0) -> 8 | T21: =VLOOKUP(M21,[1]TIPOLOGIAS!$A:$F,4,0) -> MONTERIA | U21: =VLOOKUP(T21,'BASE TARIFA 2025'!C:D,2,0) -> WOMPI COSTA | V21: =VLOOKUP(T21,'BASE TARIFA 2025'!C:F,4,0) -> 15709.5
A22: 36854 | B22: BARRIO PUERTO BERRIO ANTIOQUIA 1 | C22: 1039681777 | E22: 3015821687 | F22: 3015821687 | G22: COLEMMA ALTOS DE LA MALENA BG 1 BRR MALENA | H22: 6.4905367 | I22: -74.4179400 | J22: ANTIOQUIA | K22: PUERTO BERRÍO | L22: PUERTO BERRÍO | M22: 5579 | N22: 2025-11-06 | S22: =VLOOKUP(A22,Hoja1!A:B,2,0) -> 8 | T22: =VLOOKUP(M22,[1]TIPOLOGIAS!$A:$F,4,0) -> MEDELLIN | U22: =VLOOKUP(T22,'BASE TARIFA 2025'!C:D,2,0) -> WOMPI NOROCCIDENTE | V22: =VLOOKUP(T22,'BASE TARIFA 2025'!C:F,4,0) -> 15709.5
A23: 38484 | B23: BARRIO PLAZA DE MERCADO PUERTO BERRIO | C23: 22188241 | E23: 3017808975 | F23: 3147776504 | G23: CR 3 n 12 25 PLAZA DE MERCADO | H23: 6.4915707 | I23: -74.3997843 | J23: ANTIOQUIA | K23: PUERTO BERRÍO | L23: PUERTO BERRÍO | M23: 5579 | N23: 2025-11-06 | S23: =VLOOKUP(A23,Hoja1!A:B,2,0) -> 8 | T23: =VLOOKUP(M23,[1]TIPOLOGIAS!$A:$F,4,0) -> MEDELLIN | U23: =VLOOKUP(T23,'BASE TARIFA 2025'!C:D,2,0) -> WOMPI NOROCCIDENTE | V23: =VLOOKUP(T23,'BASE TARIFA 2025'!C:F,4,0) -> 15709.5
A24: 19841 | B24: BARRIO CENTRO ITAGUI | C24: 900356199 | D24: 3713515 | E24: 3104962846 | F24: 3104962846 | G24: CR 49 52 18 | H24: 6.1718655 | I24: -75.6075296 | J24: ANTIOQUIA | K24: ITAGÜÍ | L24: ITAGÜÍ | M24: 5360 | N24: 2025-11-20 | S24: =VLOOKUP(A24,Hoja1!A:B,2,0) -> 8 | T24: =VLOOKUP(M24,[1]TIPOLOGIAS!$A:$F,4,0) -> MEDELLIN | U24: =VLOOKUP(T24,'BASE TARIFA 2025'!C:D,2,0) -> WOMPI NOROCCIDENTE | V24: =VLOOKUP(T24,'BASE TARIFA 2025'!C:F,4,0) -> 15709.5
A25: 21690 | B25: BARRIO VILLA PAULA - ITAGUÍ | C25: 900393402 | D25: 2779804 | E25: 3218568106 | F25: 3218568106 | G25: CR 51 55 21 | H25: 6.174481 | I25: -75.606261 | J25: ANTIOQUIA | K25: ITAGÜÍ | L25: ITAGÜÍ | M25: 5360 | N25: 2025-11-05 | S25: =VLOOKUP(A25,Hoja1!A:B,2,0) -> 8 | T25: =VLOOKUP(M25,[1]TIPOLOGIAS!$A:$F,4,0) -> MEDELLIN | U25: =VLOOKUP(T25,'BASE TARIFA 2025'!C:D,2,0) -> WOMPI NOROCCIDENTE | V25: =VLOOKUP(T25,'BASE TARIFA 2025'!C:F,4,0) -> 15709.5
A26: 12172 | B26: BARRIO SANTA MARIA - ITAGUI | C26: 8162439 | D26: 3715196 | E26: 3113494477 | F26: 3113494477 | G26: CR 52 80-95 | H26: 6.1892231 | I26: -75.5934104 | J26: ANTIOQUIA | K26: ITAGÜÍ | L26: ITAGÜÍ | M26: 5360 | N26: 2025-11-20 | S26: =VLOOKUP(A26,Hoja1!A:B,2,0) -> 16 | T26: =VLOOKUP(M26,[1]TIPOLOGIAS!$A:$F,4,0) -> MEDELLIN | U26: =VLOOKUP(T26,'BASE TARIFA 2025'!C:D,2,0) -> WOMPI NOROCCIDENTE | V26: =VLOOKUP(T26,'BASE TARIFA 2025'!C:F,4,0) -> 15709.5
A27: 28499 | B27: BARRIO PARQUE PRINCIPAL 3 LA UNIÓN | C27: 900280884 | D27: 5688198 | E27: 3137052134 | F27: 3137052134 | G27: CR 09 9 73 | H27: 5.973093 | I27: -75.360755 | J27: ANTIOQUIA | K27: LA UNIÓN | L27: LA UNIÓN | M27: 5400 | N27: 2025-11-07 | S27: =VLOOKUP(A27,Hoja1!A:B,2,0) -> 16 | T27: =VLOOKUP(M27,[1]TIPOLOGIAS!$A:$F,4,0) -> MEDELLIN | U27: =VLOOKUP(T27,'BASE TARIFA 2025'!C:D,2,0) -> WOMPI NOROCCIDENTE | V27: =VLOOKUP(T27,'BASE TARIFA 2025'!C:F,4,0) -> 15709.5
A28: 40901 | B28: BARRIO CENTRO LA UNION 1 | C28: 1036779870 | E28: 3207609743 | F28: 3148595683 | G28: CR 11 NÚMERO 10-65,CENTRO | H28: 5.9734720 | I28: -75.3625684 | J28: ANTIOQUIA | K28: LA UNIÓN | L28: LA UNIÓN | M28: 5400 | N28: 2025-11-07 | S28: =VLOOKUP(A28,Hoja1!A:B,2,0) -> 8 | T28: =VLOOKUP(M28,[1]TIPOLOGIAS!$A:$F,4,0) -> MEDELLIN | U28: =VLOOKUP(T28,'BASE TARIFA 2025'!C:D,2,0) -> WOMPI NOROCCIDENTE | V28: =VLOOKUP(T28,'BASE TARIFA 2025'!C:F,4,0) -> 15709.5
A29: 79629 | B29: BARRIO EL EDEN LA UNION | C29: 1017155887 | D29: 3104455714 | E29: 3104455714 | F29: 3104455714 | G29: CR 8 9 31,EL EDEN | H29: 5.9731588 | I29: -75.3598665 | J29: ANTIOQUIA | K29: LA UNIÓN | L29: LA UNIÓN | M29: 5400 | N29: 2025-11-13 | S29: =VLOOKUP(A29,Hoja1!A:B,2,0) -> 8 | T29: =VLOOKUP(M29,[1]TIPOLOGIAS!$A:$F,4,0) -> MEDELLIN | U29: =VLOOKUP(T29,'BASE TARIFA 2025'!C:D,2,0) -> WOMPI NOROCCIDENTE | V29: =VLOOKUP(T29,'BASE TARIFA 2025'!C:F,4,0) -> 15709.5
A30: 69294 | B30: PARQUE PRINCIPAL LA UNION ANTIOQUIA | C30: 1040036655 | D30: 3148797221 | E30: 3148797221 | F30: 3148797221 | G30: CALLE 12 07 57,PARQUE PRINCIPAL | H30: 5.9753174 | I30: -75.3601249 | J30: ANTIOQUIA | K30: LA UNIÓN | L30: LA UNIÓN | M30: 5400 | N30: 2025-11-13 | S30: =VLOOKUP(A30,Hoja1!A:B,2,0) -> 8 | T30: =VLOOKUP(M30,[1]TIPOLOGIAS!$A:$F,4,0) -> MEDELLIN | U30: =VLOOKUP(T30,'BASE TARIFA 2025'!C:D,2,0) -> WOMPI NOROCCIDENTE | V30: =VLOOKUP(T30,'BASE TARIFA 2025'!C:F,4,0) -> 15709.5
A31: 72019 | B31: LA UNION HOSPITAL | C31: 1036782025 | D31: 3216642199 | E31: 3216642199 | F31: 3216642199 | G31: CL 12 NRO 11 09,HOSPITAL | H31: 5.9744872 | I31: -75.3629122 | J31: ANTIOQUIA | K31: LA UNIÓN | L31: LA UNIÓN | M31: 5400 | N31: 2025-11-07 | S31: =VLOOKUP(A31,Hoja1!A:B,2,0) -> 8 | T31: =VLOOKUP(M31,[1]TIPOLOGIAS!$A:$F,4,0) -> MEDELLIN | U31: =VLOOKUP(T31,'BASE TARIFA 2025'!C:D,2,0) -> WOMPI NOROCCIDENTE | V31: =VLOOKUP(T31,'BASE TARIFA 2025'!C:F,4,0) -> 15709.5
A32: 74952 | B32: BARRIO LA UNION LA UNION 4 | C32: 43473505 | D32: 3114204205 | E32: 3215534638 | F32: 3127102087 | G32: CR 10 11 64,LA UNION | H32: 5.9745060 | I32: -75.3619963 | J32: ANTIOQUIA | K32: LA UNIÓN | L32: LA UNIÓN | M32: 5400 | N32: 2025-11-07 | S32: =VLOOKUP(A32,Hoja1!A:B,2,0) -> 8 | T32: =VLOOKUP(M32,[1]TIPOLOGIAS!$A:$F,4,0) -> MEDELLIN | U32: =VLOOKUP(T32,'BASE TARIFA 2025'!C:D,2,0) -> WOMPI NOROCCIDENTE | V32: =VLOOKUP(T32,'BASE TARIFA 2025'!C:F,4,0) -> 15709.5
A33: 75932 | B33: BARRIO LA UNION LA UNION 5 | C33: 901711520 | D33: 0 | E33: 3104326808 | F33: 3007216779 | G33: CL 10 # 08 30 | H33: 5.9736987 | I33: -75.3602504 | J33: ANTIOQUIA | K33: LA UNIÓN | L33: LA UNIÓN | M33: 5400 | N33: 2025-11-13 | S33: =VLOOKUP(A33,Hoja1!A:B,2,0) -> 8 | T33: =VLOOKUP(M33,[1]TIPOLOGIAS!$A:$F,4,0) -> MEDELLIN | U33: =VLOOKUP(T33,'BASE TARIFA 2025'!C:D,2,0) -> WOMPI NOROCCIDENTE | V33: =VLOOKUP(T33,'BASE TARIFA 2025'!C:F,4,0) -> 15709.5
A34: 46089 | B34: BARRIO CENTRO LA UNION 2 | C34: 15355049 | E34: 3217672293 | F34: 3127587149 | G34: CL 7 10 - 02,CENTRO | H34: 5.9709510 | I34: -75.3607482 | J34: ANTIOQUIA | K34: LA UNIÓN | L34: LA UNIÓN | M34: 5400 | N34: 2025-11-13 | S34: =VLOOKUP(A34,Hoja1!A:B,2,0) -> 8 | T34: =VLOOKUP(M34,[1]TIPOLOGIAS!$A:$F,4,0) -> MEDELLIN | U34: =VLOOKUP(T34,'BASE TARIFA 2025'!C:D,2,0) -> WOMPI NOROCCIDENTE | V34: =VLOOKUP(T34,'BASE TARIFA 2025'!C:F,4,0) -> 15709.5
A35: 49305 | B35: BARRIO CENTRO LA UNION 3 | C35: 43862122 | D35: 0 | E35: 3185582078 | F35: 3185582078 | G35: CR 8 11 04 | H35: 5.974612 | I35: -75.360146 | J35: ANTIOQUIA | K35: LA UNIÓN | L35: LA UNIÓN | M35: 5400 | N35: 2025-11-13 | S35: =VLOOKUP(A35,Hoja1!A:B,2,0) -> 8 | T35: =VLOOKUP(M35,[1]TIPOLOGIAS!$A:$F,4,0) -> MEDELLIN | U35: =VLOOKUP(T35,'BASE TARIFA 2025'!C:D,2,0) -> WOMPI NOROCCIDENTE | V35: =VLOOKUP(T35,'BASE TARIFA 2025'!C:F,4,0) -> 15709.5
A36: 69014 | B36: BARRIO LATIN FLOWERS FARMS | C36: 900111576 | D36: 3136607428 | E36: 0 | F36: 3136607428 | G36: CL 12 12 68,SECTOR EL HOSPITAL | H36: 5.9741124 | I36: -75.3642466 | J36: ANTIOQUIA | K36: LA UNIÓN | L36: LA UNIÓN | M36: 5400 | N36: 2025-11-07 | S36: =VLOOKUP(A36,Hoja1!A:B,2,0) -> 8 | T36: =VLOOKUP(M36,[1]TIPOLOGIAS!$A:$F,4,0) -> MEDELLIN | U36: =VLOOKUP(T36,'BASE TARIFA 2025'!C:D,2,0) -> WOMPI NOROCCIDENTE | V36: =VLOOKUP(T36,'BASE TARIFA 2025'!C:F,4,0) -> 15709.5
A37: 78803 | B37: BARRIO VEREDA QUIRBAQUIRA ARCABUCO 1 | C37: 1095822577 | D37: 3163088919 | E37: 3163088919 | G37: VRD QUIRBAQUIRA, SECTOR CASA BLANCA,VEREDA QUIRBAQUIRA | H37: 5.6912697 | I37: -73.3675628 | J37: BOYACÁ | K37: ARCABUCO | L37: ARCABUCO | M37: 15051 | N37: 2025-11-05 | S37: =VLOOKUP(A37,Hoja1!A:B,2,0) -> 8 | T37: =VLOOKUP(M37,[1]TIPOLOGIAS!$A:$F,4,0) -> TUNJA | U37: =VLOOKUP(T37,'BASE TARIFA 2025'!C:D,2,0) -> WOMPI SANTANDERES | V37: =VLOOKUP(T37,'BASE TARIFA 2025'!C:F,4,0) -> 28277.1
A38: 47103 | B38: BARRIO CENTRO BOYACA 1 | C38: 7179742 | D38: 3165362959 | E38: 3165362959 | F38: 3165362959 | G38: Carrera 5 # 3 - 31 Centro | H38: 5.454 | I38: -73.362 | J38: BOYACÁ | K38: BOYACÁ | L38: BOYACÁ | M38: 15104 | N38: 2025-11-13 | S38: =VLOOKUP(A38,Hoja1!A:B,2,0) -> 8 | T38: =VLOOKUP(M38,[1]TIPOLOGIAS!$A:$F,4,0) -> TUNJA | U38: =VLOOKUP(T38,'BASE TARIFA 2025'!C:D,2,0) -> WOMPI SANTANDERES | V38: =VLOOKUP(T38,'BASE TARIFA 2025'!C:F,4,0) -> 28277.1
A39: 65463 | B39: BARRIO CENTRO BOYACA 4 | C39: 1050170897 | D39: 3144233419 | E39: 3144233419 | F39: 3144233419 | G39: CR 4 A 3 85,CENTRO | H39: 5.4538173 | I39: -73.3630605 | J39: BOYACÁ | K39: BOYACÁ | L39: BOYACÁ | M39: 15104 | N39: 2025-11-13 | S39: =VLOOKUP(A39,Hoja1!A:B,2,0) -> 8 | T39: =VLOOKUP(M39,[1]TIPOLOGIAS!$A:$F,4,0) -> TUNJA | U39: =VLOOKUP(T39,'BASE TARIFA 2025'!C:D,2,0) -> WOMPI SANTANDERES | V39: =VLOOKUP(T39,'BASE TARIFA 2025'!C:F,4,0) -> 28277.1
A40: 70551 | B40: BARRIO BOYACA BAJO CHIQUINQUIRA 3 | C40: 1053344552 | D40: 3225201619 | E40: 3225201619 | F40: 3225201619 | G40: CR 9 A 3 9,BOYACA BAJO | H40: 5.61052869 | I40: -73.82480853 | J40: BOYACÁ | K40: CHIQUINQUIRÁ | L40: CHIQUINQUIRÁ | M40: 15176 | N40: 2025-11-14 | S40: =VLOOKUP(A40,Hoja1!A:B,2,0) -> 8 | T40: =VLOOKUP(M40,[1]TIPOLOGIAS!$A:$F,4,0) -> TUNJA | U40: =VLOOKUP(T40,'BASE TARIFA 2025'!C:D,2,0) -> WOMPI SANTANDERES | V40: =VLOOKUP(T40,'BASE TARIFA 2025'!C:F,4,0) -> 28277.1
A41: 49763 | B41: BARRIO PUERTO BERRIO PUERTO BERRIO | C41: 901175583 | D41: 0 | E41: 3103830426 | F41: 3103830426 | G41: CL 42 A NR0. 8 -6 BRR LLERAS | H41: 6.4860518 | I41: -74.4055606 | J41: ANTIOQUIA | K41: PUERTO BERRÍO | L41: PUERTO BERRÍO | M41: 5579 | N41: 2025-11-06 | S41: =VLOOKUP(A41,Hoja1!A:B,2,0) -> 16 | T41: =VLOOKUP(M41,[1]TIPOLOGIAS!$A:$F,4,0) -> MEDELLIN | U41: =VLOOKUP(T41,'BASE TARIFA 2025'!C:D,2,0) -> WOMPI NOROCCIDENTE | V41: =VLOOKUP(T41,'BASE TARIFA 2025'!C:F,4,0) -> 15709.5
A42: 45977 | B42: BARRIO LA MARGARITA PUERTO BERRIO 1 | C42: 42960789 | D42: 8330068 | E42: 3016209379 | F42: 3016209379 | G42: VRD LA MARGARITA,LA MARGARITA | H42: 6.495189 | I42: -74.474370 | J42: ANTIOQUIA | K42: PUERTO BERRÍO | L42: PUERTO BERRÍO | M42: 5579 | N42: 2025-11-06 | S42: =VLOOKUP(A42,Hoja1!A:B,2,0) -> 8 | T42: =VLOOKUP(M42,[1]TIPOLOGIAS!$A:$F,4,0) -> MEDELLIN | U42: =VLOOKUP(T42,'BASE TARIFA 2025'!C:D,2,0) -> WOMPI NOROCCIDENTE | V42: =VLOOKUP(T42,'BASE TARIFA 2025'!C:F,4,0) -> 15709.5
...
