Workbook
Name A: #REF!
Name ACTIVIDAD: [1]Hoja2!$P$2:$P$30
Name Actividad: [2]Formulas!$H$2:$H$5000
Name arearesponsable: '[3]Listas desplegables'!$BB$2:$BB$100
Name Clientes: [4]Clientes!$A$2:$A$100
Name Clientes: [2]Clientes!$A$2:$A$100
Name COORDINADOR: [1]Hoja2!$D$2:$D$30
Name Coordinadores: [5]Coordinadores!$A$2:$A$1000
Name Coordinadores: [2]Coordinadores!$A$2:$A$1000
Name DOCUMENTADOR: [1]Hoja2!$A$2:$A$30
Name ES: [1]Hoja2!$K$2:$K$30
Name ESS: [1]Hoja2!$K$2:$K$30
Name Estado: [4]Formulas!$K$2:$K$5000
Name Estado: [2]Formulas!$K$2:$K$5000
Name ESTADOACTIVIDAD: [1]Hoja2!$M$2:$M$30
Name ESTADOS: '[6]Listas desplegables'!$B$1:$D$1
Name ESTADOSCIERRES: '[7]lista desplegable'!$CX$1:$DA$1
Name Facturacion: '[8]Listas desplegables'!$AO$1:$AR$1
Name FACTURACIÓN: '[6]Listas desplegables'!$Y$1:$AB$1
Name falla: #REF!
Name Fallas: '[9]Listas desplegables'!$F$2:$L$2
Name Grupo_Falla: '[10]Listas Desplegables'!$CH$2:$CH$5
Name inconservmanager: '[11]Listas desplegables'!$BC$2:$BC$100
Name INCUMPLIMIENTO: '[3]Listas desplegables'!$AK$1:$AN$1
Name LISTA: [12]Dptos!$A$1139:$A$1171
Name LISTA2: #REF!
Name LOLO: [13]Coordinadores!$A$2:$A$1000
Name solicitudes: '[8]Listas desplegables'!$U$1:$AF$1
Name solicitudes: '[14]Listas desplegables'!$AF$1:$AQ$1
Name Tecnicos: [4]Tecnicos!$A$2:$A$1000
Name Tecnicos: [2]Tecnicos!$A$2:$A$1000
Name Version: [2]Formulas!$I$2:$I$3

Sheet RESUMEN
A1: LÍNEA COMUNICACIONES S.A.S | F1: FACTURACIÓN CORRESPONSALES BANCARIOS TIQUIETES AEREOS
A2: FACTURACIÓN PROYECTO CB BANCOLOMBIA | F2: =A3 -> 45930
A3: 45930
F4: CONCEPTOS | G4: TRAYECTOS | H4: TOTAL | I4: % Administración | J4: TOTAL
A5: CONCEPTOS | B5: CANTIDAD | C5: VALOR UNITARIO | D5: VALOR TOTAL | I5: =H5*0.12 -> 0 | J5: =H5+I5 -> 0
A6: Adecuaciones CB | B6: =COUNTA(ADECUACIONES!A:A)-1 -> 10 | C6: 0 | D6: =ADECUACIONES!AE12 -> 1511089.2 | I6: =H6*0.12 -> 0 | J6: =H6+I6 -> 0
A7: Incidentes | B7: =COUNTA(INCIDENTES!A:A)-1 -> 210 | C7: 0 | D7: =INCIDENTES!AG212 -> 20457074 | I7: =H7*0.12 -> 0 | J7: =H7+I7 -> 0
A8: Ordenes de Cambio | B8: =COUNTA(OC!A:A)-1 -> 12 | C8: 0 | D8: =OC!AG14 -> 1484720.1 | I8: =H8*0.12 -> 0 | J8: =H8+I8 -> 0
A9: Tiquetes | B9: 0 | C9: 0 | D9: =J12 -> 0 | I9: =H9*0.12 -> 0 | J9: =H9+I9 -> 0
A10: SUBTOTAL | D10: =SUM(D6:D9) -> 23452883 | I10: =H10*0.12 -> 0 | J10: =H10+I10 -> 0
A11: Iva | D11: =D10*0.19 -> 4456047.8 | I11: =H11*0.12 -> 0 | J11: =H11+I11 -> 0
A12: TOTAL | D12: =D10+D11 -> 27908931 | F12: TOTAL | H12: =SUM(H5:H11) -> 0 | I12: =SUM(I5:I11) -> 0 | J12: =SUM(J5:J11) -> 0

Sheet Tablas dinámicas
A2: ADECUACIONES | J2: NOMBRE CC | K2: Suma de VALOR | L2: Suma de VALOR2
A3: COORDINADOR | B3: CENTRO DE COSTOS LÍNEACOM | C3: % | D3: $ | E3: NOMBRE CC | F3: VALOR | J3: Redeban Centro ( Bogotá) | K3: 1736974.8 | L3: 0.074062314
A4: DIEGO FERNANDO HENAO CARDONA | B4: 0004-0003 | C4: 0.17789869 | D4: 268820.78 | E4: =VLOOKUP(B4,'CENTRO DE COSTOS'!B:C,2,0) -> Redeban Suroccidente (Cali) | F4: =D4 -> 268820.78 | J4: Redeban Costa (Barranqullla) | K4: 2900584.4 | L4: 0.12367709
A5: JUAN SEBASTIÁN RÍOS CASTRILLÓN | B5: 0004-0005 | C5: 0.39654802 | D5: 599219.42 | E5: =VLOOKUP(B5,'CENTRO DE COSTOS'!B:C,2,0) -> Redeban Noroccidente (Medellín) | F5: =D5 -> 599219.42 | J5: Redeban Eje Cafetero (Pereira) | K5: 817097.79 | L5: 0.034839972
A6: KEVIN ALEXIS CORZO BUSTOS | B6: 0004-0007 | C6: 0.33708733 | D6: 509369.02 | E6: =VLOOKUP(B6,'CENTRO DE COSTOS'!B:C,2,0) -> Redeban Oriente (Otros) | F6: =D6 -> 509369.02 | J6: Redeban Noroccidente (Medellín) | K6: 5435677.2 | L6: 0.2317701
A7: MIGUEL JULIÁN HERNÁNDEZ GUARÍN | B7: 0004-0008 | C7: 0.058977307 | D7: 89119.97 | E7: =VLOOKUP(B7,'CENTRO DE COSTOS'!B:C,2,0) -> Redeban Santander | F7: =D7 -> 89119.97 | J7: Redeban Oriente (Otros) | K7: 4631207.7 | L7: 0.19746859
A8: WILLIAM ASDRUBAL ROZO ROZO | B8: 0004-0004 | C8: 0.029488653 | D8: 44559.985 | E8: =VLOOKUP(B8,'CENTRO DE COSTOS'!B:C,2,0) -> Redeban Centro ( Bogotá) | F8: =D8 -> 44559.985 | J8: Redeban Santander | K8: 5165648.9 | L8: 0.22025646
A9: Total general | C9: 1 | D9: 1511089.2 | F9: =D9 -> 1511089.2 | J9: Redeban Suroccidente (Cali) | K9: 2765692.4 | L9: 0.11792548
E10: =VLOOKUP(B10,'CENTRO DE COSTOS'!B:C,2,0) -> #N/A | F10: =D10 -> 0 | J10: Total general | K10: 23452883 | L10: 1
A15: INCIDENTES
A16: COORDINADOR | B16: CENTRO DE COSTOS LÍNEACOM | C16: % | D16: $ | E16: NOMBRE CC
A17: DIEGO FERNANDO HENAO CARDONA | B17: 0004-0002 | C17: 0.039942066 | D17: 817097.79 | E17: =VLOOKUP(B17,'CENTRO DE COSTOS'!B:C,2,0) -> Redeban Eje Cafetero (Pereira) | F17: =D17 -> 817097.79
B18: 0004-0003 | C18: 0.11882986 | D18: 2430911.1 | E18: =VLOOKUP(B18,'CENTRO DE COSTOS'!B:C,2,0) -> Redeban Suroccidente (Cali) | F18: =D18 -> 2430911.1
A19: JOSE MAURICIO HERNANDEZ ROJAS | B19: 0004-0001 | C19: 0.13856449 | D19: 2834623.9 | E19: =VLOOKUP(B19,'CENTRO DE COSTOS'!B:C,2,0) -> Redeban Costa (Barranqullla) | F19: =D19 -> 2834623.9
A20: JUAN SEBASTIÁN RÍOS CASTRILLÓN | B20: 0004-0005 | C20: 0.22196348 | D20: 4540723.2 | E20: =VLOOKUP(B20,'CENTRO DE COSTOS'!B:C,2,0) -> Redeban Noroccidente (Medellín) | F20: =D20 -> 4540723.2
A21: KEVIN ALEXIS CORZO BUSTOS | B21: 0004-0007 | C21: 0.17970726 | D21: 3676284.7 | E21: =VLOOKUP(B21,'CENTRO DE COSTOS'!B:C,2,0) -> Redeban Oriente (Otros) | F21: =D21 -> 3676284.7
A22: MIGUEL JULIÁN HERNÁNDEZ GUARÍN | B22: 0004-0008 | C22: 0.22471147 | D22: 4596939.2 | E22: =VLOOKUP(B22,'CENTRO DE COSTOS'!B:C,2,0) -> Redeban Santander | F22: =D22 -> 4596939.2
A23: WILLIAM ASDRUBAL ROZO ROZO | B23: 0004-0004 | C23: 0.076281382 | D23: 1560493.9 | E23: =VLOOKUP(B23,'CENTRO DE COSTOS'!B:C,2,0) -> Redeban Centro ( Bogotá) | F23: =D23 -> 1560493.9
A24: Total general | C24: 1 | D24: 20457074
A29: OC
A30: COORDINADOR | B30: CENTRO DE COSTOS LÍNEACOM | C30: % | D30: $ | E30: NOMBRE CC
A31: DIEGO FERNANDO HENAO CARDONA | B31: 0004-0003 | C31: 0.044426201 | D31: 65960.474 | E31: =VLOOKUP(B31,'CENTRO DE COSTOS'!B:C,2,0) -> Redeban Suroccidente (Cali) | F31: =D31 -> 65960.474
A32: JOSE MAURICIO HERNANDEZ ROJAS | B32: 0004-0001 | C32: 0.044426201 | D32: 65960.474 | E32: =VLOOKUP(B32,'CENTRO DE COSTOS'!B:C,2,0) -> Redeban Costa (Barranqullla) | F32: =D32 -> 65960.474
A33: JUAN SEBASTIÁN RÍOS CASTRILLÓN | B33: 0004-0005 | C33: 0.19918536 | D33: 295734.51 | E33: =VLOOKUP(B33,'CENTRO DE COSTOS'!B:C,2,0) -> Redeban Noroccidente (Medellín) | F33: =D33 -> 295734.51
A34: KEVIN ALEXIS CORZO BUSTOS | B34: 0004-0007 | C34: 0.30009291 | D34: 445553.98 | E34: =VLOOKUP(B34,'CENTRO DE COSTOS'!B:C,2,0) -> Redeban Oriente (Otros) | F34: =D34 -> 445553.98
A35: MIGUEL JULIÁN HERNÁNDEZ GUARÍN | B35: 0004-0008 | C35: 0.32301693 | D35: 479589.74 | E35: =VLOOKUP(B35,'CENTRO DE COSTOS'!B:C,2,0) -> Redeban Santander | F35: =D35 -> 479589.74
A36: WILLIAM ASDRUBAL ROZO ROZO | B36: 0004-0004 | C36: 0.088852401 | D36: 131920.95 | E36: =VLOOKUP(B36,'CENTRO DE COSTOS'!B:C,2,0) -> Redeban Centro ( Bogotá) | F36: =D36 -> 131920.95
A37: Total general | C37: 1 | D37: 1484720.1

Sheet BASE LIQUIDACION
A1: TARIFAS 2025 | E1: Incremento 2025
A2: Tipificación | B2: Descripción | C2: Dia actividad Exitosa | D2: Dia actividad Fallida | E2: 0.052
A3: Tipo I | B3: Metropolitano | C3: =62700.07*(1+$E$2) -> 65960.474 | D3: =42357.4*(1+$E$2) -> 44559.985
A4: Tipo II | B4: Hasta 3 horas | C4: =155716.31*(1+$E$2) -> 163813.56 | D4: =127766.53*(1+$E$2) -> 134410.39
A5: Tipo III | B5: De 3 a 5 horas | C5: =262099.22*(1+$E$2) -> 275728.38 | D5: =211886.19*(1+$E$2) -> 222904.27
A6: Tipo IV | B6: Más de 5 horas | C6: =455883.78*(1+$E$2) -> 479589.74 | D6: =441833.68*(1+$E$2) -> 464809.03
A7: Destino aereo | B7: No incluye valor del Tiquete | C7: =455883.78*(1+$E$2) -> 479589.74 | D7: =441833.68*(1+$E$2) -> 464809.03
A8: *Donde se requiera transporte aéreo o fluvial se factura adicional a tarifa TIPO IV el valor del tiquete + el 12% de admon.
A10: Gestión Telefónica | B10: =36031.04*(1+$E$2) -> 37904.654
A11: Mts Acometida electrica | B11: =30182.1*(1+$E$2) -> 31751.569
A12: Mts Acometida datos | B12: =15432.22*(1+$E$2) -> 16234.695
A13: switche | B13: =244669.03*(1+$E$2) -> 257391.82
A14: Router | B14: =291399.51*(1+$E$2) -> 306552.28
A15: Envio operador Logistico | B15: =53547.34*(1+$E$2) -> 56331.802

Sheet ADECUACIONES
A1: CIUDAD SEDE | B1: COORDINADOR | C1: CENTRO DE COSTOS LÍNEACOM | D1: CÓDIGO DANE | E1: TA/CODIGO ACTIVIDAD | F1: CODIGO CB | G1: ACTIVIDAD | H1: TIPO DE APERTURA | I1: DEPARTAMENTO | J1: CIUDAD | K1: NOMBRE DEL CB | L1: RED | M1: FO | N1: FECHA LISTA | O1: FECHA ULTIMA ACTUALIZACION | P1: FORMATO | Q1: CADENA | R1: ESTADO | S1: OBSERVACIONES CLIENTE | T1: FORMA DE ATENCIÓN | U1: TERMINALES | V1: TIPIFICACION | W1: TIPO DE TRAYECTO | X1: NOMBRE DEL TECNICO | Y1: ACOMETIDA DATOS | Z1: ACOMETIDA ELECTRICA | AA1: SWITCH | AB1: ROUTER | AC1: VALOR DIAS ACTIVIDAD FACTURABLES | AD1: DIAS ACTIVIDAD FACTURABLES | AE1: VALOR TOTAL INSTALACION DE PUBLICIDAD
A2: CIUDAD SEDE | B2: COORDINADOR | C2: CENTRO DE COSTOS LINEACOM | D2: CODIGO DANE | E2: TA/CODIGO ACTIVIDAD | F2: CODIGO CB | G2: ACTIVIDAD | H2: TIPO DE APERTURA | I2: DEPARTAMENTO | J2: CIUDAD | K2: NOMBRE DEL CB | L2: RED | M2: FO | P2: FORMATO | Q2: CADENA | R2: ESTADO | S2: OBSERVACIONES CLIENTE | T2: FORMA DE ATENCION | V2: TIPIFICACION | W2: TIPO DE TRAYECTO | X2: NOMBRE DEL TECNICO | Y2: ACOMETIDA DATOS | Z2: ACOMETIDA ELECTRICA | AA2: SWITCH | AB2: ROUTER | AC2: VALOR DIAS ACTIVIDAD FACTURABLES | AD2: DIAS ACTIVIDAD FACTURABLES | AE2: VALOR TOTAL INSTALACION DE PUBLICIDAD
A3: PASTO | B3: =VLOOKUP(A3,'CENTRO DE COSTOS'!A:D,4,FALSE) -> DIEGO FERNANDO HENAO CARDONA | C3: =VLOOKUP(A3,'CENTRO DE COSTOS'!A:C,2,FALSE) -> 0004-0003 | D3: 52687 | E3: TA-25-1034011 | F3: 81249 | G3: APERTURA | H3: CB CRECIMIENTO - NUEVO | I3: NARIÑO | J3: SAN LORENZO | K3: BARRIO EL CENTRO SAN LORENZO | L3: REDEBAN | M3: FO-25-1433131 | N3: 45896 | O3: 45903 | P3: UNO A UNO | Q3: UNO A UNO | R3: EJECUTADO/CANCELADO | S3: 27-08-2025 SE REALIZA LLAMADA AL CLIENTE, SE HABLA CON EL SR HECTOR ROSENDO ESPAÑA RODRIGUEZ SE VALIDA DIRECCIÓN OK, CANAL OK, DISPONIBILIDAD TOTAL, LLAMAR EL DÍA LA INSTALACIÓN PARA CONFIRMAR VISITA, AVISO EXTERIOR ALTURA APROX 3 METROS; TOMACORRIENTE CERCANO: SI; TIENE CABINA DE SEGURIDAD: NO 28-09 SE REALIZÓ COMUNICACIÓN TELEFÓNICA CON USUARIO E INFORMA QUE DEBIDO A CELEBRACIÓN DE FIESTAS EN EL MUNICIPIO ES COMPLICADO EL TRANSPORTE Y LA ATENCIÓN DE LA VISITA. SOLICITA QUE ESTA SEA REALIZADA EN LA SIGUIENTE SEMANA CUANDO YA SE HAYA NORMALIZADO TODO. 3/09/2025 SE VISITA EL COMERCIO PARA REALIZAR APERTURA PERO NO ES POSIBLE YA QUE EN EL COMERCIO FUNCIONA CORRESPONSAL DE BANCO AGRARIO POR LO QUE NO SE APERTURA YA QUE SE ESTARÍA VIOLANDO PRINCIPIO DE EXCLUSIVIDAD DE BANCOLOMBIA. | T3: VISITA _TECNICA | U3: FKZZZ662 | V3: TIPO II | W3: TERRESTRE | X3: GUERRERO RAMIREZ OSCAR DARIO | Y3: 0 | Z3: 0 | AA3: 0 | AB3: 0 | AC3: 1 | AD3: =IF(V3="TIPO I",'BASE LIQUIDACION'!$D$3,IF(V3="TIPO II",'BASE LIQUIDACION'!$D$4,IF(V3="TIPO III",'BASE LIQUIDACION'!$D$5,'BASE LIQUIDACION'!$D$7))) -> 134410.39 | AE3: =Y3*'BASE LIQUIDACION'!$B$12+Z3*'BASE LIQUIDACION'!$B$11+AA3*'BASE LIQUIDACION'!$B$13+AB3*'BASE LIQUIDACION'!$B$14+AC3*AD3 -> 134410.39
A4: NEIVA | B4: =VLOOKUP(A4,'CENTRO DE COSTOS'!A:D,4,FALSE) -> KEVIN ALEXIS CORZO BUSTOS | C4: =VLOOKUP(A4,'CENTRO DE COSTOS'!A:C,2,FALSE) -> 0004-0007 | D4: 18753 | E4: TA-25-1034461 | F4: 81230 | G4: APERTURA | H4: CB CRECIMIENTO ALIANZA - NUEVO | I4: CAQUETA | J4: SAN VICENTE DEL CAGUAN | K4: DISTRICOL SURTICELL EMILY | L4: REDEBAN | M4: FO-25-1433896 | N4: 45896 | O4: 45905 | P4: AGREGADOR | Q4: DISTRICOL | R4: EJECUTADO/CANCELADO | S4: 27-08 PROGRAMACIÓN REALIZADA POR LA ALIANZA 5/09/2025 SE REALIZA VISITA PARA IMPLEMENTACIÓN CB DISTRICOL 81230, PERO SE EVIDENCIA QUE APROXIMADAMENTE A 40MTS HAY UN CB AGREGADOR PTM SAN VICENTE DEL CAGUAN 50792, POR FAVOR NOS INDICA COMO PROCEDER. / ENTIDAD SOLICITA CANCELAR ACTIVIDAD | T4: VISITA _TECNICA | U4: FKZZZ688 | V4: TIPO IV ESPECIAL | W4: TERRESTRE / AEREO | X4: BERMUDEZ SANCHEZ JOSE NEYBER | Y4: 0 | Z4: 0 | AA4: 0 | AB4: 0 | AC4: 1 | AD4: =IF(V4="TIPO I",'BASE LIQUIDACION'!$D$3,IF(V4="TIPO II",'BASE LIQUIDACION'!$D$4,IF(V4="TIPO III",'BASE LIQUIDACION'!$D$5,'BASE LIQUIDACION'!$D$7))) -> 464809.03 | AE4: =Y4*'BASE LIQUIDACION'!$B$12+Z4*'BASE LIQUIDACION'!$B$11+AA4*'BASE LIQUIDACION'!$B$13+AB4*'BASE LIQUIDACION'!$B$14+AC4*AD4 -> 464809.03
A5: TUNJA | B5: =VLOOKUP(A5,'CENTRO DE COSTOS'!A:D,4,FALSE) -> MIGUEL JULIÁN HERNÁNDEZ GUARÍN | C5: =VLOOKUP(A5,'CENTRO DE COSTOS'!A:C,2,FALSE) -> 0004-0008 | D5: 15001 | E5: TA-25-1040108 | F5: 81267 | G5: APERTURA | H5: CB CRECIMIENTO ALIANZA - NUEVO | I5: BOYACA | J5: TUNJA | K5: DISTRICOL TIENDA KEVINS | L5: REDEBAN | M5: FO-25-1444565 | N5: 45898 | O5: 45901 | P5: AGREGADOR | Q5: DISTRICOL | R5: EJECUTADO/CANCELADO | S5: 29-08 PROGRAMACIÓN REALIZADA POR LA ALIANZA 1/09/2025 SE ESCALA NOVEDAD DE IMPLEMENTACIÓN. SE IDENTIFICA EL PUNTO DE CORRESPONSAL CON AVAL 90117612. SE PROCEDE A CANCELAR EL PUNTO DE INSTALACIÓN. | T5: VISITA _TECNICA | U5: SKZZZ569 | V5: TIPO I | W5: TERRESTRE | X5: SOLER HOYOS CRISTIAN LEONARDO | Y5: 0 | Z5: 0 | AA5: 0 | AB5: 0 | AC5: 1 | AD5: =IF(V5="TIPO I",'BASE LIQUIDACION'!$D$3,IF(V5="TIPO II",'BASE LIQUIDACION'!$D$4,IF(V5="TIPO III",'BASE LIQUIDACION'!$D$5,'BASE LIQUIDACION'!$D$7))) -> 44559.985 | AE5: =Y5*'BASE LIQUIDACION'!$B$12+Z5*'BASE LIQUIDACION'!$B$11+AA5*'BASE LIQUIDACION'!$B$13+AB5*'BASE LIQUIDACION'!$B$14+AC5*AD5 -> 44559.985
A6: BUCARAMANGA | B6: =VLOOKUP(A6,'CENTRO DE COSTOS'!A:D,4,FALSE) -> MIGUEL JULIÁN HERNÁNDEZ GUARÍN | C6: =VLOOKUP(A6,'CENTRO DE COSTOS'!A:C,2,FALSE) -> 0004-0008 | D6: 68307 | E6: TA-25-1054855 | F6: 81327 | G6: APERTURA | H6: CB CRECIMIENTO ALIANZA - NUEVO | I6: SANTANDER | J6: GIRON | K6: PTM GIRON MULTISERVICIOS LOS C | L6: REDEBAN | M6: FO-25-1467930 | N6: 45903 | O6: 45904 | P6: AGREGADOR | Q6: COMCARD - PTM | R6: EJECUTADO/CANCELADO | S6: 03-09 PROGRAMACIÓN REALIZADA POR LA ALIANZA4/09/2025 NOS PERMITIMOS INFORMARLE QUE, TRAS REALIZAR LA RESPECTIVA VERIFICACIÓN EN CAMPO, IDENTIFICAMOS QUE EL PUNTO A INSTALAR EN LA DIRECCIÓN CRA 19A NO 25-11 LC 1, BARRIO VILLA CAMPESTRE 1 (CÓDIGO 81327), SE ENCUENTRA A UNA DISTANCIA APROXIMADA DE 50 METROS DEL PUNTO YA INSTALADO EN LA DIRECCIÓN CAR 21 #22-124, VILLA CAMPESTRE 3ª ETAPA (CÓDIGO 77310). TENIENDO EN CUENTA LA CERCANÍA ENTRE AMBOS PUNTOS, SOLICITAMOS SU AUTORIZACIÓN PARA PROCEDER CON LA IMPLEMENTACIÓN EN LA DIRECCIÓN MENCIONADA, GARANTIZANDO QUE SE PARÁMETROS TÉCNICOS Y OPERATIVOS ESTABLECIDOS. / ENTIDAD SOLICITAN CANCELAR INSTALACIÓN | T6: VISITA _TECNICA | U6: SMZZZ288 | V6: TIPO I | W6: TERRESTRE | X6: SANTOS GONZALEZ JOHAN FABIAN | Y6: 0 | Z6: 0 | AA6: 0 | AB6: 0 | AC6: 1 | AD6: =IF(V6="TIPO I",'BASE LIQUIDACION'!$D$3,IF(V6="TIPO II",'BASE LIQUIDACION'!$D$4,IF(V6="TIPO III",'BASE LIQUIDACION'!$D$5,'BASE LIQUIDACION'!$D$7))) -> 44559.985 | AE6: =Y6*'BASE LIQUIDACION'!$B$12+Z6*'BASE LIQUIDACION'!$B$11+AA6*'BASE LIQUIDACION'!$B$13+AB6*'BASE LIQUIDACION'!$B$14+AC6*AD6 -> 44559.985
A7: APARTADO | B7: =VLOOKUP(A7,'CENTRO DE COSTOS'!A:D,4,FALSE) -> JUAN SEBASTIÁN RÍOS CASTRILLÓN | C7: =VLOOKUP(A7,'CENTRO DE COSTOS'!A:C,2,FALSE) -> 0004-0005 | D7: 5837 | E7: TA-25-1117897 | F7: 81501 | G7: APERTURA | H7: CB CRECIMIENTO ALIANZA - NUEVO | I7: ANTIOQUIA | J7: TURBO | K7: DISTRICOL TIENDA GINES ROPA Y ACCESORIOS | L7: REDEBAN | M7: FO-25-1543491 | N7: 45917 | O7: 45919 | P7: AGREGADOR | Q7: DISTRICOL | R7: EJECUTADO/CANCELADO | S7: 17-09 PROGRAMACIÓN REALIZADA POR LA ALIANZA 19/09/2025 VISITAMOS DIRECCIÓN RELACIONADA EN CUADRO ENCONTRANDO QUE NO HAY COMERCIO EN ESTA. SEGÚN VALIDACIONES DE PERSONAL TÉCNICO EL COMERCIO ESTÁ UBICADO REALMENTE EN DIRECCIÓN CARRERA 30 # 22-30 COMO MUESTRA UN RECIBO DE SERVICIOS PÚBLICOS. | T7: VISITA _TECNICA | U7: FSZZZ877 | V7: TIPO II | W7: TERRESTRE | X7: CASTRO HENAO DANIEL ESTEBAN | Y7: 0 | Z7: 0 | AA7: 0 | AB7: 0 | AC7: 1 | AD7: =IF(V7="TIPO I",'BASE LIQUIDACION'!$D$3,IF(V7="TIPO II",'BASE LIQUIDACION'!$D$4,IF(V7="TIPO III",'BASE LIQUIDACION'!$D$5,'BASE LIQUIDACION'!$D$7))) -> 134410.39 | AE7: =Y7*'BASE LIQUIDACION'!$B$12+Z7*'BASE LIQUIDACION'!$B$11+AA7*'BASE LIQUIDACION'!$B$13+AB7*'BASE LIQUIDACION'!$B$14+AC7*AD7 -> 134410.39
A8: PASTO | B8: =VLOOKUP(A8,'CENTRO DE COSTOS'!A:D,4,FALSE) -> DIEGO FERNANDO HENAO CARDONA | C8: =VLOOKUP(A8,'CENTRO DE COSTOS'!A:C,2,FALSE) -> 0004-0003 | D8: 52356 | E8: TA-25-1118001 | F8: 81502 | G8: APERTURA | H8: CB CRECIMIENTO ALIANZA - NUEVO | I8: NARIÑO | J8: IPIALES | K8: DISTRICOL VAR SEBASTIAN JM | L8: REDEBAN | M8: FO-25-1543540 | N8: 45917 | O8: 45918 | P8: AGREGADOR | Q8: DISTRICOL | R8: EJECUTADO/CANCELADO | S8: 17-09 PROGRAMACIÓN REALIZADA POR LA ALIANZA 18/09/2025 SE REALIZÓ VISITA AL COMERCIO PARA LA APERTURA DEL CB PERO NO ES POSIBLE YA QUE EL COMERCIO NO CUENTA CON CONEXIÓN A INTERNET, QUEDA PENDIENTE QUE EL USUARIO ADQUIERA EL SERVICIO PARA PODER INSTALAR EL CB | T8: VISITA _TECNICA | U8: FSZZZ885 | V8: TIPO II | W8: TERRESTRE | X8: GUERRERO RAMIREZ OSCAR DARIO | Y8: 0 | Z8: 0 | AA8: 0 | AB8: 0 | AC8: 1 | AD8: =IF(V8="TIPO I",'BASE LIQUIDACION'!$D$3,IF(V8="TIPO II",'BASE LIQUIDACION'!$D$4,IF(V8="TIPO III",'BASE LIQUIDACION'!$D$5,'BASE LIQUIDACION'!$D$7))) -> 134410.39 | AE8: =Y8*'BASE LIQUIDACION'!$B$12+Z8*'BASE LIQUIDACION'!$B$11+AA8*'BASE LIQUIDACION'!$B$13+AB8*'BASE LIQUIDACION'!$B$14+AC8*AD8 -> 134410.39
A9: MEDELLIN | B9: =VLOOKUP(A9,'CENTRO DE COSTOS'!A:D,4,FALSE) -> JUAN SEBASTIÁN RÍOS CASTRILLÓN | C9: =VLOOKUP(A9,'CENTRO DE COSTOS'!A:C,2,FALSE) -> 0004-0005 | D9: 5604 | E9: TA-25-1145368 | F9: 81673 | G9: APERTURA | H9: CB CRECIMIENTO ALIANZA - NUEVO | I9: ANTIOQUIA | J9: REMEDIOS | K9: DISTRICOL MUNDO PELUQUERO R | L9: REDEBAN | M9: FO-25-1585234 | N9: 45924 | O9: 45925 | P9: AGREGADOR | Q9: DISTRICOL | R9: EJECUTADO/CANCELADO | S9: 24-09 PROGRAMACIÓN REALIZADA POR LA ALIANZA 25/09/2025 VISITAMOS PUNTO ENCONTRANDO QUE COMERCIO ESTÁ EN DIRECCIÓN DISTINTA A LA RELACIONADA EN LISTA DE CHEQUEO. LA DIRECCIÓN REAL EN LA QUE ESTÁ EL COMERCIO ES CALLE 11 # 13 – 86. ESCALAMOS POR NOVEDAD DE DIRECCIÓN. 25/09/2025 POR FAVOR PROCEDER CON LA CANCELACIÓN DE LA IMPLEMENTACIÓN, YA QUE EL CB NO SE ENCUENTRA EN LA DIRECCIÓN REGISTRADA EN LA LISTA DE CHEQUEO. | T9: VISITA _TECNICA | U9: FWZZZ437 | V9: TIPO IV | W9: TERRESTRE | X9: DIAZ ZABALA FRANCIS DUBAN | Y9: 0 | Z9: 0 | AA9: 0 | AB9: 0 | AC9: 1 | AD9: =IF(V9="TIPO I",'BASE LIQUIDACION'!$D$3,IF(V9="TIPO II",'BASE LIQUIDACION'!$D$4,IF(V9="TIPO III",'BASE LIQUIDACION'!$D$5,'BASE LIQUIDACION'!$D$7))) -> 464809.03 | AE9: =Y9*'BASE LIQUIDACION'!$B$12+Z9*'BASE LIQUIDACION'!$B$11+AA9*'BASE LIQUIDACION'!$B$13+AB9*'BASE LIQUIDACION'!$B$14+AC9*AD9 -> 464809.03
A10: VILLAVICENCIO | B10: =VLOOKUP(A10,'CENTRO DE COSTOS'!A:D,4,FALSE) -> KEVIN ALEXIS CORZO BUSTOS | C10: =VLOOKUP(A10,'CENTRO DE COSTOS'!A:C,2,FALSE) -> 0004-0007 | D10: 50001 | E10: TA-25-1145459 | F10: 81695 | G10: APERTURA | H10: CB CRECIMIENTO ALIANZA - NUEVO | I10: META | J10: VILLAVICENCIO | K10: PTM VILLAVICENCIO DROGAS VILL | L10: REDEBAN | M10: FO-25-1577404 | N10: 45924 | O10: 45926 | P10: AGREGADOR | Q10: COMCARD - PTM | R10: EJECUTADO/CANCELADO | S10: 24-09 PROGRAMACIÓN REALIZADA POR LA ALIANZA 26/09/2025 SE ESCALA CASO DE APERTURA CB 3007081695 - PTM VILLAVICENCIO DROGAS VILLAVICENCIO CB A INSTALAR PTM 81695 - CALLE 10 NO 12 C - 111 ESTERO CB INSTALADO WOMPI 77610 - CALLE 10 NO 12 C – 112 BARRIO ESTERO / ENTIDAD SOLICITA CANCELAR INSTALACIÓN | T10: VISITA _TECNICA | U10: FWZZZ460 | V10: TIPO I | W10: TERRESTRE | X10: CASTRILLON URREA LONDIER LEANDRO | Y10: 0 | Z10: 0 | AA10: 0 | AB10: 0 | AC10: 1 | AD10: =IF(V10="TIPO I",'BASE LIQUIDACION'!$D$3,IF(V10="TIPO II",'BASE LIQUIDACION'!$D$4,IF(V10="TIPO III",'BASE LIQUIDACION'!$D$5,'BASE LIQUIDACION'!$D$7))) -> 44559.985 | AE10: =Y10*'BASE LIQUIDACION'!$B$12+Z10*'BASE LIQUIDACION'!$B$11+AA10*'BASE LIQUIDACION'!$B$13+AB10*'BASE LIQUIDACION'!$B$14+AC10*AD10 -> 44559.985
A11: BOGOTA | B11: =VLOOKUP(A11,'CENTRO DE COSTOS'!A:D,4,FALSE) -> WILLIAM ASDRUBAL ROZO ROZO | C11: =VLOOKUP(A11,'CENTRO DE COSTOS'!A:C,2,FALSE) -> 0004-0004 | D11: 11001 | E11: TA-25-1145952 | F11: 81630 | G11: APERTURA | H11: CB CRECIMIENTO ALIANZA - NUEVO | I11: CUNDINAMARCA | J11: BOGOTA | K11: PTM BOGOTA TIENDA SANTI LA SEP | L11: REDEBAN | M11: FO-25-1589721 | N11: 45924 | O11: 45929 | P11: AGREGADOR | Q11: COMCARD - PTM | R11: EJECUTADO | S11: 24-09 PROGRAMACIÓN REALIZADA POR LA ALIANZA 26/09/2025 SE LLEGA A SITIO, SE VERIFICA Y NO AHI PUNTO CABLEADO, NI PUERTO DISPONIBLE PARA LA CONEXIÓN DEL DATAFONO, CLIENTE SE NIEGA A DESCONECTAR DISPOSITIVOS PARA REALIZAR LA INSTALACIÓN. SE REPROGRAMA YA QUE INDICA QUE SE VA A CONSEGUIR UN SWITCH O REPETIDOR. SE ESCALA CON COORDINADOR QUIEN INDICA SE REALIZARA REPROGRAMACION PARA VISITAR NUEVAMENTE EL PUNTO. 29/09/2025 SE REALIZA INSTALACIÓN DE CORRESPONSAL, SE INSTALAN EQUIPOS CON PRUEBAS EXITOSAS, SE CAPACITA Y SE EVALÚA AL CLIENTE, SE INSTALA PUBLICIDAD COMPLETA, CB QUEDA OPERATIVO. USUARIO SOMOS BANCOLOMBIA ACTIVO | T11: VISITA _TECNICA | U11: FWZZZ506 | V11: TIPO I | W11: TERRESTRE | X11: ARIAS QUILINDO JULIAN | Y11: 0 | Z11: 0 | AA11: 0 | AB11: 0 | AC11: 1 | AD11: =IF(V11="TIPO I",'BASE LIQUIDACION'!$D$3,IF(V11="TIPO II",'BASE LIQUIDACION'!$D$4,IF(V11="TIPO III",'BASE LIQUIDACION'!$D$5,'BASE LIQUIDACION'!$D$7))) -> 44559.985 | AE11: =Y11*'BASE LIQUIDACION'!$B$12+Z11*'BASE LIQUIDACION'!$B$11+AA11*'BASE LIQUIDACION'!$B$13+AB11*'BASE LIQUIDACION'!$B$14+AC11*AD11 -> 44559.985
AE12: =SUM(AE3:AE11) -> 1511089.2
Z21: facturacion_swicth
Z22: facturacion_switch

Sheet TIPOLOGIAS
A1: COD. CIUDAD | B1: CIUDAD | C1: DEPARTAMENTO | D1: DESDE DONDE SE ATIENDE | E1: TIPO DE TRAYECTO NUEVO | F1: TIPOLOGIA NUEVA
A2: 91430 | B2: LA VICTORIA | C2: AMAZONAS | D2: BOGOTA | E2: AEREO | F2: TIPO IV ESPECIAL
A3: 91669 | B3: PUERTO SANTANDER | C3: AMAZONAS | D3: BOGOTA | E3: AEREO | F3: TIPO IV ESPECIAL
A4: 91263 | B4: EL ENCANTO | C4: AMAZONAS | D4: BOGOTA | E4: AEREO | F4: TIPO IV ESPECIAL
A5: 91405 | B5: LA CHORRERA | C5: AMAZONAS | D5: BOGOTA | E5: AEREO | F5: TIPO IV ESPECIAL
A6: 91407 | B6: LA PEDRERA | C6: AMAZONAS | D6: BOGOTA | E6: AEREO | F6: TIPO IV ESPECIAL
A7: 91001 | B7: LETICIA | C7: AMAZONAS | D7: BOGOTA | E7: AEREO | F7: TIPO IV ESPECIAL
A8: 91460 | B8: MIRITI - PARANA | C8: AMAZONAS | D8: BOGOTA | E8: AEREO | F8: TIPO IV ESPECIAL
A9: 91530 | B9: PUERTO ALEGRIA | C9: AMAZONAS | D9: BOGOTA | E9: AEREO | F9: TIPO IV ESPECIAL
A10: 91536 | B10: PUERTO ARICA | C10: AMAZONAS | D10: BOGOTA | E10: AEREO | F10: TIPO IV ESPECIAL
A11: 91540 | B11: PUERTO NARIÑO | C11: AMAZONAS | D11: BOGOTA | E11: AEREO | F11: TIPO IV ESPECIAL
A12: 91798 | B12: TARAPACA | C12: AMAZONAS | D12: BOGOTA | E12: AEREO | F12: TIPO IV ESPECIAL
A13: 5055 | B13: ARGELIA | C13: ANTIOQUIA | D13: MEDELLIN | E13: TERRESTRE | F13: TIPO IV
... A1124: 23682 | B1124: SAN JOSE DE URE | C1124: CORDOBA | D1124: MONTERIA | E1124: TERRESTRE | F1124: TIPO III

Sheet INCIDENTES
A1: CIUDAD SEDE | B1: COORDINADOR | C1: CENTRO DE COSTOS LÍNEACOM | D1: CÓDIGO DANE | E1: TA/CODIGO ACTIVIDAD | F1: CODIGO CB | G1: ACTIVIDAD | H1: DEPARTAMENTO | I1: CIUDAD | J1: NOMBRE DEL CB | K1: RED | L1: FO | M1: FECHA ASIGNACIÓN A LÍNEA COMUNICACIONES (DD/MM/AAAA HH:MM) | N1: FECHA CIERRE DEL TICKET (DD/MM/AAAA HH:MM) | O1: ACOMETIDA | P1: GRUPO_FALLA | Q1: CATEGORÍA | R1: FALLA | S1: FORMATO | T1: CADENA | U1: ESTADO | V1: OBSERVACION | W1: FORMA DE ATENCIÓN | X1: TERMINAL | Y1: TIPIFICACION | Z1: TIPO DE TRAYECTO | AA1: NOMBRE DEL TECNICO | AB1: DIAS DE VISITA | AC1: ACOMETIDA DATOS | AD1: ACOMETIDA ELÉCTRICA | AE1: SWITCH | AF1: VALOR DIAS ACTIVIDAD FACTURABLES | AG1: VALOR DIAS ACOMPAÑAMIENTO FACTURABLES
A2: CALI | B2: =VLOOKUP(A2,'CENTRO DE COSTOS'!A:D,4,FALSE) -> DIEGO FERNANDO HENAO CARDONA | C2: =VLOOKUP(A2,'CENTRO DE COSTOS'!A:D,2,FALSE) -> 0004-0003 | D2: 76001 | E2: 2811808 | F2: 65776 | G2: INCIDENTE | H2: VALLE DEL CAUCA | I2: CALI | J2: REDY CASA DEL TENDERO | K2: REDEBAN | L2: FO-25-1601530 | M2: 45930.333 | N2: 45930.426 | O2: NO | P2: USUARIO | Q2: USUARIOS | R2: USUARIOS BLOQUEADOS | U2: CERRADO | V2: 30/09/2025 SE ESCALA PARA VISITA. LLAMAR ANTES DE VISITAR, CONFIRMAR FALLA Y DATOS | 30/09/2025 SE HABLA CON EL CLIENTE QUIEN ME INCIDA QUE DESPUES DEL CAMBIO DE EQUIPO, FUERON A SACAR UN DUPLICADO Y LA CLAVE 1526 NO LE FUNCIONO , PERO QUE EN LA NOCHE CUANDO FUERON A SACAR EL CIERRE, YA PUDIERON OPERARLO NORMAL , EL DATAFONO ESTA FUNCIONAL | W2: SOPORTE_TELEFÓNICO | X2: 0 | Y2: TIPO I | Z2: TERRESTRE | AA2: HENAO CARDONA DIEGO FERNANDO | AB2: 0 | AC2: 0 | AD2: 0 | AE2: 0 | AF2: =IF(W2="SOPORTE_TELEFÓNICO",'BASE LIQUIDACION'!$B$10,IF(Y2="TIPO I",'BASE LIQUIDACION'!$C$3,IF(Y2="TIPO II",'BASE LIQUIDACION'!$C$4,IF(Y2="TIPO III",'BASE LIQUIDACION'!$C$5,'BASE LIQUIDACION'!$C$7)))) -> 37904.654 | AG2: =IF(W2="SOPORTE_TELEFÓNICO",'BASE LIQUIDACION'!$B$10,(AB2*AF2+AC2*'BASE LIQUIDACION'!$B$12+AD2*'BASE LIQUIDACION'!$B$11+INCIDENTES!AE2*'BASE LIQUIDACION'!$B$13)) -> 37904.654
A3: TUNJA | B3: =VLOOKUP(A3,'CENTRO DE COSTOS'!A:D,4,FALSE) -> MIGUEL JULIÁN HERNÁNDEZ GUARÍN | C3: =VLOOKUP(A3,'CENTRO DE COSTOS'!A:D,2,FALSE) -> 0004-0008 | D3: 15238 | E3: 2811639 | F3: 65128 | G3: INCIDENTE | H3: BOYACA | I3: DUITAMA | J3: BARRIO VATICANO DUITAMA 1 | K3: REDEBAN | L3: FO-25-1601034 | M3: 45929.745 | N3: 45930.598 | O3: NO | P3: USUARIO | Q3: CIERRE | R3: COMERCIO NO REALIZA CIERRE | U3: CERRADO | V3: 29/09/2025 SE ESCALA PARA VISITA. LLAMAR ANTES DE VISITAR, CONFIRMAR FALLA Y DATOS | 30/09/2025 SE REALIZAN VALIDACIONES DE COMUNICACION CORRESPONSAL OPERATIVO SE EVIDENCIA QUE EL EQUIPO SE ENCUENTRA CON LA MEMORIA ACOMULADA CLIENTE AUTORIZA RELIZAR BORRADO AL EQUIPO SE LE INDICA LA FORMA CORRECTA DE REALIZAR LOS CIERRES DIARIOS PRUEBAS OK CLIENTE CONFORME | W3: VISITA_TÉCNICA | X3: 1A007838 | Y3: TIPO II | Z3: TERRESTRE | AA3: RODRIGUEZ MURCIA YERSON IVAN | AB3: 1 | AC3: 0 | AD3: 0 | AE3: 0 | AF3: =IF(W3="SOPORTE_TELEFÓNICO",'BASE LIQUIDACION'!$B$10,IF(Y3="TIPO I",'BASE LIQUIDACION'!$C$3,IF(Y3="TIPO II",'BASE LIQUIDACION'!$C$4,IF(Y3="TIPO III",'BASE LIQUIDACION'!$C$5,'BASE LIQUIDACION'!$C$7)))) -> 163813.56 | AG3: =IF(W3="SOPORTE_TELEFÓNICO",'BASE LIQUIDACION'!$B$10,(AB3*AF3+AC3*'BASE LIQUIDACION'!$B$12+AD3*'BASE LIQUIDACION'!$B$11+INCIDENTES!AE3*'BASE LIQUIDACION'!$B$13)) -> 163813.56
A4: APARTADO | B4: =VLOOKUP(A4,'CENTRO DE COSTOS'!A:D,4,FALSE) -> JUAN SEBASTIÁN RÍOS CASTRILLÓN | C4: =VLOOKUP(A4,'CENTRO DE COSTOS'!A:D,2,FALSE) -> 0004-0005 | D4: 5045 | E4: 2810861 | F4: 32309 | G4: INCIDENTE | H4: ANTIOQUIA | I4: APARTADO | J4: CHINITA APARTADO ANTIOQUIA | K4: REDEBAN | L4: FO-25-1600699 | M4: 45929.683 | N4: 45930.467 | O4: NO | P4: USUARIO | Q4: COMUNICACION | R4: CANAL DEL COMERCIO | U4: CERRADO | V4: 29/09/2025 SE ESCALA PARA VISITA. LLAMAR ANTES DE VISITAR, CONFIRMAR FALLA Y DATOS | 30/09/2025 SE REALIZA BORRADO DE MEMORIA, CLIENTE INDICA REINICIOS, SE VERIFICA CABLEADO Y SE ENCUENTRA DATAFONO EN BUENAS CONDICIONES | W4: VISITA_TÉCNICA | X4: NN00M741 | Y4: TIPO I | Z4: TERRESTRE | AA4: CASTRO HENAO DANIEL ESTEBAN | AB4: 1 | AC4: 0 | AD4: 0 | AE4: 0 | AF4: =IF(W4="SOPORTE_TELEFÓNICO",'BASE LIQUIDACION'!$B$10,IF(Y4="TIPO I",'BASE LIQUIDACION'!$C$3,IF(Y4="TIPO II",'BASE LIQUIDACION'!$C$4,IF(Y4="TIPO III",'BASE LIQUIDACION'!$C$5,'BASE LIQUIDACION'!$C$7)))) -> 65960.474 | AG4: =IF(W4="SOPORTE_TELEFÓNICO",'BASE LIQUIDACION'!$B$10,(AB4*AF4+AC4*'BASE LIQUIDACION'!$B$12+AD4*'BASE LIQUIDACION'!$B$11+INCIDENTES!AE4*'BASE LIQUIDACION'!$B$13)) -> 65960.474
A5: CALI | B5: =VLOOKUP(A5,'CENTRO DE COSTOS'!A:D,4,FALSE) -> DIEGO FERNANDO HENAO CARDONA | C5: =VLOOKUP(A5,'CENTRO DE COSTOS'!A:D,2,FALSE) -> 0004-0003 | D5: 76109 | E5: 2808683 | F5: 63162 | G5: INCIDENTE | H5: VALLE DEL CAUCA | I5: BUENAVENTURA | J5: BARRIO CENTRO BUENAVENTURA 9 | K5: REDEBAN | L5: FO-25-1598975 | M5: 45929.541 | N5: 45930.594 | O5: NO | P5: USUARIO | Q5: COMUNICACION | R5: CONEXIONES DE COMERCIO | U5: CERRADO | V5: 29/09/2025 SE ESCALA PARA VISITA. LLAMAR ANTES DE VISITAR, CONFIRMAR FALLA Y DATOS | 30/09/2025 DATAFONO SIN INTERNET SE REVISA CABLEADO SE REINICIA ROUTER Y QUEDA FUNCIONANDO CORRECTAMENTE | W5: VISITA_TÉCNICA | X5: JA00T600 | Y5: TIPO III | Z5: TERRESTRE | AA5: CUERO RUIZ JHONNY | AB5: 1 | AC5: 0 | AD5: 0 | AE5: 0 | AF5: =IF(W5="SOPORTE_TELEFÓNICO",'BASE LIQUIDACION'!$B$10,IF(Y5="TIPO I",'BASE LIQUIDACION'!$C$3,IF(Y5="TIPO II",'BASE LIQUIDACION'!$C$4,IF(Y5="TIPO III",'BASE LIQUIDACION'!$C$5,'BASE LIQUIDACION'!$C$7)))) -> 275728.38 | AG5: =IF(W5="SOPORTE_TELEFÓNICO",'BASE LIQUIDACION'!$B$10,(AB5*AF5+AC5*'BASE LIQUIDACION'!$B$12+AD5*'BASE LIQUIDACION'!$B$11+INCIDENTES!AE5*'BASE LIQUIDACION'!$B$13)) -> 275728.38
A6: TUNJA | B6: =VLOOKUP(A6,'CENTRO DE COSTOS'!A:D,4,FALSE) -> MIGUEL JULIÁN HERNÁNDEZ GUARÍN | C6: =VLOOKUP(A6,'CENTRO DE COSTOS'!A:D,2,FALSE) -> 0004-0008 | D6: 15755 | E6: 2808716 | F6: 50614 | G6: INCIDENTE | H6: BOYACA | I6: SOCOTA | J6: BARRIO SAN CAYETANO SOCOTA | K6: REDEBAN | L6: FO-25-1598991 | M6: 45929.534 | N6: 45930.749 | O6: NO | P6: USUARIO | Q6: COMUNICACION | R6: CANAL DEL COMERCIO | U6: CERRADO | V6: 29/09/2025 SE ESCALA PARA VISITA. LLAMAR ANTES DE VISITAR, CONFIRMAR FALLA Y DATOS | 30/09/2025 SE ESTABLECE COMUNICACIÓN CON LA SEÑORA SANDRA OJEDA BELLO PARA VALIDACIÓN DE LA FALLA AL NÚMERO DE CONTACTO 3143427809 CLIENTE INDICA QUE LA FALLA REPORTADA SE DEBIÓ A UNA FALLA DEL INTERNET DEL COMERCIO EL CUAL YA FUE SOLUCIONADO ADICIONAL INDICA QUE SE COMUNICO EL DÍA DE AYER A LA LÍNEA 018000953344 PARA CANCELAR LA VISITA TECNICA YA QUE EL CORRESPONSAL ESTA FUNCIONANDO CORRECTAMENTE CLIENTE COMPARTE EVIDENCIA EVIDENCIANDO QUE EL CORRESPONSAL BANCARIO SE ENCUENTRA OPERATIVO SE LE INDICA QUE SE PROCEDERÁ CON EL CIERRE DE LA ORDEN DE TRABAJO CLIENTE CONFORME | W6: SOPORTE_TELEFÓNICO | X6: 0 | Y6: TIPO III | Z6: TERRESTRE | AA6: RODRIGUEZ MURCIA YERSON IVAN | AB6: 0 | AC6: 0 | AD6: 0 | AE6: 0 | AF6: =IF(W6="SOPORTE_TELEFÓNICO",'BASE LIQUIDACION'!$B$10,IF(Y6="TIPO I",'BASE LIQUIDACION'!$C$3,IF(Y6="TIPO II",'BASE LIQUIDACION'!$C$4,IF(Y6="TIPO III",'BASE LIQUIDACION'!$C$5,'BASE LIQUIDACION'!$C$7)))) -> 37904.654 | AG6: =IF(W6="SOPORTE_TELEFÓNICO",'BASE LIQUIDACION'!$B$10,(AB6*AF6+AC6*'BASE LIQUIDACION'!$B$12+AD6*'BASE LIQUIDACION'!$B$11+INCIDENTES!AE6*'BASE LIQUIDACION'!$B$13)) -> 37904.654
A7: VILLAVICENCIO | B7: =VLOOKUP(A7,'CENTRO DE COSTOS'!A:D,4,FALSE) -> KEVIN ALEXIS CORZO BUSTOS | C7: =VLOOKUP(A7,'CENTRO DE COSTOS'!A:D,2,FALSE) -> 0004-0007 | D7: 85440 | E7: 2808162 | F7: 79156 | G7: INCIDENTE | H7: CASANARE | I7: VILLANUEVA | J7: BARRIO CENTRO VILLANUEVA 10 | K7: REDEBAN | L7: FO-25-1598679 | M7: 45929.494 | N7: 45930.474 | O7: NO | P7: USUARIO | Q7: LECTOR DE BARRAS | R7: ERROR PAGOS PARCIALES DE FACTURAS | U7: CERRADO | V7: 29/09/2025 SE ESCALA PARA VISITA. LLAMAR ANTES DE VISITAR, CONFIRMAR FALLA Y DATOS SE COMUNICA CON EL SR JUAN 3132227029 PARA REPORTAR PROBLEMA CON DATÁFONO, MANIFIESTA: NO LEE LOS CÓDIGOS DE BARRA, ALUMBRA Y SUENA COMO SI LEYERA, PERO NO FUNCIONA, SE QUEDA AHÍ LEYÉNDOLO HASTA QUE UNO LE DÉ CANCELAR | 30/09/2025 SE REALIZA VISTA AL CB POR SOLICITUD DE LECTORA NO LEE LOS CÓDIGOS, REINICIAMOS EL DISPOSITIVO Y REALIZAMOS LA PRUEBA Y FUNCIONÓ LA LECTORA LEYÓ LOS CÓDIGOS, REALIZÓ PRUEBA DE CONSULTA DE SALDO PARA VERIFICAR EL FUNCIONAMIENTO Y FUE EXITOSA | W7: VISITA_TÉCNICA | X7: SASZZ731 | Y7: TIPO III | Z7: TERRESTRE | AA7: MOLINA CASTRO JAVIER ALBERTO | AB7: 1 | AC7: 0 | AD7: 0 | AE7: 0 | AF7: =IF(W7="SOPORTE_TELEFÓNICO",'BASE LIQUIDACION'!$B$10,IF(Y7="TIPO I",'BASE LIQUIDACION'!$C$3,IF(Y7="TIPO II",'BASE LIQUIDACION'!$C$4,IF(Y7="TIPO III",'BASE LIQUIDACION'!$C$5,'BASE LIQUIDACION'!$C$7)))) -> 275728.38 | AG7: =IF(W7="SOPORTE_TELEFÓNICO",'BASE LIQUIDACION'!$B$10,(AB7*AF7+AC7*'BASE LIQUIDACION'!$B$12+AD7*'BASE LIQUIDACION'!$B$11+INCIDENTES!AE7*'BASE LIQUIDACION'!$B$13)) -> 275728.38
A8: VILLAVICENCIO | B8: =VLOOKUP(A8,'CENTRO DE COSTOS'!A:D,4,FALSE) -> KEVIN ALEXIS CORZO BUSTOS | C8: =VLOOKUP(A8,'CENTRO DE COSTOS'!A:D,2,FALSE) -> 0004-0007 | D8: 50001 | E8: 2806560 | F8: 76214 | G8: INCIDENTE | H8: META | I8: VILLAVICENCIO | J8: BARRIO SERRAMONTE 2 VILLAVICEN | K8: REDEBAN | L8: FO-25-1597610 | M8: 45929.417 | N8: 45930.359 | O8: NO | P8: USUARIO | Q8: COMUNICACION | R8: CANAL DEL COMERCIO | U8: CERRADO | V8: 29/09/2025 SE ESCALA PARA VISITA. LLAMAR ANTES DE VISITAR, CONFIRMAR FALLA Y DATOS | 30/09/2025 SE LLEGA AL COMERCIO SE VÁLIDAD CONEXIONES SE ENTREGA OPERATIVO SIN NOVEDA | W8: VISITA_TÉCNICA | X8: FA0GZ506 | Y8: TIPO I | Z8: TERRESTRE | AA8: ROZO JIMENEZ EDGAR ARMANDO | AB8: 1 | AC8: 0 | AD8: 0 | AE8: 0 | AF8: =IF(W8="SOPORTE_TELEFÓNICO",'BASE LIQUIDACION'!$B$10,IF(Y8="TIPO I",'BASE LIQUIDACION'!$C$3,IF(Y8="TIPO II",'BASE LIQUIDACION'!$C$4,IF(Y8="TIPO III",'BASE LIQUIDACION'!$C$5,'BASE LIQUIDACION'!$C$7)))) -> 65960.474 | AG8: =IF(W8="SOPORTE_TELEFÓNICO",'BASE LIQUIDACION'!$B$10,(AB8*AF8+AC8*'BASE LIQUIDACION'!$B$12+AD8*'BASE LIQUIDACION'!$B$11+INCIDENTES!AE8*'BASE LIQUIDACION'!$B$13)) -> 65960.474
A9: TUNJA | B9: =VLOOKUP(A9,'CENTRO DE COSTOS'!A:D,4,FALSE) -> MIGUEL JULIÁN HERNÁNDEZ GUARÍN | C9: =VLOOKUP(A9,'CENTRO DE COSTOS'!A:D,2,FALSE) -> 0004-0008 | D9: 15806 | E9: 2803981 | F9: 29530 | G9: INCIDENTE | H9: BOYACA | I9: TIBASOSA | J9: BARRIO VDA PATROCINIO TIBASOSA | K9: REDEBAN | L9: FO-25-1594943 | M9: 45928.458 | N9: 45930.588 | O9: NO | P9: USUARIO | Q9: COMUNICACION | R9: CANAL DEL COMERCIO | U9: CERRADO | V9: 28/09/2025 SE ESCALA PARA VISITA. LLAMAR ANTES DE VISITAR, CONFIRMAR FALLA Y DATOS | 29/09/2025 SE ESTABLECE COMUNICACIÓN CON EL CLIENTE AL NÚMERO CELULAR 3118205832 SE CONTACTA A LA SEÑORA SANDRA BONILA , LA SEÑORA SANDRA COMPARTE NÚMERO TELEFONICO DE LA PARSONA ENCARGADA DEL COMERCIO AL NÚMERO 3144341413 SEÑORA YURI PARA CONFIRMAR SI PUEDE ATENDER Y NO HA CERRADO EL COMERCIO EL CUAL LA LLAMADA ES FALLIDA BUZON DE VOZ , SE SEGUIRA HACIENDO GESTIÓN PARA CONFIRMAR VISITA. | 30/09/2025 POR TEMAS DE DESPLAZAMIENTO YA ME ENCUENTRO EN SITIO , ESTOY EN LA ESPERA DE AUTORIZACIÓN DE INGRESO AL PUNTO CLIENTE SE ENCUENTRA VALIDANDO IDENTIDAD DEL TÉCNICO Y SALDO PARA EL INGRESO Y VALIDAR FALLA Y PODER CERRA ORDEN , CLIENTE CONFORME | 30/09/2025 AL REALIZAR GESTION TELÉFONICA NO HUBO COMUNICACIÓN CON EL CLIENTE , SE REALIZA VISITA EN FRIO , SE VALIDA QUE EL CORRESPONSAL ESTA OPERATIVO SE VÁLIDA CONEXIONES SE CAMBIA CABLE PACTH CORD 3 METROS POR MANTENIMIENTO PREVENTIVO DEJANDO PRUEBAS OK SIN TELECARGA | W9: VISITA_TÉCNICA | X9: 9A003382 | Y9: TIPO II | Z9: TERRESTRE | AA9: ALVARADO MORENO CRISTHIAN | AB9: 1 | AC9: 0 | AD9: 0 | AE9: 0 | AF9: =IF(W9="SOPORTE_TELEFÓNICO",'BASE LIQUIDACION'!$B$10,IF(Y9="TIPO I",'BASE LIQUIDACION'!$C$3,IF(Y9="TIPO II",'BASE LIQUIDACION'!$C$4,IF(Y9="TIPO III",'BASE LIQUIDACION'!$C$5,'BASE LIQUIDACION'!$C$7)))) -> 163813.56 | AG9: =IF(W9="SOPORTE_TELEFÓNICO",'BASE LIQUIDACION'!$B$10,(AB9*AF9+AC9*'BASE LIQUIDACION'!$B$12+AD9*'BASE LIQUIDACION'!$B$11+INCIDENTES!AE9*'BASE LIQUIDACION'!$B$13)) -> 163813.56
A10: BUCARAMANGA | B10: =VLOOKUP(A10,'CENTRO DE COSTOS'!A:D,4,FALSE) -> MIGUEL JULIÁN HERNÁNDEZ GUARÍN | C10: =VLOOKUP(A10,'CENTRO DE COSTOS'!A:D,2,FALSE) -> 0004-0008 | D10: 68755 | E10: 2803348 | F10: 64390 | G10: INCIDENTE | H10: SANTANDER | I10: SOCORRO | J10: DISTRICOL CASETA SAN VICTORINO | K10: REDEBAN | L10: FO-25-1594655 | M10: 45927.717 | N10: 45929.48 | O10: NO | P10: USUARIO | Q10: CIERRE | R10: COMERCIO NO REALIZA CIERRE | U10: CERRADO | V10: 28/09/2025 SE ESCALA PARA VISITA. LLAMAR ANTES DE VISITAR, CONFIRMAR FALLA Y DATOS | 29/09/2025 SE ESTABLECE CONTACTO TELEFÓNICOAL NÚMERO 3173031803 CON LA USUARIA LILY SAAVEDRA HOLGUIN IDENTIFICADA CON CÉDULA 37941988 QUIEN NOS INDICA QUE SE COMUNICO AL CAC YA QUE NO PODIA REALIZAR EL CIERRE A LO CUAL NOS INDICA QUE MEDIANTE LA GESTIÓN TELEFÓNICA QUE LE HICIERON YA PUEDE REALIZAR LOS CIERRES Y LOS DUPLICADOS SIN NINGÚN INCONVENIENTE NOS ENVIA COMPROBANTE DE QU ESTA OPERANDO NORMAL A LO CUAL NO REQUIERE EL SERVICIO TÉCNICO AGRADECE POR LA ATENCIÓN PRESTADA | W10: SOPORTE_TELEFÓNICO | X10: 0 | Y10: TIPO III | Z10: TERRESTRE | AA10: REYES RAMIREZ DIEGO ALEXANDER | AB10: 0 | AC10: 0 | AD10: 0 | AE10: 0 | AF10: =IF(W10="SOPORTE_TELEFÓNICO",'BASE LIQUIDACION'!$B$10,IF(Y10="TIPO I",'BASE LIQUIDACION'!$C$3,IF(Y10="TIPO II",'BASE LIQUIDACION'!$C$4,IF(Y10="TIPO III",'BASE LIQUIDACION'!$C$5,'BASE LIQUIDACION'!$C$7)))) -> 37904.654 | AG10: =IF(W10="SOPORTE_TELEFÓNICO",'BASE LIQUIDACION'!$B$10,(AB10*AF10+AC10*'BASE LIQUIDACION'!$B$12+AD10*'BASE LIQUIDACION'!$B$11+INCIDENTES!AE10*'BASE LIQUIDACION'!$B$13)) -> 37904.654
A11: CARTAGENA | B11: =VLOOKUP(A11,'CENTRO DE COSTOS'!A:D,4,FALSE) -> JOSE MAURICIO HERNANDEZ ROJAS | C11: =VLOOKUP(A11,'CENTRO DE COSTOS'!A:D,2,FALSE) -> 0004-0001 | D11: 13052 | E11: 2803201 | F11: 55393 | G11: INCIDENTE | H11: BOLIVAR | I11: ARJONA | J11: PTM ARJONA EL PUNTO DEL COLOR | K11: REDEBAN | L11: FO-25-1593456 | M11: 45927.548 | N11: 45929.531 | O11: NO | P11: USUARIO | Q11: USUARIOS | R11: USUARIOS BLOQUEADOS | U11: CERRADO | V11: 27/09/2025 SE ESCALA PARA VISITA. LLAMAR ANTES DE VISITAR, CONFIRMAR FALLA Y DATOS | 29/09/2025 SE RESTAURA USUARIO SUPERVISOR POR BLOQUEO , SE REALIZAN PRUEBAS Y TODO QUEDA OK | W11: VISITA_TÉCNICA | X11: TRFZZ018 | Y11: TIPO II | Z11: TERRESTRE | AA11: MARTINEZ SALGUEDO ANDRES AUGUSTO | AB11: 1 | AC11: 0 | AD11: 0 | AE11: 0 | AF11: =IF(W11="SOPORTE_TELEFÓNICO",'BASE LIQUIDACION'!$B$10,IF(Y11="TIPO I",'BASE LIQUIDACION'!$C$3,IF(Y11="TIPO II",'BASE LIQUIDACION'!$C$4,IF(Y11="TIPO III",'BASE LIQUIDACION'!$C$5,'BASE LIQUIDACION'!$C$7)))) -> 163813.56 | AG11: =IF(W11="SOPORTE_TELEFÓNICO",'BASE LIQUIDACION'!$B$10,(AB11*AF11+AC11*'BASE LIQUIDACION'!$B$12+AD11*'BASE LIQUIDACION'!$B$11+INCIDENTES!AE11*'BASE LIQUIDACION'!$B$13)) -> 163813.56
A12: MEDELLIN | B12: =VLOOKUP(A12,'CENTRO DE COSTOS'!A:D,4,FALSE) -> JUAN SEBASTIÁN RÍOS CASTRILLÓN | C12: =VLOOKUP(A12,'CENTRO DE COSTOS'!A:D,2,FALSE) -> 0004-0005 | D12: 5615 | E12: 2803120 | F12: 20701 | G12: INCIDENTE | H12: ANTIOQUIA | I12: RIONEGRO | J12: COMCARD SAN ANTONIO TELESAN | K12: REDEBAN | L12: FO-25-1593172 | M12: 45927.492 | N12: 45929.487 | O12: NO | P12: USUARIO | Q12: MANTENIMIENTO | R12: MANTENIMIENTO GENERAL | U12: CERRADO | V12: 27/09/2025 SE ESCALA PARA VISITA. LLAMAR ANTES DE VISITAR, CONFIRMAR FALLA Y DATOS | 28/09/2025 SE COMUNICA CON CLIENTE AL 3233282900 E INFORMA QUE EL DÍA DE HOY NO ABRE, SE APLAZA VISITA | 29/09/2025 SE LLAMA AL CLIENTE Y NOS INDICA QUE EL DATÁFONO YA FUNCIKNA CORRECTAMENTE | W12: SOPORTE_TELEFÓNICO | X12: 0 | Y12: TIPO II | Z12: TERRESTRE | AA12: CARDONA MOLINA BROLIN STIVEN | AB12: 0 | AC12: 0 | AD12: 0 | AE12: 0 | AF12: =IF(W12="SOPORTE_TELEFÓNICO",'BASE LIQUIDACION'!$B$10,IF(Y12="TIPO I",'BASE LIQUIDACION'!$C$3,IF(Y12="TIPO II",'BASE LIQUIDACION'!$C$4,IF(Y12="TIPO III",'BASE LIQUIDACION'!$C$5,'BASE LIQUIDACION'!$C$7)))) -> 37904.654 | AG12: =IF(W12="SOPORTE_TELEFÓNICO",'BASE LIQUIDACION'!$B$10,(AB12*AF12+AC12*'BASE LIQUIDACION'!$B$12+AD12*'BASE LIQUIDACION'!$B$11+INCIDENTES!AE12*'BASE LIQUIDACION'!$B$13)) -> 37904.654
A13: MONTERIA | B13: =VLOOKUP(A13,'CENTRO DE COSTOS'!A:D,4,FALSE) -> JOSE MAURICIO HERNANDEZ ROJAS | C13: =VLOOKUP(A13,'CENTRO DE COSTOS'!A:D,2,FALSE) -> 0004-0001 | D13: 23660 | E13: 2802689 | F13: 81679 | G13: INCIDENTE | H13: CORDOBA | I13: SAHAGUN | J13: DISTRICOL EL ROSARIO | K13: REDEBAN | L13: FO-25-1592359 | M13: 45927.401 | N13: 45929.387 | O13: NO | P13: USUARIO | Q13: COMUNICACION | R13: CANAL DEL COMERCIO | U13: CERRADO | V13: 27/09/2025 SE ESCALA PARA VISITA. LLAMAR ANTES DE VISITAR, CONFIRMAR FALLA Y DATOS | 29/09/2025 SE COMUNICA CON EL NÚMERO 3215382774 LUISA SUAREZ, INDICA QUE EL CB SE ENCUENTRA FUNCIONANDO CORRECTAMENTE. | W13: SOPORTE_TELEFÓNICO | X13: 0 | Y13: TIPO II | Z13: TERRESTRE | AA13: SANTOS GUZMAN CHRISTIAN FELIPE | AB13: 0 | AC13: 0 | AD13: 0 | AE13: 0 | AF13: =IF(W13="SOPORTE_TELEFÓNICO",'BASE LIQUIDACION'!$B$10,IF(Y13="TIPO I",'BASE LIQUIDACION'!$C$3,IF(Y13="TIPO II",'BASE LIQUIDACION'!$C$4,IF(Y13="TIPO III",'BASE LIQUIDACION'!$C$5,'BASE LIQUIDACION'!$C$7)))) -> 37904.654 | AG13: =IF(W13="SOPORTE_TELEFÓNICO",'BASE LIQUIDACION'!$B$10,(AB13*AF13+AC13*'BASE LIQUIDACION'!$B$12+AD13*'BASE LIQUIDACION'!$B$11+INCIDENTES!AE13*'BASE LIQUIDACION'!$B$13)) -> 37904.654
A14: BARRANQUILLA | B14: =VLOOKUP(A14,'CENTRO DE COSTOS'!A:D,4,FALSE) -> JOSE MAURICIO HERNANDEZ ROJAS | C14: =VLOOKUP(A14,'CENTRO DE COSTOS'!A:D,2,FALSE) -> 0004-0001 | D14: 8137 | E14: 2802873 | F14: 50862 | G14: INCIDENTE | H14: ATLANTICO | I14: CAMPO DE LA CRUZ | J14: PTM CAMPO DE LA CRUZ GRANERO E | K14: REDEBAN | L14: FO-25-1592365 | M14: 45927.398 | N14: 45929.385 | O14: NO | P14: USUARIO | Q14: COMUNICACION | R14: CANAL DEL COMERCIO | U14: CERRADO | V14: 27/09/2025 SE ESCALA PARA VISITA. LLAMAR ANTES DE VISITAR, CONFIRMAR FALLA Y DATOS | 29/09/2025 COMERCIO NO ATENDÍA DOMINGO Y HOY LUNES SE DESPLAZA COLABORADOR A SITIO, PERO DEBIDO A LA BAJA FRECUENCIA DE SALIDA DE BUSES A MUNICIPIO, SE ATENDERÁ A LAS 11:00M AM APROX | 29/09/2025 SE REALIZA LLAMADA AL CLIENTE EL CUAL NOS DICE QUE YA TIENE INTERNET, QUE DESDE EL SÁBADO EN LA TARDE ESTA LABORANDO NORMALMENTE, POSIBLEMENTE FALLAS DE CONEXIÓN POR SU OPERADOR DE DATOS ,CB OPERATIVO. | W14: SOPORTE_TELEFÓNICO | X14: 0 | Y14: TIPO II | Z14: TERRESTRE | AA14: PORRAS CASTRO DARLON NASCK | AB14: 0 | AC14: 0 | AD14: 0 | AE14: 0 | AF14: =IF(W14="SOPORTE_TELEFÓNICO",'BASE LIQUIDACION'!$B$10,IF(Y14="TIPO I",'BASE LIQUIDACION'!$C$3,IF(Y14="TIPO II",'BASE LIQUIDACION'!$C$4,IF(Y14="TIPO III",'BASE LIQUIDACION'!$C$5,'BASE LIQUIDACION'!$C$7)))) -> 37904.654 | AG14: =IF(W14="SOPORTE_TELEFÓNICO",'BASE LIQUIDACION'!$B$10,(AB14*AF14+AC14*'BASE LIQUIDACION'!$B$12+AD14*'BASE LIQUIDACION'!$B$11+INCIDENTES!AE14*'BASE LIQUIDACION'!$B$13)) -> 37904.654
A15: PASTO | B15: =VLOOKUP(A15,'CENTRO DE COSTOS'!A:D,4,FALSE) -> DIEGO FERNANDO HENAO CARDONA | C15: =VLOOKUP(A15,'CENTRO DE COSTOS'!A:D,2,FALSE) -> 0004-0003 | D15: 52490 | E15: 2802099 | F15: 41691 | G15: INCIDENTE | H15: NARIÑO | I15: OLAYA HERRERA | J15: BARRIO CENTRO OLAYA HERRERA 2 | K15: REDEBAN | L15: FO-25-1591693 | M15: 45927.333 | N15: 45930.573 | O15: NO | P15: USUARIO | Q15: CIERRE | R15: COMERCIO NO REALIZA CIERRE | U15: CERRADO | V15: 27/09/2025 EN COMUNICACIÓN CON LA SRA : VICENTA SEGURA PERLAZA AL NÚMERO 3214751285 NOS INFORMA QUE LA FALLA QUE TIENE CON EL DATAFONO ES CON LOS CIERRES, CONFIRMA DATOS E INDICA QUE LA RED ES REDEBAN, SE ESCALA PARA VISITA | 30/09/2025 SE REALIZA VALIDACION CON EL CLIENTE Y SE ENCUENTRA QUE USUARIO NO REALIZABA EL CIERRE GENERAL, SE LE EXPLICA AL CLIENTE LA FORMA CORRECTA DE GENERAR LOS CIERRES, CLIENTE REALIZA EL CIERRE Y SE LE EEXPLICA QUE DESPUES DE REALIZAR EL CIERRE GENERAL DEBE DARLE LA TECLA VERDE PARA QUE EL DATAFONO BORRE LO QUE TENGA EN MEMORIA. | W15: SOPORTE_TELEFÓNICO | X15: 0 | Y15: TIPO IV ESPECIAL | Z15: FLUVIAL | AA15: HENAO CARDONA DIEGO FERNANDO | AB15: 0 | AC15: 0 | AD15: 0 | AE15: 0 | AF15: =IF(W15="SOPORTE_TELEFÓNICO",'BASE LIQUIDACION'!$B$10,IF(Y15="TIPO I",'BASE LIQUIDACION'!$C$3,IF(Y15="TIPO II",'BASE LIQUIDACION'!$C$4,IF(Y15="TIPO III",'BASE LIQUIDACION'!$C$5,'BASE LIQUIDACION'!$C$7)))) -> 37904.654 | AG15: =IF(W15="SOPORTE_TELEFÓNICO",'BASE LIQUIDACION'!$B$10,(AB15*AF15+AC15*'BASE LIQUIDACION'!$B$12+AD15*'BASE LIQUIDACION'!$B$11+INCIDENTES!AE15*'BASE LIQUIDACION'!$B$13)) -> 37904.654
A16: PEREIRA | B16: =VLOOKUP(A16,'CENTRO DE COSTOS'!A:D,4,FALSE) -> DIEGO FERNANDO HENAO CARDONA | C16: =VLOOKUP(A16,'CENTRO DE COSTOS'!A:D,2,FALSE) -> 0004-0002 | D16: 76895 | E16: 2802027 | F16: 77269 | G16: INCIDENTE | H16: VALLE DEL CAUCA | I16: ZARZAL | J16: BARRIO LOS LAGOS SEGUNDA ETAPA | K16: REDEBAN | L16: FO-25-1591709 | M16: 45927.333 | N16: 45929.471 | O16: NO | P16: USUARIO | Q16: COMUNICACION | R16: CANAL DEL COMERCIO | U16: CERRADO | V16: 27/09/2025 SE INTENTA COMUNICACIÓN CON LA SRA FLOR MAYERLY CAICEDO SOLÍS A LOS NÚMEROS 3225098691-3147598029 PARA CONFIRMAR DATOS Y FALLA PERO NO HAY CONTAQCTO, SE ESCALA L COORDINADOR DE ZONA PARA VALIDAR EN SITIO | 29/09/2025 EN COMUNICACIÓN CON LA SEÑORA MAYERLY CAICEDO AL NÚMERO 3147598029 CONFIRMA QUE DATÁFONO SE ENCUENTRA TRABAJANDO SIN NOVEDAD | W16: SOPORTE_TELEFÓNICO | X16: 0 | Y16: TIPO III | Z16: TERRESTRE | AA16: LOAIZA LOPEZ JHON FREDDY | AB16: 0 | AC16: 0 | AD16: 0 | AE16: 0 | AF16: =IF(W16="SOPORTE_TELEFÓNICO",'BASE LIQUIDACION'!$B$10,IF(Y16="TIPO I",'BASE LIQUIDACION'!$C$3,IF(Y16="TIPO II",'BASE LIQUIDACION'!$C$4,IF(Y16="TIPO III",'BASE LIQUIDACION'!$C$5,'BASE LIQUIDACION'!$C$7)))) -> 37904.654 | AG16: =IF(W16="SOPORTE_TELEFÓNICO",'BASE LIQUIDACION'!$B$10,(AB16*AF16+AC16*'BASE LIQUIDACION'!$B$12+AD16*'BASE LIQUIDACION'!$B$11+INCIDENTES!AE16*'BASE LIQUIDACION'!$B$13)) -> 37904.654
A17: BARRANQUILLA | B17: =VLOOKUP(A17,'CENTRO DE COSTOS'!A:D,4,FALSE) -> JOSE MAURICIO HERNANDEZ ROJAS | C17: =VLOOKUP(A17,'CENTRO DE COSTOS'!A:D,2,FALSE) -> 0004-0001 | D17: 8078 | E17: 2801742 | F17: 62375 | G17: INCIDENTE | H17: ATLANTICO | I17: BARANOA | J17: BARRIO BARANOA BARANOA 3 | K17: REDEBAN | L17: FO-25-1590888 | M17: 45926.702 | N17: 45927.719 | O17: NO | P17: USUARIO | Q17: MANTENIMIENTO | R17: MANTENIMIENTO GENERAL | U17: CERRADO | V17: 26/09/2025 SE ESCALA PARA VISITA. LLAMAR ANTES DE VISITAR, CONFIRMAR FALLA Y DATOS | 27/09/2025 SE REALIZA VISITA SE PROCEDE A VALIDAR DATAFONO Y ESTÁ OK, SE LE INDICA AL CLIENTE EL PROCESO DE LA CARGA DE LA BATERÍA PARA QUE TENGA EN CUENTA CUANDO ESTÉ BAJA, SE REALIZA ACOMPAÑAMIENTO QUE LA BATERÍA AGARRE CARGA, SE HACEN PRUEBAS Y TODO OK | W17: VISITA_TÉCNICA | X17: HA00M871 | Y17: TIPO II | Z17: TERRESTRE | AA17: PORRAS CASTRO DARLON NASCK | AB17: 1 | AC17: 0 | AD17: 0 | AE17: 0 | AF17: =IF(W17="SOPORTE_TELEFÓNICO",'BASE LIQUIDACION'!$B$10,IF(Y17="TIPO I",'BASE LIQUIDACION'!$C$3,IF(Y17="TIPO II",'BASE LIQUIDACION'!$C$4,IF(Y17="TIPO III",'BASE LIQUIDACION'!$C$5,'BASE LIQUIDACION'!$C$7)))) -> 163813.56 | AG17: =IF(W17="SOPORTE_TELEFÓNICO",'BASE LIQUIDACION'!$B$10,(AB17*AF17+AC17*'BASE LIQUIDACION'!$B$12+AD17*'BASE LIQUIDACION'!$B$11+INCIDENTES!AE17*'BASE LIQUIDACION'!$B$13)) -> 163813.56
A18: MEDELLIN | B18: =VLOOKUP(A18,'CENTRO DE COSTOS'!A:D,4,FALSE) -> JUAN SEBASTIÁN RÍOS CASTRILLÓN | C18: =VLOOKUP(A18,'CENTRO DE COSTOS'!A:D,2,FALSE) -> 0004-0005 | D18: 5001 | E18: 2801003 | F18: 70017 | G18: INCIDENTE | H18: ANTIOQUIA | I18: MEDELLIN | J18: PTM MEDELLIN SALSAMENTARIA DO | K18: REDEBAN | L18: FO-25-1589979 | M18: 45926.62 | N18: 45927.524 | O18: NO | P18: USUARIO | Q18: MANTENIMIENTO | R18: MANTENIMIENTO GENERAL | U18: CERRADO | V18: 26/09/2025 SE ESCALA PARA VISITA. LLAMAR ANTES DE VISITAR, CONFIRMAR FALLA Y DATOS | 27/09/2025 SE INICIALIZA DE NUEVO EL CB YA QUE MOSTRABA EL NOMBRE ANTERIOR, SE ACTUALIZA A VERSIÓN 9.90, SE REALIZAN PRUEBAS Y QUEDA CON EL NUEVO NOMBRE, PRUEBAS OK | W18: VISITA_TÉCNICA | X18: UV001523 | Y18: TIPO I | Z18: TERRESTRE | AA18: CARDONA MOLINA BROLIN STIVEN | AB18: 1 | AC18: 0 | AD18: 0 | AE18: 0 | AF18: =IF(W18="SOPORTE_TELEFÓNICO",'BASE LIQUIDACION'!$B$10,IF(Y18="TIPO I",'BASE LIQUIDACION'!$C$3,IF(Y18="TIPO II",'BASE LIQUIDACION'!$C$4,IF(Y18="TIPO III",'BASE LIQUIDACION'!$C$5,'BASE LIQUIDACION'!$C$7)))) -> 65960.474 | AG18: =IF(W18="SOPORTE_TELEFÓNICO",'BASE LIQUIDACION'!$B$10,(AB18*AF18+AC18*'BASE LIQUIDACION'!$B$12+AD18*'BASE LIQUIDACION'!$B$11+INCIDENTES!AE18*'BASE LIQUIDACION'!$B$13)) -> 65960.474
A19: NEIVA | B19: =VLOOKUP(A19,'CENTRO DE COSTOS'!A:D,4,FALSE) -> KEVIN ALEXIS CORZO BUSTOS | C19: =VLOOKUP(A19,'CENTRO DE COSTOS'!A:D,2,FALSE) -> 0004-0007 | D19: 41551 | E19: 2800088 | F19: 80538 | G19: INCIDENTE | H19: HUILA | I19: PITALITO | J19: BARRIO AGUA BLANCA PITALITO 4 | K19: REDEBAN | L19: FO-25-1589312 | M19: 45926.54 | N19: 45929.507 | O19: NO | P19: ENTIDAD | Q19: ERROR DE TRANSACCIONES | R19: TRANSACCION NO PERMITIDA | U19: CERRADO | V19: 26/09/2025 SE INTENTA COMUNICACIÓN CON LA SRA YESICA TRUJILLO PERDOMO AL NÚMERO 3144434059 PARA CONFRIMAR DATOS Y FALLA PERO NO HAY CONTACTO, SE ESCALA AL COORDINADOR DE ZONA PARA VALIDAR EN SITIO | 29/09/2025 EN COMUNICACIÓN CON EL CLIENTE VIA TELÉFONICA ,LA SEÑORA YESICA TRUJILLO, AL NÚMERO +57 314 4434059, NOS INDICA QUE EL EQUIPO SE ENCUENTRA FUNCIONANDO CORRECTAMENTE YA QUE EL PROBLEMA DE TRANSACCIONES SE DEBIO A UNA CAÍDA DE LA PLATAFORMA DE BANCOLOMBIA LA CUAL YA SE RESTABLECIÓ Y FUNCIONA DE FORMA CORRECTA , CB OPERATIVO M. | W19: SOPORTE_TELEFÓNICO | X19: 0 | Y19: TIPO III | Z19: TERRESTRE | AA19: DEVIA REINOSO JUAN CARLOS | AB19: 0 | AC19: 0 | AD19: 0 | AE19: 0 | AF19: =IF(W19="SOPORTE_TELEFÓNICO",'BASE LIQUIDACION'!$B$10,IF(Y19="TIPO I",'BASE LIQUIDACION'!$C$3,IF(Y19="TIPO II",'BASE LIQUIDACION'!$C$4,IF(Y19="TIPO III",'BASE LIQUIDACION'!$C$5,'BASE LIQUIDACION'!$C$7)))) -> 37904.654 | AG19: =IF(W19="SOPORTE_TELEFÓNICO",'BASE LIQUIDACION'!$B$10,(AB19*AF19+AC19*'BASE LIQUIDACION'!$B$12+AD19*'BASE LIQUIDACION'!$B$11+INCIDENTES!AE19*'BASE LIQUIDACION'!$B$13)) -> 37904.654
A20: VILLAVICENCIO | B20: =VLOOKUP(A20,'CENTRO DE COSTOS'!A:D,4,FALSE) -> KEVIN ALEXIS CORZO BUSTOS | C20: =VLOOKUP(A20,'CENTRO DE COSTOS'!A:D,2,FALSE) -> 0004-0007 | D20: 50001 | E20: 2800046 | F20: 80632 | G20: INCIDENTE | H20: META | I20: VILLAVICENCIO | J20: BARRIO PINILLA VILLAVICENCIO 2 | K20: REDEBAN | L20: FO-25-1589002 | M20: 45926.518 | N20: 45926.737 | O20: NO | P20: USUARIO | Q20: NO ENCIENDE | R20: CONEXIONES DE COMERCIO | U20: CERRADO | V20: 26/09/2025 SE ESCALA PARA VISITA. LLAMAR ANTES DE VISITAR, CONFIRMAR FALLA Y DATOS | 26/09/2025 SE LLEGA AL COMERCIO E INDICA QUE SE ENCUENTRA FUNCIONANDO SE HABÍA QUEDO BLOQUEADO | W20: VISITA_TÉCNICA | X20: V6ZZZ816 | Y20: TIPO I | Z20: TERRESTRE | AA20: ROZO JIMENEZ EDGAR ARMANDO | AB20: 1 | AC20: 0 | AD20: 0 | AE20: 0 | AF20: =IF(W20="SOPORTE_TELEFÓNICO",'BASE LIQUIDACION'!$B$10,IF(Y20="TIPO I",'BASE LIQUIDACION'!$C$3,IF(Y20="TIPO II",'BASE LIQUIDACION'!$C$4,IF(Y20="TIPO III",'BASE LIQUIDACION'!$C$5,'BASE LIQUIDACION'!$C$7)))) -> 65960.474 | AG20: =IF(W20="SOPORTE_TELEFÓNICO",'BASE LIQUIDACION'!$B$10,(AB20*AF20+AC20*'BASE LIQUIDACION'!$B$12+AD20*'BASE LIQUIDACION'!$B$11+INCIDENTES!AE20*'BASE LIQUIDACION'!$B$13)) -> 65960.474
A21: CUCUTA | B21: =VLOOKUP(A21,'CENTRO DE COSTOS'!A:D,4,FALSE) -> MIGUEL JULIÁN HERNÁNDEZ GUARÍN | C21: =VLOOKUP(A21,'CENTRO DE COSTOS'!A:D,2,FALSE) -> 0004-0008 | D21: 54001 | E21: 2799185 | F21: 81650 | G21: INCIDENTE | H21: NORTE DE SANTANDER | I21: CUCUTA | J21: DISTRICOL MARCELAS CHIP STORE | K21: REDEBAN | L21: FO-25-1588261 | M21: 45926.463 | N21: 45926.724 | O21: NO | P21: USUARIO | Q21: COMUNICACION | R21: CONEXIONES DE COMERCIO | U21: CERRADO | V21: 26/09/2025 SE ESCALA PARA VISITA. LLAMAR ANTES DE VISITAR, CONFIRMAR FALLA Y DATOS | 26/09/2025 SE COMUNICA CON LA CLIENTE MARCELA SANTOS AL #3222295656, NOS INFORMA QUE EL PROBLEMA YA SE SOLUCIONO YA QUE ERA UNA FALLA INTERNO DEL INTERNET | W21: SOPORTE_TELEFÓNICO | X21: 0 | Y21: TIPO I | Z21: TERRESTRE | AA21: NARANJO AFANADOR RUBEN JESUS | AB21: 0 | AC21: 0 | AD21: 0 | AE21: 0 | AF21: =IF(W21="SOPORTE_TELEFÓNICO",'BASE LIQUIDACION'!$B$10,IF(Y21="TIPO I",'BASE LIQUIDACION'!$C$3,IF(Y21="TIPO II",'BASE LIQUIDACION'!$C$4,IF(Y21="TIPO III",'BASE LIQUIDACION'!$C$5,'BASE LIQUIDACION'!$C$7)))) -> 37904.654 | AG21: =IF(W21="SOPORTE_TELEFÓNICO",'BASE LIQUIDACION'!$B$10,(AB21*AF21+AC21*'BASE LIQUIDACION'!$B$12+AD21*'BASE LIQUIDACION'!$B$11+INCIDENTES!AE21*'BASE LIQUIDACION'!$B$13)) -> 37904.654
A22: MONTERIA | B22: =VLOOKUP(A22,'CENTRO DE COSTOS'!A:D,4,FALSE) -> JOSE MAURICIO HERNANDEZ ROJAS | C22: =VLOOKUP(A22,'CENTRO DE COSTOS'!A:D,2,FALSE) -> 0004-0001 | D22: 23079 | E22: 2797827 | F22: 27499 | G22: INCIDENTE | H22: CORDOBA | I22: BUENAVISTA | J22: DISTRICOL PANADERIA Y HELADERI | K22: REDEBAN | L22: FO-25-1587162 | M22: 45926.382 | N22: 45927.558 | O22: NO | P22: USUARIO | Q22: LECTOR DE TARJETAS | R22: OBSTRUCCION DEL LECTOR | U22: CERRADO | V22: 26/09/2025 SE ESCALA PARA VISITA. LLAMAR ANTES DE VISITAR, CONFIRMAR FALLA Y DATOS | 27/09/2025 SE VISITA SITIO, SE REALIZA LIMPIEZA DE LECTOR DE TARJETAS EN PINPAD YA QUE SE ENCONTRABA OBSTRUIDO. SE REALIZAN PRUEBAS EXITOSAS | W22: VISITA_TÉCNICA | X22: 99DZZ458 | Y22: TIPO II | Z22: TERRESTRE | AA22: COGOLLO VERTEL EDER LUIS | AB22: 1 | AC22: 0 | AD22: 0 | AE22: 0 | AF22: =IF(W22="SOPORTE_TELEFÓNICO",'BASE LIQUIDACION'!$B$10,IF(Y22="TIPO I",'BASE LIQUIDACION'!$C$3,IF(Y22="TIPO II",'BASE LIQUIDACION'!$C$4,IF(Y22="TIPO III",'BASE LIQUIDACION'!$C$5,'BASE LIQUIDACION'!$C$7)))) -> 163813.56 | AG22: =IF(W22="SOPORTE_TELEFÓNICO",'BASE LIQUIDACION'!$B$10,(AB22*AF22+AC22*'BASE LIQUIDACION'!$B$12+AD22*'BASE LIQUIDACION'!$B$11+INCIDENTES!AE22*'BASE LIQUIDACION'!$B$13)) -> 163813.56
A23: MEDELLIN | B23: =VLOOKUP(A23,'CENTRO DE COSTOS'!A:D,4,FALSE) -> JUAN SEBASTIÁN RÍOS CASTRILLÓN | C23: =VLOOKUP(A23,'CENTRO DE COSTOS'!A:D,2,FALSE) -> 0004-0005 | D23: 5001 | E23: 2797495 | F23: 26225 | G23: INCIDENTE | H23: ANTIOQUIA | I23: MEDELLIN | J23: COMCARD MED MINUCENTER | K23: REDEBAN | L23: FO-25-1586779 | M23: 45926.358 | N23: 45926.548 | O23: NO | P23: USUARIO | Q23: MANTENIMIENTO | R23: MANTENIMIENTO GENERAL | U23: CERRADO | V23: 26/09/2025 SE ESCALA PARA VISITA. LLAMAR ANTES DE VISITAR, CONFIRMAR FALLA Y DATOS | 26/09/2025 SE REALIZA LIMPIEZA DEL TECLADO DEL DATÁFONO Y QUEDA FUNCIONANDO, SE REINICIA Y SE REALIZAN PRUEBAS, TODO OK | W23: VISITA_TÉCNICA | X23: 99991001 | Y23: TIPO I | Z23: TERRESTRE | AA23: CARDONA MOLINA BROLIN STIVEN | AB23: 1 | AC23: 0 | AD23: 0 | AE23: 0 | AF23: =IF(W23="SOPORTE_TELEFÓNICO",'BASE LIQUIDACION'!$B$10,IF(Y23="TIPO I",'BASE LIQUIDACION'!$C$3,IF(Y23="TIPO II",'BASE LIQUIDACION'!$C$4,IF(Y23="TIPO III",'BASE LIQUIDACION'!$C$5,'BASE LIQUIDACION'!$C$7)))) -> 65960.474 | AG23: =IF(W23="SOPORTE_TELEFÓNICO",'BASE LIQUIDACION'!$B$10,(AB23*AF23+AC23*'BASE LIQUIDACION'!$B$12+AD23*'BASE LIQUIDACION'!$B$11+INCIDENTES!AE23*'BASE LIQUIDACION'!$B$13)) -> 65960.474
A24: BOGOTA | B24: =VLOOKUP(A24,'CENTRO DE COSTOS'!A:D,4,FALSE) -> WILLIAM ASDRUBAL ROZO ROZO | C24: =VLOOKUP(A24,'CENTRO DE COSTOS'!A:D,2,FALSE) -> 0004-0004 | D24: 11001 | E24: 2797427 | F24: 64118 | G24: INCIDENTE | H24: CUNDINAMARCA | I24: BOGOTA | J24: BARRIO BOSA LAURELES BOGOTA 2 | K24: REDEBAN | L24: FO-25-1586787 | M24: 45926.343 | N24: 45926.687 | O24: NO | P24: USUARIO | Q24: USUARIOS | R24: CREACION DE USUARIOS | U24: CERRADO | V24: 26/09/2025 SE ESCALA PARA VISITA. LLAMAR ANTES DE VISITAR, CONFIRMAR FALLA Y DATOS | 26/09/2025 SE REALIZA CAMBIO DE CLAVE SUPERVISOR ( CIERRES Y DUPLICADO) PRUEBA OK | W24: VISITA_TÉCNICA | X24: OA00O731 | Y24: TIPO I | Z24: TERRESTRE | AA24: ORTIZ MARTINEZ STIVEN | AB24: 1 | AC24: 0 | AD24: 0 | AE24: 0 | AF24: =IF(W24="SOPORTE_TELEFÓNICO",'BASE LIQUIDACION'!$B$10,IF(Y24="TIPO I",'BASE LIQUIDACION'!$C$3,IF(Y24="TIPO II",'BASE LIQUIDACION'!$C$4,IF(Y24="TIPO III",'BASE LIQUIDACION'!$C$5,'BASE LIQUIDACION'!$C$7)))) -> 65960.474 | AG24: =IF(W24="SOPORTE_TELEFÓNICO",'BASE LIQUIDACION'!$B$10,(AB24*AF24+AC24*'BASE LIQUIDACION'!$B$12+AD24*'BASE LIQUIDACION'!$B$11+INCIDENTES!AE24*'BASE LIQUIDACION'!$B$13)) -> 65960.474
A25: MEDELLIN | B25: =VLOOKUP(A25,'CENTRO DE COSTOS'!A:D,4,FALSE) -> JUAN SEBASTIÁN RÍOS CASTRILLÓN | C25: =VLOOKUP(A25,'CENTRO DE COSTOS'!A:D,2,FALSE) -> 0004-0005 | D25: 5001 | E25: 2795568 | F25: 80717 | G25: INCIDENTE | H25: ANTIOQUIA | I25: MEDELLIN | J25: DISTRICOL VARIEDADES Y DETALLE | K25: REDEBAN | L25: FO-25-1585334 | M25: 45925.671 | N25: 45926.527 | O25: NO | P25: USUARIO | Q25: MANTENIMIENTO | R25: MANTENIMIENTO GENERAL | U25: CERRADO | V25: 25/09/2025 SE ESCALA PARA VISITA. LLAMAR ANTES DE VISITAR, CONFIRMAR FALLA Y DATOS | 26/09/2025 SE LLAMA AL USUARIO PARA CONFIRMAR VISITA Y NOS COMENTA QUE RETIRÓ EL ROLLO Y REALIZÓ UNA LIMPIEZA Y LA IMPRESORA DEL DATÁFONO VOLVIO A FUNCIONAR CORRECTAMENTE | W25: SOPORTE_TELEFÓNICO | X25: 0 | Y25: TIPO I | Z25: TERRESTRE | AA25: CARDONA MOLINA BROLIN STIVEN | AB25: 0 | AC25: 0 | AD25: 0 | AE25: 0 | AF25: =IF(W25="SOPORTE_TELEFÓNICO",'BASE LIQUIDACION'!$B$10,IF(Y25="TIPO I",'BASE LIQUIDACION'!$C$3,IF(Y25="TIPO II",'BASE LIQUIDACION'!$C$4,IF(Y25="TIPO III",'BASE LIQUIDACION'!$C$5,'BASE LIQUIDACION'!$C$7)))) -> 37904.654 | AG25: =IF(W25="SOPORTE_TELEFÓNICO",'BASE LIQUIDACION'!$B$10,(AB25*AF25+AC25*'BASE LIQUIDACION'!$B$12+AD25*'BASE LIQUIDACION'!$B$11+INCIDENTES!AE25*'BASE LIQUIDACION'!$B$13)) -> 37904.654
A26: IBAGUE | B26: =VLOOKUP(A26,'CENTRO DE COSTOS'!A:D,4,FALSE) -> KEVIN ALEXIS CORZO BUSTOS | C26: =VLOOKUP(A26,'CENTRO DE COSTOS'!A:D,2,FALSE) -> 0004-0007 | D26: 73001 | E26: 2795532 | F26: 80945 | G26: INCIDENTE | H26: TOLIMA | I26: IBAGUE | J26: BARRIO LA POLA IBAGUE 7 | K26: REDEBAN | L26: FO-25-1585139 | M26: 45925.665 | N26: 45926.409 | O26: NO | P26: USUARIO | Q26: MANTENIMIENTO | R26: MANTENIMIENTO GENERAL | U26: CERRADO | V26: 25/09/2025 SE ESCALA PARA VISITA. LLAMAR ANTES DE VISITAR, CONFIRMAR FALLA Y DATOS | 26/09/2025 SE LE EXPLICA AL SEÑOR JHONY QUIMBAYO, DE CÓMO APAGAR CORRECTAMENTE EL EQUIPO PARA QUE NO TENGA PROBLEMAS CON LA IMPRESORA DE RECIBOS. SE HACEN PRUEBAS DE TRANSACCIONES TODO OK Y SE VERIFICA LA IMPRESORA. | W26: VISITA_TÉCNICA | X26: FIZZZ331 | Y26: TIPO I | Z26: TERRESTRE | AA26: VARGAS HERRERA JHON JAIRO | AB26: 1 | AC26: 0 | AD26: 0 | AE26: 0 | AF26: =IF(W26="SOPORTE_TELEFÓNICO",'BASE LIQUIDACION'!$B$10,IF(Y26="TIPO I",'BASE LIQUIDACION'!$C$3,IF(Y26="TIPO II",'BASE LIQUIDACION'!$C$4,IF(Y26="TIPO III",'BASE LIQUIDACION'!$C$5,'BASE LIQUIDACION'!$C$7)))) -> 65960.474 | AG26: =IF(W26="SOPORTE_TELEFÓNICO",'BASE LIQUIDACION'!$B$10,(AB26*AF26+AC26*'BASE LIQUIDACION'!$B$12+AD26*'BASE LIQUIDACION'!$B$11+INCIDENTES!AE26*'BASE LIQUIDACION'!$B$13)) -> 65960.474
A27: BOGOTA | B27: =VLOOKUP(A27,'CENTRO DE COSTOS'!A:D,4,FALSE) -> WILLIAM ASDRUBAL ROZO ROZO | C27: =VLOOKUP(A27,'CENTRO DE COSTOS'!A:D,2,FALSE) -> 0004-0004 | D27: 25754 | E27: 2793909 | F27: 80698 | G27: INCIDENTE | H27: CUNDINAMARCA | I27: SOACHA | J27: BARRIO SAN HUMBERTO SOACHA 3 | K27: REDEBAN | L27: FO-25-1583521 | M27: 45925.507 | N27: 45925.69 | O27: NO | P27: USUARIO | Q27: CIERRE | R27: COMERCIO NO REALIZA CIERRE | U27: CERRADO | V27: 25/09/2025 SE ESCALA PARA VISITA. LLAMAR ANTES DE VISITAR, CONFIRMAR FALLA Y DATOS | 25/09/2025 DURANTE LA VISITA TECNICA ENCONTRAMOS QUE EL DATÁFONO NO LE PERMITE REALIZAR EL CIERRE POR ACUMULACIÓN DE TRANSACCIONES SE REALIZA BORRADO DE TRANSACCIONES ADICIONAL SE REALIZAN TRANSACCIONES DE PRUEBA Y SE BRINDA INFORMACIÓN DEL CORRECTO CIERRE QUEDANDO OKAY LA FUNCIONALIDAD DE CIERRE SIN NOVEDAD EN EL INCIDENTE A CONFORMIDAD CORRESPONSAL BANCARIO | W27: VISITA_TÉCNICA | X27: V8ZZZ365 | Y27: TIPO I | Z27: TERRESTRE | AA27: GALEANO SORIANO JUAN DAVID | AB27: 1 | AC27: 0 | AD27: 0 | AE27: 0 | AF27: =IF(W27="SOPORTE_TELEFÓNICO",'BASE LIQUIDACION'!$B$10,IF(Y27="TIPO I",'BASE LIQUIDACION'!$C$3,IF(Y27="TIPO II",'BASE LIQUIDACION'!$C$4,IF(Y27="TIPO III",'BASE LIQUIDACION'!$C$5,'BASE LIQUIDACION'!$C$7)))) -> 65960.474 | AG27: =IF(W27="SOPORTE_TELEFÓNICO",'BASE LIQUIDACION'!$B$10,(AB27*AF27+AC27*'BASE LIQUIDACION'!$B$12+AD27*'BASE LIQUIDACION'!$B$11+INCIDENTES!AE27*'BASE LIQUIDACION'!$B$13)) -> 65960.474
