Workbook
Name A: #REF!
Name A: #REF!
Name ACTIVIDAD: [1]Hoja2!$P$2:$P$30
Name Actividad: [2]Formulas!$H$2:$H$5000
Name Analistas: '[3]Listas Desplegables'!$T$2:$T$7
Name arearesponsable: '[4]Listas desplegables'!$BB$2:$BB$100
Name CCO: [5]Tecnicos!$A$2:$A$1000
Name Clientes: [6]Clientes!$A$2:$A$100
Name Clientes: [2]Clientes!$A$2:$A$100
Name COORDINADOR: [1]Hoja2!$D$2:$D$30
Name Coordinadores: [7]Coordinadores!$A$2:$A$1000
Name Coordinadores: [2]Coordinadores!$A$2:$A$1000
Name DOCUMENTADOR: [1]Hoja2!$A$2:$A$30
Name ES: [1]Hoja2!$K$2:$K$30
Name ESS: [1]Hoja2!$K$2:$K$30
Name Estado: [6]Formulas!$K$2:$K$5000
Name Estado: [2]Formulas!$K$2:$K$5000
Name ESTADOACTIVIDAD: [1]Hoja2!$M$2:$M$30
Name ESTADOS: '[8]Listas desplegables'!$B$1:$D$1
Name ESTADOS: '[9]Listas desplegables'!$B$1:$D$1
Name ESTADOSCIERRES: '[10]lista desplegable'!$CX$1:$DA$1
Name Facturacion: '[11]Listas desplegables'!$AO$1:$AR$1
Name FACTURACIÓN: '[8]Listas desplegables'!$Y$1:$AB$1
Name FACTURACIÓN: '[9]Listas desplegables'!$Y$1:$AB$1
Name falla: #REF!
Name Fallas: '[12]Listas desplegables'!$F$2:$L$2
Name Fallas: '[13]Listas desplegables'!$F$2:$L$2
Name Grupo_Falla: '[14]Listas Desplegables'!$CH$2:$CH$5
Name Grupo_Falla: '[15]Listas Desplegables'!$CH$2:$CH$5
Name inconservmanager: '[16]Listas desplegables'!$BC$2:$BC$100
Name inconservmanager: '[4]Listas desplegables'!$BC$2:$BC$100
Name INCUMPLIMIENTO: '[4]Listas desplegables'!$AK$1:$AN$1
Name INCUMPLIMIENTO: '[17]Listas desplegables'!$AT$1:$AX$1
Name LISTA: [18]Dptos!$A$1139:$A$1171
Name LISTA: [19]Dptos!$A$1139:$A$1171
Name LISTA2: #REF!
Name LISTA2: #REF!
Name LOLO: [20]Coordinadores!$A$2:$A$1000
Name solicitudes: '[11]Listas desplegables'!$U$1:$AF$1
Name solicitudes: '[21]Listas desplegables'!$AF$1:$AQ$1
Name Tecnicos: [6]Tecnicos!$A$2:$A$1000
Name Tecnicos: [2]Tecnicos!$A$2:$A$1000
Name Version: [22]Formulas!$I$2:$I$3
Name Version: [2]Formulas!$I$2:$I$3

Sheet Detalle REDEBAN
A1: FACTURACIÓN ACTIVIDADES REDEBAN CB BANCOLOMBIA Y AVAL
A2: 1 AL 30 DE SEPTIEMBRE 2025
A4: CONCEPTOS | B4: CANTIDAD | C4: TOTAL
A5: Aperturas Bancolombia | B5: =COUNTA('APERTURAS BANCOLOMBIA'!$A:$A)-1 -> 219 | C5: ='APERTURAS BANCOLOMBIA'!AC221 -> 42735836
A6: Incidentes Bancolombia | B6: =COUNTA('INCIDENTES BANCOLOMBIA'!A:A)-1 -> 1194 | C6: ='INCIDENTES BANCOLOMBIA'!AF1196 -> 1.9131574e+08
A7: Gestión de Campo Bancolombia | B7: =COUNTA('OC BANCOLOMBIA'!A:A)-1 -> 447 | C7: ='OC BANCOLOMBIA'!AF449 -> 70068670
A8: Soporte Papelería Bancolombia | B8: =COUNTA(PAPELERIA!A:A)-1 -> 1946 | C8: =PAPELERIA!AE1948 -> 82774117
A9: Aperturas Aval | B9: =COUNTA('APERTURAS AVAL'!A:A)-1 -> 188 | C9: ='APERTURAS AVAL'!AB190 -> 39272916
A10: Incidentes Aval | B10: =COUNTA('INCIDENTES AVAL'!A:A)-1 -> 283 | C10: ='INCIDENTES AVAL'!AD285 -> 164964.32
A11: Gestión de Campo Aval | B11: =COUNTA('OC AVAL'!A:A)-1 -> 63 | C11: ='OC AVAL'!AF65 -> 7805089.8
A12: Aperturas BBVA | B12: =COUNTA('APERTURAS BBVA'!A:A)-1 -> 0 | C12: ='APERTURAS BBVA'!AH3 -> 0
A13: Gestión de Campo BBVA | B13: =COUNTA('OC BBVA'!A:A)-1 -> 0 | C13: ='OC BBVA'!AF4 -> 0
A14: Incidentes BBVA | B14: =COUNTA('INCIDENTES BBVA'!A:A)-1 -> 0 | C14: ='INCIDENTES BBVA'!AD5 -> 0
A15: SUBTOTAL | C15: =SUM(C5:C14) -> 4.3413733e+08
A16: Iva | C16: =C15*0.19 -> 82486092
A17: TOTAL | B17: TOTAL | C17: =C15+C16 -> 5.1662342e+08

Sheet BASE LIQUIDACION REDEBAN 2025
A1: Tipificación | B1: Implementaciones | C1: Incidentes – Ordenes de Cambio | D1: Fallida | G1: Tipificación | H1: Actividad sin cambio de datafono | J1: Actividad + adicional cambio de datafono | L1: Visita Fallida | N1: Incremento 2025
A2: TIPO I | B2: =71384.4052*(1+$N$2) -> 75096.394 | C2: =62699.6885*(1+$N$2) -> 65960.072 | D2: =35693.4343*(1+$N$2) -> 37549.493 | H2: Instalación Pinpad + HUB | I2: Segunda actividad en mismo comercio, misma visita | J2: Instalación Pinpad + HUB | K2: Segunda actividad en mismo comercio, misma visita | N2: 0.052
A3: TIPO II | B3: =155716.4408*(1+$N$2) -> 163813.7 | C3: =137802.16*(1+$N$2) -> 144967.87 | D3: =117879.8485*(1+$N$2) -> 124009.6 | G3: Tipo I | H3: =31819.23994686*(1+$N$2) -> 33473.84 | I3: =26222.67548178*(1+$N$2) -> 27586.255 | J3: =51196.46628516*(1+$N$2) -> 53858.683 | K3: =42157.66342524*(1+$N$2) -> 44349.862 | L3: =28948.10610808*(1+$N$2) -> 30453.408
A4: TIPO III | B4: =262099.6015*(1+$N$2) -> 275728.78 | C4: =262099.6015*(1+$N$2) -> 275728.78 | D4: =262099.6015*(1+$N$2) -> 275728.78 | G4: Tipo II | H4: =98014.03066668*(1+$N$2) -> 103110.76 | I4: =26222.67548178*(1+$N$2) -> 27586.255 | J4: =119562.49505524*(1+$N$2) -> 125779.74 | K4: =42157.66342524*(1+$N$2) -> 44349.862 | L4: =94765.6295813*(1+$N$2) -> 99693.442
A5: TIPO IV | B5: =479878.9419*(1+$N$2) -> 504832.65 | C5: =455882.9625*(1+$N$2) -> 479588.88 | D5: =370911.6746*(1+$N$2) -> 390199.08 | G5: Tipo III | H5: =189140.9827006*(1+$N$2) -> 198976.31 | I5: =26222.67548178*(1+$N$2) -> 27586.255 | J5: =200461.60194168*(1+$N$2) -> 210885.61 | K5: =42157.66342524*(1+$N$2) -> 44349.862 | L5: =171492.68108896*(1+$N$2) -> 180410.3
A6: Destino Aéreo | B6: =939603.5767*(1+$N$2) -> 988462.96 | C6: a partir del 5to servicio | G6: Tipo IV | H6: =461621.60109668*(1+$N$2) -> 485625.92 | I6: =26222.67548178*(1+$N$2) -> 27586.255 | J6: =461621.60109668*(1+$N$2) -> 485625.92 | K6: =42157.66342524*(1+$N$2) -> 44349.862 | L6: =461621.60109668*(1+$N$2) -> 485625.92
G7: * Tipo IV Especial Donde se requiera desplazamiento aéreo o fluvial será facturado el valor de la actividad y adicional el valor de $988.463 por cada 5 actividades de esta tipología
A8: Tarifas para día adicional de actividades:
A9: Tipificación | B9: Día adicional- menos de dos horas | C9: Medio día adicional | D9: Día adicional- más de 4 horas
A10: Tipo I | B10: =71384.4052*(1+$N$2) -> 75096.394 | C10: =133455.9267*(1+$N$2) -> 140395.63 | D10: =191225.1201*(1+$N$2) -> 201168.83 | G10: Actividad | H10: Unidad | I10: Valor Unitario
A11: Tipo II | B11: =133455.9267*(1+$N$2) -> 140395.63 | C11: =191225.1201*(1+$N$2) -> 201168.83 | D11: =257740.6152*(1+$N$2) -> 271143.13 | G11: Gestión telefónica y cierre de incidente de bloqueo | H11: Unidad | I11: =17639.19516086*(1+$N$2) -> 18556.433
A12: Tipo III | B12: =186821.7926*(1+$N$2) -> 196536.53 | C12: =248892.0824*(1+$N$2) -> 261834.47 | D12: =306662.5075*(1+$N$2) -> 322608.96 | G12: Servicio de cierre de incidente de bloqueo | H12: Unidad | I12: =4810.80785492*(1+$N$2) -> 5060.9699
A13: Tipo IV | B13: =186821.7926*(1+$N$2) -> 196536.53 | C13: =248892.0824*(1+$N$2) -> 261834.47 | D13: =306662.5075*(1+$N$2) -> 322608.96
A16: Servicio | B16: Tarifa actividad | D16: VALOR DE LA TERMINAL ADICIONAL | E16: VALOR DE INSTALACIÓN DE BASE EN "Y"
A17: Papelería – Tarifa única | B17: =34010.9321*(1+$N$2) -> 35779.501 | D17: =20537.3658*(1+$N$2) -> 21605.309 | E17: =10737.9606*(1+$N$2) -> 11296.335
A18: Papelería Tipo II - Visita técnica | B18: =64310*(1+$N$2) -> 67654.12
A19: Solución telefónica | B19: =39202.5476*(1+$N$2) -> 41241.08
A22: Traifas 2024
A23: Tipificación | B23: Implementaciones | C23: Incidentes – Ordenes de Cambio | D23: Fallida | G23: Tipificación | H23: Actividad sin cambio de datafono | J23: Actividad + adicional cambio de datafono | L23: Visita Fallida
A24: TIPO I | B24: 71384.405 | C24: 62699.689 | D24: 35693.434 | H24: Instalación Pinpad + HUB | I24: Segunda actividad en mismo comercio, misma visita | J24: Instalación Pinpad + HUB | K24: Segunda actividad en mismo comercio, misma visita
A25: TIPO II | B25: 155716.44 | C25: 137802.16 | D25: 117879.85 | G25: Tipo I | H25: 31819.24 | I25: 26222.675 | J25: 51196.466 | K25: 42157.663 | L25: 28948.106
A26: TIPO III | B26: 262099.6 | C26: 262099.6 | D26: 262099.6 | G26: Tipo II | H26: 98014.031 | I26: 26222.675 | J26: 119562.5 | K26: 42157.663 | L26: 94765.63
A27: TIPO IV | B27: 479878.94 | C27: 455882.96 | D27: 370911.67 | G27: Tipo III | H27: 189140.98 | I27: 26222.675 | J27: 200461.6 | K27: 42157.663 | L27: 171492.68
A28: Destino Aéreo | B28: 939603.58 | C28: a partir del 5to servicio | G28: Tipo IV | H28: 461621.6 | I28: 26222.675 | J28: 461621.6 | K28: 42157.663 | L28: 461621.6
G29: * Tipo IV Especial Donde se requiera desplazamiento aéreo o fluvial será facturado el valor de la actividad y adicional el valor de $939,604 por cada 5 actividades de esta tipología
A30: Tarifas para día adicional de actividades:
A31: Tipificación | B31: Día adicional- menos de dos horas | C31: Medio día adicional | D31: Día adicional- más de 4 horas
A32: Tipo I | B32: 71384.405 | C32: 133455.93 | D32: 191225.12 | G32: Actividad | H32: Unidad | I32: Valor Unitario
A33: Tipo II | B33: 133455.93 | C33: 191225.12 | D33: 257740.62 | G33: Gestión telefónica y cierre de incidente de bloqueo | H33: Unidad | I33: 17639.195
A34: Tipo III | B34: 186821.79 | C34: 248892.08 | D34: 306662.51 | G34: Servicio de cierre de incidente de bloqueo | H34: Unidad | I34: 4810.8079
A35: Tipo IV | B35: 186821.79 | C35: 248892.08 | D35: 306662.51
A38: Servicio | B38: Tarifa actividad | D38: VALOR DE LA TERMINAL ADICIONAL | E38: VALOR DE INSTALACIÓN DE BASE EN "Y"
A39: Papelería – Tarifa única | B39: 34010.932 | D39: 20537.366 | E39: 10737.961
A40: Papelería Tipo II - Visita técnica | B40: 64310
A41: Solución telefónica | B41: 39202.548

Sheet CENTRO DE COSTOS
A1: CIUDAD | B1: CENTRO_COSTO | C1: DESCRIPCION | D1: COORDINADOR
A2: APARTADO | B2: 0004-0005 | C2: Redeban Noroccidente (Medellín) | D2: JUAN SEBASTIÁN RÍOS CASTRILLÓN
A3: BARRANQUILLA | B3: 0004-0001 | C3: Redeban Costa (Barranqullla) | D3: JOSE MAURICIO HERNANDEZ ROJAS
A4: BOGOTA | B4: 0004-0004 | C4: Redeban Centro ( Bogotá) | D4: WILLIAM ASDRUBAL ROZO ROZO
A5: BUCARAMANGA | B5: 0004-0008 | C5: Redeban Santander | D5: MIGUEL JULIÁN HERNÁNDEZ GUARÍN
A6: CALI | B6: 0004-0003 | C6: Redeban Suroccidente (Cali) | D6: DIEGO FERNANDO HENAO CARDONA
A7: CARTAGENA | B7: 0004-0001 | C7: Redeban Costa (Barranqullla) | D7: JOSE MAURICIO HERNANDEZ ROJAS
A8: CUCUTA | B8: 0004-0008 | C8: Redeban Santander | D8: MIGUEL JULIÁN HERNÁNDEZ GUARÍN
A9: FLORENCIA | B9: 0004-0007 | C9: Redeban Oriente (Otros) | D9: KEVIN ALEXIS CORZO BUSTOS
A10: IBAGUE | B10: 0004-0007 | C10: Redeban Oriente (Otros) | D10: KEVIN ALEXIS CORZO BUSTOS
A11: MANIZALES | B11: 0004-0002 | C11: Redeban Eje Cafetero (Pereira) | D11: DIEGO FERNANDO HENAO CARDONA
A12: MEDELLIN | B12: 0004-0005 | C12: Redeban Noroccidente (Medellín) | D12: JUAN SEBASTIÁN RÍOS CASTRILLÓN
... A23: YOPAL | B23: 0004-0007 | C23: Redeban Oriente (Otros) | D23: KEVIN ALEXIS CORZO BUSTOS

Sheet Tablas dinámicas
A1: APERTURAS BANCOLOMBIA | G1: NOMBRE DE CC | H1: Suma de VALOR CC | I1: Suma de VALOR CC2
A2: COORDINADOR | B2: CENTRO DE COSTOS LÍNEACOM | C2: Suma de VALOR FACTURABLE A LA RED | D2: NOMBRE DE CC | E2: VALOR CC | G2: Redeban Centro ( Bogotá) | H2: 48969421 | I2: 0.10471527
A3: DIEGO FERNANDO HENAO CARDONA | B3: 0004-0002 | C3: 1231369.1 | D3: =VLOOKUP(B3,'CENTRO DE COSTOS'!B:C,2,0) -> Redeban Eje Cafetero (Pereira) | E3: =C3 -> 1231369.1 | G3: Redeban Costa (Barranqullla) | H3: 75691830 | I3: 0.16185796
B4: 0004-0003 | C4: 10239672 | D4: =VLOOKUP(B4,'CENTRO DE COSTOS'!B:C,2,0) -> Redeban Suroccidente (Cali) | E4: =C4 -> 10239672 | G4: Redeban Eje Cafetero (Pereira) | H4: 17132270 | I4: 0.036635318
A5: JOSE MAURICIO HERNANDEZ ROJAS | B5: 0004-0001 | C5: 5024949.9 | D5: =VLOOKUP(B5,'CENTRO DE COSTOS'!B:C,2,0) -> Redeban Costa (Barranqullla) | E5: =C5 -> 5024949.9 | G5: Redeban Noroccidente (Medellín) | H5: 1.0878126e+08 | I5: 0.23261575
A6: JUAN SEBASTIÁN RÍOS CASTRILLÓN | B6: 0004-0005 | C6: 8253502.7 | D6: =VLOOKUP(B6,'CENTRO DE COSTOS'!B:C,2,0) -> Redeban Noroccidente (Medellín) | E6: =C6 -> 8253502.7 | G6: Redeban Oriente (Otros) | H6: 64858437 | I6: 0.13869204
A7: KEVIN ALEXIS CORZO BUSTOS | B7: 0004-0007 | C7: 4179634.7 | D7: =VLOOKUP(B7,'CENTRO DE COSTOS'!B:C,2,0) -> Redeban Oriente (Otros) | E7: =C7 -> 4179634.7 | G7: Redeban Santander | H7: 79260436 | I7: 0.169489
A8: MIGUEL JULIÁN HERNÁNDEZ GUARÍN | B8: 0004-0008 | C8: 11574428 | D8: =VLOOKUP(B8,'CENTRO DE COSTOS'!B:C,2,0) -> Redeban Santander | E8: =C8 -> 11574428 | G8: Redeban Suroccidente (Cali) | H8: 72949894 | I8: 0.15599466
A9: WILLIAM ASDRUBAL ROZO ROZO | B9: 0004-0004 | C9: 2232279.1 | D9: =VLOOKUP(B9,'CENTRO DE COSTOS'!B:C,2,0) -> Redeban Centro ( Bogotá) | E9: =C9 -> 2232279.1 | G9: Total general | H9: 4.6764355e+08 | I9: 1
A10: Total general | C10: 42735836
A15: INCIDENTES BANCOLOMBIA
A16: COORDINADOR | B16: CENTRO DE COSTOS LÍNEACOM | C16: Suma de VALOR FACTURABLE A LA RED | D16: NOMBRE DE CC | E16: VALOR CC
A17: DIEGO FERNANDO HENAO CARDONA | B17: 0004-0002 | C17: 7477346.2 | D17: =VLOOKUP(B17,'CENTRO DE COSTOS'!B:C,2,0) -> Redeban Eje Cafetero (Pereira) | E17: =C17 -> 7477346.2
B18: 0004-0003 | C18: 24817715 | D18: =VLOOKUP(B18,'CENTRO DE COSTOS'!B:C,2,0) -> Redeban Suroccidente (Cali) | E18: =C18 -> 24817715
A19: JOSE MAURICIO HERNANDEZ ROJAS | B19: 0004-0001 | C19: 38450028 | D19: =VLOOKUP(B19,'CENTRO DE COSTOS'!B:C,2,0) -> Redeban Costa (Barranqullla) | E19: =C19 -> 38450028
A20: JUAN SEBASTIÁN RÍOS CASTRILLÓN | B20: 0004-0005 | C20: 56740009 | D20: =VLOOKUP(B20,'CENTRO DE COSTOS'!B:C,2,0) -> Redeban Noroccidente (Medellín) | E20: =C20 -> 56740009
A21: KEVIN ALEXIS CORZO BUSTOS | B21: 0004-0007 | C21: 22067473 | D21: =VLOOKUP(B21,'CENTRO DE COSTOS'!B:C,2,0) -> Redeban Oriente (Otros) | E21: =C21 -> 22067473
A22: MIGUEL JULIÁN HERNÁNDEZ GUARÍN | B22: 0004-0008 | C22: 26307565 | D22: =VLOOKUP(B22,'CENTRO DE COSTOS'!B:C,2,0) -> Redeban Santander | E22: =C22 -> 26307565
A23: WILLIAM ASDRUBAL ROZO ROZO | B23: 0004-0004 | C23: 15455600 | D23: =VLOOKUP(B23,'CENTRO DE COSTOS'!B:C,2,0) -> Redeban Centro ( Bogotá) | E23: =C23 -> 15455600
A24: Total general | C24: 1.9131574e+08
A30: ORDENES DE CAMBIO BANCOLOMBIA
A31: COORDINADOR | B31: CENTRO DE COSTOS LÍNEACOM | C31: Suma de VALOR TOTAL | D31: NOMBRE DE CC | E31: VALOR CC
A32: DIEGO FERNANDO HENAO CARDONA | B32: 0004-0002 | C32: 3069545.2 | D32: =VLOOKUP(B32,'CENTRO DE COSTOS'!B:C,2,0) -> Redeban Eje Cafetero (Pereira) | E32: =C32 -> 3069545.2
B33: 0004-0003 | C33: 11145765 | D33: =VLOOKUP(B33,'CENTRO DE COSTOS'!B:C,2,0) -> Redeban Suroccidente (Cali) | E33: =C33 -> 11145765
A34: JOSE MAURICIO HERNANDEZ ROJAS | B34: 0004-0001 | C34: 9237693.7 | D34: =VLOOKUP(B34,'CENTRO DE COSTOS'!B:C,2,0) -> Redeban Costa (Barranqullla) | E34: =C34 -> 9237693.7
A35: JUAN SEBASTIÁN RÍOS CASTRILLÓN | B35: 0004-0005 | C35: 8943557.5 | D35: =VLOOKUP(B35,'CENTRO DE COSTOS'!B:C,2,0) -> Redeban Noroccidente (Medellín) | E35: =C35 -> 8943557.5
A36: KEVIN ALEXIS CORZO BUSTOS | B36: 0004-0007 | C36: 14079576 | D36: =VLOOKUP(B36,'CENTRO DE COSTOS'!B:C,2,0) -> Redeban Oriente (Otros) | E36: =C36 -> 14079576
A37: MIGUEL JULIÁN HERNÁNDEZ GUARÍN | B37: 0004-0008 | C37: 15148756 | D37: =VLOOKUP(B37,'CENTRO DE COSTOS'!B:C,2,0) -> Redeban Santander | E37: =C37 -> 15148756
A38: WILLIAM ASDRUBAL ROZO ROZO | B38: 0004-0004 | C38: 8443777.4 | D38: =VLOOKUP(B38,'CENTRO DE COSTOS'!B:C,2,0) -> Redeban Centro ( Bogotá) | E38: =C38 -> 8443777.4
A39: Total general | C39: 70068670
A45: PAPELERIA BANCOLOMBIA
A46: COORDINADOR | B46: CENTRO DE COSTOS LÍNEACOM | C46: Suma de VALOR TOTAL | D46: NOMBRE DE CC | E46: VALOR CC
A47: DIEGO FERNANDO HENAO CARDONA | B47: 0004-0002 | C47: 4112644.4 | D47: =VLOOKUP(B47,'CENTRO DE COSTOS'!B:C,2,0) -> Redeban Eje Cafetero (Pereira) | E47: =C47 -> 4112644.4
B48: 0004-0003 | C48: 12574586 | D48: =VLOOKUP(B48,'CENTRO DE COSTOS'!B:C,2,0) -> Redeban Suroccidente (Cali) | E48: =C48 -> 12574586
A49: JOSE MAURICIO HERNANDEZ ROJAS | B49: 0004-0001 | C49: 15701154 | D49: =VLOOKUP(B49,'CENTRO DE COSTOS'!B:C,2,0) -> Redeban Costa (Barranqullla) | E49: =C49 -> 15701154
A50: JUAN SEBASTIÁN RÍOS CASTRILLÓN | B50: 0004-0005 | C50: 18757071 | D50: =VLOOKUP(B50,'CENTRO DE COSTOS'!B:C,2,0) -> Redeban Noroccidente (Medellín) | E50: =C50 -> 18757071
A51: KEVIN ALEXIS CORZO BUSTOS | B51: 0004-0007 | C51: 8237418.6 | D51: =VLOOKUP(B51,'CENTRO DE COSTOS'!B:C,2,0) -> Redeban Oriente (Otros) | E51: =C51 -> 8237418.6
A52: MIGUEL JULIÁN HERNÁNDEZ GUARÍN | B52: 0004-0008 | C52: 11693967 | D52: =VLOOKUP(B52,'CENTRO DE COSTOS'!B:C,2,0) -> Redeban Santander | E52: =C52 -> 11693967
A53: WILLIAM ASDRUBAL ROZO ROZO | B53: 0004-0004 | C53: 11697275 | D53: =VLOOKUP(B53,'CENTRO DE COSTOS'!B:C,2,0) -> Redeban Centro ( Bogotá) | E53: =C53 -> 11697275
A54: Total general | C54: 82774117
...

Sheet APERTURAS BANCOLOMBIA
A1: CIUDAD SEDE | B1: COORDINADOR | C1: CENTRO DE COSTOS LÍNEACOM | D1: CÓDIGO DANE | E1: TA/CODIGO ACTIVIDAD | F1: CODIGO CB | G1: ACTIVIDAD | H1: TIPO DE APERTURA | I1: DEPARTAMENTO | J1: CIUDAD | K1: NOMBRE DEL CB | L1: RED | M1: FO | N1: FECHA LISTA | O1: FECHA ULTIMA ACTUALIZACION | P1: FORMATO | Q1: CADENA | R1: ESTADO | S1: OBSERVACIONES CLIENTE | T1: FORMA DE ATENCIÓN | U1: TERMINALES | V1: TIPO DE ATENCION | W1: TIPO DE TRAYECTO | X1: NOMBRE DEL TECNICO | Y1: DIAS DE VISITA | Z1: DIA ADICIONAL | AA1: VALOR DIAS ACTIVIDAD FACTURABLES A LA RED | AB1: VALOR DIAS ACOMPAÑAMIENTO FACTURABLES | AC1: VALOR FACTURABLE A LA RED | AD1: CU CB | AE1: COBRO ENTIDAD | AF1: ESTADO | AG1: TIPO | AH1: VAL TIPO | AI1: VAL COSTO | AJ1: OBSERVACIONES | AK1: OBSERVACIONES LINEA
A2: PASTO | B2: =VLOOKUP(A2,'CENTRO DE COSTOS'!A:D,4,FALSE) -> DIEGO FERNANDO HENAO CARDONA | C2: =VLOOKUP(A2,'CENTRO DE COSTOS'!A:D,2,FALSE) -> 0004-0003 | D2: 52621 | E2: TA-25-992136 | F2: 81154 | G2: APERTURA | H2: CB CRECIMIENTO - NUEVO | I2: NARIÑO | J2: ROBERTO PAYAN | K2: BARRIO EL VILLA HORIZONTE ROBERTO PAYAN | L2: REDEBAN | M2: FO-25-1402263 | N2: 45890 | O2: 45902 | P2: UNO A UNO | Q2: UNO A UNO | R2: EJECUTADO | S2: 21-08 SE REALIZA CONTACTO CON EL CLIENTE VIA WHATSAPP, SE HABLA CON LA SRA MARIA ELVIRA PARRA ARTUNDUAGA AL NÚMERO 3236143368 SE VALIDA DIRECCIÓN OK, CANAL OK, DISPONIBILIDAD TOTAL, LLAMAR EL DIA DE LA INSTALACIÓN PARA CONFIRMAR VISITA, AVISO EXTERIOR ALTURA APROX 8 METROS; TOMACORRIENTE CERCANO: SI; TIENE CABINA DE SEGURIDAD; SI 01-09 SE INICIO DESPLAZAMIENTO PERO SOLO HOY SE LLEGO HASTA BARBACOAS, SE VALIDA Y SE DEBE TOMAR LANCHA EL DIA DE MAÑANA 2/09/2025 SE REALIZA INSTALACIÓN DE CORRESPONSAL, SE INSTALAN EQUIPOS CON PRUEBAS EXITOSAS, SE CAPACITA Y SE EVALÚA AL CLIENTE, SE INSTALA PUBLICIDAD COMPLETA, CB QUEDA OPERATIVO. USUARIO SOMOS BANCOLOMBIA ACTIVO | T2: VISITA_TÉCNICA | U2: SIZZZ900 | V2: TIPO IV ESPECIAL | W2: FLUVIAL | X2: PAZ MARTINEZ RICHARD HUMBERTO | Y2: 1 | Z2: 0 | AA2: =IF(V2="TIPO I",'BASE LIQUIDACION REDEBAN 2025'!$B$2,IF(V2="TIPO II",'BASE LIQUIDACION REDEBAN 2025'!$B$3,IF(V2="TIPO III",'BASE LIQUIDACION REDEBAN 2025'!$B$4,IF(V2="TIPO IV",'BASE LIQUIDACION REDEBAN 2025'!$B$5,IF(W2="AEREO",'BASE LIQUIDACION REDEBAN 2025'!$B$6,'BASE LIQUIDACION REDEBAN 2025'!$B$5))))) -> 504832.65 | AB2: =IF(V2="TIPO I",'BASE LIQUIDACION REDEBAN 2025'!$B$10,IF(V2="TIPO II",'BASE LIQUIDACION REDEBAN 2025'!$B$11,IF(V2="TIPO III",'BASE LIQUIDACION REDEBAN 2025'!$B$12,'BASE LIQUIDACION REDEBAN 2025'!$B$13))) -> 196536.53 | AC2: =Y2*AA2+Z2*AB2 -> 504832.65
A3: CALI | B3: =VLOOKUP(A3,'CENTRO DE COSTOS'!A:D,4,FALSE) -> DIEGO FERNANDO HENAO CARDONA | C3: =VLOOKUP(A3,'CENTRO DE COSTOS'!A:D,2,FALSE) -> 0004-0003 | D3: 19256 | E3: TA-25-992167 | F3: 81133 | G3: APERTURA | H3: CB CRECIMIENTO - NUEVO | I3: CAUCA | J3: EL TAMBO | K3: BARRIO PLAYA RICA EL TAMBO 1 | L3: REDEBAN | M3: FO-25-1402365 | N3: 45890 | O3: 45902 | P3: UNO A UNO | Q3: UNO A UNO | R3: EJECUTADO | S3: 21-08 SE REALIZA LLAMADA AL CLIENTE, SE HABLA CON LA SRA YUDY MILENA CALVACHE HERNANDEZ SE VALIDA DIRECCIÓN OK, CANAL OK, DISPONIBILIDAD TOTAL, LLAMAR EL DÍA LA INSTALACIÓN PARA CONFIRMAR VISITA, AVISO EXTERIOR ALTURA: NO INDICA ALTURA ; TOMACORRIENTE CERCANO: SI; TIENE CABINA DE SEGURIDAD: NO 25-08 DADO PROBLEMAS DE TRANSPORTE HACIA EL CORREGIMIENTO NO ES POSIBLE EL DESPLAZAMIENTO EL DIA DE HOY , SE VALIDARA EL DIA DE MAÑANA. 26-08 SE REALIZA LLAMADA CON EL CLIENTE, QUIEN INFORMA QUE PARA PODER REALIZAR EL INGRESO A LA ZONA ES NECESARIO DILIGENCIAR UNOS PERMISOS ESPECIALES, YA QUE SE TRATA DE UNA ZONA CON PRESENCIA GUERRILLERA. DEBIDO A ESTA SITUACIÓN, SE ACUERDA REPROGRAMAR LA APERTURA. 02-09 SE REALIZA INSTALACIÓN DE CORRESPONSAL, SE INSTALAN EQUIPOS CON PRUEBAS EXITOSAS, SE CAPACITA Y SE EVALÚA AL CLIENTE, SE INSTALA PUBLICIDAD COMPLETA, CB QUEDA OPERATIVO. USUARIO SOMOS BANCOLOMBIA ACTIVO | T3: VISITA_TÉCNICA | U3: SIZZZ915 | V3: TIPO III | W3: TERRESTRE | X3: GIMBUEL LASSO LUIS GERMAN | Y3: 1 | Z3: 0 | AA3: =IF(V3="TIPO I",'BASE LIQUIDACION REDEBAN 2025'!$B$2,IF(V3="TIPO II",'BASE LIQUIDACION REDEBAN 2025'!$B$3,IF(V3="TIPO III",'BASE LIQUIDACION REDEBAN 2025'!$B$4,IF(V3="TIPO IV",'BASE LIQUIDACION REDEBAN 2025'!$B$5,IF(W3="AEREO",'BASE LIQUIDACION REDEBAN 2025'!$B$6,'BASE LIQUIDACION REDEBAN 2025'!$B$5))))) -> 275728.78 | AB3: =IF(V3="TIPO I",'BASE LIQUIDACION REDEBAN 2025'!$B$10,IF(V3="TIPO II",'BASE LIQUIDACION REDEBAN 2025'!$B$11,IF(V3="TIPO III",'BASE LIQUIDACION REDEBAN 2025'!$B$12,'BASE LIQUIDACION REDEBAN 2025'!$B$13))) -> 196536.53 | AC3: =Y3*AA3+Z3*AB3 -> 275728.78
A4: PASTO | B4: =VLOOKUP(A4,'CENTRO DE COSTOS'!A:D,4,FALSE) -> DIEGO FERNANDO HENAO CARDONA | C4: =VLOOKUP(A4,'CENTRO DE COSTOS'!A:D,2,FALSE) -> 0004-0003 | D4: 52079 | E4: TA-25-1033974 | F4: 81185 | G4: APERTURA | H4: CB CRECIMIENTO - NUEVO | I4: NARIÑO | J4: BARBACOAS | K4: BARRIO GUAYACAL BARBACOAS | L4: REDEBAN | M4: FO-25-1432981 | N4: 45896 | O4: 45902 | P4: UNO A UNO | Q4: UNO A UNO | R4: EJECUTADO | S4: 27-08 SE REALIZA LLAMADA AL CLIENTE, SE HABLA CON LA SRA YULIS FIORELA PORTILLA CABEZAS SE VALIDA DIRECCIÓN OK, CANAL OK, DISPONIBILIDAD TOTAL, LLAMAR EL DÍA LA INSTALACIÓN PARA CONFIRMAR VISITA, AVISO EXTERIOR ALTURA APROX 2 METROS; TOMACORRIENTE CERCANO: SI; TIENE CABINA DE SEGURIDAD: NO - COMUNICACIÓN POR WPP / EL MODEM ESTA A 4 MT 29/08/2025 POR DISPONIBILIDAD DE TRASNPORTE NO ES POSIBLE REALIZAR LA ACTIVIDAD EL DIA DE HOY, SE VIAJARA EL DIA LUNES 01-09 SE LLEGO A BARBACOAS, SE ESTA REALIZANDO LA IMPLEMENTACIÓN EL DIA DE MAÑANA 02-09 SE REALIZA INSTALACIÓN DE CORRESPONSAL, SE INSTALAN EQUIPOS CON PRUEBAS EXITOSAS, SE CAPACITA Y SE EVALÚA AL CLIENTE, SE INSTALA PUBLICIDAD COMPLETA, CB QUEDA OPERATIVO. USUARIO SOMOS BANCOLOMBIA ACTIVO | T4: VISITA_TÉCNICA | U4: FKZZZ635 | V4: TIPO IV | W4: TERRESTRE | X4: PAZ MARTINEZ RICHARD HUMBERTO | Y4: 1 | Z4: 0 | AA4: =IF(V4="TIPO I",'BASE LIQUIDACION REDEBAN 2025'!$B$2,IF(V4="TIPO II",'BASE LIQUIDACION REDEBAN 2025'!$B$3,IF(V4="TIPO III",'BASE LIQUIDACION REDEBAN 2025'!$B$4,IF(V4="TIPO IV",'BASE LIQUIDACION REDEBAN 2025'!$B$5,IF(W4="AEREO",'BASE LIQUIDACION REDEBAN 2025'!$B$6,'BASE LIQUIDACION REDEBAN 2025'!$B$5))))) -> 504832.65 | AB4: =IF(V4="TIPO I",'BASE LIQUIDACION REDEBAN 2025'!$B$10,IF(V4="TIPO II",'BASE LIQUIDACION REDEBAN 2025'!$B$11,IF(V4="TIPO III",'BASE LIQUIDACION REDEBAN 2025'!$B$12,'BASE LIQUIDACION REDEBAN 2025'!$B$13))) -> 196536.53 | AC4: =Y4*AA4+Z4*AB4 -> 504832.65
A5: PEREIRA | B5: =VLOOKUP(A5,'CENTRO DE COSTOS'!A:D,4,FALSE) -> DIEGO FERNANDO HENAO CARDONA | C5: =VLOOKUP(A5,'CENTRO DE COSTOS'!A:D,2,FALSE) -> 0004-0002 | D5: 66001 | E5: TA-25-1033985 | F5: 81241 | G5: APERTURA | H5: CB CRECIMIENTO - NUEVO | I5: RISARALDA | J5: PEREIRA | K5: BARRIO CENTRO PEREIRA 55 | L5: REDEBAN | M5: FO-25-1433027 | N5: 45896 | O5: 45901 | P5: UNO A UNO | Q5: UNO A UNO | R5: EJECUTADO | S5: 27-08-2025 SE REALIZA LLAMADA AL CLIENTE, SE HABLA CON LA SRA JULIANA ECHEVERRY GALVEZ SE VALIDA DIRECCIÓN OK, CANAL OK, DISPONIBILIDAD TOTAL, LLAMAR EL DÍA LA INSTALACIÓN PARA CONFIRMAR VISITA, AVISO EXTERIOR ALTURA APROX 2 METROS; TOMACORRIENTE CERCANO: SI; TIENE CABINA DE SEGURIDAD: NO // CONTACTO REALIZADO POR LA APP 29-08 REALIZAMOS LLAMADA A LA SRA JULIANA LA CUAL NOS INDICA QUE EL DÍA DE HOY NO ES POSIBLE ATENDERNOS YA QUE TIENE UN COMPROMISO QUE POR FAVOR REPROGRAMAR LA VISITA PARA LA OTRA SEMANA. 1/09/2025 SE REALIZA INSTALACIÓN DE CORRESPONSAL, SE INSTALAN EQUIPOS, SE CAPACITA Y SE EVALÚA AL CLIENTE, SE INSTALA PUBLICIDAD COMPLETA, CB QUEDA OPERATIVO. USUARIO SOMOS BANCOLOMBIA ACTIVO. NOTA: SOLO SE REALIZAN PRUEBA DE CONSULTA DE SALDO YA QUE EL CLIENTE NO TIENE TARJETA PARA HACER LAS PRUEBAS DE DEPOSITO, RETIRO, RECAUDO Y TRANSFERENCIA | T5: VISITA_TÉCNICA | U5: FKZZZ643 | V5: TIPO I | W5: TERRESTRE | X5: ARROYAVE CANO MANUEL GUILLERMO | Y5: 1 | Z5: 0 | AA5: =IF(V5="TIPO I",'BASE LIQUIDACION REDEBAN 2025'!$B$2,IF(V5="TIPO II",'BASE LIQUIDACION REDEBAN 2025'!$B$3,IF(V5="TIPO III",'BASE LIQUIDACION REDEBAN 2025'!$B$4,IF(V5="TIPO IV",'BASE LIQUIDACION REDEBAN 2025'!$B$5,IF(W5="AEREO",'BASE LIQUIDACION REDEBAN 2025'!$B$6,'BASE LIQUIDACION REDEBAN 2025'!$B$5))))) -> 75096.394 | AB5: =IF(V5="TIPO I",'BASE LIQUIDACION REDEBAN 2025'!$B$10,IF(V5="TIPO II",'BASE LIQUIDACION REDEBAN 2025'!$B$11,IF(V5="TIPO III",'BASE LIQUIDACION REDEBAN 2025'!$B$12,'BASE LIQUIDACION REDEBAN 2025'!$B$13))) -> 75096.394 | AC5: =Y5*AA5+Z5*AB5 -> 75096.394
A6: MONTERIA | B6: =VLOOKUP(A6,'CENTRO DE COSTOS'!A:D,4,FALSE) -> JOSE MAURICIO HERNANDEZ ROJAS | C6: =VLOOKUP(A6,'CENTRO DE COSTOS'!A:D,2,FALSE) -> 0004-0001 | D6: 23001 | E6: TA-25-1033987 | F6: 81212 | G6: APERTURA | H6: CB CRECIMIENTO - NUEVO | I6: CORDOBA | J6: MONTERIA | K6: BARRIO POLICARPA MONTERIA 3 | L6: REDEBAN | M6: FO-25-1433037 | N6: 45896 | O6: 45901 | P6: UNO A UNO | Q6: UNO A UNO | R6: EJECUTADO | S6: 26-08 SE REALIZA LLAMADA AL CLIENTE, SE HABLA CON LA SRA SIDNEY PATRICIA VILLEGAS VILORIA SE VALIDA DIRECCIÓN OK, CANAL OK, DISPONIBILIDAD TOTAL, LLAMAR EL DÍA DE LA INSTALACIÓN PARA CONFIRMAR VISITA, AVISO EXTERIOR NO INDICA ALTURA; TOMACORRIENTE CERCANO: SI; TIENE CABINA DE SEGURIDAD: SI 28-08 SE REALIZÓ LLAMADA DE VALIDACIÓN Y LA SEÑORA SIDNEY PATRICIA VILLEGAS VILORIA, INFORMA QUE POR LAS FUERTE LLUVIA Y BRISA DE ANOCHE SE CAYERON VARIOS ÁRBOLES Y ESTÁ SIN FLUIDO ELÉCTRICO Y DAÑOS EN EL INTERNET. PIDE POR FAVOR ESPERAR A QUE LE SOLUCIONEN PARA RECIBIR LA INSTALACIÓN. 29-08 SE REALIZÓ LLAMADA DE VALIDACIÓN Y EL CLIENTE INFORMA QUE TODAVÍA TIENE PROBLEMAS CON EL CANAL DE COMUNICACIÓN, QUE NO HAN REALIZADO LOS ARREGLOS EN LA ZONA. 30-08 LA ACTIVIDAD SE REAGENDA PARA EL DÍA LUNES 01-09-25. 1/09/2025 SE ESCALA CASO, DONDE SE LLEVA A COMERCIO DE LA PAPELERÍA, PERO EL LOCAL NO CUENTA CON EL NOMBRE DE COMERCIO EN FACHADA, CABE ACLARAR QUE LA MERCANCÍA SI TIENE RELACIÓN CON PAPELERIA, // POR FAVOR, PROCEDAMOS CON LA IMPLANTACIÓN CORRESPONDIENTE Y DEJEMOS COMO EVIDENCIA LA CÁMARA DE COMERCIO, ASÍ COMO LA DOCUMENTACIÓN DE LA NOVEDAD PRESENTADA. 01-09 SE REALIZA INSTALACIÓN DE CORRESPONSAL, SE INSTALAN EQUIPOS CON PRUEBAS EXITOSAS, SE CAPACITA Y SE EVALÚA AL CLIENTE, SE INSTALA PUBLICIDAD COMPLETA, CB QUEDA OPERATIVO. USUARIO SOMOS BANCOLOMBIA ACTIVO. NO SÉ REALIZÓ PRUEBAS DE RECAUDO PORQUE EL CLIENTE NO IBA A PAGAR FACTURA EN EL MOMENTO Y LA DE TRANSFERENCIA EL CLIENTE NO TIENE MÁS CUENTA | T6: VISITA_TÉCNICA | U6: FKZZZ646 | V6: TIPO I | W6: TERRESTRE | X6: CALDERA SALCEDO CARLOS JULIO | Y6: 1 | Z6: 0 | AA6: =IF(V6="TIPO I",'BASE LIQUIDACION REDEBAN 2025'!$B$2,IF(V6="TIPO II",'BASE LIQUIDACION REDEBAN 2025'!$B$3,IF(V6="TIPO III",'BASE LIQUIDACION REDEBAN 2025'!$B$4,IF(V6="TIPO IV",'BASE LIQUIDACION REDEBAN 2025'!$B$5,IF(W6="AEREO",'BASE LIQUIDACION REDEBAN 2025'!$B$6,'BASE LIQUIDACION REDEBAN 2025'!$B$5))))) -> 75096.394 | AB6: =IF(V6="TIPO I",'BASE LIQUIDACION REDEBAN 2025'!$B$10,IF(V6="TIPO II",'BASE LIQUIDACION REDEBAN 2025'!$B$11,IF(V6="TIPO III",'BASE LIQUIDACION REDEBAN 2025'!$B$12,'BASE LIQUIDACION REDEBAN 2025'!$B$13))) -> 75096.394 | AC6: =Y6*AA6+Z6*AB6 -> 75096.394
A7: CALI | B7: =VLOOKUP(A7,'CENTRO DE COSTOS'!A:D,4,FALSE) -> DIEGO FERNANDO HENAO CARDONA | C7: =VLOOKUP(A7,'CENTRO DE COSTOS'!A:D,2,FALSE) -> 0004-0003 | D7: 19809 | E7: TA-25-1033991 | F7: 81252 | G7: APERTURA | H7: CB CRECIMIENTO - NUEVO | I7: CAUCA | J7: TIMBIQUI | K7: BARRIO UNION DE VIVIENDAS TIMBIQUI | L7: REDEBAN | M7: FO-25-1433056 | N7: 45896 | O7: 45904 | P7: UNO A UNO | Q7: UNO A UNO | R7: EJECUTADO | S7: 27-08-2025 SE REALIZA LLAMADA AL CLIENTE, SE HABLA CON LA SRA IRLANDA VENTE CONGOLINO SE VALIDA DIRECCIÓN OK, CANAL OK, DISPONIBILIDAD TOTAL, LLAMAR EL DÍA LA INSTALACIÓN PARA CONFIRMAR VISITA, AVISO EXTERIOR ALTURA APROX 3 METROS; TOMACORRIENTE CERCANO: SI; TIENE CABINA DE SEGURIDAD: SI 04-09 SE REALIZA INSTALACIÓN DE CORRESPONSAL, SE INSTALAN EQUIPOS CON PRUEBAS EXITOSAS, SE CAPACITA Y SE EVALÚA AL CLIENTE, SE INSTALA PUBLICIDAD COMPLETA, CB QUEDA OPERATIVO. USUARIO SOMOS BANCOLOMBIA ACTIVO | T7: VISITA_TÉCNICA | U7: FKZZZ649 | V7: TIPO IV ESPECIAL | W7: AEREO | X7: PAREDES CASTILLO DIEGO | Y7: 1 | Z7: 0 | AA7: =IF(V7="TIPO I",'BASE LIQUIDACION REDEBAN 2025'!$B$2,IF(V7="TIPO II",'BASE LIQUIDACION REDEBAN 2025'!$B$3,IF(V7="TIPO III",'BASE LIQUIDACION REDEBAN 2025'!$B$4,IF(V7="TIPO IV",'BASE LIQUIDACION REDEBAN 2025'!$B$5,IF(W7="AEREO",'BASE LIQUIDACION REDEBAN 2025'!$B$6,'BASE LIQUIDACION REDEBAN 2025'!$B$5))))) -> 988462.96 | AB7: =IF(V7="TIPO I",'BASE LIQUIDACION REDEBAN 2025'!$B$10,IF(V7="TIPO II",'BASE LIQUIDACION REDEBAN 2025'!$B$11,IF(V7="TIPO III",'BASE LIQUIDACION REDEBAN 2025'!$B$12,'BASE LIQUIDACION REDEBAN 2025'!$B$13))) -> 196536.53 | AC7: =Y7*AA7+Z7*AB7 -> 988462.96
A8: NEIVA | B8: =VLOOKUP(A8,'CENTRO DE COSTOS'!A:D,4,FALSE) -> KEVIN ALEXIS CORZO BUSTOS | C8: =VLOOKUP(A8,'CENTRO DE COSTOS'!A:D,2,FALSE) -> 0004-0007 | D8: 18785 | E8: TA-25-1034017 | F8: 81251 | G8: APERTURA | H8: CB CRECIMIENTO - NUEVO | I8: CAQUETA | J8: SOLITA | K8: BARRIO JORDAN SOLITA | L8: REDEBAN | M8: FO-25-1433151 | N8: 45896 | O8: 45902 | P8: UNO A UNO | Q8: UNO A UNO | R8: EJECUTADO | S8: 27-08 SE REALIZA LLAMADA AL CLIENTE, SE HABLA CON LA SRA IDARYI CANO PINZON SE VALIDA DIRECCIÓN OK, CANAL OK, DISPONIBILIDAD TOTAL, LLAMAR EL DÍA LA INSTALACIÓN PARA CONFIRMAR VISITA, AVISO EXTERIOR ALTURA APROX 2 METROS; TOMACORRIENTE CERCANO: SI; TIENE CABINA DE SEGURIDAD: NO - EL MODEM ESTA 5 MT 01-09 EN COMUNICACIÓN CON LA CLIENTA PARA CONFIRMAR LA INSTALACIÓN EL DÍA DE HOY, CLIENTE MANIFIESTO QUE NO ES POSIBLE ATENDER LA VISITA YA QUE POR MOTIVOS PERSONALES ESTÁ EN FLORENCIA REALIZANDO UNAS DILIGENCIAS, MANIFESTÓ ATENDER LA VISITA EL DÍA DE MAÑANA 02 DE SEPTIEMBRE EN EL TRANSCURSO DEL DÍA. 2/09/2025 SE REALIZA INSTALACIÓN DE CORRESPONSAL, SE INSTALAN EQUIPOS CON PRUEBAS EXITOSAS, SE CAPACITA Y SE EVALÚA AL CLIENTE, SE INSTALA PUBLICIDAD COMPLETA, CB QUEDA OPERATIVO. USUARIO SOMOS BANCOLOMBIA ACTIVO | T8: VISITA_TÉCNICA | U8: FKZZZ665 | V8: TIPO IV | W8: TERRESTRE | X8: BERMUDEZ SANCHEZ JOSE NEYBER | Y8: 1 | Z8: 0 | AA8: =IF(V8="TIPO I",'BASE LIQUIDACION REDEBAN 2025'!$B$2,IF(V8="TIPO II",'BASE LIQUIDACION REDEBAN 2025'!$B$3,IF(V8="TIPO III",'BASE LIQUIDACION REDEBAN 2025'!$B$4,IF(V8="TIPO IV",'BASE LIQUIDACION REDEBAN 2025'!$B$5,IF(W8="AEREO",'BASE LIQUIDACION REDEBAN 2025'!$B$6,'BASE LIQUIDACION REDEBAN 2025'!$B$5))))) -> 504832.65 | AB8: =IF(V8="TIPO I",'BASE LIQUIDACION REDEBAN 2025'!$B$10,IF(V8="TIPO II",'BASE LIQUIDACION REDEBAN 2025'!$B$11,IF(V8="TIPO III",'BASE LIQUIDACION REDEBAN 2025'!$B$12,'BASE LIQUIDACION REDEBAN 2025'!$B$13))) -> 196536.53 | AC8: =Y8*AA8+Z8*AB8 -> 504832.65
A9: VILLAVICENCIO | B9: =VLOOKUP(A9,'CENTRO DE COSTOS'!A:D,4,FALSE) -> KEVIN ALEXIS CORZO BUSTOS | C9: =VLOOKUP(A9,'CENTRO DE COSTOS'!A:D,2,FALSE) -> 0004-0007 | D9: 50350 | E9: TA-25-1034022 | F9: 81208 | G9: APERTURA | H9: CB CRECIMIENTO - NUEVO | I9: META | J9: LA MACARENA | K9: BARRIO CENTRO LA MACARENA 9 | L9: REDEBAN | M9: FO-25-1433176 | N9: 45896 | O9: 45903 | P9: UNO A UNO | Q9: UNO A UNO | R9: EJECUTADO | S9: 27-08 SE REALIZA LLAMADA AL CLIENTE, SE HABLA CON LA SR RICARDO FLOREZ ARENAS SE VALIDA DIRECCIÓN OK, CANAL OK, DISPONIBILIDAD TOTAL, LLAMAR EL DÍA LA INSTALACIÓN PARA CONFIRMAR VISITA, AVISO EXTERIOR ALTURA APROX 2 METROS; TOMACORRIENTE CERCANO: SI; TIENE CABINA DE SEGURIDAD: NO - COMUNICACIÓN POR WPP / EL MODEM ESTA A 5 MT Y NO TIENE PUERTO DISPONIBLES ( LLEVAR SWITCH) 03-09 SE REALIZA INSTALACIÓN DE CORRESPONSAL, SE INSTALAN EQUIPOS CON PRUEBAS EXITOSAS, SE CAPACITA Y SE EVALÚA AL CLIENTE, SE INSTALA PUBLICIDAD COMPLETA, CB QUEDA OPERATIVO. USUARIO SOMOS BANCOLOMBIA ACTIVO | T9: VISITA_TÉCNICA | U9: FKZZZ669 | V9: TIPO IV ESPECIAL | W9: AEREO | X9: ROZO JIMENEZ EDGAR ARMANDO | Y9: 1 | Z9: 0 | AA9: =IF(V9="TIPO I",'BASE LIQUIDACION REDEBAN 2025'!$B$2,IF(V9="TIPO II",'BASE LIQUIDACION REDEBAN 2025'!$B$3,IF(V9="TIPO III",'BASE LIQUIDACION REDEBAN 2025'!$B$4,IF(V9="TIPO IV",'BASE LIQUIDACION REDEBAN 2025'!$B$5,IF(W9="AEREO",'BASE LIQUIDACION REDEBAN 2025'!$B$6,'BASE LIQUIDACION REDEBAN 2025'!$B$5))))) -> 988462.96 | AB9: =IF(V9="TIPO I",'BASE LIQUIDACION REDEBAN 2025'!$B$10,IF(V9="TIPO II",'BASE LIQUIDACION REDEBAN 2025'!$B$11,IF(V9="TIPO III",'BASE LIQUIDACION REDEBAN 2025'!$B$12,'BASE LIQUIDACION REDEBAN 2025'!$B$13))) -> 196536.53 | AC9: =Y9*AA9+Z9*AB9 -> 988462.96
A10: BUCARAMANGA | B10: =VLOOKUP(A10,'CENTRO DE COSTOS'!A:D,4,FALSE) -> MIGUEL JULIÁN HERNÁNDEZ GUARÍN | C10: =VLOOKUP(A10,'CENTRO DE COSTOS'!A:D,2,FALSE) -> 0004-0008 | D10: 68679 | E10: TA-25-1034026 | F10: 81247 | G10: APERTURA | H10: CB CRECIMIENTO - NUEVO | I10: SANTANDER | J10: SAN GIL | K10: BARRIO CIUDAD FUTURO ETAPA 3 SAN GIL | L10: REDEBAN | M10: FO-25-1433206 | N10: 45896 | O10: 45901 | P10: UNO A UNO | Q10: UNO A UNO | R10: EJECUTADO | S10: 27-08 SE REALIZA LLAMADA AL CLIENTE, SE HABLA CON LA SRA OLGA PATRICIA SARMIENTO OTERO SE VALIDA DIRECCIÓN OK, CANAL OK, DISPONIBILIDAD TOTAL, LLAMAR EL DÍA LA INSTALACIÓN PARA CONFIRMAR VISITA, AVISO EXTERIOR ALTURA APROX 2 METROS; TOMACORRIENTE CERCANO: SI; TIENE CABINA DE SEGURIDAD: NO - SE PROGRAMA PARA DICHA FECHA POR SOLITUD DEL USUARIO 01-09 SE REALIZA INSTALACIÓN DE CORRESPONSAL, SE INSTALAN EQUIPOS CON PRUEBAS EXITOSAS, SE CAPACITA Y SE EVALÚA AL CLIENTE, SE INSTALA PUBLICIDAD COMPLETA, CB QUEDA OPERATIVO. USUARIO SOMOS BANCOLOMBIA ACTIVO | T10: VISITA_TÉCNICA | U10: FKZZZ672 | V10: TIPO II | W10: TERRESTRE | X10: GELVEZ MOGOLLON JOSE ELISEO | Y10: 1 | Z10: 0 | AA10: =IF(V10="TIPO I",'BASE LIQUIDACION REDEBAN 2025'!$B$2,IF(V10="TIPO II",'BASE LIQUIDACION REDEBAN 2025'!$B$3,IF(V10="TIPO III",'BASE LIQUIDACION REDEBAN 2025'!$B$4,IF(V10="TIPO IV",'BASE LIQUIDACION REDEBAN 2025'!$B$5,IF(W10="AEREO",'BASE LIQUIDACION REDEBAN 2025'!$B$6,'BASE LIQUIDACION REDEBAN 2025'!$B$5))))) -> 163813.7 | AB10: =IF(V10="TIPO I",'BASE LIQUIDACION REDEBAN 2025'!$B$10,IF(V10="TIPO II",'BASE LIQUIDACION REDEBAN 2025'!$B$11,IF(V10="TIPO III",'BASE LIQUIDACION REDEBAN 2025'!$B$12,'BASE LIQUIDACION REDEBAN 2025'!$B$13))) -> 140395.63 | AC10: =Y10*AA10+Z10*AB10 -> 163813.7
A11: CALI | B11: =VLOOKUP(A11,'CENTRO DE COSTOS'!A:D,4,FALSE) -> DIEGO FERNANDO HENAO CARDONA | C11: =VLOOKUP(A11,'CENTRO DE COSTOS'!A:D,2,FALSE) -> 0004-0003 | D11: 76001 | E11: TA-25-1034027 | F11: 81195 | G11: APERTURA | H11: CB CRECIMIENTO - NUEVO | I11: VALLE DEL CAUCA | J11: CALI | K11: BARRIO BENAJAMIN HERRERA CALI | L11: REDEBAN | M11: FO-25-1433211 | N11: 45896 | O11: 45902 | P11: UNO A UNO | Q11: UNO A UNO | R11: EJECUTADO | S11: 27-08 SE REALIZA LLAMADA AL CLIENTE, SE HABLA CON LA SRA MALLERLY RUBIANO LOPEZ SE VALIDA DIRECCIÓN OK, CANAL OK, DISPONIBILIDAD TOTAL, LLAMAR EL DÍA LA INSTALACIÓN PARA CONFIRMAR VISITA, AVISO EXTERIOR ALTURA: NO INDICA ALTURA; TOMACORRIENTE CERCANO: SI; TIENE CABINA DE SEGURIDAD: NO 29/08/2025 SE LLAMA AL CLIENTE AL NÚMERO 3104237740 HABLO CON LA SEÑORA MALLERLY INFORMA QUE EL DÍA DE HOY NO PUEDE ATENDER LA INSTALACIÓN TODO EL PERSONAL DE LA DROGUERÍA ESTÁ EN INVENTARIO NO ALGUIEN MÁS QUE NOS ATIENDA LA ACTIVIDAD NO SE PUEDE REPROGRAMAR VENCE EL HOY, SE LE INDICA AL CLIENTE QUE SE CANCELA LA INSTALACIÓN 01-09 SE LLAMO EL CLIENTE PERO NO CONTESTO, SE REALIZARA LLAMADA EL DIA DE MAÑANA PARA VALIDAR DISPONIBILIDAD 02-09 SE REALIZA INSTALACIÓN DE CORRESPONSAL, SE INSTALAN EQUIPOS CON PRUEBAS EXITOSAS, SE CAPACITA Y SE EVALÚA AL CLIENTE, SE INSTALA PUBLICIDAD COMPLETA, CB QUEDA OPERATIVO. USUARIO SOMOS BANCOLOMBIA ACTIVO | T11: VISITA_TÉCNICA | U11: FKZZZ673 | V11: TIPO I | W11: TERRESTRE | X11: PAREDES CASTILLO DIEGO | Y11: 1 | Z11: 0 | AA11: =IF(V11="TIPO I",'BASE LIQUIDACION REDEBAN 2025'!$B$2,IF(V11="TIPO II",'BASE LIQUIDACION REDEBAN 2025'!$B$3,IF(V11="TIPO III",'BASE LIQUIDACION REDEBAN 2025'!$B$4,IF(V11="TIPO IV",'BASE LIQUIDACION REDEBAN 2025'!$B$5,IF(W11="AEREO",'BASE LIQUIDACION REDEBAN 2025'!$B$6,'BASE LIQUIDACION REDEBAN 2025'!$B$5))))) -> 75096.394 | AB11: =IF(V11="TIPO I",'BASE LIQUIDACION REDEBAN 2025'!$B$10,IF(V11="TIPO II",'BASE LIQUIDACION REDEBAN 2025'!$B$11,IF(V11="TIPO III",'BASE LIQUIDACION REDEBAN 2025'!$B$12,'BASE LIQUIDACION REDEBAN 2025'!$B$13))) -> 75096.394 | AC11: =Y11*AA11+Z11*AB11 -> 75096.394
A12: PASTO | B12: =VLOOKUP(A12,'CENTRO DE COSTOS'!A:D,4,FALSE) -> DIEGO FERNANDO HENAO CARDONA | C12: =VLOOKUP(A12,'CENTRO DE COSTOS'!A:D,2,FALSE) -> 0004-0003 | D12: 86568 | E12: TA-25-1034476 | F12: 81229 | G12: APERTURA | H12: CB CRECIMIENTO ALIANZA - NUEVO | I12: PUTUMAYO | J12: PUERTO ASIS | K12: DISTRICOL LADY PERFUMERIA | L12: REDEBAN | M12: FO-25-1433932 | N12: 45896 | O12: 45902 | P12: AGREGADOR | Q12: DISTRICOL | R12: EJECUTADO | S12: 27-08 PROGRAMACIÓN REALIZADA POR LA ALIANZA 29/08/2025 POR DISPONIBILIDAD DE TRASNPORTE NO ES POSIBLE REALIZAR LA ACTIVIDAD EL DIA DE HOY, SE VIAJARA EL DIA LUNES 01-09 POR RETRASOS DEBIDO A ARREGLOS EN LA VÍA AL PUTUMAYO NO SE ALCANZA A REALIZAR VISITA EL DÍA DE HOY. SE INFORMA A CLIENTE QUE SE VISITARÁ MAÑANA DESPUÉS DE MEDIO DÍA. SEÑORA RUBIELA PIDE SE LA VISITE A LAS 3 PM 2/09/2025 SE REALIZA INSTALACIÓN DE CORRESPONSAL, SE INSTALAN EQUIPOS CON PRUEBAS EXITOSAS, SE CAPACITA Y SE EVALÚA AL CLIENTE, SE INSTALA PUBLICIDAD COMPLETA, CB QUEDA OPERATIVO. USUARIO SOMOS BANCOLOMBIA ACTIVO | T12: VISITA_TÉCNICA | U12: FKZZZ695 | V12: TIPO IV | W12: TERRESTRE | X12: CASTILLO HERRERA ALEX RICARDO | Y12: 1 | Z12: 0 | AA12: =IF(V12="TIPO I",'BASE LIQUIDACION REDEBAN 2025'!$B$2,IF(V12="TIPO II",'BASE LIQUIDACION REDEBAN 2025'!$B$3,IF(V12="TIPO III",'BASE LIQUIDACION REDEBAN 2025'!$B$4,IF(V12="TIPO IV",'BASE LIQUIDACION REDEBAN 2025'!$B$5,IF(W12="AEREO",'BASE LIQUIDACION REDEBAN 2025'!$B$6,'BASE LIQUIDACION REDEBAN 2025'!$B$5))))) -> 504832.65 | AB12: =IF(V12="TIPO I",'BASE LIQUIDACION REDEBAN 2025'!$B$10,IF(V12="TIPO II",'BASE LIQUIDACION REDEBAN 2025'!$B$11,IF(V12="TIPO III",'BASE LIQUIDACION REDEBAN 2025'!$B$12,'BASE LIQUIDACION REDEBAN 2025'!$B$13))) -> 196536.53 | AC12: =Y12*AA12+Z12*AB12 -> 504832.65
A13: MONTERIA | B13: =VLOOKUP(A13,'CENTRO DE COSTOS'!A:D,4,FALSE) -> JOSE MAURICIO HERNANDEZ ROJAS | C13: =VLOOKUP(A13,'CENTRO DE COSTOS'!A:D,2,FALSE) -> 0004-0001 | D13: 5250 | E13: TA-25-1040105 | F13: 81260 | G13: APERTURA | H13: CB CRECIMIENTO ALIANZA - NUEVO | I13: ANTIOQUIA | J13: EL BAGRE | K13: DISTRICOL DROGUERIA G&P | L13: REDEBAN | M13: FO-25-1444555 | N13: 45898 | O13: 45902 | P13: AGREGADOR | Q13: DISTRICOL | R13: EJECUTADO | S13: 29-08 PROGRAMACIÓN REALIZADA POR LA ALIANZA 2/09/2025 SE REALIZA INSTALACIÓN DE CORRESPONSAL, SE INSTALAN EQUIPOS CON PRUEBAS EXITOSAS, SE CAPACITA Y SE EVALÚA AL CLIENTE, SE INSTALA PUBLICIDAD COMPLETA, CB QUEDA OPERATIVO. USUARIO SOMOS BANCOLOMBIA ACTIVO. LAS PRUEBAS DE RECAUDO Y TRANSFERENCIA NO SE REALIZARON PORQUE EL CLIENTE NO TIENE OTRA CUENTA Y NO HAY FACTURAS PARA HACER RECAUDOS | T13: VISITA_TÉCNICA | U13: SKZZZ566 | V13: TIPO IV | W13: TERRESTRE | X13: CALDERA SALCEDO CARLOS JULIO | Y13: 1 | Z13: 0 | AA13: =IF(V13="TIPO I",'BASE LIQUIDACION REDEBAN 2025'!$B$2,IF(V13="TIPO II",'BASE LIQUIDACION REDEBAN 2025'!$B$3,IF(V13="TIPO III",'BASE LIQUIDACION REDEBAN 2025'!$B$4,IF(V13="TIPO IV",'BASE LIQUIDACION REDEBAN 2025'!$B$5,IF(W13="AEREO",'BASE LIQUIDACION REDEBAN 2025'!$B$6,'BASE LIQUIDACION REDEBAN 2025'!$B$5))))) -> 504832.65 | AB13: =IF(V13="TIPO I",'BASE LIQUIDACION REDEBAN 2025'!$B$10,IF(V13="TIPO II",'BASE LIQUIDACION REDEBAN 2025'!$B$11,IF(V13="TIPO III",'BASE LIQUIDACION REDEBAN 2025'!$B$12,'BASE LIQUIDACION REDEBAN 2025'!$B$13))) -> 196536.53 | AC13: =Y13*AA13+Z13*AB13 -> 504832.65
... A220: BUCARAMANGA | B220: =VLOOKUP(A220,'CENTRO DE COSTOS'!A:D,4,FALSE) -> MIGUEL JULIÁN HERNÁNDEZ GUARÍN | C220: =VLOOKUP(A220,'CENTRO DE COSTOS'!A:D,2,FALSE) -> 0004-0008 | D220: 68001 | E220: TA-25-1157235 | F220: 81703 | G220: APERTURA | H220: CB CRECIMIENTO ALIANZA - NUEVO | I220: SANTANDER | J220: BUCARAMANGA | K220: DISTRICOL OPULENCE SHOES | L220: REDEBAN | M220: FO-25-1598678 | N220: 45929 | O220: 45930 | P220: AGREGADOR | Q220: DISTRICOL | R220: EJECUTADO | S220: 29-09 PROGRAMACIÓN REALIZADA POR LA ALIANZA 30/09/2025 SE REALIZA INSTALACIÓN DE CORRESPONSAL, SE INSTALAN EQUIPOS CON PRUEBAS EXITOSAS, SE CAPACITA Y SE EVALÚA AL CLIENTE, SE INSTALA PUBLICIDAD COMPLETA, CB QUEDA OPERATIVO. USUARIO SOMOS BANCOLOMBIA ACTIVO | T220: REYES RAMIREZ DIEGO ALEXANDER | U220: FYZZZ196 | V220: TIPO I | W220: TERRESTRE | X220: REYES RAMIREZ DIEGO ALEXANDER | Y220: 1 | Z220: 0 | AA220: =IF(V220="TIPO I",'BASE LIQUIDACION REDEBAN 2025'!$B$2,IF(V220="TIPO II",'BASE LIQUIDACION REDEBAN 2025'!$B$3,IF(V220="TIPO III",'BASE LIQUIDACION REDEBAN 2025'!$B$4,IF(V220="TIPO IV",'BASE LIQUIDACION REDEBAN 2025'!$B$5,IF(W220="AEREO",'BASE LIQUIDACION REDEBAN 2025'!$B$6,'BASE LIQUIDACION REDEBAN 2025'!$B$5))))) -> 75096.394 | AB220: =IF(V220="TIPO I",'BASE LIQUIDACION REDEBAN 2025'!$B$10,IF(V220="TIPO II",'BASE LIQUIDACION REDEBAN 2025'!$B$11,IF(V220="TIPO III",'BASE LIQUIDACION REDEBAN 2025'!$B$12,'BASE LIQUIDACION REDEBAN 2025'!$B$13))) -> 75096.394 | AC220: =Y220*AA220+Z220*AB220 -> 75096.394
AC221: =SUM(AC2:AC220) -> 42735836

Sheet INCIDENTES BANCOLOMBIA
A1: CIUDAD SEDE | B1: COORDINADOR | C1: CENTRO DE COSTOS LÍNEACOM | D1: CÓDIGO DANE | E1: TA/CODIGO ACTIVIDAD | F1: CODIGO CB | G1: ACTIVIDAD | H1: DEPARTAMENTO | I1: CIUDAD | J1: NOMBRE DEL CB | K1: RED | L1: FO | M1: FECHA ASIGNACIÓN A LÍNEA COMUNICACIONES (DD/MM/AAAA HH:MM) | N1: FECHA CIERRE DEL TICKET (DD/MM/AAAA HH:MM) | O1: ACOMETIDA | P1: GRUPO_FALLA | Q1: CATEGORÍA | R1: FALLA | S1: FORMATO | T1: CADENA | U1: ESTADO | V1: OBSERVACION | W1: FORMA DE ATENCIÓN | X1: TERMINAL | Y1: TIPIFICACION | Z1: TIPO DE TRAYECTO | AA1: NOMBRE DEL TECNICO | AB1: DIAS DE VISITA | AC1: DIA ADICIONAL | AD1: VALOR DIAS ACTIVIDAD FACTURABLES A LA RED | AE1: VALOR DIAS ACOMPAÑAMIENTO FACTURABLES A RED | AF1: VALOR FACTURABLE A LA RED | AG1: CU CB | AH1: COBRO ENTIDAD | AI1: ESTADO | AJ1: TIPO | AK1: VAL TIPO | AL1: VAL COSTO | AM1: OBSERVACIONES | AN1: Observaciones LINEA
A2: BOGOTA | B2: =VLOOKUP(A2,'CENTRO DE COSTOS'!A:D,4,FALSE) -> WILLIAM ASDRUBAL ROZO ROZO | C2: =VLOOKUP(A2,'CENTRO DE COSTOS'!A:D,2,FALSE) -> 0004-0004 | D2: 25754 | E2: 2815944 | F2: 66235 | G2: INCIDENTE | H2: CUNDINAMARCA | I2: SOACHA | J2: BARRIO NEMESIS SOACHA | K2: REDEBAN | L2: FO-25-1605128 | M2: 45930.555 | N2: 45930.697 | O2: NO | P2: SOFTWARE | Q2: LECTOR DE BARRAS | R2: LECTOR DESCONFIGURADO | U2: CERRADO | V2: 30/09/2025 SE RELAIZA VISITA DE CAMPO ENCONTRANDO QUE LECTOR DE CODIGO DE BARRAS PERDIO CONFIGURACIÓN ARROJA FORMATO INVALIDO SE REALIZA CONFIGURACIÓN DE LECTOR CON PRUEBAS OK PARÁMETROS OK NO SE INICIALIZA EQUIPO TODO A CONFORMIDAD DE CB | W2: VISITA_TÉCNICA | X2: 2A00L313 | Y2: TIPO I | Z2: TERRESTRE | AA2: GALEANO SORIANO JUAN DAVID | AB2: 1 | AC2: 0 | AD2: =IF(W2="SOPORTE_TELEFÓNICO",'BASE LIQUIDACION REDEBAN 2025'!$B$19,IF(W2="ENVÍO",'BASE LIQUIDACION REDEBAN 2025'!$C$2,IF(Y2="TIPO I",'BASE LIQUIDACION REDEBAN 2025'!$C$2,IF(Y2="TIPO II",'BASE LIQUIDACION REDEBAN 2025'!$C$3,IF(Y2="TIPO III",'BASE LIQUIDACION REDEBAN 2025'!$C$4,IF(Y2="TIPO IV",'BASE LIQUIDACION REDEBAN 2025'!$C$5,IF(Z2="AEREO",'BASE LIQUIDACION REDEBAN 2025'!$B$6,'BASE LIQUIDACION REDEBAN 2025'!$C$5))))))) -> 65960.072 | AE2: =IF(OR(W2="SOPORTE_TELEFÓNICO",W2="ENVÍO"),0,IF(Y2="TIPO I",'BASE LIQUIDACION REDEBAN 2025'!$B$10,IF(Y2="TIPO II",'BASE LIQUIDACION REDEBAN 2025'!$B$11,IF(Y2="TIPO III",'BASE LIQUIDACION REDEBAN 2025'!$B$12,'BASE LIQUIDACION REDEBAN 2025'!$B$13)))) -> 75096.394 | AF2: =IF(OR(W2="SOPORTE_TELEFÓNICO",W2="ENVÍO"),AD2,(AD2*AB2+AE2*AC2)) -> 65960.072
A3: BUCARAMANGA | B3: =VLOOKUP(A3,'CENTRO DE COSTOS'!A:D,4,FALSE) -> MIGUEL JULIÁN HERNÁNDEZ GUARÍN | C3: =VLOOKUP(A3,'CENTRO DE COSTOS'!A:D,2,FALSE) -> 0004-0008 | D3: 68001 | E3: 2815477 | F3: 59523 | G3: INCIDENTE | H3: SANTANDER | I3: BUCARAMANGA | J3: BARRIO BETANIA BUCARAMANGA | K3: REDEBAN | L3: FO-25-1604645 | M3: 45930.501 | N3: 45930.692 | O3: NO | P3: HARDWARE | Q3: PINPAD | R3: ALERTADO | U3: CERRADO | V3: 30/09/2025 CB CON PINPAD ALERTADO, CAMBIO DE DATAFONO PINPAD, CAMBIO DE FUENTE Y CABLE MAGIC O POR TECNOLOGIA, BORRADO E INYECCION DE SO +VER 10.3N,CONFIGURACION CB OK, CUBRE CLAVE OK, PRUEBAS OK. CLIENTE NO PERMITE CIERRE POR FLUJO DE CLIENTES INDICA QUE SE DEMORA MÁS DE UN DÍA EN IMPRIMIRLO | W3: VISITA_TÉCNICA | X3: JA007449 | Y3: TIPO I | Z3: TERRESTRE | AA3: SANTOS GONZALEZ JOHAN FABIAN | AB3: 1 | AC3: 0 | AD3: =IF(W3="SOPORTE_TELEFÓNICO",'BASE LIQUIDACION REDEBAN 2025'!$B$19,IF(W3="ENVÍO",'BASE LIQUIDACION REDEBAN 2025'!$C$2,IF(Y3="TIPO I",'BASE LIQUIDACION REDEBAN 2025'!$C$2,IF(Y3="TIPO II",'BASE LIQUIDACION REDEBAN 2025'!$C$3,IF(Y3="TIPO III",'BASE LIQUIDACION REDEBAN 2025'!$C$4,IF(Y3="TIPO IV",'BASE LIQUIDACION REDEBAN 2025'!$C$5,IF(Z3="AEREO",'BASE LIQUIDACION REDEBAN 2025'!$B$6,'BASE LIQUIDACION REDEBAN 2025'!$C$5))))))) -> 65960.072 | AE3: =IF(OR(W3="SOPORTE_TELEFÓNICO",W3="ENVÍO"),0,IF(Y3="TIPO I",'BASE LIQUIDACION REDEBAN 2025'!$B$10,IF(Y3="TIPO II",'BASE LIQUIDACION REDEBAN 2025'!$B$11,IF(Y3="TIPO III",'BASE LIQUIDACION REDEBAN 2025'!$B$12,'BASE LIQUIDACION REDEBAN 2025'!$B$13)))) -> 75096.394 | AF3: =IF(OR(W3="SOPORTE_TELEFÓNICO",W3="ENVÍO"),AD3,(AD3*AB3+AE3*AC3)) -> 65960.072
A4: CALI | B4: =VLOOKUP(A4,'CENTRO DE COSTOS'!A:D,4,FALSE) -> DIEGO FERNANDO HENAO CARDONA | C4: =VLOOKUP(A4,'CENTRO DE COSTOS'!A:D,2,FALSE) -> 0004-0003 | D4: 76001 | E4: 2814912 | F4: 74231 | G4: INCIDENTE | H4: VALLE DEL CAUCA | I4: CALI | J4: PTM CALI LR EL LIDO | K4: REDEBAN | L4: FO-25-1604036 | M4: 45930.463 | N4: 45930.688 | O4: NO | P4: HARDWARE | Q4: SE REINICIA | R4: DAÑO POS | U4: CERRADO | V4: 30/09/2025 SE VISITA EL COMERCIO, SE REVISA LOS EQUIPOS SE ENCUENTRAN EL DATAFONO SE REINICIA CUANDO IMPRIME EL VOUCHER, ESTA FLOJO LA BATERÍA SE AJUSTA RESOLVIENDO EL PROBLEMA, PRUEBAS OK, TELECARGA TRNA | W4: VISITA_TÉCNICA | X4: EG3ZZ029 - EF02Z996 | Y4: TIPO I | Z4: TERRESTRE | AA4: HERRERA MONAR GEOVANNY | AB4: 1 | AC4: 0 | AD4: =IF(W4="SOPORTE_TELEFÓNICO",'BASE LIQUIDACION REDEBAN 2025'!$B$19,IF(W4="ENVÍO",'BASE LIQUIDACION REDEBAN 2025'!$C$2,IF(Y4="TIPO I",'BASE LIQUIDACION REDEBAN 2025'!$C$2,IF(Y4="TIPO II",'BASE LIQUIDACION REDEBAN 2025'!$C$3,IF(Y4="TIPO III",'BASE LIQUIDACION REDEBAN 2025'!$C$4,IF(Y4="TIPO IV",'BASE LIQUIDACION REDEBAN 2025'!$C$5,IF(Z4="AEREO",'BASE LIQUIDACION REDEBAN 2025'!$B$6,'BASE LIQUIDACION REDEBAN 2025'!$C$5))))))) -> 65960.072 | AE4: =IF(OR(W4="SOPORTE_TELEFÓNICO",W4="ENVÍO"),0,IF(Y4="TIPO I",'BASE LIQUIDACION REDEBAN 2025'!$B$10,IF(Y4="TIPO II",'BASE LIQUIDACION REDEBAN 2025'!$B$11,IF(Y4="TIPO III",'BASE LIQUIDACION REDEBAN 2025'!$B$12,'BASE LIQUIDACION REDEBAN 2025'!$B$13)))) -> 75096.394 | AF4: =IF(OR(W4="SOPORTE_TELEFÓNICO",W4="ENVÍO"),AD4,(AD4*AB4+AE4*AC4)) -> 65960.072
A5: CALI | B5: =VLOOKUP(A5,'CENTRO DE COSTOS'!A:D,4,FALSE) -> DIEGO FERNANDO HENAO CARDONA | C5: =VLOOKUP(A5,'CENTRO DE COSTOS'!A:D,2,FALSE) -> 0004-0003 | D5: 76001 | E5: 2814756 | F5: 73907 | G5: INCIDENTE | H5: VALLE DEL CAUCA | I5: CALI | J5: REVAL JARDÍN PLAZA II | K5: REDEBAN | L5: FO-25-1604054 | M5: 45930.458 | N5: 45930.683 | O5: NO | P5: HARDWARE | Q5: LECTOR DE BARRAS | R5: DAÑO POS | U5: CERRADO | V5: 30/09/2025 SE REALIZA CAMBIO DE LECTOR DE BARRAS YA QUE NO FUNCIONABA SE CAMBIÓ POR UN SYMBOL SE REALIZA PRUEBAS OK | W5: VISITA_TÉCNICA | X5: ON0IZ819 | Y5: TIPO I | Z5: TERRESTRE | AA5: ESCOBAR LENIS JUAN SEBASTIAN | AB5: 1 | AC5: 0 | AD5: =IF(W5="SOPORTE_TELEFÓNICO",'BASE LIQUIDACION REDEBAN 2025'!$B$19,IF(W5="ENVÍO",'BASE LIQUIDACION REDEBAN 2025'!$C$2,IF(Y5="TIPO I",'BASE LIQUIDACION REDEBAN 2025'!$C$2,IF(Y5="TIPO II",'BASE LIQUIDACION REDEBAN 2025'!$C$3,IF(Y5="TIPO III",'BASE LIQUIDACION REDEBAN 2025'!$C$4,IF(Y5="TIPO IV",'BASE LIQUIDACION REDEBAN 2025'!$C$5,IF(Z5="AEREO",'BASE LIQUIDACION REDEBAN 2025'!$B$6,'BASE LIQUIDACION REDEBAN 2025'!$C$5))))))) -> 65960.072 | AE5: =IF(OR(W5="SOPORTE_TELEFÓNICO",W5="ENVÍO"),0,IF(Y5="TIPO I",'BASE LIQUIDACION REDEBAN 2025'!$B$10,IF(Y5="TIPO II",'BASE LIQUIDACION REDEBAN 2025'!$B$11,IF(Y5="TIPO III",'BASE LIQUIDACION REDEBAN 2025'!$B$12,'BASE LIQUIDACION REDEBAN 2025'!$B$13)))) -> 75096.394 | AF5: =IF(OR(W5="SOPORTE_TELEFÓNICO",W5="ENVÍO"),AD5,(AD5*AB5+AE5*AC5)) -> 65960.072
A6: CALI | B6: =VLOOKUP(A6,'CENTRO DE COSTOS'!A:D,4,FALSE) -> DIEGO FERNANDO HENAO CARDONA | C6: =VLOOKUP(A6,'CENTRO DE COSTOS'!A:D,2,FALSE) -> 0004-0003 | D6: 76364 | E6: 2814200 | F6: 17613 | G6: INCIDENTE | H6: VALLE DEL CAUCA | I6: JAMUNDI | J6: BARRIO TERRANOVA III JAMUNDI | K6: REDEBAN | L6: FO-25-1603460 | M6: 45930.421 | N6: 45930.717 | O6: NO | P6: HARDWARE | Q6: COMUNICACION | R6: MENSAJE CABLE DE RED DESCONECTADO | U6: CERRADO | V6: 30/09/2025 SE REALIZA CAMBIO DE EQUIPO E6 PUERTO IP MALO, CB BANCOLOMBIA PURO, PRUEBAS OK | W6: VISITA_TÉCNICA | X6: II00S911 | Y6: TIPO II | Z6: TERRESTRE | AA6: PAREDES CASTILLO DIEGO | AB6: 1 | AC6: 0 | AD6: =IF(W6="SOPORTE_TELEFÓNICO",'BASE LIQUIDACION REDEBAN 2025'!$B$19,IF(W6="ENVÍO",'BASE LIQUIDACION REDEBAN 2025'!$C$2,IF(Y6="TIPO I",'BASE LIQUIDACION REDEBAN 2025'!$C$2,IF(Y6="TIPO II",'BASE LIQUIDACION REDEBAN 2025'!$C$3,IF(Y6="TIPO III",'BASE LIQUIDACION REDEBAN 2025'!$C$4,IF(Y6="TIPO IV",'BASE LIQUIDACION REDEBAN 2025'!$C$5,IF(Z6="AEREO",'BASE LIQUIDACION REDEBAN 2025'!$B$6,'BASE LIQUIDACION REDEBAN 2025'!$C$5))))))) -> 144967.87 | AE6: =IF(OR(W6="SOPORTE_TELEFÓNICO",W6="ENVÍO"),0,IF(Y6="TIPO I",'BASE LIQUIDACION REDEBAN 2025'!$B$10,IF(Y6="TIPO II",'BASE LIQUIDACION REDEBAN 2025'!$B$11,IF(Y6="TIPO III",'BASE LIQUIDACION REDEBAN 2025'!$B$12,'BASE LIQUIDACION REDEBAN 2025'!$B$13)))) -> 140395.63 | AF6: =IF(OR(W6="SOPORTE_TELEFÓNICO",W6="ENVÍO"),AD6,(AD6*AB6+AE6*AC6)) -> 144967.87
A7: MEDELLIN | B7: =VLOOKUP(A7,'CENTRO DE COSTOS'!A:D,4,FALSE) -> JUAN SEBASTIÁN RÍOS CASTRILLÓN | C7: =VLOOKUP(A7,'CENTRO DE COSTOS'!A:D,2,FALSE) -> 0004-0005 | D7: 5579 | E7: 2812568 | F7: 51485 | G7: INCIDENTE | H7: ANTIOQUIA | I7: PUERTO BERRIO | J7: PTM PUERTO BERRIO SERVICENTRO | K7: REDEBAN | L7: FO-25-1601968 | M7: 45930.333 | N7: 45930.621 | O7: NO | P7: HARDWARE | Q7: COMUNICACION | R7: MENSAJE CABLE DE RED DESCONECTADO | U7: CERRADO | V7: 30/09/2025 SE HACE MANTENIMIENTO OK SE ORGANIZAN CABLEADOS DE DATÁFONO SE COMFIGURA PARÁMETROS DE DE DATÁFONO OK PRUEBAS EXITOSAS | W7: VISITA_TÉCNICA | X7: 9BRZZ690 | Y7: TIPO III | Z7: TERRESTRE | AA7: DIAZ ZABALA FRANCIS DUBAN | AB7: 1 | AC7: 0 | AD7: =IF(W7="SOPORTE_TELEFÓNICO",'BASE LIQUIDACION REDEBAN 2025'!$B$19,IF(W7="ENVÍO",'BASE LIQUIDACION REDEBAN 2025'!$C$2,IF(Y7="TIPO I",'BASE LIQUIDACION REDEBAN 2025'!$C$2,IF(Y7="TIPO II",'BASE LIQUIDACION REDEBAN 2025'!$C$3,IF(Y7="TIPO III",'BASE LIQUIDACION REDEBAN 2025'!$C$4,IF(Y7="TIPO IV",'BASE LIQUIDACION REDEBAN 2025'!$C$5,IF(Z7="AEREO",'BASE LIQUIDACION REDEBAN 2025'!$B$6,'BASE LIQUIDACION REDEBAN 2025'!$C$5))))))) -> 275728.78 | AE7: =IF(OR(W7="SOPORTE_TELEFÓNICO",W7="ENVÍO"),0,IF(Y7="TIPO I",'BASE LIQUIDACION REDEBAN 2025'!$B$10,IF(Y7="TIPO II",'BASE LIQUIDACION REDEBAN 2025'!$B$11,IF(Y7="TIPO III",'BASE LIQUIDACION REDEBAN 2025'!$B$12,'BASE LIQUIDACION REDEBAN 2025'!$B$13)))) -> 196536.53 | AF7: =IF(OR(W7="SOPORTE_TELEFÓNICO",W7="ENVÍO"),AD7,(AD7*AB7+AE7*AC7)) -> 275728.78
A8: MEDELLIN | B8: =VLOOKUP(A8,'CENTRO DE COSTOS'!A:D,4,FALSE) -> JUAN SEBASTIÁN RÍOS CASTRILLÓN | C8: =VLOOKUP(A8,'CENTRO DE COSTOS'!A:D,2,FALSE) -> 0004-0005 | D8: 5001 | E8: 2811767 | F8: 37382 | G8: INCIDENTE | H8: ANTIOQUIA | I8: MEDELLIN | J8: BARRIO MANRIQUE MEDELLIN 5 | K8: REDEBAN | L8: FO-25-1601523 | M8: 45930.333 | N8: 45930.601 | O8: NO | P8: HARDWARE | Q8: HUB | R8: DETERIORO CABLE | U8: CERRADO | V8: 30/09/2025 SE REALIZA LIMPIEZA DEL LECTOR CHIP DE PINPAD, SE CAMBIA HUB CON EL CABLE PELADO, SE DEJAN SERVICIOS FUNCIONANDO CORRECTAMENTE | W8: VISITA_TÉCNICA | X8: AB00N148 | Y8: TIPO I | Z8: TERRESTRE | AA8: BARRIENTOS HERNANDEZ CRISTIAN HORACIO | AB8: 1 | AC8: 0 | AD8: =IF(W8="SOPORTE_TELEFÓNICO",'BASE LIQUIDACION REDEBAN 2025'!$B$19,IF(W8="ENVÍO",'BASE LIQUIDACION REDEBAN 2025'!$C$2,IF(Y8="TIPO I",'BASE LIQUIDACION REDEBAN 2025'!$C$2,IF(Y8="TIPO II",'BASE LIQUIDACION REDEBAN 2025'!$C$3,IF(Y8="TIPO III",'BASE LIQUIDACION REDEBAN 2025'!$C$4,IF(Y8="TIPO IV",'BASE LIQUIDACION REDEBAN 2025'!$C$5,IF(Z8="AEREO",'BASE LIQUIDACION REDEBAN 2025'!$B$6,'BASE LIQUIDACION REDEBAN 2025'!$C$5))))))) -> 65960.072 | AE8: =IF(OR(W8="SOPORTE_TELEFÓNICO",W8="ENVÍO"),0,IF(Y8="TIPO I",'BASE LIQUIDACION REDEBAN 2025'!$B$10,IF(Y8="TIPO II",'BASE LIQUIDACION REDEBAN 2025'!$B$11,IF(Y8="TIPO III",'BASE LIQUIDACION REDEBAN 2025'!$B$12,'BASE LIQUIDACION REDEBAN 2025'!$B$13)))) -> 75096.394 | AF8: =IF(OR(W8="SOPORTE_TELEFÓNICO",W8="ENVÍO"),AD8,(AD8*AB8+AE8*AC8)) -> 65960.072
A9: CALI | B9: =VLOOKUP(A9,'CENTRO DE COSTOS'!A:D,4,FALSE) -> DIEGO FERNANDO HENAO CARDONA | C9: =VLOOKUP(A9,'CENTRO DE COSTOS'!A:D,2,FALSE) -> 0004-0003 | D9: 76001 | E9: 2811812 | F9: 78740 | G9: INCIDENTE | H9: VALLE DEL CAUCA | I9: CALI | J9: PTM CALI MISCELANEA Y PAPELERI | K9: REDEBAN | L9: FO-25-1601527 | M9: 45930.333 | N9: 45930.488 | O9: NO | P9: HARDWARE | Q9: LECTOR DE TARJETAS | R9: MENSAJE RETIRE TARJETA | U9: CERRADO | V9: 30/09/2025 SE REALIZA MANTENIMIENTO PREVENTIVO Y SE EXTRAE PLÁSTICO DE SU INTERIOR. SE REALIZA PRUEBAS OPERATIVAS SIN NOVEDAD. CB QUEDA OKEY. | W9: VISITA_TÉCNICA | X9: LMQZZ730 | Y9: TIPO I | Z9: TERRESTRE | AA9: TORRES GARCIA JENDRY JOSE | AB9: 1 | AC9: 0 | AD9: =IF(W9="SOPORTE_TELEFÓNICO",'BASE LIQUIDACION REDEBAN 2025'!$B$19,IF(W9="ENVÍO",'BASE LIQUIDACION REDEBAN 2025'!$C$2,IF(Y9="TIPO I",'BASE LIQUIDACION REDEBAN 2025'!$C$2,IF(Y9="TIPO II",'BASE LIQUIDACION REDEBAN 2025'!$C$3,IF(Y9="TIPO III",'BASE LIQUIDACION REDEBAN 2025'!$C$4,IF(Y9="TIPO IV",'BASE LIQUIDACION REDEBAN 2025'!$C$5,IF(Z9="AEREO",'BASE LIQUIDACION REDEBAN 2025'!$B$6,'BASE LIQUIDACION REDEBAN 2025'!$C$5))))))) -> 65960.072 | AE9: =IF(OR(W9="SOPORTE_TELEFÓNICO",W9="ENVÍO"),0,IF(Y9="TIPO I",'BASE LIQUIDACION REDEBAN 2025'!$B$10,IF(Y9="TIPO II",'BASE LIQUIDACION REDEBAN 2025'!$B$11,IF(Y9="TIPO III",'BASE LIQUIDACION REDEBAN 2025'!$B$12,'BASE LIQUIDACION REDEBAN 2025'!$B$13)))) -> 75096.394 | AF9: =IF(OR(W9="SOPORTE_TELEFÓNICO",W9="ENVÍO"),AD9,(AD9*AB9+AE9*AC9)) -> 65960.072
A10: MEDELLIN | B10: =VLOOKUP(A10,'CENTRO DE COSTOS'!A:D,4,FALSE) -> JUAN SEBASTIÁN RÍOS CASTRILLÓN | C10: =VLOOKUP(A10,'CENTRO DE COSTOS'!A:D,2,FALSE) -> 0004-0005 | D10: 5190 | E10: 2811562 | F10: 27117 | G10: INCIDENTE | H10: ANTIOQUIA | I10: CISNEROS | J10: BARRIO PARQUE PRINCIPAL CISNER | K10: REDEBAN | L10: FO-25-1601037 | M10: 45929.734 | N10: 45930.6 | O10: NO | P10: HARDWARE | Q10: IMPRESION | R10: NO IMPRIME UNO O VARIOS CARACTERES | U10: CERRADO | V10: 30/09/2025 SE HACE MANTENIMIENTO SE OK SE CAMBIA DATÁFONO POR EN IMPRESIÓN | W10: VISITA_TÉCNICA | X10: 1FZZZ568 | Y10: TIPO II | Z10: TERRESTRE | AA10: DIAZ ZABALA FRANCIS DUBAN | AB10: 1 | AC10: 0 | AD10: =IF(W10="SOPORTE_TELEFÓNICO",'BASE LIQUIDACION REDEBAN 2025'!$B$19,IF(W10="ENVÍO",'BASE LIQUIDACION REDEBAN 2025'!$C$2,IF(Y10="TIPO I",'BASE LIQUIDACION REDEBAN 2025'!$C$2,IF(Y10="TIPO II",'BASE LIQUIDACION REDEBAN 2025'!$C$3,IF(Y10="TIPO III",'BASE LIQUIDACION REDEBAN 2025'!$C$4,IF(Y10="TIPO IV",'BASE LIQUIDACION REDEBAN 2025'!$C$5,IF(Z10="AEREO",'BASE LIQUIDACION REDEBAN 2025'!$B$6,'BASE LIQUIDACION REDEBAN 2025'!$C$5))))))) -> 144967.87 | AE10: =IF(OR(W10="SOPORTE_TELEFÓNICO",W10="ENVÍO"),0,IF(Y10="TIPO I",'BASE LIQUIDACION REDEBAN 2025'!$B$10,IF(Y10="TIPO II",'BASE LIQUIDACION REDEBAN 2025'!$B$11,IF(Y10="TIPO III",'BASE LIQUIDACION REDEBAN 2025'!$B$12,'BASE LIQUIDACION REDEBAN 2025'!$B$13)))) -> 140395.63 | AF10: =IF(OR(W10="SOPORTE_TELEFÓNICO",W10="ENVÍO"),AD10,(AD10*AB10+AE10*AC10)) -> 144967.87
A11: MEDELLIN | B11: =VLOOKUP(A11,'CENTRO DE COSTOS'!A:D,4,FALSE) -> JUAN SEBASTIÁN RÍOS CASTRILLÓN | C11: =VLOOKUP(A11,'CENTRO DE COSTOS'!A:D,2,FALSE) -> 0004-0005 | D11: 5001 | E11: 2811319 | F11: 47980 | G11: INCIDENTE | H11: ANTIOQUIA | I11: MEDELLIN | J11: DISTRICOL DROGUERIA TAYRONA | K11: REDEBAN | L11: FO-25-1600920 | M11: 45929.703 | N11: 45930.56 | O11: NO | P11: HARDWARE | Q11: LECTOR DE BARRAS | R11: FORMATO INVALIDO LECTOR DAÑADO | U11: CERRADO | V11: 30/09/2025 SE REALIZA CAMBIO DE LECTORA YA QUE LA ANTERIOR EN OCASIONES NO LEÍA. | W11: VISITA_TÉCNICA | X11: 9C00I718 | Y11: TIPO I | Z11: TERRESTRE | AA11: RAMIREZ TABARES JUAN DIEGO | AB11: 1 | AC11: 0 | AD11: =IF(W11="SOPORTE_TELEFÓNICO",'BASE LIQUIDACION REDEBAN 2025'!$B$19,IF(W11="ENVÍO",'BASE LIQUIDACION REDEBAN 2025'!$C$2,IF(Y11="TIPO I",'BASE LIQUIDACION REDEBAN 2025'!$C$2,IF(Y11="TIPO II",'BASE LIQUIDACION REDEBAN 2025'!$C$3,IF(Y11="TIPO III",'BASE LIQUIDACION REDEBAN 2025'!$C$4,IF(Y11="TIPO IV",'BASE LIQUIDACION REDEBAN 2025'!$C$5,IF(Z11="AEREO",'BASE LIQUIDACION REDEBAN 2025'!$B$6,'BASE LIQUIDACION REDEBAN 2025'!$C$5))))))) -> 65960.072 | AE11: =IF(OR(W11="SOPORTE_TELEFÓNICO",W11="ENVÍO"),0,IF(Y11="TIPO I",'BASE LIQUIDACION REDEBAN 2025'!$B$10,IF(Y11="TIPO II",'BASE LIQUIDACION REDEBAN 2025'!$B$11,IF(Y11="TIPO III",'BASE LIQUIDACION REDEBAN 2025'!$B$12,'BASE LIQUIDACION REDEBAN 2025'!$B$13)))) -> 75096.394 | AF11: =IF(OR(W11="SOPORTE_TELEFÓNICO",W11="ENVÍO"),AD11,(AD11*AB11+AE11*AC11)) -> 65960.072
A12: BOGOTA | B12: =VLOOKUP(A12,'CENTRO DE COSTOS'!A:D,4,FALSE) -> WILLIAM ASDRUBAL ROZO ROZO | C12: =VLOOKUP(A12,'CENTRO DE COSTOS'!A:D,2,FALSE) -> 0004-0004 | D12: 11001 | E12: 2810996 | F12: 75740 | G12: INCIDENTE | H12: CUNDINAMARCA | I12: BOGOTA | J12: BARRIO BOSA PRIMAVERA BOGOTA 1 | K12: REDEBAN | L12: FO-25-1600929 | M12: 45929.691 | N12: 45930.54 | O12: NO | P12: SOFTWARE | Q12: ERROR DE TRANSACCIONES | R12: RECHAZO GENERAL | U12: CERRADO | V12: 30/09/2025 SE REALIZA BORRADO DE DATAFONO SE DEJA VERSIÓN 9.90 POR FALLA EN PARÁMETROS DE COMUNICACIÓN POR REVERSO PENDIENTE PRUEBA OK | W12: VISITA_TÉCNICA | X12: V100R766 | Y12: TIPO I | Z12: TERRESTRE | AA12: ORTIZ MARTINEZ STIVEN | AB12: 1 | AC12: 0 | AD12: =IF(W12="SOPORTE_TELEFÓNICO",'BASE LIQUIDACION REDEBAN 2025'!$B$19,IF(W12="ENVÍO",'BASE LIQUIDACION REDEBAN 2025'!$C$2,IF(Y12="TIPO I",'BASE LIQUIDACION REDEBAN 2025'!$C$2,IF(Y12="TIPO II",'BASE LIQUIDACION REDEBAN 2025'!$C$3,IF(Y12="TIPO III",'BASE LIQUIDACION REDEBAN 2025'!$C$4,IF(Y12="TIPO IV",'BASE LIQUIDACION REDEBAN 2025'!$C$5,IF(Z12="AEREO",'BASE LIQUIDACION REDEBAN 2025'!$B$6,'BASE LIQUIDACION REDEBAN 2025'!$C$5))))))) -> 65960.072 | AE12: =IF(OR(W12="SOPORTE_TELEFÓNICO",W12="ENVÍO"),0,IF(Y12="TIPO I",'BASE LIQUIDACION REDEBAN 2025'!$B$10,IF(Y12="TIPO II",'BASE LIQUIDACION REDEBAN 2025'!$B$11,IF(Y12="TIPO III",'BASE LIQUIDACION REDEBAN 2025'!$B$12,'BASE LIQUIDACION REDEBAN 2025'!$B$13)))) -> 75096.394 | AF12: =IF(OR(W12="SOPORTE_TELEFÓNICO",W12="ENVÍO"),AD12,(AD12*AB12+AE12*AC12)) -> 65960.072
