Workbook
Name A: #REF!
Name A: #REF!
Name ACTIVIDAD: [1]Hoja2!$P$2:$P$30
Name Actividad: [2]Formulas!$H$2:$H$5000
Name Analistas: '[3]Listas Desplegables'!$T$2:$T$7
Name arearesponsable: '[4]Listas desplegables'!$BB$2:$BB$100
Name CCO: [5]Tecnicos!$A$2:$A$1000
Name Clientes: [6]Clientes!$A$2:$A$100
Name Clientes: [2]Clientes!$A$2:$A$100
Name COORDINADOR: [1]Hoja2!$D$2:$D$30
Name Coordinadores: [7]Coordinadores!$A$2:$A$1000
Name Coordinadores: [2]Coordinadores!$A$2:$A$1000
Name DOCUMENTADOR: [1]Hoja2!$A$2:$A$30
Name ES: [1]Hoja2!$K$2:$K$30
Name ESS: [1]Hoja2!$K$2:$K$30
Name Estado: [6]Formulas!$K$2:$K$5000
Name Estado: [2]Formulas!$K$2:$K$5000
Name ESTADOACTIVIDAD: [1]Hoja2!$M$2:$M$30
Name ESTADOS: '[8]Listas desplegables'!$B$1:$D$1
Name ESTADOS: '[9]Listas desplegables'!$B$1:$D$1
Name ESTADOSCIERRES: '[10]lista desplegable'!$CX$1:$DA$1
Name Facturacion: '[11]Listas desplegables'!$AO$1:$AR$1
Name FACTURACIÓN: '[8]Listas desplegables'!$Y$1:$AB$1
Name FACTURACIÓN: '[9]Listas desplegables'!$Y$1:$AB$1
Name falla: #REF!
Name Fallas: '[12]Listas desplegables'!$F$2:$L$2
Name Fallas: '[13]Listas desplegables'!$F$2:$L$2
Name Grupo_Falla: '[14]Listas Desplegables'!$CH$2:$CH$5
Name Grupo_Falla: '[15]Listas Desplegables'!$CH$2:$CH$5
Name inconservmanager: '[16]Listas desplegables'!$BC$2:$BC$100
Name inconservmanager: '[4]Listas desplegables'!$BC$2:$BC$100
Name INCUMPLIMIENTO: '[4]Listas desplegables'!$AK$1:$AN$1
Name INCUMPLIMIENTO: '[17]Listas desplegables'!$AT$1:$AX$1
Name LISTA: [18]Dptos!$A$1139:$A$1171
Name LISTA: [19]Dptos!$A$1139:$A$1171
Name LISTA2: #REF!
Name LISTA2: #REF!
Name LOLO: [20]Coordinadores!$A$2:$A$1000
Name solicitudes: '[11]Listas desplegables'!$U$1:$AF$1
Name solicitudes: '[21]Listas desplegables'!$AF$1:$AQ$1
Name Tecnicos: [6]Tecnicos!$A$2:$A$1000
Name Tecnicos: [2]Tecnicos!$A$2:$A$1000
Name Version: [22]Formulas!$I$2:$I$3
Name Version: [2]Formulas!$I$2:$I$3

Sheet Detalle REDEBAN
A1: FACTURACIÓN ACTIVIDADES REDEBAN CB BANCOLOMBIA Y AVAL
A2: 1 AL 30 DE JUNIO 2025
A4: CONCEPTOS | B4: CANTIDAD | C4: TOTAL
A5: Aperturas Bancolombia | B5: =COUNTA('APERTURAS BANCOLOMBIA'!$A:$A)-1 -> 512 | C5: ='APERTURAS BANCOLOMBIA'!AK514 -> 88508256
A6: Incidentes Bancolombia | B6: =COUNTA('INCIDENTES BANCOLOMBIA'!A:A)-1 -> 1087 | C6: ='INCIDENTES BANCOLOMBIA'!AM1089 -> 1.7392227e+08
A7: Gestión de Campo Bancolombia | B7: =COUNTA('OC BANCOLOMBIA'!A:A)-1 -> 504 | C7: ='OC BANCOLOMBIA'!AK506 -> 76580751
A8: Soporte Papelería Bancolombia | B8: =COUNTA(PAPELERIA!A:A)-1 -> 971 | C8: =PAPELERIA!AF973 -> 41393662
A9: Aperturas Aval | B9: =COUNTA('APERTURAS AVAL'!A:A)-1 -> 236 | C9: ='APERTURAS AVAL'!AJ238 -> 40577199
A10: Incidentes Aval | B10: =COUNTA('INCIDENTES AVAL'!A:A)-1 -> 308 | C10: ='INCIDENTES AVAL'!AO310 -> 36230429
A11: Gestión de Campo Aval | B11: =COUNTA('OC AVAL'!A:A)-1 -> 132 | C11: ='OC AVAL'!AF134 -> 15917098
A12: Aperturas BBVA | B12: =COUNTA('APERTURAS BBVA'!A:A)-1 -> 0 | C12: ='APERTURAS BBVA'!AH3 -> 0
A13: Gestión de Campo BBVA | B13: =COUNTA('OC BBVA'!A:A)-1 -> 2 | C13: ='OC BBVA'!AO4 -> 289935.74
A14: Incidentes BBVA | B14: =COUNTA('INCIDENTES BBVA'!A:A)-1 -> 0 | C14: ='INCIDENTES BBVA'!AN4 -> 0
A15: SUBTOTAL | C15: =SUM(C5:C14) -> 4.734196e+08
A16: Iva | C16: =C15*0.19 -> 89949724
A17: TOTAL | B17: TOTAL | C17: =C15+C16 -> 5.6336933e+08

Sheet BASE LIQUIDACION REDEBAN 2025
A1: Tipificación | B1: Implementaciones | C1: Incidentes – Ordenes de Cambio | D1: Fallida | G1: Tipificación | H1: Actividad sin cambio de datafono | J1: Actividad + adicional cambio de datafono | L1: Visita Fallida | N1: Incremento 2025
A2: TIPO I | B2: =71384.4052*(1+$N$2) -> 75096.394 | C2: =62699.6885*(1+$N$2) -> 65960.072 | D2: =35693.4343*(1+$N$2) -> 37549.493 | H2: Instalación Pinpad + HUB | I2: Segunda actividad en mismo comercio, misma visita | J2: Instalación Pinpad + HUB | K2: Segunda actividad en mismo comercio, misma visita | N2: 0.052
A3: TIPO II | B3: =155716.4408*(1+$N$2) -> 163813.7 | C3: =137802.16*(1+$N$2) -> 144967.87 | D3: =117879.8485*(1+$N$2) -> 124009.6 | G3: Tipo I | H3: =31819.23994686*(1+$N$2) -> 33473.84 | I3: =26222.67548178*(1+$N$2) -> 27586.255 | J3: =51196.46628516*(1+$N$2) -> 53858.683 | K3: =42157.66342524*(1+$N$2) -> 44349.862 | L3: =28948.10610808*(1+$N$2) -> 30453.408
A4: TIPO III | B4: =262099.6015*(1+$N$2) -> 275728.78 | C4: =262099.6015*(1+$N$2) -> 275728.78 | D4: =262099.6015*(1+$N$2) -> 275728.78 | G4: Tipo II | H4: =98014.03066668*(1+$N$2) -> 103110.76 | I4: =26222.67548178*(1+$N$2) -> 27586.255 | J4: =119562.49505524*(1+$N$2) -> 125779.74 | K4: =42157.66342524*(1+$N$2) -> 44349.862 | L4: =94765.6295813*(1+$N$2) -> 99693.442
A5: TIPO IV | B5: =479878.9419*(1+$N$2) -> 504832.65 | C5: =455882.9625*(1+$N$2) -> 479588.88 | D5: =370911.6746*(1+$N$2) -> 390199.08 | G5: Tipo III | H5: =189140.9827006*(1+$N$2) -> 198976.31 | I5: =26222.67548178*(1+$N$2) -> 27586.255 | J5: =200461.60194168*(1+$N$2) -> 210885.61 | K5: =42157.66342524*(1+$N$2) -> 44349.862 | L5: =171492.68108896*(1+$N$2) -> 180410.3
A6: Destino Aéreo | B6: =939603.5767*(1+$N$2) -> 988462.96 | C6: a partir del 5to servicio | G6: Tipo IV | H6: =461621.60109668*(1+$N$2) -> 485625.92 | I6: =26222.67548178*(1+$N$2) -> 27586.255 | J6: =461621.60109668*(1+$N$2) -> 485625.92 | K6: =42157.66342524*(1+$N$2) -> 44349.862 | L6: =461621.60109668*(1+$N$2) -> 485625.92
G7: * Tipo IV Especial Donde se requiera desplazamiento aéreo o fluvial será facturado el valor de la actividad y adicional el valor de $988.463 por cada 5 actividades de esta tipología
A8: Tarifas para día adicional de actividades:
A9: Tipificación | B9: Día adicional- menos de dos horas | C9: Medio día adicional | D9: Día adicional- más de 4 horas
A10: Tipo I | B10: =71384.4052*(1+$N$2) -> 75096.394 | C10: =133455.9267*(1+$N$2) -> 140395.63 | D10: =191225.1201*(1+$N$2) -> 201168.83 | G10: Actividad | H10: Unidad | I10: Valor Unitario
A11: Tipo II | B11: =133455.9267*(1+$N$2) -> 140395.63 | C11: =191225.1201*(1+$N$2) -> 201168.83 | D11: =257740.6152*(1+$N$2) -> 271143.13 | G11: Gestión telefónica y cierre de incidente de bloqueo | H11: Unidad | I11: =17639.19516086*(1+$N$2) -> 18556.433
A12: Tipo III | B12: =186821.7926*(1+$N$2) -> 196536.53 | C12: =248892.0824*(1+$N$2) -> 261834.47 | D12: =306662.5075*(1+$N$2) -> 322608.96 | G12: Servicio de cierre de incidente de bloqueo | H12: Unidad | I12: =4810.80785492*(1+$N$2) -> 5060.9699
A13: Tipo IV | B13: =186821.7926*(1+$N$2) -> 196536.53 | C13: =248892.0824*(1+$N$2) -> 261834.47 | D13: =306662.5075*(1+$N$2) -> 322608.96
A16: Servicio | B16: Tarifa actividad | D16: VALOR DE LA TERMINAL ADICIONAL | E16: VALOR DE INSTALACIÓN DE BASE EN "Y"
A17: Papelería – Tarifa única | B17: =34010.9321*(1+$N$2) -> 35779.501 | D17: =20537.3658*(1+$N$2) -> 21605.309 | E17: =10737.9606*(1+$N$2) -> 11296.335
A18: Papelería Tipo II - Visita técnica | B18: =64310*(1+$N$2) -> 67654.12
A19: Solución telefónica | B19: =39202.5476*(1+$N$2) -> 41241.08
A22: Traifas 2024
A23: Tipificación | B23: Implementaciones | C23: Incidentes – Ordenes de Cambio | D23: Fallida | G23: Tipificación | H23: Actividad sin cambio de datafono | J23: Actividad + adicional cambio de datafono | L23: Visita Fallida
A24: TIPO I | B24: 71384.405 | C24: 62699.689 | D24: 35693.434 | H24: Instalación Pinpad + HUB | I24: Segunda actividad en mismo comercio, misma visita | J24: Instalación Pinpad + HUB | K24: Segunda actividad en mismo comercio, misma visita
A25: TIPO II | B25: 155716.44 | C25: 137802.16 | D25: 117879.85 | G25: Tipo I | H25: 31819.24 | I25: 26222.675 | J25: 51196.466 | K25: 42157.663 | L25: 28948.106
A26: TIPO III | B26: 262099.6 | C26: 262099.6 | D26: 262099.6 | G26: Tipo II | H26: 98014.031 | I26: 26222.675 | J26: 119562.5 | K26: 42157.663 | L26: 94765.63
A27: TIPO IV | B27: 479878.94 | C27: 455882.96 | D27: 370911.67 | G27: Tipo III | H27: 189140.98 | I27: 26222.675 | J27: 200461.6 | K27: 42157.663 | L27: 171492.68
A28: Destino Aéreo | B28: 939603.58 | C28: a partir del 5to servicio | G28: Tipo IV | H28: 461621.6 | I28: 26222.675 | J28: 461621.6 | K28: 42157.663 | L28: 461621.6
G29: * Tipo IV Especial Donde se requiera desplazamiento aéreo o fluvial será facturado el valor de la actividad y adicional el valor de $939,604 por cada 5 actividades de esta tipología
A30: Tarifas para día adicional de actividades:
A31: Tipificación | B31: Día adicional- menos de dos horas | C31: Medio día adicional | D31: Día adicional- más de 4 horas
A32: Tipo I | B32: 71384.405 | C32: 133455.93 | D32: 191225.12 | G32: Actividad | H32: Unidad | I32: Valor Unitario
A33: Tipo II | B33: 133455.93 | C33: 191225.12 | D33: 257740.62 | G33: Gestión telefónica y cierre de incidente de bloqueo | H33: Unidad | I33: 17639.195
A34: Tipo III | B34: 186821.79 | C34: 248892.08 | D34: 306662.51 | G34: Servicio de cierre de incidente de bloqueo | H34: Unidad | I34: 4810.8079
A35: Tipo IV | B35: 186821.79 | C35: 248892.08 | D35: 306662.51
A38: Servicio | B38: Tarifa actividad | D38: VALOR DE LA TERMINAL ADICIONAL | E38: VALOR DE INSTALACIÓN DE BASE EN "Y"
A39: Papelería – Tarifa única | B39: 34010.932 | D39: 20537.366 | E39: 10737.961
A40: Papelería Tipo II - Visita técnica | B40: 64310
A41: Solución telefónica | B41: 39202.548

Sheet CENTRO DE COSTOS
A1: CIUDAD | B1: CENTRO_COSTO | C1: DESCRIPCION | D1: COORDINADOR
A2: APARTADO | B2: 0004-0005 | C2: Redeban Noroccidente (Medellín) | D2: JUAN SEBASTIÁN RÍOS CASTRILLÓN
A3: BARRANQUILLA | B3: 0004-0001 | C3: Redeban Costa (Barranqullla) | D3: JOSE MAURICIO HERNANDEZ ROJAS
A4: BOGOTA | B4: 0004-0004 | C4: Redeban Centro ( Bogotá) | D4: WILLIAM ASDRUBAL ROZO ROZO
A5: BUCARAMANGA | B5: 0004-0008 | C5: Redeban Santander | D5: MIGUEL JULIÁN HERNÁNDEZ GUARÍN
A6: CALI | B6: 0004-0003 | C6: Redeban Suroccidente (Cali) | D6: DIEGO FERNANDO HENAO CARDONA
A7: CARTAGENA | B7: 0004-0001 | C7: Redeban Costa (Barranqullla) | D7: JOSE MAURICIO HERNANDEZ ROJAS
A8: CUCUTA | B8: 0004-0008 | C8: Redeban Santander | D8: MIGUEL JULIÁN HERNÁNDEZ GUARÍN
A9: FLORENCIA | B9: 0004-0007 | C9: Redeban Oriente (Otros) | D9: KEVIN ALEXIS CORZO BUSTOS
A10: IBAGUE | B10: 0004-0007 | C10: Redeban Oriente (Otros) | D10: KEVIN ALEXIS CORZO BUSTOS
A11: MANIZALES | B11: 0004-0002 | C11: Redeban Eje Cafetero (Pereira) | D11: DIEGO FERNANDO HENAO CARDONA
A12: MEDELLIN | B12: 0004-0005 | C12: Redeban Noroccidente (Medellín) | D12: JUAN SEBASTIÁN RÍOS CASTRILLÓN
... A23: YOPAL | B23: 0004-0007 | C23: Redeban Oriente (Otros) | D23: KEVIN ALEXIS CORZO BUSTOS

Sheet Tablas dinámicas
A1: APERTURAS BANCOLOMBIA | G1: NOMBRE DE CC | H1: Suma de VALOR CC | I1: Suma de VALOR CC2
A2: COORDINADOR | B2: CENTRO DE COSTOS | C2: Suma de VALOR FACTURABLE A LA RED | D2: NOMBRE DE CC | E2: VALOR CC | G2: Redeban Centro ( Bogotá) | H2: 57891327 | I2: 0.12228333
A3: DIEGO FERNANDO HENAO CARDONA | B3: 0004-0002 | C3: 4042347.6 | D3: =VLOOKUP(B3,'CENTRO DE COSTOS'!B:C,2,0) -> Redeban Eje Cafetero (Pereira) | E3: =C3 -> 4042347.6 | G3: Redeban Costa (Barranqullla) | H3: 73951110 | I3: 0.15620627
B4: 0004-0003 | C4: 16115364 | D4: =VLOOKUP(B4,'CENTRO DE COSTOS'!B:C,2,0) -> Redeban Suroccidente (Cali) | E4: =C4 -> 16115364 | G4: Redeban Eje Cafetero (Pereira) | H4: 20201376 | I4: 0.042671186
A5: JOSE MAURICIO HERNANDEZ ROJAS | B5: 0004-0001 | C5: 14611827 | D5: =VLOOKUP(B5,'CENTRO DE COSTOS'!B:C,2,0) -> Redeban Costa (Barranqullla) | E5: =C5 -> 14611827 | G5: Redeban Noroccidente (Medellín) | H5: 94649348 | I5: 0.19992697
A6: JUAN SEBASTIÁN RÍOS CASTRILLÓN | B6: 0004-0005 | C6: 17750937 | D6: =VLOOKUP(B6,'CENTRO DE COSTOS'!B:C,2,0) -> Redeban Noroccidente (Medellín) | E6: =C6 -> 17750937 | G6: Redeban Oriente (Otros) | H6: 77158103 | I6: 0.16298037
A7: KEVIN ALEXIS CORZO BUSTOS | B7: 0004-0007 | C7: 13719277 | D7: =VLOOKUP(B7,'CENTRO DE COSTOS'!B:C,2,0) -> Redeban Oriente (Otros) | E7: =C7 -> 13719277 | G7: Redeban Santander | H7: 87798894 | I7: 0.18545682
A8: MIGUEL JULIÁN HERNÁNDEZ GUARÍN | B8: 0004-0008 | C8: 13834110 | D8: =VLOOKUP(B8,'CENTRO DE COSTOS'!B:C,2,0) -> Redeban Santander | E8: =C8 -> 13834110 | G8: Redeban Suroccidente (Cali) | H8: 61769445 | I8: 0.13047505
A9: WILLIAM ASDRUBAL ROZO ROZO | B9: 0004-0004 | C9: 8434394.3 | D9: =VLOOKUP(B9,'CENTRO DE COSTOS'!B:C,2,0) -> Redeban Centro ( Bogotá) | E9: =C9 -> 8434394.3 | G9: Total general | H9: 4.734196e+08 | I9: 1
A10: Total general | C10: 88508256
A15: INCIDENTES BANCOLOMBIA
A16: COORDINADOR | B16: CENTRO DE COSTOS | C16: Suma de VALOR FACTURABLE A LA RED | D16: NOMBRE DE CC | E16: VALOR CC
A17: DIEGO FERNANDO HENAO CARDONA | B17: 0004-0002 | C17: 6532633.7 | D17: =VLOOKUP(B17,'CENTRO DE COSTOS'!B:C,2,0) -> Redeban Eje Cafetero (Pereira) | E17: =C17 -> 6532633.7
B18: 0004-0003 | C18: 19798837 | D18: =VLOOKUP(B18,'CENTRO DE COSTOS'!B:C,2,0) -> Redeban Suroccidente (Cali) | E18: =C18 -> 19798837
A19: JOSE MAURICIO HERNANDEZ ROJAS | B19: 0004-0001 | C19: 29495276 | D19: =VLOOKUP(B19,'CENTRO DE COSTOS'!B:C,2,0) -> Redeban Costa (Barranqullla) | E19: =C19 -> 29495276
A20: JUAN SEBASTIÁN RÍOS CASTRILLÓN | B20: 0004-0005 | C20: 41891791 | D20: =VLOOKUP(B20,'CENTRO DE COSTOS'!B:C,2,0) -> Redeban Noroccidente (Medellín) | E20: =C20 -> 41891791
A21: KEVIN ALEXIS CORZO BUSTOS | B21: 0004-0007 | C21: 29538126 | D21: =VLOOKUP(B21,'CENTRO DE COSTOS'!B:C,2,0) -> Redeban Oriente (Otros) | E21: =C21 -> 29538126
A22: MIGUEL JULIÁN HERNÁNDEZ GUARÍN | B22: 0004-0008 | C22: 28604867 | D22: =VLOOKUP(B22,'CENTRO DE COSTOS'!B:C,2,0) -> Redeban Santander | E22: =C22 -> 28604867
A23: WILLIAM ASDRUBAL ROZO ROZO | B23: 0004-0004 | C23: 18060740 | D23: =VLOOKUP(B23,'CENTRO DE COSTOS'!B:C,2,0) -> Redeban Centro ( Bogotá) | E23: =C23 -> 18060740
A24: Total general | C24: 1.7392227e+08
A30: ORDENES DE CAMBIO BANCOLOMBIA
A31: COORDINADOR | B31: CENTRO DE COSTOS | C31: Suma de VALOR FACTURABLE A LA RED | D31: NOMBRE DE CC | E31: VALOR CC
A32: DIEGO FERNANDO HENAO CARDONA | B32: 0004-0002 | C32: 4000237.7 | D32: =VLOOKUP(B32,'CENTRO DE COSTOS'!B:C,2,0) -> Redeban Eje Cafetero (Pereira) | E32: =C32 -> 4000237.7
B33: 0004-0003 | C33: 9269370.8 | D33: =VLOOKUP(B33,'CENTRO DE COSTOS'!B:C,2,0) -> Redeban Suroccidente (Cali) | E33: =C33 -> 9269370.8
A34: JOSE MAURICIO HERNANDEZ ROJAS | B34: 0004-0001 | C34: 11963449 | D34: =VLOOKUP(B34,'CENTRO DE COSTOS'!B:C,2,0) -> Redeban Costa (Barranqullla) | E34: =C34 -> 11963449
A35: JUAN SEBASTIÁN RÍOS CASTRILLÓN | B35: 0004-0005 | C35: 13057799 | D35: =VLOOKUP(B35,'CENTRO DE COSTOS'!B:C,2,0) -> Redeban Noroccidente (Medellín) | E35: =C35 -> 13057799
A36: KEVIN ALEXIS CORZO BUSTOS | B36: 0004-0007 | C36: 11314313 | D36: =VLOOKUP(B36,'CENTRO DE COSTOS'!B:C,2,0) -> Redeban Oriente (Otros) | E36: =C36 -> 11314313
A37: MIGUEL JULIÁN HERNÁNDEZ GUARÍN | B37: 0004-0008 | C37: 14859474 | D37: =VLOOKUP(B37,'CENTRO DE COSTOS'!B:C,2,0) -> Redeban Santander | E37: =C37 -> 14859474
A38: WILLIAM ASDRUBAL ROZO ROZO | B38: 0004-0004 | C38: 12116106 | D38: =VLOOKUP(B38,'CENTRO DE COSTOS'!B:C,2,0) -> Redeban Centro ( Bogotá) | E38: =C38 -> 12116106
A39: Total general | C39: 76580751
A45: PAPELERIA BANCOLOMBIA
A46: COORDINADOR | B46: CENTRO DE COSTOS | C46: Suma de VALOR FACTURABLE A LA RED | D46: NOMBRE DE CC | E46: VALOR CC
A47: DIEGO FERNANDO HENAO CARDONA | B47: 0004-0002 | C47: 1666652.6 | D47: =VLOOKUP(B47,'CENTRO DE COSTOS'!B:C,2,0) -> Redeban Eje Cafetero (Pereira) | E47: =C47 -> 1666652.6
B48: 0004-0003 | C48: 6669879.6 | D48: =VLOOKUP(B48,'CENTRO DE COSTOS'!B:C,2,0) -> Redeban Suroccidente (Cali) | E48: =C48 -> 6669879.6
A49: JOSE MAURICIO HERNANDEZ ROJAS | B49: 0004-0001 | C49: 7453888.9 | D49: =VLOOKUP(B49,'CENTRO DE COSTOS'!B:C,2,0) -> Redeban Costa (Barranqullla) | E49: =C49 -> 7453888.9
A50: JUAN SEBASTIÁN RÍOS CASTRILLÓN | B50: 0004-0005 | C50: 11941816 | D50: =VLOOKUP(B50,'CENTRO DE COSTOS'!B:C,2,0) -> Redeban Noroccidente (Medellín) | E50: =C50 -> 11941816
A51: KEVIN ALEXIS CORZO BUSTOS | B51: 0004-0007 | C51: 3482961.8 | D51: =VLOOKUP(B51,'CENTRO DE COSTOS'!B:C,2,0) -> Redeban Oriente (Otros) | E51: =C51 -> 3482961.8
A52: MIGUEL JULIÁN HERNÁNDEZ GUARÍN | B52: 0004-0008 | C52: 6474091.4 | D52: =VLOOKUP(B52,'CENTRO DE COSTOS'!B:C,2,0) -> Redeban Santander | E52: =C52 -> 6474091.4
A53: WILLIAM ASDRUBAL ROZO ROZO | B53: 0004-0004 | C53: 3704371.5 | D53: =VLOOKUP(B53,'CENTRO DE COSTOS'!B:C,2,0) -> Redeban Centro ( Bogotá) | E53: =C53 -> 3704371.5
A54: Total general | C54: 41393662
...

Sheet APERTURAS BANCOLOMBIA
A1: CIUDAD BASE | B1: COORDINADOR | C1: CENTRO DE COSTOS | D1: CÓDIGO DANE | E1: TA | F1: FO | G1: FECHA LISTA | H1: FECHA LIMITE | I1: FECHA SOLICITUD DE LA ACTIVIDAD | J1: FECHA INICIO DE LA ACTIVIDAD | K1: FECHA ULTIMA ACTUALIZACION | L1: DEPARTAMENTO | M1: CIUDAD | N1: NOMBRE PUNTO | O1: CÓDIGO PUNTO | P1: TIPO DE SOLICITUD | Q1: ACTIVIDAD | R1: RED ASOCIADA AL PUNTO | S1: FORMATO | T1: CADENA | U1: ESTADO RESULTADO DE ACTIVIDAD | V1: OBSERVACIONES RESULTADO DE ACTIVIDAD | W1: TÉCNICO | X1: TERMINALES | Y1: PLACA DATAFONOS INSTALADOS | Z1: PLACA DATAFONOS RETIRADOS | AA1: PLACA LECTOR INSTALADO | AB1: PLACA LECTOR RETIRADO | AC1: CANTIDAD ROLLOS ENTREGADOS | AD1: TIPO DE ATENCION | AE1: TIPO DE TRAYECTO | AF1: FORMA DE ATENCIÓN | AG1: DIAS ACTIVIDAD FACTURABLES A LA RED | AH1: DIAS ACOMPAÑAMIENTO FACTURABLES A RED | AI1: VALOR DIAS ACTIVIDAD FACTURABLES A LA RED | AJ1: VALOR DIAS ACOMPAÑAMIENTO FACTURABLES A RED MENOS DE 2 HORAS | AK1: VALOR FACTURABLE A LA RED | AL1: CU CB | AM1: COBRO ENTIDAD | AN1: ESTADO | AO1: TIPO | AP1: VAL TIPO | AQ1: VAL COSTO | AR1: OBSERVACIONES | AS1: OBSERVACIONES LINEA
A2: PASTO | B2: =VLOOKUP(A2,'CENTRO DE COSTOS'!A:D,4,FALSE) -> DIEGO FERNANDO HENAO CARDONA | C2: =VLOOKUP(A2,'CENTRO DE COSTOS'!A:D,2,FALSE) -> 0004-0003 | D2: 52490 | E2: TA-25-545965 | F2: FO-25-823658 | G2: 45796 | H2: 45805 | I2: 45796 | J2: 45813 | K2: 45813 | L2: NARIÑO | M2: OLAYA HERRERA | N2: BARRIO SAN MARTIN 2 CORREGIMIENTO DE BOAS DE SATINGA OLAYA HERRERA | O2: 79313 | P2: CB CRECIMIENTO - NUEVO | Q2: APERTURA | R2: REDEBAN | S2: UNO A UNO | T2: UNO A UNO | U2: EJECUTADO | V2: 19-05-2025 SE REALIZA LLAMADA AL CLIENTE, SE HABLA CON LA SRA ALEIDA RIASCOS PERLAZA, SE VALIDA DIRECCIÓN OK, CANAL OK, DISPONIBILIDAD TOTAL, LLAMAR EL DÍA LA INSTALACIÓN PARA CONFIRMAR VISITA, AVISO EXTERIOR ALTURA APROX NO TIENE CONOCIMIENTO DE MEDIDAS; TOMACORRIENTE CERCANO: SI; TIENE CABINA DE SEGURIDAD:NO // CONTACTO REALIZADO POR WHATSAPP 28-05 SE REPROGRAMA VISITA PARA LA PRÓXIMA SEMANA SEBIDO A QUE NO SE LOGRO CONSEGUIR TRANSPORTE INTERMUNICIPAL DE CALI A BUENAVENTURA POR CIERRE DE LA VIA 05-06 SE REALIZA INSTALACIÓN DE CORRESPONSAL, SE INSTALAN EQUIPOS CON PRUEBAS EXITOSAS, SE CAPACITA Y SE EVALÚA AL CLIENTE, SE INSTALA PUBLICIDAD COMPLETA, CB QUEDA OPERATIVO. USUARIO SOMOS BANCOLOMBIA ACTIVO | W2: PAREDES CASTILLO DIEGO | X2: A4WZZ840 | Y2: 1169751 | Z2: N/A | AA2: 860310 | AB2: N/A | AC2: 40 ROLLOS | AD2: TIPO IV ESPECIAL | AE2: FLUVIAL | AF2: VISITA_TÉCNICA | AG2: 1 | AH2: 0 | AI2: =IF(AD2="TIPO I",'BASE LIQUIDACION REDEBAN 2025'!$B$2,IF(AD2="TIPO II",'BASE LIQUIDACION REDEBAN 2025'!$B$3,IF(AD2="TIPO III",'BASE LIQUIDACION REDEBAN 2025'!$B$4,IF(AD2="TIPO IV",'BASE LIQUIDACION REDEBAN 2025'!$B$5,IF(AE2="AEREO",'BASE LIQUIDACION REDEBAN 2025'!$B$6,'BASE LIQUIDACION REDEBAN 2025'!$B$5))))) -> 504832.65 | AJ2: =IF(AD2="TIPO I",'BASE LIQUIDACION REDEBAN 2025'!$B$10,IF(AD2="TIPO II",'BASE LIQUIDACION REDEBAN 2025'!$B$11,IF(AD2="TIPO III",'BASE LIQUIDACION REDEBAN 2025'!$B$12,'BASE LIQUIDACION REDEBAN 2025'!$B$13))) -> 196536.53 | AK2: =AG2*AI2+AH2*AJ2 -> 504832.65
A3: BUCARAMANGA | B3: =VLOOKUP(A3,'CENTRO DE COSTOS'!A:D,4,FALSE) -> MIGUEL JULIÁN HERNÁNDEZ GUARÍN | C3: =VLOOKUP(A3,'CENTRO DE COSTOS'!A:D,2,FALSE) -> 0004-0008 | D3: 68276 | E3: TA-25-545971 | F3: FO-25-856966 | G3: 45800 | H3: 45804 | I3: 45800 | J3: 45811 | K3: 45811 | L3: SANTANDER | M3: FLORIDABLANCA | N3: BARRIO CASCO ANTIGUO FLORIDABLANCA FLORIDABLANCA | O3: 79387 | P3: CAMBIO DE RAZON SOCIAL | Q3: APERTURA | R3: REDEBAN | S3: UNO A UNO | T3: UNO A UNO | U3: EJECUTADO | V3: 23-05 SE REALIZA LLAMADA AL CLIENTE, SE HABLA CON LA SRA CARLOS ANDRES MORALES OTERO SE VALIDA DIRECCIÓN OK, CANAL OK, DISPONIBILIDAD TOTAL, LLAMAR EL DÍA LA INSTALACIÓN PARA CONFIRMAR VISITA - CAMBIO DE RAZON SOCIAL - USUARIO SOLICITA FECHA PARA EL MIERCOLES 28-05 SE ESTABLECE COMUNICACIÓN CON EL SEÑOR CARLOS AL NÚMERO 3183832689 QUIEN SOLICITA QUE SE REPROGRAME ACTIVIDAD PARA EL DIA 2 DE JUNIO DEL AÑO EN CURSO DEBIDO A QUE SE ENCUENTRA REALIZAN UNOS EXÁMENES Y NO NOS PUEDE ATENDER 31-05 SE ESTABLECE COMUNICACIÓN CON EL SEÑOR CARLOS AL NÚMERO 3183832689 QUIEN SOLICITA QUE SE REPROGRAME ACTIVIDAD PARA EL DIA 3 DE JUNIO DEL AÑO EN CURSO DEBIDO A QUE SE ENCUENTRA REALIZAN UNOS EXÁMENES Y NO NOS PUEDE ATENDER 3/6/2025 SE REALIZA INSTALACIÓN DE CORRESPONSAL, SE INSTALAN EQUIPOS CON PRUEBAS EXITOSAS, SE CAPACITA Y SE EVALÚA AL CLIENTE, SE INSTALA PUBLICIDAD COMPLETA, CB QUEDA OPERATIVO. USUARIO SOMOS BANCOLOMBIA ACTIVO | W3: BARRERA ORTEGA MARLON STWAR | X3: 10XZZ925-SXXZZ344 | Y3: 989054-1016076 | Z3: 793883 | AA3: 1103341-893140 | AB3: N/A | AC3: 40 ROLLOS | AD3: TIPO I | AE3: TERRESTRE | AF3: VISITA_TÉCNICA | AG3: 1 | AH3: 0 | AI3: =IF(AD3="TIPO I",'BASE LIQUIDACION REDEBAN 2025'!$B$2,IF(AD3="TIPO II",'BASE LIQUIDACION REDEBAN 2025'!$B$3,IF(AD3="TIPO III",'BASE LIQUIDACION REDEBAN 2025'!$B$4,IF(AD3="TIPO IV",'BASE LIQUIDACION REDEBAN 2025'!$B$5,IF(AE3="AEREO",'BASE LIQUIDACION REDEBAN 2025'!$B$6,'BASE LIQUIDACION REDEBAN 2025'!$B$5))))) -> 75096.394 | AJ3: =IF(AD3="TIPO I",'BASE LIQUIDACION REDEBAN 2025'!$B$10,IF(AD3="TIPO II",'BASE LIQUIDACION REDEBAN 2025'!$B$11,IF(AD3="TIPO III",'BASE LIQUIDACION REDEBAN 2025'!$B$12,'BASE LIQUIDACION REDEBAN 2025'!$B$13))) -> 75096.394 | AK3: =AG3*AI3+AH3*AJ3 -> 75096.394
A4: VILLAVICENCIO | B4: =VLOOKUP(A4,'CENTRO DE COSTOS'!A:D,4,FALSE) -> KEVIN ALEXIS CORZO BUSTOS | C4: =VLOOKUP(A4,'CENTRO DE COSTOS'!A:D,2,FALSE) -> 0004-0007 | D4: 50124 | E4: TA-25-554280 | F4: FO-25-842171 | G4: 45800 | H4: 45804 | I4: 45800 | J4: 45812 | K4: 45812 | L4: META | M4: CABUYARO | N4: BARRIO CENTRO CABUYARO 5 | O4: 79356 | P4: CB CRECIMIENTO - NUEVO | Q4: APERTURA | R4: REDEBAN | S4: UNO A UNO | T4: UNO A UNO | U4: EJECUTADO | V4: 23-05 SE REALIZA LLAMADA AL CLIENTE, SE HABLA CON LA SR JULIETTE DANIELA QUIJANO ORTIZ SE VALIDA DIRECCIÓN OK, CANAL OK, DISPONIBILIDAD TOTAL, LLAMAR EL DÍA LA INSTALACIÓN PARA CONFIRMAR VISITA, AVISO EXTERIOR ALTURA APROX 2.50 METROS; TOMACORRIENTE CERCANO: SI; TIENE CABINA DE SEGURIDAD: NO 27-05 DE REALIZA CONTACTO TELEFÓNICO 3208738350 CON LA SEÑORA JULIETTE QUIEN MANIFIESTA EL DÍA DE HOY 27 MAYO NO NOS PUEDE ATENDER. SOLICITA VISITA PARA EL DÍA MARTES 3 DE JUNIO 03-06 SE PROGR 4/6/2025 SE REALIZA INSTALACIÓN DE CORRESPONSAL, SE INSTALAN EQUIPOS CON PRUEBAS EXITOSAS, SE CAPACITA Y SE EVALÚA AL CLIENTE, SE INSTALA PUBLICIDAD COMPLETA, CB QUEDA OPERATIVO. USUARIO SOMOS BANCOLOMBIA ACTIVO | W4: CASTRILLON URREA LONDIER LEANDRO | X4: 10XZZ894 | Y4: 859272 | Z4: N/A | AA4: 915631 | AB4: N/A | AC4: 40 ROLLOS | AD4: TIPO III | AE4: TERRESTRE | AF4: VISITA_TÉCNICA | AG4: 1 | AH4: 0 | AI4: =IF(AD4="TIPO I",'BASE LIQUIDACION REDEBAN 2025'!$B$2,IF(AD4="TIPO II",'BASE LIQUIDACION REDEBAN 2025'!$B$3,IF(AD4="TIPO III",'BASE LIQUIDACION REDEBAN 2025'!$B$4,IF(AD4="TIPO IV",'BASE LIQUIDACION REDEBAN 2025'!$B$5,IF(AE4="AEREO",'BASE LIQUIDACION REDEBAN 2025'!$B$6,'BASE LIQUIDACION REDEBAN 2025'!$B$5))))) -> 275728.78 | AJ4: =IF(AD4="TIPO I",'BASE LIQUIDACION REDEBAN 2025'!$B$10,IF(AD4="TIPO II",'BASE LIQUIDACION REDEBAN 2025'!$B$11,IF(AD4="TIPO III",'BASE LIQUIDACION REDEBAN 2025'!$B$12,'BASE LIQUIDACION REDEBAN 2025'!$B$13))) -> 196536.53 | AK4: =AG4*AI4+AH4*AJ4 -> 275728.78
A5: CALI | B5: =VLOOKUP(A5,'CENTRO DE COSTOS'!A:D,4,FALSE) -> DIEGO FERNANDO HENAO CARDONA | C5: =VLOOKUP(A5,'CENTRO DE COSTOS'!A:D,2,FALSE) -> 0004-0003 | D5: 19397 | E5: TA-25-554298 | F5: FO-25-842246 | G5: 45805 | H5: 45807 | I5: 45805 | J5: 45811 | K5: 45811 | L5: CAUCA | M5: LA VEGA | N5: BARRIO SANTA MARIA LA VEGA | O5: 79561 | P5: CB CRECIMIENTO - NUEVO | Q5: APERTURA | R5: REDEBAN | S5: UNO A UNO | T5: UNO A UNO | U5: EJECUTADO | V5: 28-05-2025 SE REALIZA LLAMADA AL CLIENTE, SE HABLA CON EL SR LEINER ALEJANDRO GARCIA MAMIAN SE VALIDA DIRECCIÓN OK, CANAL OK, DISPONIBILIDAD TOTAL, LLAMAR EL DÍA LA INSTALACIÓN PARA CONFIRMAR VISITA, AVISO EXTERIOR ALTURA APROX 1,60 METROS; TOMACORRIENTE CERCANO: SI; TIENE CABINA DE SEGURIDAD: NO // CONTACTO REALIZADO POR LA APP 30-05 SE REALIZA LLAMADA CELULAR AL SEÑOR LEINER Y SE LE INFORMA QUE POR TEMAS DE EL PARO ARMADO NO SE CUENTA CON TRANSPORTE A LA ZONA SE REPROGRAMA VISITA CON EL CB PARA EL DÍA MARTES 3/6/2025 SE REALIZA INSTALACIÓN DE CORRESPONSAL, SE INSTALAN EQUIPOS CON PRUEBAS EXITOSAS, SE CAPACITA Y SE EVALÚA AL CLIENTE, SE INSTALA PUBLICIDAD COMPLETA, CB QUEDA OPERATIVO. USUARIO SOMOS BANCOLOMBIA ACTIVO | W5: GIMBUEL LASSO LUIS GERMAN | X5: LMUZZ995 | Y5: 761185 | Z5: N/A | AA5: 933206 | AB5: N/A | AC5: 40 ROLLOS | AD5: TIPO IV | AE5: TERRESTRE | AF5: VISITA_TÉCNICA | AG5: 1 | AH5: 0 | AI5: =IF(AD5="TIPO I",'BASE LIQUIDACION REDEBAN 2025'!$B$2,IF(AD5="TIPO II",'BASE LIQUIDACION REDEBAN 2025'!$B$3,IF(AD5="TIPO III",'BASE LIQUIDACION REDEBAN 2025'!$B$4,IF(AD5="TIPO IV",'BASE LIQUIDACION REDEBAN 2025'!$B$5,IF(AE5="AEREO",'BASE LIQUIDACION REDEBAN 2025'!$B$6,'BASE LIQUIDACION REDEBAN 2025'!$B$5))))) -> 504832.65 | AJ5: =IF(AD5="TIPO I",'BASE LIQUIDACION REDEBAN 2025'!$B$10,IF(AD5="TIPO II",'BASE LIQUIDACION REDEBAN 2025'!$B$11,IF(AD5="TIPO III",'BASE LIQUIDACION REDEBAN 2025'!$B$12,'BASE LIQUIDACION REDEBAN 2025'!$B$13))) -> 196536.53 | AK5: =AG5*AI5+AH5*AJ5 -> 504832.65
A6: APARTADO | B6: =VLOOKUP(A6,'CENTRO DE COSTOS'!A:D,4,FALSE) -> JUAN SEBASTIÁN RÍOS CASTRILLÓN | C6: =VLOOKUP(A6,'CENTRO DE COSTOS'!A:D,2,FALSE) -> 0004-0005 | D6: 27135 | E6: TA-25-554336 | F6: FO-25-842394 | G6: 45805 | H6: 45807 | I6: 45805 | J6: 45814 | K6: 45814 | L6: CHOCO | M6: EL CANTON DEL SAN PABLO | N6: BARRIO AVENIDA 20 DE JULIO CARTON DEL SAN PABLO CHOCO EL CANTON DEL SAN PABLO | O6: 79580 | P6: CB CRECIMIENTO - NUEVO | Q6: APERTURA | R6: REDEBAN | S6: UNO A UNO | T6: UNO A UNO | U6: EJECUTADO | V6: 28-05-2025 SE REALIZA LLAMADA AL CLIENTE, SE HABLA CON LA SRA DORIS MARIA PALACIOS CORDOBA SE VALIDA DIRECCIÓN OK, CANAL OK, DISPONIBILIDAD TOTAL, LLAMAR EL DÍA LA INSTALACIÓN PARA CONFIRMAR VISITA, AVISO EXTERIOR ALTURA APROX 3 - 4 METROS; TOMACORRIENTE CERCANO: SI; TIENE CABINA DE SEGURIDAD: NO // CONTACTO REALIZADO POR LA APP 06-06 SE REALIZA INSTALACIÓN DE CORRESPONSAL, SE INSTALAN EQUIPOS CON PRUEBAS EXITOSAS, SE CAPACITA Y SE EVALÚA AL CLIENTE, SE INSTALA PUBLICIDAD COMPLETA, CB QUEDA OPERATIVO. USUARIO SOMOS BANCOLOMBIA ACTIVO | W6: ROBLEDO DIAZ ANDRES FELIPE | X6: LMVZZ014 | Y6: 792636 | Z6: N/A | AA6: 905838 | AB6: N/A | AC6: 40 ROLLOS | AD6: TIPO IV | AE6: TERRESTRE | AF6: VISITA_TÉCNICA | AG6: 1 | AH6: 0 | AI6: =IF(AD6="TIPO I",'BASE LIQUIDACION REDEBAN 2025'!$B$2,IF(AD6="TIPO II",'BASE LIQUIDACION REDEBAN 2025'!$B$3,IF(AD6="TIPO III",'BASE LIQUIDACION REDEBAN 2025'!$B$4,IF(AD6="TIPO IV",'BASE LIQUIDACION REDEBAN 2025'!$B$5,IF(AE6="AEREO",'BASE LIQUIDACION REDEBAN 2025'!$B$6,'BASE LIQUIDACION REDEBAN 2025'!$B$5))))) -> 504832.65 | AJ6: =IF(AD6="TIPO I",'BASE LIQUIDACION REDEBAN 2025'!$B$10,IF(AD6="TIPO II",'BASE LIQUIDACION REDEBAN 2025'!$B$11,IF(AD6="TIPO III",'BASE LIQUIDACION REDEBAN 2025'!$B$12,'BASE LIQUIDACION REDEBAN 2025'!$B$13))) -> 196536.53 | AK6: =AG6*AI6+AH6*AJ6 -> 504832.65
A7: PASTO | B7: =VLOOKUP(A7,'CENTRO DE COSTOS'!A:D,4,FALSE) -> DIEGO FERNANDO HENAO CARDONA | C7: =VLOOKUP(A7,'CENTRO DE COSTOS'!A:D,2,FALSE) -> 0004-0003 | D7: 52320 | E7: TA-25-561190 | F7: FO-25-854599 | G7: 45805 | H7: 45807 | I7: 45805 | J7: 45811 | K7: 45811 | L7: NARIÑO | M7: GUAITARILLA | N7: BARRIO CENTRO GUAITARILLA | O7: 79558 | P7: CB CRECIMIENTO - NUEVO | Q7: APERTURA | R7: REDEBAN | S7: UNO A UNO | T7: UNO A UNO | U7: EJECUTADO | V7: 28-05 SE REALIZA LLAMADA AL CLIENTE, SE HABLA CON EL SR JOSE ARMANDO ROSERO MARTINEZ, SE VALIDA DIRECCIÓN OK, CANAL OK, DISPONIBILIDAD TOTAL, LLAMAR EL DÍA LA INSTALACIÓN PARA CONFIRMAR VISITA, AVISO EXTERIOR ALTURA APROX 2 METROS; TOMACORRIENTE CERCANO: SI; TIENE CABINA DE SEGURIDAD:SI //MODEN SE ENCUENTRA A 5 MEGTROS DE DISTANCIA DE DONDE VA SER INSTALADO EL DATAFONO 30-05 NO SE PUEDE NO SE LOGRA TRANSPORTE PARA EL MUNICIPIO DE GUAITARILLA DEBIDO A QUE ZONA NO HAY TRANSPORTE DISPONIBLE. SE VISITARÁ EL DÍA MARTES 03/06/2025 3/6/2025 SE REALIZA INSTALACIÓN DE CORRESPONSAL, SE INSTALAN EQUIPOS CON PRUEBAS EXITOSAS, SE CAPACITA Y SE EVALÚA AL CLIENTE, SE INSTALA PUBLICIDAD COMPLETA, CB QUEDA OPERATIVO. USUARIO SOMOS BANCOLOMBIA ACTIVO | W7: BOLAÑOS TABORDA JORGE ENRIQUE | X7: LMUZZ992 | Y7: 1115746 | Z7: N/A | AA7: 892665 | AB7: N/A | AC7: 40 ROLLOS | AD7: TIPO II | AE7: TERRESTRE | AF7: VISITA_TÉCNICA | AG7: 1 | AH7: 0 | AI7: =IF(AD7="TIPO I",'BASE LIQUIDACION REDEBAN 2025'!$B$2,IF(AD7="TIPO II",'BASE LIQUIDACION REDEBAN 2025'!$B$3,IF(AD7="TIPO III",'BASE LIQUIDACION REDEBAN 2025'!$B$4,IF(AD7="TIPO IV",'BASE LIQUIDACION REDEBAN 2025'!$B$5,IF(AE7="AEREO",'BASE LIQUIDACION REDEBAN 2025'!$B$6,'BASE LIQUIDACION REDEBAN 2025'!$B$5))))) -> 163813.7 | AJ7: =IF(AD7="TIPO I",'BASE LIQUIDACION REDEBAN 2025'!$B$10,IF(AD7="TIPO II",'BASE LIQUIDACION REDEBAN 2025'!$B$11,IF(AD7="TIPO III",'BASE LIQUIDACION REDEBAN 2025'!$B$12,'BASE LIQUIDACION REDEBAN 2025'!$B$13))) -> 140395.63 | AK7: =AG7*AI7+AH7*AJ7 -> 163813.7
A8: MEDELLIN | B8: =VLOOKUP(A8,'CENTRO DE COSTOS'!A:D,4,FALSE) -> JUAN SEBASTIÁN RÍOS CASTRILLÓN | C8: =VLOOKUP(A8,'CENTRO DE COSTOS'!A:D,2,FALSE) -> 0004-0005 | D8: 27361 | E8: TA-25-561193 | F8: FO-25-854607 | G8: 45805 | H8: 45817 | I8: 45805 | J8: 45812 | K8: 45812 | L8: CHOCO | M8: ISTMINA | N8: BARRIO CUBIS SEC MESETA ALTA ISTMINA CHOCO ISTMINA | O8: 79563 | P8: CB CRECIMIENTO - NUEVO | Q8: APERTURA | R8: REDEBAN | S8: UNO A UNO | T8: UNO A UNO | U8: EJECUTADO | V8: 28-05 SE REALIZA LLAMADA AL CLIENTE, SE HABLA CON LA SRA JOAN AVENDAÑO DAZA SE VALIDA DIRECCIÓN OK, CANAL OK, DISPONIBILIDAD TOTAL, LLAMAR EL DÍA LA INSTALACIÓN PARA CONFIRMAR VISITA, AVISO EXTERIOR ALTURA APROX 2 METROS; TOMACORRIENTE CERCANO: SI; TIENE CABINA DE SEGURIDAD: SI 04-06 SE REALIZA INSTALACIÓN DE CORRESPONSAL, SE INSTALAN EQUIPOS CON PRUEBAS EXITOSAS, SE CAPACITA Y SE EVALÚA AL CLIENTE, SE INSTALA PUBLICIDAD COMPLETA, CB QUEDA OPERATIVO. USUARIO SOMOS BANCOLOMBIA ACTIVO. SE INSTALAN 10 MT DE CABLE UTP | W8: ROBLEDO DIAZ ANDRES FELIPE | X8: LMUZZ997 | Y8: 771855 | Z8: N/A | AA8: 1146028 | AB8: N/A | AC8: 40 ROLLOS | AD8: TIPO IV ESPECIAL | AE8: AEREO | AF8: VISITA_TÉCNICA | AG8: 1 | AH8: 0 | AI8: =IF(AD8="TIPO I",'BASE LIQUIDACION REDEBAN 2025'!$B$2,IF(AD8="TIPO II",'BASE LIQUIDACION REDEBAN 2025'!$B$3,IF(AD8="TIPO III",'BASE LIQUIDACION REDEBAN 2025'!$B$4,IF(AD8="TIPO IV",'BASE LIQUIDACION REDEBAN 2025'!$B$5,IF(AE8="AEREO",'BASE LIQUIDACION REDEBAN 2025'!$B$6,'BASE LIQUIDACION REDEBAN 2025'!$B$5))))) -> 988462.96 | AJ8: =IF(AD8="TIPO I",'BASE LIQUIDACION REDEBAN 2025'!$B$10,IF(AD8="TIPO II",'BASE LIQUIDACION REDEBAN 2025'!$B$11,IF(AD8="TIPO III",'BASE LIQUIDACION REDEBAN 2025'!$B$12,'BASE LIQUIDACION REDEBAN 2025'!$B$13))) -> 196536.53 | AK8: =AG8*AI8+AH8*AJ8 -> 988462.96
A9: CALI | B9: =VLOOKUP(A9,'CENTRO DE COSTOS'!A:D,4,FALSE) -> DIEGO FERNANDO HENAO CARDONA | C9: =VLOOKUP(A9,'CENTRO DE COSTOS'!A:D,2,FALSE) -> 0004-0003 | D9: 76109 | E9: TA-25-561196 | F9: FO-25-854618 | G9: 45805 | H9: 45807 | I9: 45805 | J9: 45812 | K9: 45812 | L9: VALLE DEL CAUCA | M9: BUENAVENTURA | N9: BARRIO PUNTA DEL ESTE BUENAVENTURA | O9: 79355 | P9: CB CRECIMIENTO - OTRAS LISTAS | Q9: APERTURA | R9: REDEBAN | S9: UNO A UNO | T9: UNO A UNO | U9: EJECUTADO | V9: 28-05 SE REALIZA LLAMADA AL CLIENTE, SE HABLA CON LA SR JESSICA PAOLA VALENCIA BECERRA SE VALIDA DIRECCIÓN OK, CANAL OK, DISPONIBILIDAD TOTAL, LLAMAR EL DÍA LA INSTALACIÓN PARA CONFIRMAR VISITA, AVISO EXTERIOR ALTURA: NO INDICA ALTURA; TOMACORRIENTE CERCANO: SI; TIENE CABINA DE SEGURIDAD: NO 30-05 DEBIDO A PROBLEMAS EN LA VIA CALI - BUENAVENTURA POR CIERRES Y PROTESTAS NO SE CONSIGUE TRANSPORTE PARA EL PUERTO NO ESTAN SALIENDO LOS BUSES DESDE LA TERMINAL, SE DEBE REALIZAR DESPLAZAMIENTO EL PROXIMO MARTES VALIDANDO ESTADO DEL TRANSPORTE. 4/6/2025 SE REALIZA INSTALACIÓN DE CORRESPONSAL, SE INSTALAN EQUIPOS CON PRUEBAS EXITOSAS, SE CAPACITA Y SE EVALÚA AL CLIENTE, SE INSTALA PUBLICIDAD COMPLETA, CB QUEDA OPERATIVO. USUARIO SOMOS BANCOLOMBIA ACTIVO | W9: PAREDES CASTILLO DIEGO | X9: 10XZZ893 | Y9: 1072780 | Z9: N/A | AA9: 528290 | AB9: N/A | AC9: 40 ROLLOS | AD9: TIPO III | AE9: TERRESTRE | AF9: VISITA_TÉCNICA | AG9: 1 | AH9: 0 | AI9: =IF(AD9="TIPO I",'BASE LIQUIDACION REDEBAN 2025'!$B$2,IF(AD9="TIPO II",'BASE LIQUIDACION REDEBAN 2025'!$B$3,IF(AD9="TIPO III",'BASE LIQUIDACION REDEBAN 2025'!$B$4,IF(AD9="TIPO IV",'BASE LIQUIDACION REDEBAN 2025'!$B$5,IF(AE9="AEREO",'BASE LIQUIDACION REDEBAN 2025'!$B$6,'BASE LIQUIDACION REDEBAN 2025'!$B$5))))) -> 275728.78 | AJ9: =IF(AD9="TIPO I",'BASE LIQUIDACION REDEBAN 2025'!$B$10,IF(AD9="TIPO II",'BASE LIQUIDACION REDEBAN 2025'!$B$11,IF(AD9="TIPO III",'BASE LIQUIDACION REDEBAN 2025'!$B$12,'BASE LIQUIDACION REDEBAN 2025'!$B$13))) -> 196536.53 | AK9: =AG9*AI9+AH9*AJ9 -> 275728.78
A10: CALI | B10: =VLOOKUP(A10,'CENTRO DE COSTOS'!A:D,4,FALSE) -> DIEGO FERNANDO HENAO CARDONA | C10: =VLOOKUP(A10,'CENTRO DE COSTOS'!A:D,2,FALSE) -> 0004-0003 | D10: 76001 | E10: TA-25-561199 | F10: FO-25-854624 | G10: 45805 | H10: 45807 | I10: 45805 | J10: 45811 | K10: 45811 | L10: VALLE DEL CAUCA | M10: CALI | N10: BARRIO VILLA DEL LAGO CALI 2 | O10: 79361 | P10: CB CRECIMIENTO - OTRAS LISTAS | Q10: APERTURA | R10: REDEBAN | S10: UNO A UNO | T10: UNO A UNO | U10: EJECUTADO | V10: 28-05 SE REALIZA LLAMADA AL CLIENTE, SE HABLA CON LA SRA DEISY (HIJA) SE VALIDA DIRECCIÓN OK, CANAL OK, DISPONIBILIDAD TOTAL, LLAMAR EL DÍA LA INSTALACIÓN PARA CONFIRMAR VISITA, AVISO EXTERIOR ALTURA: NO INDICA ALTURA; TOMACORRIENTE CERCANO: SI; TIENE CABINA DE SEGURIDAD: NO - COMUNICACIÓN POR WPP 30/5/2025 SE LLEGA AL PUNTO DESPUES DE LAS 4 PM YA QUE SE TUVO INCONVENIENTE CON VARIOS CAMBIOS DE EQUIPOS EN LA PRIMERA APERTURA, SE CONFIGURAN EQUIPOS PERO AL MOMENTO DE INICIALIZAR SE ENCUENTRA QUE LA TERMINAL NO ESTA EN BASE 24 , YA NO SE CUENTA CON SOPORTE DE REDEBAN, POR LO CUAL NO SE PUEDE LLEVAR A CABO LA APERTURA 3/6/2025 SE REALIZA INSTALACIÓN DE CORRESPONSAL, SE INSTALAN EQUIPOS CON PRUEBAS EXITOSAS, SE CAPACITA Y SE EVALÚA AL CLIENTE, SE INSTALA PUBLICIDAD COMPLETA, CB QUEDA OPERATIVO. USUARIO SOMOS BANCOLOMBIA ACTIVO | W10: HERRERA MONAR GEOVANNY | X10: 10XZZ899 | Y10: 1219158 | Z10: 1006564 | AA10: 789713 | AB10: N/A | AC10: 40 ROLLOS | AD10: TIPO I | AE10: TERRESTRE | AF10: VISITA_TÉCNICA | AG10: 1 | AH10: 0 | AI10: =IF(AD10="TIPO I",'BASE LIQUIDACION REDEBAN 2025'!$B$2,IF(AD10="TIPO II",'BASE LIQUIDACION REDEBAN 2025'!$B$3,IF(AD10="TIPO III",'BASE LIQUIDACION REDEBAN 2025'!$B$4,IF(AD10="TIPO IV",'BASE LIQUIDACION REDEBAN 2025'!$B$5,IF(AE10="AEREO",'BASE LIQUIDACION REDEBAN 2025'!$B$6,'BASE LIQUIDACION REDEBAN 2025'!$B$5))))) -> 75096.394 | AJ10: =IF(AD10="TIPO I",'BASE LIQUIDACION REDEBAN 2025'!$B$10,IF(AD10="TIPO II",'BASE LIQUIDACION REDEBAN 2025'!$B$11,IF(AD10="TIPO III",'BASE LIQUIDACION REDEBAN 2025'!$B$12,'BASE LIQUIDACION REDEBAN 2025'!$B$13))) -> 75096.394 | AK10: =AG10*AI10+AH10*AJ10 -> 75096.394
A11: VILLAVICENCIO | B11: =VLOOKUP(A11,'CENTRO DE COSTOS'!A:D,4,FALSE) -> KEVIN ALEXIS CORZO BUSTOS | C11: =VLOOKUP(A11,'CENTRO DE COSTOS'!A:D,2,FALSE) -> 0004-0007 | D11: 50001 | E11: TA-25-561200 | F11: FO-25-854628 | G11: 45807 | H11: 45812 | I11: 45807 | J11: 45812 | K11: 45812 | L11: META | M11: VILLAVICENCIO | N11: BARRIOI CATUMARE VILLAVICENCIO | O11: 79665 | P11: CB CRECIMIENTO - NUEVO | Q11: APERTURA | R11: REDEBAN | S11: UNO A UNO | T11: UNO A UNO | U11: EJECUTADO | V11: 30-05-2025 SE REALIZA LLAMADA AL CLIENTE, SE HABLA CON LA SRA ERIKA FERNANDA MARRERO INFANTE SE VALIDA DIRECCIÓN OK, CANAL OK, DISPONIBILIDAD TOTAL, LLAMAR EL DÍA LA INSTALACIÓN PARA CONFIRMAR VISITA, AVISO EXTERIOR ALTURA: CLIENTE NO TIENE CONOCIMIENTO DE MEDIDAS; TOMACORRIENTE CERCANO: SI; TIENE CABINA DE SEGURIDAD: NO // CONTACTO REALIZADO POR LA APP 4/6/2025 SE REALIZA INSTALACIÓN DE CORRESPONSAL, SE INSTALAN EQUIPOS CON PRUEBAS EXITOSAS, SE CAPACITA Y SE EVALÚA AL CLIENTE, SE INSTALA PUBLICIDAD COMPLETA, CB QUEDA OPERATIVO. USUARIO SOMOS BANCOLOMBIA ACTIVO | W11: PEDREROS CONTRERAS MICHAEL STEVENS | X11: SXUZZ191 | Y11: 1040805 | Z11: 1138829 | AA11: 523819 | AB11: N/A | AC11: 40 ROLLOS | AD11: TIPO I | AE11: TERRESTRE | AF11: VISITA_TÉCNICA | AG11: 1 | AH11: 0 | AI11: =IF(AD11="TIPO I",'BASE LIQUIDACION REDEBAN 2025'!$B$2,IF(AD11="TIPO II",'BASE LIQUIDACION REDEBAN 2025'!$B$3,IF(AD11="TIPO III",'BASE LIQUIDACION REDEBAN 2025'!$B$4,IF(AD11="TIPO IV",'BASE LIQUIDACION REDEBAN 2025'!$B$5,IF(AE11="AEREO",'BASE LIQUIDACION REDEBAN 2025'!$B$6,'BASE LIQUIDACION REDEBAN 2025'!$B$5))))) -> 75096.394 | AJ11: =IF(AD11="TIPO I",'BASE LIQUIDACION REDEBAN 2025'!$B$10,IF(AD11="TIPO II",'BASE LIQUIDACION REDEBAN 2025'!$B$11,IF(AD11="TIPO III",'BASE LIQUIDACION REDEBAN 2025'!$B$12,'BASE LIQUIDACION REDEBAN 2025'!$B$13))) -> 75096.394 | AK11: =AG11*AI11+AH11*AJ11 -> 75096.394
A12: VILLAVICENCIO | B12: =VLOOKUP(A12,'CENTRO DE COSTOS'!A:D,4,FALSE) -> KEVIN ALEXIS CORZO BUSTOS | C12: =VLOOKUP(A12,'CENTRO DE COSTOS'!A:D,2,FALSE) -> 0004-0007 | D12: 50313 | E12: TA-25-561203 | F12: FO-25-854632 | G12: 45807 | H12: 45812 | I12: 45807 | J12: 45811 | K12: 45811 | L12: META | M12: GRANADA | N12: BARRIO RICAUTE GRANADA 2 | O12: 79637 | P12: CB CRECIMIENTO - NUEVO | Q12: APERTURA | R12: REDEBAN | S12: UNO A UNO | T12: UNO A UNO | U12: EJECUTADO | V12: 30-05-2025 SE REALIZA LLAMADA AL CLIENTE, SE HABLA CON LA SRA LEIDY VIVIANA PENAGOS ALARCON SE VALIDA DIRECCIÓN OK, CANAL OK, DISPONIBILIDAD TOTAL, LLAMAR EL DÍA LA INSTALACIÓN PARA CONFIRMAR VISITA, AVISO EXTERIOR ALTURA: CLIENTE NO TIENE CONOCIMIENTO DE MEDIDAS; TOMACORRIENTE CERCANO: SI; TIENE CABINA DE SEGURIDAD: NO // CONTACTO REALIZADO POR LA APP 3/6/2025 SE REALIZA VISITA PARA IMPLEMENTACIÓN, PERO SE EVIDENCIA QUE EL BARRIO NO COINCIDE CON EL RELACIONADO EN LISTA DE CHEQUEO, LA DIRECCIÓN CL 19 NRO 12 - 41 ESTÁ BIEN, PERO EL BARRIO ES CENTRO Y NO RICAUTE. POR FAVOR NOS INDICA COMO PROCEDER. 3/6/2025 SE REALIZA INSTALACIÓN DE CORRESPONSAL, SE INSTALAN EQUIPOS CON PRUEBAS EXITOSAS, SE CAPACITA Y SE EVALÚA AL CLIENTE, SE INSTALA PUBLICIDAD COMPLETA, CB QUEDA OPERATIVO. USUARIO SOMOS BANCOLOMBIA ACTIVO | W12: PEDREROS CONTRERAS MICHAEL STEVENS | X12: SXUZZ163 | Y12: 981893 | Z12: N/A | AA12: 514973 | AB12: N/A | AC12: 40 ROLLOS | AD12: TIPO II | AE12: TERRESTRE | AF12: VISITA_TÉCNICA | AG12: 1 | AH12: 0 | AI12: =IF(AD12="TIPO I",'BASE LIQUIDACION REDEBAN 2025'!$B$2,IF(AD12="TIPO II",'BASE LIQUIDACION REDEBAN 2025'!$B$3,IF(AD12="TIPO III",'BASE LIQUIDACION REDEBAN 2025'!$B$4,IF(AD12="TIPO IV",'BASE LIQUIDACION REDEBAN 2025'!$B$5,IF(AE12="AEREO",'BASE LIQUIDACION REDEBAN 2025'!$B$6,'BASE LIQUIDACION REDEBAN 2025'!$B$5))))) -> 163813.7 | AJ12: =IF(AD12="TIPO I",'BASE LIQUIDACION REDEBAN 2025'!$B$10,IF(AD12="TIPO II",'BASE LIQUIDACION REDEBAN 2025'!$B$11,IF(AD12="TIPO III",'BASE LIQUIDACION REDEBAN 2025'!$B$12,'BASE LIQUIDACION REDEBAN 2025'!$B$13))) -> 140395.63 | AK12: =AG12*AI12+AH12*AJ12 -> 163813.7
A13: NEIVA | B13: =VLOOKUP(A13,'CENTRO DE COSTOS'!A:D,4,FALSE) -> KEVIN ALEXIS CORZO BUSTOS | C13: =VLOOKUP(A13,'CENTRO DE COSTOS'!A:D,2,FALSE) -> 0004-0007 | D13: 41001 | E13: TA-25-561204 | F13: FO-25-854635 | G13: 45807 | H13: 45812 | I13: 45807 | J13: 45811 | K13: 45811 | L13: HUILA | M13: NEIVA | N13: BARRIO PRADOS DEL SAUCE NEIVA 1 | O13: 79645 | P13: CB CRECIMIENTO - NUEVO | Q13: APERTURA | R13: REDEBAN | S13: UNO A UNO | T13: UNO A UNO | U13: EJECUTADO | V13: 30-05-2025 SE REALIZA LLAMADA AL CLIENTE, SE HABLA CON EL SR JOSE ANDRES PERDOMO PERDOMO SE VALIDA DIRECCIÓN OK, CANAL OK, DISPONIBILIDAD TOTAL, LLAMAR EL DÍA LA INSTALACIÓN PARA CONFIRMAR VISITA, AVISO EXTERIOR ALTURA APROX 1,70 A 2 METROS; TOMACORRIENTE CERCANO: SI; TIENE CABINA DE SEGURIDAD: SI // CONTACTO REALIZADO POR LA APP 03-06 SE REALIZA INSTALACIÓN DE CORRESPONSAL, SE INSTALAN EQUIPOS CON PRUEBAS EXITOSAS, SE CAPACITA Y SE EVALÚA AL CLIENTE, SE INSTALA PUBLICIDAD COMPLETA, CB QUEDA OPERATIVO. USUARIO SOMOS BANCOLOMBIA ACTIVO | W13: DIAZ VARGAS JONATHAN MIGUEL | X13: SXUZZ171 | Y13: 792659 | Z13: N/A | AA13: 892883 | AB13: N/A | AC13: 40 ROLLOS | AD13: TIPO I | AE13: TERRESTRE | AF13: VISITA_TÉCNICA | AG13: 1 | AH13: 0 | AI13: =IF(AD13="TIPO I",'BASE LIQUIDACION REDEBAN 2025'!$B$2,IF(AD13="TIPO II",'BASE LIQUIDACION REDEBAN 2025'!$B$3,IF(AD13="TIPO III",'BASE LIQUIDACION REDEBAN 2025'!$B$4,IF(AD13="TIPO IV",'BASE LIQUIDACION REDEBAN 2025'!$B$5,IF(AE13="AEREO",'BASE LIQUIDACION REDEBAN 2025'!$B$6,'BASE LIQUIDACION REDEBAN 2025'!$B$5))))) -> 75096.394 | AJ13: =IF(AD13="TIPO I",'BASE LIQUIDACION REDEBAN 2025'!$B$10,IF(AD13="TIPO II",'BASE LIQUIDACION REDEBAN 2025'!$B$11,IF(AD13="TIPO III",'BASE LIQUIDACION REDEBAN 2025'!$B$12,'BASE LIQUIDACION REDEBAN 2025'!$B$13))) -> 75096.394 | AK13: =AG13*AI13+AH13*AJ13 -> 75096.394
A14: VILLAVICENCIO | B14: =VLOOKUP(A14,'CENTRO DE COSTOS'!A:D,4,FALSE) -> KEVIN ALEXIS CORZO BUSTOS | C14: =VLOOKUP(A14,'CENTRO DE COSTOS'!A:D,2,FALSE) -> 0004-0007 | D14: 50001 | E14: TA-25-561205 | F14: FO-25-854639 | G14: 45807 | H14: 45812 | I14: 45807 | J14: 45812 | K14: 45812 | L14: META | M14: VILLAVICENCIO | N14: BARRIO LA MADRID ETAPA 4 VILLAVICENCIO | O14: 79666 | P14: CB CRECIMIENTO - NUEVO | Q14: APERTURA | R14: REDEBAN | S14: UNO A UNO | T14: UNO A UNO | U14: EJECUTADO | V14: 30-05-2025 SE REALIZA LLAMADA AL CLIENTE, SE HABLA CON LA SRA CAROL JULIETH ARIZA FONTECHA SE VALIDA DIRECCIÓN OK, CANAL OK, DISPONIBILIDAD TOTAL, LLAMAR EL DÍA LA INSTALACIÓN PARA CONFIRMAR VISITA, AVISO EXTERIOR ALTURA: CLIENTE NO TIENE CONOCIMIENTO DE MEDIDAS; TOMACORRIENTE CERCANO: SI; TIENE CABINA DE SEGURIDAD: NO // CONTACTO REALIZADO POR LA APP 4/6/2025 SE REALIZA INSTALACIÓN DE CORRESPONSAL, SE INSTALAN EQUIPOS CON PRUEBAS EXITOSAS, SE CAPACITA Y SE EVALÚA AL CLIENTE, SE INSTALA PUBLICIDAD COMPLETA, CB QUEDA OPERATIVO. USUARIO SOMOS BANCOLOMBIA ACTIVO | W14: ROZO JIMENEZ EDGAR ARMANDO | X14: SXUZZ192 | Y14: 1169258 | Z14: N/A | AA14: 903879 | AB14: N/A | AC14: 40 ROLLOS | AD14: TIPO I | AE14: TERRESTRE | AF14: VISITA_TÉCNICA | AG14: 1 | AH14: 0 | AI14: =IF(AD14="TIPO I",'BASE LIQUIDACION REDEBAN 2025'!$B$2,IF(AD14="TIPO II",'BASE LIQUIDACION REDEBAN 2025'!$B$3,IF(AD14="TIPO III",'BASE LIQUIDACION REDEBAN 2025'!$B$4,IF(AD14="TIPO IV",'BASE LIQUIDACION REDEBAN 2025'!$B$5,IF(AE14="AEREO",'BASE LIQUIDACION REDEBAN 2025'!$B$6,'BASE LIQUIDACION REDEBAN 2025'!$B$5))))) -> 75096.394 | AJ14: =IF(AD14="TIPO I",'BASE LIQUIDACION REDEBAN 2025'!$B$10,IF(AD14="TIPO II",'BASE LIQUIDACION REDEBAN 2025'!$B$11,IF(AD14="TIPO III",'BASE LIQUIDACION REDEBAN 2025'!$B$12,'BASE LIQUIDACION REDEBAN 2025'!$B$13))) -> 75096.394 | AK14: =AG14*AI14+AH14*AJ14 -> 75096.394
A15: VALLEDUPAR | B15: =VLOOKUP(A15,'CENTRO DE COSTOS'!A:D,4,FALSE) -> JOSE MAURICIO HERNANDEZ ROJAS | C15: =VLOOKUP(A15,'CENTRO DE COSTOS'!A:D,2,FALSE) -> 0004-0001 | D15: 20238 | E15: TA-25-561209 | F15: FO-25-854645 | G15: 45807 | H15: 45812 | I15: 45807 | J15: 45814 | K15: 45814 | L15: CESAR | M15: EL COPEY | N15: BARRIO EL BOSQUE EL COPEY 1 | O15: 79633 | P15: CB CRECIMIENTO - NUEVO | Q15: APERTURA | R15: REDEBAN | S15: UNO A UNO | T15: UNO A UNO | U15: EJECUTADO | V15: 30-05-2025 SE REALIZA LLAMADA AL CLIENTE, SE HABLA CON LA SRA EDWIN CHINCHILLA MANOSALVA SE VALIDA DIRECCIÓN OK, CANAL OK, DISPONIBILIDAD TOTAL, LLAMAR EL DÍA LA INSTALACIÓN PARA CONFIRMAR VISITA, AVISO EXTERIOR ALTURA: 2,50 METROS; TOMACORRIENTE CERCANO: A 4 METROS ; TIENE CABINA DE SEGURIDAD: NO // CONTACTO REALIZADO POR WHATSAPP 03-06 NO SE PUEDE ACCEDER A LA APERTURA E INSTALACIÓN DE EQUIPOS EN COPEY YA QUE HAY PROTESTA Y PARO EN LA VIA SANTA MARTA Y BOSCONIA POR PARTE DE COMUNIDADES DE LA SIERRA DESDE EL DÍA DE AYER, INFORMAN FUENTES QUE EL PARO VA A SEGUIR HASTA EL RESTO DEL DÍA DE HOY 5/6/2025 SE REALIZA VALIDACIÓN NUEVAMENTE Y LA NOVEDAD CONTINUA6/6/2025 SE REALIZA INSTALACIÓN DE CORRESPONSAL, SE INSTALAN EQUIPOS CON PRUEBAS EXITOSAS, SE CAPACITA Y SE EVALÚA AL CLIENTE, SE INSTALA PUBLICIDAD COMPLETA, CB QUEDA OPERATIVO. USUARIO SOMOS BANCOLOMBIA ACTIVO | W15: MAESTRE MENGUAL EDGAR ENRIQUE | X15: SXUZZ159 | Y15: 929689 | Z15: N/A | AA15: 531715 | AB15: N/A | AC15: 40 ROLLOS | AD15: TIPO II | AE15: TERRESTRE | AF15: VISITA_TÉCNICA | AG15: 1 | AH15: 0 | AI15: =IF(AD15="TIPO I",'BASE LIQUIDACION REDEBAN 2025'!$B$2,IF(AD15="TIPO II",'BASE LIQUIDACION REDEBAN 2025'!$B$3,IF(AD15="TIPO III",'BASE LIQUIDACION REDEBAN 2025'!$B$4,IF(AD15="TIPO IV",'BASE LIQUIDACION REDEBAN 2025'!$B$5,IF(AE15="AEREO",'BASE LIQUIDACION REDEBAN 2025'!$B$6,'BASE LIQUIDACION REDEBAN 2025'!$B$5))))) -> 163813.7 | AJ15: =IF(AD15="TIPO I",'BASE LIQUIDACION REDEBAN 2025'!$B$10,IF(AD15="TIPO II",'BASE LIQUIDACION REDEBAN 2025'!$B$11,IF(AD15="TIPO III",'BASE LIQUIDACION REDEBAN 2025'!$B$12,'BASE LIQUIDACION REDEBAN 2025'!$B$13))) -> 140395.63 | AK15: =AG15*AI15+AH15*AJ15 -> 163813.7
A16: BARRANQUILLA | B16: =VLOOKUP(A16,'CENTRO DE COSTOS'!A:D,4,FALSE) -> JOSE MAURICIO HERNANDEZ ROJAS | C16: =VLOOKUP(A16,'CENTRO DE COSTOS'!A:D,2,FALSE) -> 0004-0001 | D16: 8001 | E16: TA-25-561210 | F16: FO-25-854649 | G16: 45807 | H16: 45812 | I16: 45807 | J16: 45811 | K16: 45811 | L16: ATLANTICO | M16: BARRANQUILLA | N16: BARRIO LA MAGDALENA BARRANQUILLA 4 | O16: 79598 | P16: CB CRECIMIENTO - NUEVO | Q16: APERTURA | R16: REDEBAN | S16: UNO A UNO | T16: UNO A UNO | U16: EJECUTADO | V16: 30-05-2025 SE REALIZA LLAMADA AL CLIENTE, SE HABLA CON LA SRA LIGIA MUÑOS SILVA SE VALIDA DIRECCIÓN OK, CANAL OK, DISPONIBILIDAD TOTAL, LLAMAR EL DÍA LA INSTALACIÓN PARA CONFIRMAR VISITA, AVISO EXTERIOR ALTURA: 2,10 METROS; TOMACORRIENTE CERCANO: SI; TIENE CABINA DE SEGURIDAD: SI // CONTACTO REALIZADO POR LA APP 3/6/2025 SE REALIZA INSTALACIÓN DE CORRESPONSAL, SE INSTALAN EQUIPOS CON PRUEBAS EXITOSAS, SE CAPACITA Y SE EVALÚA AL CLIENTE, SE INSTALA PUBLICIDAD COMPLETA, CB QUEDA OPERATIVO. USUARIO SOMOS BANCOLOMBIA ACTIVO | W16: DE AVILA SIADES ALBERTO ENRIQUE | X16: SXUZZ124 | Y16: 1115570 | Z16: N/A | AA16: 905668 | AB16: N/A | AC16: 40 ROLLOS | AD16: TIPO I | AE16: TERRESTRE | AF16: VISITA_TÉCNICA | AG16: 1 | AH16: 0 | AI16: =IF(AD16="TIPO I",'BASE LIQUIDACION REDEBAN 2025'!$B$2,IF(AD16="TIPO II",'BASE LIQUIDACION REDEBAN 2025'!$B$3,IF(AD16="TIPO III",'BASE LIQUIDACION REDEBAN 2025'!$B$4,IF(AD16="TIPO IV",'BASE LIQUIDACION REDEBAN 2025'!$B$5,IF(AE16="AEREO",'BASE LIQUIDACION REDEBAN 2025'!$B$6,'BASE LIQUIDACION REDEBAN 2025'!$B$5))))) -> 75096.394 | AJ16: =IF(AD16="TIPO I",'BASE LIQUIDACION REDEBAN 2025'!$B$10,IF(AD16="TIPO II",'BASE LIQUIDACION REDEBAN 2025'!$B$11,IF(AD16="TIPO III",'BASE LIQUIDACION REDEBAN 2025'!$B$12,'BASE LIQUIDACION REDEBAN 2025'!$B$13))) -> 75096.394 | AK16: =AG16*AI16+AH16*AJ16 -> 75096.394
A17: CALI | B17: =VLOOKUP(A17,'CENTRO DE COSTOS'!A:D,4,FALSE) -> DIEGO FERNANDO HENAO CARDONA | C17: =VLOOKUP(A17,'CENTRO DE COSTOS'!A:D,2,FALSE) -> 0004-0003 | D17: 76126 | E17: TA-25-561211 | F17: FO-25-854657 | G17: 45807 | H17: 45812 | I17: 45807 | J17: 45812 | K17: 45812 | L17: VALLE DEL CAUCA | M17: CALIMA | N17: BARRIO OBRERO CALIMA | O17: 79619 | P17: CB CRECIMIENTO - NUEVO | Q17: APERTURA | R17: REDEBAN | S17: UNO A UNO | T17: UNO A UNO | U17: EJECUTADO | V17: 30-05-2025 SE REALIZA LLAMADA AL CLIENTE, SE HABLA CON LA SRA SHARIN LOPEZ ARANA SE VALIDA DIRECCIÓN OK, CANAL OK, DISPONIBILIDAD TOTAL, LLAMAR EL DÍA LA INSTALACIÓN PARA CONFIRMAR VISITA, AVISO EXTERIOR ALTURA: 2 - 2,50 METROS; TOMACORRIENTE CERCANO: SI; TIENE CABINA DE SEGURIDAD: NO // CONTACTO REALIZADO POR LA APP 4/6/2025 SE REALIZA INSTALACIÓN DE CORRESPONSAL, SE INSTALAN EQUIPOS CON PRUEBAS EXITOSAS, SE CAPACITA Y SE EVALÚA AL CLIENTE, SE INSTALA PUBLICIDAD COMPLETA, CB QUEDA OPERATIVO. USUARIO SOMOS BANCOLOMBIA ACTIVO | W17: HERRERA MONAR GEOVANNY | X17: SXUZZ145 | Y17: 793073 | Z17: N/A | AA17: 750456 | AB17: N/A | AC17: 40 ROLLOS | AD17: TIPO II | AE17: TERRESTRE | AF17: VISITA_TÉCNICA | AG17: 1 | AH17: 0 | AI17: =IF(AD17="TIPO I",'BASE LIQUIDACION REDEBAN 2025'!$B$2,IF(AD17="TIPO II",'BASE LIQUIDACION REDEBAN 2025'!$B$3,IF(AD17="TIPO III",'BASE LIQUIDACION REDEBAN 2025'!$B$4,IF(AD17="TIPO IV",'BASE LIQUIDACION REDEBAN 2025'!$B$5,IF(AE17="AEREO",'BASE LIQUIDACION REDEBAN 2025'!$B$6,'BASE LIQUIDACION REDEBAN 2025'!$B$5))))) -> 163813.7 | AJ17: =IF(AD17="TIPO I",'BASE LIQUIDACION REDEBAN 2025'!$B$10,IF(AD17="TIPO II",'BASE LIQUIDACION REDEBAN 2025'!$B$11,IF(AD17="TIPO III",'BASE LIQUIDACION REDEBAN 2025'!$B$12,'BASE LIQUIDACION REDEBAN 2025'!$B$13))) -> 140395.63 | AK17: =AG17*AI17+AH17*AJ17 -> 163813.7
A18: MEDELLIN | B18: =VLOOKUP(A18,'CENTRO DE COSTOS'!A:D,4,FALSE) -> JUAN SEBASTIÁN RÍOS CASTRILLÓN | C18: =VLOOKUP(A18,'CENTRO DE COSTOS'!A:D,2,FALSE) -> 0004-0005 | D18: 5088 | E18: TA-25-561212 | F18: FO-25-854662 | G18: 45807 | H18: 45812 | I18: 45807 | J18: 45811 | K18: 45811 | L18: ANTIOQUIA | M18: BELLO | N18: BARRIO PACHELY BELLO 1 | O18: 79661 | P18: CB CRECIMIENTO - NUEVO | Q18: APERTURA | R18: REDEBAN | S18: UNO A UNO | T18: UNO A UNO | U18: EJECUTADO | V18: 30-05-2025 SE REALIZA LLAMADA AL CLIENTE, SE HABLA CON EL SR JUAN DAVID GUTIERREZ OQUENDO SE VALIDA DIRECCIÓN OK, CANAL OK, DISPONIBILIDAD TOTAL, LLAMAR EL DÍA LA INSTALACIÓN PARA CONFIRMAR VISITA, AVISO EXTERIOR ALTURA APROX 3 METROS; TOMACORRIENTE CERCANO: SI; TIENE CABINA DE SEGURIDAD: NO // CONTACTO REALIZADO POR LA APP 3/6/2025 SE REALIZA INSTALACIÓN DE CORRESPONSAL, SE INSTALAN EQUIPOS CON PRUEBAS EXITOSAS, SE CAPACITA Y SE EVALÚA AL CLIENTE, SE INSTALA PUBLICIDAD COMPLETA, CB QUEDA OPERATIVO. USUARIO SOMOS BANCOLOMBIA ACTIVO | W18: ZAPATA LOPEZ EDWARD ASDRUBAL | X18: SXUZZ187 | Y18: 1175437 | Z18: N/A | AA18: 1239626 | AB18: N/A | AC18: 40 ROLLOS | AD18: TIPO I | AE18: TERRESTRE | AF18: VISITA_TÉCNICA | AG18: 1 | AH18: 0 | AI18: =IF(AD18="TIPO I",'BASE LIQUIDACION REDEBAN 2025'!$B$2,IF(AD18="TIPO II",'BASE LIQUIDACION REDEBAN 2025'!$B$3,IF(AD18="TIPO III",'BASE LIQUIDACION REDEBAN 2025'!$B$4,IF(AD18="TIPO IV",'BASE LIQUIDACION REDEBAN 2025'!$B$5,IF(AE18="AEREO",'BASE LIQUIDACION REDEBAN 2025'!$B$6,'BASE LIQUIDACION REDEBAN 2025'!$B$5))))) -> 75096.394 | AJ18: =IF(AD18="TIPO I",'BASE LIQUIDACION REDEBAN 2025'!$B$10,IF(AD18="TIPO II",'BASE LIQUIDACION REDEBAN 2025'!$B$11,IF(AD18="TIPO III",'BASE LIQUIDACION REDEBAN 2025'!$B$12,'BASE LIQUIDACION REDEBAN 2025'!$B$13))) -> 75096.394 | AK18: =AG18*AI18+AH18*AJ18 -> 75096.394
A19: BOGOTA | B19: =VLOOKUP(A19,'CENTRO DE COSTOS'!A:D,4,FALSE) -> WILLIAM ASDRUBAL ROZO ROZO | C19: =VLOOKUP(A19,'CENTRO DE COSTOS'!A:D,2,FALSE) -> 0004-0004 | D19: 11001 | E19: TA-25-561213 | F19: FO-25-854669 | G19: 45807 | H19: 45812 | I19: 45807 | J19: 45811 | K19: 45811 | L19: CUNDINAMARCA | M19: BOGOTA | N19: BARRIO EL POA BOGOTA 1 | O19: 79614 | P19: CB CRECIMIENTO - NUEVO | Q19: APERTURA | R19: REDEBAN | S19: UNO A UNO | T19: UNO A UNO | U19: EJECUTADO | V19: 30-05-2025 SE REALIZA LLAMADA AL CLIENTE, SE HABLA CON LA SRA BLANCA NIDIA RAMIREZ QUINTERO SE VALIDA DIRECCIÓN OK, CANAL OK, DISPONIBILIDAD TOTAL, LLAMAR EL DÍA LA INSTALACIÓN PARA CONFIRMAR VISITA, AVISO EXTERIOR ALTURA APROX CLIENTE NO TIENE CONOCIMIENTO DE MEDIDAS; TOMACORRIENTE CERCANO: SI; TIENE CABINA DE SEGURIDAD: SI // CONTACTO REALIZADO POR LA APP 3/6/2025 SE REALIZA INSTALACIÓN DE CORRESPONSAL, SE INSTALAN EQUIPOS CON PRUEBAS EXITOSAS, SE CAPACITA Y SE EVALÚA AL CLIENTE, SE INSTALA PUBLICIDAD COMPLETA, CB QUEDA OPERATIVO. USUARIO SOMOS BANCOLOMBIA ACTIVO | W19: MURCIA HERNANDEZ HARVEY IGNACIO | X19: SXUZZ140 | Y19: 1040491 | Z19: N/A | AA19: 1110498 | AB19: N/A | AC19: 40 ROLLOS | AD19: TIPO I | AE19: TERRESTRE | AF19: VISITA_TÉCNICA | AG19: 1 | AH19: 0 | AI19: =IF(AD19="TIPO I",'BASE LIQUIDACION REDEBAN 2025'!$B$2,IF(AD19="TIPO II",'BASE LIQUIDACION REDEBAN 2025'!$B$3,IF(AD19="TIPO III",'BASE LIQUIDACION REDEBAN 2025'!$B$4,IF(AD19="TIPO IV",'BASE LIQUIDACION REDEBAN 2025'!$B$5,IF(AE19="AEREO",'BASE LIQUIDACION REDEBAN 2025'!$B$6,'BASE LIQUIDACION REDEBAN 2025'!$B$5))))) -> 75096.394 | AJ19: =IF(AD19="TIPO I",'BASE LIQUIDACION REDEBAN 2025'!$B$10,IF(AD19="TIPO II",'BASE LIQUIDACION REDEBAN 2025'!$B$11,IF(AD19="TIPO III",'BASE LIQUIDACION REDEBAN 2025'!$B$12,'BASE LIQUIDACION REDEBAN 2025'!$B$13))) -> 75096.394 | AK19: =AG19*AI19+AH19*AJ19 -> 75096.394
A20: MEDELLIN | B20: =VLOOKUP(A20,'CENTRO DE COSTOS'!A:D,4,FALSE) -> JUAN SEBASTIÁN RÍOS CASTRILLÓN | C20: =VLOOKUP(A20,'CENTRO DE COSTOS'!A:D,2,FALSE) -> 0004-0005 | D20: 5001 | E20: TA-25-561215 | F20: FO-25-854673 | G20: 45807 | H20: 45812 | I20: 45807 | J20: 45811 | K20: 45811 | L20: ANTIOQUIA | M20: MEDELLIN | N20: BARRIO CALASANZ MEDELLIN 7 | O20: 79676 | P20: CB CRECIMIENTO - NUEVO | Q20: APERTURA | R20: REDEBAN | S20: UNO A UNO | T20: UNO A UNO | U20: EJECUTADO | V20: 30-05-2025 SE REALIZA LLAMADA AL CLIENTE, SE HABLA CON EL SR LUIS FERNANDO ARIAS RIOS SE VALIDA DIRECCIÓN OK, CANAL OK, DISPONIBILIDAD TOTAL, LLAMAR EL DÍA LA INSTALACIÓN PARA CONFIRMAR VISITA, AVISO EXTERIOR ALTURA APROX NO TIENE CONOCIMIENTO DE MEDIDAS; TOMACORRIENTE CERCANO: SI; TIENE CABINA DE SEGURIDAD: NO // CONTACTO REALIZADO POR LA APP 3/6/2025 SE REALIZA INSTALACIÓN DE CORRESPONSAL, SE INSTALAN EQUIPOS CON PRUEBAS EXITOSAS, SE CAPACITA Y SE EVALÚA AL CLIENTE, SE INSTALA PUBLICIDAD COMPLETA, CB QUEDA OPERATIVO. USUARIO SOMOS BANCOLOMBIA ACTIVO | W20: BADEL ACUÑA LUIS ALBERTO | X20: SXUZZ202 | Y20: 1092122 | Z20: N/A | AA20: 1239775 | AB20: N/A | AC20: 40 ROLLOS | AD20: TIPO I | AE20: TERRESTRE | AF20: VISITA_TÉCNICA | AG20: 1 | AH20: 0 | AI20: =IF(AD20="TIPO I",'BASE LIQUIDACION REDEBAN 2025'!$B$2,IF(AD20="TIPO II",'BASE LIQUIDACION REDEBAN 2025'!$B$3,IF(AD20="TIPO III",'BASE LIQUIDACION REDEBAN 2025'!$B$4,IF(AD20="TIPO IV",'BASE LIQUIDACION REDEBAN 2025'!$B$5,IF(AE20="AEREO",'BASE LIQUIDACION REDEBAN 2025'!$B$6,'BASE LIQUIDACION REDEBAN 2025'!$B$5))))) -> 75096.394 | AJ20: =IF(AD20="TIPO I",'BASE LIQUIDACION REDEBAN 2025'!$B$10,IF(AD20="TIPO II",'BASE LIQUIDACION REDEBAN 2025'!$B$11,IF(AD20="TIPO III",'BASE LIQUIDACION REDEBAN 2025'!$B$12,'BASE LIQUIDACION REDEBAN 2025'!$B$13))) -> 75096.394 | AK20: =AG20*AI20+AH20*AJ20 -> 75096.394
A21: CALI | B21: =VLOOKUP(A21,'CENTRO DE COSTOS'!A:D,4,FALSE) -> DIEGO FERNANDO HENAO CARDONA | C21: =VLOOKUP(A21,'CENTRO DE COSTOS'!A:D,2,FALSE) -> 0004-0003 | D21: 76001 | E21: TA-25-561216 | F21: FO-25-854677 | G21: 45807 | H21: 45812 | I21: 45807 | J21: 45811 | K21: 45811 | L21: VALLE DEL CAUCA | M21: CALI | N21: BARRIO ALTOS DE SANTA ELENA CALI | O21: 79618 | P21: CB CRECIMIENTO - NUEVO | Q21: APERTURA | R21: REDEBAN | S21: UNO A UNO | T21: UNO A UNO | U21: EJECUTADO | V21: 30-05-2025 SE REALIZA LLAMADA AL CLIENTE, SE HABLA CON LA SRA DIANA MARCELA VELEZ HUERTAS SE VALIDA DIRECCIÓN OK, CANAL OK, DISPONIBILIDAD TOTAL, LLAMAR EL DÍA LA INSTALACIÓN PARA CONFIRMAR VISITA, AVISO EXTERIOR ALTURA APROX 2 METROS; TOMACORRIENTE CERCANO: SI; TIENE CABINA DE SEGURIDAD: NO // CONTACTO REALIZADO POR LA APP 3/6/2025 SE REALIZA INSTALACIÓN DE CORRESPONSAL, SE INSTALAN EQUIPOS CON PRUEBAS EXITOSAS, SE CAPACITA Y SE EVALÚA AL CLIENTE, SE INSTALA PUBLICIDAD COMPLETA, CB QUEDA OPERATIVO. USUARIO SOMOS BANCOLOMBIA ACTIVO | W21: MONTERO MUESES GIAN CARLO | X21: SXUZZ144 | Y21: 1074324 | Z21: N/A | AA21: 864190 | AB21: N/A | AC21: 40 ROLLOS | AD21: TIPO I | AE21: TERRESTRE | AF21: VISITA_TÉCNICA | AG21: 1 | AH21: 0 | AI21: =IF(AD21="TIPO I",'BASE LIQUIDACION REDEBAN 2025'!$B$2,IF(AD21="TIPO II",'BASE LIQUIDACION REDEBAN 2025'!$B$3,IF(AD21="TIPO III",'BASE LIQUIDACION REDEBAN 2025'!$B$4,IF(AD21="TIPO IV",'BASE LIQUIDACION REDEBAN 2025'!$B$5,IF(AE21="AEREO",'BASE LIQUIDACION REDEBAN 2025'!$B$6,'BASE LIQUIDACION REDEBAN 2025'!$B$5))))) -> 75096.394 | AJ21: =IF(AD21="TIPO I",'BASE LIQUIDACION REDEBAN 2025'!$B$10,IF(AD21="TIPO II",'BASE LIQUIDACION REDEBAN 2025'!$B$11,IF(AD21="TIPO III",'BASE LIQUIDACION REDEBAN 2025'!$B$12,'BASE LIQUIDACION REDEBAN 2025'!$B$13))) -> 75096.394 | AK21: =AG21*AI21+AH21*AJ21 -> 75096.394
A22: CALI | B22: =VLOOKUP(A22,'CENTRO DE COSTOS'!A:D,4,FALSE) -> DIEGO FERNANDO HENAO CARDONA | C22: =VLOOKUP(A22,'CENTRO DE COSTOS'!A:D,2,FALSE) -> 0004-0003 | D22: 76563 | E22: TA-25-561217 | F22: FO-25-854680 | G22: 45807 | H22: 45812 | I22: 45807 | J22: 45811 | K22: 45811 | L22: VALLE DEL CAUCA | M22: PRADERA | N22: BARRIO CENTRO PRADERA 9 | O22: 79650 | P22: CB CRECIMIENTO - NUEVO | Q22: APERTURA | R22: REDEBAN | S22: UNO A UNO | T22: UNO A UNO | U22: EJECUTADO | V22: 30-05-2025 SE REALIZA LLAMADA AL CLIENTE, SE HABLA CON LA SRA YEDSICA LORENA PLAZA SALAZAR SE VALIDA DIRECCIÓN OK, CANAL OK, DISPONIBILIDAD TOTAL, LLAMAR EL DÍA LA INSTALACIÓN PARA CONFIRMAR VISITA, AVISO EXTERIOR ALTURA APROX 1,30 METROS; TOMACORRIENTE CERCANO: SI; TIENE CABINA DE SEGURIDAD: NO // CONTACTO REALIZADO POR LA APP 03-06 SE REALIZA INSTALACIÓN DE CORRESPONSAL, SE INSTALAN EQUIPOS CON PRUEBAS EXITOSAS, SE CAPACITA Y SE EVALÚA AL CLIENTE, SE INSTALA PUBLICIDAD COMPLETA, CB QUEDA OPERATIVO. USUARIO SOMOS BANCOLOMBIA ACTIVO | W22: TORRES GARCIA JENDRY JOSE | X22: SXUZZ176 | Y22: 868754 | Z22: N/A | AA22: 846414 | AB22: N/A | AC22: 40 ROLLOS | AD22: TIPO II | AE22: TERRESTRE | AF22: VISITA_TÉCNICA | AG22: 1 | AH22: 0 | AI22: =IF(AD22="TIPO I",'BASE LIQUIDACION REDEBAN 2025'!$B$2,IF(AD22="TIPO II",'BASE LIQUIDACION REDEBAN 2025'!$B$3,IF(AD22="TIPO III",'BASE LIQUIDACION REDEBAN 2025'!$B$4,IF(AD22="TIPO IV",'BASE LIQUIDACION REDEBAN 2025'!$B$5,IF(AE22="AEREO",'BASE LIQUIDACION REDEBAN 2025'!$B$6,'BASE LIQUIDACION REDEBAN 2025'!$B$5))))) -> 163813.7 | AJ22: =IF(AD22="TIPO I",'BASE LIQUIDACION REDEBAN 2025'!$B$10,IF(AD22="TIPO II",'BASE LIQUIDACION REDEBAN 2025'!$B$11,IF(AD22="TIPO III",'BASE LIQUIDACION REDEBAN 2025'!$B$12,'BASE LIQUIDACION REDEBAN 2025'!$B$13))) -> 140395.63 | AK22: =AG22*AI22+AH22*AJ22 -> 163813.7
A23: BOGOTA | B23: =VLOOKUP(A23,'CENTRO DE COSTOS'!A:D,4,FALSE) -> WILLIAM ASDRUBAL ROZO ROZO | C23: =VLOOKUP(A23,'CENTRO DE COSTOS'!A:D,2,FALSE) -> 0004-0004 | D23: 11001 | E23: TA-25-561218 | F23: FO-25-854684 | G23: 45807 | H23: 45812 | I23: 45807 | J23: 45811 | K23: 45811 | L23: CUNDINAMARCA | M23: BOGOTA | N23: BARRIO VILLA ALAMOS BOGOTA | O23: 79609 | P23: CB CRECIMIENTO - NUEVO | Q23: APERTURA | R23: REDEBAN | S23: UNO A UNO | T23: UNO A UNO | U23: EJECUTADO | V23: 30-05-2025 SE REALIZA LLAMADA AL CLIENTE, SE HABLA CON LA SRA YESSICA SAAVEDRA PARRA SE VALIDA DIRECCIÓN OK, CANAL OK, DISPONIBILIDAD TOTAL, LLAMAR EL DÍA LA INSTALACIÓN PARA CONFIRMAR VISITA, AVISO EXTERIOR ALTURA APROX 2,50 A 3 METROS; TOMACORRIENTE CERCANO: SI; TIENE CABINA DE SEGURIDAD: NO // CONTACTO REALIZADO POR LA APP 3/6/2025 SE REALIZA INSTALACIÓN DE CORRESPONSAL, SE INSTALAN EQUIPOS CON PRUEBAS EXITOSAS, SE CAPACITA Y SE EVALÚA AL CLIENTE, SE INSTALA PUBLICIDAD COMPLETA, CB QUEDA OPERATIVO. USUARIO SOMOS BANCOLOMBIA ACTIVO | W23: GOMEZ VEGA DAVID SNEYDER | X23: SXUZZ135 | Y23: 1021069 | Z23: N/A | AA23: 1076249 | AB23: N/A | AC23: 40 ROLLOS | AD23: TIPO I | AE23: TERRESTRE | AF23: VISITA_TÉCNICA | AG23: 1 | AH23: 0 | AI23: =IF(AD23="TIPO I",'BASE LIQUIDACION REDEBAN 2025'!$B$2,IF(AD23="TIPO II",'BASE LIQUIDACION REDEBAN 2025'!$B$3,IF(AD23="TIPO III",'BASE LIQUIDACION REDEBAN 2025'!$B$4,IF(AD23="TIPO IV",'BASE LIQUIDACION REDEBAN 2025'!$B$5,IF(AE23="AEREO",'BASE LIQUIDACION REDEBAN 2025'!$B$6,'BASE LIQUIDACION REDEBAN 2025'!$B$5))))) -> 75096.394 | AJ23: =IF(AD23="TIPO I",'BASE LIQUIDACION REDEBAN 2025'!$B$10,IF(AD23="TIPO II",'BASE LIQUIDACION REDEBAN 2025'!$B$11,IF(AD23="TIPO III",'BASE LIQUIDACION REDEBAN 2025'!$B$12,'BASE LIQUIDACION REDEBAN 2025'!$B$13))) -> 75096.394 | AK23: =AG23*AI23+AH23*AJ23 -> 75096.394
