Workbook
Name ACTIVIDAD: [1]Hoja2!$P$2:$P$30
Name Clientes: [2]Clientes!$A$2:$A$100
Name COORDINADOR: [1]Hoja2!$D$2:$D$30
Name Coordinadores: [3]Coordinadores!$A$2:$A$1000
Name DOCUMENTADOR: [1]Hoja2!$A$2:$A$30
Name ES: [1]Hoja2!$K$2:$K$30
Name ESS: [1]Hoja2!$K$2:$K$30
Name Estado: [2]Formulas!$K$2:$K$5000
Name ESTADOACTIVIDAD: [1]Hoja2!$M$2:$M$30
Name ESTADOSCIERRES: '[4]lista desplegable'!$CX$1:$DA$1
Name Facturacion: '[5]Listas desplegables'!$AO$1:$AR$1
Name solicitudes: '[5]Listas desplegables'!$U$1:$AF$1
Name Tecnicos: [2]Tecnicos!$A$2:$A$1000

Sheet RESUMEN
A1: LÍNEA COMUNICACIONES S.A.S | F1: FACTURACIÓN CORRESPONSALES BANCARIOS TIQUIETES AÉREOS
A2: FACTURACIÓN VISITAS FALLIDAS CORRESPONSALES BANCARIOS | F2: =A3 -> JUNIO 2025
A3: JUNIO 2025
F4: CONCEPTOS | G4: TRAYECTOS | H4: TOTAL | I4: % ADMINISTRACIÓN | J4: TOTAL
A5: CONCEPTOS | B5: CANT | D5: TOTAL | I5: =H5*0.12 -> 0 | J5: =H5+I5 -> 0
A6: =CONCATENATE("CIERRES NO EXITOSOS ",A3) -> CIERRES NO EXITOSOS JUNIO 2025 | B6: =COUNTA(CIERRES!A:A)-1 -> 90 | D6: =CIERRES!AE92 -> 10083278 | I6: =H6*0.12 -> 0 | J6: =H6+I6 -> 0
A7: TIQUETES | B7: 0 | D7: =J10 -> 0 | I7: =H7*0.12 -> 0 | J7: =H7+I7 -> 0
A8: SUBTOTAL | D8: =SUM(D6:D7) -> 10083278
A9: IVA | D9: =D8*0.19 -> 1915822.8
A10: TOTAL | D10: =SUM(D8:D9) -> 11999101 | F10: TOTAL | H10: =SUM(H5:H7) -> 0 | I10: =SUM(I5:I7) -> 0 | J10: =SUM(J5:J7) -> 0

Sheet BASE DE LIQUIDACION 2025
A1: CIERRE CB - VISITAS FALLIDAS O CIERRES NO EXITOSOS TARIFAS 2024 | D1: Incremento 2025
A2: Tipificación | B2: Descripción | C2: Tarifa | D2: 0.052
A3: Tipo I | B3: Metropolitano | C3: =42357*(1+$D$2) -> 44559.564
A4: Tipo II | B4: Hasta 3 horas | C4: =127767*(1+$D$2) -> 134410.88
A5: Tipo III | B5: De 3 a 5 horas | C5: =211886*(1+$D$2) -> 222904.07
A6: Tipo IV | B6: Más de 5 horas | C6: =441834*(1+$D$2) -> 464809.37
A7: Trayecto Especial | B7: No incluye valor del Tiquete | C7: Valor de actividad Tipo IV + Valor tiquete aéreo (o fluvial) + 12% administración)
A9: Gestión telefonica | B9: =36031*(1+$D$2) -> 37904.612

Sheet Tabla Dinámica
A3: COORDINADOR | B3: CENTRO DE COSTOS LINEACOM | C3: % | D3: Suma de VALOR TOTAL2 | E3: NOMBRE CC
A4: DIEGO FERNANDO HENAO CARDONA | B4: 0004-0002 | C4: 0.025927543 | D4: 261434.62 | E4: =VLOOKUP(B4,'CENTRO DE COSTOS'!B:C,2,0) -> Redeban Eje Cafetero (Pereira)
B5: 0004-0003 | C5: 0.17909631 | D5: 1805877.9 | E5: =VLOOKUP(B5,'CENTRO DE COSTOS'!B:C,2,0) -> Redeban Suroccidente (Cali)
A6: JOSE MAURICIO HERNANDEZ ROJAS | B6: 0004-0001 | C6: 0.24191066 | D6: 2439252.4 | E6: =VLOOKUP(B6,'CENTRO DE COSTOS'!B:C,2,0) -> Redeban Costa (Barranqullla)
A7: JUAN SEBASTIÁN RÍOS CASTRILLÓN | B7: 0004-0005 | C7: 0.11496876 | D7: 1159261.9 | E7: =VLOOKUP(B7,'CENTRO DE COSTOS'!B:C,2,0) -> Redeban Noroccidente (Medellín)
A8: KEVIN ALEXIS CORZO BUSTOS | B8: 0004-0007 | C8: 0.22684054 | D8: 2287296.3 | E8: =VLOOKUP(B8,'CENTRO DE COSTOS'!B:C,2,0) -> Redeban Oriente (Otros)
A9: MIGUEL JULIÁN HERNÁNDEZ GUARÍN | B9: 0004-0008 | C9: 0.11374433 | D9: 1146915.6 | E9: =VLOOKUP(B9,'CENTRO DE COSTOS'!B:C,2,0) -> Redeban Santander
A10: WILLIAM ASDRUBAL ROZO ROZO | B10: 0004-0004 | C10: 0.097511859 | D10: 983239.18 | E10: =VLOOKUP(B10,'CENTRO DE COSTOS'!B:C,2,0) -> Redeban Centro ( Bogotá)
A11: Total general | C11: 1 | D11: 10083278

Sheet CIERRES
A1: Ciudad Sede | B1: COORDINADOR | C1: CENTRO DE COSTOS LINEACOM | D1: Código DANE | E1: TA | F1: FO | G1: Fecha Asignación a Línea Comunicaciones (DD/MM/AAAA) | H1: Fecha del cierre del ticket (DD/MM/AAAA) | I1: Departamento | J1: Ciudad | K1: Nmbre del cb | L1: CB | M1: TIPO DE ACTIVIDAD | N1: SOLICITUD | O1: DESCRIPCIÓN | P1: RED | Q1: FORMATO | R1: CADENA | S1: ESTADO | T1: CAUSAL | U1: OBSERVACIÓN | V1: TECNICO | W1: TERMINAL | X1: TIPOLOGIA | Y1: TIPO DE TRAYECTO | Z1: FORMA DE ATENCIÓN | AA1: SERIAL / PLACA- GUIA | AB1: LECTOR | AC1: Dias de visita | AD1: VALOR ACTIVIDAD | AE1: VALOR TOTAL
A2: PASTO | B2: =VLOOKUP(A2,'CENTRO DE COSTOS'!A:D,4,FALSE) -> DIEGO FERNANDO HENAO CARDONA | C2: =VLOOKUP(A2,'CENTRO DE COSTOS'!A:C,2,FALSE) -> 0004-0003 | D2: 52110 | E2: TA-25-680336 | F2: FO-25-1006058 | G2: 45805.551 | H2: 45810.611 | I2: NARIÑO | J2: BUESACO | K2: DISTRICOL MISCELANEA, VARIEDAD | L2: 44480 | M2: ORDEN DE CAMBIO | N2: CIERRE | O2: CIERRE | P2: REDEBAN | Q2: AGREGADOR | R2: DISTRICOL | S2: NO_EXITOSO | T2: CB NO ENTREGA EQUIPO | U2: 02-06-2025 SOPORTE TELEFÓNICO: SE LLAMA AL CONTACTO E INDICA QUE NO AH SOLITARIO EL CIERRE DEL CORRESPONSAL. | V2: BOLAÑOS TABORDA JORGE ENRIQUE | W2: 0 | X2: TIPO II | Y2: =VLOOKUP(D2,TIPOLOGIAS!A:F,5,0) -> TERRESTRE | Z2: SOPORTE_TELEFÓNICO | AA2: 0 | AB2: 0 | AC2: 0 | AD2: =IF(AND(Z2="SOPORTE_TELEFÓNICO",OR(T2="SIN CONTACTO CON EL CB",T2="NÚMEROS DE CONTACTO ERRADOS")),0,IF(Z2="SOPORTE_TELEFÓNICO",'BASE DE LIQUIDACION 2025'!$B$9,IF(X2="TIPO I",'BASE DE LIQUIDACION 2025'!$C$3,IF(X2="TIPO II",'BASE DE LIQUIDACION 2025'!$C$4,IF(X2="TIPO III",'BASE DE LIQUIDACION 2025'!$C$5,'BASE DE LIQUIDACION 2025'!$C$6))))) -> 37904.612 | AE2: =IF(Z2="SOPORTE_TELEFÓNICO",AD2,CIERRES!AC2*CIERRES!AD2) -> 37904.612
A3: PASTO | B3: =VLOOKUP(A3,'CENTRO DE COSTOS'!A:D,4,FALSE) -> DIEGO FERNANDO HENAO CARDONA | C3: =VLOOKUP(A3,'CENTRO DE COSTOS'!A:C,2,FALSE) -> 0004-0003 | D3: 52110 | E3: TA-25-682391 | F3: FO-25-1011023 | G3: 45806.485 | H3: 45810.619 | I3: NARIÑO | J3: BUESACO | K3: BARRIO GGT SANTA MARIA BUESACO | L3: 78244 | M3: ORDEN DE CAMBIO | N3: CIERRE | O3: CIERRE | P3: REDEBAN | Q3: CB UNO A UNO | R3: CB UNO A UNO | S3: NO_EXITOSO | T3: CB NO ENTREGA EQUIPO | U3: 02-06-2025 SOPORTE TELEFÓNICO: CLIENTE INDICA QUE NO AH SOLICITADO EL CIERRE DEL CORREPONSAL. | V3: BOLAÑOS TABORDA JORGE ENRIQUE | W3: 0 | X3: TIPO II | Y3: =VLOOKUP(D3,TIPOLOGIAS!A:F,5,0) -> TERRESTRE | Z3: SOPORTE_TELEFÓNICO | AA3: 0 | AB3: 0 | AC3: 0 | AD3: =IF(AND(Z3="SOPORTE_TELEFÓNICO",OR(T3="SIN CONTACTO CON EL CB",T3="NÚMEROS DE CONTACTO ERRADOS")),0,IF(Z3="SOPORTE_TELEFÓNICO",'BASE DE LIQUIDACION 2025'!$B$9,IF(X3="TIPO I",'BASE DE LIQUIDACION 2025'!$C$3,IF(X3="TIPO II",'BASE DE LIQUIDACION 2025'!$C$4,IF(X3="TIPO III",'BASE DE LIQUIDACION 2025'!$C$5,'BASE DE LIQUIDACION 2025'!$C$6))))) -> 37904.612 | AE3: =IF(Z3="SOPORTE_TELEFÓNICO",AD3,CIERRES!AC3*CIERRES!AD3) -> 37904.612
A4: NEIVA | B4: =VLOOKUP(A4,'CENTRO DE COSTOS'!A:D,4,FALSE) -> KEVIN ALEXIS CORZO BUSTOS | C4: =VLOOKUP(A4,'CENTRO DE COSTOS'!A:C,2,FALSE) -> 0004-0007 | D4: 18460 | E4: TA-25-673749 | F4: FO-25-992079 | G4: 45803.534 | H4: 45811.345 | I4: CAQUETA | J4: MILAN | K4: DISTRICOL DROG MUNDO FARMACO | L4: 57007 | M4: ORDEN DE CAMBIO | N4: CIERRE | O4: CIERRE | P4: REDEBAN | Q4: AGREGADOR | R4: DISTRICOL | S4: NO_EXITOSO | T4: CB NO ENTREGA EQUIPO | U4: 03-06-2025 SE LLEGA A LA DIRECCIÓN INDICANDA PERO COMERCIO SE ENCUENTRA CERRADO, SE LLAMA AL CLIENTE Y MANIFIESTA QUE SE ENCUENTRA HOSPITALIZADA EN LA CLÍNICA DE FLORENCIA Y NO TIENE QUIEN HAGA LA ENTREGA DE LOS EQUIPOS, INDICA QUE CUANDO SALGA DE LA HOSPITALIZACIÓN LLAMARÁ PARA SOLICITAR LA ENTREGA DE LOS EQUIPOS. | V4: BERMUDEZ SANCHEZ JOSE NEYBER | W4: XPRZZ673 | X4: TIPO IV | Y4: =VLOOKUP(D4,TIPOLOGIAS!A:F,5,0) -> TERRESTRE | Z4: VISITA_TÉCNICA | AA4: 0 | AB4: 0 | AC4: 1 | AD4: =IF(AND(Z4="SOPORTE_TELEFÓNICO",OR(T4="SIN CONTACTO CON EL CB",T4="NÚMEROS DE CONTACTO ERRADOS")),0,IF(Z4="SOPORTE_TELEFÓNICO",'BASE DE LIQUIDACION 2025'!$B$9,IF(X4="TIPO I",'BASE DE LIQUIDACION 2025'!$C$3,IF(X4="TIPO II",'BASE DE LIQUIDACION 2025'!$C$4,IF(X4="TIPO III",'BASE DE LIQUIDACION 2025'!$C$5,'BASE DE LIQUIDACION 2025'!$C$6))))) -> 464809.37 | AE4: =IF(Z4="SOPORTE_TELEFÓNICO",AD4,CIERRES!AC4*CIERRES!AD4) -> 464809.37
A5: BOGOTA | B5: =VLOOKUP(A5,'CENTRO DE COSTOS'!A:D,4,FALSE) -> WILLIAM ASDRUBAL ROZO ROZO | C5: =VLOOKUP(A5,'CENTRO DE COSTOS'!A:C,2,FALSE) -> 0004-0004 | D5: 11001 | E5: TA-25-686012 | F5: FO-25-1018582 | G5: 45807.653 | H5: 45811.636 | I5: CUNDINAMARCA | J5: BOGOTA | K5: BARRIO NORMANDIA II BOGOTA | L5: 13548 | M5: ORDEN DE CAMBIO | N5: CIERRE | O5: RECUPERACION DE EQUIPOS | P5: REDEBAN | Q5: CB UNO A UNO | R5: CB UNO A UNO | S5: NO_EXITOSO | T5: CB NO ENTREGA EQUIPO | U5: 03-06-2025 DIRECCIÓN NO EXISTE, SE SE TIENE CONTACTO CON EL COMERCIO VÍA TELEFÓNICA EL SEÑOR FABIO INDICA QUE NO SE ENCUENTRA EN LA CIUDAD DE BOGOTÁ. | V5: GARCIA PASTRANA KEVIN FERNANDO | W5: 0 | X5: TIPO I | Y5: =VLOOKUP(D5,TIPOLOGIAS!A:F,5,0) -> TERRESTRE | Z5: VISITA_TÉCNICA | AA5: 0 | AB5: 0 | AC5: 1 | AD5: =IF(AND(Z5="SOPORTE_TELEFÓNICO",OR(T5="SIN CONTACTO CON EL CB",T5="NÚMEROS DE CONTACTO ERRADOS")),0,IF(Z5="SOPORTE_TELEFÓNICO",'BASE DE LIQUIDACION 2025'!$B$9,IF(X5="TIPO I",'BASE DE LIQUIDACION 2025'!$C$3,IF(X5="TIPO II",'BASE DE LIQUIDACION 2025'!$C$4,IF(X5="TIPO III",'BASE DE LIQUIDACION 2025'!$C$5,'BASE DE LIQUIDACION 2025'!$C$6))))) -> 44559.564 | AE5: =IF(Z5="SOPORTE_TELEFÓNICO",AD5,CIERRES!AC5*CIERRES!AD5) -> 44559.564
A6: NEIVA | B6: =VLOOKUP(A6,'CENTRO DE COSTOS'!A:D,4,FALSE) -> KEVIN ALEXIS CORZO BUSTOS | C6: =VLOOKUP(A6,'CENTRO DE COSTOS'!A:C,2,FALSE) -> 0004-0007 | D6: 18150 | E6: TA-25-682373 | F6: FO-25-1010988 | G6: 45806.485 | H6: 45811.685 | I6: CAQUETA | J6: CARTAGENA DEL CHAIRA | K6: BARRIO BELLA VISTA CARTAGENA DEL CHAIRA | L6: 76062 | M6: ORDEN DE CAMBIO | N6: CIERRE | O6: CIERRE | P6: REDEBAN | Q6: CB UNO A UNO | R6: CB UNO A UNO | S6: NO_EXITOSO | T6: CB NO ENTREGA EQUIPO | U6: 03-06-2025 SE REALIZA VISITA AL CORRESPONSAL Y CLIENTE MANIFIESTA QUE NO PERMITE EL RETIRO DEL CORRESPONSAL YA QUE SE ENCUENTRA EN UNA GESTIÓN DE LA FACTURACION ELECTRÓNICA CON LA ENTIDAD Y ESPERA UNA RESPUESTA POR PARTE DEL BANCO, YA QUE ELLOS NO HAN SOLICITADO EL CIERRE DEL CORRESPONSAL. | V6: BERMUDEZ SANCHEZ JOSE NEYBER | W6: FA0BZ311 | X6: TIPO IV ESPECIAL | Y6: =VLOOKUP(D6,TIPOLOGIAS!A:F,5,0) -> TERRESTRE | Z6: VISITA_TÉCNICA | AA6: 0 | AB6: 0 | AC6: 1 | AD6: =IF(AND(Z6="SOPORTE_TELEFÓNICO",OR(T6="SIN CONTACTO CON EL CB",T6="NÚMEROS DE CONTACTO ERRADOS")),0,IF(Z6="SOPORTE_TELEFÓNICO",'BASE DE LIQUIDACION 2025'!$B$9,IF(X6="TIPO I",'BASE DE LIQUIDACION 2025'!$C$3,IF(X6="TIPO II",'BASE DE LIQUIDACION 2025'!$C$4,IF(X6="TIPO III",'BASE DE LIQUIDACION 2025'!$C$5,'BASE DE LIQUIDACION 2025'!$C$6))))) -> 464809.37 | AE6: =IF(Z6="SOPORTE_TELEFÓNICO",AD6,CIERRES!AC6*CIERRES!AD6) -> 464809.37
A7: PASTO | B7: =VLOOKUP(A7,'CENTRO DE COSTOS'!A:D,4,FALSE) -> DIEGO FERNANDO HENAO CARDONA | C7: =VLOOKUP(A7,'CENTRO DE COSTOS'!A:C,2,FALSE) -> 0004-0003 | D7: 52079 | E7: TA-25-682390 | F7: FO-25-1011020 | G7: 45806.485 | H7: 45812.355 | I7: NARIÑO | J7: BARBACOAS | K7: BARRIO CL DEL COMERCIO BARBACOAS | L7: 78063 | M7: ORDEN DE CAMBIO | N7: CIERRE | O7: CIERRE | P7: REDEBAN | Q7: CB UNO A UNO | R7: CB UNO A UNO | S7: NO_EXITOSO | T7: CB NO ENTREGA EQUIPO | U7: 04-06-2025 SE REALIZA LLAMADA TELEFONICA EL CLIENTE PARA VALIDAR CIERRE, CLIENTE INFORMA QUE NO HA SOLICITADO NINGUN CIERRE , QUE TENIA UN TEMA DE FACTURACION CON LA ENTIDAD PERO QUE YA FUE RESUELTO, POR LO TENTO NO DESEA ENTREGAR EQUIPOS, | V7: HENAO CARDONA DIEGO FERNANDO | W7: 0 | X7: TIPO IV | Y7: =VLOOKUP(D7,TIPOLOGIAS!A:F,5,0) -> TERRESTRE | Z7: SOPORTE_TELEFÓNICO | AA7: 0 | AB7: 0 | AC7: 0 | AD7: =IF(AND(Z7="SOPORTE_TELEFÓNICO",OR(T7="SIN CONTACTO CON EL CB",T7="NÚMEROS DE CONTACTO ERRADOS")),0,IF(Z7="SOPORTE_TELEFÓNICO",'BASE DE LIQUIDACION 2025'!$B$9,IF(X7="TIPO I",'BASE DE LIQUIDACION 2025'!$C$3,IF(X7="TIPO II",'BASE DE LIQUIDACION 2025'!$C$4,IF(X7="TIPO III",'BASE DE LIQUIDACION 2025'!$C$5,'BASE DE LIQUIDACION 2025'!$C$6))))) -> 37904.612 | AE7: =IF(Z7="SOPORTE_TELEFÓNICO",AD7,CIERRES!AC7*CIERRES!AD7) -> 37904.612
A8: BARRANQUILLA | B8: =VLOOKUP(A8,'CENTRO DE COSTOS'!A:D,4,FALSE) -> JOSE MAURICIO HERNANDEZ ROJAS | C8: =VLOOKUP(A8,'CENTRO DE COSTOS'!A:C,2,FALSE) -> 0004-0001 | D8: 8001 | E8: TA-25-683192 | F8: FO-25-1013175 | G8: 45806.669 | H8: 45812.43 | I8: ATLANTICO | J8: BARRANQUILLA | K8: BARRIO RIOMAR BARRANQUILLA 2 | L8: 75043 | M8: ORDEN DE CAMBIO | N8: CIERRE | O8: CIERRE | P8: REDEBAN | Q8: CB UNO A UNO | R8: CB UNO A UNO | S8: ILOCALIZADO | T8: CB CERRADO - DESOCUPADO | U8: 04-06-2025 SE REALIZA VISITA AL COMERCIO PARA REALIZAR EL CIERRE DEL CORRESPONSAL BANCOLOMBIA PERO NO ES POSIBLE TRATO COMUNICACION CON EL NÚMERO ASOCIADO EN LA TAREA PERO NO CONTESTAN 3007345725 | V8: PEÑALOZA GUTIERREZ RAFAEL GUSTAVO | W8: 0 | X8: TIPO I | Y8: =VLOOKUP(D8,TIPOLOGIAS!A:F,5,0) -> TERRESTRE | Z8: VISITA_TÉCNICA | AA8: 0 | AB8: 0 | AC8: 1 | AD8: =IF(AND(Z8="SOPORTE_TELEFÓNICO",OR(T8="SIN CONTACTO CON EL CB",T8="NÚMEROS DE CONTACTO ERRADOS")),0,IF(Z8="SOPORTE_TELEFÓNICO",'BASE DE LIQUIDACION 2025'!$B$9,IF(X8="TIPO I",'BASE DE LIQUIDACION 2025'!$C$3,IF(X8="TIPO II",'BASE DE LIQUIDACION 2025'!$C$4,IF(X8="TIPO III",'BASE DE LIQUIDACION 2025'!$C$5,'BASE DE LIQUIDACION 2025'!$C$6))))) -> 44559.564 | AE8: =IF(Z8="SOPORTE_TELEFÓNICO",AD8,CIERRES!AC8*CIERRES!AD8) -> 44559.564
A9: BUCARAMANGA | B9: =VLOOKUP(A9,'CENTRO DE COSTOS'!A:D,4,FALSE) -> MIGUEL JULIÁN HERNÁNDEZ GUARÍN | C9: =VLOOKUP(A9,'CENTRO DE COSTOS'!A:C,2,FALSE) -> 0004-0008 | D9: 68001 | E9: TA-25-680768 | F9: FO-25-1007152 | G9: 45805.582 | H9: 45812.601 | I9: SANTANDER | J9: BUCARAMANGA | K9: BARRIO CAMPOHERMOSO BUCARAMANA | L9: 73231 | M9: ORDEN DE CAMBIO | N9: CIERRE | O9: CIERRE | P9: REDEBAN | Q9: CB UNO A UNO | R9: CB UNO A UNO | S9: NO_EXITOSO | T9: CB NO ENTREGA EQUIPO | U9: 04-06-2025 SE ESTABLECE COMUNICACIÓN CON LA SEÑORA MARIA FERNANDA VIA WHATSAPP SE LE INFORMA QUE EL BANCO DIO LA INDICACIÓN DE CERRAR ORDEN DE TRABAJO GENERADA YA QUE EL CLIENTE NO CUENTA CON DISPONIBILIDAD PARA ENTREGAR LOS EQUIPOS SE LE INFORMA QUE TAN PRONTO TENGA DISPONIBILIDAD SE COMUNIQUE CON LA LINEA 018000953344 Y SOLICITE LA RECOLECCIÓN DE LOS MISMOS | V9: BARRERA ORTEGA MARLON STWAR | W9: 0 | X9: TIPO I | Y9: =VLOOKUP(D9,TIPOLOGIAS!A:F,5,0) -> TERRESTRE | Z9: VISITA_TÉCNICA | AA9: 0 | AB9: 0 | AC9: 1 | AD9: =IF(AND(Z9="SOPORTE_TELEFÓNICO",OR(T9="SIN CONTACTO CON EL CB",T9="NÚMEROS DE CONTACTO ERRADOS")),0,IF(Z9="SOPORTE_TELEFÓNICO",'BASE DE LIQUIDACION 2025'!$B$9,IF(X9="TIPO I",'BASE DE LIQUIDACION 2025'!$C$3,IF(X9="TIPO II",'BASE DE LIQUIDACION 2025'!$C$4,IF(X9="TIPO III",'BASE DE LIQUIDACION 2025'!$C$5,'BASE DE LIQUIDACION 2025'!$C$6))))) -> 44559.564 | AE9: =IF(Z9="SOPORTE_TELEFÓNICO",AD9,CIERRES!AC9*CIERRES!AD9) -> 44559.564
A10: PEREIRA | B10: =VLOOKUP(A10,'CENTRO DE COSTOS'!A:D,4,FALSE) -> DIEGO FERNANDO HENAO CARDONA | C10: =VLOOKUP(A10,'CENTRO DE COSTOS'!A:C,2,FALSE) -> 0004-0002 | D10: 66400 | E10: TA-25-682398 | F10: FO-25-1011040 | G10: 45806.485 | H10: 45812.666 | I10: RISARALDA | J10: LA VIRGINIA | K10: LA VIRGINIA - LOS LIBERTADORES | L10: 71934 | M10: ORDEN DE CAMBIO | N10: CIERRE | O10: CIERRE | P10: REDEBAN | Q10: CB UNO A UNO | R10: CB UNO A UNO | S10: NO_EXITOSO | T10: CB NO ENTREGA EQUIPO | U10: 04-06-2025 VISITAMOS COMERCIO PERO LA PERSONA QUE ESTÁ A CARGO NO TIENE CONOCIMIENTO, NO FUE POSIBLE COMUNICARSE CON EL ADMINISTRADOR YA QUE ESTA EN UNA REUNIÓN PERO NOS INDICA QUE EL TAMPOCO DEBE TENER CONOCIMIENTO DE QUE REALIZARAN EL CIERRE DEL CORRESPONSAL, ELLOS REALIZARÁN LA VALIDACIÓN CON EL ASESOR DE LA ZONA PARA CONTINUAR CON EL CORRESPONSAL. | V10: ARROYAVE CANO MANUEL GUILLERMO | W10: LN00M144 | X10: TIPO I | Y10: =VLOOKUP(D10,TIPOLOGIAS!A:F,5,0) -> TERRESTRE | Z10: VISITA_TÉCNICA | AA10: 0 | AB10: 0 | AC10: 1 | AD10: =IF(AND(Z10="SOPORTE_TELEFÓNICO",OR(T10="SIN CONTACTO CON EL CB",T10="NÚMEROS DE CONTACTO ERRADOS")),0,IF(Z10="SOPORTE_TELEFÓNICO",'BASE DE LIQUIDACION 2025'!$B$9,IF(X10="TIPO I",'BASE DE LIQUIDACION 2025'!$C$3,IF(X10="TIPO II",'BASE DE LIQUIDACION 2025'!$C$4,IF(X10="TIPO III",'BASE DE LIQUIDACION 2025'!$C$5,'BASE DE LIQUIDACION 2025'!$C$6))))) -> 44559.564 | AE10: =IF(Z10="SOPORTE_TELEFÓNICO",AD10,CIERRES!AC10*CIERRES!AD10) -> 44559.564
A11: VILLAVICENCIO | B11: =VLOOKUP(A11,'CENTRO DE COSTOS'!A:D,4,FALSE) -> KEVIN ALEXIS CORZO BUSTOS | C11: =VLOOKUP(A11,'CENTRO DE COSTOS'!A:C,2,FALSE) -> 0004-0007 | D11: 50001 | E11: TA-25-682444 | F11: FO-25-1011076 | G11: 45806.485 | H11: 45812.698 | I11: META | J11: VILLAVICENCIO | K11: BARRIO MANANTIAL VILLAVICENCIO | L11: 69923 | M11: ORDEN DE CAMBIO | N11: CIERRE | O11: RECUPERACION DE EQUIPOS | P11: REDEBAN | Q11: CB UNO A UNO | R11: CB UNO A UNO | S11: ILOCALIZADO | T11: CB CERRADO - DESOCUPADO | U11: 04-06-2025 SE REALIZA VISITA AL PUNTO Y COMERCIO SE ENCUENTRA CERRADO, NO ES POSIBLE CONTACTO TELEFONICO CON EL CLIENTE | V11: PEDREROS CONTRERAS MICHAEL STEVENS | W11: 0 | X11: TIPO I | Y11: =VLOOKUP(D11,TIPOLOGIAS!A:F,5,0) -> TERRESTRE | Z11: VISITA_TÉCNICA | AA11: 0 | AB11: 0 | AC11: 1 | AD11: =IF(AND(Z11="SOPORTE_TELEFÓNICO",OR(T11="SIN CONTACTO CON EL CB",T11="NÚMEROS DE CONTACTO ERRADOS")),0,IF(Z11="SOPORTE_TELEFÓNICO",'BASE DE LIQUIDACION 2025'!$B$9,IF(X11="TIPO I",'BASE DE LIQUIDACION 2025'!$C$3,IF(X11="TIPO II",'BASE DE LIQUIDACION 2025'!$C$4,IF(X11="TIPO III",'BASE DE LIQUIDACION 2025'!$C$5,'BASE DE LIQUIDACION 2025'!$C$6))))) -> 44559.564 | AE11: =IF(Z11="SOPORTE_TELEFÓNICO",AD11,CIERRES!AC11*CIERRES!AD11) -> 44559.564
A12: MONTERIA | B12: =VLOOKUP(A12,'CENTRO DE COSTOS'!A:D,4,FALSE) -> JOSE MAURICIO HERNANDEZ ROJAS | C12: =VLOOKUP(A12,'CENTRO DE COSTOS'!A:C,2,FALSE) -> 0004-0001 | D12: 23001 | E12: TA-25-682386 | F12: FO-25-1011009 | G12: 45806.485 | H12: 45812.76 | I12: CORDOBA | J12: MONTERIA | K12: BARRIO CENTRO MONTERIA | L12: 74413 | M12: ORDEN DE CAMBIO | N12: CIERRE | O12: CIERRE | P12: REDEBAN | Q12: CB UNO A UNO | R12: CB UNO A UNO | S12: NO_EXITOSO | T12: CB NO ENTREGA EQUIPO | U12: 04-06-2025 SE LLEGA AL SITIO Y NOS INFORMAN QUE LA PERSONA ENCARGADA NO SE ENCUENTRA, QUE REGRESEMOS EN OTRA OCASIÓN PARA EFECTUAR LA ENTREGA. NOS ATIENDE MARÍA ALEJANDRA ORTEGA SÁNCHEZ. | V12: CASSIANI PEREZ RAUL RAMIRO | W12: 0 | X12: TIPO I | Y12: =VLOOKUP(D12,TIPOLOGIAS!A:F,5,0) -> TERRESTRE | Z12: VISITA_TÉCNICA | AA12: 0 | AB12: 0 | AC12: 1 | AD12: =IF(AND(Z12="SOPORTE_TELEFÓNICO",OR(T12="SIN CONTACTO CON EL CB",T12="NÚMEROS DE CONTACTO ERRADOS")),0,IF(Z12="SOPORTE_TELEFÓNICO",'BASE DE LIQUIDACION 2025'!$B$9,IF(X12="TIPO I",'BASE DE LIQUIDACION 2025'!$C$3,IF(X12="TIPO II",'BASE DE LIQUIDACION 2025'!$C$4,IF(X12="TIPO III",'BASE DE LIQUIDACION 2025'!$C$5,'BASE DE LIQUIDACION 2025'!$C$6))))) -> 44559.564 | AE12: =IF(Z12="SOPORTE_TELEFÓNICO",AD12,CIERRES!AC12*CIERRES!AD12) -> 44559.564
A13: CALI | B13: =VLOOKUP(A13,'CENTRO DE COSTOS'!A:D,4,FALSE) -> DIEGO FERNANDO HENAO CARDONA | C13: =VLOOKUP(A13,'CENTRO DE COSTOS'!A:C,2,FALSE) -> 0004-0003 | D13: 19001 | E13: TA-25-682381 | F13: FO-25-1011001 | G13: 45806.485 | H13: 45813.636 | I13: CAUCA | J13: POPAYAN | K13: BARRIO BELLAVISTA POPAYAN 1 | L13: 76647 | M13: ORDEN DE CAMBIO | N13: CIERRE | O13: CIERRE | P13: REDEBAN | Q13: CB UNO A UNO | R13: CB UNO A UNO | S13: ILOCALIZADO | T13: CB CERRADO - DESOCUPADO | U13: 05-06-2025 SE REALIZA LLAMADA CELULAR CB NO RESPONDE SE LLEGA AL SITIO SE ENCUENTRA CERRADO COMERCIO | V13: GIMBUEL LASSO LUIS GERMAN | W13: LA2ZZ430 | X13: TIPO III | Y13: =VLOOKUP(D13,TIPOLOGIAS!A:F,5,0) -> TERRESTRE | Z13: VISITA_TÉCNICA | AA13: 0 | AB13: 0 | AC13: 1 | AD13: =IF(AND(Z13="SOPORTE_TELEFÓNICO",OR(T13="SIN CONTACTO CON EL CB",T13="NÚMEROS DE CONTACTO ERRADOS")),0,IF(Z13="SOPORTE_TELEFÓNICO",'BASE DE LIQUIDACION 2025'!$B$9,IF(X13="TIPO I",'BASE DE LIQUIDACION 2025'!$C$3,IF(X13="TIPO II",'BASE DE LIQUIDACION 2025'!$C$4,IF(X13="TIPO III",'BASE DE LIQUIDACION 2025'!$C$5,'BASE DE LIQUIDACION 2025'!$C$6))))) -> 222904.07 | AE13: =IF(Z13="SOPORTE_TELEFÓNICO",AD13,CIERRES!AC13*CIERRES!AD13) -> 222904.07
A14: TUNJA | B14: =VLOOKUP(A14,'CENTRO DE COSTOS'!A:D,4,FALSE) -> MIGUEL JULIÁN HERNÁNDEZ GUARÍN | C14: =VLOOKUP(A14,'CENTRO DE COSTOS'!A:C,2,FALSE) -> 0004-0008 | D14: 15759 | E14: TA-25-716434 | F14: FO-25-1049138 | G14: 45813.674 | H14: 45814.521 | I14: BOYACA | J14: SOGAMOSO | K14: BARRIO EL LIBERTADOR | L14: 25666 | M14: ORDEN DE CAMBIO | N14: CIERRE | O14: CIERRE | P14: REDEBAN | Q14: CB UNO A UNO | R14: CB UNO A UNO | S14: SOLICITUD_CANCELADA | T14: CANCELADO POR LA ENTIDAD | U14: 06-06-2025 SE CIERRA ORDEN , SE NO SE ATIENDE ACTIVIDAD , SE CANCELA ORDEN POR SOLICITUD DE LA ENTIDAD | V14: ALVARADO MORENO CRISTHIAN | W14: 0 | X14: TIPO II | Y14: =VLOOKUP(D14,TIPOLOGIAS!A:F,5,0) -> TERRESTRE | Z14: SOPORTE_TELEFÓNICO | AA14: 0 | AB14: 0 | AC14: 0 | AD14: =IF(AND(Z14="SOPORTE_TELEFÓNICO",OR(T14="SIN CONTACTO CON EL CB",T14="NÚMEROS DE CONTACTO ERRADOS")),0,IF(Z14="SOPORTE_TELEFÓNICO",'BASE DE LIQUIDACION 2025'!$B$9,IF(X14="TIPO I",'BASE DE LIQUIDACION 2025'!$C$3,IF(X14="TIPO II",'BASE DE LIQUIDACION 2025'!$C$4,IF(X14="TIPO III",'BASE DE LIQUIDACION 2025'!$C$5,'BASE DE LIQUIDACION 2025'!$C$6))))) -> 37904.612 | AE14: =IF(Z14="SOPORTE_TELEFÓNICO",AD14,CIERRES!AC14*CIERRES!AD14) -> 37904.612
A15: BOGOTA | B15: =VLOOKUP(A15,'CENTRO DE COSTOS'!A:D,4,FALSE) -> WILLIAM ASDRUBAL ROZO ROZO | C15: =VLOOKUP(A15,'CENTRO DE COSTOS'!A:C,2,FALSE) -> 0004-0004 | D15: 11001 | E15: TA-25-716462 | F15: FO-25-1049196 | G15: 45813.674 | H15: 45814.57 | I15: CUNDINAMARCA | J15: BOGOTA | K15: BARRIO MINUTO DE DIOS BOGOTA 8 | L15: 66835 | M15: ORDEN DE CAMBIO | N15: CIERRE | O15: CIERRE | P15: REDEBAN | Q15: CB UNO A UNO | R15: CB UNO A UNO | S15: ILOCALIZADO | T15: CB CERRADO - DESOCUPADO | U15: 06-06-2025 SE REALIZS VISITA A CB PARA REALIZAR CIERRE SE ENCUENTRA CERRADO ,SE INTENTA COMUNICAR CON CLIENTE NO CONTESTAN | V15: GALINDO ROJAS LUIS FELIPE | W15: 0 | X15: TIPO I | Y15: =VLOOKUP(D15,TIPOLOGIAS!A:F,5,0) -> TERRESTRE | Z15: VISITA_TÉCNICA | AA15: 0 | AB15: 0 | AC15: 1 | AD15: =IF(AND(Z15="SOPORTE_TELEFÓNICO",OR(T15="SIN CONTACTO CON EL CB",T15="NÚMEROS DE CONTACTO ERRADOS")),0,IF(Z15="SOPORTE_TELEFÓNICO",'BASE DE LIQUIDACION 2025'!$B$9,IF(X15="TIPO I",'BASE DE LIQUIDACION 2025'!$C$3,IF(X15="TIPO II",'BASE DE LIQUIDACION 2025'!$C$4,IF(X15="TIPO III",'BASE DE LIQUIDACION 2025'!$C$5,'BASE DE LIQUIDACION 2025'!$C$6))))) -> 44559.564 | AE15: =IF(Z15="SOPORTE_TELEFÓNICO",AD15,CIERRES!AC15*CIERRES!AD15) -> 44559.564
A16: MONTERIA | B16: =VLOOKUP(A16,'CENTRO DE COSTOS'!A:D,4,FALSE) -> JOSE MAURICIO HERNANDEZ ROJAS | C16: =VLOOKUP(A16,'CENTRO DE COSTOS'!A:C,2,FALSE) -> 0004-0001 | D16: 23001 | E16: TA-25-716443 | F16: FO-25-1049157 | G16: 45813.674 | H16: 45814.597 | I16: CORDOBA | J16: MONTERIA | K16: BARRIO EL DORADO MONTERIA CORD | L16: 72141 | M16: ORDEN DE CAMBIO | N16: CIERRE | O16: CIERRE | P16: REDEBAN | Q16: CB UNO A UNO | R16: CB UNO A UNO | S16: NO_EXITOSO | T16: CB NO ENTREGA EQUIPO | U16: 06-06-2025 SE LLEGA A CB, IMFOAM QUE NO ESTÁ LA PERSONA ENCARGADA DEL CB, POR ESE MOTIVO NO PERMITEN EL RETIRO DE LOS EQUIPOS DEL PUNTO | V16: COGOLLO ROSSO CAMILO ANDRES | W16: NN00N610 | X16: TIPO I | Y16: =VLOOKUP(D16,TIPOLOGIAS!A:F,5,0) -> TERRESTRE | Z16: VISITA_TÉCNICA | AA16: 0 | AB16: 0 | AC16: 1 | AD16: =IF(AND(Z16="SOPORTE_TELEFÓNICO",OR(T16="SIN CONTACTO CON EL CB",T16="NÚMEROS DE CONTACTO ERRADOS")),0,IF(Z16="SOPORTE_TELEFÓNICO",'BASE DE LIQUIDACION 2025'!$B$9,IF(X16="TIPO I",'BASE DE LIQUIDACION 2025'!$C$3,IF(X16="TIPO II",'BASE DE LIQUIDACION 2025'!$C$4,IF(X16="TIPO III",'BASE DE LIQUIDACION 2025'!$C$5,'BASE DE LIQUIDACION 2025'!$C$6))))) -> 44559.564 | AE16: =IF(Z16="SOPORTE_TELEFÓNICO",AD16,CIERRES!AC16*CIERRES!AD16) -> 44559.564
A17: CALI | B17: =VLOOKUP(A17,'CENTRO DE COSTOS'!A:D,4,FALSE) -> DIEGO FERNANDO HENAO CARDONA | C17: =VLOOKUP(A17,'CENTRO DE COSTOS'!A:C,2,FALSE) -> 0004-0003 | D17: 19532 | E17: TA-25-683193 | F17: FO-25-1013178 | G17: 45806.669 | H17: 45814.64 | I17: CAUCA | J17: PATIA | K17: BARRIO PATIA PATIA | L17: 77803 | M17: ORDEN DE CAMBIO | N17: CIERRE | O17: CIERRE | P17: REDEBAN | Q17: CB UNO A UNO | R17: CB UNO A UNO | S17: ILOCALIZADO | T17: CB CERRADO - DESOCUPADO | U17: 06-06-2025 SE REALIZA LLAMADA CELULAR CB NO RESPONDE SE ENCUENTRA COMERCIO CERRADO | V17: GIMBUEL LASSO LUIS GERMAN | W17: 10OZZ064 | X17: TIPO IV | Y17: =VLOOKUP(D17,TIPOLOGIAS!A:F,5,0) -> TERRESTRE | Z17: VISITA_TÉCNICA | AA17: 0 | AB17: 0 | AC17: 1 | AD17: =IF(AND(Z17="SOPORTE_TELEFÓNICO",OR(T17="SIN CONTACTO CON EL CB",T17="NÚMEROS DE CONTACTO ERRADOS")),0,IF(Z17="SOPORTE_TELEFÓNICO",'BASE DE LIQUIDACION 2025'!$B$9,IF(X17="TIPO I",'BASE DE LIQUIDACION 2025'!$C$3,IF(X17="TIPO II",'BASE DE LIQUIDACION 2025'!$C$4,IF(X17="TIPO III",'BASE DE LIQUIDACION 2025'!$C$5,'BASE DE LIQUIDACION 2025'!$C$6))))) -> 464809.37 | AE17: =IF(Z17="SOPORTE_TELEFÓNICO",AD17,CIERRES!AC17*CIERRES!AD17) -> 464809.37
A18: BOGOTA | B18: =VLOOKUP(A18,'CENTRO DE COSTOS'!A:D,4,FALSE) -> WILLIAM ASDRUBAL ROZO ROZO | C18: =VLOOKUP(A18,'CENTRO DE COSTOS'!A:C,2,FALSE) -> 0004-0004 | D18: 11001 | E18: TA-25-716460 | F18: FO-25-1049191 | G18: 45813.674 | H18: 45814.653 | I18: CUNDINAMARCA | J18: BOGOTA | K18: BARRIO TIERRA BUENA KENNEDY BO | L18: 59263 | M18: ORDEN DE CAMBIO | N18: CIERRE | O18: CIERRE | P18: REDEBAN | Q18: CB UNO A UNO | R18: CB UNO A UNO | S18: ILOCALIZADO | T18: CB CERRADO - DESOCUPADO | U18: 06-06-2025 SE LLEGA A SITIO SE LLAMAN A LOS NÚMEROS DE CONTACTO NO CONTESTAN SE VÁLIDA EN PORTERÍA NO RESPONDEN NI DAN INFORMACIÓN, ESTO DEBIDO A QUE NO EXISTE CORRESPONSAL BANCARIO A LA VISTA. | V18: INFANTE SIERRA MANUEL FERNANDO | W18: 0 | X18: TIPO I | Y18: =VLOOKUP(D18,TIPOLOGIAS!A:F,5,0) -> TERRESTRE | Z18: VISITA_TÉCNICA | AA18: 0 | AB18: 0 | AC18: 1 | AD18: =IF(AND(Z18="SOPORTE_TELEFÓNICO",OR(T18="SIN CONTACTO CON EL CB",T18="NÚMEROS DE CONTACTO ERRADOS")),0,IF(Z18="SOPORTE_TELEFÓNICO",'BASE DE LIQUIDACION 2025'!$B$9,IF(X18="TIPO I",'BASE DE LIQUIDACION 2025'!$C$3,IF(X18="TIPO II",'BASE DE LIQUIDACION 2025'!$C$4,IF(X18="TIPO III",'BASE DE LIQUIDACION 2025'!$C$5,'BASE DE LIQUIDACION 2025'!$C$6))))) -> 44559.564 | AE18: =IF(Z18="SOPORTE_TELEFÓNICO",AD18,CIERRES!AC18*CIERRES!AD18) -> 44559.564
A19: NEIVA | B19: =VLOOKUP(A19,'CENTRO DE COSTOS'!A:D,4,FALSE) -> KEVIN ALEXIS CORZO BUSTOS | C19: =VLOOKUP(A19,'CENTRO DE COSTOS'!A:C,2,FALSE) -> 0004-0007 | D19: 41001 | E19: TA-25-716446 | F19: FO-25-1049163 | G19: 45813.674 | H19: 45814.653 | I19: HUILA | J19: NEIVA | K19: BARRIO ALTICO NEIVA 3 | L19: 76201 | M19: ORDEN DE CAMBIO | N19: CIERRE | O19: CIERRE | P19: REDEBAN | Q19: CB UNO A UNO | R19: CB UNO A UNO | S19: NO_EXITOSO | T19: CB NO ENTREGA EQUIPO | U19: 06-06-2025 SE REALIZA VISITA AL PUNTO , PERSONA ENCARGADA INDICA QUE NO HA HECHO SOLICITUD PARA EL CIERRE DEL PUNTO, INDICA QUE SE VA A COMUNICAR CON EL BANCO PARA VALIDAR, POR AHORA NO ENTREGA EQUIPOS, CIERRE FALLIDO . | V19: DEVIA REINOSO JUAN CARLOS | W19: FA0GZ493 | X19: TIPO I | Y19: =VLOOKUP(D19,TIPOLOGIAS!A:F,5,0) -> TERRESTRE | Z19: VISITA_TÉCNICA | AA19: 0 | AB19: 0 | AC19: 1 | AD19: =IF(AND(Z19="SOPORTE_TELEFÓNICO",OR(T19="SIN CONTACTO CON EL CB",T19="NÚMEROS DE CONTACTO ERRADOS")),0,IF(Z19="SOPORTE_TELEFÓNICO",'BASE DE LIQUIDACION 2025'!$B$9,IF(X19="TIPO I",'BASE DE LIQUIDACION 2025'!$C$3,IF(X19="TIPO II",'BASE DE LIQUIDACION 2025'!$C$4,IF(X19="TIPO III",'BASE DE LIQUIDACION 2025'!$C$5,'BASE DE LIQUIDACION 2025'!$C$6))))) -> 44559.564 | AE19: =IF(Z19="SOPORTE_TELEFÓNICO",AD19,CIERRES!AC19*CIERRES!AD19) -> 44559.564
A20: VILLAVICENCIO | B20: =VLOOKUP(A20,'CENTRO DE COSTOS'!A:D,4,FALSE) -> KEVIN ALEXIS CORZO BUSTOS | C20: =VLOOKUP(A20,'CENTRO DE COSTOS'!A:C,2,FALSE) -> 0004-0007 | D20: 50287 | E20: TA-25-716448 | F20: FO-25-1049168 | G20: 45813.674 | H20: 45814.72 | I20: META | J20: FUENTE DE ORO | K20: BARRIO CENTRO 1 FUENTE DE ORO | L20: 34950 | M20: ORDEN DE CAMBIO | N20: CIERRE | O20: CIERRE | P20: REDEBAN | Q20: CB UNO A UNO | R20: CB UNO A UNO | S20: ILOCALIZADO | T20: CB CERRADO - DESOCUPADO | U20: 06-06-2025 SE REALIZA VISITA Y COMERCIO SE ENCUENTRA CERRADO, SE REALIZA CONTACTO TELEFONICO Y NO ES POSIBLE | V20: PEDREROS CONTRERAS MICHAEL STEVENS | W20: NONE | X20: TIPO III | Y20: =VLOOKUP(D20,TIPOLOGIAS!A:F,5,0) -> TERRESTRE | Z20: VISITA_TÉCNICA | AA20: 0 | AB20: 0 | AC20: 1 | AD20: =IF(AND(Z20="SOPORTE_TELEFÓNICO",OR(T20="SIN CONTACTO CON EL CB",T20="NÚMEROS DE CONTACTO ERRADOS")),0,IF(Z20="SOPORTE_TELEFÓNICO",'BASE DE LIQUIDACION 2025'!$B$9,IF(X20="TIPO I",'BASE DE LIQUIDACION 2025'!$C$3,IF(X20="TIPO II",'BASE DE LIQUIDACION 2025'!$C$4,IF(X20="TIPO III",'BASE DE LIQUIDACION 2025'!$C$5,'BASE DE LIQUIDACION 2025'!$C$6))))) -> 222904.07 | AE20: =IF(Z20="SOPORTE_TELEFÓNICO",AD20,CIERRES!AC20*CIERRES!AD20) -> 222904.07
A21: BUCARAMANGA | B21: =VLOOKUP(A21,'CENTRO DE COSTOS'!A:D,4,FALSE) -> MIGUEL JULIÁN HERNÁNDEZ GUARÍN | C21: =VLOOKUP(A21,'CENTRO DE COSTOS'!A:C,2,FALSE) -> 0004-0008 | D21: 68255 | E21: TA-25-719474 | F21: FO-25-1053434 | G21: 45814.458 | H21: 45814.741 | I21: SANTANDER | J21: EL PLAYON | K21: PTM EL PLAYON DAYECEL | L21: 62274 | M21: ORDEN DE CAMBIO | N21: CIERRE | O21: CIERRE | P21: REDEBAN | Q21: AGREGADOR | R21: COMCARD - PTM | S21: ILOCALIZADO | T21: CB CERRADO - DESOCUPADO | U21: 06-06-2025 SE INTENTA COMUCACION CON LA ADMINISTRADORA ELCIDA ACERO AL CELULAR 3163547179 Y WHATSAPP NO FUE POSIBLE, SE LLEGA A DIRECCIÓN CRA 8 #11-83, Y YA NO ESTÁ EL CORRESPONSAL, ADMINISTRADOR DEL LOCAL EXISTENTE, INFORMA QUE ELLOS TOMARON EL LOCAL APROXIMADAMENTE 3 MESES, QUE EL PROPIETARIO ANTERIOR SE FUE PARA EL MUNICIPIO DE RIO NEGRO, SE DEJA MENSAJE POR WHATSAPP, SE REALIZA LLAMADA TELEFÓNICA Y CLIENTE NO CONTESTA SE PROCEDE A CERRAR LA ORDEN. | V21: MARTINEZ FLOREZ DONIS ALBERTO | W21: 0 | X21: TIPO II | Y21: =VLOOKUP(D21,TIPOLOGIAS!A:F,5,0) -> TERRESTRE | Z21: VISITA_TÉCNICA | AA21: 0 | AB21: 0 | AC21: 1 | AD21: =IF(AND(Z21="SOPORTE_TELEFÓNICO",OR(T21="SIN CONTACTO CON EL CB",T21="NÚMEROS DE CONTACTO ERRADOS")),0,IF(Z21="SOPORTE_TELEFÓNICO",'BASE DE LIQUIDACION 2025'!$B$9,IF(X21="TIPO I",'BASE DE LIQUIDACION 2025'!$C$3,IF(X21="TIPO II",'BASE DE LIQUIDACION 2025'!$C$4,IF(X21="TIPO III",'BASE DE LIQUIDACION 2025'!$C$5,'BASE DE LIQUIDACION 2025'!$C$6))))) -> 134410.88 | AE21: =IF(Z21="SOPORTE_TELEFÓNICO",AD21,CIERRES!AC21*CIERRES!AD21) -> 134410.88
A22: MANIZALES | B22: =VLOOKUP(A22,'CENTRO DE COSTOS'!A:D,4,FALSE) -> DIEGO FERNANDO HENAO CARDONA | C22: =VLOOKUP(A22,'CENTRO DE COSTOS'!A:C,2,FALSE) -> 0004-0002 | D22: 17001 | E22: TA-25-716437 | F22: FO-25-1049142 | G22: 45813.674 | H22: 45815.397 | I22: CALDAS | J22: MANIZALES | K22: BARRIO SANTOS MANIZALES 1 | L22: 51030 | M22: ORDEN DE CAMBIO | N22: CIERRE | O22: CIERRE | P22: REDEBAN | Q22: CB UNO A UNO | R22: CB UNO A UNO | S22: ILOCALIZADO | T22: CB CERRADO - DESOCUPADO | U22: 07-06-2025 SE LLEGA A DIRECCIÓN REGISTRADA EN EL CUAL EL ESTABLECIMIENTO SE ENCUENTRA CERRADO Y SIN PUBLICIDAD DEL CORRESPONSAL Y CON AVISO SE ARRIENDA, SE PREGUNTA EN COMERCIOS CERCANOS DICEN QUE CERRARON HACE 3 SEMANAS APROX, SE TRATA COMUNICACIÓN CON USUARIO PERO NO HAY RESPUESTA | V22: AGUIRRE HENAO RAUL EDUARDO | W22: 0 | X22: TIPO I | Y22: =VLOOKUP(D22,TIPOLOGIAS!A:F,5,0) -> TERRESTRE | Z22: VISITA_TÉCNICA | AA22: 0 | AB22: 0 | AC22: 1 | AD22: =IF(AND(Z22="SOPORTE_TELEFÓNICO",OR(T22="SIN CONTACTO CON EL CB",T22="NÚMEROS DE CONTACTO ERRADOS")),0,IF(Z22="SOPORTE_TELEFÓNICO",'BASE DE LIQUIDACION 2025'!$B$9,IF(X22="TIPO I",'BASE DE LIQUIDACION 2025'!$C$3,IF(X22="TIPO II",'BASE DE LIQUIDACION 2025'!$C$4,IF(X22="TIPO III",'BASE DE LIQUIDACION 2025'!$C$5,'BASE DE LIQUIDACION 2025'!$C$6))))) -> 44559.564 | AE22: =IF(Z22="SOPORTE_TELEFÓNICO",AD22,CIERRES!AC22*CIERRES!AD22) -> 44559.564
A23: MONTERIA | B23: =VLOOKUP(A23,'CENTRO DE COSTOS'!A:D,4,FALSE) -> JOSE MAURICIO HERNANDEZ ROJAS | C23: =VLOOKUP(A23,'CENTRO DE COSTOS'!A:C,2,FALSE) -> 0004-0001 | D23: 23001 | E23: TA-25-719466 | F23: FO-25-1053413 | G23: 45814.458 | H23: 45815.448 | I23: CORDOBA | J23: MONTERIA | K23: PTM MONTERIA INVERSIONES DO CA | L23: 76641 | M23: ORDEN DE CAMBIO | N23: CIERRE | O23: CIERRE | P23: REDEBAN | Q23: AGREGADOR | R23: COMCARD - PTM | S23: ILOCALIZADO | T23: CB CERRADO - DESOCUPADO | U23: 07-06-2025 SE LLEGA A CB, ESTÁ CERRADO, SE PREGUNTA EN LUGARES CERCANOS INFORMAN QUE TIENE TIEMPO QUE NO ABREN, SE MARCA A NÚMERO ASIGNADO 3164976081, INFORMAN QUE ES NÚMERO EQUIVOCADO | V23: COGOLLO ROSSO CAMILO ANDRES | W23: LA2ZZ424 | X23: TIPO I | Y23: =VLOOKUP(D23,TIPOLOGIAS!A:F,5,0) -> TERRESTRE | Z23: VISITA_TÉCNICA | AA23: 0 | AB23: 0 | AC23: 1 | AD23: =IF(AND(Z23="SOPORTE_TELEFÓNICO",OR(T23="SIN CONTACTO CON EL CB",T23="NÚMEROS DE CONTACTO ERRADOS")),0,IF(Z23="SOPORTE_TELEFÓNICO",'BASE DE LIQUIDACION 2025'!$B$9,IF(X23="TIPO I",'BASE DE LIQUIDACION 2025'!$C$3,IF(X23="TIPO II",'BASE DE LIQUIDACION 2025'!$C$4,IF(X23="TIPO III",'BASE DE LIQUIDACION 2025'!$C$5,'BASE DE LIQUIDACION 2025'!$C$6))))) -> 44559.564 | AE23: =IF(Z23="SOPORTE_TELEFÓNICO",AD23,CIERRES!AC23*CIERRES!AD23) -> 44559.564
A24: VILLAVICENCIO | B24: =VLOOKUP(A24,'CENTRO DE COSTOS'!A:D,4,FALSE) -> KEVIN ALEXIS CORZO BUSTOS | C24: =VLOOKUP(A24,'CENTRO DE COSTOS'!A:C,2,FALSE) -> 0004-0007 | D24: 50001 | E24: TA-25-716447 | F24: FO-25-1049165 | G24: 45813.674 | H24: 45815.49 | I24: META | J24: VILLAVICENCIO | K24: BARRIO PANORAMA VILLAVICENCIO | L24: 67216 | M24: ORDEN DE CAMBIO | N24: CIERRE | O24: CIERRE | P24: REDEBAN | Q24: CB UNO A UNO | R24: CB UNO A UNO | S24: NO_EXITOSO | T24: CB NO ENTREGA EQUIPO | U24: 07-06-2025 SE LLEGA AL COMERCIO SE VALIDA QUE EL CLIENTE NO ENTREGA EL EQUIPO YA QUE ESTA SOLICITANDO LA ACTIVACIÓN PORQUE HACE POCO REALIZO UN TRASLADO | V24: ROZO JIMENEZ EDGAR ARMANDO | W24: AAL06558 | X24: TIPO I | Y24: =VLOOKUP(D24,TIPOLOGIAS!A:F,5,0) -> TERRESTRE | Z24: VISITA_TÉCNICA | AA24: 0 | AB24: 0 | AC24: 1 | AD24: =IF(AND(Z24="SOPORTE_TELEFÓNICO",OR(T24="SIN CONTACTO CON EL CB",T24="NÚMEROS DE CONTACTO ERRADOS")),0,IF(Z24="SOPORTE_TELEFÓNICO",'BASE DE LIQUIDACION 2025'!$B$9,IF(X24="TIPO I",'BASE DE LIQUIDACION 2025'!$C$3,IF(X24="TIPO II",'BASE DE LIQUIDACION 2025'!$C$4,IF(X24="TIPO III",'BASE DE LIQUIDACION 2025'!$C$5,'BASE DE LIQUIDACION 2025'!$C$6))))) -> 44559.564 | AE24: =IF(Z24="SOPORTE_TELEFÓNICO",AD24,CIERRES!AC24*CIERRES!AD24) -> 44559.564
A25: BOGOTA | B25: =VLOOKUP(A25,'CENTRO DE COSTOS'!A:D,4,FALSE) -> WILLIAM ASDRUBAL ROZO ROZO | C25: =VLOOKUP(A25,'CENTRO DE COSTOS'!A:C,2,FALSE) -> 0004-0004 | D25: 11001 | E25: TA-25-719482 | F25: FO-25-1053457 | G25: 45814.458 | H25: 45815.548 | I25: CUNDINAMARCA | J25: BOGOTA | K25: PAGAFACIL BOSA | L25: 26555 | M25: ORDEN DE CAMBIO | N25: CIERRE | O25: RECUPERACION DE EQUIPOS | P25: REDEBAN | Q25: ROBUSTO | R25: PAGAFACIL | S25: NO_EXITOSO | T25: CB NO ENTREGA EQUIPO | U25: 07-06-2025 SE REALIZA VISITA A A CB PARA REALIZAR RETIRO DE EQUIPOS CLIENTE NO TIENE NINGÚN EQUIPO PARA RETIRAR INFORMA QUE TIENE SON UNOS CABLES PERO SE VALIDAN Y NO SON DE REDEBAN ,Y LOS DATAFONOS QUE TIENEN SON LOS QUE ACTUALMENTE ESTÁN UTILIZANDO | V25: GALINDO ROJAS LUIS FELIPE | W25: 0 | X25: TIPO I | Y25: =VLOOKUP(D25,TIPOLOGIAS!A:F,5,0) -> TERRESTRE | Z25: VISITA_TÉCNICA | AA25: 0 | AB25: 0 | AC25: 1 | AD25: =IF(AND(Z25="SOPORTE_TELEFÓNICO",OR(T25="SIN CONTACTO CON EL CB",T25="NÚMEROS DE CONTACTO ERRADOS")),0,IF(Z25="SOPORTE_TELEFÓNICO",'BASE DE LIQUIDACION 2025'!$B$9,IF(X25="TIPO I",'BASE DE LIQUIDACION 2025'!$C$3,IF(X25="TIPO II",'BASE DE LIQUIDACION 2025'!$C$4,IF(X25="TIPO III",'BASE DE LIQUIDACION 2025'!$C$5,'BASE DE LIQUIDACION 2025'!$C$6))))) -> 44559.564 | AE25: =IF(Z25="SOPORTE_TELEFÓNICO",AD25,CIERRES!AC25*CIERRES!AD25) -> 44559.564
A26: CUCUTA | B26: =VLOOKUP(A26,'CENTRO DE COSTOS'!A:D,4,FALSE) -> MIGUEL JULIÁN HERNÁNDEZ GUARÍN | C26: =VLOOKUP(A26,'CENTRO DE COSTOS'!A:C,2,FALSE) -> 0004-0008 | D26: 54518 | E26: TA-25-716452 | F26: FO-25-1049177 | G26: 45813.674 | H26: 45815.602 | I26: NORTE DE SANTANDER | J26: PAMPLONA | K26: BARRIO SIMON BOLIVAR PAMPLONA | L26: 29182 | M26: ORDEN DE CAMBIO | N26: CIERRE | O26: CIERRE | P26: REDEBAN | Q26: CB UNO A UNO | R26: CB UNO A UNO | S26: NO_EXITOSO | T26: CB NO ENTREGA EQUIPO | U26: 07-06-2025 SE REALIZA VISITA, ME INFORMAN QUE EL COMERCIO CAMBIO DE DUEÑO Y LOS EQUIPOS NO SE ENCUENTRAN EN EL LOCAL. SE INTENTA CONTACTAR TELEFÓNICAMENTE AL CLIENTE, PERO NO RESPONDE EL NÚMERO DE CONTACTO. 3124598287 | V26: PACHECO BUITRAGO JAVIER ALONSO | W26: 0 | X26: TIPO III | Y26: =VLOOKUP(D26,TIPOLOGIAS!A:F,5,0) -> TERRESTRE | Z26: VISITA_TÉCNICA | AA26: 0 | AB26: 0 | AC26: 1 | AD26: =IF(AND(Z26="SOPORTE_TELEFÓNICO",OR(T26="SIN CONTACTO CON EL CB",T26="NÚMEROS DE CONTACTO ERRADOS")),0,IF(Z26="SOPORTE_TELEFÓNICO",'BASE DE LIQUIDACION 2025'!$B$9,IF(X26="TIPO I",'BASE DE LIQUIDACION 2025'!$C$3,IF(X26="TIPO II",'BASE DE LIQUIDACION 2025'!$C$4,IF(X26="TIPO III",'BASE DE LIQUIDACION 2025'!$C$5,'BASE DE LIQUIDACION 2025'!$C$6))))) -> 222904.07 | AE26: =IF(Z26="SOPORTE_TELEFÓNICO",AD26,CIERRES!AC26*CIERRES!AD26) -> 222904.07
A27: BOGOTA | B27: =VLOOKUP(A27,'CENTRO DE COSTOS'!A:D,4,FALSE) -> WILLIAM ASDRUBAL ROZO ROZO | C27: =VLOOKUP(A27,'CENTRO DE COSTOS'!A:C,2,FALSE) -> 0004-0004 | D27: 11001 | E27: TA-25-719483 | F27: FO-25-1053459 | G27: 45814.458 | H27: 45815.603 | I27: CUNDINAMARCA | J27: BOGOTA | K27: MULTIPAGAS CHAPINERO | L27: 22814 | M27: ORDEN DE CAMBIO | N27: CIERRE | O27: RECUPERACION DE EQUIPOS | P27: REDEBAN | Q27: ROBUSTO | R27: MULTIPAGAS | S27: NO_EXITOSO | T27: CB NO ENTREGA EQUIPO | U27: 07-06-2025 COMERCIO NO PERMITE EL RETIRO DE LOS EQUIPOS QUE ESTÁN RELACIONADOS DENTRO DE LA TA EN SYTEX, INDICA QUE NO ESTÁN SOLICITANDO CIERRE SINO EL RETIRO DE EQUIPOS QUE TIENEN ALMACENADOS DESDE HACE MUCHO TIEMPO. SE CONSULTA CON EL COORDINADOR DE LA ZONA E INDICA QUE NO SE PUEDE REALIZAR EL CIERRE | V27: GARCIA PASTRANA KEVIN FERNANDO | W27: BBBBV322 | X27: TIPO I | Y27: =VLOOKUP(D27,TIPOLOGIAS!A:F,5,0) -> TERRESTRE | Z27: VISITA_TÉCNICA | AA27: 0 | AB27: 0 | AC27: 1 | AD27: =IF(AND(Z27="SOPORTE_TELEFÓNICO",OR(T27="SIN CONTACTO CON EL CB",T27="NÚMEROS DE CONTACTO ERRADOS")),0,IF(Z27="SOPORTE_TELEFÓNICO",'BASE DE LIQUIDACION 2025'!$B$9,IF(X27="TIPO I",'BASE DE LIQUIDACION 2025'!$C$3,IF(X27="TIPO II",'BASE DE LIQUIDACION 2025'!$C$4,IF(X27="TIPO III",'BASE DE LIQUIDACION 2025'!$C$5,'BASE DE LIQUIDACION 2025'!$C$6))))) -> 44559.564 | AE27: =IF(Z27="SOPORTE_TELEFÓNICO",AD27,CIERRES!AC27*CIERRES!AD27) -> 44559.564
A28: APARTADO | B28: =VLOOKUP(A28,'CENTRO DE COSTOS'!A:D,4,FALSE) -> JUAN SEBASTIÁN RÍOS CASTRILLÓN | C28: =VLOOKUP(A28,'CENTRO DE COSTOS'!A:C,2,FALSE) -> 0004-0005 | D28: 5490 | E28: TA-25-721683 | F28: FO-25-1061522 | G28: 45817.387 | H28: 45817.435 | I28: ANTIOQUIA | J28: NECOCLI | K28: PTM NECOCLI AUTOSERVICIO MAX D | L28: 51222 | M28: ORDEN DE CAMBIO | N28: CIERRE | O28: CIERRE | P28: REDEBAN | Q28: AGREGADOR | R28: COMCARD - PTM | S28: NO_EXITOSO | T28: CB NO ENTREGA EQUIPO | U28: 09-06-2025 PTM INDICA QUE EQUIPO YA FUERON ENTREGADOS A A REDEBAN BODEGA MEDELLÍN. | V28: DIAZ ZABALA FRANCIS DUBAN | W28: 0 | X28: TIPO II | Y28: =VLOOKUP(D28,TIPOLOGIAS!A:F,5,0) -> TERRESTRE | Z28: VISITA_TÉCNICA | AA28: 0 | AB28: 0 | AC28: 1 | AD28: =IF(AND(Z28="SOPORTE_TELEFÓNICO",OR(T28="SIN CONTACTO CON EL CB",T28="NÚMEROS DE CONTACTO ERRADOS")),0,IF(Z28="SOPORTE_TELEFÓNICO",'BASE DE LIQUIDACION 2025'!$B$9,IF(X28="TIPO I",'BASE DE LIQUIDACION 2025'!$C$3,IF(X28="TIPO II",'BASE DE LIQUIDACION 2025'!$C$4,IF(X28="TIPO III",'BASE DE LIQUIDACION 2025'!$C$5,'BASE DE LIQUIDACION 2025'!$C$6))))) -> 134410.88 | AE28: =IF(Z28="SOPORTE_TELEFÓNICO",AD28,CIERRES!AC28*CIERRES!AD28) -> 134410.88
A29: CALI | B29: =VLOOKUP(A29,'CENTRO DE COSTOS'!A:D,4,FALSE) -> DIEGO FERNANDO HENAO CARDONA | C29: =VLOOKUP(A29,'CENTRO DE COSTOS'!A:C,2,FALSE) -> 0004-0003 | D29: 76001 | E29: TA-25-720448 | F29: FO-25-1057186 | G29: 45814.519 | H29: 45817.465 | I29: VALLE DEL CAUCA | J29: CALI | K29: BARRIO VILLA DEL PRADO CALI 1 | L29: 62001 | M29: ORDEN DE CAMBIO | N29: CIERRE | O29: CIERRE | P29: REDEBAN | Q29: CB UNO A UNO | R29: CB UNO A UNO | S29: NO_EXITOSO | T29: CB NO ENTREGA EQUIPO | U29: 09-06-2025 CLIENTE ME COMUNICA QUE NO PUEDE ENTREGAR LOS EQUIPOS EL DÍA DE HOY SE LE COMUNICA QUE TIENE QUE VOLVER A SOLICITAR EL RETIRO DE LOS EQUIPOS | V29: HENAO CARDONA DIEGO FERNANDO | W29: 0 | X29: TIPO I | Y29: =VLOOKUP(D29,TIPOLOGIAS!A:F,5,0) -> TERRESTRE | Z29: SOPORTE_TELEFÓNICO | AA29: 0 | AB29: 0 | AC29: 0 | AD29: =IF(AND(Z29="SOPORTE_TELEFÓNICO",OR(T29="SIN CONTACTO CON EL CB",T29="NÚMEROS DE CONTACTO ERRADOS")),0,IF(Z29="SOPORTE_TELEFÓNICO",'BASE DE LIQUIDACION 2025'!$B$9,IF(X29="TIPO I",'BASE DE LIQUIDACION 2025'!$C$3,IF(X29="TIPO II",'BASE DE LIQUIDACION 2025'!$C$4,IF(X29="TIPO III",'BASE DE LIQUIDACION 2025'!$C$5,'BASE DE LIQUIDACION 2025'!$C$6))))) -> 37904.612 | AE29: =IF(Z29="SOPORTE_TELEFÓNICO",AD29,CIERRES!AC29*CIERRES!AD29) -> 37904.612
A30: MEDELLIN | B30: =VLOOKUP(A30,'CENTRO DE COSTOS'!A:D,4,FALSE) -> JUAN SEBASTIÁN RÍOS CASTRILLÓN | C30: =VLOOKUP(A30,'CENTRO DE COSTOS'!A:C,2,FALSE) -> 0004-0005 | D30: 5360 | E30: TA-25-719458 | F30: FO-25-1053386 | G30: 45814.458 | H30: 45817.54 | I30: ANTIOQUIA | J30: ITAGUI | K30: PTM ITAGUI D1 FARMA S A S | L30: 42723 | M30: ORDEN DE CAMBIO | N30: CIERRE | O30: CIERRE | P30: REDEBAN | Q30: AGREGADOR | R30: COMCARD - PTM | S30: NO_EXITOSO | T30: CB NO ENTREGA EQUIPO | U30: 09-06-2025 SE VISITA PUNTO Y ACTUALES DUEÑOS DE LOCAL INFORMAN QUE LOS EQUIPOS YA SE LOS LLEVARON A LA OFICINA DE PTM, NO FIRMAN POR QUE NO SON LA PERSONA QUE TENIA EL CB | V30: QUINTERO SANCHEZ JUAN SEBASTIAN | W30: GZ7ZZ115 | X30: TIPO I | Y30: =VLOOKUP(D30,TIPOLOGIAS!A:F,5,0) -> TERRESTRE | Z30: VISITA_TÉCNICA | AA30: 0 | AB30: 0 | AC30: 1 | AD30: =IF(AND(Z30="SOPORTE_TELEFÓNICO",OR(T30="SIN CONTACTO CON EL CB",T30="NÚMEROS DE CONTACTO ERRADOS")),0,IF(Z30="SOPORTE_TELEFÓNICO",'BASE DE LIQUIDACION 2025'!$B$9,IF(X30="TIPO I",'BASE DE LIQUIDACION 2025'!$C$3,IF(X30="TIPO II",'BASE DE LIQUIDACION 2025'!$C$4,IF(X30="TIPO III",'BASE DE LIQUIDACION 2025'!$C$5,'BASE DE LIQUIDACION 2025'!$C$6))))) -> 44559.564 | AE30: =IF(Z30="SOPORTE_TELEFÓNICO",AD30,CIERRES!AC30*CIERRES!AD30) -> 44559.564
A31: BARRANQUILLA | B31: =VLOOKUP(A31,'CENTRO DE COSTOS'!A:D,4,FALSE) -> JOSE MAURICIO HERNANDEZ ROJAS | C31: =VLOOKUP(A31,'CENTRO DE COSTOS'!A:C,2,FALSE) -> 0004-0001 | D31: 47205 | E31: TA-25-719471 | F31: FO-25-1053423 | G31: 45814.458 | H31: 45817.582 | I31: MAGDALENA | J31: CONCORDIA | K31: DISTRICOL FERRETERIA SAN ISIDR | L31: 35491 | M31: ORDEN DE CAMBIO | N31: CIERRE | O31: CIERRE | P31: REDEBAN | Q31: AGREGADOR | R31: DISTRICOL | S31: NO_EXITOSO | T31: CB NO ENTREGA EQUIPO | U31: 09-06-2025 SE REALIZA VISITA TÉCNICA, CLIENTE INDICA QUE ENVÍO LOS EQUIPOS A MEDELLÍN, PUBLICIDAD LE DIÓ DISPOSICIÓN FINAL. | V31: DE AGUAS MUÑOZ DAVID JOSE | W31: GZ000512 | X31: TIPO III | Y31: =VLOOKUP(D31,TIPOLOGIAS!A:F,5,0) -> TERRESTRE | Z31: VISITA_TÉCNICA | AA31: 0 | AB31: 0 | AC31: 1 | AD31: =IF(AND(Z31="SOPORTE_TELEFÓNICO",OR(T31="SIN CONTACTO CON EL CB",T31="NÚMEROS DE CONTACTO ERRADOS")),0,IF(Z31="SOPORTE_TELEFÓNICO",'BASE DE LIQUIDACION 2025'!$B$9,IF(X31="TIPO I",'BASE DE LIQUIDACION 2025'!$C$3,IF(X31="TIPO II",'BASE DE LIQUIDACION 2025'!$C$4,IF(X31="TIPO III",'BASE DE LIQUIDACION 2025'!$C$5,'BASE DE LIQUIDACION 2025'!$C$6))))) -> 222904.07 | AE31: =IF(Z31="SOPORTE_TELEFÓNICO",AD31,CIERRES!AC31*CIERRES!AD31) -> 222904.07
A32: MEDELLIN | B32: =VLOOKUP(A32,'CENTRO DE COSTOS'!A:D,4,FALSE) -> JUAN SEBASTIÁN RÍOS CASTRILLÓN | C32: =VLOOKUP(A32,'CENTRO DE COSTOS'!A:C,2,FALSE) -> 0004-0005 | D32: 5001 | E32: TA-25-719455 | F32: FO-25-1053377 | G32: 45814.458 | H32: 45817.625 | I32: ANTIOQUIA | J32: MEDELLIN | K32: PTM MED SU SALUD | L32: 39315 | M32: ORDEN DE CAMBIO | N32: CIERRE | O32: CIERRE | P32: REDEBAN | Q32: AGREGADOR | R32: COMCARD - PTM | S32: ILOCALIZADO | T32: CB CERRADO - DESOCUPADO | U32: 09-06-2025 SE LLEGA A DIRECCIÓN Y YA SE ENCUENTRA OTRO COMERCIO NO TIENEN IDEA DE LOS EQUIPOS, NO ES POSIBLE COMUNICACIÓN CON EL CLIENTE | V32: DIAZ ZABALA FRANCIS DUBAN | W32: 0 | X32: TIPO I | Y32: =VLOOKUP(D32,TIPOLOGIAS!A:F,5,0) -> TERRESTRE | Z32: VISITA_TÉCNICA | AA32: 0 | AB32: 0 | AC32: 1 | AD32: =IF(AND(Z32="SOPORTE_TELEFÓNICO",OR(T32="SIN CONTACTO CON EL CB",T32="NÚMEROS DE CONTACTO ERRADOS")),0,IF(Z32="SOPORTE_TELEFÓNICO",'BASE DE LIQUIDACION 2025'!$B$9,IF(X32="TIPO I",'BASE DE LIQUIDACION 2025'!$C$3,IF(X32="TIPO II",'BASE DE LIQUIDACION 2025'!$C$4,IF(X32="TIPO III",'BASE DE LIQUIDACION 2025'!$C$5,'BASE DE LIQUIDACION 2025'!$C$6))))) -> 44559.564 | AE32: =IF(Z32="SOPORTE_TELEFÓNICO",AD32,CIERRES!AC32*CIERRES!AD32) -> 44559.564
A33: MEDELLIN | B33: =VLOOKUP(A33,'CENTRO DE COSTOS'!A:D,4,FALSE) -> JUAN SEBASTIÁN RÍOS CASTRILLÓN | C33: =VLOOKUP(A33,'CENTRO DE COSTOS'!A:C,2,FALSE) -> 0004-0005 | D33: 5001 | E33: TA-25-719452 | F33: FO-25-1053374 | G33: 45814.458 | H33: 45817.698 | I33: ANTIOQUIA | J33: MEDELLIN | K33: COMCARD MED PIEDRANET 2 | L33: 32236 | M33: ORDEN DE CAMBIO | N33: CIERRE | O33: CIERRE | P33: REDEBAN | Q33: AGREGADOR | R33: COMCARD - PTM | S33: ILOCALIZADO | T33: CB CERRADO - DESOCUPADO | U33: 09-06-2025 SE LLEGA A LA DIRECCIÓN NO SE ENCUENTRA PUNTO ,SE REALIZA LLAMADA AL USUARIO Y NO CONTESTA | V33: CERPA SUAREZ DUVAN CAMILO | W33: 111DZ920 | X33: TIPO I | Y33: =VLOOKUP(D33,TIPOLOGIAS!A:F,5,0) -> TERRESTRE | Z33: VISITA_TÉCNICA | AA33: 0 | AB33: 0 | AC33: 1 | AD33: =IF(AND(Z33="SOPORTE_TELEFÓNICO",OR(T33="SIN CONTACTO CON EL CB",T33="NÚMEROS DE CONTACTO ERRADOS")),0,IF(Z33="SOPORTE_TELEFÓNICO",'BASE DE LIQUIDACION 2025'!$B$9,IF(X33="TIPO I",'BASE DE LIQUIDACION 2025'!$C$3,IF(X33="TIPO II",'BASE DE LIQUIDACION 2025'!$C$4,IF(X33="TIPO III",'BASE DE LIQUIDACION 2025'!$C$5,'BASE DE LIQUIDACION 2025'!$C$6))))) -> 44559.564 | AE33: =IF(Z33="SOPORTE_TELEFÓNICO",AD33,CIERRES!AC33*CIERRES!AD33) -> 44559.564
A34: BARRANQUILLA | B34: =VLOOKUP(A34,'CENTRO DE COSTOS'!A:D,4,FALSE) -> JOSE MAURICIO HERNANDEZ ROJAS | C34: =VLOOKUP(A34,'CENTRO DE COSTOS'!A:C,2,FALSE) -> 0004-0001 | D34: 8001 | E34: TA-25-716466 | F34: FO-25-1049203 | G34: 45813.674 | H34: 45818.284 | I34: ATLANTICO | J34: BARRANQUILLA | K34: BARRIO FERRY I BARRANQUILLA | L34: 23367 | M34: ORDEN DE CAMBIO | N34: CIERRE | O34: RECUPERACION DE EQUIPOS | P34: REDEBAN | Q34: CB UNO A UNO | R34: CB UNO A UNO | S34: NO_EXITOSO | T34: CB NO ENTREGA EQUIPO | U34: 10-06-2025 SE REALIZA VISITA AL COMERCIO PARA REALIZAR EL CIERRE DEL CORRESPONSAL BANCOLOMBIA PERO NO ES POSIBLE TRATO COMUNICACION CON EL NÚMERO DADO 3246098339 PERO NO CONTESTAN PREGUNTO Y ME DICEN QUE EL ENCARGADO ESTÁ DE VIAJE LE MANIFIESTO QUE CUANDO LLEGUE SE COMUNIQUE ALA LÍNEA DE SOPORTE PARA REAGENDAR VISITA | V34: PEÑALOZA GUTIERREZ RAFAEL GUSTAVO | W34: AA7ZZ984-11119862-ABC04331 | X34: TIPO I | Y34: =VLOOKUP(D34,TIPOLOGIAS!A:F,5,0) -> TERRESTRE | Z34: VISITA_TÉCNICA | AA34: 0 | AB34: 0 | AC34: 1 | AD34: =IF(AND(Z34="SOPORTE_TELEFÓNICO",OR(T34="SIN CONTACTO CON EL CB",T34="NÚMEROS DE CONTACTO ERRADOS")),0,IF(Z34="SOPORTE_TELEFÓNICO",'BASE DE LIQUIDACION 2025'!$B$9,IF(X34="TIPO I",'BASE DE LIQUIDACION 2025'!$C$3,IF(X34="TIPO II",'BASE DE LIQUIDACION 2025'!$C$4,IF(X34="TIPO III",'BASE DE LIQUIDACION 2025'!$C$5,'BASE DE LIQUIDACION 2025'!$C$6))))) -> 44559.564 | AE34: =IF(Z34="SOPORTE_TELEFÓNICO",AD34,CIERRES!AC34*CIERRES!AD34) -> 44559.564
A35: TUNJA | B35: =VLOOKUP(A35,'CENTRO DE COSTOS'!A:D,4,FALSE) -> MIGUEL JULIÁN HERNÁNDEZ GUARÍN | C35: =VLOOKUP(A35,'CENTRO DE COSTOS'!A:C,2,FALSE) -> 0004-0008 | D35: 15667 | E35: TA-25-722650 | F35: FO-25-1064604 | G35: 45817.565 | H35: 45818.461 | I35: BOYACA | J35: SAN LUIS DE GACENO | K35: CENTRO SAN LUIS DE GACENO BOYA | L35: 24216 | M35: ORDEN DE CAMBIO | N35: CIERRE | O35: CIERRE | P35: REDEBAN | Q35: CB UNO A UNO | R35: CB UNO A UNO | S35: NO_EXITOSO | T35: CB NO ENTREGA EQUIPO | U35: 10-06-2025 SE CIERRA ORDEN , CLIENTE INDICA POR GESTION TELEFÓNICA VIA WHATSAPP AL NÚMERO CELULAR 3106091366 QUE DESCONOCE LOS MOTIVOS POR EL CUAL LE CIERRAN EL PUNTO QUE SE VA A COMUNICAR CON LA ENTIDAD BANCARIA , SE LE RECUERDA LA LINEA NACIONAL 018000953344 DEL BANCO PARA QUE HAGA SU SOLICITUD. SE PROCEDE A CERRAR ORDEN | V35: ALVARADO MORENO CRISTHIAN | W35: 0 | X35: TIPO III | Y35: =VLOOKUP(D35,TIPOLOGIAS!A:F,5,0) -> TERRESTRE | Z35: VISITA_TÉCNICA | AA35: 0 | AC35: 1 | AD35: =IF(AND(Z35="SOPORTE_TELEFÓNICO",OR(T35="SIN CONTACTO CON EL CB",T35="NÚMEROS DE CONTACTO ERRADOS")),0,IF(Z35="SOPORTE_TELEFÓNICO",'BASE DE LIQUIDACION 2025'!$B$9,IF(X35="TIPO I",'BASE DE LIQUIDACION 2025'!$C$3,IF(X35="TIPO II",'BASE DE LIQUIDACION 2025'!$C$4,IF(X35="TIPO III",'BASE DE LIQUIDACION 2025'!$C$5,'BASE DE LIQUIDACION 2025'!$C$6))))) -> 222904.07 | AE35: =IF(Z35="SOPORTE_TELEFÓNICO",AD35,CIERRES!AC35*CIERRES!AD35) -> 222904.07
A36: PASTO | B36: =VLOOKUP(A36,'CENTRO DE COSTOS'!A:D,4,FALSE) -> DIEGO FERNANDO HENAO CARDONA | C36: =VLOOKUP(A36,'CENTRO DE COSTOS'!A:C,2,FALSE) -> 0004-0003 | D36: 52001 | E36: TA-25-722651 | F36: FO-25-1064609 | G36: 45817.565 | H36: 45818.656 | I36: NARIÑO | J36: PASTO | K36: BARRIO ALTAMIRA PASTO | L36: 75662 | M36: ORDEN DE CAMBIO | N36: CIERRE | O36: CIERRE | P36: REDEBAN | Q36: CB UNO A UNO | R36: CB UNO A UNO | S36: ILOCALIZADO | T36: CB CERRADO - DESOCUPADO | U36: 10-06-2025 SE LLEGÓ A DIRECCIÓN INDICADA PERO SE ENCUENTRA EL CORRESPONSAL CERRADO, SE INTENTO COMUNICACIÓN A LOS TELÉFONOS DE LA USUARIA, PERO NO CONTESTA LLAMADAS NI WHATSAPP. | V36: GUERRERO RAMIREZ OSCAR DARIO | W36: FA01Z642 | X36: TIPO I | Y36: =VLOOKUP(D36,TIPOLOGIAS!A:F,5,0) -> TERRESTRE | Z36: VISITA_TÉCNICA | AA36: 0 | AB36: 0 | AC36: 1 | AD36: =IF(AND(Z36="SOPORTE_TELEFÓNICO",OR(T36="SIN CONTACTO CON EL CB",T36="NÚMEROS DE CONTACTO ERRADOS")),0,IF(Z36="SOPORTE_TELEFÓNICO",'BASE DE LIQUIDACION 2025'!$B$9,IF(X36="TIPO I",'BASE DE LIQUIDACION 2025'!$C$3,IF(X36="TIPO II",'BASE DE LIQUIDACION 2025'!$C$4,IF(X36="TIPO III",'BASE DE LIQUIDACION 2025'!$C$5,'BASE DE LIQUIDACION 2025'!$C$6))))) -> 44559.564 | AE36: =IF(Z36="SOPORTE_TELEFÓNICO",AD36,CIERRES!AC36*CIERRES!AD36) -> 44559.564
A37: PASTO | B37: =VLOOKUP(A37,'CENTRO DE COSTOS'!A:D,4,FALSE) -> DIEGO FERNANDO HENAO CARDONA | C37: =VLOOKUP(A37,'CENTRO DE COSTOS'!A:C,2,FALSE) -> 0004-0003 | D37: 52356 | E37: TA-25-716449 | F37: FO-25-1049170 | G37: 45813.674 | H37: 45819.392 | I37: NARIÑO | J37: IPIALES | K37: BARRIO ESMERALDA IPIALES 1 | L37: 63875 | M37: ORDEN DE CAMBIO | N37: CIERRE | O37: CIERRE | P37: REDEBAN | Q37: CB UNO A UNO | R37: CB UNO A UNO | S37: NO_EXITOSO | T37: CB NO ENTREGA EQUIPO | U37: 11-06-2025 SE HABLA CON EL CLIENTE Y SE REALIZA VALIDACION DE CIERRE, PERO EL CLIENTE INDICA QUE AUN ESTA EN UN PROCESO CON LA ENTIDAD POR ELLO NO VA A ANTREGAR LOS EQUIPOS AUN PUES ESTA EN ESPERA DE UNA RESPUESTA DE LA ENTIDAD | V37: HENAO CARDONA DIEGO FERNANDO | W37: 0 | X37: TIPO II | Y37: =VLOOKUP(D37,TIPOLOGIAS!A:F,5,0) -> TERRESTRE | Z37: SOPORTE_TELEFÓNICO | AA37: 0 | AB37: 0 | AC37: 0 | AD37: =IF(AND(Z37="SOPORTE_TELEFÓNICO",OR(T37="SIN CONTACTO CON EL CB",T37="NÚMEROS DE CONTACTO ERRADOS")),0,IF(Z37="SOPORTE_TELEFÓNICO",'BASE DE LIQUIDACION 2025'!$B$9,IF(X37="TIPO I",'BASE DE LIQUIDACION 2025'!$C$3,IF(X37="TIPO II",'BASE DE LIQUIDACION 2025'!$C$4,IF(X37="TIPO III",'BASE DE LIQUIDACION 2025'!$C$5,'BASE DE LIQUIDACION 2025'!$C$6))))) -> 37904.612 | AE37: =IF(Z37="SOPORTE_TELEFÓNICO",AD37,CIERRES!AC37*CIERRES!AD37) -> 37904.612
A38: MANIZALES | B38: =VLOOKUP(A38,'CENTRO DE COSTOS'!A:D,4,FALSE) -> DIEGO FERNANDO HENAO CARDONA | C38: =VLOOKUP(A38,'CENTRO DE COSTOS'!A:C,2,FALSE) -> 0004-0002 | D38: 17777 | E38: TA-25-719465 | F38: FO-25-1053410 | G38: 45814.458 | H38: 45819.672 | I38: CALDAS | J38: SUPIA | K38: DISTRICOL NAF BOUTIQUE | L38: 44439 | M38: ORDEN DE CAMBIO | N38: CIERRE | O38: CIERRE | P38: REDEBAN | Q38: AGREGADOR | R38: DISTRICOL | S38: NO_EXITOSO | T38: CB NO ENTREGA EQUIPO | U38: 11-06-2025 SE HABLA TELEFONICAMENTE CON EL SEÑOR YEISON QUIEN FIGURA EN EL CONTACTO PERO EL INDICA QUE ESE NEGOCIO SE ACABO HACE MAS DE 2 AÑOS Y LOS EQUIPOS FUERON DEVUELTOS, QUE EL CORTO TODO CONTACTO CON LA ENTIDAD HACE MUCHO RATO, INDICA QUE EL NO DEBE FIGURAR EN NADA DE ESO PUES ESO NO EXISTE HACE YA MUCHO TIEMPO. | V38: HENAO CARDONA DIEGO FERNANDO | W38: 0 | X38: TIPO II | Y38: =VLOOKUP(D38,TIPOLOGIAS!A:F,5,0) -> TERRESTRE | Z38: SOPORTE_TELEFÓNICO | AA38: 0 | AB38: 0 | AC38: 0 | AD38: =IF(AND(Z38="SOPORTE_TELEFÓNICO",OR(T38="SIN CONTACTO CON EL CB",T38="NÚMEROS DE CONTACTO ERRADOS")),0,IF(Z38="SOPORTE_TELEFÓNICO",'BASE DE LIQUIDACION 2025'!$B$9,IF(X38="TIPO I",'BASE DE LIQUIDACION 2025'!$C$3,IF(X38="TIPO II",'BASE DE LIQUIDACION 2025'!$C$4,IF(X38="TIPO III",'BASE DE LIQUIDACION 2025'!$C$5,'BASE DE LIQUIDACION 2025'!$C$6))))) -> 37904.612 | AE38: =IF(Z38="SOPORTE_TELEFÓNICO",AD38,CIERRES!AC38*CIERRES!AD38) -> 37904.612
A39: SANTA MARTA | B39: =VLOOKUP(A39,'CENTRO DE COSTOS'!A:D,4,FALSE) -> JOSE MAURICIO HERNANDEZ ROJAS | C39: =VLOOKUP(A39,'CENTRO DE COSTOS'!A:C,2,FALSE) -> 0004-0001 | D39: 47001 | E39: TA-25-722824 | F39: FO-25-1065060 | G39: 45817.674 | H39: 45820.481 | I39: MAGDALENA | J39: SANTA MARTA | K39: DISTRICOL DROG Y VAR EBENEZER | L39: 70400 | M39: ORDEN DE CAMBIO | N39: CIERRE | O39: RECUPERACION DE EQUIPOS | P39: REDEBAN | Q39: AGREGADOR | R39: DISTRICOL | S39: NO_EXITOSO | T39: CB NO ENTREGA EQUIPO | U39: 12-06-2025 SE LLAMA AL NÚMERO INDICADO Y LA USUARIA MARLEN ROJAS INDICA QUE EL EQUIPO YA FUE ENTREGADO | V39: RUA ALVAREZ RICHARD ANDRES | W39: 0 | X39: TIPO I | Y39: =VLOOKUP(D39,TIPOLOGIAS!A:F,5,0) -> TERRESTRE | Z39: SOPORTE_TELEFÓNICO | AA39: 0 | AB39: 0 | AC39: 0 | AD39: =IF(AND(Z39="SOPORTE_TELEFÓNICO",OR(T39="SIN CONTACTO CON EL CB",T39="NÚMEROS DE CONTACTO ERRADOS")),0,IF(Z39="SOPORTE_TELEFÓNICO",'BASE DE LIQUIDACION 2025'!$B$9,IF(X39="TIPO I",'BASE DE LIQUIDACION 2025'!$C$3,IF(X39="TIPO II",'BASE DE LIQUIDACION 2025'!$C$4,IF(X39="TIPO III",'BASE DE LIQUIDACION 2025'!$C$5,'BASE DE LIQUIDACION 2025'!$C$6))))) -> 37904.612 | AE39: =IF(Z39="SOPORTE_TELEFÓNICO",AD39,CIERRES!AC39*CIERRES!AD39) -> 37904.612
A40: BOGOTA | B40: =VLOOKUP(A40,'CENTRO DE COSTOS'!A:D,4,FALSE) -> WILLIAM ASDRUBAL ROZO ROZO | C40: =VLOOKUP(A40,'CENTRO DE COSTOS'!A:C,2,FALSE) -> 0004-0004 | D40: 25386 | E40: TA-25-722660 | F40: FO-25-1069367 | G40: 45817.565 | H40: 45820.546 | I40: CUNDINAMARCA | J40: LA MESA | K40: BARRIO CENTRO LA MESA 7 | L40: 76271 | M40: ORDEN DE CAMBIO | N40: CIERRE | O40: RECUPERACION DE EQUIPOS | P40: REDEBAN | Q40: CB UNO A UNO | R40: CB UNO A UNO | S40: EJECUTADO_EXITOSO | T40: CIERRE EXITOSO | U40: 12-06-2025 DURANTE LA VISITA TECNICA SE REALIZA RETIRO DE DATAFONO, LECTOR DE CODIGO DE BARRAS POR CIERRE DE PUNTO PUBLICIDAD FUE RETIRADA Y DESTRUIDA POR COMERCIO INDICAN | V40: GALEANO SORIANO JUAN DAVID | W40: EG0OZ133 | X40: TIPO II | Y40: =VLOOKUP(D40,TIPOLOGIAS!A:F,5,0) -> TERRESTRE | Z40: VISITA_TÉCNICA | AA40: 1072112 | AB40: 775711 | AC40: 1 | AD40: =IF(AND(Z40="SOPORTE_TELEFÓNICO",OR(T40="SIN CONTACTO CON EL CB",T40="NÚMEROS DE CONTACTO ERRADOS")),0,IF(Z40="SOPORTE_TELEFÓNICO",'BASE DE LIQUIDACION 2025'!$B$9,IF(X40="TIPO I",'BASE DE LIQUIDACION 2025'!$C$3,IF(X40="TIPO II",'BASE DE LIQUIDACION 2025'!$C$4,IF(X40="TIPO III",'BASE DE LIQUIDACION 2025'!$C$5,'BASE DE LIQUIDACION 2025'!$C$6))))) -> 134410.88 | AE40: =IF(Z40="SOPORTE_TELEFÓNICO",AD40,CIERRES!AC40*CIERRES!AD40) -> 134410.88
...

Sheet TIPOLOGIAS
A1: COD. CIUDAD | B1: CIUDAD | C1: DEPARTAMENTO | D1: DESDE DONDE SE ATIENDE | E1: TIPO DE TRAYECTO NUEVO | F1: TIPOLOGIA NUEVA
A2: 91430 | B2: LA VICTORIA | C2: AMAZONAS | D2: BOGOTA | E2: AEREO | F2: TIPO IV ESPECIAL
A3: 91669 | B3: PUERTO SANTANDER | C3: AMAZONAS | D3: BOGOTA | E3: AEREO | F3: TIPO IV ESPECIAL
A4: 91263 | B4: EL ENCANTO | C4: AMAZONAS | D4: BOGOTA | E4: AEREO | F4: TIPO IV ESPECIAL
A5: 91405 | B5: LA CHORRERA | C5: AMAZONAS | D5: BOGOTA | E5: AEREO | F5: TIPO IV ESPECIAL
A6: 91407 | B6: LA PEDRERA | C6: AMAZONAS | D6: BOGOTA | E6: AEREO | F6: TIPO IV ESPECIAL
A7: 91001 | B7: LETICIA | C7: AMAZONAS | D7: BOGOTA | E7: AEREO | F7: TIPO IV ESPECIAL
A8: 91460 | B8: MIRITI - PARANA | C8: AMAZONAS | D8: BOGOTA | E8: AEREO | F8: TIPO IV ESPECIAL
A9: 91530 | B9: PUERTO ALEGRIA | C9: AMAZONAS | D9: BOGOTA | E9: AEREO | F9: TIPO IV ESPECIAL
A10: 91536 | B10: PUERTO ARICA | C10: AMAZONAS | D10: BOGOTA | E10: AEREO | F10: TIPO IV ESPECIAL
A11: 91540 | B11: PUERTO NARIÑO | C11: AMAZONAS | D11: BOGOTA | E11: AEREO | F11: TIPO IV ESPECIAL
A12: 91798 | B12: TARAPACA | C12: AMAZONAS | D12: BOGOTA | E12: AEREO | F12: TIPO IV ESPECIAL
A13: 5055 | B13: ARGELIA | C13: ANTIOQUIA | D13: MEDELLIN | E13: TERRESTRE | F13: TIPO IV
... A1124: 23682 | B1124: SAN JOSE DE URE | C1124: CORDOBA | D1124: MONTERIA | E1124: TERRESTRE | F1124: TIPO III

Sheet CENTRO DE COSTOS
A1: CIUDAD | B1: CENTRO_COSTO | C1: DESCRIPCION | D1: COORDINADOR
A2: APARTADO | B2: 0004-0005 | C2: Redeban Noroccidente (Medellín) | D2: JUAN SEBASTIÁN RÍOS CASTRILLÓN
A3: BARRANQUILLA | B3: 0004-0001 | C3: Redeban Costa (Barranqullla) | D3: JOSE MAURICIO HERNANDEZ ROJAS
A4: BOGOTA | B4: 0004-0004 | C4: Redeban Centro ( Bogotá) | D4: WILLIAM ASDRUBAL ROZO ROZO
A5: BUCARAMANGA | B5: 0004-0008 | C5: Redeban Santander | D5: MIGUEL JULIÁN HERNÁNDEZ GUARÍN
A6: CALI | B6: 0004-0003 | C6: Redeban Suroccidente (Cali) | D6: DIEGO FERNANDO HENAO CARDONA
A7: CARTAGENA | B7: 0004-0001 | C7: Redeban Costa (Barranqullla) | D7: JOSE MAURICIO HERNANDEZ ROJAS
A8: CUCUTA | B8: 0004-0008 | C8: Redeban Santander | D8: MIGUEL JULIÁN HERNÁNDEZ GUARÍN
A9: FLORENCIA | B9: 0004-0007 | C9: Redeban Oriente (Otros) | D9: KEVIN ALEXIS CORZO BUSTOS
A10: IBAGUE | B10: 0004-0007 | C10: Redeban Oriente (Otros) | D10: KEVIN ALEXIS CORZO BUSTOS
A11: MANIZALES | B11: 0004-0002 | C11: Redeban Eje Cafetero (Pereira) | D11: DIEGO FERNANDO HENAO CARDONA
A12: MEDELLIN | B12: 0004-0005 | C12: Redeban Noroccidente (Medellín) | D12: JUAN SEBASTIÁN RÍOS CASTRILLÓN
... A23: YOPAL | B23: 0004-0007 | C23: Redeban Oriente (Otros) | D23: KEVIN ALEXIS CORZO BUSTOS
