Workbook
Name A: #REF!
Name ACTIVIDAD: [1]Hoja2!$P$2:$P$30
Name Actividad: [2]Formulas!$H$2:$H$5000
Name arearesponsable: '[3]Listas desplegables'!$BB$2:$BB$100
Name Clientes: [4]Clientes!$A$2:$A$100
Name Clientes: [2]Clientes!$A$2:$A$100
Name COORDINADOR: [1]Hoja2!$D$2:$D$30
Name Coordinadores: [5]Coordinadores!$A$2:$A$1000
Name Coordinadores: [2]Coordinadores!$A$2:$A$1000
Name DOCUMENTADOR: [1]Hoja2!$A$2:$A$30
Name ES: [1]Hoja2!$K$2:$K$30
Name ESS: [1]Hoja2!$K$2:$K$30
Name Estado: [4]Formulas!$K$2:$K$5000
Name Estado: [2]Formulas!$K$2:$K$5000
Name ESTADOACTIVIDAD: [1]Hoja2!$M$2:$M$30
Name ESTADOS: '[6]Listas desplegables'!$B$1:$D$1
Name ESTADOSCIERRES: '[7]lista desplegable'!$CX$1:$DA$1
Name Facturacion: '[8]Listas desplegables'!$AO$1:$AR$1
Name FACTURACIÓN: '[6]Listas desplegables'!$Y$1:$AB$1
Name falla: #REF!
Name Fallas: '[9]Listas desplegables'!$F$2:$L$2
Name Grupo_Falla: '[10]Listas Desplegables'!$CH$2:$CH$5
Name inconservmanager: '[11]Listas desplegables'!$BC$2:$BC$100
Name INCUMPLIMIENTO: '[3]Listas desplegables'!$AK$1:$AN$1
Name LISTA: [12]Dptos!$A$1139:$A$1171
Name LISTA2: #REF!
Name LOLO: [13]Coordinadores!$A$2:$A$1000
Name solicitudes: '[8]Listas desplegables'!$U$1:$AF$1
Name solicitudes: '[14]Listas desplegables'!$AF$1:$AQ$1
Name Tecnicos: [4]Tecnicos!$A$2:$A$1000
Name Tecnicos: [2]Tecnicos!$A$2:$A$1000
Name Version: [2]Formulas!$I$2:$I$3

Sheet RESUMEN
A1: LÍNEA COMUNICACIONES S.A.S | F1: FACTURACIÓN CORRESPONSALES BANCARIOS TIQUIETES AEREOS
A2: FACTURACIÓN PROYECTO CB BANCOLOMBIA | F2: =A3 -> 45838
A3: 45838
F4: CONCEPTOS | G4: TRAYECTOS | H4: TOTAL | I4: % Administración | J4: TOTAL
A5: CONCEPTOS | B5: CANTIDAD | C5: VALOR UNITARIO | D5: VALOR TOTAL | F5: INCIDENTE 2242568 | G5: MEDELLIN- ISTMINA-MEDELLIN | H5: 850800 | I5: =H5*0.12 -> 102096 | J5: =H5+I5 -> 952896
A6: Adecuaciones CB | B6: =COUNTA(ADECUACIONES!A:A)-1 -> 45 | C6: 0 | D6: =ADECUACIONES!AM47 -> 7602999.8 | F6: INCIDENTE 2268184 | G6: MEDELLIN-QUIBDO-MEDELLIN | H6: 457600 | I6: =H6*0.12 -> 54912 | J6: =H6+I6 -> 512512
A7: Incidentes | B7: =COUNTA(INCIDENTES!A:A)-1 -> 185 | C7: 0 | D7: =INCIDENTES!AM187 -> 17712902 | I7: =H7*0.12 -> 0 | J7: =H7+I7 -> 0
A8: Ordenes de Cambio | B8: =COUNTA(OC!A:A)-1 -> 5 | C8: 0 | D8: =OC!AH7 -> 511514.45 | I8: =H8*0.12 -> 0 | J8: =H8+I8 -> 0
A9: Tiquetes | B9: 2 | C9: 0 | D9: =J12 -> 1465408 | I9: =H9*0.12 -> 0 | J9: =H9+I9 -> 0
A10: SUBTOTAL | D10: =SUM(D6:D9) -> 27292825 | I10: =H10*0.12 -> 0 | J10: =H10+I10 -> 0
A11: Iva | D11: =D10*0.19 -> 5185636.7 | I11: =H11*0.12 -> 0 | J11: =H11+I11 -> 0
A12: TOTAL | D12: =D10+D11 -> 32478461 | F12: TOTAL | H12: =SUM(H5:H11) -> 1308400 | I12: =SUM(I5:I11) -> 157008 | J12: =SUM(J5:J11) -> 1465408

Sheet BASE LIQUIDACION
A1: TARIFAS 2025 | E1: Incremento 2025
A2: Tipificación | B2: Descripción | C2: Dia actividad Exitosa | D2: Dia actividad Fallida | E2: 0.052
A3: Tipo I | B3: Metropolitano | C3: =62700.07*(1+$E$2) -> 65960.474 | D3: =42357.4*(1+$E$2) -> 44559.985
A4: Tipo II | B4: Hasta 3 horas | C4: =155716.31*(1+$E$2) -> 163813.56 | D4: =127766.53*(1+$E$2) -> 134410.39
A5: Tipo III | B5: De 3 a 5 horas | C5: =262099.22*(1+$E$2) -> 275728.38 | D5: =211886.19*(1+$E$2) -> 222904.27
A6: Tipo IV | B6: Más de 5 horas | C6: =455883.78*(1+$E$2) -> 479589.74 | D6: =441833.68*(1+$E$2) -> 464809.03
A7: Destino aereo | B7: No incluye valor del Tiquete | C7: =455883.78*(1+$E$2) -> 479589.74 | D7: =441833.68*(1+$E$2) -> 464809.03
A8: *Donde se requiera transporte aéreo o fluvial se factura adicional a tarifa TIPO IV el valor del tiquete + el 12% de admon.
A10: Gestión Telefónica | B10: =36031.04*(1+$E$2) -> 37904.654
A11: Mts Acometida electrica | B11: =30182.1*(1+$E$2) -> 31751.569
A12: Mts Acometida datos | B12: =15432.22*(1+$E$2) -> 16234.695
A13: switche | B13: =244669.03*(1+$E$2) -> 257391.82
A14: Router | B14: =291399.51*(1+$E$2) -> 306552.28
A15: Envio operador Logistico | B15: =53547.34*(1+$E$2) -> 56331.802

Sheet Tablas dinámicas
A2: ADECUACIONES | J2: NOMBRE CC | K2: Suma de VALOR | L2: Suma de VALOR2
A3: COORDINADOR | B3: CENTRO DE COSTOS LÍNEACOM | C3: % | D3: $ | E3: NOMBRE CC | F3: VALOR | J3: Redeban Centro ( Bogotá) | K3: 2202836.5 | L3: 0.085734376
A4: DIEGO FERNANDO HENAO CARDONA | B4: 0004-0002 | C4: 0.076073103 | D4: 568214.34 | E4: =VLOOKUP(B4,'CENTRO DE COSTOS'!B:C,2,0) -> Redeban Eje Cafetero (Pereira) | F4: =D4 -> 568214.34 | J4: Redeban Costa (Barranqullla) | K4: 1811081.3 | L4: 0.070487268
B5: 0004-0003 | C5: 0.2094254 | D5: 1564265.3 | E5: =VLOOKUP(B5,'CENTRO DE COSTOS'!B:C,2,0) -> Redeban Suroccidente (Cali) | F5: =D5 -> 1564265.3 | J5: Redeban Eje Cafetero (Pereira) | K5: 2058226.4 | L5: 0.080106152
A6: JOSE MAURICIO HERNANDEZ ROJAS | B6: 0004-0001 | C6: 0.01193147 | D6: 89119.97 | E6: =VLOOKUP(B6,'CENTRO DE COSTOS'!B:C,2,0) -> Redeban Costa (Barranqullla) | F6: =D6 -> 89119.97 | J6: Redeban Noroccidente (Medellín) | K6: 8916103.2 | L6: 0.34701466
A7: JUAN SEBASTIÁN RÍOS CASTRILLÓN | B7: 0004-0005 | C7: 0.1087279 | D7: 812123.5 | E7: =VLOOKUP(B7,'CENTRO DE COSTOS'!B:C,2,0) -> Redeban Noroccidente (Medellín) | F7: =D7 -> 812123.5 | J7: Redeban Oriente (Otros) | K7: 2740326.7 | L7: 0.10665349
A8: KEVIN ALEXIS CORZO BUSTOS | B8: 0004-0007 | C8: 0.12723136 | D8: 950331.69 | E8: =VLOOKUP(B8,'CENTRO DE COSTOS'!B:C,2,0) -> Redeban Oriente (Otros) | F8: =D8 -> 950331.69 | J8: Redeban Santander | K8: 4195509.5 | L8: 0.16328919
A9: MIGUEL JULIÁN HERNÁNDEZ GUARÍN | B9: 0004-0008 | C9: 0.35038225 | D9: 2617117.1 | E9: =VLOOKUP(B9,'CENTRO DE COSTOS'!B:C,2,0) -> Redeban Santander | F9: =D9 -> 2617117.1 | J9: Redeban Suroccidente (Cali) | K9: 3769653.2 | L9: 0.14671487
A10: WILLIAM ASDRUBAL ROZO ROZO | B10: 0004-0004 | C10: 0.11622852 | D10: 868147.99 | E10: =VLOOKUP(B10,'CENTRO DE COSTOS'!B:C,2,0) -> Redeban Centro ( Bogotá) | F10: =D10 -> 868147.99 | J10: Total general | K10: 25693737 | L10: 1
A11: Total general | C11: 1 | D11: 7469319.9
A15: INCIDENTES
A16: COORDINADOR | B16: CENTRO DE COSTOS LÍNEACOM | C16: % | D16: $ | E16: NOMBRE CC
A17: DIEGO FERNANDO HENAO CARDONA | B17: 0004-0002 | C17: 0.084120152 | D17: 1490012 | E17: =VLOOKUP(B17,'CENTRO DE COSTOS'!B:C,2,0) -> Redeban Eje Cafetero (Pereira) | F17: =D17 -> 1490012
B18: 0004-0003 | C18: 0.12078356 | D18: 2139427.4 | E18: =VLOOKUP(B18,'CENTRO DE COSTOS'!B:C,2,0) -> Redeban Suroccidente (Cali) | F18: =D18 -> 2139427.4
A19: JOSE MAURICIO HERNANDEZ ROJAS | B19: 0004-0001 | C19: 0.09507514 | D19: 1684056.7 | E19: =VLOOKUP(B19,'CENTRO DE COSTOS'!B:C,2,0) -> Redeban Costa (Barranqullla) | F19: =D19 -> 1684056.7
A20: JUAN SEBASTIÁN RÍOS CASTRILLÓN | B20: 0004-0005 | C20: 0.44195193 | D20: 7828251.3 | E20: =VLOOKUP(B20,'CENTRO DE COSTOS'!B:C,2,0) -> Redeban Noroccidente (Medellín) | F20: =D20 -> 7828251.3
A21: KEVIN ALEXIS CORZO BUSTOS | B21: 0004-0007 | C21: 0.101056 | D21: 1789995 | E21: =VLOOKUP(B21,'CENTRO DE COSTOS'!B:C,2,0) -> Redeban Oriente (Otros) | F21: =D21 -> 1789995
A22: MIGUEL JULIÁN HERNÁNDEZ GUARÍN | B22: 0004-0008 | C22: 0.089109756 | D22: 1578392.4 | E22: =VLOOKUP(B22,'CENTRO DE COSTOS'!B:C,2,0) -> Redeban Santander | F22: =D22 -> 1578392.4
A23: WILLIAM ASDRUBAL ROZO ROZO | B23: 0004-0004 | C23: 0.067903471 | D23: 1202767.6 | E23: =VLOOKUP(B23,'CENTRO DE COSTOS'!B:C,2,0) -> Redeban Centro ( Bogotá) | F23: =D23 -> 1202767.6
A24: Total general | C24: 1 | D24: 17712902
A29: OC
A30: COORDINADOR | B30: CENTRO DE COSTOS LÍNEACOM | C30: % | D30: $ | E30: NOMBRE CC
A31: DIEGO FERNANDO HENAO CARDONA | B31: 0004-0003 | C31: 0.12895134 | D31: 65960.474 | E31: =VLOOKUP(B31,'CENTRO DE COSTOS'!B:C,2,0) -> Redeban Suroccidente (Cali) | F31: =D31 -> 65960.474
A32: JOSE MAURICIO HERNANDEZ ROJAS | B32: 0004-0001 | C32: 0.074102801 | D32: 37904.654 | E32: =VLOOKUP(B32,'CENTRO DE COSTOS'!B:C,2,0) -> Redeban Costa (Barranqullla) | F32: =D32 -> 37904.654
A33: JUAN SEBASTIÁN RÍOS CASTRILLÓN | B33: 0004-0005 | C33: 0.53904318 | D33: 275728.38 | E33: =VLOOKUP(B33,'CENTRO DE COSTOS'!B:C,2,0) -> Redeban Noroccidente (Medellín) | F33: =D33 -> 275728.38
A34: WILLIAM ASDRUBAL ROZO ROZO | B34: 0004-0004 | C34: 0.25790268 | D34: 131920.95 | E34: =VLOOKUP(B34,'CENTRO DE COSTOS'!B:C,2,0) -> Redeban Centro ( Bogotá) | F34: =D34 -> 131920.95
A35: Total general | C35: 1 | D35: 511514.45 | E35: =VLOOKUP(B35,'CENTRO DE COSTOS'!B:C,2,0) -> #N/A | F35: =D35 -> 511514.45

Sheet ADECUACIONES
A1: CIUDAD | B1: COORDINADOR | C1: CENTRO DE COSTOS LÍNEACOM | D1: CÓDIGO DANE | E1: TA | F1: FO | G1: FECHA LISTA | H1: FECHA LIMITE | I1: FECHA SOLICITUD DE LA ACTIVIDAD | J1: FECHA INICIO DE LA ACTIVIDAD | K1: FECHA ULTIMA ACTUALIZACION | L1: DEPARTAMENTO | M1: CIUDAD | N1: NOMBRE PUNTO | O1: CÓDIGO PUNTO | P1: TIPO DE APERTURA | Q1: ACTIVIDAD | R1: RED | S1: FORMATO | T1: CADENA | U1: ESTADO | V1: OBSERVACIONES CLIENTE | W1: NOMBRE DEL TECNICO | X1: TERMINALES | Y1: PLACA DATAFONOS INSTALADOS | Z1: PLACA DATAFONOS RETIRADOS | AA1: PLACA LECTOR INSTALADO | AB1: PLACA LECTOR RETIRADO | AC1: CANTIDAD ROLLOS ENTREGADOS | AD1: TIPIFICACION | AE1: TIPO DE TRAYECTO | AF1: FORMA DE ATENCIÓN | AG1: ACOMETIDA DATOS (metros) | AH1: ACOMETIDA ELECTRICA (metros) | AI1: SWITCH | AJ1: ROUTER | AK1: VISITAS | AL1: VALOR DIAS ACTIVIDAD FACTURABLES | AM1: VALOR FACTURABLE A BANCOLMBIA TECNOLOGIA
A2: MEDELLIN | B2: =VLOOKUP(A2,'CENTRO DE COSTOS'!A:D,4,FALSE) -> JUAN SEBASTIÁN RÍOS CASTRILLÓN | C2: =VLOOKUP(A2,'CENTRO DE COSTOS'!A:C,2,FALSE) -> 0004-0005 | D2: 27361 | E2: TA-25-680473 | F2: FO-25-1006417 | G2: 45805 | H2: 45817 | I2: 45805 | J2: 45812 | K2: 45812 | L2: CHOCO | M2: ISTMINA | N2: BARRIO CUBIS SEC MESETA ALTA ISTMINA CHOCO ISTMINA | O2: 79563 | P2: CB CRECIMIENTO - NUEVO | Q2: APERTURA | R2: REDEBAN | S2: UNO A UNO | T2: UNO A UNO | U2: EJECUTADO | V2: 28-05 SE REALIZA LLAMADA AL CLIENTE, SE HABLA CON LA SRA JOAN AVENDAÑO DAZA SE VALIDA DIRECCIÓN OK, CANAL OK, DISPONIBILIDAD TOTAL, LLAMAR EL DÍA LA INSTALACIÓN PARA CONFIRMAR VISITA, AVISO EXTERIOR ALTURA APROX 2 METROS; TOMACORRIENTE CERCANO: SI; TIENE CABINA DE SEGURIDAD: SI 04-06 SE REALIZA INSTALACIÓN DE CORRESPONSAL, SE INSTALAN EQUIPOS CON PRUEBAS EXITOSAS, SE CAPACITA Y SE EVALÚA AL CLIENTE, SE INSTALA PUBLICIDAD COMPLETA, CB QUEDA OPERATIVO. USUARIO SOMOS BANCOLOMBIA ACTIVO. SE INSTALAN 10 MT DE CABLE UTP | W2: ROBLEDO DIAZ ANDRES FELIPE | X2: LMUZZ997 | Y2: 771855 | Z2: N/A | AA2: 1146028 | AB2: N/A | AC2: 40 ROLLOS | AD2: =VLOOKUP(D2,TIPOLOGIAS!A:F,6,0) -> TIPO IV ESPECIAL | AE2: =VLOOKUP(D2,TIPOLOGIAS!A:F,5,0) -> AEREO | AF2: VISITA _TECNICA | AG2: 10 | AH2: 0 | AI2: 0 | AJ2: 0 | AK2: 0 | AL2: =IF(AD2="TIPO I",'BASE LIQUIDACION'!$D$3,IF(AD2="TIPO II",'BASE LIQUIDACION'!$D$4,IF(AD2="TIPO III",'BASE LIQUIDACION'!$D$5,'BASE LIQUIDACION'!$D$7))) -> 464809.03 | AM2: =AG2*'BASE LIQUIDACION'!$B$12+AH2*'BASE LIQUIDACION'!$B$11+AI2*'BASE LIQUIDACION'!$B$13+AJ2*'BASE LIQUIDACION'!$B$14+AK2*AL2 -> 162346.95
A3: APARTADO | B3: =VLOOKUP(A3,'CENTRO DE COSTOS'!A:D,4,FALSE) -> JUAN SEBASTIÁN RÍOS CASTRILLÓN | C3: =VLOOKUP(A3,'CENTRO DE COSTOS'!A:C,2,FALSE) -> 0004-0005 | D3: 5837 | E3: TA-25-695256 | F3: FO-25-1029598 | G3: 45811 | H3: 45813 | I3: 45811 | J3: 45819 | K3: 45819 | L3: ANTIOQUIA | M3: TURBO | N3: BARRIO CGT NUEVA COLONIA TURBO ANTIOQUIA TURBO | O3: 79383 | P3: CB CRECIMIENTO - OTRAS LISTAS | Q3: APERTURA | R3: REDEBAN | S3: UNO A UNO | T3: UNO A UNO | U3: EJECUTADO | V3: 31-05 SE REALIZA LLAMADA AL CLIENTE, SE HABLA CON EL SR MAURICIO RIVERA ARIAS, SE VALIDA DIRECCIÓN OK, CANAL OK, DISPONIBILIDAD TOTAL, LLAMAR EL DÍA LA INSTALACIÓN PARA CONFIRMAR VISITA, AVISO EXTERIOR ALTURA APROX DONDE EL TECNICO LO VEA CONVENIENTE METROS; TOMACORRIENTE CERCANO: SI; TIENE CABINA DE SEGURIDAD:NO// MODEM SE ENCUEN TRA A 10 METROS DE DISTANCIA 05-06 SE REALIZA LLAMADA A USUARIO PARA CONFIRMAR LA INSTALACIÓN DEL CORRESPONSAL, USUARIO INFORMA DE NO PODER ATENDER POR NOVEDAD MEDICA DE LA ESPOSA, USUARIO PIDE POR FAVOR PROGRAMAR PARA LA PRÓXIMA SEMANA OK 11-06 SE REALIZA INSTALACIÓN DE CORRESPONSAL, SE INSTALAN EQUIPOS CON PRUEBAS EXITOSAS, SE CAPACITA Y SE EVALÚA AL CLIENTE, SE INSTALA PUBLICIDAD COMPLETA, CB QUEDA OPERATIVO. USUARIO SOMOS BANCOLOMBIA ACTIVO. SE INSTALAN 10 MT DE CABLE UTP | W3: JULIO TUBERQUIA JOSE SEBASTIAN | X3: 10XZZ921 | Y3: 1051048 | Z3: N/A | AA3: 545397 | AB3: N/A | AC3: 40 ROLLOS | AD3: =VLOOKUP(D3,TIPOLOGIAS!A:F,6,0) -> TIPO II | AE3: =VLOOKUP(D3,TIPOLOGIAS!A:F,5,0) -> TERRESTRE | AF3: VISITA _TECNICA | AG3: 10 | AH3: 0 | AI3: 0 | AJ3: 0 | AK3: 0 | AL3: =IF(AD3="TIPO I",'BASE LIQUIDACION'!$D$3,IF(AD3="TIPO II",'BASE LIQUIDACION'!$D$4,IF(AD3="TIPO III",'BASE LIQUIDACION'!$D$5,'BASE LIQUIDACION'!$D$7))) -> 134410.39 | AM3: =AG3*'BASE LIQUIDACION'!$B$12+AH3*'BASE LIQUIDACION'!$B$11+AI3*'BASE LIQUIDACION'!$B$13+AJ3*'BASE LIQUIDACION'!$B$14+AK3*AL3 -> 162346.95
A4: CALI | B4: =VLOOKUP(A4,'CENTRO DE COSTOS'!A:D,4,FALSE) -> DIEGO FERNANDO HENAO CARDONA | C4: =VLOOKUP(A4,'CENTRO DE COSTOS'!A:C,2,FALSE) -> 0004-0003 | D4: 76318 | E4: TA-25-721875 | F4: FO-25-1062664 | G4: 45817 | H4: 45819 | I4: 45817 | J4: 45818 | K4: 45818 | L4: VALLE DEL CAUCA | M4: GUACARI | N4: BARRIO EL FARO GUACARI GUACARI | O4: 79774 | P4: CB CRECIMIENTO - NUEVO | Q4: APERTURA | R4: REDEBAN | S4: UNO A UNO | T4: UNO A UNO | U4: EJECUTADO | V4: 9-06-2025 SE REALIZA LLAMADA AL CLIENTE, SE HABLA CON EL SR JORGE LUIS PEÑA CORTES SE VALIDA DIRECCIÓN OK, CANAL OK, DISPONIBILIDAD TOTAL, LLAMAR EL DÍA 10/6/2025 SE REALIZA INSTALACIÓN DE CORRESPONSAL, SE INSTALAN EQUIPOS CON PRUEBAS EXITOSAS, SE CAPACITA Y SE EVALÚA AL CLIENTE, SE INSTALA PUBLICIDAD COMPLETA, CB QUEDA OPERATIVO. USUARIO SOMOS BANCOLOMBIA ACTIVO. SE INSTALAN 17 MT DE CABLE UTP | W4: TORRES GARCIA JENDRY JOSE | X4: F1XZZ006 | Y4: 851866 | Z4: N/A | AA4: 932961 | AB4: N/A | AC4: 40 ROLLOS | AD4: =VLOOKUP(D4,TIPOLOGIAS!A:F,6,0) -> TIPO II | AE4: =VLOOKUP(D4,TIPOLOGIAS!A:F,5,0) -> TERRESTRE | AF4: VISITA _TECNICA | AG4: 17 | AH4: 0 | AI4: 0 | AJ4: 0 | AK4: 0 | AL4: =IF(AD4="TIPO I",'BASE LIQUIDACION'!$D$3,IF(AD4="TIPO II",'BASE LIQUIDACION'!$D$4,IF(AD4="TIPO III",'BASE LIQUIDACION'!$D$5,'BASE LIQUIDACION'!$D$7))) -> 134410.39 | AM4: =AG4*'BASE LIQUIDACION'!$B$12+AH4*'BASE LIQUIDACION'!$B$11+AI4*'BASE LIQUIDACION'!$B$13+AJ4*'BASE LIQUIDACION'!$B$14+AK4*AL4 -> 275989.82
A5: TUNJA | B5: =VLOOKUP(A5,'CENTRO DE COSTOS'!A:D,4,FALSE) -> MIGUEL JULIÁN HERNÁNDEZ GUARÍN | C5: =VLOOKUP(A5,'CENTRO DE COSTOS'!A:C,2,FALSE) -> 0004-0008 | D5: 15176 | E5: TA-25-721906 | F5: FO-25-1062920 | G5: 45817 | H5: 45819 | I5: 45817 | J5: 45818 | K5: 45818 | L5: BOYACA | M5: CHIQUINQUIRA | N5: BARRIO LA POLA CHIQUINQUIRA 2 | O5: 79763 | P5: CB CRECIMIENTO - NUEVO | Q5: APERTURA | R5: REDEBAN | S5: UNO A UNO | T5: UNO A UNO | U5: EJECUTADO | V5: 07-06 SE REALIZA LLAMADA AL CLIENTE, SE HABLA CON LA SRA KAROL MAITE GONZÁLEZ PORRAS SE VALIDA DIRECCIÓN OK, CANAL OK, DISPONIBILIDAD TOTAL, LLAMAR EL DÍA LA INSTALACIÓN PARA CONFIRMAR VISITA, AVISO EXTERIOR ALTURA APROX 2.70 METROS; TOMACORRIENTE CERCANO: SI; TIENE CABINA DE SEGURIDAD: SI - EL MODEM ESTA A 8 MT - COMUNICACIÓN POR WPP 10/6/2025 SE REALIZA INSTALACIÓN DE CORRESPONSAL, SE INSTALAN EQUIPOS CON PRUEBAS EXITOSAS, SE CAPACITA Y SE EVALÚA AL CLIENTE, SE INSTALA PUBLICIDAD COMPLETA, CB QUEDA OPERATIVO. USUARIO SOMOS BANCOLOMBIA ACTIVO. SE INSTALAN 15 MT DE CABLE UTP | W5: SOLER HOYOS CRISTIAN LEONARDO | X5: F1XZZ029 | Y5: 916662 | Z5: N/A | AA5: 1077082 | AB5: N/A | AC5: 40 ROLLOS | AD5: =VLOOKUP(D5,TIPOLOGIAS!A:F,6,0) -> TIPO III | AE5: =VLOOKUP(D5,TIPOLOGIAS!A:F,5,0) -> TERRESTRE | AF5: VISITA _TECNICA | AG5: 15 | AH5: 0 | AI5: 0 | AJ5: 0 | AK5: 0 | AL5: =IF(AD5="TIPO I",'BASE LIQUIDACION'!$D$3,IF(AD5="TIPO II",'BASE LIQUIDACION'!$D$4,IF(AD5="TIPO III",'BASE LIQUIDACION'!$D$5,'BASE LIQUIDACION'!$D$7))) -> 222904.27 | AM5: =AG5*'BASE LIQUIDACION'!$B$12+AH5*'BASE LIQUIDACION'!$B$11+AI5*'BASE LIQUIDACION'!$B$13+AJ5*'BASE LIQUIDACION'!$B$14+AK5*AL5 -> 243520.43
A6: CALI | B6: =VLOOKUP(A6,'CENTRO DE COSTOS'!A:D,4,FALSE) -> DIEGO FERNANDO HENAO CARDONA | C6: =VLOOKUP(A6,'CENTRO DE COSTOS'!A:C,2,FALSE) -> 0004-0003 | D6: 76233 | E6: TA-25-721931 | F6: FO-25-1062997 | G6: 45817 | H6: 45819 | I6: 45817 | J6: 45818 | K6: 45818 | L6: VALLE DEL CAUCA | M6: DAGUA | N6: BARRIO PRIMERO DE MAYO DAGUA DAGUA | O6: 79769 | P6: CB CRECIMIENTO - NUEVO | Q6: APERTURA | R6: REDEBAN | S6: UNO A UNO | T6: UNO A UNO | U6: EJECUTADO | V6: 9-06-2025 SE REALIZA LLAMADA AL CLIENTE, SE HABLA CON LA SRA KIMBERLY MARTINEZ TORRES SE VALIDA DIRECCIÓN OK, CANAL OK, DISPONIBILIDAD TOTAL, LLAMAR EL DÍA LA INSTALACIÓN PARA CONFIRMAR VISITA, AVISO EXTERIOR ALTURA APROX 1,70 METROS; TOMACORRIENTE CERCANO: SI; TIENE CABINA DE SEGURIDAD: SI // CONTACTO REALIZADO POR LA APP 10-06 SE REALIZA INSTALACIÓN DE CORRESPONSAL, SE INSTALAN EQUIPOS CON PRUEBAS EXITOSAS, SE CAPACITA Y SE EVALÚA AL CLIENTE, SE INSTALA PUBLICIDAD COMPLETA, CB QUEDA OPERATIVO. USUARIO SOMOS BANCOLOMBIA ACTIVO. SE INSTALAN 10 MT DE CABLE UTP | W6: BOLAÑOS TABORDA JORGE ENRIQUE | X6: F1XZZ043 | Y6: 994427 | Z6: N/A | AA6: 933109 | AB6: N/A | AC6: 40 ROLLOS | AD6: =VLOOKUP(D6,TIPOLOGIAS!A:F,6,0) -> TIPO II | AE6: =VLOOKUP(D6,TIPOLOGIAS!A:F,5,0) -> TERRESTRE | AF6: VISITA _TECNICA | AG6: 10 | AH6: 0 | AI6: 0 | AJ6: 0 | AK6: 0 | AL6: =IF(AD6="TIPO I",'BASE LIQUIDACION'!$D$3,IF(AD6="TIPO II",'BASE LIQUIDACION'!$D$4,IF(AD6="TIPO III",'BASE LIQUIDACION'!$D$5,'BASE LIQUIDACION'!$D$7))) -> 134410.39 | AM6: =AG6*'BASE LIQUIDACION'!$B$12+AH6*'BASE LIQUIDACION'!$B$11+AI6*'BASE LIQUIDACION'!$B$13+AJ6*'BASE LIQUIDACION'!$B$14+AK6*AL6 -> 162346.95
A7: BOGOTA | B7: =VLOOKUP(A7,'CENTRO DE COSTOS'!A:D,4,FALSE) -> WILLIAM ASDRUBAL ROZO ROZO | C7: =VLOOKUP(A7,'CENTRO DE COSTOS'!A:C,2,FALSE) -> 0004-0004 | D7: 11001 | E7: TA-25-721993 | F7: FO-25-1063185 | G7: 45817 | H7: 45819 | I7: 45817 | J7: 45819 | K7: 45819 | L7: CUNDINAMARCA | M7: BOGOTA | N7: BARRIO LAS MARGARITAS BOGOTA 4 | O7: 79749 | P7: CB CRECIMIENTO - NUEVO | Q7: APERTURA | R7: REDEBAN | S7: UNO A UNO | T7: UNO A UNO | U7: EJECUTADO | V7: 07-06 SE REALIZA LLAMADA AL CLIENTE, SE HABLA CON LA SR LEONARDO SORIANO GALEANO SE VALIDA DIRECCIÓN OK, CANAL OK, DISPONIBILIDAD TOTAL, LLAMAR EL DÍA LA INSTALACIÓN PARA CONFIRMAR VISITA, AVISO EXTERIOR ALTURA: NO INDICA ALTURA; TOMACORRIENTE CERCANO: SI; TIENE CABINA DE SEGURIDAD: NO - EL MODEM ESTA A 10 MT 11/6/2025 SE REALIZA INSTALACIÓN DE CORRESPONSAL, SE INSTALAN EQUIPOS CON PRUEBAS EXITOSAS, SE CAPACITA Y SE EVALÚA AL CLIENTE, SE INSTALA PUBLICIDAD COMPLETA, CB QUEDA OPERATIVO. USUARIO SOMOS BANCOLOMBIA ACTIVO. SE INSTALAN 18 MT DE CABLE UTP | W7: GOMEZ VEGA DAVID SNEYDER | X7: F1XZZ090 | Y7: 1235210 | Z7: N/A | AA7: 1238697-241587317561324755886660 | AB7: N/A | AC7: 40 ROLLOS | AD7: =VLOOKUP(D7,TIPOLOGIAS!A:F,6,0) -> TIPO I | AE7: =VLOOKUP(D7,TIPOLOGIAS!A:F,5,0) -> TERRESTRE | AF7: VISITA _TECNICA | AG7: 18 | AH7: 0 | AI7: 0 | AJ7: 0 | AK7: 0 | AL7: =IF(AD7="TIPO I",'BASE LIQUIDACION'!$D$3,IF(AD7="TIPO II",'BASE LIQUIDACION'!$D$4,IF(AD7="TIPO III",'BASE LIQUIDACION'!$D$5,'BASE LIQUIDACION'!$D$7))) -> 44559.985 | AM7: =AG7*'BASE LIQUIDACION'!$B$12+AH7*'BASE LIQUIDACION'!$B$11+AI7*'BASE LIQUIDACION'!$B$13+AJ7*'BASE LIQUIDACION'!$B$14+AK7*AL7 -> 292224.52
A8: BUCARAMANGA | B8: =VLOOKUP(A8,'CENTRO DE COSTOS'!A:D,4,FALSE) -> MIGUEL JULIÁN HERNÁNDEZ GUARÍN | C8: =VLOOKUP(A8,'CENTRO DE COSTOS'!A:C,2,FALSE) -> 0004-0008 | D8: 68001 | E8: TA-25-736405 | F8: FO-25-1073947 | G8: 45819 | H8: 45821 | I8: 45819 | J8: 45820 | K8: 45820 | L8: SANTANDER | M8: BUCARAMANGA | N8: BARRIO CENTRO BUCARAMANGA BUCARAMANGA | O8: 79843 | P8: CB CRECIMIENTO - NUEVO | Q8: APERTURA | R8: REDEBAN | S8: UNO A UNO | T8: UNO A UNO | U8: EJECUTADO | V8: 10-06 SE REALIZA LLAMADA AL CLIENTE, SE HABLA CON LA SR OMAR CARRILLO QUIÑONESSE VALIDA DIRECCIÓN OK, CANAL OK, DISPONIBILIDAD TOTAL, LLAMAR EL DÍA LA INSTALACIÓN PARA CONFIRMAR VISITA, AVISO EXTERIOR ALTURA APROX 2 METROS; TOMACORRIENTE CERCANO: SI; TIENE CABINA DE SEGURIDAD: NO - COMUNICACION POR WPP 12/6/2025SE REALIZA INSTALACIÓN DE CORRESPONSAL, SE INSTALAN EQUIPOS CON PRUEBAS EXITOSAS, SE CAPACITA Y SE EVALÚA AL CLIENTE, SE INSTALA PUBLICIDAD COMPLETA, CB QUEDA OPERATIVO. USUARIO SOMOS BANCOLOMBIA ACTIVO. SE INSTALAN 10 MT DE CABLE UTP | W8: GONZALEZ ESTUPIÑAN YEISON WALTER ANTONIO | X8: FAUZZ210 | Y8: 1120059 | Z8: N/A | AA8: 1071354 | AB8: N/A | AC8: 40 ROLLOS | AD8: =VLOOKUP(D8,TIPOLOGIAS!A:F,6,0) -> TIPO I | AE8: =VLOOKUP(D8,TIPOLOGIAS!A:F,5,0) -> TERRESTRE | AF8: VISITA _TECNICA | AG8: 10 | AH8: 0 | AI8: 0 | AJ8: 0 | AK8: 0 | AL8: =IF(AD8="TIPO I",'BASE LIQUIDACION'!$D$3,IF(AD8="TIPO II",'BASE LIQUIDACION'!$D$4,IF(AD8="TIPO III",'BASE LIQUIDACION'!$D$5,'BASE LIQUIDACION'!$D$7))) -> 44559.985 | AM8: =AG8*'BASE LIQUIDACION'!$B$12+AH8*'BASE LIQUIDACION'!$B$11+AI8*'BASE LIQUIDACION'!$B$13+AJ8*'BASE LIQUIDACION'!$B$14+AK8*AL8 -> 162346.95
A9: CALI | B9: =VLOOKUP(A9,'CENTRO DE COSTOS'!A:D,4,FALSE) -> DIEGO FERNANDO HENAO CARDONA | C9: =VLOOKUP(A9,'CENTRO DE COSTOS'!A:C,2,FALSE) -> 0004-0003 | D9: 76111 | E9: TA-25-736409 | F9: FO-25-1073958 | G9: 45819 | H9: 45821 | I9: 45819 | J9: 45820 | K9: 45820 | L9: VALLE DEL CAUCA | M9: GUADALAJARA DE BUGA | N9: BARRIO CENTRO GUADALAJARA DE BUGA GUADALAJARA DE BUGA | O9: 79848 | P9: CB CRECIMIENTO - NUEVO | Q9: APERTURA | R9: REDEBAN | S9: UNO A UNO | T9: UNO A UNO | U9: EJECUTADO | V9: 11-06 SE REALIZA LLAMADA AL CLIENTE, SE HABLA CON EL SR JAVIER MAURICIO PLAZA VARGAS, SE VALIDA DIRECCIÓN OK, CANAL OK, DISPONIBILIDAD TOTAL, LLAMAR EL DÍA LA INSTALACIÓN PARA CONFIRMAR VISITA, AVISO EXTERIOR ALTURA APROX 3 METROS; TOMACORRIENTE CERCANO: SI; TIENE CABINA DE SEGURIDAD: NO- MODEM A 4 METROS 12-06 SE REALIZA INSTALACIÓN DE CORRESPONSAL, SE INSTALAN EQUIPOS CON PRUEBAS EXITOSAS, SE CAPACITA Y SE EVALÚA AL CLIENTE, SE INSTALA PUBLICIDAD COMPLETA, CB QUEDA OPERATIVO. USUARIO SOMOS BANCOLOMBIA ACTIVO. SE INSTALAN 20 MT DE CABLE UTP | W9: MONTERO MUESES GIAN CARLO | X9: FAUZZ213 | Y9: 1242553 | Z9: N/A | AA9: 940518-241597317561324755900749 | AB9: N/A | AC9: 40 ROLLOS | AD9: =VLOOKUP(D9,TIPOLOGIAS!A:F,6,0) -> TIPO II | AE9: =VLOOKUP(D9,TIPOLOGIAS!A:F,5,0) -> TERRESTRE | AF9: VISITA _TECNICA | AG9: 20 | AH9: 0 | AI9: 0 | AJ9: 0 | AK9: 0 | AL9: =IF(AD9="TIPO I",'BASE LIQUIDACION'!$D$3,IF(AD9="TIPO II",'BASE LIQUIDACION'!$D$4,IF(AD9="TIPO III",'BASE LIQUIDACION'!$D$5,'BASE LIQUIDACION'!$D$7))) -> 134410.39 | AM9: =AG9*'BASE LIQUIDACION'!$B$12+AH9*'BASE LIQUIDACION'!$B$11+AI9*'BASE LIQUIDACION'!$B$13+AJ9*'BASE LIQUIDACION'!$B$14+AK9*AL9 -> 324693.91
A10: BUCARAMANGA | B10: =VLOOKUP(A10,'CENTRO DE COSTOS'!A:D,4,FALSE) -> MIGUEL JULIÁN HERNÁNDEZ GUARÍN | C10: =VLOOKUP(A10,'CENTRO DE COSTOS'!A:C,2,FALSE) -> 0004-0008 | D10: 68307 | E10: TA-25-755918 | F10: FO-25-1085436 | G10: 45821 | H10: 45825 | I10: 45821 | J10: 45824 | K10: 45824 | L10: SANTANDER | M10: GIRON | N10: BARRIO VEREDA CHOCOITA SECTOR TRES ESQUINAS GIRON | O10: 79867 | P10: CB CRECIMIENTO - NUEVO | Q10: APERTURA | R10: REDEBAN | S10: UNO A UNO | T10: UNO A UNO | U10: EJECUTADO | V10: 13-06 SE REALIZA LLAMADA AL CLIENTE, SE HABLA CON LA SR LIBARDO GOMEZ GOMEZ SE VALIDA DIRECCIÓN OK, CANAL OK, DISPONIBILIDAD TOTAL, LLAMAR EL DÍA LA INSTALACIÓN PARA CONFIRMAR VISITA, AVISO EXTERIOR ALTURA APROX 3 METROS; TOMACORRIENTE CERCANO: SI; TIENE CABINA DE SEGURIDAD: NO - COMUNICACIÓN POR WPP - EL MODEM ESTA A 5 MT // SE DEBEN COMUNICAR POR WPP YA QUE LA SEÑAL ES MALA 16/6/2025 SE REALIZA INSTALACIÓN DE CORRESPONSAL, SE INSTALAN EQUIPOS CON PRUEBAS EXITOSAS, SE CAPACITA Y SE EVALÚA AL CLIENTE, SE INSTALA PUBLICIDAD COMPLETA, CB QUEDA OPERATIVO. USUARIO SOMOS BANCOLOMBIA ACTIVO. SE INSTALAN 12 MT DE CABLE UTP | W10: SANTOS GONZALEZ JOHAN FABIAN | X10: FAWZZ662 | Y10: 914673 | Z10: N/A | AA10: 905863 | AB10: N/A | AC10: 40 ROLLOS | AD10: =VLOOKUP(D10,TIPOLOGIAS!A:F,6,0) -> TIPO I | AE10: =VLOOKUP(D10,TIPOLOGIAS!A:F,5,0) -> TERRESTRE | AF10: VISITA _TECNICA | AG10: 12 | AH10: 0 | AI10: 0 | AJ10: 0 | AK10: 0 | AL10: =IF(AD10="TIPO I",'BASE LIQUIDACION'!$D$3,IF(AD10="TIPO II",'BASE LIQUIDACION'!$D$4,IF(AD10="TIPO III",'BASE LIQUIDACION'!$D$5,'BASE LIQUIDACION'!$D$7))) -> 44559.985 | AM10: =AG10*'BASE LIQUIDACION'!$B$12+AH10*'BASE LIQUIDACION'!$B$11+AI10*'BASE LIQUIDACION'!$B$13+AJ10*'BASE LIQUIDACION'!$B$14+AK10*AL10 -> 194816.35
A11: PEREIRA | B11: =VLOOKUP(A11,'CENTRO DE COSTOS'!A:D,4,FALSE) -> DIEGO FERNANDO HENAO CARDONA | C11: =VLOOKUP(A11,'CENTRO DE COSTOS'!A:C,2,FALSE) -> 0004-0002 | D11: 66001 | E11: TA-25-790519 | F11: FO-25-1106940 | G11: 45826 | H11: 45828 | I11: 45826 | J11: 45828 | K11: 45828 | L11: RISARALDA | M11: PEREIRA | N11: BARRIO BETULIA BAJA PEREIRA | O11: 79947 | P11: CB CRECIMIENTO - NUEVO | Q11: APERTURA | R11: REDEBAN | S11: UNO A UNO | T11: UNO A UNO | U11: EJECUTADO | V11: 17-06 SE REALIZA LLAMADA AL CLIENTE, SE HABLA CON LA SRA NATHALI RIVERA MARTINEZ SE VALIDA DIRECCIÓN OK, CANAL OK, DISPONIBILIDAD TOTAL, LLAMAR EL DÍA LA INSTALACIÓN PARA CONFIRMAR VISITA, AVISO EXTERIOR ALTURA APROX 2 METROS; TOMACORRIENTE CERCANO: SI; TIENE CABINA DE SEGURIDAD: SI // CONTACTO REALIZADO POR LA APP 20/6/2025 SE REALIZA INSTALACIÓN DE CORRESPONSAL, SE INSTALAN EQUIPOS CON PRUEBAS EXITOSAS, SE CAPACITA Y SE EVALÚA AL CLIENTE, SE INSTALA PUBLICIDAD COMPLETA, CB QUEDA OPERATIVO. USUARIO SOMOS BANCOLOMBIA ACTIVO. SE INSTALAN 10 MT DE CABLE UTP | W11: ARROYAVE CANO MANUEL GUILLERMO | X11: SAVZZ109 | Y11: 1235257 | Z11: N/A | AA11: 1071586-241597317561324755899579 | AB11: N/A | AC11: 40 ROLLOS | AD11: =VLOOKUP(D11,TIPOLOGIAS!A:F,6,0) -> TIPO I | AE11: =VLOOKUP(D11,TIPOLOGIAS!A:F,5,0) -> TERRESTRE | AF11: VISITA _TECNICA | AG11: 10 | AH11: 0 | AI11: 0 | AJ11: 0 | AK11: 0 | AL11: =IF(AD11="TIPO I",'BASE LIQUIDACION'!$D$3,IF(AD11="TIPO II",'BASE LIQUIDACION'!$D$4,IF(AD11="TIPO III",'BASE LIQUIDACION'!$D$5,'BASE LIQUIDACION'!$D$7))) -> 44559.985 | AM11: =AG11*'BASE LIQUIDACION'!$B$12+AH11*'BASE LIQUIDACION'!$B$11+AI11*'BASE LIQUIDACION'!$B$13+AJ11*'BASE LIQUIDACION'!$B$14+AK11*AL11 -> 162346.95
A12: BUCARAMANGA | B12: =VLOOKUP(A12,'CENTRO DE COSTOS'!A:D,4,FALSE) -> MIGUEL JULIÁN HERNÁNDEZ GUARÍN | C12: =VLOOKUP(A12,'CENTRO DE COSTOS'!A:C,2,FALSE) -> 0004-0008 | D12: 68001 | E12: TA-25-790557 | F12: FO-25-1107050 | G12: 45826 | H12: 45828 | I12: 45826 | J12: 45827 | K12: 45827 | L12: SANTANDER | M12: BUCARAMANGA | N12: BARRIO LAS MERCEDES BUCARAMANGA | O12: 79935 | P12: CB CRECIMIENTO - NUEVO | Q12: APERTURA | R12: REDEBAN | S12: UNO A UNO | T12: UNO A UNO | U12: EJECUTADO | V12: 17-06 SE REALIZA LLAMADA AL CLIENTE, SE HABLA CON LA SRA FRANCEDID ESTEPA SE VALIDA DIRECCIÓN OK, CANAL OK, DISPONIBILIDAD TOTAL, LLAMAR EL DÍA LA INSTALACIÓN PARA CONFIRMAR VISITA, AVISO EXTERIOR ALTURA APROX 3 METROS; TOMACORRIENTE CERCANO: SI; TIENE CABINA DE SEGURIDAD: SI - COMUNICACIÓN POR WPP 19/6/2025 SE REALIZA INSTALACIÓN DE CORRESPONSAL, SE INSTALAN EQUIPOS CON PRUEBAS EXITOSAS, SE CAPACITA Y SE EVALÚA AL CLIENTE, SE INSTALA PUBLICIDAD COMPLETA, CB QUEDA OPERATIVO. USUARIO SOMOS BANCOLOMBIA ACTIVO. SE INSTALAN 10 MT DE CABLE UTP | W12: SANTOS GONZALEZ JOHAN FABIAN | X12: SAVZZ135 | Y12: 1074974 | Z12: N/A | AA12: 1060202 | AB12: N/A | AC12: 40 ROLLOS | AD12: =VLOOKUP(D12,TIPOLOGIAS!A:F,6,0) -> TIPO I | AE12: =VLOOKUP(D12,TIPOLOGIAS!A:F,5,0) -> TERRESTRE | AF12: VISITA _TECNICA | AG12: 10 | AH12: 0 | AI12: 0 | AJ12: 0 | AK12: 0 | AL12: =IF(AD12="TIPO I",'BASE LIQUIDACION'!$D$3,IF(AD12="TIPO II",'BASE LIQUIDACION'!$D$4,IF(AD12="TIPO III",'BASE LIQUIDACION'!$D$5,'BASE LIQUIDACION'!$D$7))) -> 44559.985 | AM12: =AG12*'BASE LIQUIDACION'!$B$12+AH12*'BASE LIQUIDACION'!$B$11+AI12*'BASE LIQUIDACION'!$B$13+AJ12*'BASE LIQUIDACION'!$B$14+AK12*AL12 -> 162346.95
A13: BOGOTA | B13: =VLOOKUP(A13,'CENTRO DE COSTOS'!A:D,4,FALSE) -> WILLIAM ASDRUBAL ROZO ROZO | C13: =VLOOKUP(A13,'CENTRO DE COSTOS'!A:C,2,FALSE) -> 0004-0004 | D13: 25473 | E13: TA-25-790574 | F13: FO-25-1107071 | G13: 45826 | H13: 45828 | I13: 45826 | J13: 45828 | K13: 45828 | L13: CUNDINAMARCA | M13: MOSQUERA | N13: BARRIO EL POBLADO MOSQUERA 5 | O13: 79945 | P13: CB CRECIMIENTO - NUEVO | Q13: APERTURA | R13: REDEBAN | S13: UNO A UNO | T13: UNO A UNO | U13: EJECUTADO | V13: 18-06 SE REALIZA LLAMADA AL CLIENTE, SE HABLA CON LA SRA NORMA KRISTYNNA MONTEALEGRE QUINTANA SE VALIDA DIRECCIÓN OK, CANAL OK, DISPONIBILIDAD TOTAL, LLAMAR EL DÍA LA INSTALACIÓN PARA CONFIRMAR VISITA, AVISO EXTERIOR ALTURA APROX 2 METROS; TOMACORRIENTE CERCANO: SI; TIENE CABINA DE SEGURIDAD: NO - COMUNICACION POR WPP - EL MODEM ESTA A 8 MT 20/6/2025 SE REALIZA INSTALACIÓN DE CORRESPONSAL, SE INSTALAN EQUIPOS CON PRUEBAS EXITOSAS, SE CAPACITA Y SE EVALÚA AL CLIENTE, SE INSTALA PUBLICIDAD COMPLETA, CB QUEDA OPERATIVO. USUARIO SOMOS BANCOLOMBIA ACTIVO. SE INSTALAN 13 MT DE CABLE UTP | W13: VEGA MANRIQUE JONATAN MAURICIO | X13: SAVZZ140 | Y13: 1235389 | Z13: N/A | AA13: 1238706-243637317561365457309488 | AB13: N/A | AC13: 40 ROLLOS | AD13: =VLOOKUP(D13,TIPOLOGIAS!A:F,6,0) -> TIPO I | AE13: =VLOOKUP(D13,TIPOLOGIAS!A:F,5,0) -> TERRESTRE | AF13: VISITA _TECNICA | AG13: 13 | AH13: 0 | AI13: 0 | AJ13: 0 | AK13: 0 | AL13: =IF(AD13="TIPO I",'BASE LIQUIDACION'!$D$3,IF(AD13="TIPO II",'BASE LIQUIDACION'!$D$4,IF(AD13="TIPO III",'BASE LIQUIDACION'!$D$5,'BASE LIQUIDACION'!$D$7))) -> 44559.985 | AM13: =AG13*'BASE LIQUIDACION'!$B$12+AH13*'BASE LIQUIDACION'!$B$11+AI13*'BASE LIQUIDACION'!$B$13+AJ13*'BASE LIQUIDACION'!$B$14+AK13*AL13 -> 211051.04
A14: BUCARAMANGA | B14: =VLOOKUP(A14,'CENTRO DE COSTOS'!A:D,4,FALSE) -> MIGUEL JULIÁN HERNÁNDEZ GUARÍN | C14: =VLOOKUP(A14,'CENTRO DE COSTOS'!A:C,2,FALSE) -> 0004-0008 | D14: 68500 | E14: TA-25-799030 | F14: FO-25-1128521 | G14: 45832 | H14: 45834 | I14: 45832 | J14: 45833 | K14: 45833 | L14: SANTANDER | M14: OIBA | N14: BARRIO POIMA OIBA OIBA | O14: 80035 | P14: CB CRECIMIENTO - NUEVO | Q14: APERTURA | R14: REDEBAN | S14: UNO A UNO | T14: UNO A UNO | U14: EJECUTADO | V14: 21-06 SE REALIZA LLAMADA AL CLIENTE, SE HABLA CON LA SRA SANDRA MILENA PABON SILVA, SE VALIDA DIRECCIÓN OK, CANAL OK, DISPONIBILIDAD TOTAL, LLAMAR EL DÍA LA INSTALACIÓN PARA CONFIRMAR VISITA, AVISO EXTERIOR ALTURA APROX 1,50 METROS; TOMACORRIENTE CERCANO: SI; TIENE CABINA DE SEGURIDAD: NO// TOMACORRIENTE A 6 METROS 25/6/2025 SE REALIZA INSTALACIÓN DE CORRESPONSAL, SE INSTALAN EQUIPOS CON PRUEBAS EXITOSAS, SE CAPACITA Y SE EVALÚA AL CLIENTE, SE INSTALA PUBLICIDAD COMPLETA, CB QUEDA OPERATIVO. USUARIO SOMOS BANCOLOMBIA ACTIVO. SE INSTALAN 10 MT DE CABLE UTP | W14: GELVEZ MOGOLLON JOSE ELISEO | X14: SAXZZ451 | Y14: 1052001 | Z14: N/A | AA14: 1103658 | AB14: N/A | AC14: 40 ROLLOS | AD14: =VLOOKUP(D14,TIPOLOGIAS!A:F,6,0) -> TIPO III | AE14: =VLOOKUP(D14,TIPOLOGIAS!A:F,5,0) -> TERRESTRE | AF14: VISITA _TECNICA | AG14: 10 | AH14: 0 | AI14: 0 | AJ14: 0 | AK14: 0 | AL14: =IF(AD14="TIPO I",'BASE LIQUIDACION'!$D$3,IF(AD14="TIPO II",'BASE LIQUIDACION'!$D$4,IF(AD14="TIPO III",'BASE LIQUIDACION'!$D$5,'BASE LIQUIDACION'!$D$7))) -> 222904.27 | AM14: =AG14*'BASE LIQUIDACION'!$B$12+AH14*'BASE LIQUIDACION'!$B$11+AI14*'BASE LIQUIDACION'!$B$13+AJ14*'BASE LIQUIDACION'!$B$14+AK14*AL14 -> 162346.95
A15: BUCARAMANGA | B15: =VLOOKUP(A15,'CENTRO DE COSTOS'!A:D,4,FALSE) -> MIGUEL JULIÁN HERNÁNDEZ GUARÍN | C15: =VLOOKUP(A15,'CENTRO DE COSTOS'!A:C,2,FALSE) -> 0004-0008 | D15: 68615 | E15: TA-25-799038 | F15: FO-25-1128558 | G15: 45832 | H15: 45834 | I15: 45832 | J15: 45833 | K15: 45833 | L15: SANTANDER | M15: RIONEGRO | N15: BARRIO CENTRO RIONEGRO 3 | O15: 80055 | P15: CB CRECIMIENTO - NUEVO | Q15: APERTURA | R15: REDEBAN | S15: UNO A UNO | T15: UNO A UNO | U15: EJECUTADO | V15: 24-06-2025 SE REALIZA LLAMADA AL CLIENTE, SE HABLA CON LA SRA LIZY ANDREA JAIMES OLAVE SE VALIDA DIRECCIÓN OK, CANAL OK, DISPONIBILIDAD TOTAL, LLAMAR EL DÍA LA INSTALACIÓN PARA CONFIRMAR VISITA, AVISO EXTERIOR ALTURA APROX CLIENTE NO TIENE CONOCIMIENTO DE MEDIDAS; TOMACORRIENTE CERCANO: SI; TIENE CABINA DE SEGURIDAD: SI // CONTACTO REALIZADO POR LA APP // CLIENTE INDICA QUE SI NO CONTESTA POR LLAMADA, S ECOMUNIQUEN POR WHATSAPP QUE ES MAS FIJO 25/6/2025 SE REALIZA INSTALACIÓN DE CORRESPONSAL, SE INSTALAN EQUIPOS CON PRUEBAS EXITOSAS, SE CAPACITA Y SE EVALÚA AL CLIENTE, SE INSTALA PUBLICIDAD COMPLETA, CB QUEDA OPERATIVO. USUARIO SOMOS BANCOLOMBIA ACTIVO. SE INSTALAN 10 MT DE CABLE UTP | W15: SANTOS GONZALEZ JOHAN FABIAN | X15: SAXZZ458 | Y15: 1240742 | Z15: N/A | AA15: 879503 | AB15: N/A | AC15: 40 ROLLOS | AD15: =VLOOKUP(D15,TIPOLOGIAS!A:F,6,0) -> TIPO II | AE15: =VLOOKUP(D15,TIPOLOGIAS!A:F,5,0) -> TERRESTRE | AF15: VISITA _TECNICA | AG15: 10 | AH15: 0 | AI15: 0 | AJ15: 0 | AK15: 0 | AL15: =IF(AD15="TIPO I",'BASE LIQUIDACION'!$D$3,IF(AD15="TIPO II",'BASE LIQUIDACION'!$D$4,IF(AD15="TIPO III",'BASE LIQUIDACION'!$D$5,'BASE LIQUIDACION'!$D$7))) -> 134410.39 | AM15: =AG15*'BASE LIQUIDACION'!$B$12+AH15*'BASE LIQUIDACION'!$B$11+AI15*'BASE LIQUIDACION'!$B$13+AJ15*'BASE LIQUIDACION'!$B$14+AK15*AL15 -> 162346.95
A16: TUNJA | B16: =VLOOKUP(A16,'CENTRO DE COSTOS'!A:D,4,FALSE) -> MIGUEL JULIÁN HERNÁNDEZ GUARÍN | C16: =VLOOKUP(A16,'CENTRO DE COSTOS'!A:C,2,FALSE) -> 0004-0008 | D16: 15001 | E16: TA-25-799125 | F16: FO-25-1128655 | G16: 45832 | H16: 45834 | I16: 45832 | J16: 45833 | K16: 45833 | L16: BOYACA | M16: TUNJA | N16: BARRIO TUNJUELITO TUNJA 1 | O16: 80068 | P16: CB CRECIMIENTO - NUEVO | Q16: APERTURA | R16: REDEBAN | S16: UNO A UNO | T16: UNO A UNO | U16: EJECUTADO | V16: 24-06-2025 SE REALIZA LLAMADA AL CLIENTE, SE HABLA CON LA SRA DIANA ESPERANZA GONZÁLEZ IBAÑEZ SE VALIDA DIRECCIÓN OK, CANAL OK, DISPONIBILIDAD TOTAL, LLAMAR EL DÍA LA INSTALACIÓN PARA CONFIRMAR VISITA, AVISO EXTERIOR ALTURA APROX 1,80 METROS; TOMACORRIENTE CERCANO: SI; TIENE CABINA DE SEGURIDAD: NO // CONTACTO REALIZADO POR LA APP 25/6/2025 SE REALIZA INSTALACIÓN DE CORRESPONSAL, SE INSTALAN EQUIPOS CON PRUEBAS EXITOSAS, SE CAPACITA Y SE EVALÚA AL CLIENTE, SE INSTALA PUBLICIDAD COMPLETA, CB QUEDA OPERATIVO. USUARIO SOMOS BANCOLOMBIA ACTIVO. SE INSTALAN 6 MT DE CABLE UTP | W16: SOLER HOYOS CRISTIAN LEONARDO | X16: SAXZZ466 | Y16: 1242413 | Z16: 274888 | AA16: 903638-243637317561365457310152 | AB16: N/A | AC16: 40 ROLLOS | AD16: =VLOOKUP(D16,TIPOLOGIAS!A:F,6,0) -> TIPO I | AE16: =VLOOKUP(D16,TIPOLOGIAS!A:F,5,0) -> TERRESTRE | AF16: VISITA _TECNICA | AG16: 6 | AH16: 0 | AI16: 0 | AJ16: 0 | AK16: 0 | AL16: =IF(AD16="TIPO I",'BASE LIQUIDACION'!$D$3,IF(AD16="TIPO II",'BASE LIQUIDACION'!$D$4,IF(AD16="TIPO III",'BASE LIQUIDACION'!$D$5,'BASE LIQUIDACION'!$D$7))) -> 44559.985 | AM16: =AG16*'BASE LIQUIDACION'!$B$12+AH16*'BASE LIQUIDACION'!$B$11+AI16*'BASE LIQUIDACION'!$B$13+AJ16*'BASE LIQUIDACION'!$B$14+AK16*AL16 -> 97408.173
A17: CALI | B17: =VLOOKUP(A17,'CENTRO DE COSTOS'!A:D,4,FALSE) -> DIEGO FERNANDO HENAO CARDONA | C17: =VLOOKUP(A17,'CENTRO DE COSTOS'!A:C,2,FALSE) -> 0004-0003 | D17: 76001 | E17: TA-25-799143 | F17: FO-25-1128724 | G17: 45832 | H17: 45834 | I17: 45832 | J17: 45833 | K17: 45833 | L17: VALLE DEL CAUCA | M17: CALI | N17: BARRIO COMUNEROS I CALI 2 | O17: 79989 | P17: CB CRECIMIENTO - NUEVO | Q17: APERTURA | R17: REDEBAN | S17: UNO A UNO | T17: UNO A UNO | U17: EJECUTADO | V17: 24-06-2025 SE REALIZA LLAMADA AL CLIENTE, SE HABLA CON LA ESPOSA DE SR CARLOS JAVIER LEFFA ZAMBRANO SE VALIDA DIRECCIÓN OK, CANAL OK, DISPONIBILIDAD TOTAL, LLAMAR EL DÍA LA INSTALACIÓN PARA CONFIRMAR VISITA, AVISO EXTERIOR ALTURA APROX CLIENTE NO TIENE CONOCIMIENTO DE MEDIDAS; TOMACORRIENTE CERCANO: SI; TIENE CABINA DE SEGURIDAD: SI // CONTACTO REALIZADO POR WHATSAPP 25/6/2025 SE REALIZA INSTALACIÓN DE CORRESPONSAL, SE INSTALAN EQUIPOS CON PRUEBAS EXITOSAS, SE CAPACITA Y SE EVALÚA AL CLIENTE, SE INSTALA PUBLICIDAD COMPLETA, CB QUEDA OPERATIVO. USUARIO SOMOS BANCOLOMBIA ACTIVO. SE INSTALA 6 MT DE CABLE UTP | W17: MONTERO MUESES GIAN CARLO | X17: SAXZZ479 | Y17: 1175384 | Z17: N/A | AA17: 914088 | AB17: N/A | AC17: 40 ROLLOS | AD17: =VLOOKUP(D17,TIPOLOGIAS!A:F,6,0) -> TIPO I | AE17: =VLOOKUP(D17,TIPOLOGIAS!A:F,5,0) -> TERRESTRE | AF17: VISITA _TECNICA | AG17: 6 | AH17: 0 | AI17: 0 | AJ17: 0 | AK17: 0 | AL17: =IF(AD17="TIPO I",'BASE LIQUIDACION'!$D$3,IF(AD17="TIPO II",'BASE LIQUIDACION'!$D$4,IF(AD17="TIPO III",'BASE LIQUIDACION'!$D$5,'BASE LIQUIDACION'!$D$7))) -> 44559.985 | AM17: =AG17*'BASE LIQUIDACION'!$B$12+AH17*'BASE LIQUIDACION'!$B$11+AI17*'BASE LIQUIDACION'!$B$13+AJ17*'BASE LIQUIDACION'!$B$14+AK17*AL17 -> 97408.173
A18: PEREIRA | B18: =VLOOKUP(A18,'CENTRO DE COSTOS'!A:D,4,FALSE) -> DIEGO FERNANDO HENAO CARDONA | C18: =VLOOKUP(A18,'CENTRO DE COSTOS'!A:C,2,FALSE) -> 0004-0002 | D18: 66001 | E18: TA-25-799158 | F18: FO-25-1128788 | G18: 45832 | H18: 45834 | I18: 45832 | J18: 45834 | K18: 45834 | L18: RISARALDA | M18: PEREIRA | N18: BARRIO CENTRO PEREIRA 48 | O18: 80044 | P18: CB CRECIMIENTO - NUEVO | Q18: APERTURA | R18: REDEBAN | S18: UNO A UNO | T18: UNO A UNO | U18: EJECUTADO | V18: 24-06 SE REALIZA LLAMADA AL CLIENTE, SE HABLA CON LA SRA YULI ANDREA BECERRA YA QUE SR CARLOS ANDRES ARIZA GONZALEZ NO SE ENCUENTRA SE VALIDA DIRECCIÓN OK, DISPONIBILIDAD TOTAL, LLAMAR EL DÍA LA INSTALACIÓN PARA CONFIRMAR VISITA, AVISO EXTERIOR ALTURA APROX 2.00 METROS; TOMA CORRIENTE CERCANO: SI; TIENE CABINA DE SEGURIDAD: NO , USUARIO INDICA QUE SE EL MODEN SE ENCUENTRA 10 METROS 26/6/2025 SE REALIZA INSTALACIÓN DE CORRESPONSAL, SE INSTALAN EQUIPOS CON PRUEBAS EXITOSAS, SE CAPACITA Y SE EVALÚA AL CLIENTE, SE INSTALA PUBLICIDAD COMPLETA, CB QUEDA OPERATIVO. USUARIO SOMOS BANCOLOMBIA ACTIVO. SE INSTALAN 15 MT DE CABLE UTP | W18: FRANCO CAÑAVERAL YAMID RAUL | X18: SAXZZ492 | Y18: 1235358 | Z18: N/A | AA18: 1076556-241587317561324755887228 | AB18: N/A | AC18: 40 ROLLOS | AD18: =VLOOKUP(D18,TIPOLOGIAS!A:F,6,0) -> TIPO I | AE18: =VLOOKUP(D18,TIPOLOGIAS!A:F,5,0) -> TERRESTRE | AF18: VISITA _TECNICA | AG18: 15 | AH18: 0 | AI18: 0 | AJ18: 0 | AK18: 0 | AL18: =IF(AD18="TIPO I",'BASE LIQUIDACION'!$D$3,IF(AD18="TIPO II",'BASE LIQUIDACION'!$D$4,IF(AD18="TIPO III",'BASE LIQUIDACION'!$D$5,'BASE LIQUIDACION'!$D$7))) -> 44559.985 | AM18: =AG18*'BASE LIQUIDACION'!$B$12+AH18*'BASE LIQUIDACION'!$B$11+AI18*'BASE LIQUIDACION'!$B$13+AJ18*'BASE LIQUIDACION'!$B$14+AK18*AL18 -> 243520.43
A19: MEDELLIN | B19: =VLOOKUP(A19,'CENTRO DE COSTOS'!A:D,4,FALSE) -> JUAN SEBASTIÁN RÍOS CASTRILLÓN | C19: =VLOOKUP(A19,'CENTRO DE COSTOS'!A:C,2,FALSE) -> 0004-0005 | D19: 5690 | E19: TA-25-799214 | F19: FO-25-1128965 | G19: 45832 | H19: 45834 | I19: 45832 | J19: 45834 | K19: 45834 | L19: ANTIOQUIA | M19: SANTO DOMINGO | N19: BARRIO CENTRO SANTO DOMINGO | O19: 80054 | P19: CB CRECIMIENTO - NUEVO | Q19: APERTURA | R19: REDEBAN | S19: UNO A UNO | T19: UNO A UNO | U19: EJECUTADO | V19: 21-06 SE REALIZA LLAMADA AL CLIENTE, SE HABLA CON LA SR SANTIAGO RESTREPO CASTRILLON SE VALIDA DIRECCIÓN OK, CANAL OK, DISPONIBILIDAD TOTAL, LLAMAR EL DÍA LA INSTALACIÓN PARA CONFIRMAR VISITA, AVISO EXTERIOR ALTURA APROX 3 METROS; TOMACORRIENTE CERCANO: SI; TIENE CABINA DE SEGURIDAD: NO - COMUNICACIÓN POR WPP 26/6/2025 ESCALAMOS NOVEDAD DE INSTALACIÓN. EN DIRECCIÓN TENEMOS LT LA MAQUINA VRD PORCESITO, PERO DOCUMENTO DE CÁMARA DE COMERCIO QUE NOS FACILITA USUARIO TIENE DIRECCIÓN CON NOMENCLATURA COMPLETA CALLE 39 64ª 35 INTERIOR 701 EN MEDELLIN. USUARIO INFORMA QUE ESA DIRECCIÓN ES DE LA OFICINA PRINCIPAL EN MEDELLIN. TAMBIÉN NOS FACILITA UNA FOTO DE UNA FACTURA DE UN PROVEEDOR DONDE SALE LA MISMA DIRECCIÓN EN MEDELLIN, PERO ABAJO SI DICE PORSECITO. 26/6/2025 SEGÚN LO CONVERSADO, SE EVIDENCIÓ QUE EN LA SEGUNDA HOJA DEL CERTIFICADO DE CÁMARA DE COMERCIO SE ENCUENTRA REGISTRADA LA DIRECCIÓN CORRECTA. POR LO TANTO, SE DEBE PROCEDER CON LA IMPLEMENTACIÓN DEL CB 3007080054. 26/6/2025 SE REALIZA INSTALACIÓN DE CORRESPONSAL, SE INSTALAN EQUIPOS CON PRUEBAS EXITOSAS, SE CAPACITA Y SE EVALÚA AL CLIENTE, SE INSTALA PUBLICIDAD COMPLETA, CB QUEDA OPERATIVO. USUARIO SOMOS BANCOLOMBIA ACTIVO. SE INSTALANN 12 MT DE CABLE UTP | W19: ZAPATA LOPEZ EDWARD ASDRUBAL | X19: SAXZZ525 | Y19: 1254223 | Z19: N/A | AA19: 1238897-243627317561365457299638 | AB19: N/A | AC19: 40 ROLLOS | AD19: =VLOOKUP(D19,TIPOLOGIAS!A:F,6,0) -> TIPO II | AE19: =VLOOKUP(D19,TIPOLOGIAS!A:F,5,0) -> TERRESTRE | AF19: VISITA _TECNICA | AG19: 12 | AH19: 0 | AI19: 0 | AJ19: 0 | AK19: 0 | AL19: =IF(AD19="TIPO I",'BASE LIQUIDACION'!$D$3,IF(AD19="TIPO II",'BASE LIQUIDACION'!$D$4,IF(AD19="TIPO III",'BASE LIQUIDACION'!$D$5,'BASE LIQUIDACION'!$D$7))) -> 134410.39 | AM19: =AG19*'BASE LIQUIDACION'!$B$12+AH19*'BASE LIQUIDACION'!$B$11+AI19*'BASE LIQUIDACION'!$B$13+AJ19*'BASE LIQUIDACION'!$B$14+AK19*AL19 -> 194816.35
A20: MEDELLIN | B20: =VLOOKUP(A20,'CENTRO DE COSTOS'!A:D,4,FALSE) -> JUAN SEBASTIÁN RÍOS CASTRILLÓN | C20: =VLOOKUP(A20,'CENTRO DE COSTOS'!A:C,2,FALSE) -> 0004-0005 | D20: 5001 | E20: TA-25-799289 | F20: FO-25-1129202 | G20: 45832 | H20: 45834 | I20: 45832 | J20: 45834 | K20: 45834 | L20: ANTIOQUIA | M20: MEDELLIN | N20: BARRIO BELEN MEDELLIN 15 | O20: 80087 | P20: CB CRECIMIENTO - NUEVO | Q20: APERTURA | R20: REDEBAN | S20: UNO A UNO | T20: UNO A UNO | U20: EJECUTADO | V20: 21-06 SE REALIZA LLAMADA AL CLIENTE, SE HABLA CON LA SR MARTIN ALONSO HERNANDEZ LARREA SE VALIDA DIRECCIÓN OK, CANAL OK, DISPONIBILIDAD TOTAL, LLAMAR EL DÍA LA INSTALACIÓN PARA CONFIRMAR VISITA, AVISO EXTERIOR ALTURA APROX 3 METROS; TOMACORRIENTE CERCANO: SI; TIENE CABINA DE SEGURIDAD: NO - EL MODEM ESTA A 5 MT 26/6/2025 SE REALIZA INSTALACIÓN DE CORRESPONSAL, SE INSTALAN EQUIPOS CON PRUEBAS EXITOSAS, SE CAPACITA Y SE EVALÚA AL CLIENTE, SE INSTALA PUBLICIDAD COMPLETA, CB QUEDA OPERATIVO. USUARIO SOMOS BANCOLOMBIA ACTIVO. SE INSTALAN 7 MT DE CABLE UTP | W20: ALVAREZ ARENAS VICTOR HUGO | X20: SAXZZ563 | Y20: 1254482 | Z20: N/A | AA20: 1238899-243627317561365457298717 | AB20: N/A | AC20: 40 ROLLOS | AD20: =VLOOKUP(D20,TIPOLOGIAS!A:F,6,0) -> TIPO I | AE20: =VLOOKUP(D20,TIPOLOGIAS!A:F,5,0) -> TERRESTRE | AF20: VISITA _TECNICA | AG20: 7 | AH20: 0 | AI20: 0 | AJ20: 0 | AK20: 0 | AL20: =IF(AD20="TIPO I",'BASE LIQUIDACION'!$D$3,IF(AD20="TIPO II",'BASE LIQUIDACION'!$D$4,IF(AD20="TIPO III",'BASE LIQUIDACION'!$D$5,'BASE LIQUIDACION'!$D$7))) -> 44559.985 | AM20: =AG20*'BASE LIQUIDACION'!$B$12+AH20*'BASE LIQUIDACION'!$B$11+AI20*'BASE LIQUIDACION'!$B$13+AJ20*'BASE LIQUIDACION'!$B$14+AK20*AL20 -> 113642.87
A21: BOGOTA | B21: =VLOOKUP(A21,'CENTRO DE COSTOS'!A:D,4,FALSE) -> WILLIAM ASDRUBAL ROZO ROZO | C21: =VLOOKUP(A21,'CENTRO DE COSTOS'!A:C,2,FALSE) -> 0004-0004 | D21: 11001 | E21: TA-25-799293 | F21: FO-25-1129213 | G21: 45832 | H21: 45834 | I21: 45832 | J21: 45833 | K21: 45833 | L21: CUNDINAMARCA | M21: BOGOTA | N21: BARRIO SAN DIEGO BOGOTA | O21: 79977 | P21: CB CRECIMIENTO - NUEVO | Q21: APERTURA | R21: REDEBAN | S21: UNO A UNO | T21: UNO A UNO | U21: EJECUTADO | V21: 21-06 SE REALIZA LLAMADA AL CLIENTE, SE HABLA CON LA SR AARON EULICES AGUILERA JUNCA SE VALIDA DIRECCIÓN OK, CANAL OK, DISPONIBILIDAD TOTAL, LLAMAR EL DÍA LA INSTALACIÓN PARA CONFIRMAR VISITA, AVISO EXTERIOR ALTURA: NO INDICA ALTURA; TOMACORRIENTE CERCANO: SI; TIENE CABINA DE SEGURIDAD: NO - COMUNICACIÓN POR WPP / EL MODEM ESTA A 6 MT 25/6/2025 NOTA; ESTANDO EN SITIO EL COMERCIO INFORMA NO TENER PERMISO DE INSTALAR LA PUBLICIDAD EN LA PARTE EXTERIOR DEL LOCAL, PIDE SEA INSTALADO EN EL VIDRIO POR LA PARTE INTERNA SIN EL MARCO. DE ACUERDO A LA AUTORIZACIÓN VÍA WHATSAPP, SE INSTALA SEGÚN SOLICITUD DEL COMERCIO. SE REALIZA INSTALACIÓN DE CORRESPONSAL, SE INSTALAN EQUIPOS CON PRUEBAS EXITOSAS, SE CAPACITA Y SE EVALÚA AL CLIENTE, SE INSTALA PUBLICIDAD COMPLETA, CB QUEDA OPERATIVO. USUARIO SOMOS BANCOLOMBIA ACTIVO. SE INSTALAN 6 MT DE CABLE UTP | W21: GOMEZ VEGA DAVID SNEYDER | X21: SAXZZ565 | Y21: 1235380 | Z21: N/A | AA21: 528124-241587317561324755886735 | AB21: N/A | AC21: 40 ROLLOS | AD21: =VLOOKUP(D21,TIPOLOGIAS!A:F,6,0) -> TIPO I | AE21: =VLOOKUP(D21,TIPOLOGIAS!A:F,5,0) -> TERRESTRE | AF21: VISITA _TECNICA | AG21: 6 | AH21: 0 | AI21: 0 | AJ21: 0 | AK21: 0 | AL21: =IF(AD21="TIPO I",'BASE LIQUIDACION'!$D$3,IF(AD21="TIPO II",'BASE LIQUIDACION'!$D$4,IF(AD21="TIPO III",'BASE LIQUIDACION'!$D$5,'BASE LIQUIDACION'!$D$7))) -> 44559.985 | AM21: =AG21*'BASE LIQUIDACION'!$B$12+AH21*'BASE LIQUIDACION'!$B$11+AI21*'BASE LIQUIDACION'!$B$13+AJ21*'BASE LIQUIDACION'!$B$14+AK21*AL21 -> 97408.173
A22: PEREIRA | B22: =VLOOKUP(A22,'CENTRO DE COSTOS'!A:D,4,FALSE) -> DIEGO FERNANDO HENAO CARDONA | C22: =VLOOKUP(A22,'CENTRO DE COSTOS'!A:C,2,FALSE) -> 0004-0002 | D22: 66001 | E22: TA-25-799295 | F22: FO-25-1129221 | G22: 45832 | H22: 45834 | I22: 45832 | J22: 45833 | K22: 45833 | L22: RISARALDA | M22: PEREIRA | N22: BARRIO BELMONTE PEREIRA 6 | O22: 80043 | P22: CB CRECIMIENTO - NUEVO | Q22: APERTURA | R22: REDEBAN | S22: UNO A UNO | T22: UNO A UNO | U22: EJECUTADO | V22: 24-06 SE REALIZA LLAMADA AL CLIENTE, SE HABLA CON LA SR ORLANDO ZAPATA OROZCO SE VALIDA DIRECCIÓN OK, CANAL OK, DISPONIBILIDAD TOTAL, LLAMAR EL DÍA LA INSTALACIÓN PARA CONFIRMAR VISITA, AVISO EXTERIOR ALTURA: NO INDICA ALTURA; TOMACORRIENTE CERCANO: SI; TIENE CABINA DE SEGURIDAD: NO - EL MODEM ESTA A 10 MT 25/6/2025 SE REALIZA INSTALACIÓN DE CORRESPONSAL, SE INSTALAN EQUIPOS CON PRUEBAS EXITOSAS, SE CAPACITA Y SE EVALÚA AL CLIENTE, SE INSTALA PUBLICIDAD COMPLETA, CB QUEDA OPERATIVO. USUARIO SOMOS BANCOLOMBIA ACTIVO | W22: ARROYAVE CANO MANUEL GUILLERMO | X22: SAXZZ567 | Y22: 1235292 | Z22: N/A | AA22: 1217682-241597317561324755901244 | AB22: N/A | AC22: 40 ROLLOS | AD22: =VLOOKUP(D22,TIPOLOGIAS!A:F,6,0) -> TIPO I | AE22: =VLOOKUP(D22,TIPOLOGIAS!A:F,5,0) -> TERRESTRE | AF22: VISITA _TECNICA | AG22: 10 | AH22: 0 | AI22: 0 | AJ22: 0 | AK22: 0 | AL22: =IF(AD22="TIPO I",'BASE LIQUIDACION'!$D$3,IF(AD22="TIPO II",'BASE LIQUIDACION'!$D$4,IF(AD22="TIPO III",'BASE LIQUIDACION'!$D$5,'BASE LIQUIDACION'!$D$7))) -> 44559.985 | AM22: =AG22*'BASE LIQUIDACION'!$B$12+AH22*'BASE LIQUIDACION'!$B$11+AI22*'BASE LIQUIDACION'!$B$13+AJ22*'BASE LIQUIDACION'!$B$14+AK22*AL22 -> 162346.95
A23: CUCUTA | B23: =VLOOKUP(A23,'CENTRO DE COSTOS'!A:D,4,FALSE) -> MIGUEL JULIÁN HERNÁNDEZ GUARÍN | C23: =VLOOKUP(A23,'CENTRO DE COSTOS'!A:C,2,FALSE) -> 0004-0008 | D23: 54498 | E23: TA-25-721901 | F23: FO-25-1062900 | G23: 45817 | H23: 45819 | I23: 45817 | J23: 45818 | K23: 45818 | L23: NORTE DE SANTANDER | M23: OCAÑA | N23: BARRIO EDIFICIO MIRADORES DE LA COLINA OCAÑA | O23: 79815 | P23: CB CRECIMIENTO - NUEVO | Q23: APERTURA | R23: REDEBAN | S23: UNO A UNO | T23: UNO A UNO | U23: EJECUTADO | V23: 07-06 SE REALIZA LLAMADA AL CLIENTE, SE HABLA CON LA S JULIO CESAR JAIME SEPÚLVEDA SE VALIDA DIRECCIÓN OK, CANAL OK, DISPONIBILIDAD TOTAL, LLAMAR EL DÍA LA INSTALACIÓN PARA CONFIRMAR VISITA, AVISO EXTERIOR ALTURA APROX 2.50 METROS; TOMACORRIENTE CERCANO: SI; TIENE CABINA DE SEGURIDAD: NO, EL MODEM ESTA A 6 MT - COMUNICACIÓN POR WPP 10-06 SE REALIZA INSTALACIÓN DE CORRESPONSAL, SE INSTALAN EQUIPOS CON PRUEBAS EXITOSAS, SE CAPACITA Y SE EVALÚA AL CLIENTE, SE INSTALA PUBLICIDAD COMPLETA, CB QUEDA OPERATIVO. USUARIO SOMOS BANCOLOMBIA ACTIVO. SE INSTALA SWITCH 224B0A0009381 | W23: GELVEZ MOGOLLON JOSE ELISEO | X23: F1XZZ025 | Y23: 801650 | Z23: N/A | AA23: 513517 | AB23: N/A | AC23: 40 ROLLOS | AD23: =VLOOKUP(D23,TIPOLOGIAS!A:F,6,0) -> TIPO IV | AE23: =VLOOKUP(D23,TIPOLOGIAS!A:F,5,0) -> TERRESTRE | AF23: VISITA _TECNICA | AG23: 0 | AH23: 0 | AI23: 1 | AJ23: 0 | AK23: 0 | AL23: =IF(AD23="TIPO I",'BASE LIQUIDACION'!$D$3,IF(AD23="TIPO II",'BASE LIQUIDACION'!$D$4,IF(AD23="TIPO III",'BASE LIQUIDACION'!$D$5,'BASE LIQUIDACION'!$D$7))) -> 464809.03 | AM23: =AG23*'BASE LIQUIDACION'!$B$12+AH23*'BASE LIQUIDACION'!$B$11+AI23*'BASE LIQUIDACION'!$B$13+AJ23*'BASE LIQUIDACION'!$B$14+AK23*AL23 -> 257391.82
A24: CALI | B24: =VLOOKUP(A24,'CENTRO DE COSTOS'!A:D,4,FALSE) -> DIEGO FERNANDO HENAO CARDONA | C24: =VLOOKUP(A24,'CENTRO DE COSTOS'!A:C,2,FALSE) -> 0004-0003 | D24: 19698 | E24: TA-25-799178 | F24: FO-25-1128861 | G24: 45832 | H24: 45834 | I24: 45832 | J24: 45834 | K24: 45834 | L24: CAUCA | M24: SANTANDER DE QUILICHAO | N24: BARRIO CENTENARIO SANTANDER DE QUILICHAO 5 | O24: 80062 | P24: CB CRECIMIENTO - NUEVO | Q24: APERTURA | R24: REDEBAN | S24: UNO A UNO | T24: UNO A UNO | U24: EJECUTADO | V24: 24-06 SE REALIZA LLAMADA AL CLIENTE, SE HABLA CON LA SRA JUAN JOSE DELGADO ARIAS SE VALIDA DIRECCIÓN OK, CANAL OK, DISPONIBILIDAD TOTAL, LLAMAR EL DÍA LA INSTALACIÓN PARA CONFIRMAR VISITA, AVISO EXTERIOR ALTURA APROX 3 METROS; TOMACORRIENTE CERCANO: SI; TIENE CABINA DE SEGURIDAD: NO - COMUNICACIÓN POR WPP / EL MODEM NO TIENE PUERTO DISPONIBLES LLEVAR SWITCH 26/6/2025 SE REALIZA INSTALACIÓN DE CORRESPONSAL, SE INSTALAN EQUIPOS CON PRUEBAS EXITOSAS, SE CAPACITA Y SE EVALÚA AL CLIENTE, SE INSTALA PUBLICIDAD COMPLETA, CB QUEDA OPERATIVO. USUARIO SOMOS BANCOLOMBIA ACTIVO. SE INSTALA WITCH QS013CC000233 | W24: MONTERO MUESES GIAN CARLO | X24: SAXZZ504 | Y24: 1254318 | Z24: N/A | AA24: 1233700-243637317561365457309861 | AB24: N/A | AC24: 40 ROLLOS | AD24: =VLOOKUP(D24,TIPOLOGIAS!A:F,6,0) -> TIPO II | AE24: =VLOOKUP(D24,TIPOLOGIAS!A:F,5,0) -> TERRESTRE | AF24: VISITA _TECNICA | AG24: 0 | AH24: 0 | AI24: 1 | AJ24: 0 | AK24: 0 | AL24: =IF(AD24="TIPO I",'BASE LIQUIDACION'!$D$3,IF(AD24="TIPO II",'BASE LIQUIDACION'!$D$4,IF(AD24="TIPO III",'BASE LIQUIDACION'!$D$5,'BASE LIQUIDACION'!$D$7))) -> 134410.39 | AM24: =AG24*'BASE LIQUIDACION'!$B$12+AH24*'BASE LIQUIDACION'!$B$11+AI24*'BASE LIQUIDACION'!$B$13+AJ24*'BASE LIQUIDACION'!$B$14+AK24*AL24 -> 257391.82
A25: TUNJA | B25: =VLOOKUP(A25,'CENTRO DE COSTOS'!A:D,4,FALSE) -> MIGUEL JULIÁN HERNÁNDEZ GUARÍN | C25: =VLOOKUP(A25,'CENTRO DE COSTOS'!A:C,2,FALSE) -> 0004-0008 | D25: 15681 | E25: TA-25-755896 | F25: FO-25-1085382 | G25: 45821 | H25: 45825 | I25: 45821 | J25: 45825 | K25: 45825 | L25: BOYACA | M25: SAN PABLO DE BORBUR | N25: BARRIO CHACARO SAN PABLO DE BORBUR | O25: 79858 | P25: CB CRECIMIENTO - NUEVO | Q25: APERTURA | R25: REDEBAN | S25: UNO A UNO | T25: UNO A UNO | U25: EJECUTADO | V25: 13-06 SE REALIZA LLAMADA AL CLIENTE, SE HABLA CON LA SRA HEIDY TATIANA OSORIO RUEDA SE VALIDA DIRECCIÓN OK, CANAL OK, DISPONIBILIDAD TOTAL, LLAMAR EL DÍA LA INSTALACIÓN PARA CONFIRMAR VISITA, AVISO EXTERIOR ALTURA APROX CLEINTE NO TIENE CONOCIMIENTO DE MEDIDAS; TOMACORRIENTE CERCANO: SI; TIENE CABINA DE SEGURIDAD: NO // CONTACTO REALIZADO POR LA APP 16-06 ME ENCUENTRO EN RUTA HACIA LA ZONA DE CHIQUINQUIRÁ POR TEMAS DE TRASPORTE YA QUE NO ES MUY SEGUIDO NO SE LOGRARIA LLEGAR AL SITIO DE LA INSTALACION , EN COMUNICACIÓN CON EL CLIENTE LA SEÑORA TATIANA OSORIO AL NÚMERO CELULAR 3046464134 SE LE INDICA QUE SE ATENDERA ACTIVIDAD EL DÍA DE MAÑANA 17 JUNIO DEL 2025 EN TRANSCURSO DE DIA , CLIENTE CONFORME 17/6/2025 SE REALIZA INSTALACIÓN DE CORRESPONSAL, SE INSTALAN EQUIPOS CON PRUEBAS EXITOSAS, SE CAPACITA Y SE EVALÚA AL CLIENTE, SE INSTALA PUBLICIDAD COMPLETA, CB QUEDA OPERATIVO. USUARIO SOMOS BANCOLOMBIA ACTIVO. SE INTALO ROUTER E0682016411002194 | W25: ALVARADO MORENO CRISTHIAN | X25: FAWZZ650 | Y25: 771689 | Z25: 869561 | AA25: 1071457 | AB25: N/A | AC25: 40 ROLLOS | AD25: =VLOOKUP(D25,TIPOLOGIAS!A:F,6,0) -> TIPO IV | AE25: =VLOOKUP(D25,TIPOLOGIAS!A:F,5,0) -> TERRESTRE | AF25: VISITA _TECNICA | AG25: 0 | AH25: 0 | AI25: 0 | AJ25: 1 | AK25: 0 | AL25: =IF(AD25="TIPO I",'BASE LIQUIDACION'!$D$3,IF(AD25="TIPO II",'BASE LIQUIDACION'!$D$4,IF(AD25="TIPO III",'BASE LIQUIDACION'!$D$5,'BASE LIQUIDACION'!$D$7))) -> 464809.03 | AM25: =AG25*'BASE LIQUIDACION'!$B$12+AH25*'BASE LIQUIDACION'!$B$11+AI25*'BASE LIQUIDACION'!$B$13+AJ25*'BASE LIQUIDACION'!$B$14+AK25*AL25 -> 306552.28
A26: NEIVA | B26: =VLOOKUP(A26,'CENTRO DE COSTOS'!A:D,4,FALSE) -> KEVIN ALEXIS CORZO BUSTOS | C26: =VLOOKUP(A26,'CENTRO DE COSTOS'!A:C,2,FALSE) -> 0004-0007 | D26: 18001 | E26: TA-25-755897 | F26: FO-25-1085384 | G26: 45821 | H26: 45825 | I26: 45821 | J26: 45825 | K26: 45825 | L26: CAQUETA | M26: FLORENCIA | N26: BARRIO COOPERATIVA FLORENCIA 1 | O26: 79866 | P26: CB CRECIMIENTO - NUEVO | Q26: APERTURA | R26: REDEBAN | S26: UNO A UNO | T26: UNO A UNO | U26: EJECUTADO | V26: 13-06 SE REALIZA LLAMADA AL CLIENTE, SE HABLA CON EL SR OINER RUIZ ALVAREZ SE VALIDA DIRECCIÓN OK, CANAL OK, DISPONIBILIDAD TOTAL, LLAMAR EL DÍA LA INSTALACIÓN PARA CONFIRMAR VISITA, AVISO EXTERIOR ALTURA APROX 2 METROS; TOMACORRIENTE CERCANO: SI; TIENE CABINA DE SEGURIDAD: NO // CONTACTO REALIZADO POR LA APP 16-06 EN COMUNICACIÓN CON EL CLIENTE EL SEÑOR OINER RUIZ, AL NÚMERO 3115485300, INDICA QUE NOS PUEDE RECIBIR A PARTIR DE MAÑANA MARTES 17 DE JUNIO , EN EL TRANSCURSO DEL DIA. 17-06 SE REALIZA INSTALACIÓN DE CORRESPONSAL, SE INSTALAN EQUIPOS CON PRUEBAS EXITOSAS, SE CAPACITA Y SE EVALÚA AL CLIENTE, SE INSTALA PUBLICIDAD COMPLETA, CB QUEDA OPERATIVO. USUARIO SOMOS BANCOLOMBIA ACTIVO | W26: DEVIA REINOSO JUAN CARLOS | X26: FAWZZ651 | Y26: 1050463 | Z26: N/A | AA26: 1076442 | AB26: N/A | AC26: 40 ROLLOS | AD26: =VLOOKUP(D26,TIPOLOGIAS!A:F,6,0) -> TIPO IV | AE26: =VLOOKUP(D26,TIPOLOGIAS!A:F,5,0) -> TERRESTRE | AF26: VISITA _TECNICA | AG26: 0 | AH26: 0 | AI26: 0 | AJ26: 1 | AK26: 0 | AL26: =IF(AD26="TIPO I",'BASE LIQUIDACION'!$D$3,IF(AD26="TIPO II",'BASE LIQUIDACION'!$D$4,IF(AD26="TIPO III",'BASE LIQUIDACION'!$D$5,'BASE LIQUIDACION'!$D$7))) -> 464809.03 | AM26: =AG26*'BASE LIQUIDACION'!$B$12+AH26*'BASE LIQUIDACION'!$B$11+AI26*'BASE LIQUIDACION'!$B$13+AJ26*'BASE LIQUIDACION'!$B$14+AK26*AL26 -> 306552.28
A27: TUNJA | B27: =VLOOKUP(A27,'CENTRO DE COSTOS'!A:D,4,FALSE) -> MIGUEL JULIÁN HERNÁNDEZ GUARÍN | C27: =VLOOKUP(A27,'CENTRO DE COSTOS'!A:C,2,FALSE) -> 0004-0008 | D27: 15759 | E27: TA-25-684764 | F27: FO-25-1033867 | G27: 45807 | H27: 45812 | I27: 45807 | J27: 45813 | K27: 45813 | L27: BOYACA | M27: SOGAMOSO | N27: BARRIO LA PRADERA SOGAMOSO 3 | O27: 79655 | P27: CB CRECIMIENTO - NUEVO | Q27: APERTURA | R27: REDEBAN | S27: UNO A UNO | T27: UNO A UNO | U27: EJECUTADO | V27: 30-05-2025 SE REALIZA LLAMADA AL CLIENTE, SE HABLA CON LA SRA LADIS ESPERANZA SOSA AMAROI SE VALIDA DIRECCIÓN OK, CANAL OK, DISPONIBILIDAD TOTAL, LLAMAR EL DÍA LA INSTALACIÓN PARA CONFIRMAR VISITA, AVISO EXTERIOR ALTURA APROX 3 METROS; TOMACORRIENTE CERCANO: SI; TIENE CABINA DE SEGURIDAD: NO // CONTACTO REALIZADO POR LA APP 3/6/2025 SE VISITA COMERCIO ,LA INSTALACIÓN EL DIA DE HOY ES FALLIDA COMERCIO SIN COMUNICACION RED DE INTERNET ,EL USUARIO INDICA QUE SE COMUNICARA CON EL PROVEDOR DEL INTERNET PARA QUE HABILITE LA RED DE COMUNICACIÓN EN EL COMERCIO A INSTALAR , SE REPROGRAMA VISITA PARA EL DIA JUEVES 05 DE JUNIO DEL 2025 INDICA QUE PARA ESE DIA TENDRIA LISTO EL PUNTO DE INTERNET 5/6/2025 SE REALIZA INSTALACIÓN DE CORRESPONSAL, SE INSTALAN EQUIPOS CON PRUEBAS EXITOSAS, SE CAPACITA Y SE EVALÚA AL CLIENTE, SE INSTALA PUBLICIDAD COMPLETA, CB QUEDA OPERATIVO. USUARIO SOMOS BANCOLOMBIA ACTIVO | W27: ALVARADO MORENO CRISTHIAN | X27: SXUZZ181 | Y27: 793119 | Z27: N/A | AA27: 905615 | AB27: N/A | AC27: 40 ROLLOS | AD27: =VLOOKUP(D27,TIPOLOGIAS!A:F,6,0) -> TIPO II | AE27: =VLOOKUP(D27,TIPOLOGIAS!A:F,5,0) -> TERRESTRE | AF27: VISITA _TECNICA | AG27: 0 | AH27: 0 | AI27: 0 | AJ27: 0 | AK27: 1 | AL27: =IF(AD27="TIPO I",'BASE LIQUIDACION'!$D$3,IF(AD27="TIPO II",'BASE LIQUIDACION'!$D$4,IF(AD27="TIPO III",'BASE LIQUIDACION'!$D$5,'BASE LIQUIDACION'!$D$7))) -> 134410.39 | AM27: =AG27*'BASE LIQUIDACION'!$B$12+AH27*'BASE LIQUIDACION'!$B$11+AI27*'BASE LIQUIDACION'!$B$13+AJ27*'BASE LIQUIDACION'!$B$14+AK27*AL27 -> 134410.39
A28: MEDELLIN | B28: =VLOOKUP(A28,'CENTRO DE COSTOS'!A:D,4,FALSE) -> JUAN SEBASTIÁN RÍOS CASTRILLÓN | C28: =VLOOKUP(A28,'CENTRO DE COSTOS'!A:C,2,FALSE) -> 0004-0005 | D28: 5079 | E28: TA-25-684795 | F28: FO-25-1050326 | G28: 45807 | H28: 45812 | I28: 45807 | J28: 45817 | K28: 45817 | L28: ANTIOQUIA | M28: BARBOSA | N28: BARRIO BARBOSA AUTOPISTA BARBOSA | O28: 79623 | P28: CB CRECIMIENTO - NUEVO | Q28: APERTURA | R28: REDEBAN | S28: UNO A UNO | T28: UNO A UNO | U28: EJECUTADO | V28: 30-05 SE REALIZA LLAMADA AL CLIENTE, SE HABLA CON LA SRA LIZETH MARIANA GALINDO ORTIZ, SE VALIDA DIRECCIÓN OK, CANAL OK, DISPONIBILIDAD TOTAL, LLAMAR EL DÍA LA INSTALACIÓN PARA CONFIRMAR VISITA, AVISO EXTERIOR ALTURA APROX DONDE EL TECNICO LO VEA CONVENIENTE METROS; TOMACORRIENTE CERCANO: SI; TIENE CABINA DE SEGURIDAD: NO 4/6/2025 LLEGAMOS A SITIO ENCONTRANDO OTRO PUNTO CERCANO A 30 METROS CODIGO 49691 PTM BARBOSA DROGUERÍA SE ESCALA CASO POR CERCANÍA DE 2 PUNTOS UNO DE AGREGADOR Y OTRO UNO A UNO. 05-06 ENTIDAD APRUEBA INSTALACIÓN 9/6/2025 SE REALIZA INSTALACIÓN DE CORRESPONSAL, SE INSTALAN EQUIPOS CON PRUEBAS EXITOSAS, SE CAPACITA Y SE EVALÚA AL CLIENTE, SE INSTALA PUBLICIDAD COMPLETA, CB QUEDA OPERATIVO. PLATAFORMA SOMOS BANCOLOMBIA CON CORREO ERRÓNEO, SE CAPACITA CON USUARIO DE PRUEBA | W28: BADEL ACUÑA LUIS ALBERTO | X28: SXUZZ149 | Y28: 1173964 | Z28: N/A | AA28: 529350 | AB28: N/A | AC28: 40 ROLLOS | AD28: =VLOOKUP(D28,TIPOLOGIAS!A:F,6,0) -> TIPO II | AE28: =VLOOKUP(D28,TIPOLOGIAS!A:F,5,0) -> TERRESTRE | AF28: VISITA _TECNICA | AG28: 0 | AH28: 0 | AI28: 0 | AJ28: 0 | AK28: 1 | AL28: =IF(AD28="TIPO I",'BASE LIQUIDACION'!$D$3,IF(AD28="TIPO II",'BASE LIQUIDACION'!$D$4,IF(AD28="TIPO III",'BASE LIQUIDACION'!$D$5,'BASE LIQUIDACION'!$D$7))) -> 134410.39 | AM28: =AG28*'BASE LIQUIDACION'!$B$12+AH28*'BASE LIQUIDACION'!$B$11+AI28*'BASE LIQUIDACION'!$B$13+AJ28*'BASE LIQUIDACION'!$B$14+AK28*AL28 -> 134410.39
A29: BARRANQUILLA | B29: =VLOOKUP(A29,'CENTRO DE COSTOS'!A:D,4,FALSE) -> JOSE MAURICIO HERNANDEZ ROJAS | C29: =VLOOKUP(A29,'CENTRO DE COSTOS'!A:C,2,FALSE) -> 0004-0001 | D29: 8001 | E29: TA-25-684828 | F29: FO-25-1035630 | G29: 45807 | H29: 45812 | I29: 45807 | J29: 45812 | K29: 45812 | L29: ATLANTICO | M29: BARRANQUILLA | N29: BARRIO LA VICTORIA BARRANQUILLA 2 | O29: 79597 | P29: CB CRECIMIENTO - NUEVO | Q29: APERTURA | R29: REDEBAN | S29: UNO A UNO | T29: UNO A UNO | U29: EJECUTADO | V29: 30-05 SE REALIZA LLAMADA AL CLIENTE, SE HABLA CON LA SR LUIS GUILLERMO SERJE RAPELLO VALIDA DIRECCIÓN OK, DISPONIBILIDAD TOTAL, LLAMAR EL DÍA LA INSTALACIÓN PARA CONFIRMAR VISITA, AVISO EXTERIOR ALTURA APROX 2.00 METROS; TOMACORRIENTE CERCANO: SI; TIENE CABINA DE SEGURIDAD: USUARIO TIENE REJA 03-06 SE LOGRA COMUNICACION VÍA WASHAP AL NÚMERO 3008485338, Y ME CONTESTA LA SEÑORA MARIANELA CANTILLO, CON QUIÉN SE ACUERDA LLEGAR TIPO 11 AM PARA ATENDERME, SE LLAMA A SITIO, PERO NO CONTESTAN WASHAP, NO LE ENTRAN MENSAJES NI LLAMADAS , ES UN CONJUNTO CERRADO, PERO ME DICE EL VIGILANTE QUE ESTÁ A LA VUELTA ,SE DA LA VUELTA A LA MANZANA PERO NO SE LOGRA VER EL LOCAL, ME VOY A OTRO SITIO HACER OTRA ACTIVIDAD, Y AHORA EN LAS HORAS DE LA TARDE REGRESO, ESTÁ VEZ SI ME CONTESTAN LOS MENSAJES INDICANDOME QUE DÉBIDO AL PARO EN FUNDACIÓN, NO PUDO REGRESAR, QUE POR FAVOR REAGENDE LA VISITA PARA MAÑANA 4 DE JUNIO 4/6/2025 SE REALIZA INSTALACIÓN DE CORRESPONSAL, SE INSTALAN EQUIPOS CON PRUEBAS EXITOSAS, SE CAPACITA Y SE EVALÚA AL CLIENTE, SE INSTALA PUBLICIDAD COMPLETA, CB QUEDA OPERATIVO. USUARIO SOMOS BANCOLOMBIA ACTIVO | W29: DE AVILA SIADES ALBERTO ENRIQUE | X29: SXUZZ123 | Y29: 1045719 | Z29: N/A | AA29: 905781 | AB29: N/A | AC29: 40 ROLLOS | AD29: =VLOOKUP(D29,TIPOLOGIAS!A:F,6,0) -> TIPO I | AE29: =VLOOKUP(D29,TIPOLOGIAS!A:F,5,0) -> TERRESTRE | AF29: VISITA _TECNICA | AG29: 0 | AH29: 0 | AI29: 0 | AJ29: 0 | AK29: 1 | AL29: =IF(AD29="TIPO I",'BASE LIQUIDACION'!$D$3,IF(AD29="TIPO II",'BASE LIQUIDACION'!$D$4,IF(AD29="TIPO III",'BASE LIQUIDACION'!$D$5,'BASE LIQUIDACION'!$D$7))) -> 44559.985 | AM29: =AG29*'BASE LIQUIDACION'!$B$12+AH29*'BASE LIQUIDACION'!$B$11+AI29*'BASE LIQUIDACION'!$B$13+AJ29*'BASE LIQUIDACION'!$B$14+AK29*AL29 -> 44559.985
