Workbook
Name A: #REF!
Name A: #REF!
Name ACTIVIDAD: [1]Hoja2!$P$2:$P$30
Name Actividad: [2]Formulas!$H$2:$H$5000
Name Analistas: '[3]Listas Desplegables'!$T$2:$T$7
Name arearesponsable: '[4]Listas desplegables'!$BB$2:$BB$100
Name CCO: [5]Tecnicos!$A$2:$A$1000
Name Clientes: [6]Clientes!$A$2:$A$100
Name Clientes: [2]Clientes!$A$2:$A$100
Name COORDINADOR: [1]Hoja2!$D$2:$D$30
Name Coordinadores: [7]Coordinadores!$A$2:$A$1000
Name Coordinadores: [2]Coordinadores!$A$2:$A$1000
Name DOCUMENTADOR: [1]Hoja2!$A$2:$A$30
Name ES: [1]Hoja2!$K$2:$K$30
Name ESS: [1]Hoja2!$K$2:$K$30
Name Estado: [6]Formulas!$K$2:$K$5000
Name Estado: [2]Formulas!$K$2:$K$5000
Name ESTADOACTIVIDAD: [1]Hoja2!$M$2:$M$30
Name ESTADOS: '[8]Listas desplegables'!$B$1:$D$1
Name ESTADOS: '[9]Listas desplegables'!$B$1:$D$1
Name ESTADOSCIERRES: '[10]lista desplegable'!$CX$1:$DA$1
Name Facturacion: '[11]Listas desplegables'!$AO$1:$AR$1
Name FACTURACIÓN: '[8]Listas desplegables'!$Y$1:$AB$1
Name FACTURACIÓN: '[9]Listas desplegables'!$Y$1:$AB$1
Name falla: #REF!
Name Fallas: '[12]Listas desplegables'!$F$2:$L$2
Name Fallas: '[13]Listas desplegables'!$F$2:$L$2
Name Grupo_Falla: '[14]Listas Desplegables'!$CH$2:$CH$5
Name Grupo_Falla: '[15]Listas Desplegables'!$CH$2:$CH$5
Name inconservmanager: '[16]Listas desplegables'!$BC$2:$BC$100
Name inconservmanager: '[4]Listas desplegables'!$BC$2:$BC$100
Name INCUMPLIMIENTO: '[4]Listas desplegables'!$AK$1:$AN$1
Name INCUMPLIMIENTO: '[17]Listas desplegables'!$AT$1:$AX$1
Name LISTA: [18]Dptos!$A$1139:$A$1171
Name LISTA: [19]Dptos!$A$1139:$A$1171
Name LISTA2: #REF!
Name LISTA2: [20]Hoja3!$A$1:$A$26
Name LOLO: [21]Coordinadores!$A$2:$A$1000
Name solicitudes: '[11]Listas desplegables'!$U$1:$AF$1
Name solicitudes: '[11]Listas desplegables'!$U$1:$AF$1
Name Tecnicos: [6]Tecnicos!$A$2:$A$1000
Name Tecnicos: [2]Tecnicos!$A$2:$A$1000
Name Version: [22]Formulas!$I$2:$I$3
Name Version: [2]Formulas!$I$2:$I$3

Sheet RESUMEN
A1: =CONCATENATE("TOTAL GENERAL MES ",A3) -> TOTAL GENERAL MES JUNIO DE 2025 | J1: FACTURACIÓN CORRESPONSALES BANCARIOS TIQUIETES AEREOS
A2: MES | B2: NIT Proveedor | C2: Nombre Proveedor (el proveedor ya debe estar creado para el Grupo Bancolombia) | D2: Concepto Facturación | E2: Público al que le instalo la publicidad | F2: No. personas impactadas | G2: Valor a Facturar sin IVA | H2: Valor a Facturar con IVA | J2: CONCEPTOS | K2: TRAYECTOS | L2: TOTAL | M2: % Administración | N2: TOTAL
A3: JUNIO DE 2025 | B3: 811013990-5 | C3: LINEA COMUNICACIONES S.A.S | D3: INSTALACION PUBLICIDAD APERTURAS CORRESPONSALES BANCARIOS | E3: OPERADOR DEL CORRESPONSAL BANCARIO | F3: =COUNTA('PUBLICIDAD APERTURAS'!A:A)-1 -> 490 | G3: ='PUBLICIDAD APERTURAS'!AO492 -> 1.0808399e+08 | H3: =G3*1.19 -> 1.2861994e+08 | J3: APERTURA 79313 | K3: PASTO - OLAYA HERRERA - PASTO | L3: 300000 | M3: =L3*0.12 -> 36000 | N3: =L3+M3 -> 336000
A4: =A3 -> JUNIO DE 2025 | B4: 811013990-5 | C4: LINEA COMUNICACIONES S.A.S | D4: ORDENES DE CAMBIO POR DEMANDA | E4: OPERADOR DEL CORRESPONSAL BANCARIO | F4: =COUNTA('PUBLICIDAD OC'!A:A)-1 -> 118 | G4: ='PUBLICIDAD OC'!AE120 -> 29749553 | H4: =G4*1.19 -> 35401968 | J4: APERTURA 79563 - 79643 | K4: MEDELLIN - ISTMINA - MEDELLIN | L4: 850800 | M4: =L4*0.12 -> 102096 | N4: =L4+M4 -> 952896
A5: =A4 -> JUNIO DE 2025 | B5: 811013990-5 | C5: LINEA COMUNICACIONES S.A.S | D5: TRAYECTOS ESPECIALES OC | E5: OPERADOR DEL CORRESPONSAL BANCARIO | F5: 8 | G5: =N11 -> 4454788.8 | H5: =G5*1.19 -> 5301198.7 | J5: APERTURA 79657 | K5: CALI - TIMBIQUI - CALI | L5: 620900 | M5: =L5*0.12 -> 74508 | N5: =L5+M5 -> 695408
A6: TOTAL A FACTURAR | F6: =SUM(F3:F5) -> 616 | G6: =SUM(G3:G5) -> 1.4228833e+08 | H6: =SUM(H3:H5) -> 1.6932311e+08 | J6: APERTURA 79779 | K6: MEDELLIN - ISTMINA - MEDELLIN | L6: 654800 | M6: =L6*0.12 -> 78576 | N6: =L6+M6 -> 733376
J7: APERTURA 79818 | K7: MEDELLIN - NUQUI - MEDELLIN | L7: 506100 | M7: =L7*0.12 -> 60732 | N7: =L7+M7 -> 566832
J8: APERTURA 79909 - 79910 | K8: BUCARAMANGA - SANTA ROSA DEL SUR - BUCARAMANGA | L8: 300000 | M8: =L8*0.12 -> 36000 | N8: =L8+M8 -> 336000
J9: APERTURA 80036 | K9: MEDELLIN - NUQUI - MEDELLIN | L9: 345740 | M9: =L9*0.12 -> 41488.8 | N9: =L9+M9 -> 387228.8
J10: OC PUBLICIDAD 77228 | K10: MEDELLIN - QUIBDO - MEDELLIN | L10: 399150 | M10: =L10*0.12 -> 47898 | N10: =L10+M10 -> 447048
J11: TOTAL | L11: =SUM(L3:L10) -> 3977490 | M11: =SUM(M3:M10) -> 477298.8 | N11: =SUM(N3:N10) -> 4454788.8

Sheet BASE DE LIQUIDACION 2025
A1: TARIFAS AÑO 2025 | G1: TARIFAS AÑO 2025 | N1: Incremento 2025
A2: TIPOLOGÍA | B2: Instalación de avisos internos | C2: Instalación de avisos EXTERNOS | D2: Transporte de señalización y aviso de 1,50m x 50 cm. | E2: Total Valor Actividad | G2: ORDENES DE CAMBIO | N2: 0.052
A3: TIPO I | B3: =10695.08*(1+$N$2) -> 11251.224 | C3: =120073.31*(1+$N$2) -> 126317.12 | D3: =54574.12*(1+$N$2) -> 57411.974 | E3: =185342.51*(1+$N$2) -> 194980.32 | G3: Tipificación | H3: Descripción | I3: Dia actividad | J3: Transporte | K3: Envio operador Logistico | L3: Gestión telefónica
A4: TIPO II - TIPO III - TIPO IV | B4: =10695.08*(1+$N$2) -> 11251.224 | C4: =120073.31*(1+$N$2) -> 126317.12 | D4: =105331.06*(1+$N$2) -> 110808.28 | E4: =236099.45*(1+$N$2) -> 248376.62 | G4: Tipo I | H4: Metropolitano | I4: =91255.89*(1+$N$2) -> 96001.196 | J4: =54574.12*(1+$N$2) -> 57411.974 | K4: =53547.34*(1+$N$2) -> 56331.802 | L4: =36031.04*(1+$N$2) -> 37904.654
G5: Tipo II | H5: Hasta 3 horas | I5: =221348.48*(1+$N$2) -> 232858.6 | J5: =105331.06*(1+$N$2) -> 110808.28 | K5: =53547.34*(1+$N$2) -> 56331.802 | L5: =36031.04*(1+$N$2) -> 37904.654
G6: Tipo III | H6: De 3 a 5 horas | I6: =327732.48*(1+$N$2) -> 344774.57 | J6: =105331.06*(1+$N$2) -> 110808.28 | K6: =53547.34*(1+$N$2) -> 56331.802 | L6: =36031.04*(1+$N$2) -> 37904.654
G7: Tipo IV | H7: Más de 5 horas | I7: =521514.86*(1+$N$2) -> 548633.63 | J7: =105331.06*(1+$N$2) -> 110808.28 | K7: =53547.34*(1+$N$2) -> 56331.802 | L7: =36031.04*(1+$N$2) -> 37904.654
G8: Destino Aereo* | H8: Viaje en Avión | I8: =521514.86*(1+$N$2) -> 548633.63 | J8: =105331.06*(1+$N$2) -> 110808.28 | K8: =53547.34*(1+$N$2) -> 56331.802 | L8: =36031.04*(1+$N$2) -> 37904.654
G9: * donde se requiera transporte aéreo o fluvial se factura adicional a tarifa TIPO IV el valor del tiquete + el 12% de admon

Sheet Tabla dinámica
A2: PUBLICIDAD APERTURAS | J2: NOMBRE CC | K2: Suma de VALOR | L2: Suma de VALOR2
A3: COORDINADOR | B3: CENTRO DE COSTOS LÍNEACOM | C3: % | D3: $ | E3: NOMBRE CC | F3: VALOR | J3: Redeban Centro ( Bogotá) | K3: 21894105 | L3: 0.15884454
A4: DIEGO FERNANDO HENAO CARDONA | B4: 0004-0002 | C4: 0.059059374 | D4: 6383372.6 | E4: =VLOOKUP(B4,'CENTRO DE COSTOS'!B:C,2,0) -> Redeban Eje Cafetero (Pereira) | F4: =D4 -> 6383372.6 | J4: Redeban Costa (Barranqullla) | K4: 19197961 | L4: 0.13928367
B5: 0004-0003 | C5: 0.1796278 | D5: 19414889 | E5: =VLOOKUP(B5,'CENTRO DE COSTOS'!B:C,2,0) -> Redeban Suroccidente (Cali) | F5: =D5 -> 19414889 | J5: Redeban Eje Cafetero (Pereira) | K5: 7414373.3 | L5: 0.053792228
A6: JOSE MAURICIO HERNANDEZ ROJAS | B6: 0004-0001 | C6: 0.14537167 | D6: 15712349 | E6: =VLOOKUP(B6,'CENTRO DE COSTOS'!B:C,2,0) -> Redeban Costa (Barranqullla) | F6: =D6 -> 15712349 | J6: Redeban Noroccidente (Medellín) | K6: 27023029 | L6: 0.19605554
A7: JUAN SEBASTIÁN RÍOS CASTRILLÓN | B7: 0004-0005 | C7: 0.19874469 | D7: 21481119 | E7: =VLOOKUP(B7,'CENTRO DE COSTOS'!B:C,2,0) -> Redeban Noroccidente (Medellín) | F7: =D7 -> 21481119 | J7: Redeban Oriente (Otros) | K7: 17023112 | L7: 0.12350486
A8: KEVIN ALEXIS CORZO BUSTOS | B8: 0004-0007 | C8: 0.12701007 | D8: 13727755 | E8: =VLOOKUP(B8,'CENTRO DE COSTOS'!B:C,2,0) -> Redeban Oriente (Otros) | F8: =D8 -> 13727755 | J8: Redeban Santander | K8: 22008202 | L8: 0.15967232
A9: MIGUEL JULIÁN HERNÁNDEZ GUARÍN | B9: 0004-0008 | C9: 0.14295883 | D9: 15451560 | E9: =VLOOKUP(B9,'CENTRO DE COSTOS'!B:C,2,0) -> Redeban Santander | F9: =D9 -> 15451560 | J9: Redeban Suroccidente (Cali) | K9: 23272758 | L9: 0.16884684
A10: WILLIAM ASDRUBAL ROZO ROZO | B10: 0004-0004 | C10: 0.14722757 | D10: 15912943 | E10: =VLOOKUP(B10,'CENTRO DE COSTOS'!B:C,2,0) -> Redeban Centro ( Bogotá) | F10: =D10 -> 15912943 | J10: Total general | K10: 1.3783354e+08 | L10: 1
A11: Total general | C11: 1 | D11: 1.0808399e+08
A15: COORDINADOR | B15: CENTRO DE COSTOS LÍNEACOM | C15: % | D15: $ | E15: NOMBRE CC | F15: VALOR
A16: DIEGO FERNANDO HENAO CARDONA | B16: 0004-0002 | C16: 0.034656004 | D16: 1031000.6 | E16: =VLOOKUP(B16,'CENTRO DE COSTOS'!B:C,2,0) -> Redeban Eje Cafetero (Pereira) | F16: =D16 -> 1031000.6
B17: 0004-0003 | C17: 0.12967824 | D17: 3857869.6 | E17: =VLOOKUP(B17,'CENTRO DE COSTOS'!B:C,2,0) -> Redeban Suroccidente (Cali) | F17: =D17 -> 3857869.6
A18: JOSE MAURICIO HERNANDEZ ROJAS | B18: 0004-0001 | C18: 0.11716517 | D18: 3485611.4 | E18: =VLOOKUP(B18,'CENTRO DE COSTOS'!B:C,2,0) -> Redeban Costa (Barranqullla) | F18: =D18 -> 3485611.4
A19: JUAN SEBASTIÁN RÍOS CASTRILLÓN | B19: 0004-0005 | C19: 0.18628549 | D19: 5541910.2 | E19: =VLOOKUP(B19,'CENTRO DE COSTOS'!B:C,2,0) -> Redeban Noroccidente (Medellín) | F19: =D19 -> 5541910.2
A20: KEVIN ALEXIS CORZO BUSTOS | B20: 0004-0007 | C20: 0.11076999 | D20: 3295357.7 | E20: =VLOOKUP(B20,'CENTRO DE COSTOS'!B:C,2,0) -> Redeban Oriente (Otros) | F20: =D20 -> 3295357.7
A21: MIGUEL JULIÁN HERNÁNDEZ GUARÍN | B21: 0004-0008 | C21: 0.22039463 | D21: 6556641.7 | E21: =VLOOKUP(B21,'CENTRO DE COSTOS'!B:C,2,0) -> Redeban Santander | F21: =D21 -> 6556641.7
A22: WILLIAM ASDRUBAL ROZO ROZO | B22: 0004-0004 | C22: 0.20105048 | D22: 5981162 | E22: =VLOOKUP(B22,'CENTRO DE COSTOS'!B:C,2,0) -> Redeban Centro ( Bogotá) | F22: =D22 -> 5981162
A23: Total general | C23: 1 | D23: 29749553

Sheet PUBLICIDAD APERTURAS
A1: CIUDAD | B1: COORDINADOR | C1: CENTRO DE COSTOS LÍNEACOM | D1: CODIGO DANE | E1: TA | F1: FO | G1: FECHA LISTA | H1: FECHA LIMITE | I1: FECHA SOLICITUD DE LA ACTIVIDAD | J1: FECHA INICIO DE LA ACTIVIDAD | K1: FECHA ULTIMA ACTUALIZACION | L1: DEPARTAMENTO | M1: CIUDAD | N1: NOMBRE PUNTO | O1: CÓDIGO PUNTO | P1: TIPO DE APERTURA | Q1: ACTIVIDAD | R1: RED | S1: FORMATO | T1: CADENA | U1: ESTADO | V1: OBSERVACIONES CLIENTE | W1: NOMBRE DEL TECNICO | X1: TERMINALES | Y1: PLACA DATAFONOS INSTALADOS | Z1: PLACA DATAFONOS RETIRADOS | AA1: PLACA LECTOR INSTALADO | AB1: PLACA LECTOR RETIRADO | AC1: OBSERVACION ESTANDAR | AD1: PRIMER CAUSAL DE INCUMPLIMIENTO | AE1: CANTIDAD ROLLOS ENTREGADOS | AF1: TIPIFICACION | AG1: TIPO DE TRAYECTO | AH1: FORMA DE ATENCIÓN | AI1: Flanger, Display Legal, Display Carta o Tabloide | AJ1: Instalación de avisos EXTERNOS | AK1: TRANSPORTE DE AVISO POR INSTALACION O POR NO INSTALACION (IDA-REGRESO) | AL1: VALOR Flanger, Separador, Sticker, Display | AM1: VALOR Instalación de avisos EXTERNOS | AN1: VALOR TRANSPORTE DE AVISO | AO1: VALOR TOTAL INSTALACION DE PUBLICIDAD
A2: PASTO | B2: =VLOOKUP(A2,'CENTRO DE COSTOS'!A:D,4,FALSE) -> DIEGO FERNANDO HENAO CARDONA | C2: =VLOOKUP(A2,'CENTRO DE COSTOS'!A:D,2,FALSE) -> 0004-0003 | D2: 52490 | E2: TA-25-634237 | F2: FO-25-955291 | G2: 45796 | H2: 45805 | I2: 45796 | J2: 45813 | K2: 45813 | L2: NARIÑO | M2: OLAYA HERRERA | N2: BARRIO SAN MARTIN 2 CORREGIMIENTO DE BOAS DE SATINGA OLAYA HERRERA | O2: 79313 | P2: CB CRECIMIENTO - NUEVO | Q2: APERTURA | R2: REDEBAN | S2: UNO A UNO | T2: UNO A UNO | U2: EJECUTADO | V2: 19-05-2025 SE REALIZA LLAMADA AL CLIENTE, SE HABLA CON LA SRA ALEIDA RIASCOS PERLAZA, SE VALIDA DIRECCIÓN OK, CANAL OK, DISPONIBILIDAD TOTAL, LLAMAR EL DÍA LA INSTALACIÓN PARA CONFIRMAR VISITA, AVISO EXTERIOR ALTURA APROX NO TIENE CONOCIMIENTO DE MEDIDAS; TOMACORRIENTE CERCANO: SI; TIENE CABINA DE SEGURIDAD:NO // CONTACTO REALIZADO POR WHATSAPP 28-05 SE REPROGRAMA VISITA PARA LA PRÓXIMA SEMANA SEBIDO A QUE NO SE LOGRO CONSEGUIR TRANSPORTE INTERMUNICIPAL DE CALI A BUENAVENTURA POR CIERRE DE LA VIA 05-06 SE REALIZA INSTALACIÓN DE CORRESPONSAL, SE INSTALAN EQUIPOS CON PRUEBAS EXITOSAS, SE CAPACITA Y SE EVALÚA AL CLIENTE, SE INSTALA PUBLICIDAD COMPLETA, CB QUEDA OPERATIVO. USUARIO SOMOS BANCOLOMBIA ACTIVO | W2: PAREDES CASTILLO DIEGO | X2: A4WZZ840 | Y2: 1169751 | Z2: N/A | AA2: 860310 | AB2: N/A | AC2: FACTOR/EXTERNO | AD2: TRANSPORTE | AE2: 40 ROLLOS | AF2: TIPO IV ESPECIAL | AG2: FLUVIAL | AH2: VISITA_TÉCNICA | AI2: 1 | AJ2: 1 | AK2: 1 | AL2: =IF(AF2="TIPO I",'BASE DE LIQUIDACION 2025'!$B$3,'BASE DE LIQUIDACION 2025'!$B$4) -> 11251.224 | AM2: =IF(AF2="TIPO I",'BASE DE LIQUIDACION 2025'!$C$3,'BASE DE LIQUIDACION 2025'!$C$4) -> 126317.12 | AN2: =IF(AF2="TIPO I",'BASE DE LIQUIDACION 2025'!$D$3,'BASE DE LIQUIDACION 2025'!$D$4) -> 110808.28 | AO2: =AL2*AI2+AJ2*AM2+AK2*AN2 -> 248376.62
A3: BUCARAMANGA | B3: =VLOOKUP(A3,'CENTRO DE COSTOS'!A:D,4,FALSE) -> MIGUEL JULIÁN HERNÁNDEZ GUARÍN | C3: =VLOOKUP(A3,'CENTRO DE COSTOS'!A:D,2,FALSE) -> 0004-0008 | D3: 68276 | E3: TA-25-669597 | F3: FO-25-979659 | G3: 45800 | H3: 45804 | I3: 45800 | J3: 45811 | K3: 45811 | L3: SANTANDER | M3: FLORIDABLANCA | N3: BARRIO CASCO ANTIGUO FLORIDABLANCA FLORIDABLANCA | O3: 79387 | P3: CAMBIO DE RAZON SOCIAL | Q3: APERTURA | R3: REDEBAN | S3: UNO A UNO | T3: UNO A UNO | U3: EJECUTADO | V3: 23-05 SE REALIZA LLAMADA AL CLIENTE, SE HABLA CON LA SRA CARLOS ANDRES MORALES OTERO SE VALIDA DIRECCIÓN OK, CANAL OK, DISPONIBILIDAD TOTAL, LLAMAR EL DÍA LA INSTALACIÓN PARA CONFIRMAR VISITA - CAMBIO DE RAZON SOCIAL - USUARIO SOLICITA FECHA PARA EL MIERCOLES 28-05 SE ESTABLECE COMUNICACIÓN CON EL SEÑOR CARLOS AL NÚMERO 3183832689 QUIEN SOLICITA QUE SE REPROGRAME ACTIVIDAD PARA EL DIA 2 DE JUNIO DEL AÑO EN CURSO DEBIDO A QUE SE ENCUENTRA REALIZAN UNOS EXÁMENES Y NO NOS PUEDE ATENDER 31-05 SE ESTABLECE COMUNICACIÓN CON EL SEÑOR CARLOS AL NÚMERO 3183832689 QUIEN SOLICITA QUE SE REPROGRAME ACTIVIDAD PARA EL DIA 3 DE JUNIO DEL AÑO EN CURSO DEBIDO A QUE SE ENCUENTRA REALIZAN UNOS EXÁMENES Y NO NOS PUEDE ATENDER 3/6/2025 SE REALIZA INSTALACIÓN DE CORRESPONSAL, SE INSTALAN EQUIPOS CON PRUEBAS EXITOSAS, SE CAPACITA Y SE EVALÚA AL CLIENTE, SE INSTALA PUBLICIDAD COMPLETA, CB QUEDA OPERATIVO. USUARIO SOMOS BANCOLOMBIA ACTIVO | W3: BARRERA ORTEGA MARLON STWAR | X3: 10XZZ925-SXXZZ344 | Y3: 989054-1016076 | Z3: 793883 | AA3: 1103341-893140 | AB3: N/A | AC3: USUARIO | AD3: SIN DISPONIBILIDAD | AE3: 40 ROLLOS | AF3: TIPO I | AG3: TERRESTRE | AH3: VISITA_TÉCNICA | AI3: 1 | AJ3: 1 | AK3: 1 | AL3: =IF(AF3="TIPO I",'BASE DE LIQUIDACION 2025'!$B$3,'BASE DE LIQUIDACION 2025'!$B$4) -> 11251.224 | AM3: =IF(AF3="TIPO I",'BASE DE LIQUIDACION 2025'!$C$3,'BASE DE LIQUIDACION 2025'!$C$4) -> 126317.12 | AN3: =IF(AF3="TIPO I",'BASE DE LIQUIDACION 2025'!$D$3,'BASE DE LIQUIDACION 2025'!$D$4) -> 57411.974 | AO3: =AL3*AI3+AJ3*AM3+AK3*AN3 -> 194980.32
A4: VILLAVICENCIO | B4: =VLOOKUP(A4,'CENTRO DE COSTOS'!A:D,4,FALSE) -> KEVIN ALEXIS CORZO BUSTOS | C4: =VLOOKUP(A4,'CENTRO DE COSTOS'!A:D,2,FALSE) -> 0004-0007 | D4: 50124 | E4: TA-25-669663 | F4: FO-25-979669 | G4: 45800 | H4: 45804 | I4: 45800 | J4: 45812 | K4: 45812 | L4: META | M4: CABUYARO | N4: BARRIO CENTRO CABUYARO 5 | O4: 79356 | P4: CB CRECIMIENTO - NUEVO | Q4: APERTURA | R4: REDEBAN | S4: UNO A UNO | T4: UNO A UNO | U4: EJECUTADO | V4: 23-05 SE REALIZA LLAMADA AL CLIENTE, SE HABLA CON LA SR JULIETTE DANIELA QUIJANO ORTIZ SE VALIDA DIRECCIÓN OK, CANAL OK, DISPONIBILIDAD TOTAL, LLAMAR EL DÍA LA INSTALACIÓN PARA CONFIRMAR VISITA, AVISO EXTERIOR ALTURA APROX 2.50 METROS; TOMACORRIENTE CERCANO: SI; TIENE CABINA DE SEGURIDAD: NO 27-05 DE REALIZA CONTACTO TELEFÓNICO 3208738350 CON LA SEÑORA JULIETTE QUIEN MANIFIESTA EL DÍA DE HOY 27 MAYO NO NOS PUEDE ATENDER. SOLICITA VISITA PARA EL DÍA MARTES 3 DE JUNIO 03-06 SE PROGR 4/6/2025 SE REALIZA INSTALACIÓN DE CORRESPONSAL, SE INSTALAN EQUIPOS CON PRUEBAS EXITOSAS, SE CAPACITA Y SE EVALÚA AL CLIENTE, SE INSTALA PUBLICIDAD COMPLETA, CB QUEDA OPERATIVO. USUARIO SOMOS BANCOLOMBIA ACTIVO | W4: CASTRILLON URREA LONDIER LEANDRO | X4: 10XZZ894 | Y4: 859272 | Z4: N/A | AA4: 915631 | AB4: N/A | AC4: USUARIO | AD4: SIN DISPONIBILIDAD | AE4: 40 ROLLOS | AF4: TIPO III | AG4: TERRESTRE | AH4: VISITA_TÉCNICA | AI4: 1 | AJ4: 1 | AK4: 1 | AL4: =IF(AF4="TIPO I",'BASE DE LIQUIDACION 2025'!$B$3,'BASE DE LIQUIDACION 2025'!$B$4) -> 11251.224 | AM4: =IF(AF4="TIPO I",'BASE DE LIQUIDACION 2025'!$C$3,'BASE DE LIQUIDACION 2025'!$C$4) -> 126317.12 | AN4: =IF(AF4="TIPO I",'BASE DE LIQUIDACION 2025'!$D$3,'BASE DE LIQUIDACION 2025'!$D$4) -> 110808.28 | AO4: =AL4*AI4+AJ4*AM4+AK4*AN4 -> 248376.62
A5: CALI | B5: =VLOOKUP(A5,'CENTRO DE COSTOS'!A:D,4,FALSE) -> DIEGO FERNANDO HENAO CARDONA | C5: =VLOOKUP(A5,'CENTRO DE COSTOS'!A:D,2,FALSE) -> 0004-0003 | D5: 19397 | E5: TA-25-680398 | F5: FO-25-1006223 | G5: 45805 | H5: 45807 | I5: 45805 | J5: 45811 | K5: 45811 | L5: CAUCA | M5: LA VEGA | N5: BARRIO SANTA MARIA LA VEGA | O5: 79561 | P5: CB CRECIMIENTO - NUEVO | Q5: APERTURA | R5: REDEBAN | S5: UNO A UNO | T5: UNO A UNO | U5: EJECUTADO | V5: 28-05-2025 SE REALIZA LLAMADA AL CLIENTE, SE HABLA CON EL SR LEINER ALEJANDRO GARCIA MAMIAN SE VALIDA DIRECCIÓN OK, CANAL OK, DISPONIBILIDAD TOTAL, LLAMAR EL DÍA LA INSTALACIÓN PARA CONFIRMAR VISITA, AVISO EXTERIOR ALTURA APROX 1,60 METROS; TOMACORRIENTE CERCANO: SI; TIENE CABINA DE SEGURIDAD: NO // CONTACTO REALIZADO POR LA APP 30-05 SE REALIZA LLAMADA CELULAR AL SEÑOR LEINER Y SE LE INFORMA QUE POR TEMAS DE EL PARO ARMADO NO SE CUENTA CON TRANSPORTE A LA ZONA SE REPROGRAMA VISITA CON EL CB PARA EL DÍA MARTES 3/6/2025 SE REALIZA INSTALACIÓN DE CORRESPONSAL, SE INSTALAN EQUIPOS CON PRUEBAS EXITOSAS, SE CAPACITA Y SE EVALÚA AL CLIENTE, SE INSTALA PUBLICIDAD COMPLETA, CB QUEDA OPERATIVO. USUARIO SOMOS BANCOLOMBIA ACTIVO | W5: GIMBUEL LASSO LUIS GERMAN | X5: LMUZZ995 | Y5: 761185 | Z5: N/A | AA5: 933206 | AB5: N/A | AC5: FACTOR/EXTERNO | AD5: PARO | AE5: 40 ROLLOS | AF5: TIPO IV | AG5: TERRESTRE | AH5: VISITA_TÉCNICA | AI5: 1 | AJ5: 1 | AK5: 1 | AL5: =IF(AF5="TIPO I",'BASE DE LIQUIDACION 2025'!$B$3,'BASE DE LIQUIDACION 2025'!$B$4) -> 11251.224 | AM5: =IF(AF5="TIPO I",'BASE DE LIQUIDACION 2025'!$C$3,'BASE DE LIQUIDACION 2025'!$C$4) -> 126317.12 | AN5: =IF(AF5="TIPO I",'BASE DE LIQUIDACION 2025'!$D$3,'BASE DE LIQUIDACION 2025'!$D$4) -> 110808.28 | AO5: =AL5*AI5+AJ5*AM5+AK5*AN5 -> 248376.62
A6: APARTADO | B6: =VLOOKUP(A6,'CENTRO DE COSTOS'!A:D,4,FALSE) -> JUAN SEBASTIÁN RÍOS CASTRILLÓN | C6: =VLOOKUP(A6,'CENTRO DE COSTOS'!A:D,2,FALSE) -> 0004-0005 | D6: 27135 | E6: TA-25-680419 | F6: FO-25-1006269 | G6: 45805 | H6: 45807 | I6: 45805 | J6: 45814 | K6: 45814 | L6: CHOCO | M6: EL CANTON DEL SAN PABLO | N6: BARRIO AVENIDA 20 DE JULIO CARTON DEL SAN PABLO CHOCO EL CANTON DEL SAN PABLO | O6: 79580 | P6: CB CRECIMIENTO - NUEVO | Q6: APERTURA | R6: REDEBAN | S6: UNO A UNO | T6: UNO A UNO | U6: EJECUTADO | V6: 28-05-2025 SE REALIZA LLAMADA AL CLIENTE, SE HABLA CON LA SRA DORIS MARIA PALACIOS CORDOBA SE VALIDA DIRECCIÓN OK, CANAL OK, DISPONIBILIDAD TOTAL, LLAMAR EL DÍA LA INSTALACIÓN PARA CONFIRMAR VISITA, AVISO EXTERIOR ALTURA APROX 3 - 4 METROS; TOMACORRIENTE CERCANO: SI; TIENE CABINA DE SEGURIDAD: NO // CONTACTO REALIZADO POR LA APP 06-06 SE REALIZA INSTALACIÓN DE CORRESPONSAL, SE INSTALAN EQUIPOS CON PRUEBAS EXITOSAS, SE CAPACITA Y SE EVALÚA AL CLIENTE, SE INSTALA PUBLICIDAD COMPLETA, CB QUEDA OPERATIVO. USUARIO SOMOS BANCOLOMBIA ACTIVO | W6: ROBLEDO DIAZ ANDRES FELIPE | X6: LMVZZ014 | Y6: 792636 | Z6: N/A | AA6: 905838 | AB6: N/A | AC6: FACTOR/EXTERNO | AD6: TRANSPORTE | AE6: 40 ROLLOS | AF6: TIPO IV | AG6: TERRESTRE | AH6: VISITA_TÉCNICA | AI6: 1 | AJ6: 1 | AK6: 1 | AL6: =IF(AF6="TIPO I",'BASE DE LIQUIDACION 2025'!$B$3,'BASE DE LIQUIDACION 2025'!$B$4) -> 11251.224 | AM6: =IF(AF6="TIPO I",'BASE DE LIQUIDACION 2025'!$C$3,'BASE DE LIQUIDACION 2025'!$C$4) -> 126317.12 | AN6: =IF(AF6="TIPO I",'BASE DE LIQUIDACION 2025'!$D$3,'BASE DE LIQUIDACION 2025'!$D$4) -> 110808.28 | AO6: =AL6*AI6+AJ6*AM6+AK6*AN6 -> 248376.62
A7: PASTO | B7: =VLOOKUP(A7,'CENTRO DE COSTOS'!A:D,4,FALSE) -> DIEGO FERNANDO HENAO CARDONA | C7: =VLOOKUP(A7,'CENTRO DE COSTOS'!A:D,2,FALSE) -> 0004-0003 | D7: 52320 | E7: TA-25-680438 | F7: FO-25-1006318 | G7: 45805 | H7: 45807 | I7: 45805 | J7: 45811 | K7: 45811 | L7: NARIÑO | M7: GUAITARILLA | N7: BARRIO CENTRO GUAITARILLA | O7: 79558 | P7: CB CRECIMIENTO - NUEVO | Q7: APERTURA | R7: REDEBAN | S7: UNO A UNO | T7: UNO A UNO | U7: EJECUTADO | V7: 28-05 SE REALIZA LLAMADA AL CLIENTE, SE HABLA CON EL SR JOSE ARMANDO ROSERO MARTINEZ, SE VALIDA DIRECCIÓN OK, CANAL OK, DISPONIBILIDAD TOTAL, LLAMAR EL DÍA LA INSTALACIÓN PARA CONFIRMAR VISITA, AVISO EXTERIOR ALTURA APROX 2 METROS; TOMACORRIENTE CERCANO: SI; TIENE CABINA DE SEGURIDAD:SI //MODEN SE ENCUENTRA A 5 MEGTROS DE DISTANCIA DE DONDE VA SER INSTALADO EL DATAFONO 30-05 NO SE PUEDE NO SE LOGRA TRANSPORTE PARA EL MUNICIPIO DE GUAITARILLA DEBIDO A QUE ZONA NO HAY TRANSPORTE DISPONIBLE. SE VISITARÁ EL DÍA MARTES 03/06/2025 3/6/2025 SE REALIZA INSTALACIÓN DE CORRESPONSAL, SE INSTALAN EQUIPOS CON PRUEBAS EXITOSAS, SE CAPACITA Y SE EVALÚA AL CLIENTE, SE INSTALA PUBLICIDAD COMPLETA, CB QUEDA OPERATIVO. USUARIO SOMOS BANCOLOMBIA ACTIVO | W7: BOLAÑOS TABORDA JORGE ENRIQUE | X7: LMUZZ992 | Y7: 1115746 | Z7: N/A | AA7: 892665 | AB7: N/A | AC7: FACTOR/EXTERNO | AD7: TRANSPORTE | AE7: 40 ROLLOS | AF7: TIPO II | AG7: TERRESTRE | AH7: VISITA_TÉCNICA | AI7: 1 | AJ7: 1 | AK7: 1 | AL7: =IF(AF7="TIPO I",'BASE DE LIQUIDACION 2025'!$B$3,'BASE DE LIQUIDACION 2025'!$B$4) -> 11251.224 | AM7: =IF(AF7="TIPO I",'BASE DE LIQUIDACION 2025'!$C$3,'BASE DE LIQUIDACION 2025'!$C$4) -> 126317.12 | AN7: =IF(AF7="TIPO I",'BASE DE LIQUIDACION 2025'!$D$3,'BASE DE LIQUIDACION 2025'!$D$4) -> 110808.28 | AO7: =AL7*AI7+AJ7*AM7+AK7*AN7 -> 248376.62
A8: MEDELLIN | B8: =VLOOKUP(A8,'CENTRO DE COSTOS'!A:D,4,FALSE) -> JUAN SEBASTIÁN RÍOS CASTRILLÓN | C8: =VLOOKUP(A8,'CENTRO DE COSTOS'!A:D,2,FALSE) -> 0004-0005 | D8: 27361 | E8: TA-25-680473 | F8: FO-25-1006417 | G8: 45805 | H8: 45817 | I8: 45805 | J8: 45812 | K8: 45812 | L8: CHOCO | M8: ISTMINA | N8: BARRIO CUBIS SEC MESETA ALTA ISTMINA CHOCO ISTMINA | O8: 79563 | P8: CB CRECIMIENTO - NUEVO | Q8: APERTURA | R8: REDEBAN | S8: UNO A UNO | T8: UNO A UNO | U8: EJECUTADO | V8: 28-05 SE REALIZA LLAMADA AL CLIENTE, SE HABLA CON LA SRA JOAN AVENDAÑO DAZA SE VALIDA DIRECCIÓN OK, CANAL OK, DISPONIBILIDAD TOTAL, LLAMAR EL DÍA LA INSTALACIÓN PARA CONFIRMAR VISITA, AVISO EXTERIOR ALTURA APROX 2 METROS; TOMACORRIENTE CERCANO: SI; TIENE CABINA DE SEGURIDAD: SI 04-06 SE REALIZA INSTALACIÓN DE CORRESPONSAL, SE INSTALAN EQUIPOS CON PRUEBAS EXITOSAS, SE CAPACITA Y SE EVALÚA AL CLIENTE, SE INSTALA PUBLICIDAD COMPLETA, CB QUEDA OPERATIVO. USUARIO SOMOS BANCOLOMBIA ACTIVO. SE INSTALAN 10 MT DE CABLE UTP | W8: ROBLEDO DIAZ ANDRES FELIPE | X8: LMUZZ997 | Y8: 771855 | Z8: N/A | AA8: 1146028 | AB8: N/A | AC8: N/A | AD8: N/A | AE8: 40 ROLLOS | AF8: TIPO IV ESPECIAL | AG8: AEREO | AH8: VISITA_TÉCNICA | AI8: 1 | AJ8: 1 | AK8: 1 | AL8: =IF(AF8="TIPO I",'BASE DE LIQUIDACION 2025'!$B$3,'BASE DE LIQUIDACION 2025'!$B$4) -> 11251.224 | AM8: =IF(AF8="TIPO I",'BASE DE LIQUIDACION 2025'!$C$3,'BASE DE LIQUIDACION 2025'!$C$4) -> 126317.12 | AN8: =IF(AF8="TIPO I",'BASE DE LIQUIDACION 2025'!$D$3,'BASE DE LIQUIDACION 2025'!$D$4) -> 110808.28 | AO8: =AL8*AI8+AJ8*AM8+AK8*AN8 -> 248376.62
A9: CALI | B9: =VLOOKUP(A9,'CENTRO DE COSTOS'!A:D,4,FALSE) -> DIEGO FERNANDO HENAO CARDONA | C9: =VLOOKUP(A9,'CENTRO DE COSTOS'!A:D,2,FALSE) -> 0004-0003 | D9: 76109 | E9: TA-25-680495 | F9: FO-25-1006485 | G9: 45805 | H9: 45807 | I9: 45805 | J9: 45812 | K9: 45812 | L9: VALLE DEL CAUCA | M9: BUENAVENTURA | N9: BARRIO PUNTA DEL ESTE BUENAVENTURA | O9: 79355 | P9: CB CRECIMIENTO - OTRAS LISTAS | Q9: APERTURA | R9: REDEBAN | S9: UNO A UNO | T9: UNO A UNO | U9: EJECUTADO | V9: 28-05 SE REALIZA LLAMADA AL CLIENTE, SE HABLA CON LA SR JESSICA PAOLA VALENCIA BECERRA SE VALIDA DIRECCIÓN OK, CANAL OK, DISPONIBILIDAD TOTAL, LLAMAR EL DÍA LA INSTALACIÓN PARA CONFIRMAR VISITA, AVISO EXTERIOR ALTURA: NO INDICA ALTURA; TOMACORRIENTE CERCANO: SI; TIENE CABINA DE SEGURIDAD: NO 30-05 DEBIDO A PROBLEMAS EN LA VIA CALI - BUENAVENTURA POR CIERRES Y PROTESTAS NO SE CONSIGUE TRANSPORTE PARA EL PUERTO NO ESTAN SALIENDO LOS BUSES DESDE LA TERMINAL, SE DEBE REALIZAR DESPLAZAMIENTO EL PROXIMO MARTES VALIDANDO ESTADO DEL TRANSPORTE. 4/6/2025 SE REALIZA INSTALACIÓN DE CORRESPONSAL, SE INSTALAN EQUIPOS CON PRUEBAS EXITOSAS, SE CAPACITA Y SE EVALÚA AL CLIENTE, SE INSTALA PUBLICIDAD COMPLETA, CB QUEDA OPERATIVO. USUARIO SOMOS BANCOLOMBIA ACTIVO | W9: PAREDES CASTILLO DIEGO | X9: 10XZZ893 | Y9: 1072780 | Z9: N/A | AA9: 528290 | AB9: N/A | AC9: FACTOR/EXTERNO | AD9: TRANSPORTE | AE9: 40 ROLLOS | AF9: TIPO III | AG9: TERRESTRE | AH9: VISITA_TÉCNICA | AI9: 1 | AJ9: 1 | AK9: 1 | AL9: =IF(AF9="TIPO I",'BASE DE LIQUIDACION 2025'!$B$3,'BASE DE LIQUIDACION 2025'!$B$4) -> 11251.224 | AM9: =IF(AF9="TIPO I",'BASE DE LIQUIDACION 2025'!$C$3,'BASE DE LIQUIDACION 2025'!$C$4) -> 126317.12 | AN9: =IF(AF9="TIPO I",'BASE DE LIQUIDACION 2025'!$D$3,'BASE DE LIQUIDACION 2025'!$D$4) -> 110808.28 | AO9: =AL9*AI9+AJ9*AM9+AK9*AN9 -> 248376.62
A10: CALI | B10: =VLOOKUP(A10,'CENTRO DE COSTOS'!A:D,4,FALSE) -> DIEGO FERNANDO HENAO CARDONA | C10: =VLOOKUP(A10,'CENTRO DE COSTOS'!A:D,2,FALSE) -> 0004-0003 | D10: 76001 | E10: TA-25-680500 | F10: FO-25-1027231 | G10: 45805 | H10: 45807 | I10: 45805 | J10: 45811 | K10: 45811 | L10: VALLE DEL CAUCA | M10: CALI | N10: BARRIO VILLA DEL LAGO CALI 2 | O10: 79361 | P10: CB CRECIMIENTO - OTRAS LISTAS | Q10: APERTURA | R10: REDEBAN | S10: UNO A UNO | T10: UNO A UNO | U10: EJECUTADO | V10: 28-05 SE REALIZA LLAMADA AL CLIENTE, SE HABLA CON LA SRA DEISY (HIJA) SE VALIDA DIRECCIÓN OK, CANAL OK, DISPONIBILIDAD TOTAL, LLAMAR EL DÍA LA INSTALACIÓN PARA CONFIRMAR VISITA, AVISO EXTERIOR ALTURA: NO INDICA ALTURA; TOMACORRIENTE CERCANO: SI; TIENE CABINA DE SEGURIDAD: NO - COMUNICACIÓN POR WPP 30/5/2025 SE LLEGA AL PUNTO DESPUES DE LAS 4 PM YA QUE SE TUVO INCONVENIENTE CON VARIOS CAMBIOS DE EQUIPOS EN LA PRIMERA APERTURA, SE CONFIGURAN EQUIPOS PERO AL MOMENTO DE INICIALIZAR SE ENCUENTRA QUE LA TERMINAL NO ESTA EN BASE 24 , YA NO SE CUENTA CON SOPORTE DE REDEBAN, POR LO CUAL NO SE PUEDE LLEVAR A CABO LA APERTURA 3/6/2025 SE REALIZA INSTALACIÓN DE CORRESPONSAL, SE INSTALAN EQUIPOS CON PRUEBAS EXITOSAS, SE CAPACITA Y SE EVALÚA AL CLIENTE, SE INSTALA PUBLICIDAD COMPLETA, CB QUEDA OPERATIVO. USUARIO SOMOS BANCOLOMBIA ACTIVO | W10: HERRERA MONAR GEOVANNY | X10: 10XZZ899 | Y10: 1219158 | Z10: 1006564 | AA10: 789713 | AB10: N/A | AC10: RED | AD10: SIN SOPORTE RBM | AE10: 40 ROLLOS | AF10: TIPO I | AG10: TERRESTRE | AH10: VISITA_TÉCNICA | AI10: 1 | AJ10: 1 | AK10: 3 | AL10: =IF(AF10="TIPO I",'BASE DE LIQUIDACION 2025'!$B$3,'BASE DE LIQUIDACION 2025'!$B$4) -> 11251.224 | AM10: =IF(AF10="TIPO I",'BASE DE LIQUIDACION 2025'!$C$3,'BASE DE LIQUIDACION 2025'!$C$4) -> 126317.12 | AN10: =IF(AF10="TIPO I",'BASE DE LIQUIDACION 2025'!$D$3,'BASE DE LIQUIDACION 2025'!$D$4) -> 57411.974 | AO10: =AL10*AI10+AJ10*AM10+AK10*AN10 -> 309804.27
A11: VILLAVICENCIO | B11: =VLOOKUP(A11,'CENTRO DE COSTOS'!A:D,4,FALSE) -> KEVIN ALEXIS CORZO BUSTOS | C11: =VLOOKUP(A11,'CENTRO DE COSTOS'!A:D,2,FALSE) -> 0004-0007 | D11: 50001 | E11: TA-25-684715 | F11: FO-25-1016284 | G11: 45807 | H11: 45812 | I11: 45807 | J11: 45812 | K11: 45812 | L11: META | M11: VILLAVICENCIO | N11: BARRIOI CATUMARE VILLAVICENCIO | O11: 79665 | P11: CB CRECIMIENTO - NUEVO | Q11: APERTURA | R11: REDEBAN | S11: UNO A UNO | T11: UNO A UNO | U11: EJECUTADO | V11: 30-05-2025 SE REALIZA LLAMADA AL CLIENTE, SE HABLA CON LA SRA ERIKA FERNANDA MARRERO INFANTE SE VALIDA DIRECCIÓN OK, CANAL OK, DISPONIBILIDAD TOTAL, LLAMAR EL DÍA LA INSTALACIÓN PARA CONFIRMAR VISITA, AVISO EXTERIOR ALTURA: CLIENTE NO TIENE CONOCIMIENTO DE MEDIDAS; TOMACORRIENTE CERCANO: SI; TIENE CABINA DE SEGURIDAD: NO // CONTACTO REALIZADO POR LA APP 4/6/2025 SE REALIZA INSTALACIÓN DE CORRESPONSAL, SE INSTALAN EQUIPOS CON PRUEBAS EXITOSAS, SE CAPACITA Y SE EVALÚA AL CLIENTE, SE INSTALA PUBLICIDAD COMPLETA, CB QUEDA OPERATIVO. USUARIO SOMOS BANCOLOMBIA ACTIVO | W11: PEDREROS CONTRERAS MICHAEL STEVENS | X11: SXUZZ191 | Y11: 1040805 | Z11: 1138829 | AA11: 523819 | AB11: N/A | AC11: N/A | AD11: N/A | AE11: 40 ROLLOS | AF11: TIPO I | AG11: TERRESTRE | AH11: VISITA_TÉCNICA | AI11: 1 | AJ11: 1 | AK11: 1 | AL11: =IF(AF11="TIPO I",'BASE DE LIQUIDACION 2025'!$B$3,'BASE DE LIQUIDACION 2025'!$B$4) -> 11251.224 | AM11: =IF(AF11="TIPO I",'BASE DE LIQUIDACION 2025'!$C$3,'BASE DE LIQUIDACION 2025'!$C$4) -> 126317.12 | AN11: =IF(AF11="TIPO I",'BASE DE LIQUIDACION 2025'!$D$3,'BASE DE LIQUIDACION 2025'!$D$4) -> 57411.974 | AO11: =AL11*AI11+AJ11*AM11+AK11*AN11 -> 194980.32
A12: VILLAVICENCIO | B12: =VLOOKUP(A12,'CENTRO DE COSTOS'!A:D,4,FALSE) -> KEVIN ALEXIS CORZO BUSTOS | C12: =VLOOKUP(A12,'CENTRO DE COSTOS'!A:D,2,FALSE) -> 0004-0007 | D12: 50313 | E12: TA-25-684717 | F12: FO-25-1016288 | G12: 45807 | H12: 45812 | I12: 45807 | J12: 45811 | K12: 45811 | L12: META | M12: GRANADA | N12: BARRIO RICAUTE GRANADA 2 | O12: 79637 | P12: CB CRECIMIENTO - NUEVO | Q12: APERTURA | R12: REDEBAN | S12: UNO A UNO | T12: UNO A UNO | U12: EJECUTADO | V12: 30-05-2025 SE REALIZA LLAMADA AL CLIENTE, SE HABLA CON LA SRA LEIDY VIVIANA PENAGOS ALARCON SE VALIDA DIRECCIÓN OK, CANAL OK, DISPONIBILIDAD TOTAL, LLAMAR EL DÍA LA INSTALACIÓN PARA CONFIRMAR VISITA, AVISO EXTERIOR ALTURA: CLIENTE NO TIENE CONOCIMIENTO DE MEDIDAS; TOMACORRIENTE CERCANO: SI; TIENE CABINA DE SEGURIDAD: NO // CONTACTO REALIZADO POR LA APP 3/6/2025 SE REALIZA VISITA PARA IMPLEMENTACIÓN, PERO SE EVIDENCIA QUE EL BARRIO NO COINCIDE CON EL RELACIONADO EN LISTA DE CHEQUEO, LA DIRECCIÓN CL 19 NRO 12 - 41 ESTÁ BIEN, PERO EL BARRIO ES CENTRO Y NO RICAUTE. POR FAVOR NOS INDICA COMO PROCEDER. 3/6/2025 SE REALIZA INSTALACIÓN DE CORRESPONSAL, SE INSTALAN EQUIPOS CON PRUEBAS EXITOSAS, SE CAPACITA Y SE EVALÚA AL CLIENTE, SE INSTALA PUBLICIDAD COMPLETA, CB QUEDA OPERATIVO. USUARIO SOMOS BANCOLOMBIA ACTIVO | W12: PEDREROS CONTRERAS MICHAEL STEVENS | X12: SXUZZ163 | Y12: 981893 | Z12: N/A | AA12: 514973 | AB12: N/A | AC12: N/A | AD12: N/A | AE12: 40 ROLLOS | AF12: TIPO II | AG12: TERRESTRE | AH12: VISITA_TÉCNICA | AI12: 1 | AJ12: 1 | AK12: 1 | AL12: =IF(AF12="TIPO I",'BASE DE LIQUIDACION 2025'!$B$3,'BASE DE LIQUIDACION 2025'!$B$4) -> 11251.224 | AM12: =IF(AF12="TIPO I",'BASE DE LIQUIDACION 2025'!$C$3,'BASE DE LIQUIDACION 2025'!$C$4) -> 126317.12 | AN12: =IF(AF12="TIPO I",'BASE DE LIQUIDACION 2025'!$D$3,'BASE DE LIQUIDACION 2025'!$D$4) -> 110808.28 | AO12: =AL12*AI12+AJ12*AM12+AK12*AN12 -> 248376.62
A13: NEIVA | B13: =VLOOKUP(A13,'CENTRO DE COSTOS'!A:D,4,FALSE) -> KEVIN ALEXIS CORZO BUSTOS | C13: =VLOOKUP(A13,'CENTRO DE COSTOS'!A:D,2,FALSE) -> 0004-0007 | D13: 41001 | E13: TA-25-684720 | F13: FO-25-1016294 | G13: 45807 | H13: 45812 | I13: 45807 | J13: 45811 | K13: 45811 | L13: HUILA | M13: NEIVA | N13: BARRIO PRADOS DEL SAUCE NEIVA 1 | O13: 79645 | P13: CB CRECIMIENTO - NUEVO | Q13: APERTURA | R13: REDEBAN | S13: UNO A UNO | T13: UNO A UNO | U13: EJECUTADO | V13: 30-05-2025 SE REALIZA LLAMADA AL CLIENTE, SE HABLA CON EL SR JOSE ANDRES PERDOMO PERDOMO SE VALIDA DIRECCIÓN OK, CANAL OK, DISPONIBILIDAD TOTAL, LLAMAR EL DÍA LA INSTALACIÓN PARA CONFIRMAR VISITA, AVISO EXTERIOR ALTURA APROX 1,70 A 2 METROS; TOMACORRIENTE CERCANO: SI; TIENE CABINA DE SEGURIDAD: SI // CONTACTO REALIZADO POR LA APP 03-06 SE REALIZA INSTALACIÓN DE CORRESPONSAL, SE INSTALAN EQUIPOS CON PRUEBAS EXITOSAS, SE CAPACITA Y SE EVALÚA AL CLIENTE, SE INSTALA PUBLICIDAD COMPLETA, CB QUEDA OPERATIVO. USUARIO SOMOS BANCOLOMBIA ACTIVO | W13: DIAZ VARGAS JONATHAN MIGUEL | X13: SXUZZ171 | Y13: 792659 | Z13: N/A | AA13: 892883 | AB13: N/A | AC13: N/A | AD13: N/A | AE13: 40 ROLLOS | AF13: TIPO I | AG13: TERRESTRE | AH13: VISITA_TÉCNICA | AI13: 1 | AJ13: 1 | AK13: 1 | AL13: =IF(AF13="TIPO I",'BASE DE LIQUIDACION 2025'!$B$3,'BASE DE LIQUIDACION 2025'!$B$4) -> 11251.224 | AM13: =IF(AF13="TIPO I",'BASE DE LIQUIDACION 2025'!$C$3,'BASE DE LIQUIDACION 2025'!$C$4) -> 126317.12 | AN13: =IF(AF13="TIPO I",'BASE DE LIQUIDACION 2025'!$D$3,'BASE DE LIQUIDACION 2025'!$D$4) -> 57411.974 | AO13: =AL13*AI13+AJ13*AM13+AK13*AN13 -> 194980.32
A14: VILLAVICENCIO | B14: =VLOOKUP(A14,'CENTRO DE COSTOS'!A:D,4,FALSE) -> KEVIN ALEXIS CORZO BUSTOS | C14: =VLOOKUP(A14,'CENTRO DE COSTOS'!A:D,2,FALSE) -> 0004-0007 | D14: 50001 | E14: TA-25-684721 | F14: FO-25-1016299 | G14: 45807 | H14: 45812 | I14: 45807 | J14: 45812 | K14: 45812 | L14: META | M14: VILLAVICENCIO | N14: BARRIO LA MADRID ETAPA 4 VILLAVICENCIO | O14: 79666 | P14: CB CRECIMIENTO - NUEVO | Q14: APERTURA | R14: REDEBAN | S14: UNO A UNO | T14: UNO A UNO | U14: EJECUTADO | V14: 30-05-2025 SE REALIZA LLAMADA AL CLIENTE, SE HABLA CON LA SRA CAROL JULIETH ARIZA FONTECHA SE VALIDA DIRECCIÓN OK, CANAL OK, DISPONIBILIDAD TOTAL, LLAMAR EL DÍA LA INSTALACIÓN PARA CONFIRMAR VISITA, AVISO EXTERIOR ALTURA: CLIENTE NO TIENE CONOCIMIENTO DE MEDIDAS; TOMACORRIENTE CERCANO: SI; TIENE CABINA DE SEGURIDAD: NO // CONTACTO REALIZADO POR LA APP 4/6/2025 SE REALIZA INSTALACIÓN DE CORRESPONSAL, SE INSTALAN EQUIPOS CON PRUEBAS EXITOSAS, SE CAPACITA Y SE EVALÚA AL CLIENTE, SE INSTALA PUBLICIDAD COMPLETA, CB QUEDA OPERATIVO. USUARIO SOMOS BANCOLOMBIA ACTIVO | W14: ROZO JIMENEZ EDGAR ARMANDO | X14: SXUZZ192 | Y14: 1169258 | Z14: N/A | AA14: 903879 | AB14: N/A | AC14: N/A | AD14: N/A | AE14: 40 ROLLOS | AF14: TIPO I | AG14: TERRESTRE | AH14: VISITA_TÉCNICA | AI14: 1 | AJ14: 1 | AK14: 1 | AL14: =IF(AF14="TIPO I",'BASE DE LIQUIDACION 2025'!$B$3,'BASE DE LIQUIDACION 2025'!$B$4) -> 11251.224 | AM14: =IF(AF14="TIPO I",'BASE DE LIQUIDACION 2025'!$C$3,'BASE DE LIQUIDACION 2025'!$C$4) -> 126317.12 | AN14: =IF(AF14="TIPO I",'BASE DE LIQUIDACION 2025'!$D$3,'BASE DE LIQUIDACION 2025'!$D$4) -> 57411.974 | AO14: =AL14*AI14+AJ14*AM14+AK14*AN14 -> 194980.32
A15: VALLEDUPAR | B15: =VLOOKUP(A15,'CENTRO DE COSTOS'!A:D,4,FALSE) -> JOSE MAURICIO HERNANDEZ ROJAS | C15: =VLOOKUP(A15,'CENTRO DE COSTOS'!A:D,2,FALSE) -> 0004-0001 | D15: 20238 | E15: TA-25-684723 | F15: FO-25-1016304 | G15: 45807 | H15: 45812 | I15: 45807 | J15: 45814 | K15: 45814 | L15: CESAR | M15: EL COPEY | N15: BARRIO EL BOSQUE EL COPEY 1 | O15: 79633 | P15: CB CRECIMIENTO - NUEVO | Q15: APERTURA | R15: REDEBAN | S15: UNO A UNO | T15: UNO A UNO | U15: EJECUTADO | V15: 30-05-2025 SE REALIZA LLAMADA AL CLIENTE, SE HABLA CON LA SRA EDWIN CHINCHILLA MANOSALVA SE VALIDA DIRECCIÓN OK, CANAL OK, DISPONIBILIDAD TOTAL, LLAMAR EL DÍA LA INSTALACIÓN PARA CONFIRMAR VISITA, AVISO EXTERIOR ALTURA: 2,50 METROS; TOMACORRIENTE CERCANO: A 4 METROS ; TIENE CABINA DE SEGURIDAD: NO // CONTACTO REALIZADO POR WHATSAPP 03-06 NO SE PUEDE ACCEDER A LA APERTURA E INSTALACIÓN DE EQUIPOS EN COPEY YA QUE HAY PROTESTA Y PARO EN LA VIA SANTA MARTA Y BOSCONIA POR PARTE DE COMUNIDADES DE LA SIERRA DESDE EL DÍA DE AYER, INFORMAN FUENTES QUE EL PARO VA A SEGUIR HASTA EL RESTO DEL DÍA DE HOY 5/6/2025 SE REALIZA VALIDACIÓN NUEVAMENTE Y LA NOVEDAD CONTINUA6/6/2025 SE REALIZA INSTALACIÓN DE CORRESPONSAL, SE INSTALAN EQUIPOS CON PRUEBAS EXITOSAS, SE CAPACITA Y SE EVALÚA AL CLIENTE, SE INSTALA PUBLICIDAD COMPLETA, CB QUEDA OPERATIVO. USUARIO SOMOS BANCOLOMBIA ACTIVO | W15: MAESTRE MENGUAL EDGAR ENRIQUE | X15: SXUZZ159 | Y15: 929689 | Z15: N/A | AA15: 531715 | AB15: N/A | AC15: FACTOR/EXTERNO | AD15: PARO | AE15: 40 ROLLOS | AF15: TIPO II | AG15: TERRESTRE | AH15: VISITA_TÉCNICA | AI15: 1 | AJ15: 1 | AK15: 1 | AL15: =IF(AF15="TIPO I",'BASE DE LIQUIDACION 2025'!$B$3,'BASE DE LIQUIDACION 2025'!$B$4) -> 11251.224 | AM15: =IF(AF15="TIPO I",'BASE DE LIQUIDACION 2025'!$C$3,'BASE DE LIQUIDACION 2025'!$C$4) -> 126317.12 | AN15: =IF(AF15="TIPO I",'BASE DE LIQUIDACION 2025'!$D$3,'BASE DE LIQUIDACION 2025'!$D$4) -> 110808.28 | AO15: =AL15*AI15+AJ15*AM15+AK15*AN15 -> 248376.62
A16: BARRANQUILLA | B16: =VLOOKUP(A16,'CENTRO DE COSTOS'!A:D,4,FALSE) -> JOSE MAURICIO HERNANDEZ ROJAS | C16: =VLOOKUP(A16,'CENTRO DE COSTOS'!A:D,2,FALSE) -> 0004-0001 | D16: 8001 | E16: TA-25-684728 | F16: FO-25-1016309 | G16: 45807 | H16: 45812 | I16: 45807 | J16: 45811 | K16: 45811 | L16: ATLANTICO | M16: BARRANQUILLA | N16: BARRIO LA MAGDALENA BARRANQUILLA 4 | O16: 79598 | P16: CB CRECIMIENTO - NUEVO | Q16: APERTURA | R16: REDEBAN | S16: UNO A UNO | T16: UNO A UNO | U16: EJECUTADO | V16: 30-05-2025 SE REALIZA LLAMADA AL CLIENTE, SE HABLA CON LA SRA LIGIA MUÑOS SILVA SE VALIDA DIRECCIÓN OK, CANAL OK, DISPONIBILIDAD TOTAL, LLAMAR EL DÍA LA INSTALACIÓN PARA CONFIRMAR VISITA, AVISO EXTERIOR ALTURA: 2,10 METROS; TOMACORRIENTE CERCANO: SI; TIENE CABINA DE SEGURIDAD: SI // CONTACTO REALIZADO POR LA APP 3/6/2025 SE REALIZA INSTALACIÓN DE CORRESPONSAL, SE INSTALAN EQUIPOS CON PRUEBAS EXITOSAS, SE CAPACITA Y SE EVALÚA AL CLIENTE, SE INSTALA PUBLICIDAD COMPLETA, CB QUEDA OPERATIVO. USUARIO SOMOS BANCOLOMBIA ACTIVO | W16: DE AVILA SIADES ALBERTO ENRIQUE | X16: SXUZZ124 | Y16: 1115570 | Z16: N/A | AA16: 905668 | AB16: N/A | AC16: N/A | AD16: N/A | AE16: 40 ROLLOS | AF16: TIPO I | AG16: TERRESTRE | AH16: VISITA_TÉCNICA | AI16: 1 | AJ16: 1 | AK16: 1 | AL16: =IF(AF16="TIPO I",'BASE DE LIQUIDACION 2025'!$B$3,'BASE DE LIQUIDACION 2025'!$B$4) -> 11251.224 | AM16: =IF(AF16="TIPO I",'BASE DE LIQUIDACION 2025'!$C$3,'BASE DE LIQUIDACION 2025'!$C$4) -> 126317.12 | AN16: =IF(AF16="TIPO I",'BASE DE LIQUIDACION 2025'!$D$3,'BASE DE LIQUIDACION 2025'!$D$4) -> 57411.974 | AO16: =AL16*AI16+AJ16*AM16+AK16*AN16 -> 194980.32
A17: CALI | B17: =VLOOKUP(A17,'CENTRO DE COSTOS'!A:D,4,FALSE) -> DIEGO FERNANDO HENAO CARDONA | C17: =VLOOKUP(A17,'CENTRO DE COSTOS'!A:D,2,FALSE) -> 0004-0003 | D17: 76126 | E17: TA-25-684731 | F17: FO-25-1016315 | G17: 45807 | H17: 45812 | I17: 45807 | J17: 45812 | K17: 45812 | L17: VALLE DEL CAUCA | M17: CALIMA | N17: BARRIO OBRERO CALIMA | O17: 79619 | P17: CB CRECIMIENTO - NUEVO | Q17: APERTURA | R17: REDEBAN | S17: UNO A UNO | T17: UNO A UNO | U17: EJECUTADO | V17: 30-05-2025 SE REALIZA LLAMADA AL CLIENTE, SE HABLA CON LA SRA SHARIN LOPEZ ARANA SE VALIDA DIRECCIÓN OK, CANAL OK, DISPONIBILIDAD TOTAL, LLAMAR EL DÍA LA INSTALACIÓN PARA CONFIRMAR VISITA, AVISO EXTERIOR ALTURA: 2 - 2,50 METROS; TOMACORRIENTE CERCANO: SI; TIENE CABINA DE SEGURIDAD: NO // CONTACTO REALIZADO POR LA APP 4/6/2025 SE REALIZA INSTALACIÓN DE CORRESPONSAL, SE INSTALAN EQUIPOS CON PRUEBAS EXITOSAS, SE CAPACITA Y SE EVALÚA AL CLIENTE, SE INSTALA PUBLICIDAD COMPLETA, CB QUEDA OPERATIVO. USUARIO SOMOS BANCOLOMBIA ACTIVO | W17: HERRERA MONAR GEOVANNY | X17: SXUZZ145 | Y17: 793073 | Z17: N/A | AA17: 750456 | AB17: N/A | AC17: N/A | AD17: N/A | AE17: 40 ROLLOS | AF17: TIPO II | AG17: TERRESTRE | AH17: VISITA_TÉCNICA | AI17: 1 | AJ17: 1 | AK17: 1 | AL17: =IF(AF17="TIPO I",'BASE DE LIQUIDACION 2025'!$B$3,'BASE DE LIQUIDACION 2025'!$B$4) -> 11251.224 | AM17: =IF(AF17="TIPO I",'BASE DE LIQUIDACION 2025'!$C$3,'BASE DE LIQUIDACION 2025'!$C$4) -> 126317.12 | AN17: =IF(AF17="TIPO I",'BASE DE LIQUIDACION 2025'!$D$3,'BASE DE LIQUIDACION 2025'!$D$4) -> 110808.28 | AO17: =AL17*AI17+AJ17*AM17+AK17*AN17 -> 248376.62
A18: MEDELLIN | B18: =VLOOKUP(A18,'CENTRO DE COSTOS'!A:D,4,FALSE) -> JUAN SEBASTIÁN RÍOS CASTRILLÓN | C18: =VLOOKUP(A18,'CENTRO DE COSTOS'!A:D,2,FALSE) -> 0004-0005 | D18: 5088 | E18: TA-25-684734 | F18: FO-25-1016320 | G18: 45807 | H18: 45812 | I18: 45807 | J18: 45811 | K18: 45811 | L18: ANTIOQUIA | M18: BELLO | N18: BARRIO PACHELY BELLO 1 | O18: 79661 | P18: CB CRECIMIENTO - NUEVO | Q18: APERTURA | R18: REDEBAN | S18: UNO A UNO | T18: UNO A UNO | U18: EJECUTADO | V18: 30-05-2025 SE REALIZA LLAMADA AL CLIENTE, SE HABLA CON EL SR JUAN DAVID GUTIERREZ OQUENDO SE VALIDA DIRECCIÓN OK, CANAL OK, DISPONIBILIDAD TOTAL, LLAMAR EL DÍA LA INSTALACIÓN PARA CONFIRMAR VISITA, AVISO EXTERIOR ALTURA APROX 3 METROS; TOMACORRIENTE CERCANO: SI; TIENE CABINA DE SEGURIDAD: NO // CONTACTO REALIZADO POR LA APP 3/6/2025 SE REALIZA INSTALACIÓN DE CORRESPONSAL, SE INSTALAN EQUIPOS CON PRUEBAS EXITOSAS, SE CAPACITA Y SE EVALÚA AL CLIENTE, SE INSTALA PUBLICIDAD COMPLETA, CB QUEDA OPERATIVO. USUARIO SOMOS BANCOLOMBIA ACTIVO | W18: ZAPATA LOPEZ EDWARD ASDRUBAL | X18: SXUZZ187 | Y18: 1175437 | Z18: N/A | AA18: 1239626 | AB18: N/A | AC18: N/A | AD18: N/A | AE18: 40 ROLLOS | AF18: TIPO I | AG18: TERRESTRE | AH18: VISITA_TÉCNICA | AI18: 1 | AJ18: 1 | AK18: 1 | AL18: =IF(AF18="TIPO I",'BASE DE LIQUIDACION 2025'!$B$3,'BASE DE LIQUIDACION 2025'!$B$4) -> 11251.224 | AM18: =IF(AF18="TIPO I",'BASE DE LIQUIDACION 2025'!$C$3,'BASE DE LIQUIDACION 2025'!$C$4) -> 126317.12 | AN18: =IF(AF18="TIPO I",'BASE DE LIQUIDACION 2025'!$D$3,'BASE DE LIQUIDACION 2025'!$D$4) -> 57411.974 | AO18: =AL18*AI18+AJ18*AM18+AK18*AN18 -> 194980.32
A19: BOGOTA | B19: =VLOOKUP(A19,'CENTRO DE COSTOS'!A:D,4,FALSE) -> WILLIAM ASDRUBAL ROZO ROZO | C19: =VLOOKUP(A19,'CENTRO DE COSTOS'!A:D,2,FALSE) -> 0004-0004 | D19: 11001 | E19: TA-25-684736 | F19: FO-25-1016326 | G19: 45807 | H19: 45812 | I19: 45807 | J19: 45811 | K19: 45811 | L19: CUNDINAMARCA | M19: BOGOTA | N19: BARRIO EL POA BOGOTA 1 | O19: 79614 | P19: CB CRECIMIENTO - NUEVO | Q19: APERTURA | R19: REDEBAN | S19: UNO A UNO | T19: UNO A UNO | U19: EJECUTADO | V19: 30-05-2025 SE REALIZA LLAMADA AL CLIENTE, SE HABLA CON LA SRA BLANCA NIDIA RAMIREZ QUINTERO SE VALIDA DIRECCIÓN OK, CANAL OK, DISPONIBILIDAD TOTAL, LLAMAR EL DÍA LA INSTALACIÓN PARA CONFIRMAR VISITA, AVISO EXTERIOR ALTURA APROX CLIENTE NO TIENE CONOCIMIENTO DE MEDIDAS; TOMACORRIENTE CERCANO: SI; TIENE CABINA DE SEGURIDAD: SI // CONTACTO REALIZADO POR LA APP 3/6/2025 SE REALIZA INSTALACIÓN DE CORRESPONSAL, SE INSTALAN EQUIPOS CON PRUEBAS EXITOSAS, SE CAPACITA Y SE EVALÚA AL CLIENTE, SE INSTALA PUBLICIDAD COMPLETA, CB QUEDA OPERATIVO. USUARIO SOMOS BANCOLOMBIA ACTIVO | W19: MURCIA HERNANDEZ HARVEY IGNACIO | X19: SXUZZ140 | Y19: 1040491 | Z19: N/A | AA19: 1110498 | AB19: N/A | AC19: N/A | AD19: N/A | AE19: 40 ROLLOS | AF19: TIPO I | AG19: TERRESTRE | AH19: VISITA_TÉCNICA | AI19: 1 | AJ19: 1 | AK19: 1 | AL19: =IF(AF19="TIPO I",'BASE DE LIQUIDACION 2025'!$B$3,'BASE DE LIQUIDACION 2025'!$B$4) -> 11251.224 | AM19: =IF(AF19="TIPO I",'BASE DE LIQUIDACION 2025'!$C$3,'BASE DE LIQUIDACION 2025'!$C$4) -> 126317.12 | AN19: =IF(AF19="TIPO I",'BASE DE LIQUIDACION 2025'!$D$3,'BASE DE LIQUIDACION 2025'!$D$4) -> 57411.974 | AO19: =AL19*AI19+AJ19*AM19+AK19*AN19 -> 194980.32
A20: MEDELLIN | B20: =VLOOKUP(A20,'CENTRO DE COSTOS'!A:D,4,FALSE) -> JUAN SEBASTIÁN RÍOS CASTRILLÓN | C20: =VLOOKUP(A20,'CENTRO DE COSTOS'!A:D,2,FALSE) -> 0004-0005 | D20: 5001 | E20: TA-25-684740 | F20: FO-25-1016330 | G20: 45807 | H20: 45812 | I20: 45807 | J20: 45811 | K20: 45811 | L20: ANTIOQUIA | M20: MEDELLIN | N20: BARRIO CALASANZ MEDELLIN 7 | O20: 79676 | P20: CB CRECIMIENTO - NUEVO | Q20: APERTURA | R20: REDEBAN | S20: UNO A UNO | T20: UNO A UNO | U20: EJECUTADO | V20: 30-05-2025 SE REALIZA LLAMADA AL CLIENTE, SE HABLA CON EL SR LUIS FERNANDO ARIAS RIOS SE VALIDA DIRECCIÓN OK, CANAL OK, DISPONIBILIDAD TOTAL, LLAMAR EL DÍA LA INSTALACIÓN PARA CONFIRMAR VISITA, AVISO EXTERIOR ALTURA APROX NO TIENE CONOCIMIENTO DE MEDIDAS; TOMACORRIENTE CERCANO: SI; TIENE CABINA DE SEGURIDAD: NO // CONTACTO REALIZADO POR LA APP 3/6/2025 SE REALIZA INSTALACIÓN DE CORRESPONSAL, SE INSTALAN EQUIPOS CON PRUEBAS EXITOSAS, SE CAPACITA Y SE EVALÚA AL CLIENTE, SE INSTALA PUBLICIDAD COMPLETA, CB QUEDA OPERATIVO. USUARIO SOMOS BANCOLOMBIA ACTIVO | W20: BADEL ACUÑA LUIS ALBERTO | X20: SXUZZ202 | Y20: 1092122 | Z20: N/A | AA20: 1239775 | AB20: N/A | AC20: N/A | AD20: N/A | AE20: 40 ROLLOS | AF20: TIPO I | AG20: TERRESTRE | AH20: VISITA_TÉCNICA | AI20: 1 | AJ20: 1 | AK20: 1 | AL20: =IF(AF20="TIPO I",'BASE DE LIQUIDACION 2025'!$B$3,'BASE DE LIQUIDACION 2025'!$B$4) -> 11251.224 | AM20: =IF(AF20="TIPO I",'BASE DE LIQUIDACION 2025'!$C$3,'BASE DE LIQUIDACION 2025'!$C$4) -> 126317.12 | AN20: =IF(AF20="TIPO I",'BASE DE LIQUIDACION 2025'!$D$3,'BASE DE LIQUIDACION 2025'!$D$4) -> 57411.974 | AO20: =AL20*AI20+AJ20*AM20+AK20*AN20 -> 194980.32
A21: CALI | B21: =VLOOKUP(A21,'CENTRO DE COSTOS'!A:D,4,FALSE) -> DIEGO FERNANDO HENAO CARDONA | C21: =VLOOKUP(A21,'CENTRO DE COSTOS'!A:D,2,FALSE) -> 0004-0003 | D21: 76001 | E21: TA-25-684743 | F21: FO-25-1016336 | G21: 45807 | H21: 45812 | I21: 45807 | J21: 45811 | K21: 45811 | L21: VALLE DEL CAUCA | M21: CALI | N21: BARRIO ALTOS DE SANTA ELENA CALI | O21: 79618 | P21: CB CRECIMIENTO - NUEVO | Q21: APERTURA | R21: REDEBAN | S21: UNO A UNO | T21: UNO A UNO | U21: EJECUTADO | V21: 30-05-2025 SE REALIZA LLAMADA AL CLIENTE, SE HABLA CON LA SRA DIANA MARCELA VELEZ HUERTAS SE VALIDA DIRECCIÓN OK, CANAL OK, DISPONIBILIDAD TOTAL, LLAMAR EL DÍA LA INSTALACIÓN PARA CONFIRMAR VISITA, AVISO EXTERIOR ALTURA APROX 2 METROS; TOMACORRIENTE CERCANO: SI; TIENE CABINA DE SEGURIDAD: NO // CONTACTO REALIZADO POR LA APP 3/6/2025 SE REALIZA INSTALACIÓN DE CORRESPONSAL, SE INSTALAN EQUIPOS CON PRUEBAS EXITOSAS, SE CAPACITA Y SE EVALÚA AL CLIENTE, SE INSTALA PUBLICIDAD COMPLETA, CB QUEDA OPERATIVO. USUARIO SOMOS BANCOLOMBIA ACTIVO | W21: MONTERO MUESES GIAN CARLO | X21: SXUZZ144 | Y21: 1074324 | Z21: N/A | AA21: 864190 | AB21: N/A | AC21: N/A | AD21: N/A | AE21: 40 ROLLOS | AF21: TIPO I | AG21: TERRESTRE | AH21: VISITA_TÉCNICA | AI21: 1 | AJ21: 1 | AK21: 1 | AL21: =IF(AF21="TIPO I",'BASE DE LIQUIDACION 2025'!$B$3,'BASE DE LIQUIDACION 2025'!$B$4) -> 11251.224 | AM21: =IF(AF21="TIPO I",'BASE DE LIQUIDACION 2025'!$C$3,'BASE DE LIQUIDACION 2025'!$C$4) -> 126317.12 | AN21: =IF(AF21="TIPO I",'BASE DE LIQUIDACION 2025'!$D$3,'BASE DE LIQUIDACION 2025'!$D$4) -> 57411.974 | AO21: =AL21*AI21+AJ21*AM21+AK21*AN21 -> 194980.32
A22: CALI | B22: =VLOOKUP(A22,'CENTRO DE COSTOS'!A:D,4,FALSE) -> DIEGO FERNANDO HENAO CARDONA | C22: =VLOOKUP(A22,'CENTRO DE COSTOS'!A:D,2,FALSE) -> 0004-0003 | D22: 76563 | E22: TA-25-684746 | F22: FO-25-1016342 | G22: 45807 | H22: 45812 | I22: 45807 | J22: 45811 | K22: 45811 | L22: VALLE DEL CAUCA | M22: PRADERA | N22: BARRIO CENTRO PRADERA 9 | O22: 79650 | P22: CB CRECIMIENTO - NUEVO | Q22: APERTURA | R22: REDEBAN | S22: UNO A UNO | T22: UNO A UNO | U22: EJECUTADO | V22: 30-05-2025 SE REALIZA LLAMADA AL CLIENTE, SE HABLA CON LA SRA YEDSICA LORENA PLAZA SALAZAR SE VALIDA DIRECCIÓN OK, CANAL OK, DISPONIBILIDAD TOTAL, LLAMAR EL DÍA LA INSTALACIÓN PARA CONFIRMAR VISITA, AVISO EXTERIOR ALTURA APROX 1,30 METROS; TOMACORRIENTE CERCANO: SI; TIENE CABINA DE SEGURIDAD: NO // CONTACTO REALIZADO POR LA APP 03-06 SE REALIZA INSTALACIÓN DE CORRESPONSAL, SE INSTALAN EQUIPOS CON PRUEBAS EXITOSAS, SE CAPACITA Y SE EVALÚA AL CLIENTE, SE INSTALA PUBLICIDAD COMPLETA, CB QUEDA OPERATIVO. USUARIO SOMOS BANCOLOMBIA ACTIVO | W22: TORRES GARCIA JENDRY JOSE | X22: SXUZZ176 | Y22: 868754 | Z22: N/A | AA22: 846414 | AB22: N/A | AC22: N/A | AD22: N/A | AE22: 40 ROLLOS | AF22: TIPO II | AG22: TERRESTRE | AH22: VISITA_TÉCNICA | AI22: 1 | AJ22: 1 | AK22: 1 | AL22: =IF(AF22="TIPO I",'BASE DE LIQUIDACION 2025'!$B$3,'BASE DE LIQUIDACION 2025'!$B$4) -> 11251.224 | AM22: =IF(AF22="TIPO I",'BASE DE LIQUIDACION 2025'!$C$3,'BASE DE LIQUIDACION 2025'!$C$4) -> 126317.12 | AN22: =IF(AF22="TIPO I",'BASE DE LIQUIDACION 2025'!$D$3,'BASE DE LIQUIDACION 2025'!$D$4) -> 110808.28 | AO22: =AL22*AI22+AJ22*AM22+AK22*AN22 -> 248376.62
A23: BOGOTA | B23: =VLOOKUP(A23,'CENTRO DE COSTOS'!A:D,4,FALSE) -> WILLIAM ASDRUBAL ROZO ROZO | C23: =VLOOKUP(A23,'CENTRO DE COSTOS'!A:D,2,FALSE) -> 0004-0004 | D23: 11001 | E23: TA-25-684748 | F23: FO-25-1016347 | G23: 45807 | H23: 45812 | I23: 45807 | J23: 45811 | K23: 45811 | L23: CUNDINAMARCA | M23: BOGOTA | N23: BARRIO VILLA ALAMOS BOGOTA | O23: 79609 | P23: CB CRECIMIENTO - NUEVO | Q23: APERTURA | R23: REDEBAN | S23: UNO A UNO | T23: UNO A UNO | U23: EJECUTADO | V23: 30-05-2025 SE REALIZA LLAMADA AL CLIENTE, SE HABLA CON LA SRA YESSICA SAAVEDRA PARRA SE VALIDA DIRECCIÓN OK, CANAL OK, DISPONIBILIDAD TOTAL, LLAMAR EL DÍA LA INSTALACIÓN PARA CONFIRMAR VISITA, AVISO EXTERIOR ALTURA APROX 2,50 A 3 METROS; TOMACORRIENTE CERCANO: SI; TIENE CABINA DE SEGURIDAD: NO // CONTACTO REALIZADO POR LA APP 3/6/2025 SE REALIZA INSTALACIÓN DE CORRESPONSAL, SE INSTALAN EQUIPOS CON PRUEBAS EXITOSAS, SE CAPACITA Y SE EVALÚA AL CLIENTE, SE INSTALA PUBLICIDAD COMPLETA, CB QUEDA OPERATIVO. USUARIO SOMOS BANCOLOMBIA ACTIVO | W23: GOMEZ VEGA DAVID SNEYDER | X23: SXUZZ135 | Y23: 1021069 | Z23: N/A | AA23: 1076249 | AB23: N/A | AC23: N/A | AD23: N/A | AE23: 40 ROLLOS | AF23: TIPO I | AG23: TERRESTRE | AH23: VISITA_TÉCNICA | AI23: 1 | AJ23: 1 | AK23: 1 | AL23: =IF(AF23="TIPO I",'BASE DE LIQUIDACION 2025'!$B$3,'BASE DE LIQUIDACION 2025'!$B$4) -> 11251.224 | AM23: =IF(AF23="TIPO I",'BASE DE LIQUIDACION 2025'!$C$3,'BASE DE LIQUIDACION 2025'!$C$4) -> 126317.12 | AN23: =IF(AF23="TIPO I",'BASE DE LIQUIDACION 2025'!$D$3,'BASE DE LIQUIDACION 2025'!$D$4) -> 57411.974 | AO23: =AL23*AI23+AJ23*AM23+AK23*AN23 -> 194980.32
A24: BOGOTA | B24: =VLOOKUP(A24,'CENTRO DE COSTOS'!A:D,4,FALSE) -> WILLIAM ASDRUBAL ROZO ROZO | C24: =VLOOKUP(A24,'CENTRO DE COSTOS'!A:D,2,FALSE) -> 0004-0004 | D24: 11001 | E24: TA-25-684749 | F24: FO-25-1016351 | G24: 45807 | H24: 45812 | I24: 45807 | J24: 45811 | K24: 45811 | L24: CUNDINAMARCA | M24: BOGOTA | N24: BARRIO SANTA LUCIA BOGOTA 11 | O24: 79615 | P24: CB CRECIMIENTO - NUEVO | Q24: APERTURA | R24: REDEBAN | S24: UNO A UNO | T24: UNO A UNO | U24: EJECUTADO | V24: 30-05-2025 SE REALIZA LLAMADA AL CLIENTE, SE HABLA CON LA SRA DORA EDITH NAVARRETE SE VALIDA DIRECCIÓN OK, CANAL OK, DISPONIBILIDAD TOTAL, LLAMAR EL DÍA LA INSTALACIÓN PARA CONFIRMAR VISITA, AVISO EXTERIOR ALTURA APROX 3 METROS; TOMACORRIENTE CERCANO: SI; TIENE CABINA DE SEGURIDAD: SI // CONTACTO REALIZADO POR LA APP 3/6/2025 SE REALIZA INSTALACIÓN DE CORRESPONSAL, SE INSTALAN EQUIPOS CON PRUEBAS EXITOSAS, SE CAPACITA Y SE EVALÚA AL CLIENTE, SE INSTALA PUBLICIDAD COMPLETA, CB QUEDA OPERATIVO. USUARIO SOMOS BANCOLOMBIA ACTIVO | W24: ROMERO ROJAS BREIDY JHOHAN | X24: SXUZZ141 | Y24: 1235482 | Z24: 917143 | AA24: 1139296-241597317561324755897568 | AB24: N/A | AC24: N/A | AD24: N/A | AE24: 40 ROLLOS | AF24: TIPO I | AG24: TERRESTRE | AH24: VISITA_TÉCNICA | AI24: 1 | AJ24: 1 | AK24: 1 | AL24: =IF(AF24="TIPO I",'BASE DE LIQUIDACION 2025'!$B$3,'BASE DE LIQUIDACION 2025'!$B$4) -> 11251.224 | AM24: =IF(AF24="TIPO I",'BASE DE LIQUIDACION 2025'!$C$3,'BASE DE LIQUIDACION 2025'!$C$4) -> 126317.12 | AN24: =IF(AF24="TIPO I",'BASE DE LIQUIDACION 2025'!$D$3,'BASE DE LIQUIDACION 2025'!$D$4) -> 57411.974 | AO24: =AL24*AI24+AJ24*AM24+AK24*AN24 -> 194980.32
A25: MEDELLIN | B25: =VLOOKUP(A25,'CENTRO DE COSTOS'!A:D,4,FALSE) -> JUAN SEBASTIÁN RÍOS CASTRILLÓN | C25: =VLOOKUP(A25,'CENTRO DE COSTOS'!A:D,2,FALSE) -> 0004-0005 | D25: 5079 | E25: TA-25-684752 | F25: FO-25-1016355 | G25: 45807 | H25: 45812 | I25: 45807 | J25: 45812 | K25: 45812 | L25: ANTIOQUIA | M25: BARBOSA | N25: BARRIO GGTO HATILLO BARBOSA BARBOSA | O25: 79624 | P25: CB CRECIMIENTO - NUEVO | Q25: APERTURA | R25: REDEBAN | S25: UNO A UNO | T25: UNO A UNO | U25: EJECUTADO | V25: 30-05-2025 SE REALIZA LLAMADA AL CLIENTE, SE HABLA CON LA SRA ALEJANDRA MARCELA MACIAS ECHEVERRI SE VALIDA DIRECCIÓN OK, CANAL OK, DISPONIBILIDAD TOTAL, LLAMAR EL DÍA LA INSTALACIÓN PARA CONFIRMAR VISITA, AVISO EXTERIOR ALTURA APROX 1,80 METROS; TOMACORRIENTE CERCANO: SI; TIENE CABINA DE SEGURIDAD: SI // CONTACTO REALIZADO POR LA APP 4/6/2025 SE REALIZA INSTALACIÓN DE CORRESPONSAL, SE INSTALAN EQUIPOS CON PRUEBAS EXITOSAS, SE CAPACITA Y SE EVALÚA AL CLIENTE, SE INSTALA PUBLICIDAD COMPLETA, CB QUEDA OPERATIVO. USUARIO SOMOS BANCOLOMBIA ACTIVO. SE PRESENTO NOVEDAD CON DIRECCIÓN YA QUE EN LISTA APARECE CORREGIMIENTO, PERO EN CAMARA DE COMERCIO NO, SE ESCALO CASO A RBM Y AUTORIZARON LA INSTALACIÓN YA QUE EL COMERCIO SI QUEDA EN EL CORREGIMIENTO | W25: ALVAREZ ARENAS VICTOR HUGO | X25: SXUZZ150 | Y25: 1051697 | Z25: N/A | AA25: 863827 | AB25: N/A | AC25: N/A | AD25: N/A | AE25: 40 ROLLOS | AF25: TIPO II | AG25: TERRESTRE | AH25: VISITA_TÉCNICA | AI25: 1 | AJ25: 1 | AK25: 1 | AL25: =IF(AF25="TIPO I",'BASE DE LIQUIDACION 2025'!$B$3,'BASE DE LIQUIDACION 2025'!$B$4) -> 11251.224 | AM25: =IF(AF25="TIPO I",'BASE DE LIQUIDACION 2025'!$C$3,'BASE DE LIQUIDACION 2025'!$C$4) -> 126317.12 | AN25: =IF(AF25="TIPO I",'BASE DE LIQUIDACION 2025'!$D$3,'BASE DE LIQUIDACION 2025'!$D$4) -> 110808.28 | AO25: =AL25*AI25+AJ25*AM25+AK25*AN25 -> 248376.62
A26: BOGOTA | B26: =VLOOKUP(A26,'CENTRO DE COSTOS'!A:D,4,FALSE) -> WILLIAM ASDRUBAL ROZO ROZO | C26: =VLOOKUP(A26,'CENTRO DE COSTOS'!A:D,2,FALSE) -> 0004-0004 | D26: 11001 | E26: TA-25-684755 | F26: FO-25-1016360 | G26: 45807 | H26: 45812 | I26: 45807 | J26: 45812 | K26: 45812 | L26: CUNDINAMARCA | M26: BOGOTA | N26: BARRIO LAS ACACIAS BOGOTA 1 | O26: 79610 | P26: CAMBIO DE REZON SOCIAL | Q26: APERTURA | R26: REDEBAN | S26: UNO A UNO | T26: UNO A UNO | U26: EJECUTADO | V26: 30-05-2025 SE REALIZA LLAMADA AL CLIENTE, SE HABLA CON LA HERMANA DEL SR JAIBER JULIAN LOPEZ MARTINEZ SE VALIDA DIRECCIÓN OK, CANAL OK, DISPONIBILIDAD TOTAL, LLAMAR EL DÍA LA INSTALACIÓN PARA CONFIRMAR VISITA, AVISO EXTERIOR ALTURA APROX 2; TOMACORRIENTE CERCANO: SI; TIENE CABINA DE SEGURIDAD: SI // CONTACTO REALIZADO POR LA APP 03-06 EN COMUNICACIÓN CON EL COMERCIO PARA VALIDAR APERTURA AL JAIBER JULIAN LOPEZ MARTINEZ / TELEFONO DE CONTACTO: 3222100576, MANIFIESTA RECIBIR EL DÍA DE MAÑANA 04-06-2025 4/6/2025 SE REALIZA INSTALACIÓN DE CORRESPONSAL, SE INSTALAN EQUIPOS CON PRUEBAS EXITOSAS, SE CAPACITA Y SE EVALÚA AL CLIENTE, SE INSTALA PUBLICIDAD COMPLETA, CB QUEDA OPERATIVO. USUARIO SOMOS BANCOLOMBIA ACTIVO | W26: ROMERO ROJAS BREIDY JHOHAN | X26: SXUZZ136 | Y26: 1235338 | Z26: 893558 | AA26: 984296-241587317561324755886591 | AB26: N/A | AC26: N/A | AD26: N/A | AE26: 40 ROLLOS | AF26: TIPO I | AG26: TERRESTRE | AH26: VISITA_TÉCNICA | AI26: 1 | AJ26: 1 | AK26: 1 | AL26: =IF(AF26="TIPO I",'BASE DE LIQUIDACION 2025'!$B$3,'BASE DE LIQUIDACION 2025'!$B$4) -> 11251.224 | AM26: =IF(AF26="TIPO I",'BASE DE LIQUIDACION 2025'!$C$3,'BASE DE LIQUIDACION 2025'!$C$4) -> 126317.12 | AN26: =IF(AF26="TIPO I",'BASE DE LIQUIDACION 2025'!$D$3,'BASE DE LIQUIDACION 2025'!$D$4) -> 57411.974 | AO26: =AL26*AI26+AJ26*AM26+AK26*AN26 -> 194980.32
A27: MEDELLIN | B27: =VLOOKUP(A27,'CENTRO DE COSTOS'!A:D,4,FALSE) -> JUAN SEBASTIÁN RÍOS CASTRILLÓN | C27: =VLOOKUP(A27,'CENTRO DE COSTOS'!A:D,2,FALSE) -> 0004-0005 | D27: 5308 | E27: TA-25-684757 | F27: FO-25-1016370 | G27: 45807 | H27: 45812 | I27: 45807 | J27: 45811 | K27: 45811 | L27: ANTIOQUIA | M27: GIRARDOTA | N27: BARRIO SANTA ANA GIRARDOTA 1 | O27: 79627 | P27: CAMBIO DE RAZON SOCIAL | Q27: APERTURA | R27: REDEBAN | S27: UNO A UNO | T27: UNO A UNO | U27: EJECUTADO | V27: 30-05-2025 SE REALIZA LLAMADA AL CLIENTE, SE HABLA CON LA SRA ANGELA YANETH BEDOYA JARAMILLOI SE VALIDA DIRECCIÓN OK, CANAL OK, DISPONIBILIDAD TOTAL, LLAMAR EL DÍA LA INSTALACIÓN PARA CONFIRMAR VISITA, AVISO EXTERIOR ALTURA APROX 2 METROS; TOMACORRIENTE CERCANO: SI; TIENE CABINA DE SEGURIDAD: SI // CONTACTO REALIZADO POR LA APP 03-06 SE REALIZA INSTALACIÓN DE CORRESPONSAL POR CAMBIO DE RAZON SOCIAL, SE INSTALAN EQUIPOS CON PRUEBAS EXITOSAS, NO SE CAPACITA Y SE EVALÚA AL CLIENTE, SE INSTALA FLANGGER Y DISPLAY DE HORARIO, EL AVISO YA ESTABA INSTALADO EN BUEN ESTADO, SE REGGRESA EL QUE SE LLEVO A BODEGA, CB QUEDA OPERATIVO. USUARIO SOMOS BANCOLOMBIA ACTIVO | W27: MARTINEZ TOVAR OSCAR DAVID | X27: SXUZZ153 | Y27: 771289 | Z27: N/A | AA27: 940524 | AB27: 1239756 | AC27: N/A | AD27: N/A | AE27: 40 ROLLOS | AF27: TIPO I | AG27: TERRESTRE | AH27: VISITA_TÉCNICA | AI27: 1 | AJ27: 0 | AK27: 2 | AL27: =IF(AF27="TIPO I",'BASE DE LIQUIDACION 2025'!$B$3,'BASE DE LIQUIDACION 2025'!$B$4) -> 11251.224 | AM27: =IF(AF27="TIPO I",'BASE DE LIQUIDACION 2025'!$C$3,'BASE DE LIQUIDACION 2025'!$C$4) -> 126317.12 | AN27: =IF(AF27="TIPO I",'BASE DE LIQUIDACION 2025'!$D$3,'BASE DE LIQUIDACION 2025'!$D$4) -> 57411.974 | AO27: =AL27*AI27+AJ27*AM27+AK27*AN27 -> 126075.17
A28: MEDELLIN | B28: =VLOOKUP(A28,'CENTRO DE COSTOS'!A:D,4,FALSE) -> JUAN SEBASTIÁN RÍOS CASTRILLÓN | C28: =VLOOKUP(A28,'CENTRO DE COSTOS'!A:D,2,FALSE) -> 0004-0005 | D28: 5001 | E28: TA-25-684760 | F28: FO-25-1016375 | G28: 45807 | H28: 45812 | I28: 45807 | J28: 45811 | K28: 45811 | L28: ANTIOQUIA | M28: MEDELLIN | N28: BARRIO BELLEN MEDELLIN | O28: 79669 | P28: CAMBIO DE RAZON SOCIAL | Q28: APERTURA | R28: REDEBAN | S28: UNO A UNO | T28: UNO A UNO | U28: EJECUTADO | V28: 30-05-2025 SE REALIZA LLAMADA AL CLIENTE, SE HABLA CON EL SR WALTER ANDRES HERNANDEZ GUERRA SE VALIDA DIRECCIÓN OK, CANAL OK, DISPONIBILIDAD TOTAL, LLAMAR EL DÍA LA INSTALACIÓN PARA CONFIRMAR VISITA, AVISO EXTERIOR ALTURA APROX 3 - 4 METROS; TOMACORRIENTE CERCANO: SI; TIENE CABINA DE SEGURIDAD: SI // CONTACTO REALIZADO POR LA APP 3/6/2025 SE REALIZA INSTALACIÓN DE CORRESPONSAL POR CAMBIO DE RAZON SOCIAL, SE INSTALAN EQUIPOS CON PRUEBAS EXITOSAS, SE CAPACITA Y SE EVALÚA AL CLIENTE, NO SE INSTALA PUBLICIDAD, CB QUEDA OPERATIVO. USUARIO SOMOS BANCOLOMBIA ACTIVO | W28: QUINTERO SANCHEZ JUAN SEBASTIAN | X28: SXUZZ195 | Y28: 772256 | Z28: N/A | AA28: 1239771 | AB28: N/A | AC28: N/A | AD28: N/A | AE28: 40 ROLLOS | AF28: TIPO I | AG28: TERRESTRE | AH28: VISITA_TÉCNICA | AI28: 0 | AJ28: 0 | AK28: 2 | AL28: =IF(AF28="TIPO I",'BASE DE LIQUIDACION 2025'!$B$3,'BASE DE LIQUIDACION 2025'!$B$4) -> 11251.224 | AM28: =IF(AF28="TIPO I",'BASE DE LIQUIDACION 2025'!$C$3,'BASE DE LIQUIDACION 2025'!$C$4) -> 126317.12 | AN28: =IF(AF28="TIPO I",'BASE DE LIQUIDACION 2025'!$D$3,'BASE DE LIQUIDACION 2025'!$D$4) -> 57411.974 | AO28: =AL28*AI28+AJ28*AM28+AK28*AN28 -> 114823.95
A29: CARTAGENA | B29: =VLOOKUP(A29,'CENTRO DE COSTOS'!A:D,4,FALSE) -> JOSE MAURICIO HERNANDEZ ROJAS | C29: =VLOOKUP(A29,'CENTRO DE COSTOS'!A:D,2,FALSE) -> 0004-0001 | D29: 13001 | E29: TA-25-684762 | F29: FO-25-1016379 | G29: 45807 | H29: 45812 | I29: 45807 | J29: 45812 | K29: 45812 | L29: BOLIVAR | M29: CARTAGENA | N29: BARRIO LOS ANGELES CARTAGENA DE INDIAS | O29: 79621 | P29: CB CRECIMIENTO - NUEVO | Q29: APERTURA | R29: REDEBAN | S29: UNO A UNO | T29: UNO A UNO | U29: EJECUTADO | V29: 30-05-2025 SE REALIZA LLAMADA AL CLIENTE, SE HABLA CON LA SRA GERALDINE OYOLA MENDOZA SE VALIDA DIRECCIÓN OK, CANAL OK, DISPONIBILIDAD TOTAL, LLAMAR EL DÍA LA INSTALACIÓN PARA CONFIRMAR VISITA, AVISO EXTERIOR ALTURA APROX 1,50 - 2 METROS; TOMACORRIENTE CERCANO: SI; TIENE CABINA DE SEGURIDAD: SI // CONTACTO REALIZADO POR LA APP 04-06 SE REALIZA INSTALACIÓN DE CORRESPONSAL, SE INSTALAN EQUIPOS CON PRUEBAS EXITOSAS, SE CAPACITA Y SE EVALÚA AL CLIENTE, SE INSTALA PUBLICIDAD COMPLETA, CB QUEDA OPERATIVO. USUARIO SOMOS BANCOLOMBIA ACTIVO | W29: CANEDO HERRERA ALEXANDER | X29: SXUZZ147 | Y29: 791031 | Z29: N/A | AA29: 529616 | AB29: N/A | AC29: N/A | AD29: N/A | AE29: 40 ROLLOS | AF29: TIPO I | AG29: TERRESTRE | AH29: VISITA_TÉCNICA | AI29: 1 | AJ29: 1 | AK29: 1 | AL29: =IF(AF29="TIPO I",'BASE DE LIQUIDACION 2025'!$B$3,'BASE DE LIQUIDACION 2025'!$B$4) -> 11251.224 | AM29: =IF(AF29="TIPO I",'BASE DE LIQUIDACION 2025'!$C$3,'BASE DE LIQUIDACION 2025'!$C$4) -> 126317.12 | AN29: =IF(AF29="TIPO I",'BASE DE LIQUIDACION 2025'!$D$3,'BASE DE LIQUIDACION 2025'!$D$4) -> 57411.974 | AO29: =AL29*AI29+AJ29*AM29+AK29*AN29 -> 194980.32
