Workbook
Name A: #REF!
Name ACTIVIDAD: [1]Hoja2!$P$2:$P$30
Name Actividad: [2]Formulas!$H$2:$H$5000
Name arearesponsable: '[3]Listas desplegables'!$BB$2:$BB$100
Name Clientes: [4]Clientes!$A$2:$A$100
Name Clientes: [2]Clientes!$A$2:$A$100
Name COORDINADOR: [1]Hoja2!$D$2:$D$30
Name Coordinadores: [5]Coordinadores!$A$2:$A$1000
Name Coordinadores: [2]Coordinadores!$A$2:$A$1000
Name DOCUMENTADOR: [1]Hoja2!$A$2:$A$30
Name ES: [1]Hoja2!$K$2:$K$30
Name ESS: [1]Hoja2!$K$2:$K$30
Name Estado: [4]Formulas!$K$2:$K$5000
Name Estado: [2]Formulas!$K$2:$K$5000
Name ESTADOACTIVIDAD: [1]Hoja2!$M$2:$M$30
Name ESTADOS: '[6]Listas desplegables'!$B$1:$D$1
Name ESTADOSCIERRES: '[7]lista desplegable'!$CX$1:$DA$1
Name Facturacion: '[8]Listas desplegables'!$AO$1:$AR$1
Name FACTURACIÓN: '[6]Listas desplegables'!$Y$1:$AB$1
Name falla: #REF!
Name Fallas: '[9]Listas desplegables'!$F$2:$L$2
Name Grupo_Falla: '[10]Listas Desplegables'!$CH$2:$CH$5
Name inconservmanager: '[11]Listas desplegables'!$BC$2:$BC$100
Name INCUMPLIMIENTO: '[3]Listas desplegables'!$AK$1:$AN$1
Name LISTA: [12]Dptos!$A$1139:$A$1171
Name LISTA2: #REF!
Name LOLO: [13]Coordinadores!$A$2:$A$1000
Name solicitudes: '[8]Listas desplegables'!$U$1:$AF$1
Name solicitudes: '[14]Listas desplegables'!$AF$1:$AQ$1
Name Tecnicos: [4]Tecnicos!$A$2:$A$1000
Name Tecnicos: [2]Tecnicos!$A$2:$A$1000
Name Version: [2]Formulas!$I$2:$I$3

Sheet RESUMEN
A1: LÍNEA COMUNICACIONES S.A.S | F1: FACTURACIÓN CORRESPONSALES BANCARIOS TIQUIETES AEREOS
A2: FACTURACIÓN PROYECTO CB BANCOLOMBIA | F2: =A3 -> 45868
A3: 45868
F4: CONCEPTOS | G4: TRAYECTOS | H4: TOTAL | I4: % Administración | J4: TOTAL
A5: CONCEPTOS | B5: CANTIDAD | C5: VALOR UNITARIO | D5: VALOR TOTAL | I5: =H5*0.12 -> 0 | J5: =H5+I5 -> 0
A6: Adecuaciones CB | B6: =COUNTA(ADECUACIONES!A:A)-1 -> 69 | C6: 0 | D6: =ADECUACIONES!AE71 -> 13282763 | I6: =H6*0.12 -> 0 | J6: =H6+I6 -> 0
A7: Incidentes | B7: =COUNTA(INCIDENTES!A:A)-1 -> 208 | C7: 0 | D7: =INCIDENTES!AG210 -> 18322378 | I7: =H7*0.12 -> 0 | J7: =H7+I7 -> 0
A8: Ordenes de Cambio | B8: =COUNTA(OC!A:A)-1 -> 8 | C8: 0 | D8: =OC!AG10 -> 1010801.9 | I8: =H8*0.12 -> 0 | J8: =H8+I8 -> 0
A9: Tiquetes | B9: 0 | C9: 0 | D9: =J12 -> 0 | I9: =H9*0.12 -> 0 | J9: =H9+I9 -> 0
A10: SUBTOTAL | D10: =SUM(D6:D9) -> 32615942 | I10: =H10*0.12 -> 0 | J10: =H10+I10 -> 0
A11: Iva | D11: =D10*0.19 -> 6197029 | I11: =H11*0.12 -> 0 | J11: =H11+I11 -> 0
A12: TOTAL | D12: =D10+D11 -> 38812971 | F12: TOTAL | H12: =SUM(H5:H11) -> 0 | I12: =SUM(I5:I11) -> 0 | J12: =SUM(J5:J11) -> 0

Sheet BASE LIQUIDACION
A1: TARIFAS 2025 | E1: Incremento 2025
A2: Tipificación | B2: Descripción | C2: Dia actividad Exitosa | D2: Dia actividad Fallida | E2: 0.052
A3: Tipo I | B3: Metropolitano | C3: =62700.07*(1+$E$2) -> 65960.474 | D3: =42357.4*(1+$E$2) -> 44559.985
A4: Tipo II | B4: Hasta 3 horas | C4: =155716.31*(1+$E$2) -> 163813.56 | D4: =127766.53*(1+$E$2) -> 134410.39
A5: Tipo III | B5: De 3 a 5 horas | C5: =262099.22*(1+$E$2) -> 275728.38 | D5: =211886.19*(1+$E$2) -> 222904.27
A6: Tipo IV | B6: Más de 5 horas | C6: =455883.78*(1+$E$2) -> 479589.74 | D6: =441833.68*(1+$E$2) -> 464809.03
A7: Destino aereo | B7: No incluye valor del Tiquete | C7: =455883.78*(1+$E$2) -> 479589.74 | D7: =441833.68*(1+$E$2) -> 464809.03
A8: *Donde se requiera transporte aéreo o fluvial se factura adicional a tarifa TIPO IV el valor del tiquete + el 12% de admon.
A10: Gestión Telefónica | B10: =36031.04*(1+$E$2) -> 37904.654
A11: Mts Acometida electrica | B11: =30182.1*(1+$E$2) -> 31751.569
A12: Mts Acometida datos | B12: =15432.22*(1+$E$2) -> 16234.695
A13: switche | B13: =244669.03*(1+$E$2) -> 257391.82
A14: Router | B14: =291399.51*(1+$E$2) -> 306552.28
A15: Envio operador Logistico | B15: =53547.34*(1+$E$2) -> 56331.802

Sheet Tablas dinámicas
A2: ADECUACIONES | J2: NOMBRE CC | K2: Suma de VALOR | L2: Suma de VALOR2
A3: COORDINADOR | B3: CENTRO DE COSTOS LÍNEACOM | C3: % | D3: $ | E3: NOMBRE CC | F3: VALOR | J3: Redeban Centro ( Bogotá) | K3: 2098133.1 | L3: 0.064328454
A4: DIEGO FERNANDO HENAO CARDONA | B4: 0004-0002 | C4: 0.038828886 | D4: 515754.88 | E4: =VLOOKUP(B4,'CENTRO DE COSTOS'!B:C,2,0) -> Redeban Eje Cafetero (Pereira) | F4: =D4 -> 515754.88 | J4: Redeban Costa (Barranqullla) | K4: 3188171.7 | L4: 0.097748877
B5: 0004-0003 | C5: 0.20892662 | D5: 2775122.7 | E5: =VLOOKUP(B5,'CENTRO DE COSTOS'!B:C,2,0) -> Redeban Suroccidente (Cali) | F5: =D5 -> 2775122.7 | J5: Redeban Eje Cafetero (Pereira) | K5: 1898065 | L5: 0.058194394
A6: JOSE MAURICIO HERNANDEZ ROJAS | B6: 0004-0001 | C6: 0.13941229 | D6: 1851780.4 | E6: =VLOOKUP(B6,'CENTRO DE COSTOS'!B:C,2,0) -> Redeban Costa (Barranqullla) | F6: =D6 -> 1851780.4 | J6: Redeban Noroccidente (Medellín) | K6: 9497012.5 | L6: 0.29117701
A7: JUAN SEBASTIÁN RÍOS CASTRILLÓN | B7: 0004-0005 | C7: 0.13165335 | D7: 1748720.3 | E7: =VLOOKUP(B7,'CENTRO DE COSTOS'!B:C,2,0) -> Redeban Noroccidente (Medellín) | F7: =D7 -> 1748720.3 | J7: Redeban Oriente (Otros) | K7: 5197327.1 | L7: 0.15934929
A8: KEVIN ALEXIS CORZO BUSTOS | B8: 0004-0007 | C8: 0.18071535 | D8: 2400399.1 | E8: =VLOOKUP(B8,'CENTRO DE COSTOS'!B:C,2,0) -> Redeban Oriente (Otros) | F8: =D8 -> 2400399.1 | J8: Redeban Santander | K8: 6202314.1 | L8: 0.19016204
A9: MIGUEL JULIÁN HERNÁNDEZ GUARÍN | B9: 0004-0008 | C9: 0.24854912 | D9: 3301419 | E9: =VLOOKUP(B9,'CENTRO DE COSTOS'!B:C,2,0) -> Redeban Santander | F9: =D9 -> 3301419 | J9: Redeban Suroccidente (Cali) | K9: 4534918.7 | L9: 0.13903994
A10: WILLIAM ASDRUBAL ROZO ROZO | B10: 0004-0004 | C10: 0.051914376 | D10: 689566.34 | E10: =VLOOKUP(B10,'CENTRO DE COSTOS'!B:C,2,0) -> Redeban Centro ( Bogotá) | F10: =D10 -> 689566.34 | J10: Total general | K10: 32615942 | L10: 1
A11: Total general | C11: 1 | D11: 13282763
A15: INCIDENTES
A16: COORDINADOR | B16: CENTRO DE COSTOS LÍNEACOM | C16: % | D16: $ | E16: NOMBRE CC
A17: DIEGO FERNANDO HENAO CARDONA | B17: 0004-0002 | C17: 0.071843822 | D17: 1316349.7 | E17: =VLOOKUP(B17,'CENTRO DE COSTOS'!B:C,2,0) -> Redeban Eje Cafetero (Pereira) | F17: =D17 -> 1316349.7
B18: 0004-0003 | C18: 0.080997547 | D18: 1484067.7 | E18: =VLOOKUP(B18,'CENTRO DE COSTOS'!B:C,2,0) -> Redeban Suroccidente (Cali) | F18: =D18 -> 1484067.7
A19: JOSE MAURICIO HERNANDEZ ROJAS | B19: 0004-0001 | C19: 0.070868895 | D19: 1298486.7 | E19: =VLOOKUP(B19,'CENTRO DE COSTOS'!B:C,2,0) -> Redeban Costa (Barranqullla) | F19: =D19 -> 1298486.7
A20: JUAN SEBASTIÁN RÍOS CASTRILLÓN | B20: 0004-0005 | C20: 0.42081807 | D20: 7710387.5 | E20: =VLOOKUP(B20,'CENTRO DE COSTOS'!B:C,2,0) -> Redeban Noroccidente (Medellín) | F20: =D20 -> 7710387.5
A21: KEVIN ALEXIS CORZO BUSTOS | B21: 0004-0007 | C21: 0.15265093 | D21: 2796928 | E21: =VLOOKUP(B21,'CENTRO DE COSTOS'!B:C,2,0) -> Redeban Oriente (Otros) | F21: =D21 -> 2796928
A22: MIGUEL JULIÁN HERNÁNDEZ GUARÍN | B22: 0004-0008 | C22: 0.12801265 | D22: 2345496.1 | E22: =VLOOKUP(B22,'CENTRO DE COSTOS'!B:C,2,0) -> Redeban Santander | F22: =D22 -> 2345496.1
A23: WILLIAM ASDRUBAL ROZO ROZO | B23: 0004-0004 | C23: 0.074808094 | D23: 1370662.2 | E23: =VLOOKUP(B23,'CENTRO DE COSTOS'!B:C,2,0) -> Redeban Centro ( Bogotá) | F23: =D23 -> 1370662.2
A24: Total general | C24: 1 | D24: 18322378
A29: OC
A30: COORDINADOR | B30: CENTRO DE COSTOS LÍNEACOM | C30: % | D30: $ | E30: NOMBRE CC
A31: DIEGO FERNANDO HENAO CARDONA | B31: 0004-0003 | C31: 0.27278183 | D31: 275728.38 | E31: =VLOOKUP(B31,'CENTRO DE COSTOS'!B:C,2,0) -> Redeban Suroccidente (Cali) | F31: =D31 -> 275728.38
B32: 0004-0002 | C32: 0.065255592 | D32: 65960.474 | E32: =VLOOKUP(B32,'CENTRO DE COSTOS'!B:C,2,0) -> Redeban Eje Cafetero (Pereira) | F32: =D32 -> 65960.474
A33: JOSE MAURICIO HERNANDEZ ROJAS | B33: 0004-0001 | C33: 0.037499589 | D33: 37904.654 | E33: =VLOOKUP(B33,'CENTRO DE COSTOS'!B:C,2,0) -> Redeban Costa (Barranqullla) | F33: =D33 -> 37904.654
A34: JUAN SEBASTIÁN RÍOS CASTRILLÓN | B34: 0004-0005 | C34: 0.037499589 | D34: 37904.654 | E34: =VLOOKUP(B34,'CENTRO DE COSTOS'!B:C,2,0) -> Redeban Noroccidente (Medellín) | F34: =D34 -> 37904.654
A35: MIGUEL JULIÁN HERNÁNDEZ GUARÍN | B35: 0004-0008 | C35: 0.54946381 | D35: 555399.04 | E35: =VLOOKUP(B35,'CENTRO DE COSTOS'!B:C,2,0) -> Redeban Santander | F35: =D35 -> 555399.04
A36: WILLIAM ASDRUBAL ROZO ROZO | B36: 0004-0004 | C36: 0.037499589 | D36: 37904.654 | E36: =VLOOKUP(B36,'CENTRO DE COSTOS'!B:C,2,0) -> Redeban Centro ( Bogotá) | F36: =D36 -> 37904.654
A37: Total general | C37: 1 | D37: 1010801.9

Sheet ADECUACIONES
A1: CIUDAD SEDE | B1: COORDINADOR | C1: CENTRO DE COSTOS LÍNEACOM | D1: CÓDIGO DANE | E1: TA/CODIGO ACTIVIDAD | F1: CODIGO CB | G1: ACTIVIDAD | H1: TIPO DE APERTURA | I1: DEPARTAMENTO | J1: CIUDAD | K1: NOMBRE DEL CB | L1: RED | M1: FO | N1: FECHA LISTA | O1: FECHA ULTIMA ACTUALIZACION | P1: FORMATO | Q1: CADENA | R1: ESTADO | S1: OBSERVACIONES CLIENTE | T1: FORMA DE ATENCIÓN | U1: TERMINALES | V1: TIPIFICACION | W1: TIPO DE TRAYECTO | X1: NOMBRE DEL TECNICO | Y1: ACOMETIDA DATOS | Z1: ACOMETIDA ELECTRICA | AA1: SWITCH | AB1: ROUTER | AC1: VALOR DIAS ACTIVIDAD FACTURABLES | AD1: DIAS ACTIVIDAD FACTURABLES | AE1: VALOR TOTAL INSTALACION DE PUBLICIDAD
A2: MEDELLIN | B2: =VLOOKUP(A2,'CENTRO DE COSTOS'!A:D,4,FALSE) -> JUAN SEBASTIÁN RÍOS CASTRILLÓN | C2: =VLOOKUP(A2,'CENTRO DE COSTOS'!A:C,2,FALSE) -> 0004-0005 | D2: 5091 | E2: TA-25-792913 | F2: 79058 | G2: APERTURA | H2: CB CRECIMIENTO - OTRAS LISTAS | I2: ANTIOQUIA | J2: BETANIA | K2: BARRIO BETANIA ANTIOQUIA BETANIA | L2: REDEBAN | M2: FO-25-1167345 | N2: 45821 | O2: 45842 | P2: UNO A UNO | Q2: UNO A UNO | R2: EJECUTADO | S2: 13-06 SE ESTABLECE COMUNICACIÓN CON EL USUARIO EL CUAL IDNICA QUE EL NECESITA ES UN CORRESPONSAL CON UN CUPO BASTANTES GRANDE, QUE SI EL CORRESPONSAL ES SOLO POR 10 MILLONES NO LE INTERESA - COMUNICACIÓN POR WPP 13/6/2025 ESTE PUNTO FUE ENVIADO EN LA LISTA DE AYER, ME APOYAN POR FAVOR DEJÁNDOLO PENDIENTE HASTA LAS HORAS DE LA TARDE, ES DECIR, NO PROCESEN LA PROGRAMACIÓN, PERO TAMPOCO LO CANCELEN. 19/6/2025 POR FAVOR PROCEDER CON LA IMPLEMENTACIÓN, AGRADEZCO NOS CONFIRMEN CUANDO SE PROGRAME EL PUNTO. 26/6/2025 SE REALIZÓ VISITA NO SE LOGRA INSTALAR YA QUE EL CUPO ASIGNADO ES DE 10 MILLONES EL CB SOLICITO QUE FUERA MÁS ALTO, SE ESCALO TEMA A BANCO Y NO BRINDAN INFORMACIÓN OPORTUNA ADICIONAL NOS INDICA QUE SE DEBE CORREGIR EL CORREO ELECTRÓNICO RDESCOBARARANGO@YAHOO.ES SE POSPONE ACTIVIDAD 4/7/2025 SE REALIZA INSTALACIÓN DE CORRESPONSAL, SE INSTALAN EQUIPOS CON PRUEBAS EXITOSAS, SE CAPACITA Y SE EVALÚA AL CLIENTE, SE INSTALA PUBLICIDAD COMPLETA, CB QUEDA OPERATIVO. USUARIO SOMOS BANCOLOMBIA ACTIVO | T2: VISITA _TECNICA | U2: SASZZ633 | V2: TIPO III | W2: TERRESTRE | X2: QUINTERO SANCHEZ JUAN SEBASTIAN | Y2: 0 | Z2: 0 | AA2: 0 | AB2: 0 | AC2: 1 | AD2: =IF(V2="TIPO I",'BASE LIQUIDACION'!$D$3,IF(V2="TIPO II",'BASE LIQUIDACION'!$D$4,IF(V2="TIPO III",'BASE LIQUIDACION'!$D$5,'BASE LIQUIDACION'!$D$7))) -> 222904.27 | AE2: =Y2*'BASE LIQUIDACION'!$B$12+Z2*'BASE LIQUIDACION'!$B$11+AA2*'BASE LIQUIDACION'!$B$13+AB2*'BASE LIQUIDACION'!$B$14+AC2*AD2 -> 222904.27
A3: SANTA MARTA | B3: =VLOOKUP(A3,'CENTRO DE COSTOS'!A:D,4,FALSE) -> JOSE MAURICIO HERNANDEZ ROJAS | C3: =VLOOKUP(A3,'CENTRO DE COSTOS'!A:C,2,FALSE) -> 0004-0001 | D3: 44430 | E3: TA-25-790987 | F3: 79898 | G3: APERTURA | H3: CB CRECIMIENTO ALIANZA - NUEVO | I3: LA GUAJIRA | J3: MAICAO | K3: DISTRICOL COMERCIALIZADORA | L3: REDEBAN | M3: FO-25-1186686 | N3: 45826 | O3: 45843 | P3: AGREGADOR | Q3: DISTRICOL | R3: EJECUTADO | S3: 18-06 PROGRAMACIÓN REALIZADA POR LA ALIANZA 21/6/2025 EN COMUNICACIÓN CON EL SEÑOR FRANCISCO VELÁZQUEZ AL NÚMERO 3003299172, ME INFORMA QUE EL PEAJE ENTRE MAICAO Y RIOHACHA FUE VOLADO POR EL ELN, Y QUE EL SECTOR ESTÁ EN ZONA ROJA POR PROBLEMAS DE ORDEN PÚBLICO , SE REPROGRAMA LA VISITA PARA LA PRÓXIMA SEMANA QUE SE RESTABLEZCA EL ORDEN EN EL SECTOR 26/6/2025 LA ALTERACIÓN AUN CONTINUA POR ESTE MOTIVO NO SE HA PODIDO REALIZAR IMPLEMENTACIÓN 2/7/2025 SE PROGRAMA VISITA PARA EL 04-07 04-07 NO SE LOGRA COMPLETAR LA APERTURA YA QUE EL CLIENTE MANIFIESTA NO TENER DISPOSICIÓN POR COMPROMISO FAMILIAR, QUEDA PENDIENTE LA CAPACITACIÓN ESTÁ QUEDA APLAZADA PARA EL DÍA SÁBADO 5 DE JULIO 5/7/2025 SE REALIZA INSTALACIÓN DE CORRESPONSAL, SE INSTALAN EQUIPOS CON PRUEBAS EXITOSAS, SE CAPACITA Y SE EVALÚA AL CLIENTE, SE INSTALA PUBLICIDAD COMPLETA, CB QUEDA OPERATIVO. USUARIO SOMOS BANCOLOMBIA ACTIVO | T3: VISITA _TECNICA | U3: SAUZZ961 | V3: TIPO IV | W3: TERRESTRE | X3: THOMAS CAMPO SIGIFREDO SEGUNDO | Y3: 0 | Z3: 0 | AA3: 0 | AB3: 0 | AC3: 1 | AD3: =IF(V3="TIPO I",'BASE LIQUIDACION'!$D$3,IF(V3="TIPO II",'BASE LIQUIDACION'!$D$4,IF(V3="TIPO III",'BASE LIQUIDACION'!$D$5,'BASE LIQUIDACION'!$D$7))) -> 464809.03 | AE3: =Y3*'BASE LIQUIDACION'!$B$12+Z3*'BASE LIQUIDACION'!$B$11+AA3*'BASE LIQUIDACION'!$B$13+AB3*'BASE LIQUIDACION'!$B$14+AC3*AD3 -> 464809.03
A4: PEREIRA | B4: =VLOOKUP(A4,'CENTRO DE COSTOS'!A:D,4,FALSE) -> DIEGO FERNANDO HENAO CARDONA | C4: =VLOOKUP(A4,'CENTRO DE COSTOS'!A:C,2,FALSE) -> 0004-0002 | D4: 66318 | E4: TA-25-799134 | F4: 80021 | G4: APERTURA | H4: CB CRECIMIENTO - NUEVO | I4: RISARALDA | J4: GUATICA | K4: BARRIO CENTRO GUATICA 4 | L4: REDEBAN | M4: FO-25-1158501 | N4: 45832 | O4: 45847 | P4: UNO A UNO | Q4: UNO A UNO | R4: EJECUTADO | S4: 24-06-2025 SE REALIZA LLAMADA AL CLIENTE, SE HABLA CON LA SRA ZHARICK QUINTERO TABARES SE VALIDA DIRECCIÓN OK, CANAL OK, DISPONIBILIDAD TOTAL, LLAMAR EL DÍA LA INSTALACIÓN PARA CONFIRMAR VISITA, AVISO EXTERIOR ALTURA APROX 3 METROS; TOMACORRIENTE CERCANO: SI; TIENE CABINA DE SEGURIDAD: SI // CONTACTO REALIZADO POR LA APP 27/6/2025 SE REALIZA VISITA DE APERTURA AL CB UNO A UNO CON CÓDIGO 3007080021 BARRIO CENTRO GUATICA 44, DIRECCIÓN CR 5 12 32 , COORDENADAS 5.315427, -75.798033, PERO SE ENCUENTRA CERCANÍA CON CORRESPONSAL DISTRICOL INSTALADO CON CÓDIGO 3007070765 DISTRICOL UNIVERSO ESCOLAR , DIRECCIÓN CL 13 12 66, COORDENADAS 5.315486, -75.797833, QUEDANDO A MENOS DE 25 MTS DE DISTANCIA UNO DEL OTRO A DOS CASAS EN LA MISMA CUADRA, SE REALIZA ESCALAMIENTO POR CERCANÍA EN ESPERA DE COMO PROCEDER. / ENTIDAD APRUEBA INSTALACIÓN 9/7/2025 SE REALIZA INSTALACIÓN DE CORRESPONSAL, SE INSTALAN EQUIPOS CON PRUEBAS EXITOSAS, SE CAPACITA Y SE EVALÚA AL CLIENTE, SE INSTALA PUBLICIDAD COMPLETA, CB QUEDA OPERATIVO. USUARIO SOMOS BANCOLOMBIA ACTIVO | T4: VISITA _TECNICA | U4: SAXZZ471 | V4: TIPO II | W4: TERRESTRE | X4: ARROYAVE CANO MANUEL GUILLERMO | Y4: 0 | Z4: 0 | AA4: 0 | AB4: 0 | AC4: 1 | AD4: =IF(V4="TIPO I",'BASE LIQUIDACION'!$D$3,IF(V4="TIPO II",'BASE LIQUIDACION'!$D$4,IF(V4="TIPO III",'BASE LIQUIDACION'!$D$5,'BASE LIQUIDACION'!$D$7))) -> 134410.39 | AE4: =Y4*'BASE LIQUIDACION'!$B$12+Z4*'BASE LIQUIDACION'!$B$11+AA4*'BASE LIQUIDACION'!$B$13+AB4*'BASE LIQUIDACION'!$B$14+AC4*AD4 -> 134410.39
A5: PEREIRA | B5: =VLOOKUP(A5,'CENTRO DE COSTOS'!A:D,4,FALSE) -> DIEGO FERNANDO HENAO CARDONA | C5: =VLOOKUP(A5,'CENTRO DE COSTOS'!A:C,2,FALSE) -> 0004-0002 | D5: 66001 | E5: TA-25-803999 | F5: 23092 | G5: APERTURA | H5: DATAFONO ADICIONAL - ALIANZA | I5: RISARALDA | J5: PEREIRA | K5: MULTIPAGAS PLAZA DE BOLIVAR PEREIRA | L5: REDEBAN | M5: FO-25-1138992 | N5: 45834 | O5: 45839 | P5: ROBUSTO | Q5: MULTIPAGAS | R5: EJECUTADO/CANCELADO | S5: 26-06 SE REALIZA LLAMADA AL CLIENTE, SE HABLA CON LA SRA CLAUDIA OSORIO SE VALIDA DIRECCIÓN OK, CANAL OK, DISPONIBILIDAD TOTAL, LLAMAR EL DÍA LA INSTALACIÓN PARA CONFIRMAR VISITA, 1/7/2025 SE REALIZA VISITA, EL CLIENTE INDICA QUE NO SE PUEDE DAR INGRESO YA QUE DE CENTRO DE GESTIÓN DE MULTIPAGAS SOLICITAN UN ERRADICADO PARA EL INGRESO, SE LE INDICA AL CLIENTE QUE SE VA A REALIZAR UNA INSTALACIÓN DE DATÁFONO ADICIONAL POR PETICIÓN DE MULTIPAGAS, PERO INDICA QUE UNA VEZ VALIDEN CON EL CENTRO DE GESTIÓN LLAMAN NUEVAMENTE A SOLICITAR LA INSTALACIÓN. | T5: VISITA _TECNICA | U5: V1ZZZ965 | V5: TIPO I | W5: TERRESTRE | X5: FRANCO CAÑAVERAL YAMID RAUL | Y5: 0 | Z5: 0 | AA5: 0 | AB5: 0 | AC5: 1 | AD5: =IF(V5="TIPO I",'BASE LIQUIDACION'!$D$3,IF(V5="TIPO II",'BASE LIQUIDACION'!$D$4,IF(V5="TIPO III",'BASE LIQUIDACION'!$D$5,'BASE LIQUIDACION'!$D$7))) -> 44559.985 | AE5: =Y5*'BASE LIQUIDACION'!$B$12+Z5*'BASE LIQUIDACION'!$B$11+AA5*'BASE LIQUIDACION'!$B$13+AB5*'BASE LIQUIDACION'!$B$14+AC5*AD5 -> 44559.985
A6: SINCELEJO | B6: =VLOOKUP(A6,'CENTRO DE COSTOS'!A:D,4,FALSE) -> JOSE MAURICIO HERNANDEZ ROJAS | C6: =VLOOKUP(A6,'CENTRO DE COSTOS'!A:C,2,FALSE) -> 0004-0001 | D6: 70742 | E6: TA-25-820441 | F6: 80190 | G6: APERTURA | H6: CB CRECIMIENTO - NUEVO | I6: SUCRE | J6: SAN LUIS DE SINCE | K6: BARRIO EL TREBOL SAN LUIS DE SINCE | L6: REDEBAN | M6: FO-25-1161762 | N6: 45839 | O6: 45841 | P6: UNO A UNO | Q6: UNO A UNO | R6: EJECUTADO/CANCELADO | S6: 28-06 SE REALIZA LLAMADA AL CLIENTE, SE HABLA CON EL SR HECTOR MAURICIO HERAZO GALVAN, SE VALIDA DIRECCIÓN OK, CANAL OK, DISPONIBILIDAD TOTAL, LLAMAR EL DÍA LA INSTALACIÓN PARA CONFIRMAR VISITA, AVISO EXTERIOR ALTURA APROX 3 METROS; TOMACORRIENTE CERCANO: SI; TIENE CABINA DE SEGURIDAD: NO 3/7/2025 SE LLEGA A LA DIRECCIÓN RELACIONADA EN LA LISTA DE CHEQUEO CRA 14 12 5,EL TRÉBOL, PERO SE EVIDENCIA QUE EN ESA DIRECCIÓN NO ESTÁ EL COMERCIO, EL COMERCIO ESTA UBICADO EN LA CRA 13 12 03. POR TAL MOTIVO SE CANCELA. | T6: VISITA _TECNICA | U6: F1ZZZ689 | V6: TIPO II | W6: TERRESTRE | X6: SANTOS GUZMAN CHRISTIAN FELIPE | Y6: 0 | Z6: 0 | AA6: 0 | AB6: 0 | AC6: 1 | AD6: =IF(V6="TIPO I",'BASE LIQUIDACION'!$D$3,IF(V6="TIPO II",'BASE LIQUIDACION'!$D$4,IF(V6="TIPO III",'BASE LIQUIDACION'!$D$5,'BASE LIQUIDACION'!$D$7))) -> 134410.39 | AE6: =Y6*'BASE LIQUIDACION'!$B$12+Z6*'BASE LIQUIDACION'!$B$11+AA6*'BASE LIQUIDACION'!$B$13+AB6*'BASE LIQUIDACION'!$B$14+AC6*AD6 -> 134410.39
A7: CALI | B7: =VLOOKUP(A7,'CENTRO DE COSTOS'!A:D,4,FALSE) -> DIEGO FERNANDO HENAO CARDONA | C7: =VLOOKUP(A7,'CENTRO DE COSTOS'!A:C,2,FALSE) -> 0004-0003 | D7: 19001 | E7: TA-25-820966 | F7: 80185 | G7: APERTURA | H7: CB CRECIMIENTO - NUEVO | I7: CAUCA | J7: POPAYAN | K7: BARRIO ESMERALDA POPAYAN 5 | L7: REDEBAN | M7: FO-25-1174585 | N7: 45839 | O7: 45850 | P7: UNO A UNO | Q7: UNO A UNO | R7: EJECUTADO | S7: 01-07-2025 SE REALIZA LLAMADA AL CLIENTE, SE HABLA CON LA SRA SANDRA LORENA PAMPLONA DORADO SE VALIDA DIRECCIÓN OK, CANAL OK, DISPONIBILIDAD TOTAL, LLAMAR EL DÍA LA INSTALACIÓN PARA CONFIRMAR VISITA, AVISO EXTERIOR ALTURA APROX CLIENTE NO TIENE CONOCIMIENTO DE MEDIDAS; TOMACORRIENTE CERCANO: SI; TIENE CABINA DE SEGURIDAD: SI // CONTACTO REALIZADO POR LA APP 2/7/2025 SE REALIZA VISITA DE APERTURA AL CB UNO A UNO CON CÓDIGO 3007080021 BARRIO ESMERALDA POPAYAN 5 , DIRECCIÓN CR 18 7 B 11 LC 1 , COORDENADAS 2.442165, -76.616340, PERO SE ENCUENTRA CERCANÍA CON CORRESPONSAL PTM INSTALADO CON CÓDIGO 3007072845 PTM POPAYAN VARIEDADES , DIRECCIÓN CR 18 7 A 15, COORDENADAS 2.442495, -76.616620, QUEDANDO A MENOS DE 30 MTS DE DISTANCIA UNO DEL OTRO , SE REALIZA ESCALAMIENTO POR CERCANÍA EN ESPERA DE COMO PROCEDER. 2/7/2025 ENTIDAD APRUEBA INSTALACIÓN 02-07 SE REALIZÓ LLAMADA DE VALIDACIÓN Y EL CLIENTE, EL SEÑOR JONATHAN MORA ME COMENTÓ QUE NO PUEDE ATENDERNOS EL DÍA DE HOY PORQUE NO LE HABÍAN INFORMADO NADA, QUE PORFA PARA EL DÍA VIERNES POR LA TARDE O PARA LA OTRA SEMANA PERO QUE SE LE INFORME ANTES PARA ÉL ESTAR PREPARADO. 11/7/2025 EN NUEVA COMUNICACIÓN CON EL USUARIO INDICA QUE NOS ATIENDE EL DIA DE MAÑANA 12-07 SE REALIZA INSTALACIÓN DE CORRESPONSAL, SE INSTALAN EQUIPOS CON PRUEBAS EXITOSAS, SE CAPACITA Y SE EVALÚA AL CLIENTE, SE INSTALA PUBLICIDAD COMPLETA, CB QUEDA OPERATIVO. USUARIO SOMOS BANCOLOMBIA ACTIVO | T7: VISITA _TECNICA | U7: F1ZZZ726 | V7: TIPO III | W7: TERRESTRE | X7: GIMBUEL LASSO LUIS GERMAN | Y7: 0 | Z7: 0 | AA7: 0 | AB7: 0 | AC7: 1 | AD7: =IF(V7="TIPO I",'BASE LIQUIDACION'!$D$3,IF(V7="TIPO II",'BASE LIQUIDACION'!$D$4,IF(V7="TIPO III",'BASE LIQUIDACION'!$D$5,'BASE LIQUIDACION'!$D$7))) -> 222904.27 | AE7: =Y7*'BASE LIQUIDACION'!$B$12+Z7*'BASE LIQUIDACION'!$B$11+AA7*'BASE LIQUIDACION'!$B$13+AB7*'BASE LIQUIDACION'!$B$14+AC7*AD7 -> 222904.27
A8: BOGOTA | B8: =VLOOKUP(A8,'CENTRO DE COSTOS'!A:D,4,FALSE) -> WILLIAM ASDRUBAL ROZO ROZO | C8: =VLOOKUP(A8,'CENTRO DE COSTOS'!A:C,2,FALSE) -> 0004-0004 | D8: 25320 | E8: TA-25-821243 | F8: 80152 | G8: APERTURA | H8: CB CRECIMIENTO - NUEVO | I8: CUNDINAMARCA | J8: GUADUAS | K8: BARRIO CENTRO GUADUAS 5 | L8: REDEBAN | M8: FO-25-1180211 | N8: 45839 | O8: 45847 | P8: UNO A UNO | Q8: UNO A UNO | R8: EJECUTADO | S8: 1-07-2025 SE REALIZA COMUNICACION CON CLIENTE, SE HABLA CON LA SRA ARAMINTA GALINDO ROJAS SE VALIDA DIRECCIÓN OK, CANAL OK, DISPONIBILIDAD TOTAL, LLAMAR EL DÍA DE LA INSTALACIÓN PARA CONFIRMAR VISITA, ALTURA APROX 2 METROS; TOMACORRIENTE CERCANO: SI; TIENE CABINA DE SEGURIDAD: NO // CONTACTO REALIZADO POR WHATSAPP 10:49 a. m. 3/7/2025 SE VISITA COMERCIO, SE EVIDENCIA QUE EL CLIENTE NO TIENE UN PUNTO DE RED LISTO PARA CONECTAR EL EQUIPO CB BANCOLOMBIA A INSTALAR, EL CLIENTE INDICA QUE SI PODEMOS REPROGRAMAR LA VISITA PARA EL DÍA MIERCOLES 9 DE JULIO QUE YA TENDRÍA EL PUNTO DE INTERNET, SE INFORMA AL COORDINADOR QUIEN INDICA REPROGRAMAR VISITA PARA DICHA FECHA. 09-07 SE REALIZA INSTALACIÓN DE CORRESPONSAL, SE INSTALAN EQUIPOS CON PRUEBAS EXITOSAS, SE CAPACITA Y SE EVALÚA AL CLIENTE, SE INSTALA PUBLICIDAD COMPLETA, CB QUEDA OPERATIVO. USUARIO SOMOS BANCOLOMBIA ACTIVO | T8: VISITA _TECNICA | U8: F1ZZZ749 | V8: TIPO III | W8: TERRESTRE | X8: BUSTOS MORA DIEGO MANUEL | Y8: 0 | Z8: 0 | AA8: 0 | AB8: 0 | AC8: 1 | AD8: =IF(V8="TIPO I",'BASE LIQUIDACION'!$D$3,IF(V8="TIPO II",'BASE LIQUIDACION'!$D$4,IF(V8="TIPO III",'BASE LIQUIDACION'!$D$5,'BASE LIQUIDACION'!$D$7))) -> 222904.27 | AE8: =Y8*'BASE LIQUIDACION'!$B$12+Z8*'BASE LIQUIDACION'!$B$11+AA8*'BASE LIQUIDACION'!$B$13+AB8*'BASE LIQUIDACION'!$B$14+AC8*AD8 -> 222904.27
A9: NEIVA | B9: =VLOOKUP(A9,'CENTRO DE COSTOS'!A:D,4,FALSE) -> KEVIN ALEXIS CORZO BUSTOS | C9: =VLOOKUP(A9,'CENTRO DE COSTOS'!A:C,2,FALSE) -> 0004-0007 | D9: 18001 | E9: TA-25-821658 | F9: 79863 | G9: APERTURA | H9: CB CRECIMIENTO - OTRAS LISTAS | I9: CAQUETA | J9: FLORENCIA | K9: BARRIO CENTRO FLORENCIA 38 | L9: REDEBAN | M9: FO-25-1163140 | N9: 45839 | O9: 45840 | P9: UNO A UNO | Q9: UNO A UNO | R9: EJECUTADO/CANCELADO | S9: 01-07 SE REALIZA LLAMADA AL CLIENTE, SE HABLA CON LA SR JUAN CAMILO SANCHEZ SILVASE VALIDA DIRECCIÓN OK, CANAL OK, DISPONIBILIDAD TOTAL, LLAMAR EL DÍA LA INSTALACIÓN PARA CONFIRMAR VISITA, AVISO EXTERIOR ALTURA APROX 2.50 METROS; TOMACORRIENTE CERCANO: SI; TIENE CABINA DE SEGURIDAD: NO 2/7/2025 SALIÓ NUEVAMENTE ESTA APERTURA, SE REALIZÓ VISITA PARA IMPLEMENTACIÓN DEL CB 79863, PERO SE EVIDENCIA QUE EL COMERCIO ESTÁ UBICADO EN LA CARRERA 16 # 15 – 37 EN UN LOCAL DE ESA DIRECCIÓN, SIN EMBARGO EL USUARIO INDICA QUE AHÍ LA DIRECCIÓN ES CARRERA 16 # 15 – 36, NOS INDICA QUE CÁMARA DE COMERCIO Y RECIBO DE SERVICIOS PÚBLICOS APARECEN DE ESA FORMA, SE VALIDA LA ACERA DONDE EL USUARIO INDICA Y ESTA ES LA ACERA DONDE VAN LAS DIRECCIONES DE NÚMEROS IMPARES, ADICIONAL SE EVIDENCIA QUE PARA ESTA VISITA PEGARON UNA NOMENCLATURA CON LA DIRECCIÓN CARRERA 16 # 15 – 36 DONDE ESTA DEBE IR EN LA ACERA DEL FRENTE, PUES LA DEL FRENTE VAN LAS DIRECCIONES PARES TAMBIÉN SE VALIDAN EN LOS LOCALES QUE ESTÁN EN LA DIRECCIÓN Y SE EVIDENCIA QUE HAY UNO DICE QUE CARRERA 16 # 15 – 37 LOCAL 4, ADEMÁS DONDE EL USUARIO DICE INSTALAR TIENE OTRO NOMBRE DE COMERCIO DIFERENTE AL QUE SE RELACIONA EN LISTA DE CHEQUEO. SEGÚN LO CONVERSADO SE PROCEDE CON LA CANCELACIÓN DE LA APERTURA | T9: VISITA _TECNICA | U9: F1ZZZ594 | V9: TIPO IV | W9: TERRESTRE | X9: BERMUDEZ SANCHEZ JOSE NEYBER | Y9: 0 | Z9: 0 | AA9: 0 | AB9: 0 | AC9: 1 | AD9: =IF(V9="TIPO I",'BASE LIQUIDACION'!$D$3,IF(V9="TIPO II",'BASE LIQUIDACION'!$D$4,IF(V9="TIPO III",'BASE LIQUIDACION'!$D$5,'BASE LIQUIDACION'!$D$7))) -> 464809.03 | AE9: =Y9*'BASE LIQUIDACION'!$B$12+Z9*'BASE LIQUIDACION'!$B$11+AA9*'BASE LIQUIDACION'!$B$13+AB9*'BASE LIQUIDACION'!$B$14+AC9*AD9 -> 464809.03
A10: NEIVA | B10: =VLOOKUP(A10,'CENTRO DE COSTOS'!A:D,4,FALSE) -> KEVIN ALEXIS CORZO BUSTOS | C10: =VLOOKUP(A10,'CENTRO DE COSTOS'!A:C,2,FALSE) -> 0004-0007 | D10: 41001 | E10: TA-25-821800 | F10: 76738 | G10: APERTURA | H10: DATAFONO ADICIONAL | I10: HUILA | J10: NEIVA | K10: BARRIO IPANEMA NEIVA 2 | L10: REDEBAN | M10: FO-25-1163305 | N10: 45839 | O10: 45841 | P10: UNO A UNO | Q10: UNO A UNO | R10: EJECUTADO/CANCELADO | S10: 01-07 SE REALIZA LLAMADA AL CLIENTE, SE HABLA CON LA SR ERIK JESCE PERDOMO RODRIGUEZ SE VALIDA DIRECCIÓN OK, CANAL OK, DISPONIBILIDAD TOTAL, LLAMAR EL DÍA LA INSTALACIÓN PARA CONFIRMAR VISITA 3/7/2025 SE LLEGA A SITIO, SE ENCUENTRA LOCAL DESOCUPADO, SE LLAMA A CLIENTE E INDICA QUE YA NO NECESITA EL DATAFONO ADICIONAL. | T10: VISITA _TECNICA | U10: F1ZZZ785 | V10: TIPO I | W10: TERRESTRE | X10: DIAZ VARGAS JONATHAN MIGUEL | Y10: 0 | Z10: 0 | AA10: 0 | AB10: 0 | AC10: 1 | AD10: =IF(V10="TIPO I",'BASE LIQUIDACION'!$D$3,IF(V10="TIPO II",'BASE LIQUIDACION'!$D$4,IF(V10="TIPO III",'BASE LIQUIDACION'!$D$5,'BASE LIQUIDACION'!$D$7))) -> 44559.985 | AE10: =Y10*'BASE LIQUIDACION'!$B$12+Z10*'BASE LIQUIDACION'!$B$11+AA10*'BASE LIQUIDACION'!$B$13+AB10*'BASE LIQUIDACION'!$B$14+AC10*AD10 -> 44559.985
A11: PEREIRA | B11: =VLOOKUP(A11,'CENTRO DE COSTOS'!A:D,4,FALSE) -> DIEGO FERNANDO HENAO CARDONA | C11: =VLOOKUP(A11,'CENTRO DE COSTOS'!A:C,2,FALSE) -> 0004-0002 | D11: 66001 | E11: TA-25-831668 | F11: 80221 | G11: APERTURA | H11: CB CRECIMIENTO ALIANZA - NUEVO | I11: RISARALDA | J11: PEREIRA | K11: PTM PEREIRA SUPER SERVICIOS PU | L11: REDEBAN | M11: FO-25-1195655 | N11: 45841 | O11: 45846 | P11: AGREGADOR | Q11: COMCARD - PTM | R11: EJECUTADO | S11: 03-07 PROGRAMACIÓN REALIZADA POR LA ALIANZA 7/7/2025 SE REALIZA VISITA DE APERTURA AL CB PTM CON CÓDIGO 3007080221 PTM PEREIRA SUPERSERVICIOS , DIRECCIÓN CR 8 NO 15-20 LC 74 , COORDENADAS 4.813491, -75.691164, PERO SE ENCUENTRA CERCANÍA CON CORRESPONSAL UNO A UNO INSTALADO CON CÓDIGO 3007075477 BARRIO CENTRO PEREIRA 49 , DIRECCIÓN CR 8 14 73, COORDENADAS 4.813375,-75.690848, QUEDANDO A MENOS DE 30 MTS DE DISTANCIA UNO DEL OTRO , Y SE ENCUENTRA CERCANIA CON CORRESPONSAL DISTRICOL INSTALADO CON CODIGO 3007079902 DISTRICOL MULTICENTER, DIRECCION CR 8 15 62, CORDENADAS 4.813540,-75.691522, QUEDANDO A MENOS DE 40 MTS, SE REALIZA ESCALAMIENTO POR DOBLE CERCANÍA EN ESPERA DE COMO PROCEDER. / ENTIDAD APRUEBA INSTALACIÓN 8/7/2025 SE REALIZA INSTALACIÓN DE CORRESPONSAL, SE INSTALAN EQUIPOS CON PRUEBAS EXITOSAS, SE CAPACITA Y SE EVALÚA AL CLIENTE, SE INSTALA PUBLICIDAD COMPLETA, CB QUEDA OPERATIVO. USUARIO SOMOS BANCOLOMBIA ACTIVO | T11: VISITA _TECNICA | U11: F4ZZZ852 | V11: TIPO I | W11: TERRESTRE | X11: FRANCO CAÑAVERAL YAMID RAUL | Y11: 0 | Z11: 0 | AA11: 0 | AB11: 0 | AC11: 1 | AD11: =IF(V11="TIPO I",'BASE LIQUIDACION'!$D$3,IF(V11="TIPO II",'BASE LIQUIDACION'!$D$4,IF(V11="TIPO III",'BASE LIQUIDACION'!$D$5,'BASE LIQUIDACION'!$D$7))) -> 44559.985 | AE11: =Y11*'BASE LIQUIDACION'!$B$12+Z11*'BASE LIQUIDACION'!$B$11+AA11*'BASE LIQUIDACION'!$B$13+AB11*'BASE LIQUIDACION'!$B$14+AC11*AD11 -> 44559.985
A12: SINCELEJO | B12: =VLOOKUP(A12,'CENTRO DE COSTOS'!A:D,4,FALSE) -> JOSE MAURICIO HERNANDEZ ROJAS | C12: =VLOOKUP(A12,'CENTRO DE COSTOS'!A:C,2,FALSE) -> 0004-0001 | D12: 70001 | E12: TA-25-837839 | F12: 80305 | G12: APERTURA | H12: CB CRECIMIENTO - NUEVO | I12: SUCRE | J12: SINCELEJO | K12: BARRIO LA FE SINCELEJO 1 | L12: REDEBAN | M12: FO-25-1193644 | N12: 45845 | O12: 45846 | P12: UNO A UNO | Q12: UNO A UNO | R12: EJECUTADO/CANCELADO | S12: 5-07 SE REALIZA LLAMADA AL CLIENTE, SE HABLA CON EL FABIAN LIEVANO ROJAS, SE VALIDA DIRECCIÓN OK, CANAL OK, DISPONIBILIDAD TOTAL, LLAMAR EL DÍA LA INSTALACIÓN PARA CONFIRMAR VISITA, AVISO EXTERIOR ALTURA APROX DONDE EL TECNICO LO VEA CONVENIENTE, TOMACORRIENTE CERCANO: SI; TIENE CABINA DE SEGURIDAD: SI 8/7/2025 SE REALIZA VISITA PARA IMPLEMENTACIÓN DEL CB, PERO SE EVIDENCIA QUE EL PUNTO ESTÁ UBICADO EN LA DIRECCIÓN CRA 24 # 5 – 53, AUNQUE EL USUARIO MUESTRA CÁMARA DE COMERCIO Y RECIBO DE ENERGÍA ESTOS NO CORRESPONDEN A LA RELACIONADA EN LA LISTA DE CHEQUEO CR 24 24C 11,LA FE, POR TAL RAZÓN SE CANCELA ACTIVIDAD | T12: VISITA _TECNICA | U12: FAZZZ513 | V12: TIPO I | W12: TERRESTRE | X12: SANTOS GUZMAN CHRISTIAN FELIPE | Y12: 0 | Z12: 0 | AA12: 0 | AB12: 0 | AC12: 1 | AD12: =IF(V12="TIPO I",'BASE LIQUIDACION'!$D$3,IF(V12="TIPO II",'BASE LIQUIDACION'!$D$4,IF(V12="TIPO III",'BASE LIQUIDACION'!$D$5,'BASE LIQUIDACION'!$D$7))) -> 44559.985 | AE12: =Y12*'BASE LIQUIDACION'!$B$12+Z12*'BASE LIQUIDACION'!$B$11+AA12*'BASE LIQUIDACION'!$B$13+AB12*'BASE LIQUIDACION'!$B$14+AC12*AD12 -> 44559.985
A13: CALI | B13: =VLOOKUP(A13,'CENTRO DE COSTOS'!A:D,4,FALSE) -> DIEGO FERNANDO HENAO CARDONA | C13: =VLOOKUP(A13,'CENTRO DE COSTOS'!A:C,2,FALSE) -> 0004-0003 | D13: 76670 | E13: TA-25-837933 | F13: 80302 | G13: APERTURA | H13: CB CRECIMIENTO - NUEVO | I13: VALLE DEL CAUCA | J13: SAN PEDRO | K13: BARRIO JARDIN SAN PEDRO | L13: REDEBAN | M13: FO-25-1193861 | N13: 45845 | O13: 45847 | P13: UNO A UNO | Q13: UNO A UNO | R13: EJECUTADO/CANCELADO | S13: 07-07-2025 SE REALIZA LLAMADA AL CLIENTE, SE HABLA CON LA SRA ANDREA VILLALOBOS VAZQUEZOROZCO SE VALIDA DIRECCIÓN OK, CANAL OK, DISPONIBILIDAD TOTAL, LLAMAR EL DÍA LA INSTALACIÓN PARA CONFIRMAR VISITA, AVISO EXTERIOR ALTURA APROX 2 METROS; TOMACORRIENTE CERCANO: SI; TIENE CABINA DE SEGURIDAD: SI // CONTACTO REALIZADO POR LA APP 9/7/2025 SE VISITÓ COMERCIO, CLIENTE SIN ADECUACIÓN PARA INSTALACIÓN; NO HAY PUERTOS DE RED DISPONIBLES PARA INSTALACION DEL EQUIPO EN UBICACIÓN ASIGNADA. EN OFICINA PRINCIPAL NO ES POSIBLE INSTALAR DEBIDO A QUE NO PUEDE ATENDER A CLIENTES ALLÁ PORQUE ES RIESGOSO PARA EL COMERCIO A DEMÁS ES ZONA ADMINISTRATIVA NO ADECUADA PARA PARA ATENCIÓN. A DEMÁS TAMPOCO SE PUDO DEJAR PARCIALMENTE EQUIPO ALLÁ DEBIDO QUE TAMPOCO HAY PUERTOS DISPONIBLE. CLIENTE TOMA LA DECISIÓN DE RE PROGRAMAR E INDICA QUE VA REALIZAR LA ADECUACIÓN PARA QUE QUEDE OPERATIVO DE LA FORMA CORRECTA. | T13: VISITA _TECNICA | U13: FAZZZ539 | V13: TIPO II | W13: TERRESTRE | X13: BOLAÑOS TABORDA JORGE ENRIQUE | Y13: 0 | Z13: 0 | AA13: 0 | AB13: 0 | AC13: 1 | AD13: =IF(V13="TIPO I",'BASE LIQUIDACION'!$D$3,IF(V13="TIPO II",'BASE LIQUIDACION'!$D$4,IF(V13="TIPO III",'BASE LIQUIDACION'!$D$5,'BASE LIQUIDACION'!$D$7))) -> 134410.39 | AE13: =Y13*'BASE LIQUIDACION'!$B$12+Z13*'BASE LIQUIDACION'!$B$11+AA13*'BASE LIQUIDACION'!$B$13+AB13*'BASE LIQUIDACION'!$B$14+AC13*AD13 -> 134410.39
... A70: TUNJA | B70: =VLOOKUP(A70,'CENTRO DE COSTOS'!A:D,4,FALSE) -> MIGUEL JULIÁN HERNÁNDEZ GUARÍN | C70: =VLOOKUP(A70,'CENTRO DE COSTOS'!A:C,2,FALSE) -> 0004-0008 | D70: 15238 | E70: TA-25-904103 | F70: 80731 | G70: APERTURA | H70: CB CRECIMIENTO - NUEVO | I70: BOYACA | J70: DUITAMA | K70: BARRIO LA GRUTA DUITAMA 1 | L70: REDEBAN | M70: FO-25-1305107 | N70: 45868 | O70: 45869 | P70: UNO A UNO | Q70: UNO A UNO | R70: EJECUTADO | S70: 30-07 SE REALIZA LLAMADA AL CLIENTE, SE HABLA CON LA SR RUBEN ARMANDO LEAL SUAREZ SE VALIDA DIRECCIÓN OK, CANAL OK, DISPONIBILIDAD TOTAL, LLAMAR EL DÍA LA INSTALACIÓN PARA CONFIRMAR VISITA, AVISO EXTERIOR ALTURA APROX 2.5 METROS; TOMACORRIENTE CERCANO: SI; TIENE CABINA DE SEGURIDAD: NO - EL MODEM ESTA A 10 MT 31-07 SE REALIZA INSTALACIÓN DE CORRESPONSAL, SE INSTALAN EQUIPOS CON PRUEBAS EXITOSAS, SE CAPACITA Y SE EVALÚA AL CLIENTE, SE INSTALA PUBLICIDAD COMPLETA, CB QUEDA OPERATIVO. USUARIO SOMOS BANCOLOMBIA ACTIVO. SE INSTALA ROUTER | T70: VISITA _TECNICA | U70: VAZZZ391 | V70: TIPO II | W70: TERRESTRE | X70: RODRIGUEZ MURCIA YERSON IVAN | Y70: 0 | Z70: 0 | AA70: 0 | AB70: 1 | AC70: 0 | AD70: =IF(V70="TIPO I",'BASE LIQUIDACION'!$D$3,IF(V70="TIPO II",'BASE LIQUIDACION'!$D$4,IF(V70="TIPO III",'BASE LIQUIDACION'!$D$5,'BASE LIQUIDACION'!$D$7))) -> 134410.39 | AE70: =Y70*'BASE LIQUIDACION'!$B$12+Z70*'BASE LIQUIDACION'!$B$11+AA70*'BASE LIQUIDACION'!$B$13+AB70*'BASE LIQUIDACION'!$B$14+AC70*AD70 -> 306552.28
AE71: =SUM(AE2:AE70) -> 13282763

Sheet TIPOLOGIAS
A1: COD. CIUDAD | B1: CIUDAD | C1: DEPARTAMENTO | D1: DESDE DONDE SE ATIENDE | E1: TIPO DE TRAYECTO NUEVO | F1: TIPOLOGIA NUEVA
A2: 91430 | B2: LA VICTORIA | C2: AMAZONAS | D2: BOGOTA | E2: AEREO | F2: TIPO IV ESPECIAL
A3: 91669 | B3: PUERTO SANTANDER | C3: AMAZONAS | D3: BOGOTA | E3: AEREO | F3: TIPO IV ESPECIAL
A4: 91263 | B4: EL ENCANTO | C4: AMAZONAS | D4: BOGOTA | E4: AEREO | F4: TIPO IV ESPECIAL
A5: 91405 | B5: LA CHORRERA | C5: AMAZONAS | D5: BOGOTA | E5: AEREO | F5: TIPO IV ESPECIAL
A6: 91407 | B6: LA PEDRERA | C6: AMAZONAS | D6: BOGOTA | E6: AEREO | F6: TIPO IV ESPECIAL
A7: 91001 | B7: LETICIA | C7: AMAZONAS | D7: BOGOTA | E7: AEREO | F7: TIPO IV ESPECIAL
A8: 91460 | B8: MIRITI - PARANA | C8: AMAZONAS | D8: BOGOTA | E8: AEREO | F8: TIPO IV ESPECIAL
A9: 91530 | B9: PUERTO ALEGRIA | C9: AMAZONAS | D9: BOGOTA | E9: AEREO | F9: TIPO IV ESPECIAL
A10: 91536 | B10: PUERTO ARICA | C10: AMAZONAS | D10: BOGOTA | E10: AEREO | F10: TIPO IV ESPECIAL
A11: 91540 | B11: PUERTO NARIÑO | C11: AMAZONAS | D11: BOGOTA | E11: AEREO | F11: TIPO IV ESPECIAL
A12: 91798 | B12: TARAPACA | C12: AMAZONAS | D12: BOGOTA | E12: AEREO | F12: TIPO IV ESPECIAL
A13: 5055 | B13: ARGELIA | C13: ANTIOQUIA | D13: MEDELLIN | E13: TERRESTRE | F13: TIPO IV
... A1124: 23682 | B1124: SAN JOSE DE URE | C1124: CORDOBA | D1124: MONTERIA | E1124: TERRESTRE | F1124: TIPO III

Sheet INCIDENTES
A1: CIUDAD SEDE | B1: COORDINADOR | C1: CENTRO DE COSTOS LÍNEACOM | D1: CÓDIGO DANE | E1: TA/CODIGO ACTIVIDAD | F1: CODIGO CB | G1: ACTIVIDAD | H1: DEPARTAMENTO | I1: CIUDAD | J1: NOMBRE DEL CB | K1: RED | L1: FO | M1: FECHA ASIGNACIÓN A LÍNEA COMUNICACIONES (DD/MM/AAAA HH:MM) | N1: FECHA CIERRE DEL TICKET (DD/MM/AAAA HH:MM) | O1: ACOMETIDA | P1: GRUPO_FALLA | Q1: CATEGORÍA | R1: FALLA | S1: FORMATO | T1: CADENA | U1: ESTADO | V1: OBSERVACION | W1: FORMA DE ATENCIÓN | X1: TERMINAL | Y1: TIPIFICACION | Z1: TIPO DE TRAYECTO | AA1: NOMBRE DEL TECNICO | AB1: DIAS DE VISITA | AC1: ACOMETIDA DATOS | AD1: ACOMETIDA ELÉCTRICA | AE1: SWITCH | AF1: VALOR DIAS ACTIVIDAD FACTURABLES | AG1: VALOR DIAS ACOMPAÑAMIENTO FACTURABLES
A2: CUCUTA | B2: =VLOOKUP(A2,'CENTRO DE COSTOS'!A:D,4,FALSE) -> MIGUEL JULIÁN HERNÁNDEZ GUARÍN | C2: =VLOOKUP(A2,'CENTRO DE COSTOS'!A:D,2,FALSE) -> 0004-0008 | D2: 54001 | E2: 2373443 | F2: 74274 | G2: INCIDENTE | H2: NORTE DE SANTANDER | I2: CUCUTA | J2: BARRIO LA LIBERTAD CUCUTA 20 | K2: REDEBAN | L2: FO-25-1159231 | M2: 45839.408 | N2: 45839.622 | O2: NO | P2: USUARIO | Q2: MANTENIMIENTO | R2: MANTENIMIENTO GENERAL | S2: CB UNO A UNO | U2: CERRADO | V2: 01-07 SE ESCALA PARA VISITA. LLAMAR ANTES DE VISITAR, CONFIRMAR FALLA Y DATOS 0 01-07 SE REALIZÓ VISITA AL COMERCIO Y CLIENTE MANIFIESTA QUE SE LE CALLO EL CUBRE TECLADO, SE REALIZA MANTENIMIENTO Y SE COLOCA CUBRE TECLADO NUEVO | W2: VISITA_TÉCNICA | X2: MN3ZZ476 | Y2: TIPO I | Z2: TERRESTRE | AA2: MORA VEGA JEAMPIER | AB2: 1 | AC2: 0 | AD2: 0 | AE2: 0 | AF2: =IF(W2="SOPORTE_TELEFÓNICO",'BASE LIQUIDACION'!$B$10,IF(Y2="TIPO I",'BASE LIQUIDACION'!$C$3,IF(Y2="TIPO II",'BASE LIQUIDACION'!$C$4,IF(Y2="TIPO III",'BASE LIQUIDACION'!$C$5,'BASE LIQUIDACION'!$C$7)))) -> 65960.474 | AG2: =IF(W2="SOPORTE_TELEFÓNICO",'BASE LIQUIDACION'!$B$10,(AB2*AF2+AC2*'BASE LIQUIDACION'!$B$12+AD2*'BASE LIQUIDACION'!$B$11+INCIDENTES!AE2*'BASE LIQUIDACION'!$B$13)) -> 65960.474
A3: NEIVA | B3: =VLOOKUP(A3,'CENTRO DE COSTOS'!A:D,4,FALSE) -> KEVIN ALEXIS CORZO BUSTOS | C3: =VLOOKUP(A3,'CENTRO DE COSTOS'!A:D,2,FALSE) -> 0004-0007 | D3: 18001 | E3: 2373754 | F3: 76544 | G3: INCIDENTE | H3: CAQUETA | I3: FLORENCIA | J3: OPRAP EXITO GRAN PLAZA FLORENCIA | K3: REDEBAN | L3: FO-25-1159163 | M3: 45839.417 | N3: 45839.64 | O3: NO | P3: USUARIO | Q3: USUARIOS | R3: MALA MANIPULACION POS | S3: ROBUSTO | U3: CERRADO | V3: 01-07 SE ESCALA PARA VISITA. LLAMAR ANTES DE VISITAR, CONFIRMAR FALLA Y DATOS 0 01-07 SE LLEGA AL CB Y CB SE ENCUENTRA FUNCIONANDO CON NORMALIDAD, SE EVIDENCIA QUE EL USUARIO REALIZA MALA LA MANIPULACIÓN DEL DATÁFONO AL MOMENTO DE REALIZAR EL CIERRE Y ESTO GENERA EL LLENADO DE MEMORIA Y ENDE SE REINICIA EL DATÁFONO. | W3: VISITA_TÉCNICA | X3: 103ZZ224 | Y3: TIPO IV | Z3: TERRESTRE | AA3: BERMUDEZ SANCHEZ JOSE NEYBER | AB3: 1 | AC3: 0 | AD3: 0 | AE3: 0 | AF3: =IF(W3="SOPORTE_TELEFÓNICO",'BASE LIQUIDACION'!$B$10,IF(Y3="TIPO I",'BASE LIQUIDACION'!$C$3,IF(Y3="TIPO II",'BASE LIQUIDACION'!$C$4,IF(Y3="TIPO III",'BASE LIQUIDACION'!$C$5,'BASE LIQUIDACION'!$C$7)))) -> 479589.74 | AG3: =IF(W3="SOPORTE_TELEFÓNICO",'BASE LIQUIDACION'!$B$10,(AB3*AF3+AC3*'BASE LIQUIDACION'!$B$12+AD3*'BASE LIQUIDACION'!$B$11+INCIDENTES!AE3*'BASE LIQUIDACION'!$B$13)) -> 479589.74
A4: MEDELLIN | B4: =VLOOKUP(A4,'CENTRO DE COSTOS'!A:D,4,FALSE) -> JUAN SEBASTIÁN RÍOS CASTRILLÓN | C4: =VLOOKUP(A4,'CENTRO DE COSTOS'!A:D,2,FALSE) -> 0004-0005 | D4: 5001 | E4: 2376452 | F4: 78286 | G4: INCIDENTE | H4: ANTIOQUIA | I4: MEDELLIN | J4: BARRIO ROBLEDO MIRAMAR MEDELLIN 3 | K4: REDEBAN | L4: FO-25-1165748 | M4: 45839.547 | N4: 45839.651 | O4: NO | P4: USUARIO | Q4: LECTOR DE TARJETAS | R4: OBSTRUCCION DEL LECTOR | S4: CB UNO A UNO | U4: CERRADO | V4: 01-07 SE ESCALA PARA VISITA. LLAMAR ANTES DE VISITAR, CONFIRMAR FALLA Y DATOS 0 01-07 SE REALIZA MANTENIMIENTO GENERAL | W4: VISITA_TÉCNICA | X4: SXNZZ611 | Y4: TIPO I | Z4: TERRESTRE | AA4: HERNANDEZ CHAVARRIA JUAN CAMILO | AB4: 1 | AC4: 0 | AD4: 0 | AE4: 0 | AF4: =IF(W4="SOPORTE_TELEFÓNICO",'BASE LIQUIDACION'!$B$10,IF(Y4="TIPO I",'BASE LIQUIDACION'!$C$3,IF(Y4="TIPO II",'BASE LIQUIDACION'!$C$4,IF(Y4="TIPO III",'BASE LIQUIDACION'!$C$5,'BASE LIQUIDACION'!$C$7)))) -> 65960.474 | AG4: =IF(W4="SOPORTE_TELEFÓNICO",'BASE LIQUIDACION'!$B$10,(AB4*AF4+AC4*'BASE LIQUIDACION'!$B$12+AD4*'BASE LIQUIDACION'!$B$11+INCIDENTES!AE4*'BASE LIQUIDACION'!$B$13)) -> 65960.474
A5: VALLEDUPAR | B5: =VLOOKUP(A5,'CENTRO DE COSTOS'!A:D,4,FALSE) -> JOSE MAURICIO HERNANDEZ ROJAS | C5: =VLOOKUP(A5,'CENTRO DE COSTOS'!A:D,2,FALSE) -> 0004-0001 | D5: 20032 | E5: 2359858 | F5: 12343 | G5: INCIDENTE | H5: CESAR | I5: ASTREA | J5: ASTREA II - CESAR | K5: REDEBAN | L5: FO-25-1139132 | M5: 45834.497 | N5: 45839.658 | O5: NO | P5: USUARIO | Q5: LECTOR DE TARJETAS | R5: OBSTRUCCION DEL LECTOR | S5: CB UNO A UNO | U5: CERRADO | V5: 26-06 SE INTENTA COMUNICACION CON CB AL NUMERO 3106382156 SIN RESPUESTA, FAVOR LLAMAR A CLIENTE ANTES DE DESPLAZARSE PARA VALIDAR SOLICITUD Y DATOS 28/06/2025 SE REQUIERE CAMBIO DE EQUIPO Y POR LA HORA NO SE PODRIA REALIZAR DEBIDO A QUE SOPORTEDE REDEBAN NO LABORA DESPUES DE 1 PM 01-07 SE LLAMA A LA USUARIA LISETH RIVERA, LA CUAL INDICA QUE DURANTE TRES DIAS PRESENTABA FALLAS CON EL LECTOR DE TARJETA, YA QUE NO LEIA NINGUNA, PERO QUE DESPUES SE ARREGLO EL SERVICIO Y HASTA EL MOMENTO ESTA FUNCIONANDO CORRECTAMENTE SIN NINGUNA NOVEDAD, POR ENDE INDICA QUE NO REQUIERE VISITA TÉCNICA | W5: SOPORTE_TELEFÓNICO | X5: 0 | Y5: TIPO III | Z5: TERRESTRE | AA5: MONTES DIAZ JOHN FRED | AB5: 0 | AC5: 0 | AD5: 0 | AE5: 0 | AF5: =IF(W5="SOPORTE_TELEFÓNICO",'BASE LIQUIDACION'!$B$10,IF(Y5="TIPO I",'BASE LIQUIDACION'!$C$3,IF(Y5="TIPO II",'BASE LIQUIDACION'!$C$4,IF(Y5="TIPO III",'BASE LIQUIDACION'!$C$5,'BASE LIQUIDACION'!$C$7)))) -> 37904.654 | AG5: =IF(W5="SOPORTE_TELEFÓNICO",'BASE LIQUIDACION'!$B$10,(AB5*AF5+AC5*'BASE LIQUIDACION'!$B$12+AD5*'BASE LIQUIDACION'!$B$11+INCIDENTES!AE5*'BASE LIQUIDACION'!$B$13)) -> 37904.654
A6: CALI | B6: =VLOOKUP(A6,'CENTRO DE COSTOS'!A:D,4,FALSE) -> DIEGO FERNANDO HENAO CARDONA | C6: =VLOOKUP(A6,'CENTRO DE COSTOS'!A:D,2,FALSE) -> 0004-0003 | D6: 76111 | E6: 2379555 | F6: 15527 | G6: INCIDENTE | H6: VALLE DEL CAUCA | I6: GUADALAJARA DE BUGA | J6: MULTIPAGAS BUGA | K6: REDEBAN | L6: FO-25-1169391 | M6: 45840.333 | N6: 45840.426 | O6: NO | P6: USUARIO | Q6: USUARIOS | R6: USUARIOS BLOQUEADOS | S6: ROBUSTO | U6: CERRADO | V6: 02-07 SE ESCALA PARA VISITA. LLAMAR ANTES DE VISITAR, CONFIRMAR FALLA Y DATOS 0 02-07 SE LLAMA A LA SEÑORA KELLY PARA VALIDAR INCIDENTE, PERO INDICA QUE ESTA MAÑANA AL LLEGAR Y REALIZAR EL CIERRE YA LES FUNCIONO NORMAL, AL PARECER EL USUARIO ESTABA COMO BLOQUEADO, EL DATAFONO YA ESTA OPERANDO NORMALMENTE. | W6: SOPORTE_TELEFÓNICO | X6: 0 | Y6: TIPO II | Z6: TERRESTRE | AA6: HENAO CARDONA DIEGO FERNANDO | AB6: 0 | AC6: 0 | AD6: 0 | AE6: 0 | AF6: =IF(W6="SOPORTE_TELEFÓNICO",'BASE LIQUIDACION'!$B$10,IF(Y6="TIPO I",'BASE LIQUIDACION'!$C$3,IF(Y6="TIPO II",'BASE LIQUIDACION'!$C$4,IF(Y6="TIPO III",'BASE LIQUIDACION'!$C$5,'BASE LIQUIDACION'!$C$7)))) -> 37904.654 | AG6: =IF(W6="SOPORTE_TELEFÓNICO",'BASE LIQUIDACION'!$B$10,(AB6*AF6+AC6*'BASE LIQUIDACION'!$B$12+AD6*'BASE LIQUIDACION'!$B$11+INCIDENTES!AE6*'BASE LIQUIDACION'!$B$13)) -> 37904.654
A7: MEDELLIN | B7: =VLOOKUP(A7,'CENTRO DE COSTOS'!A:D,4,FALSE) -> JUAN SEBASTIÁN RÍOS CASTRILLÓN | C7: =VLOOKUP(A7,'CENTRO DE COSTOS'!A:D,2,FALSE) -> 0004-0005 | D7: 5088 | E7: 2377476 | F7: 74249 | G7: INCIDENTE | H7: ANTIOQUIA | I7: BELLO | J7: DISTRICOL FERRO DEPÓSITO JUAN | K7: REDEBAN | L7: FO-25-1167175 | M7: 45839.618 | N7: 45840.458 | O7: NO | P7: USUARIO | Q7: MANTENIMIENTO | R7: MANTENIMIENTO GENERAL | S7: AGREGADOR | U7: CERRADO | V7: 01-07 SE ESCALA PARA VISITA. LLAMAR ANTES DE VISITAR, CONFIRMAR FALLA Y DATOS 0 02-07 SE REALIZA MANTENIMIENTO AL EQUIPO | W7: VISITA_TÉCNICA | X7: MN3ZZ451 | Y7: TIPO I | Z7: TERRESTRE | AA7: CERPA SUAREZ DUVAN CAMILO | AB7: 1 | AC7: 0 | AD7: 0 | AE7: 0 | AF7: =IF(W7="SOPORTE_TELEFÓNICO",'BASE LIQUIDACION'!$B$10,IF(Y7="TIPO I",'BASE LIQUIDACION'!$C$3,IF(Y7="TIPO II",'BASE LIQUIDACION'!$C$4,IF(Y7="TIPO III",'BASE LIQUIDACION'!$C$5,'BASE LIQUIDACION'!$C$7)))) -> 65960.474 | AG7: =IF(W7="SOPORTE_TELEFÓNICO",'BASE LIQUIDACION'!$B$10,(AB7*AF7+AC7*'BASE LIQUIDACION'!$B$12+AD7*'BASE LIQUIDACION'!$B$11+INCIDENTES!AE7*'BASE LIQUIDACION'!$B$13)) -> 65960.474
A8: MEDELLIN | B8: =VLOOKUP(A8,'CENTRO DE COSTOS'!A:D,4,FALSE) -> JUAN SEBASTIÁN RÍOS CASTRILLÓN | C8: =VLOOKUP(A8,'CENTRO DE COSTOS'!A:D,2,FALSE) -> 0004-0005 | D8: 5001 | E8: 2378083 | F8: 10228 | G8: INCIDENTE | H8: ANTIOQUIA | I8: MEDELLIN | J8: BARRIO MANRIQUE ORIENTAL | K8: REDEBAN | L8: FO-25-1167420 | M8: 45839.654 | N8: 45840.466 | O8: NO | P8: USUARIO | Q8: MANTENIMIENTO | R8: MANTENIMIENTO GENERAL | S8: CB UNO A UNO | U8: CERRADO | V8: 01-07 SE ESCALA PARA VISITA. LLAMAR ANTES DE VISITAR, CONFIRMAR FALLA Y DATOS 0 02-07 SE LLEGÓ A SITIO CORRESPONSAL INFORMA QUE EL EQUIPO SE ENCUENTRA FUNCIONANDO NORMALMENTE | W8: VISITA_TÉCNICA | X8: JRZZZ707 | Y8: TIPO I | Z8: TERRESTRE | AA8: CASTAÑEDA PALACIO CARLOS FELIPE | AB8: 1 | AC8: 0 | AD8: 0 | AE8: 0 | AF8: =IF(W8="SOPORTE_TELEFÓNICO",'BASE LIQUIDACION'!$B$10,IF(Y8="TIPO I",'BASE LIQUIDACION'!$C$3,IF(Y8="TIPO II",'BASE LIQUIDACION'!$C$4,IF(Y8="TIPO III",'BASE LIQUIDACION'!$C$5,'BASE LIQUIDACION'!$C$7)))) -> 65960.474 | AG8: =IF(W8="SOPORTE_TELEFÓNICO",'BASE LIQUIDACION'!$B$10,(AB8*AF8+AC8*'BASE LIQUIDACION'!$B$12+AD8*'BASE LIQUIDACION'!$B$11+INCIDENTES!AE8*'BASE LIQUIDACION'!$B$13)) -> 65960.474
A9: PEREIRA | B9: =VLOOKUP(A9,'CENTRO DE COSTOS'!A:D,4,FALSE) -> DIEGO FERNANDO HENAO CARDONA | C9: =VLOOKUP(A9,'CENTRO DE COSTOS'!A:D,2,FALSE) -> 0004-0002 | D9: 76147 | E9: 2380625 | F9: 59182 | G9: INCIDENTE | H9: VALLE DEL CAUCA | I9: CARTAGO | J9: BARRIO GUAYACANES CARTAGO | K9: REDEBAN | L9: FO-25-1171516 | M9: 45840.347 | N9: 45840.472 | O9: NO | P9: USUARIO | Q9: NO ENCIENDE | R9: CONEXIONES DE COMERCIO | S9: CB UNO A UNO | U9: CERRADO | V9: 02-07 SE ESCALA PARA VISITA. LLAMAR ANTES DE VISITAR, CONFIRMAR FALLA Y DATOS 0 02-07 SE REALIZA VALIDACION CON EL SEÑOR ALEJANDRO QUIEN REPORTA PROBLEMAS CON EL PIN PAD, SE REVISA CONEXIONES Y SE ENCUENTRA QUE EL PIN PAD NO ESTA BIEN CONECTADO, SE PROCCEDE A REALIZAR CONEXION CORRECTA Y EL SERVICIO EMPIEZA A OPERAR SIN PROBLEMAS. | W9: SOPORTE_TELEFÓNICO | X9: 0 | Y9: TIPO I | Z9: TERRESTRE | AA9: HENAO CARDONA DIEGO FERNANDO | AB9: 0 | AC9: 0 | AD9: 0 | AE9: 0 | AF9: =IF(W9="SOPORTE_TELEFÓNICO",'BASE LIQUIDACION'!$B$10,IF(Y9="TIPO I",'BASE LIQUIDACION'!$C$3,IF(Y9="TIPO II",'BASE LIQUIDACION'!$C$4,IF(Y9="TIPO III",'BASE LIQUIDACION'!$C$5,'BASE LIQUIDACION'!$C$7)))) -> 37904.654 | AG9: =IF(W9="SOPORTE_TELEFÓNICO",'BASE LIQUIDACION'!$B$10,(AB9*AF9+AC9*'BASE LIQUIDACION'!$B$12+AD9*'BASE LIQUIDACION'!$B$11+INCIDENTES!AE9*'BASE LIQUIDACION'!$B$13)) -> 37904.654
A10: MEDELLIN | B10: =VLOOKUP(A10,'CENTRO DE COSTOS'!A:D,4,FALSE) -> JUAN SEBASTIÁN RÍOS CASTRILLÓN | C10: =VLOOKUP(A10,'CENTRO DE COSTOS'!A:D,2,FALSE) -> 0004-0005 | D10: 5308 | E10: 2378675 | F10: 41627 | G10: INCIDENTE | H10: ANTIOQUIA | I10: GIRARDOTA | J10: BARRIO GIRARDOTA GIRARDOTA | K10: REDEBAN | L10: FO-25-1168257 | M10: 45839.685 | N10: 45840.491 | O10: NO | P10: USUARIO | Q10: MANTENIMIENTO | R10: MANTENIMIENTO GENERAL | S10: CB UNO A UNO | U10: CERRADO | V10: 01-07 SE ESCALA PARA VISITA. LLAMAR ANTES DE VISITAR, CONFIRMAR FALLA Y DATOS 0 02-07 SE REALIZA MANTENIMIENTO Y SE CONECTA CABLE DE PODER BIEN | W10: VISITA_TÉCNICA | X10: EF01Z882 | Y10: TIPO I | Z10: TERRESTRE | AA10: CERPA SUAREZ DUVAN CAMILO | AB10: 1 | AC10: 0 | AD10: 0 | AE10: 0 | AF10: =IF(W10="SOPORTE_TELEFÓNICO",'BASE LIQUIDACION'!$B$10,IF(Y10="TIPO I",'BASE LIQUIDACION'!$C$3,IF(Y10="TIPO II",'BASE LIQUIDACION'!$C$4,IF(Y10="TIPO III",'BASE LIQUIDACION'!$C$5,'BASE LIQUIDACION'!$C$7)))) -> 65960.474 | AG10: =IF(W10="SOPORTE_TELEFÓNICO",'BASE LIQUIDACION'!$B$10,(AB10*AF10+AC10*'BASE LIQUIDACION'!$B$12+AD10*'BASE LIQUIDACION'!$B$11+INCIDENTES!AE10*'BASE LIQUIDACION'!$B$13)) -> 65960.474
A11: BOGOTA | B11: =VLOOKUP(A11,'CENTRO DE COSTOS'!A:D,4,FALSE) -> WILLIAM ASDRUBAL ROZO ROZO | C11: =VLOOKUP(A11,'CENTRO DE COSTOS'!A:D,2,FALSE) -> 0004-0004 | D11: 11001 | E11: 2379253 | F11: 60017 | G11: INCIDENTE | H11: CUNDINAMARCA | I11: BOGOTA | J11: PTM BOGOTA PUNTOSERVICE BOGOT | K11: REDEBAN | L11: FO-25-1169432 | M11: 45839.719 | N11: 45840.494 | O11: NO | P11: USUARIO | Q11: COMUNICACION | R11: CANAL DEL COMERCIO | S11: AGREGADOR | U11: CERRADO | V11: 01-07 SE ESCALA PARA VISITA. LLAMAR ANTES DE VISITAR, CONFIRMAR FALLA Y DATOS 0 02-07 SE REALIZA DESPLAZAMIENTO A DIRECCIÓN DE COMERCIO, SE ENCUENTRA COMERCIO CERRADO, PERSONA QUE ATIENDE POR UNA VENTANA DEL 3 PISO DEL PREDIO SE COMUNICA CON LA SRA. CLAUDIA Y ELLA LE INDICA QUE LLAMO A CANCELAR LA VISITA POR QUÉ LA FALLA ES DEL SERVICIO DE INTERNET DEL PREDIO. | W11: VISITA_TÉCNICA | X11: MA00B423 | Y11: TIPO I | Z11: TERRESTRE | AA11: MURCIA HERNANDEZ HARVEY IGNACIO | AB11: 1 | AC11: 0 | AD11: 0 | AE11: 0 | AF11: =IF(W11="SOPORTE_TELEFÓNICO",'BASE LIQUIDACION'!$B$10,IF(Y11="TIPO I",'BASE LIQUIDACION'!$C$3,IF(Y11="TIPO II",'BASE LIQUIDACION'!$C$4,IF(Y11="TIPO III",'BASE LIQUIDACION'!$C$5,'BASE LIQUIDACION'!$C$7)))) -> 65960.474 | AG11: =IF(W11="SOPORTE_TELEFÓNICO",'BASE LIQUIDACION'!$B$10,(AB11*AF11+AC11*'BASE LIQUIDACION'!$B$12+AD11*'BASE LIQUIDACION'!$B$11+INCIDENTES!AE11*'BASE LIQUIDACION'!$B$13)) -> 65960.474
A12: MEDELLIN | B12: =VLOOKUP(A12,'CENTRO DE COSTOS'!A:D,4,FALSE) -> JUAN SEBASTIÁN RÍOS CASTRILLÓN | C12: =VLOOKUP(A12,'CENTRO DE COSTOS'!A:D,2,FALSE) -> 0004-0005 | D12: 5631 | E12: 2379765 | F12: 79007 | G12: INCIDENTE | H12: ANTIOQUIA | I12: SABANETA | J12: PTM SABANETA PAPELERIA Y RECAR | K12: REDEBAN | L12: FO-25-1171187 | M12: 45840.333 | N12: 45840.553 | O12: NO | P12: USUARIO | Q12: CIERRE | R12: COMERCIO NO REALIZA CIERRE | S12: AGREGADOR | U12: CERRADO | V12: 02-07 SE ESCALA PARA VISITA. LLAMAR ANTES DE VISITAR, CONFIRMAR FALLA Y DATOS 0 02-07 SE REALIZA AJUSTES SOBRE LOS CIERRES | W12: VISITA_TÉCNICA | X12: FATZZ894 | Y12: TIPO I | Z12: TERRESTRE | AA12: HERNANDEZ CHAVARRIA JUAN CAMILO | AB12: 1 | AC12: 0 | AD12: 0 | AE12: 0 | AF12: =IF(W12="SOPORTE_TELEFÓNICO",'BASE LIQUIDACION'!$B$10,IF(Y12="TIPO I",'BASE LIQUIDACION'!$C$3,IF(Y12="TIPO II",'BASE LIQUIDACION'!$C$4,IF(Y12="TIPO III",'BASE LIQUIDACION'!$C$5,'BASE LIQUIDACION'!$C$7)))) -> 65960.474 | AG12: =IF(W12="SOPORTE_TELEFÓNICO",'BASE LIQUIDACION'!$B$10,(AB12*AF12+AC12*'BASE LIQUIDACION'!$B$12+AD12*'BASE LIQUIDACION'!$B$11+INCIDENTES!AE12*'BASE LIQUIDACION'!$B$13)) -> 65960.474
A13: MEDELLIN | B13: =VLOOKUP(A13,'CENTRO DE COSTOS'!A:D,4,FALSE) -> JUAN SEBASTIÁN RÍOS CASTRILLÓN | C13: =VLOOKUP(A13,'CENTRO DE COSTOS'!A:D,2,FALSE) -> 0004-0005 | D13: 5088 | E13: 2381539 | F13: 80073 | G13: INCIDENTE | H13: ANTIOQUIA | I13: BELLO | J13: BARRIO LA GABRIELA CALLE VIEJA BELLO 4 | K13: REDEBAN | L13: FO-25-1172101 | M13: 45840.39 | N13: 45840.554 | O13: NO | P13: USUARIO | Q13: MANTENIMIENTO | R13: MANTENIMIENTO GENERAL | S13: CB UNO A UNO | U13: CERRADO | V13: 02-07 SE ESCALA PARA VISITA. LLAMAR ANTES DE VISITAR, CONFIRMAR FALLA Y DATOS 0 02-07 SE REALIZÓ LIMPIEZA DE IMPRESORA POS OK | W13: VISITA_TÉCNICA | X13: SAXZZ552 | Y13: TIPO I | Z13: TERRESTRE | AA13: CASTAÑEDA PALACIO CARLOS FELIPE | AB13: 1 | AC13: 0 | AD13: 0 | AE13: 0 | AF13: =IF(W13="SOPORTE_TELEFÓNICO",'BASE LIQUIDACION'!$B$10,IF(Y13="TIPO I",'BASE LIQUIDACION'!$C$3,IF(Y13="TIPO II",'BASE LIQUIDACION'!$C$4,IF(Y13="TIPO III",'BASE LIQUIDACION'!$C$5,'BASE LIQUIDACION'!$C$7)))) -> 65960.474 | AG13: =IF(W13="SOPORTE_TELEFÓNICO",'BASE LIQUIDACION'!$B$10,(AB13*AF13+AC13*'BASE LIQUIDACION'!$B$12+AD13*'BASE LIQUIDACION'!$B$11+INCIDENTES!AE13*'BASE LIQUIDACION'!$B$13)) -> 65960.474
A14: MEDELLIN | B14: =VLOOKUP(A14,'CENTRO DE COSTOS'!A:D,4,FALSE) -> JUAN SEBASTIÁN RÍOS CASTRILLÓN | C14: =VLOOKUP(A14,'CENTRO DE COSTOS'!A:D,2,FALSE) -> 0004-0005 | D14: 5088 | E14: 2383581 | F14: 66013 | G14: INCIDENTE | H14: ANTIOQUIA | I14: BELLO | J14: BARRIO NIQUIA BELLO 16 | K14: REDEBAN | L14: FO-25-1173213 | M14: 45840.481 | N14: 45840.558 | O14: NO | P14: USUARIO | Q14: MANTENIMIENTO | R14: MANTENIMIENTO GENERAL | S14: CB UNO A UNO | U14: CERRADO | V14: 02-07 SE ESCALA PARA VISITA. LLAMAR ANTES DE VISITAR, CONFIRMAR FALLA Y DATOS 0 02-07 SE REALIZA MANTENIMIENTO AL EQUIPO Y SE CONECTA FUENTE DE PODER | W14: VISITA_TÉCNICA | X14: 9A00N419 | Y14: TIPO I | Z14: TERRESTRE | AA14: CERPA SUAREZ DUVAN CAMILO | AB14: 1 | AC14: 0 | AD14: 0 | AE14: 0 | AF14: =IF(W14="SOPORTE_TELEFÓNICO",'BASE LIQUIDACION'!$B$10,IF(Y14="TIPO I",'BASE LIQUIDACION'!$C$3,IF(Y14="TIPO II",'BASE LIQUIDACION'!$C$4,IF(Y14="TIPO III",'BASE LIQUIDACION'!$C$5,'BASE LIQUIDACION'!$C$7)))) -> 65960.474 | AG14: =IF(W14="SOPORTE_TELEFÓNICO",'BASE LIQUIDACION'!$B$10,(AB14*AF14+AC14*'BASE LIQUIDACION'!$B$12+AD14*'BASE LIQUIDACION'!$B$11+INCIDENTES!AE14*'BASE LIQUIDACION'!$B$13)) -> 65960.474
A15: IBAGUE | B15: =VLOOKUP(A15,'CENTRO DE COSTOS'!A:D,4,FALSE) -> KEVIN ALEXIS CORZO BUSTOS | C15: =VLOOKUP(A15,'CENTRO DE COSTOS'!A:D,2,FALSE) -> 0004-0007 | D15: 73585 | E15: 2384587 | F15: 28326 | G15: INCIDENTE | H15: TOLIMA | I15: PURIFICACION | J15: ARA0354 PURIFICACION ZONA SU | K15: REDEBAN | L15: FO-25-1175014 | M15: 45840.582 | N15: 45840.628 | O15: NO | P15: USUARIO | Q15: MANTENIMIENTO | R15: MANTENIMIENTO GENERAL | S15: RETAIL | U15: CERRADO | V15: 02-07 SE ESCALA A LA RED - SE PROCEDE A CERRAR YA QUE NO ATENDEMOS CADENA ARA ..02-07 RESPUESTA DE LA RED: TU SOLICITUD REFERENTE A GENERACIÓN DE CASOS CB ARA BANCOLOMBIA QUEDÓ RADICADA BAJO EL TICKET NÚMERO 5697837 AL ÁREA ENCARGADA. 0 | W15: SOPORTE_TELEFÓNICO | X15: 0 | Y15: TIPO II | Z15: TERRESTRE | AA15: 0 | AB15: 0 | AC15: 0 | AD15: 0 | AE15: 0 | AF15: =IF(W15="SOPORTE_TELEFÓNICO",'BASE LIQUIDACION'!$B$10,IF(Y15="TIPO I",'BASE LIQUIDACION'!$C$3,IF(Y15="TIPO II",'BASE LIQUIDACION'!$C$4,IF(Y15="TIPO III",'BASE LIQUIDACION'!$C$5,'BASE LIQUIDACION'!$C$7)))) -> 37904.654 | AG15: =IF(W15="SOPORTE_TELEFÓNICO",'BASE LIQUIDACION'!$B$10,(AB15*AF15+AC15*'BASE LIQUIDACION'!$B$12+AD15*'BASE LIQUIDACION'!$B$11+INCIDENTES!AE15*'BASE LIQUIDACION'!$B$13)) -> 37904.654
A16: CALI | B16: =VLOOKUP(A16,'CENTRO DE COSTOS'!A:D,4,FALSE) -> DIEGO FERNANDO HENAO CARDONA | C16: =VLOOKUP(A16,'CENTRO DE COSTOS'!A:D,2,FALSE) -> 0004-0003 | D16: 19001 | E16: 2379720 | F16: 69029 | G16: INCIDENTE | H16: CAUCA | I16: POPAYAN | J16: BARRIO BELMONTE POPAYAN | K16: REDEBAN | L16: FO-25-1171196 | M16: 45840.333 | N16: 45840.683 | O16: NO | P16: ENTIDAD | Q16: ERROR DE TRANSACCIONES | R16: TIPO DE TARJETA INVALIDA | S16: CB UNO A UNO | U16: CERRADO | V16: 02-07 SE ESCALA PARA VISITA. LLAMAR ANTES DE VISITAR, CONFIRMAR FALLA Y DATOS 0 02-07 SE LLEGA AL SITIO SE ENCUENTRA EQUIPO OK SE LLAMA ALA LÍNEA CORRESPONSALES INFORMAN PRESENTA BLOQUEO POR LA ENTIDAD POR TEMA COMPENSACION | W16: VISITA_TÉCNICA | X16: 9T1ZZ294 | Y16: TIPO III | Z16: TERRESTRE | AA16: GIMBUEL LASSO LUIS GERMAN | AB16: 1 | AC16: 0 | AD16: 0 | AE16: 0 | AF16: =IF(W16="SOPORTE_TELEFÓNICO",'BASE LIQUIDACION'!$B$10,IF(Y16="TIPO I",'BASE LIQUIDACION'!$C$3,IF(Y16="TIPO II",'BASE LIQUIDACION'!$C$4,IF(Y16="TIPO III",'BASE LIQUIDACION'!$C$5,'BASE LIQUIDACION'!$C$7)))) -> 275728.38 | AG16: =IF(W16="SOPORTE_TELEFÓNICO",'BASE LIQUIDACION'!$B$10,(AB16*AF16+AC16*'BASE LIQUIDACION'!$B$12+AD16*'BASE LIQUIDACION'!$B$11+INCIDENTES!AE16*'BASE LIQUIDACION'!$B$13)) -> 275728.38
A17: BOGOTA | B17: =VLOOKUP(A17,'CENTRO DE COSTOS'!A:D,4,FALSE) -> WILLIAM ASDRUBAL ROZO ROZO | C17: =VLOOKUP(A17,'CENTRO DE COSTOS'!A:D,2,FALSE) -> 0004-0004 | D17: 11001 | E17: 2384573 | F17: 18902 | G17: INCIDENTE | H17: CUNDINAMARCA | I17: BOGOTA | J17: PAGAFACIL CENTRO DE PAGOS LA 9 | K17: REDEBAN | L17: FO-25-1174015 | M17: 45840.58 | N17: 45841.476 | O17: NO | P17: USUARIO | Q17: USUARIOS | R17: USUARIOS BLOQUEADOS | S17: ROBUSTO | U17: CERRADO | V17: 02-07 SE ESCALA PARA VISITA. LLAMAR ANTES DE VISITAR, CONFIRMAR FALLA Y DATOS 0 03-07 SE RESTABLECEN CLAVES COMERCIO REALIZA PRUEBAS REALIZANDO EL CIERRE NO SE REALIZA PRUEBAS DE TRANSACCIÓNES DEBIDO A QUE LA CAJA NO LA ESTÁN USANDO Y NO LA PUEDEB ABRIR HASTA MAÑANA | W17: VISITA_TÉCNICA | X17: XRZZZ663 | Y17: TIPO I | Z17: TERRESTRE | AA17: MICHELI LOPEZ MIGUEL ANGEL | AB17: 1 | AC17: 0 | AD17: 0 | AE17: 0 | AF17: =IF(W17="SOPORTE_TELEFÓNICO",'BASE LIQUIDACION'!$B$10,IF(Y17="TIPO I",'BASE LIQUIDACION'!$C$3,IF(Y17="TIPO II",'BASE LIQUIDACION'!$C$4,IF(Y17="TIPO III",'BASE LIQUIDACION'!$C$5,'BASE LIQUIDACION'!$C$7)))) -> 65960.474 | AG17: =IF(W17="SOPORTE_TELEFÓNICO",'BASE LIQUIDACION'!$B$10,(AB17*AF17+AC17*'BASE LIQUIDACION'!$B$12+AD17*'BASE LIQUIDACION'!$B$11+INCIDENTES!AE17*'BASE LIQUIDACION'!$B$13)) -> 65960.474
A18: CALI | B18: =VLOOKUP(A18,'CENTRO DE COSTOS'!A:D,4,FALSE) -> DIEGO FERNANDO HENAO CARDONA | C18: =VLOOKUP(A18,'CENTRO DE COSTOS'!A:D,2,FALSE) -> 0004-0003 | D18: 76001 | E18: 2388444 | F18: 53834 | G18: INCIDENTE | H18: VALLE DEL CAUCA | I18: CALI | J18: BARRIO FLORESTA CALI 2 | K18: REDEBAN | L18: FO-25-1176899 | M18: 45841.356 | N18: 45841.494 | O18: NO | P18: USUARIO | Q18: CIERRE | R18: COMERCIO NO REALIZA CIERRE | S18: CB UNO A UNO | U18: CERRADO | V18: 03-07 SE ESCALA PARA VISITA. LLAMAR ANTES DE VISITAR, CONFIRMAR FALLA Y DATOS 0 03-07 SE REALIZA LLAMADA AL CLIENTE , SE VALIDA INCONVENIENTE, EL CLIENTE ESTABA DIGITANDO UNA CLAVE PARA CIERRES ERRADA, SE LE INDICA QUE LA CLAVE ESTANDAR ES 1526, EL CLIENTE PROCEDE A REALIZAR PRUEBAS Y INGRESA AL CIERRE CORRECTAMENTE. | W18: SOPORTE_TELEFÓNICO | X18: 0 | Y18: TIPO I | Z18: TERRESTRE | AA18: HENAO CARDONA DIEGO FERNANDO | AB18: 0 | AC18: 0 | AD18: 0 | AE18: 0 | AF18: =IF(W18="SOPORTE_TELEFÓNICO",'BASE LIQUIDACION'!$B$10,IF(Y18="TIPO I",'BASE LIQUIDACION'!$C$3,IF(Y18="TIPO II",'BASE LIQUIDACION'!$C$4,IF(Y18="TIPO III",'BASE LIQUIDACION'!$C$5,'BASE LIQUIDACION'!$C$7)))) -> 37904.654 | AG18: =IF(W18="SOPORTE_TELEFÓNICO",'BASE LIQUIDACION'!$B$10,(AB18*AF18+AC18*'BASE LIQUIDACION'!$B$12+AD18*'BASE LIQUIDACION'!$B$11+INCIDENTES!AE18*'BASE LIQUIDACION'!$B$13)) -> 37904.654
A19: MEDELLIN | B19: =VLOOKUP(A19,'CENTRO DE COSTOS'!A:D,4,FALSE) -> JUAN SEBASTIÁN RÍOS CASTRILLÓN | C19: =VLOOKUP(A19,'CENTRO DE COSTOS'!A:D,2,FALSE) -> 0004-0005 | D19: 5001 | E19: 2389782 | F19: 79923 | G19: INCIDENTE | H19: ANTIOQUIA | I19: MEDELLIN | J19: DISTRICOL EL MERCADO J&S PARQU | K19: REDEBAN | L19: FO-25-1177953 | M19: 45841.432 | N19: 45841.635 | O19: NO | P19: USUARIO | Q19: MANTENIMIENTO | R19: MANTENIMIENTO GENERAL | S19: AGREGADOR | U19: CERRADO | V19: 03-07 SE ESCALA PARA VISITA. LLAMAR ANTES DE VISITAR, CONFIRMAR FALLA Y DATOS 0 03-07 SE REALIZA MANTENIMIENTO AL EQUIPO TODO ESTÁ EN BUEN FUNCIONAMIENTO | W19: VISITA_TÉCNICA | X19: SAUZZ938 | Y19: TIPO I | Z19: TERRESTRE | AA19: CERPA SUAREZ DUVAN CAMILO | AB19: 1 | AC19: 0 | AD19: 0 | AE19: 0 | AF19: =IF(W19="SOPORTE_TELEFÓNICO",'BASE LIQUIDACION'!$B$10,IF(Y19="TIPO I",'BASE LIQUIDACION'!$C$3,IF(Y19="TIPO II",'BASE LIQUIDACION'!$C$4,IF(Y19="TIPO III",'BASE LIQUIDACION'!$C$5,'BASE LIQUIDACION'!$C$7)))) -> 65960.474 | AG19: =IF(W19="SOPORTE_TELEFÓNICO",'BASE LIQUIDACION'!$B$10,(AB19*AF19+AC19*'BASE LIQUIDACION'!$B$12+AD19*'BASE LIQUIDACION'!$B$11+INCIDENTES!AE19*'BASE LIQUIDACION'!$B$13)) -> 65960.474
A20: PASTO | B20: =VLOOKUP(A20,'CENTRO DE COSTOS'!A:D,4,FALSE) -> DIEGO FERNANDO HENAO CARDONA | C20: =VLOOKUP(A20,'CENTRO DE COSTOS'!A:D,2,FALSE) -> 0004-0003 | D20: 52356 | E20: 2386804 | F20: 44682 | G20: INCIDENTE | H20: NARIÑO | I20: IPIALES | J20: PTM IPIALES MISCELANEA Y PAPEL | K20: REDEBAN | L20: FO-25-1175433 | M20: 45840.691 | N20: 45841.644 | O20: NO | P20: USUARIO | Q20: MANTENIMIENTO | R20: MANTENIMIENTO GENERAL | S20: AGREGADOR | U20: CERRADO | V20: 02-07 SE ESCALA PARA VISITA. LLAMAR ANTES DE VISITAR, CONFIRMAR FALLA Y DATOS 0 03-07 SE VISITÓ EL CB PARA REVISAR INCONVENIENTE CON DATÁFONO, CLIENTE MANIFIESTA QUE SE REINICIABA, SE REALIZA MANTENIMIENTO, BORRADO DE SISTEMA OPERATIVO Y VERSIÓN, SE REINSTALA Y SE INICIALIZA, PRUEBAS OK, CB FUNCIONA CON NORMALIDAD | W20: VISITA_TÉCNICA | X20: AB1EZ108, MA00E720 | Y20: TIPO II | Z20: TERRESTRE | AA20: GUERRERO RAMIREZ OSCAR DARIO | AB20: 1 | AC20: 0 | AD20: 0 | AE20: 0 | AF20: =IF(W20="SOPORTE_TELEFÓNICO",'BASE LIQUIDACION'!$B$10,IF(Y20="TIPO I",'BASE LIQUIDACION'!$C$3,IF(Y20="TIPO II",'BASE LIQUIDACION'!$C$4,IF(Y20="TIPO III",'BASE LIQUIDACION'!$C$5,'BASE LIQUIDACION'!$C$7)))) -> 163813.56 | AG20: =IF(W20="SOPORTE_TELEFÓNICO",'BASE LIQUIDACION'!$B$10,(AB20*AF20+AC20*'BASE LIQUIDACION'!$B$12+AD20*'BASE LIQUIDACION'!$B$11+INCIDENTES!AE20*'BASE LIQUIDACION'!$B$13)) -> 163813.56
A21: MEDELLIN | B21: =VLOOKUP(A21,'CENTRO DE COSTOS'!A:D,4,FALSE) -> JUAN SEBASTIÁN RÍOS CASTRILLÓN | C21: =VLOOKUP(A21,'CENTRO DE COSTOS'!A:D,2,FALSE) -> 0004-0005 | D21: 5425 | E21: 2375218 | F21: 79106 | G21: INCIDENTE | H21: ANTIOQUIA | I21: MACEO | J21: BARRIO CALLE BOLIVAR MACEO | K21: REDEBAN | L21: FO-25-1163418 | M21: 45839.473 | N21: 45842.377 | O21: NO | P21: USUARIO | Q21: COMUNICACION | R21: CANAL DEL COMERCIO | S21: CB UNO A UNO | U21: CERRADO | V21: 01-07 SE REALIZA CONTACTO CON LUZ MARY CELIS AL NUMERO 3206745652 CONFIRMA FALLA, DATOS CORRECTOS. SE ESCALA PARA VISITA 0 03-07 SE VERIFICAN CONEXIÓNES Y SE IDENTIFICA CAÍDA DEL CANAL DEL USUARIO, SE ENSAYA EL SERVICIO CON EL CANAL DE UN VECINO Y EL SERVICIO FUNCIONA CORRECTAMENTE. | W21: VISITA_TÉCNICA | X21: SASZZ681 | Y21: TIPO III | Z21: TERRESTRE | AA21: BARRIENTOS HERNANDEZ CRISTIAN HORACIO | AB21: 1 | AC21: 0 | AD21: 0 | AE21: 0 | AF21: =IF(W21="SOPORTE_TELEFÓNICO",'BASE LIQUIDACION'!$B$10,IF(Y21="TIPO I",'BASE LIQUIDACION'!$C$3,IF(Y21="TIPO II",'BASE LIQUIDACION'!$C$4,IF(Y21="TIPO III",'BASE LIQUIDACION'!$C$5,'BASE LIQUIDACION'!$C$7)))) -> 275728.38 | AG21: =IF(W21="SOPORTE_TELEFÓNICO",'BASE LIQUIDACION'!$B$10,(AB21*AF21+AC21*'BASE LIQUIDACION'!$B$12+AD21*'BASE LIQUIDACION'!$B$11+INCIDENTES!AE21*'BASE LIQUIDACION'!$B$13)) -> 275728.38
