Workbook
Name ACTIVIDAD: [1]Hoja2!$P$2:$P$30
Name Clientes: [2]Clientes!$A$2:$A$100
Name COORDINADOR: [1]Hoja2!$D$2:$D$30
Name Coordinadores: [3]Coordinadores!$A$2:$A$1000
Name DOCUMENTADOR: [1]Hoja2!$A$2:$A$30
Name ES: [1]Hoja2!$K$2:$K$30
Name ESS: [1]Hoja2!$K$2:$K$30
Name Estado: [2]Formulas!$K$2:$K$5000
Name ESTADOACTIVIDAD: [1]Hoja2!$M$2:$M$30
Name ESTADOSCIERRES: '[4]lista desplegable'!$CX$1:$DA$1
Name Facturacion: '[5]Listas desplegables'!$AO$1:$AR$1
Name solicitudes: '[5]Listas desplegables'!$U$1:$AF$1
Name Tecnicos: [2]Tecnicos!$A$2:$A$1000

Sheet RESUMEN
A1: LÍNEA COMUNICACIONES S.A.S | F1: FACTURACIÓN CORRESPONSALES BANCARIOS TIQUIETES AÉREOS
A2: FACTURACIÓN VISITAS FALLIDAS CORRESPONSALES BANCARIOS | F2: =A3 -> JULIO 2025
A3: JULIO 2025
F4: CONCEPTOS | G4: TRAYECTOS | H4: TOTAL | I4: % ADMINISTRACIÓN | J4: TOTAL
A5: CONCEPTOS | B5: CANT | D5: TOTAL | F5: ORDEN DE CAMBIO CB 72634 | G5: SINCELEJO-MAJAGUAL-SINCELEJO | H5: 300000 | I5: =H5*0.12 -> 36000 | J5: =H5+I5 -> 336000
A6: =CONCATENATE("CIERRES NO EXITOSOS ",A3) -> CIERRES NO EXITOSOS JULIO 2025 | B6: =COUNTA(CIERRES!A:A)-1 -> 162 | D6: =CIERRES!AD164 -> 16375995 | I6: =H6*0.12 -> 0 | J6: =H6+I6 -> 0
A7: TIQUETES | B7: 0 | D7: =J10 -> 336000 | I7: =H7*0.12 -> 0 | J7: =H7+I7 -> 0
A8: SUBTOTAL | D8: =SUM(D6:D7) -> 16711995
A9: IVA | D9: =D8*0.19 -> 3175279
A10: TOTAL | D10: =SUM(D8:D9) -> 19887274 | F10: TOTAL | H10: =SUM(H5:H7) -> 300000 | I10: =SUM(I5:I7) -> 36000 | J10: =SUM(J5:J7) -> 336000

Sheet BASE DE LIQUIDACION 2025
A1: CIERRE CB - VISITAS FALLIDAS O CIERRES NO EXITOSOS TARIFAS 2024 | D1: Incremento 2025
A2: Tipificación | B2: Descripción | C2: Tarifa | D2: 0.052
A3: Tipo I | B3: Metropolitano | C3: =42357*(1+$D$2) -> 44559.564
A4: Tipo II | B4: Hasta 3 horas | C4: =127767*(1+$D$2) -> 134410.88
A5: Tipo III | B5: De 3 a 5 horas | C5: =211886*(1+$D$2) -> 222904.07
A6: Tipo IV | B6: Más de 5 horas | C6: =441834*(1+$D$2) -> 464809.37
A7: Trayecto Especial | B7: No incluye valor del Tiquete | C7: Valor de actividad Tipo IV + Valor tiquete aéreo (o fluvial) + 12% administración)
A9: Gestión telefonica | B9: =36031*(1+$D$2) -> 37904.612

Sheet Tabla Dinámica
A3: COORDINADOR | B3: CENTRO DE COSTOS LÍNEACOM | C3: % | D3: Suma de VALOR TOTAL2 | E3: NOMBRE CC
A4: DIEGO FERNANDO HENAO CARDONA | B4: 0004-0002 | C4: 0.020593793 | D4: 337243.85 | E4: =VLOOKUP(B4,'CENTRO DE COSTOS'!B:C,2,0) -> Redeban Eje Cafetero (Pereira)
B5: 0004-0003 | C5: 0.12905852 | D5: 2113461.7 | E5: =VLOOKUP(B5,'CENTRO DE COSTOS'!B:C,2,0) -> Redeban Suroccidente (Cali)
A6: JOSE MAURICIO HERNANDEZ ROJAS | B6: 0004-0001 | C6: 0.11050911 | D6: 1809696.7 | E6: =VLOOKUP(B6,'CENTRO DE COSTOS'!B:C,2,0) -> Redeban Costa (Barranqullla)
A7: JUAN SEBASTIÁN RÍOS CASTRILLÓN | B7: 0004-0005 | C7: 0.24273546 | D7: 3975034.6 | E7: =VLOOKUP(B7,'CENTRO DE COSTOS'!B:C,2,0) -> Redeban Noroccidente (Medellín)
A8: KEVIN ALEXIS CORZO BUSTOS | B8: 0004-0007 | C8: 0.22036304 | D8: 3608664 | E8: =VLOOKUP(B8,'CENTRO DE COSTOS'!B:C,2,0) -> Redeban Oriente (Otros)
A9: MIGUEL JULIÁN HERNÁNDEZ GUARÍN | B9: 0004-0008 | C9: 0.08513693 | D9: 1394201.9 | E9: =VLOOKUP(B9,'CENTRO DE COSTOS'!B:C,2,0) -> Redeban Santander
A10: WILLIAM ASDRUBAL ROZO ROZO | B10: 0004-0004 | C10: 0.19160314 | D10: 3137692 | E10: =VLOOKUP(B10,'CENTRO DE COSTOS'!B:C,2,0) -> Redeban Centro ( Bogotá)
A11: Total general | C11: 1 | D11: 16375995

Sheet CIERRES
A1: CIUDAD SEDE | B1: COORDINADOR | C1: CENTRO DE COSTOS LÍNEACOM | D1: CÓDIGO DANE | E1: TA/CODIGO ACTIVIDAD | F1: CODIGO CB | G1: ACTIVIDAD | H1: DEPARTAMENTO | I1: CIUDAD | J1: NOMBRE DEL CB | K1: RED | L1: FO | M1: FECHA ASIGNACION A LINEA COMUNICACIONES | N1: FECHA DEL CIERRE DEL TICKET (DD/MM/AAAA) | O1: ACOMETIDA | P1: SOLICITUD | Q1: DESCRIPCIÓN | R1: FORMATO | S1: CADENA | T1: ESTADO | U1: CAUSAL ESTADO | V1: OBSERVACION | W1: FORMA DE ATENCIÓN | X1: TERMINAL | Y1: TIPIFICACION | Z1: TIPO DE TRAYECTO | AA1: NOMBRE DEL TECNICO | AB1: DIAS DE VISITA | AC1: VALOR ACTIVIDAD | AD1: VALOR TOTAL
A2: BOGOTA | B2: =VLOOKUP(A2,'CENTRO DE COSTOS'!A:D,4,FALSE) -> WILLIAM ASDRUBAL ROZO ROZO | C2: =VLOOKUP(A2,'CENTRO DE COSTOS'!A:C,2,FALSE) -> 0004-0004 | D2: 25736 | E2: TA-25-809615 | F2: 68733 | G2: ORDEN DE CAMBIO | H2: CUNDINAMARCA | I2: SESQUILE | J2: BARRIO CENTRO SESQUILE SESQUIL | K2: REDEBAN | L2: FO-25-1148318 | M2: 45836.333 | N2: 45839.467 | P2: CIERRE | Q2: RECUPERACION DE EQUIPOS | R2: CB UNO A UNO | S2: CB UNO A UNO | T2: ILOCALIZADO | U2: CB CERRADO - DESOCUPADO | V2: 01-07-2025 SE REALIZA DESPLAZAMIENTO A DIRECCIÓN DE COMERCIO, SE ENCUENTRA COMERCIO CERRADO, NO SE TIENE RESPUESTA A NÚMERO DE CONTACTO, SE REALIZA VALIDACIÓN CON COMERCIO UBICADO EN EL MISMO INMUEBLE Y NO CONOCEN A LA CLIENTE. | W2: VISITA_TÉCNICA | X2: 0 | Y2: TIPO II | Z2: TERRESTRE | AA2: MURCIA HERNANDEZ HARVEY IGNACIO | AB2: 1 | AC2: =IF(AND(W2="SOPORTE_TELEFÓNICO",OR(U2="SIN CONTACTO CON EL CB",U2="NÚMEROS DE CONTACTO ERRADOS")),0,IF(W2="SOPORTE_TELEFÓNICO",'BASE DE LIQUIDACION 2025'!$B$9,IF(Y2="TIPO I",'BASE DE LIQUIDACION 2025'!$C$3,IF(Y2="TIPO II",'BASE DE LIQUIDACION 2025'!$C$4,IF(Y2="TIPO III",'BASE DE LIQUIDACION 2025'!$C$5,'BASE DE LIQUIDACION 2025'!$C$6))))) -> 134410.88 | AD2: =IF(W2="SOPORTE_TELEFÓNICO",AC2,CIERRES!AB2*CIERRES!AC2) -> 134410.88
A3: PASTO | B3: =VLOOKUP(A3,'CENTRO DE COSTOS'!A:D,4,FALSE) -> DIEGO FERNANDO HENAO CARDONA | C3: =VLOOKUP(A3,'CENTRO DE COSTOS'!A:C,2,FALSE) -> 0004-0003 | D3: 52001 | E3: TA-25-809579 | F3: 76203 | G3: ORDEN DE CAMBIO | H3: NARIÑO | I3: PASTO | J3: BARRIO CENTRO PASTO 36 | K3: REDEBAN | L3: FO-25-1148186 | M3: 45836.333 | N3: 45839.552 | P3: CIERRE | Q3: CIERRE | R3: CB UNO A UNO | S3: CB UNO A UNO | T3: ILOCALIZADO | U3: CB CERRADO - DESOCUPADO | V3: 01-07-2025 SE LLEGÓ AL COMERCIO PERO ESTÁ CERRADO EL LOCAL, SE INTENTÓ COMUNICACIÓN TELEFÓNICA, PERO EL TELÉFONO ESTÁ ERRADO, HAY OTRO NÚMERO DE CELULAR PERO ESTÁ FUERA DE SERVICIO. | W3: VISITA_TÉCNICA | X3: 0 | Y3: TIPO I | Z3: TERRESTRE | AA3: GUERRERO RAMIREZ OSCAR DARIO | AB3: 1 | AC3: =IF(AND(W3="SOPORTE_TELEFÓNICO",OR(U3="SIN CONTACTO CON EL CB",U3="NÚMEROS DE CONTACTO ERRADOS")),0,IF(W3="SOPORTE_TELEFÓNICO",'BASE DE LIQUIDACION 2025'!$B$9,IF(Y3="TIPO I",'BASE DE LIQUIDACION 2025'!$C$3,IF(Y3="TIPO II",'BASE DE LIQUIDACION 2025'!$C$4,IF(Y3="TIPO III",'BASE DE LIQUIDACION 2025'!$C$5,'BASE DE LIQUIDACION 2025'!$C$6))))) -> 44559.564 | AD3: =IF(W3="SOPORTE_TELEFÓNICO",AC3,CIERRES!AB3*CIERRES!AC3) -> 44559.564
A4: CALI | B4: =VLOOKUP(A4,'CENTRO DE COSTOS'!A:D,4,FALSE) -> DIEGO FERNANDO HENAO CARDONA | C4: =VLOOKUP(A4,'CENTRO DE COSTOS'!A:C,2,FALSE) -> 0004-0003 | D4: 19698 | E4: TA-25-809571 | F4: 61823 | G4: ORDEN DE CAMBIO | H4: CAUCA | I4: SANTANDER DE QUILICHAO | J4: BARRIO GENERAL SANTANDER SANTA | K4: REDEBAN | L4: FO-25-1148154 | M4: 45836.333 | N4: 45839.572 | P4: CIERRE | Q4: CIERRE | R4: CB UNO A UNO | S4: CB UNO A UNO | T4: ILOCALIZADO | U4: SIN CONTACTO CON EL CB | V4: 01-07-2025 SE LLEGO AL SITIO Y NO SE ENCONTRÓ EL CB, SE INDAGO EN EL SECTOR E IMFORMARON QUE LA CLIENTE SE FUE PARA ESPAÑA Y QUE ENTREGARON EL LOCAL, EL NÚMERO DE CONTACTO SE VA A BUZON, NO CONTESTA LOS MENSAJES SE WHATSAPP | W4: VISITA_TÉCNICA | X4: 0 | Y4: TIPO II | Z4: TERRESTRE | AA4: PAREDES CASTILLO DIEGO | AB4: 1 | AC4: =IF(AND(W4="SOPORTE_TELEFÓNICO",OR(U4="SIN CONTACTO CON EL CB",U4="NÚMEROS DE CONTACTO ERRADOS")),0,IF(W4="SOPORTE_TELEFÓNICO",'BASE DE LIQUIDACION 2025'!$B$9,IF(Y4="TIPO I",'BASE DE LIQUIDACION 2025'!$C$3,IF(Y4="TIPO II",'BASE DE LIQUIDACION 2025'!$C$4,IF(Y4="TIPO III",'BASE DE LIQUIDACION 2025'!$C$5,'BASE DE LIQUIDACION 2025'!$C$6))))) -> 134410.88 | AD4: =IF(W4="SOPORTE_TELEFÓNICO",AC4,CIERRES!AB4*CIERRES!AC4) -> 134410.88
A5: MONTERIA | B5: =VLOOKUP(A5,'CENTRO DE COSTOS'!A:D,4,FALSE) -> JOSE MAURICIO HERNANDEZ ROJAS | C5: =VLOOKUP(A5,'CENTRO DE COSTOS'!A:C,2,FALSE) -> 0004-0001 | D5: 23001 | E5: TA-25-809568 | F5: 52374 | G5: ORDEN DE CAMBIO | H5: CORDOBA | I5: MONTERIA | J5: BARRIO PANAMA MONTERIA 1 | K5: REDEBAN | L5: FO-25-1148140 | M5: 45836.333 | N5: 45839.592 | P5: CIERRE | Q5: CIERRE | R5: CB UNO A UNO | S5: CB UNO A UNO | T5: NO_EXITOSO | U5: CB NO ENTREGA EQUIPO | V5: 01-07-2025 SE LLEGÓ A LA DIRECCIÓN Y SE ENCUENTRA EL LOCAL CERRADO, SE HACE VALIDACIÓN CON LOS VECINOS Y NO DAN RAZÓN DEL CLIENTE, SE INTENTÓ COMUNICACIÓN VÍA TELEFÓNICA Y EL CLIENTE INFORMA QUE NO SE ENCUENTRA EN EL LOCAL PORQUE HACE MUCHO TIEMPO LO ENTREGÓ QUE TIENE LOS EQUIPOS EN LA CASA DE UNA PRIMA PERO EN EL MOMENTO SE ENCUENTRA CERRADA Y NO HAY QUIÉN ENTREGUE LOS EQUIPOS, SE LE INDICA QUE DEBE LLAMAR A LA LÍNEA DE ATENCIÓN CUÁNDO TENGA LA DISPONIBILIDAD Y LOS EQUIPOS PARA PODER REALIZAR EL CIERRE DE CB. | W5: VISITA_TÉCNICA | X5: 0 | Y5: TIPO I | Z5: TERRESTRE | AA5: CALDERA SALCEDO CARLOS JULIO | AB5: 1 | AC5: =IF(AND(W5="SOPORTE_TELEFÓNICO",OR(U5="SIN CONTACTO CON EL CB",U5="NÚMEROS DE CONTACTO ERRADOS")),0,IF(W5="SOPORTE_TELEFÓNICO",'BASE DE LIQUIDACION 2025'!$B$9,IF(Y5="TIPO I",'BASE DE LIQUIDACION 2025'!$C$3,IF(Y5="TIPO II",'BASE DE LIQUIDACION 2025'!$C$4,IF(Y5="TIPO III",'BASE DE LIQUIDACION 2025'!$C$5,'BASE DE LIQUIDACION 2025'!$C$6))))) -> 44559.564 | AD5: =IF(W5="SOPORTE_TELEFÓNICO",AC5,CIERRES!AB5*CIERRES!AC5) -> 44559.564
A6: SANTA MARTA | B6: =VLOOKUP(A6,'CENTRO DE COSTOS'!A:D,4,FALSE) -> JOSE MAURICIO HERNANDEZ ROJAS | C6: =VLOOKUP(A6,'CENTRO DE COSTOS'!A:C,2,FALSE) -> 0004-0001 | D6: 47707 | E6: TA-25-809559 | F6: 11452 | G6: ORDEN DE CAMBIO | H6: MAGDALENA | I6: SANTA ANA | J6: SANTA ANA MAGDALENA | K6: REDEBAN | L6: FO-25-1148107 | M6: 45836.333 | N6: 45839.618 | P6: CIERRE | Q6: CIERRE | R6: CB UNO A UNO | S6: CB UNO A UNO | T6: NO_EXITOSO | U6: CB NO ENTREGA EQUIPO | V6: 01-07-2025 SE REALIZA VISITA POR RECUPERACIÓN DE EQUIPO ATIENDE EL SR LUIS GABRIEL YEPES INDICANDO QUE NO ENTREGARA LOS EQUIPOS YA QUE EL BANCO LE ADEUDA LAS COMISIONES DE LOS MESES MARZO ,ABRIL Y MAYO , SE COMUNICA CON EL BANCO Y LE INDICAN QUE LAS COMISIONES SE LAS CONSIGNARON A UNA CUENTA DEL BANCO AGRARIO Y EL CLIENTE INDICA QUE EL NO TIENE CUENTA CON ESE BANCO POR TAL MOTIVO SE NIEGA A ENTREGAR EQUIPOS HASTA QUE EL BANCO LE PAGE LOS MESES DE COMISIONES | W6: VISITA_TÉCNICA | X6: 0 | Y6: TIPO IV | Z6: TERRESTRE | AA6: MAESTRE MENGUAL EDGAR ENRIQUE | AB6: 1 | AC6: =IF(AND(W6="SOPORTE_TELEFÓNICO",OR(U6="SIN CONTACTO CON EL CB",U6="NÚMEROS DE CONTACTO ERRADOS")),0,IF(W6="SOPORTE_TELEFÓNICO",'BASE DE LIQUIDACION 2025'!$B$9,IF(Y6="TIPO I",'BASE DE LIQUIDACION 2025'!$C$3,IF(Y6="TIPO II",'BASE DE LIQUIDACION 2025'!$C$4,IF(Y6="TIPO III",'BASE DE LIQUIDACION 2025'!$C$5,'BASE DE LIQUIDACION 2025'!$C$6))))) -> 464809.37 | AD6: =IF(W6="SOPORTE_TELEFÓNICO",AC6,CIERRES!AB6*CIERRES!AC6) -> 464809.37
A7: VILLAVICENCIO | B7: =VLOOKUP(A7,'CENTRO DE COSTOS'!A:D,4,FALSE) -> KEVIN ALEXIS CORZO BUSTOS | C7: =VLOOKUP(A7,'CENTRO DE COSTOS'!A:C,2,FALSE) -> 0004-0007 | D7: 95015 | E7: TA-25-809563 | F7: 46949 | G7: ORDEN DE CAMBIO | H7: GUAVIARE | I7: CALAMAR | J7: BARRIO LA PAZ CALAMAR | K7: REDEBAN | L7: FO-25-1148127 | M7: 45836.333 | N7: 45840.344 | P7: CIERRE | Q7: CIERRE | R7: CB UNO A UNO | S7: CB UNO A UNO | T7: NO_EXITOSO | U7: CB NO ENTREGA EQUIPO | V7: 01-07-2025 SE REALIZA CONTACTO TELEFONICO CON EL CLIENTE EL CUAL INDICA QUE NO SE ENCUENTRA EN EL PAÍS Y QUE VA COMUNICARSE CON EL BANCO PARA CONOCIMIENTO DEL CIERRE | W7: SOPORTE_TELEFÓNICO | X7: 0 | Y7: TIPO IV ESPECIAL | Z7: AEREO | AA7: PEDREROS CONTRERAS MICHAEL STEVENS | AB7: 0 | AC7: =IF(AND(W7="SOPORTE_TELEFÓNICO",OR(U7="SIN CONTACTO CON EL CB",U7="NÚMEROS DE CONTACTO ERRADOS")),0,IF(W7="SOPORTE_TELEFÓNICO",'BASE DE LIQUIDACION 2025'!$B$9,IF(Y7="TIPO I",'BASE DE LIQUIDACION 2025'!$C$3,IF(Y7="TIPO II",'BASE DE LIQUIDACION 2025'!$C$4,IF(Y7="TIPO III",'BASE DE LIQUIDACION 2025'!$C$5,'BASE DE LIQUIDACION 2025'!$C$6))))) -> 37904.612 | AD7: =IF(W7="SOPORTE_TELEFÓNICO",AC7,CIERRES!AB7*CIERRES!AC7) -> 37904.612
A8: PEREIRA | B8: =VLOOKUP(A8,'CENTRO DE COSTOS'!A:D,4,FALSE) -> DIEGO FERNANDO HENAO CARDONA | C8: =VLOOKUP(A8,'CENTRO DE COSTOS'!A:C,2,FALSE) -> 0004-0002 | D8: 76147 | E8: TA-25-799609 | F8: 71044 | G8: ORDEN DE CAMBIO | H8: VALLE DEL CAUCA | I8: CARTAGO | J8: DISTRICOL DROG. SALUD Y VIDA | K8: REDEBAN | L8: FO-25-1130568 | M8: 45832.599 | N8: 45840.395 | P8: CIERRE | Q8: CIERRE | R8: AGREGADOR | S8: DISTRICOL | T8: NO_EXITOSO | U8: CB NO ENTREGA EQUIPO | V8: 02-07-2025 EN COMUNICACIÓN CON ASESOR DE DISTRICOL INFORMA QUE CLIENTE ENTREGO EQUIPOS DIRECTAMENTE EN OFICINAS DE DISTRICOL | W8: SOPORTE_TELEFÓNICO | X8: 0 | Y8: TIPO I | Z8: TERRESTRE | AA8: LOAIZA LOPEZ JHON FREDDY | AB8: 0 | AC8: =IF(AND(W8="SOPORTE_TELEFÓNICO",OR(U8="SIN CONTACTO CON EL CB",U8="NÚMEROS DE CONTACTO ERRADOS")),0,IF(W8="SOPORTE_TELEFÓNICO",'BASE DE LIQUIDACION 2025'!$B$9,IF(Y8="TIPO I",'BASE DE LIQUIDACION 2025'!$C$3,IF(Y8="TIPO II",'BASE DE LIQUIDACION 2025'!$C$4,IF(Y8="TIPO III",'BASE DE LIQUIDACION 2025'!$C$5,'BASE DE LIQUIDACION 2025'!$C$6))))) -> 37904.612 | AD8: =IF(W8="SOPORTE_TELEFÓNICO",AC8,CIERRES!AB8*CIERRES!AC8) -> 37904.612
A9: MONTERIA | B9: =VLOOKUP(A9,'CENTRO DE COSTOS'!A:D,4,FALSE) -> JOSE MAURICIO HERNANDEZ ROJAS | C9: =VLOOKUP(A9,'CENTRO DE COSTOS'!A:C,2,FALSE) -> 0004-0001 | D9: 23417 | E9: TA-25-809572 | F9: 67036 | G9: ORDEN DE CAMBIO | H9: CORDOBA | I9: LORICA | J9: CALLE CORREGIMIENTO LAS FLORES | K9: REDEBAN | L9: FO-25-1148159 | M9: 45836.333 | N9: 45840.517 | P9: CIERRE | Q9: CIERRE | R9: CB UNO A UNO | S9: CB UNO A UNO | T9: NO_EXITOSO | U9: CB NO ENTREGA EQUIPO | V9: 02-07-2025 NO SÉ REALIZA CIERRE, POR QUÉ CLIENTE INFORMA QUE ESTÁ EN PROCESO DE SOLICITUD DE TRASLADO PARA REACTIVAR EL SERVICIO, NO PERMITEN EL CIERRE | W9: VISITA_TÉCNICA | X9: 6Z0HZ993 | Y9: TIPO II | Z9: TERRESTRE | AA9: COGOLLO ROSSO CAMILO ANDRES | AB9: 1 | AC9: =IF(AND(W9="SOPORTE_TELEFÓNICO",OR(U9="SIN CONTACTO CON EL CB",U9="NÚMEROS DE CONTACTO ERRADOS")),0,IF(W9="SOPORTE_TELEFÓNICO",'BASE DE LIQUIDACION 2025'!$B$9,IF(Y9="TIPO I",'BASE DE LIQUIDACION 2025'!$C$3,IF(Y9="TIPO II",'BASE DE LIQUIDACION 2025'!$C$4,IF(Y9="TIPO III",'BASE DE LIQUIDACION 2025'!$C$5,'BASE DE LIQUIDACION 2025'!$C$6))))) -> 134410.88 | AD9: =IF(W9="SOPORTE_TELEFÓNICO",AC9,CIERRES!AB9*CIERRES!AC9) -> 134410.88
A10: MEDELLIN | B10: =VLOOKUP(A10,'CENTRO DE COSTOS'!A:D,4,FALSE) -> JUAN SEBASTIÁN RÍOS CASTRILLÓN | C10: =VLOOKUP(A10,'CENTRO DE COSTOS'!A:C,2,FALSE) -> 0004-0005 | D10: 5591 | E10: TA-25-809614 | F10: 57196 | G10: ORDEN DE CAMBIO | H10: ANTIOQUIA | I10: PUERTO TRIUNFO | J10: BARRIO CORREGIMIENTO DORADAL PÚERTO TRIUNFO | K10: REDEBAN | L10: FO-25-1148316 | M10: 45836.333 | N10: 45841.508 | P10: CIERRE | Q10: RECUPERACION DE EQUIPOS | R10: CB UNO A UNO | S10: CB UNO A UNO | T10: NO_EXITOSO | U10: CB NO ENTREGA EQUIPO | V10: 03-07-2025 SE LLEGA A LA DIRECCIÓN Y NO SE ENCONTRÓ CORRESPONSAL Y ADICIONAL ESTABA CERRADO, SE REALIZA GESTIÓN TELEFÓNICA Y PERSONA QUE ATIENDE INFORMA QUE LOS EQUIPOS NO ESTÁN EN DORADAL QUE AGENDEN OTRA VISITA PARA ACORDAR DIRECCIÓN DE RECOGIDA | W10: VISITA_TÉCNICA | X10: 0 | Y10: TIPO IV | Z10: TERRESTRE | AA10: BARRIENTOS HERNANDEZ CRISTIAN HORACIO | AB10: 1 | AC10: =IF(AND(W10="SOPORTE_TELEFÓNICO",OR(U10="SIN CONTACTO CON EL CB",U10="NÚMEROS DE CONTACTO ERRADOS")),0,IF(W10="SOPORTE_TELEFÓNICO",'BASE DE LIQUIDACION 2025'!$B$9,IF(Y10="TIPO I",'BASE DE LIQUIDACION 2025'!$C$3,IF(Y10="TIPO II",'BASE DE LIQUIDACION 2025'!$C$4,IF(Y10="TIPO III",'BASE DE LIQUIDACION 2025'!$C$5,'BASE DE LIQUIDACION 2025'!$C$6))))) -> 464809.37 | AD10: =IF(W10="SOPORTE_TELEFÓNICO",AC10,CIERRES!AB10*CIERRES!AC10) -> 464809.37
A11: BOGOTA | B11: =VLOOKUP(A11,'CENTRO DE COSTOS'!A:D,4,FALSE) -> WILLIAM ASDRUBAL ROZO ROZO | C11: =VLOOKUP(A11,'CENTRO DE COSTOS'!A:C,2,FALSE) -> 0004-0004 | D11: 25885 | E11: TA-25-809582 | F11: 78439 | G11: ORDEN DE CAMBIO | H11: CUNDINAMARCA | I11: YACOPI | J11: BARRIO CENTRO YACOPI 5 | K11: REDEBAN | L11: FO-25-1148196 | M11: 45836.333 | N11: 45842.466 | P11: CIERRE | Q11: CIERRE | R11: CB UNO A UNO | S11: CB UNO A UNO | T11: NO_EXITOSO | U11: CB NO ENTREGA EQUIPO | V11: 04-07-2025 SE LLEGA A SITIO SE ENCUENTRA CERRADO EL PUNTO, SE LLAMA AL CLIENTE # DE CONTACTO MARIA PAULA BELTRAN COTRINA 3227475455, LO CUAL INDICA NO ENTREGAR EQUIPOS NI HACER PROCEDIMIENTO DE RETIRO YA QUE LLEVA UN PROCESO VÍA TELEFÓNICA POR UN TEMA DE PAGO DE HONORARIOS CON LA PARTE COMERCIAL DEL COMERCIO. | W11: VISITA_TÉCNICA | X11: 0 | Y11: TIPO IV | Z11: TERRESTRE | AA11: INFANTE SIERRA MANUEL FERNANDO | AB11: 1 | AC11: =IF(AND(W11="SOPORTE_TELEFÓNICO",OR(U11="SIN CONTACTO CON EL CB",U11="NÚMEROS DE CONTACTO ERRADOS")),0,IF(W11="SOPORTE_TELEFÓNICO",'BASE DE LIQUIDACION 2025'!$B$9,IF(Y11="TIPO I",'BASE DE LIQUIDACION 2025'!$C$3,IF(Y11="TIPO II",'BASE DE LIQUIDACION 2025'!$C$4,IF(Y11="TIPO III",'BASE DE LIQUIDACION 2025'!$C$5,'BASE DE LIQUIDACION 2025'!$C$6))))) -> 464809.37 | AD11: =IF(W11="SOPORTE_TELEFÓNICO",AC11,CIERRES!AB11*CIERRES!AC11) -> 464809.37
A12: CALI | B12: =VLOOKUP(A12,'CENTRO DE COSTOS'!A:D,4,FALSE) -> DIEGO FERNANDO HENAO CARDONA | C12: =VLOOKUP(A12,'CENTRO DE COSTOS'!A:C,2,FALSE) -> 0004-0003 | D12: 19256 | E12: TA-25-809608 | F12: 32966 | G12: ORDEN DE CAMBIO | H12: CAUCA | I12: EL TAMBO | J12: BARRIO CENTRO EL TAMBO 1 | K12: REDEBAN | L12: FO-25-1148287 | M12: 45836.333 | N12: 45842.545 | P12: CIERRE | Q12: RECUPERACION DE EQUIPOS | R12: CB UNO A UNO | S12: CB UNO A UNO | T12: NO_EXITOSO | U12: CB NO ENTREGA EQUIPO | V12: 04-07-2025 SE REALIZA LLAMADA AL CLIENTE, E INDICA QUE ESTA POR FUERA DE LA CIUDAD, PARA PODER RECOJER LOS EQUIPOS DEL CIERRE, POR VENCIMIENTO DE LA ACTIVIDAD , SE CIERRA Y SE LE INDICA AL CLIENTE UNA VEZ RETORNE LLAMAR A LA LINEA PARA PODER VOLVER A PROGRAMAR EL CIERRE, | W12: SOPORTE_TELEFÓNICO | X12: 0 | Y12: TIPO III | Z12: TERRESTRE | AA12: HENAO CARDONA DIEGO FERNANDO | AB12: 0 | AC12: =IF(AND(W12="SOPORTE_TELEFÓNICO",OR(U12="SIN CONTACTO CON EL CB",U12="NÚMEROS DE CONTACTO ERRADOS")),0,IF(W12="SOPORTE_TELEFÓNICO",'BASE DE LIQUIDACION 2025'!$B$9,IF(Y12="TIPO I",'BASE DE LIQUIDACION 2025'!$C$3,IF(Y12="TIPO II",'BASE DE LIQUIDACION 2025'!$C$4,IF(Y12="TIPO III",'BASE DE LIQUIDACION 2025'!$C$5,'BASE DE LIQUIDACION 2025'!$C$6))))) -> 37904.612 | AD12: =IF(W12="SOPORTE_TELEFÓNICO",AC12,CIERRES!AB12*CIERRES!AC12) -> 37904.612
A13: BOGOTA | B13: =VLOOKUP(A13,'CENTRO DE COSTOS'!A:D,4,FALSE) -> WILLIAM ASDRUBAL ROZO ROZO | C13: =VLOOKUP(A13,'CENTRO DE COSTOS'!A:C,2,FALSE) -> 0004-0004 | D13: 25126 | E13: TA-25-809576 | F13: 69256 | G13: ORDEN DE CAMBIO | H13: CUNDINAMARCA | I13: CAJICA | J13: CHUNTAME CAJICA 3 | K13: REDEBAN | L13: FO-25-1182209 | M13: 45836.333 | N13: 45842.562 | P13: CIERRE | Q13: CIERRE | R13: CB UNO A UNO | S13: CB UNO A UNO | T13: NO_EXITOSO | U13: CB NO ENTREGA EQUIPO | V13: 04-07-2025 SE REALIZA VISITA AL COMERCIO PARA EJECUTAR CIERRE DE CB BANCOLOMBIA PERO AL LLEGAR AL PUNTO SE ENCUENTRA CERRADO, SE ESTABLECE COMUNICACIÓN CON LA CLIENTE QUIEN INFORMA QUE NO PUEDE ENTREGAR LOS EQUIPOS DEL CIERRE NO TIENE EL TIEMPO, QUE ELLA MUEVAMENTE SE CONTACTA CON BANCOLOMBIA PARA CUADRA VISTA NUEVAMENTE. | W13: VISITA_TÉCNICA | X13: 0 | Y13: TIPO II | Z13: TERRESTRE | AA13: CORTES VELANDIA MIGUEL ANGEL | AB13: 2 | AC13: =IF(AND(W13="SOPORTE_TELEFÓNICO",OR(U13="SIN CONTACTO CON EL CB",U13="NÚMEROS DE CONTACTO ERRADOS")),0,IF(W13="SOPORTE_TELEFÓNICO",'BASE DE LIQUIDACION 2025'!$B$9,IF(Y13="TIPO I",'BASE DE LIQUIDACION 2025'!$C$3,IF(Y13="TIPO II",'BASE DE LIQUIDACION 2025'!$C$4,IF(Y13="TIPO III",'BASE DE LIQUIDACION 2025'!$C$5,'BASE DE LIQUIDACION 2025'!$C$6))))) -> 134410.88 | AD13: =IF(W13="SOPORTE_TELEFÓNICO",AC13,CIERRES!AB13*CIERRES!AC13) -> 268821.77
A14: TUNJA | B14: =VLOOKUP(A14,'CENTRO DE COSTOS'!A:D,4,FALSE) -> MIGUEL JULIÁN HERNÁNDEZ GUARÍN | C14: =VLOOKUP(A14,'CENTRO DE COSTOS'!A:C,2,FALSE) -> 0004-0008 | D14: 15238 | E14: TA-25-833858 | F14: 71876 | G14: ORDEN DE CAMBIO | H14: BOYACA | I14: DUITAMA | J14: BOYACA DUITAMA 2 | K14: REDEBAN | L14: FO-25-1182463 | M14: 45842.333 | N14: 45842.591 | P14: CIERRE | Q14: CIERRE | R14: CB UNO A UNO | S14: CB UNO A UNO | T14: NO_EXITOSO | U14: CB NO ENTREGA EQUIPO | V14: 04-07-2025 EN COMUNICACIÓN CON LA LÍNEA 3212895583 EL SEÑOR HECTOR ALFONSO MONROY CUCUNUBA INFORMA QUE NO ENTREGARÁ EQUIPOS YA QUE NO FUE NOTIFICADO, INFORMA QUE SOLICITO UN TRASLADO DEL SERVICIO Y NO UNA SOLICITUD DE CIERRE, INFORMA QUE SE COMUNICARÁ CON ASESOR COMERCIAL Y CON EL BANCO PARA MAYOR EXPLICACIÓN Y PARA ACTIVACIÓN DEL SERVICIO. SE LE INFORMA TAMBIÉN QUE SE PUEDE COMUNICAR A LA LÍNEA 018000953344 PARA MAYOR INFORMACIÓN. SIN VOLUNTAD DE ENTREGA SE CIERRA ORDEN. | W14: SOPORTE_TELEFÓNICO | X14: 0 | Y14: TIPO II | Z14: TERRESTRE | AA14: HERRERA GARZON JEYSON STEVENT | AB14: 0 | AC14: =IF(AND(W14="SOPORTE_TELEFÓNICO",OR(U14="SIN CONTACTO CON EL CB",U14="NÚMEROS DE CONTACTO ERRADOS")),0,IF(W14="SOPORTE_TELEFÓNICO",'BASE DE LIQUIDACION 2025'!$B$9,IF(Y14="TIPO I",'BASE DE LIQUIDACION 2025'!$C$3,IF(Y14="TIPO II",'BASE DE LIQUIDACION 2025'!$C$4,IF(Y14="TIPO III",'BASE DE LIQUIDACION 2025'!$C$5,'BASE DE LIQUIDACION 2025'!$C$6))))) -> 37904.612 | AD14: =IF(W14="SOPORTE_TELEFÓNICO",AC14,CIERRES!AB14*CIERRES!AC14) -> 37904.612
A15: IBAGUE | B15: =VLOOKUP(A15,'CENTRO DE COSTOS'!A:D,4,FALSE) -> KEVIN ALEXIS CORZO BUSTOS | C15: =VLOOKUP(A15,'CENTRO DE COSTOS'!A:C,2,FALSE) -> 0004-0007 | D15: 73001 | E15: TA-25-833789 | F15: 48235 | G15: ORDEN DE CAMBIO | H15: TOLIMA | I15: IBAGUE | J15: DISTRICOL MIL SOLUTIONS | K15: REDEBAN | L15: FO-25-1182234 | M15: 45842.333 | N15: 45842.686 | P15: CIERRE | Q15: CIERRE | R15: AGREGADOR | S15: DISTRICOL | T15: ILOCALIZADO | U15: CB CERRADO - DESOCUPADO | V15: 04-07-2025 SE VISITA DIRECCIÓN INDICADA DE CB EVIDENCIA QUE YA NO ESTÁ , SE REALIZA CONSULTA CON VECINOS DESCONOCEN UBICACIÓN INTENTA CONTACTAR TELEFÓNICAMENTE # 3124979196-3203596257SIN RESPUESTA | W15: VISITA_TÉCNICA | X15: 0 | Y15: TIPO I | Z15: TERRESTRE | AA15: GUTIERREZ CAMILO ANDRES | AB15: 1 | AC15: =IF(AND(W15="SOPORTE_TELEFÓNICO",OR(U15="SIN CONTACTO CON EL CB",U15="NÚMEROS DE CONTACTO ERRADOS")),0,IF(W15="SOPORTE_TELEFÓNICO",'BASE DE LIQUIDACION 2025'!$B$9,IF(Y15="TIPO I",'BASE DE LIQUIDACION 2025'!$C$3,IF(Y15="TIPO II",'BASE DE LIQUIDACION 2025'!$C$4,IF(Y15="TIPO III",'BASE DE LIQUIDACION 2025'!$C$5,'BASE DE LIQUIDACION 2025'!$C$6))))) -> 44559.564 | AD15: =IF(W15="SOPORTE_TELEFÓNICO",AC15,CIERRES!AB15*CIERRES!AC15) -> 44559.564
A16: CALI | B16: =VLOOKUP(A16,'CENTRO DE COSTOS'!A:D,4,FALSE) -> DIEGO FERNANDO HENAO CARDONA | C16: =VLOOKUP(A16,'CENTRO DE COSTOS'!A:C,2,FALSE) -> 0004-0003 | D16: 19001 | E16: TA-25-833849 | F16: 43981 | G16: ORDEN DE CAMBIO | H16: CAUCA | I16: POPAYAN | J16: BARRIO CAMPO BELLO POPAYAN | K16: REDEBAN | L16: FO-25-1182431 | M16: 45842.333 | N16: 45843.378 | P16: CIERRE | Q16: CIERRE | R16: CB UNO A UNO | S16: CB UNO A UNO | T16: NO_EXITOSO | U16: CB NO ENTREGA EQUIPO | V16: 05-07-2025 SE HABLA CON LA SEÑORA LUZ QUIEN INDICA QUE ESTA EN ESPERA DE UNA INDICACION PARA VALIDAR SI SE CONTINUA CON EL SERVICIO, SOLICITA DAR UNA ESPERA Y YA CUANDO SE DEFINA TODO ELLA SE COMUNICA SI ES NECESARIO. | W16: SOPORTE_TELEFÓNICO | X16: 0 | Y16: TIPO III | Z16: TERRESTRE | AA16: HENAO CARDONA DIEGO FERNANDO | AB16: 0 | AC16: =IF(AND(W16="SOPORTE_TELEFÓNICO",OR(U16="SIN CONTACTO CON EL CB",U16="NÚMEROS DE CONTACTO ERRADOS")),0,IF(W16="SOPORTE_TELEFÓNICO",'BASE DE LIQUIDACION 2025'!$B$9,IF(Y16="TIPO I",'BASE DE LIQUIDACION 2025'!$C$3,IF(Y16="TIPO II",'BASE DE LIQUIDACION 2025'!$C$4,IF(Y16="TIPO III",'BASE DE LIQUIDACION 2025'!$C$5,'BASE DE LIQUIDACION 2025'!$C$6))))) -> 37904.612 | AD16: =IF(W16="SOPORTE_TELEFÓNICO",AC16,CIERRES!AB16*CIERRES!AC16) -> 37904.612
A17: VILLAVICENCIO | B17: =VLOOKUP(A17,'CENTRO DE COSTOS'!A:D,4,FALSE) -> KEVIN ALEXIS CORZO BUSTOS | C17: =VLOOKUP(A17,'CENTRO DE COSTOS'!A:C,2,FALSE) -> 0004-0007 | D17: 50001 | E17: TA-25-833860 | F17: 78305 | G17: ORDEN DE CAMBIO | H17: META | I17: VILLAVICENCIO | J17: BARRIO VILLA DEL RIO VILLAVICENCIO 1 | K17: REDEBAN | L17: FO-25-1182468 | M17: 45842.333 | N17: 45843.446 | P17: CIERRE | Q17: CIERRE | R17: CB UNO A UNO | S17: CB UNO A UNO | T17: ILOCALIZADO | U17: CB CERRADO - DESOCUPADO | V17: 05-07-2025 SE REALIZA VISITA A CB COMERCIO CERRADO NO ES POSIBLE COMUNICACIÓN 3124822757 | W17: VISITA_TÉCNICA | X17: 0 | Y17: TIPO I | Z17: TERRESTRE | AA17: CASTRILLON URREA LONDIER LEANDRO | AB17: 1 | AC17: =IF(AND(W17="SOPORTE_TELEFÓNICO",OR(U17="SIN CONTACTO CON EL CB",U17="NÚMEROS DE CONTACTO ERRADOS")),0,IF(W17="SOPORTE_TELEFÓNICO",'BASE DE LIQUIDACION 2025'!$B$9,IF(Y17="TIPO I",'BASE DE LIQUIDACION 2025'!$C$3,IF(Y17="TIPO II",'BASE DE LIQUIDACION 2025'!$C$4,IF(Y17="TIPO III",'BASE DE LIQUIDACION 2025'!$C$5,'BASE DE LIQUIDACION 2025'!$C$6))))) -> 44559.564 | AD17: =IF(W17="SOPORTE_TELEFÓNICO",AC17,CIERRES!AB17*CIERRES!AC17) -> 44559.564
A18: PEREIRA | B18: =VLOOKUP(A18,'CENTRO DE COSTOS'!A:D,4,FALSE) -> DIEGO FERNANDO HENAO CARDONA | C18: =VLOOKUP(A18,'CENTRO DE COSTOS'!A:C,2,FALSE) -> 0004-0002 | D18: 66001 | E18: TA-25-809574 | F18: 68391 | G18: ORDEN DE CAMBIO | H18: RISARALDA | I18: PEREIRA | J18: VEREDA TRIBUNA | K18: REDEBAN | L18: FO-25-1148163 | M18: 45836.333 | N18: 45843.601 | P18: CIERRE | Q18: CIERRE | R18: CB UNO A UNO | S18: CB UNO A UNO | T18: NO_EXITOSO | U18: CB NO ENTREGA EQUIPO | V18: 05-07-2025 SE VISITA COMERCIO CLIENTE INFORMA QUE DESEA CONTINUAR CON CB SE ENCUENTRA PENDIENTE REAPERTURA DE COMERCIO POR REMODELACIÓN PENDIENTE COMUNICACIÓN CON LA ENTIDAD | W18: VISITA_TÉCNICA | X18: AALFZ736 | Y18: TIPO I | Z18: TERRESTRE | AA18: LOAIZA LOPEZ JHON FREDDY | AB18: 1 | AC18: =IF(AND(W18="SOPORTE_TELEFÓNICO",OR(U18="SIN CONTACTO CON EL CB",U18="NÚMEROS DE CONTACTO ERRADOS")),0,IF(W18="SOPORTE_TELEFÓNICO",'BASE DE LIQUIDACION 2025'!$B$9,IF(Y18="TIPO I",'BASE DE LIQUIDACION 2025'!$C$3,IF(Y18="TIPO II",'BASE DE LIQUIDACION 2025'!$C$4,IF(Y18="TIPO III",'BASE DE LIQUIDACION 2025'!$C$5,'BASE DE LIQUIDACION 2025'!$C$6))))) -> 44559.564 | AD18: =IF(W18="SOPORTE_TELEFÓNICO",AC18,CIERRES!AB18*CIERRES!AC18) -> 44559.564
A19: BARRANQUILLA | B19: =VLOOKUP(A19,'CENTRO DE COSTOS'!A:D,4,FALSE) -> JOSE MAURICIO HERNANDEZ ROJAS | C19: =VLOOKUP(A19,'CENTRO DE COSTOS'!A:C,2,FALSE) -> 0004-0001 | D19: 8758 | E19: TA-25-809577 | F19: 71519 | G19: ORDEN DE CAMBIO | H19: ATLANTICO | I19: SOLEDAD | J19: BARRIO ALMENDROS SOLEDAD 5 | K19: REDEBAN | L19: FO-25-1148174 | M19: 45836.333 | N19: 45844.377 | P19: CIERRE | Q19: CIERRE | R19: CB UNO A UNO | S19: CB UNO A UNO | T19: ILOCALIZADO | U19: CB CERRADO - DESOCUPADO | V19: 06-07-2025 SE REALIZA VISITA AL COMERCIO PARA REALIZAR EL CIERRE DEL CORRESPONSAL BANCOLOMBIA PERO NO ES POSIBLE TRATO COMUNICACION CON EL NÚMERO DADO PERO NO CONTESTAN | W19: VISITA_TÉCNICA | X19: A30KZ086 | Y19: TIPO I | Z19: TERRESTRE | AA19: PEÑALOZA GUTIERREZ RAFAEL GUSTAVO | AB19: 1 | AC19: =IF(AND(W19="SOPORTE_TELEFÓNICO",OR(U19="SIN CONTACTO CON EL CB",U19="NÚMEROS DE CONTACTO ERRADOS")),0,IF(W19="SOPORTE_TELEFÓNICO",'BASE DE LIQUIDACION 2025'!$B$9,IF(Y19="TIPO I",'BASE DE LIQUIDACION 2025'!$C$3,IF(Y19="TIPO II",'BASE DE LIQUIDACION 2025'!$C$4,IF(Y19="TIPO III",'BASE DE LIQUIDACION 2025'!$C$5,'BASE DE LIQUIDACION 2025'!$C$6))))) -> 44559.564 | AD19: =IF(W19="SOPORTE_TELEFÓNICO",AC19,CIERRES!AB19*CIERRES!AC19) -> 44559.564
A20: CALI | B20: =VLOOKUP(A20,'CENTRO DE COSTOS'!A:D,4,FALSE) -> DIEGO FERNANDO HENAO CARDONA | C20: =VLOOKUP(A20,'CENTRO DE COSTOS'!A:C,2,FALSE) -> 0004-0003 | D20: 19001 | E20: TA-25-809567 | F20: 49086 | G20: ORDEN DE CAMBIO | H20: CAUCA | I20: POPAYAN | J20: BARRIO SANTA ELENA POPAYAN 1 | K20: REDEBAN | L20: FO-25-1148135 | M20: 45836.333 | N20: 45845.205 | P20: CIERRE | Q20: CIERRE | R20: CB UNO A UNO | S20: CB UNO A UNO | T20: ILOCALIZADO | U20: CB CERRADO - DESOCUPADO | V20: 06-07-2025 SE LLEGA AL COMERCIO SE ENCUENTRA CERRADO | W20: VISITA_TÉCNICA | X20: BA0O0050 | Y20: TIPO III | Z20: TERRESTRE | AA20: GIMBUEL LASSO LUIS GERMAN | AB20: 1 | AC20: =IF(AND(W20="SOPORTE_TELEFÓNICO",OR(U20="SIN CONTACTO CON EL CB",U20="NÚMEROS DE CONTACTO ERRADOS")),0,IF(W20="SOPORTE_TELEFÓNICO",'BASE DE LIQUIDACION 2025'!$B$9,IF(Y20="TIPO I",'BASE DE LIQUIDACION 2025'!$C$3,IF(Y20="TIPO II",'BASE DE LIQUIDACION 2025'!$C$4,IF(Y20="TIPO III",'BASE DE LIQUIDACION 2025'!$C$5,'BASE DE LIQUIDACION 2025'!$C$6))))) -> 222904.07 | AD20: =IF(W20="SOPORTE_TELEFÓNICO",AC20,CIERRES!AB20*CIERRES!AC20) -> 222904.07
A21: IBAGUE | B21: =VLOOKUP(A21,'CENTRO DE COSTOS'!A:D,4,FALSE) -> KEVIN ALEXIS CORZO BUSTOS | C21: =VLOOKUP(A21,'CENTRO DE COSTOS'!A:C,2,FALSE) -> 0004-0007 | D21: 73001 | E21: TA-25-835647 | F21: 69181 | G21: ORDEN DE CAMBIO | H21: TOLIMA | I21: IBAGUE | J21: BARRIO PORTALES DEL NORTE IBAG | K21: REDEBAN | L21: FO-25-1186228 | M21: 45842.69 | N21: 45845.47 | P21: CIERRE | Q21: RECUPERACION DE EQUIPOS | R21: CB UNO A UNO | S21: CB UNO A UNO | T21: ILOCALIZADO | U21: CB CERRADO - DESOCUPADO | V21: 07-07-2025 SE LLEGA A LA DIRECCIÓN Y NO EXISTE CB CON ESE CU. SE LLAMA A LA SEÑORA DIANA REYES, AL NÚMERO 3185539461, PARA HACER CONTACTO, LAS PRIMERAS LLAMADAS SUENA EL TELÉFONO Y A LA CUARTA APAGAN EL NÚMERO. ME INDICAN QUE VIVE EN EL SEGUNDO PISO, GOLPEÓ LA PUERTA PERO NADIE RESPONDE. | W21: VISITA_TÉCNICA | X21: A103Z587 | Y21: TIPO I | Z21: TERRESTRE | AA21: VARGAS HERRERA JHON JAIRO | AB21: 1 | AC21: =IF(AND(W21="SOPORTE_TELEFÓNICO",OR(U21="SIN CONTACTO CON EL CB",U21="NÚMEROS DE CONTACTO ERRADOS")),0,IF(W21="SOPORTE_TELEFÓNICO",'BASE DE LIQUIDACION 2025'!$B$9,IF(Y21="TIPO I",'BASE DE LIQUIDACION 2025'!$C$3,IF(Y21="TIPO II",'BASE DE LIQUIDACION 2025'!$C$4,IF(Y21="TIPO III",'BASE DE LIQUIDACION 2025'!$C$5,'BASE DE LIQUIDACION 2025'!$C$6))))) -> 44559.564 | AD21: =IF(W21="SOPORTE_TELEFÓNICO",AC21,CIERRES!AB21*CIERRES!AC21) -> 44559.564
A22: BOGOTA | B22: =VLOOKUP(A22,'CENTRO DE COSTOS'!A:D,4,FALSE) -> WILLIAM ASDRUBAL ROZO ROZO | C22: =VLOOKUP(A22,'CENTRO DE COSTOS'!A:C,2,FALSE) -> 0004-0004 | D22: 11001 | E22: TA-25-833864 | F22: 22764 | G22: ORDEN DE CAMBIO | H22: CUNDINAMARCA | I22: BOGOTA | J22: EXXON BARRIO UNICENTRO BOGOTÁ | K22: REDEBAN | L22: FO-25-1182484 | M22: 45842.333 | N22: 45845.587 | P22: CIERRE | Q22: RECUPERACION DE EQUIPOS | R22: CB UNO A UNO | S22: CB UNO A UNO | T22: ILOCALIZADO | U22: CB CERRADO - DESOCUPADO | V22: 07-07-2025 SE REALIZA VISITA AL COMERCIO PARA EJECUTAR CIERRE DE CB BANCOLOMBIA PERO AL LLEGAR AL PUNTO YA NO EXITE EL CB INFORMA LA SRA. LINA AZA | W22: VISITA_TÉCNICA | X22: 0 | Y22: TIPO I | Z22: TERRESTRE | AA22: CORTES VELANDIA MIGUEL ANGEL | AB22: 1 | AC22: =IF(AND(W22="SOPORTE_TELEFÓNICO",OR(U22="SIN CONTACTO CON EL CB",U22="NÚMEROS DE CONTACTO ERRADOS")),0,IF(W22="SOPORTE_TELEFÓNICO",'BASE DE LIQUIDACION 2025'!$B$9,IF(Y22="TIPO I",'BASE DE LIQUIDACION 2025'!$C$3,IF(Y22="TIPO II",'BASE DE LIQUIDACION 2025'!$C$4,IF(Y22="TIPO III",'BASE DE LIQUIDACION 2025'!$C$5,'BASE DE LIQUIDACION 2025'!$C$6))))) -> 44559.564 | AD22: =IF(W22="SOPORTE_TELEFÓNICO",AC22,CIERRES!AB22*CIERRES!AC22) -> 44559.564
A23: NEIVA | B23: =VLOOKUP(A23,'CENTRO DE COSTOS'!A:D,4,FALSE) -> KEVIN ALEXIS CORZO BUSTOS | C23: =VLOOKUP(A23,'CENTRO DE COSTOS'!A:C,2,FALSE) -> 0004-0007 | D23: 18001 | E23: TA-25-833859 | F23: 78426 | G23: ORDEN DE CAMBIO | H23: CAQUETA | I23: FLORENCIA | J23: BARRIO LA ESTRELLA FLORENCIA | K23: REDEBAN | L23: FO-25-1182466 | M23: 45842.333 | N23: 45845.612 | P23: CIERRE | Q23: CIERRE | R23: CB UNO A UNO | S23: CB UNO A UNO | T23: SOLICITUD_CANCELADA | U23: CANCELADO POR LA ENTIDAD | V23: 07-07-2025 SE LLEGA AL COMERCIO Y CLIENTE MANIFIESTA QUE NO HA SOLICITADO EL CIERRE, INDICA QUE ESTUVO TRABAJANDO HASTA EL DÍA JUEVES Y QUE NO ENTIENDE POR SE LO ESTÁN ENVIANDO A CERRAR, MANIFIESTA LLAMAR A LA LÍNEA BANCOLOMBIA Y SOLICITAR LA ACTIVACIÓN NUEVAMENTE. | W23: VISITA_TÉCNICA | X23: V10ZZ346 | Y23: TIPO IV | Z23: TERRESTRE | AA23: BERMUDEZ SANCHEZ JOSE NEYBER | AB23: 1 | AC23: =IF(AND(W23="SOPORTE_TELEFÓNICO",OR(U23="SIN CONTACTO CON EL CB",U23="NÚMEROS DE CONTACTO ERRADOS")),0,IF(W23="SOPORTE_TELEFÓNICO",'BASE DE LIQUIDACION 2025'!$B$9,IF(Y23="TIPO I",'BASE DE LIQUIDACION 2025'!$C$3,IF(Y23="TIPO II",'BASE DE LIQUIDACION 2025'!$C$4,IF(Y23="TIPO III",'BASE DE LIQUIDACION 2025'!$C$5,'BASE DE LIQUIDACION 2025'!$C$6))))) -> 464809.37 | AD23: =IF(W23="SOPORTE_TELEFÓNICO",AC23,CIERRES!AB23*CIERRES!AC23) -> 464809.37
A24: BOGOTA | B24: =VLOOKUP(A24,'CENTRO DE COSTOS'!A:D,4,FALSE) -> WILLIAM ASDRUBAL ROZO ROZO | C24: =VLOOKUP(A24,'CENTRO DE COSTOS'!A:C,2,FALSE) -> 0004-0004 | D24: 11001 | E24: TA-25-833828 | F24: 54832 | G24: ORDEN DE CAMBIO | H24: CUNDINAMARCA | I24: BOGOTA | J24: AUTOSERVICIO BOSQUES DEL VIRRE | K24: REDEBAN | L24: FO-25-1182377 | M24: 45842.333 | N24: 45845.644 | P24: CIERRE | Q24: CIERRE | R24: RETAIL | S24: CONTIGO | T24: ILOCALIZADO | U24: CB CERRADO - DESOCUPADO | V24: 07-07-2025 SE REALIZA VISITA A DIRECCIÓN DE COMERCIO, SE ENCUENTRA COMERCIO CERRADO Y CON OTRA RAZÓN SOCIAL, NO SÉ TIENE RESPUESTA TELEFÓNICA EN NÚMERO DE CONTACTO RELACIONADO EN LA TA. | W24: VISITA_TÉCNICA | X24: 0 | Y24: TIPO I | Z24: TERRESTRE | AA24: MURCIA HERNANDEZ HARVEY IGNACIO | AB24: 1 | AC24: =IF(AND(W24="SOPORTE_TELEFÓNICO",OR(U24="SIN CONTACTO CON EL CB",U24="NÚMEROS DE CONTACTO ERRADOS")),0,IF(W24="SOPORTE_TELEFÓNICO",'BASE DE LIQUIDACION 2025'!$B$9,IF(Y24="TIPO I",'BASE DE LIQUIDACION 2025'!$C$3,IF(Y24="TIPO II",'BASE DE LIQUIDACION 2025'!$C$4,IF(Y24="TIPO III",'BASE DE LIQUIDACION 2025'!$C$5,'BASE DE LIQUIDACION 2025'!$C$6))))) -> 44559.564 | AD24: =IF(W24="SOPORTE_TELEFÓNICO",AC24,CIERRES!AB24*CIERRES!AC24) -> 44559.564
A25: MEDELLIN | B25: =VLOOKUP(A25,'CENTRO DE COSTOS'!A:D,4,FALSE) -> JUAN SEBASTIÁN RÍOS CASTRILLÓN | C25: =VLOOKUP(A25,'CENTRO DE COSTOS'!A:C,2,FALSE) -> 0004-0005 | D25: 5313 | E25: TA-25-835642 | F25: 62141 | G25: ORDEN DE CAMBIO | H25: ANTIOQUIA | I25: GRANADA | J25: BARRIO SECTOR LA ASUNCION GRAN | K25: REDEBAN | L25: FO-25-1186215 | M25: 45842.69 | N25: 45846.401 | P25: CIERRE | Q25: CIERRE | R25: CB UNO A UNO | S25: CB UNO A UNO | T25: ILOCALIZADO | U25: CB CERRADO - DESOCUPADO | V25: 07-07-2025 SE LLEGA A LA DIRECCIÓN SUMINISTRADA POR LA APLICACIÓN SYTEX Y NO SE ENCONTRÓ EL COMERCIO, SE REALIZA GESTIÓN TELEFÓNICA Y USUARIA INFORMA QUE NO SE ENCUENTRA EN LA DIRECCIÓN Y NO HAY NADIE QUE ATIENDA YA QUE NO SE LES NOTIFICO DE LA VISITA | W25: VISITA_TÉCNICA | X25: 0 | Y25: TIPO II | Z25: TERRESTRE | AA25: BARRIENTOS HERNANDEZ CRISTIAN HORACIO | AB25: 1 | AC25: =IF(AND(W25="SOPORTE_TELEFÓNICO",OR(U25="SIN CONTACTO CON EL CB",U25="NÚMEROS DE CONTACTO ERRADOS")),0,IF(W25="SOPORTE_TELEFÓNICO",'BASE DE LIQUIDACION 2025'!$B$9,IF(Y25="TIPO I",'BASE DE LIQUIDACION 2025'!$C$3,IF(Y25="TIPO II",'BASE DE LIQUIDACION 2025'!$C$4,IF(Y25="TIPO III",'BASE DE LIQUIDACION 2025'!$C$5,'BASE DE LIQUIDACION 2025'!$C$6))))) -> 134410.88 | AD25: =IF(W25="SOPORTE_TELEFÓNICO",AC25,CIERRES!AB25*CIERRES!AC25) -> 134410.88
A26: CALI | B26: =VLOOKUP(A26,'CENTRO DE COSTOS'!A:D,4,FALSE) -> DIEGO FERNANDO HENAO CARDONA | C26: =VLOOKUP(A26,'CENTRO DE COSTOS'!A:C,2,FALSE) -> 0004-0003 | D26: 76001 | E26: TA-25-835646 | F26: 34502 | G26: ORDEN DE CAMBIO | H26: VALLE DEL CAUCA | I26: CALI | J26: BARRIO SAN LUIS CALI 1 | K26: REDEBAN | L26: FO-25-1191209 | M26: 45842.69 | N26: 45846.416 | P26: CIERRE | Q26: RECUPERACION DE EQUIPOS | R26: CB UNO A UNO | S26: CB UNO A UNO | T26: EJECUTADO_EXITOSO | U26: CIERRE EXITOSO | V26: 07-07-2025 SE RECOGEN EQUIPOS DATÁFONO,LECTOR, PINPAD Y HUD EN DIRECCIÓN DIFERENTE CLIENTE NO FIRMA | W26: VISITA_TÉCNICA | X26: 9A002807 | Y26: TIPO I | Z26: TERRESTRE | AA26: CUERO RUIZ JHONNY | AB26: 1 | AC26: =IF(AND(W26="SOPORTE_TELEFÓNICO",OR(U26="SIN CONTACTO CON EL CB",U26="NÚMEROS DE CONTACTO ERRADOS")),0,IF(W26="SOPORTE_TELEFÓNICO",'BASE DE LIQUIDACION 2025'!$B$9,IF(Y26="TIPO I",'BASE DE LIQUIDACION 2025'!$C$3,IF(Y26="TIPO II",'BASE DE LIQUIDACION 2025'!$C$4,IF(Y26="TIPO III",'BASE DE LIQUIDACION 2025'!$C$5,'BASE DE LIQUIDACION 2025'!$C$6))))) -> 44559.564 | AD26: =IF(W26="SOPORTE_TELEFÓNICO",AC26,CIERRES!AB26*CIERRES!AC26) -> 44559.564
A27: CALI | B27: =VLOOKUP(A27,'CENTRO DE COSTOS'!A:D,4,FALSE) -> DIEGO FERNANDO HENAO CARDONA | C27: =VLOOKUP(A27,'CENTRO DE COSTOS'!A:C,2,FALSE) -> 0004-0003 | D27: 76130 | E27: TA-25-833775 | F27: 47874 | G27: ORDEN DE CAMBIO | H27: VALLE DEL CAUCA | I27: CANDELARIA | J27: DISTRICOL KEYVIVAN | K27: REDEBAN | L27: FO-25-1182181 | M27: 45842.333 | N27: 45848.387 | P27: CIERRE | Q27: CIERRE | R27: AGREGADOR | S27: DISTRICOL | T27: NO_EXITOSO | U27: CB NO ENTREGA EQUIPO | V27: 10-07-2025 SE REALIZA LLAMADA AL CLIENTE, PERO EL SEÑOR ANDRES QUE NOS CONTESTA, INDICA QUE NO TIENE CONOCIMIENTO DE LOS EQUIPOS, YA QUE EL LOCAL FUE CERRADO, ALLA NO EXISTE EL PUNTO Y NO TIENE CONTACTO DE LA PERSONA QUE FIGURA COMO TITULAR, PIDE QUE VALIDEMOS POR QUE EL NO TIENE CONTACTO CON LA PERSONA | W27: SOPORTE_TELEFÓNICO | X27: 0 | Y27: TIPO II | Z27: TERRESTRE | AA27: HENAO CARDONA DIEGO FERNANDO | AB27: 0 | AC27: =IF(AND(W27="SOPORTE_TELEFÓNICO",OR(U27="SIN CONTACTO CON EL CB",U27="NÚMEROS DE CONTACTO ERRADOS")),0,IF(W27="SOPORTE_TELEFÓNICO",'BASE DE LIQUIDACION 2025'!$B$9,IF(Y27="TIPO I",'BASE DE LIQUIDACION 2025'!$C$3,IF(Y27="TIPO II",'BASE DE LIQUIDACION 2025'!$C$4,IF(Y27="TIPO III",'BASE DE LIQUIDACION 2025'!$C$5,'BASE DE LIQUIDACION 2025'!$C$6))))) -> 37904.612 | AD27: =IF(W27="SOPORTE_TELEFÓNICO",AC27,CIERRES!AB27*CIERRES!AC27) -> 37904.612
A28: VILLAVICENCIO | B28: =VLOOKUP(A28,'CENTRO DE COSTOS'!A:D,4,FALSE) -> KEVIN ALEXIS CORZO BUSTOS | C28: =VLOOKUP(A28,'CENTRO DE COSTOS'!A:C,2,FALSE) -> 0004-0007 | D28: 50568 | E28: TA-25-847309 | F28: 72483 | G28: ORDEN DE CAMBIO | H28: META | I28: PUERTO GAITAN | J28: BARRIO PUERTO GAITAN BATEAS | K28: REDEBAN | L28: FO-25-1207487 | M28: 45847.543 | N28: 45848.425 | P28: CIERRE | Q28: CIERRE | R28: CB UNO A UNO | S28: CB UNO A UNO | T28: ILOCALIZADO | U28: CB CERRADO - DESOCUPADO | V28: 10-07-2025 SE REALIZA VISITA A COMERCI CB NO EXISTE NO ES POSIBLE COMUNICACIÓN CON TITULAR 3124206522- 3107724187 SE INDAGA EN EL SECTOR NO DAN INFORMACIÓN ILOCALIZABLE | W28: VISITA_TÉCNICA | X28: 0 | Y28: TIPO III | Z28: TERRESTRE | AA28: CASTRILLON URREA LONDIER LEANDRO | AB28: 1 | AC28: =IF(AND(W28="SOPORTE_TELEFÓNICO",OR(U28="SIN CONTACTO CON EL CB",U28="NÚMEROS DE CONTACTO ERRADOS")),0,IF(W28="SOPORTE_TELEFÓNICO",'BASE DE LIQUIDACION 2025'!$B$9,IF(Y28="TIPO I",'BASE DE LIQUIDACION 2025'!$C$3,IF(Y28="TIPO II",'BASE DE LIQUIDACION 2025'!$C$4,IF(Y28="TIPO III",'BASE DE LIQUIDACION 2025'!$C$5,'BASE DE LIQUIDACION 2025'!$C$6))))) -> 222904.07 | AD28: =IF(W28="SOPORTE_TELEFÓNICO",AC28,CIERRES!AB28*CIERRES!AC28) -> 222904.07
A29: CALI | B29: =VLOOKUP(A29,'CENTRO DE COSTOS'!A:D,4,FALSE) -> DIEGO FERNANDO HENAO CARDONA | C29: =VLOOKUP(A29,'CENTRO DE COSTOS'!A:C,2,FALSE) -> 0004-0003 | D29: 76001 | E29: TA-25-846848 | F29: 58164 | G29: ORDEN DE CAMBIO | H29: VALLE DEL CAUCA | I29: CALI | J29: PTM CALI FERRE INDUSTRIAS LU | K29: REDEBAN | L29: FO-25-1205694 | M29: 45847.453 | N29: 45848.473 | P29: CIERRE | Q29: CIERRE | R29: AGREGADOR | S29: COMCARD - PTM | T29: ILOCALIZADO | U29: CB CERRADO - DESOCUPADO | V29: 10-07-2025 SE LLEGA AL COMERCIO PERO ESTABA CERRADO SE LLAMA AL CLIENTE PERO NO CONTESTA , SE VALIDA EN LA ZONA Y MANIFIESTAN QUE EL LOCAL SE ENCUENTRA CERRADO HACE VARIO TIEMPO, SE PUEDE VALIDAR QUE LA CORRESPONDENCIA EN EL SITIO LLEVA VARIO TIEMPO EN EL BUZON DEL LOCAL , HASTA ROLLOS ENTREGADOS POR INTERAPIDISIMO SE ENCUENTRA ALLI ABANDONADOS | W29: VISITA_TÉCNICA | X29: TUZZZ355 | Y29: TIPO I | Z29: TERRESTRE | AA29: CUERO RUIZ JHONNY | AB29: 1 | AC29: =IF(AND(W29="SOPORTE_TELEFÓNICO",OR(U29="SIN CONTACTO CON EL CB",U29="NÚMEROS DE CONTACTO ERRADOS")),0,IF(W29="SOPORTE_TELEFÓNICO",'BASE DE LIQUIDACION 2025'!$B$9,IF(Y29="TIPO I",'BASE DE LIQUIDACION 2025'!$C$3,IF(Y29="TIPO II",'BASE DE LIQUIDACION 2025'!$C$4,IF(Y29="TIPO III",'BASE DE LIQUIDACION 2025'!$C$5,'BASE DE LIQUIDACION 2025'!$C$6))))) -> 44559.564 | AD29: =IF(W29="SOPORTE_TELEFÓNICO",AC29,CIERRES!AB29*CIERRES!AC29) -> 44559.564
A30: IBAGUE | B30: =VLOOKUP(A30,'CENTRO DE COSTOS'!A:D,4,FALSE) -> KEVIN ALEXIS CORZO BUSTOS | C30: =VLOOKUP(A30,'CENTRO DE COSTOS'!A:C,2,FALSE) -> 0004-0007 | D30: 17380 | E30: TA-25-846836 | F30: 44954 | G30: ORDEN DE CAMBIO | H30: CALDAS | I30: LA DORADA | J30: DISTRICOL FUNERALES CASA SAGRA | K30: REDEBAN | L30: FO-25-1205632 | M30: 45847.453 | N30: 45848.683 | P30: CIERRE | Q30: CIERRE | R30: AGREGADOR | S30: DISTRICOL | T30: NO_EXITOSO | U30: CB NO ENTREGA EQUIPO | V30: 10-07-2025 SE HABLA CON LA SEÑORA CLAUDIA RODRÍGUEZ, AL NÚMERO DE TELÉFONO 3108301952, ME INDICA QUE LO EQUIPOS LOS ENVÍO A MEDELLÍN. | W30: SOPORTE_TELEFÓNICO | X30: 0 | Y30: TIPO III | Z30: TERRESTRE | AA30: VARGAS HERRERA JHON JAIRO | AB30: 0 | AC30: =IF(AND(W30="SOPORTE_TELEFÓNICO",OR(U30="SIN CONTACTO CON EL CB",U30="NÚMEROS DE CONTACTO ERRADOS")),0,IF(W30="SOPORTE_TELEFÓNICO",'BASE DE LIQUIDACION 2025'!$B$9,IF(Y30="TIPO I",'BASE DE LIQUIDACION 2025'!$C$3,IF(Y30="TIPO II",'BASE DE LIQUIDACION 2025'!$C$4,IF(Y30="TIPO III",'BASE DE LIQUIDACION 2025'!$C$5,'BASE DE LIQUIDACION 2025'!$C$6))))) -> 37904.612 | AD30: =IF(W30="SOPORTE_TELEFÓNICO",AC30,CIERRES!AB30*CIERRES!AC30) -> 37904.612
A31: NEIVA | B31: =VLOOKUP(A31,'CENTRO DE COSTOS'!A:D,4,FALSE) -> KEVIN ALEXIS CORZO BUSTOS | C31: =VLOOKUP(A31,'CENTRO DE COSTOS'!A:C,2,FALSE) -> 0004-0007 | D31: 41001 | E31: TA-25-846839 | F31: 45438 | G31: ORDEN DE CAMBIO | H31: HUILA | I31: NEIVA | J31: DISTRICOL SANCHEZ LUBRICANTES | K31: REDEBAN | L31: FO-25-1205647 | M31: 45847.453 | N31: 45848.701 | P31: CIERRE | Q31: CIERRE | R31: AGREGADOR | S31: DISTRICOL | T31: NO_EXITOSO | U31: CB NO ENTREGA EQUIPO | V31: 10-07-2025 SE LLEGA A SITIO, CLIENTE INDICA QUE YA REALIZÓ ENVÍO DE EQUIPOS A DISTRICOL EN MEDELLIN | W31: VISITA_TÉCNICA | X31: AC0MZ790 | Y31: TIPO I | Z31: TERRESTRE | AA31: DIAZ VARGAS JONATHAN MIGUEL | AB31: 1 | AC31: =IF(AND(W31="SOPORTE_TELEFÓNICO",OR(U31="SIN CONTACTO CON EL CB",U31="NÚMEROS DE CONTACTO ERRADOS")),0,IF(W31="SOPORTE_TELEFÓNICO",'BASE DE LIQUIDACION 2025'!$B$9,IF(Y31="TIPO I",'BASE DE LIQUIDACION 2025'!$C$3,IF(Y31="TIPO II",'BASE DE LIQUIDACION 2025'!$C$4,IF(Y31="TIPO III",'BASE DE LIQUIDACION 2025'!$C$5,'BASE DE LIQUIDACION 2025'!$C$6))))) -> 44559.564 | AD31: =IF(W31="SOPORTE_TELEFÓNICO",AC31,CIERRES!AB31*CIERRES!AC31) -> 44559.564
A32: BUCARAMANGA | B32: =VLOOKUP(A32,'CENTRO DE COSTOS'!A:D,4,FALSE) -> MIGUEL JULIÁN HERNÁNDEZ GUARÍN | C32: =VLOOKUP(A32,'CENTRO DE COSTOS'!A:C,2,FALSE) -> 0004-0008 | D32: 68755 | E32: TA-25-847303 | F32: 67285 | G32: ORDEN DE CAMBIO | H32: SANTANDER | I32: SOCORRO | J32: BARRIO NARANJITO SOCORRO | K32: REDEBAN | L32: FO-25-1207453 | M32: 45847.543 | N32: 45848.708 | P32: CIERRE | Q32: CIERRE | R32: CB UNO A UNO | S32: CB UNO A UNO | T32: SOLICITUD_CANCELADA | U32: CANCELADO POR LA ENTIDAD | V32: 10-07-2025 ENTIDAD SOLICITA CERRAR LA ORDEN | W32: SOPORTE_TELEFÓNICO | X32: 0 | Y32: TIPO III | Z32: TERRESTRE | AA32: GELVEZ MOGOLLON JOSE ELISEO | AB32: 0 | AC32: =IF(AND(W32="SOPORTE_TELEFÓNICO",OR(U32="SIN CONTACTO CON EL CB",U32="NÚMEROS DE CONTACTO ERRADOS")),0,IF(W32="SOPORTE_TELEFÓNICO",'BASE DE LIQUIDACION 2025'!$B$9,IF(Y32="TIPO I",'BASE DE LIQUIDACION 2025'!$C$3,IF(Y32="TIPO II",'BASE DE LIQUIDACION 2025'!$C$4,IF(Y32="TIPO III",'BASE DE LIQUIDACION 2025'!$C$5,'BASE DE LIQUIDACION 2025'!$C$6))))) -> 37904.612 | AD32: =IF(W32="SOPORTE_TELEFÓNICO",AC32,CIERRES!AB32*CIERRES!AC32) -> 37904.612
A33: MEDELLIN | B33: =VLOOKUP(A33,'CENTRO DE COSTOS'!A:D,4,FALSE) -> JUAN SEBASTIÁN RÍOS CASTRILLÓN | C33: =VLOOKUP(A33,'CENTRO DE COSTOS'!A:C,2,FALSE) -> 0004-0005 | D33: 15572 | E33: TA-25-846843 | F33: 52844 | G33: ORDEN DE CAMBIO | H33: BOYACA | I33: PUERTO BOYACA | J33: DISTRICOL PAPELERIA Y MISCELAN | K33: REDEBAN | L33: FO-25-1205668 | M33: 45847.453 | N33: 45848.717 | P33: CIERRE | Q33: CIERRE | R33: AGREGADOR | S33: DISTRICOL | T33: NO_EXITOSO | U33: CB NO ENTREGA EQUIPO | V33: 10-07-2025 SE LLEGA A SITO Y USUARIO CONFIRMA QUE LOS EQUIPOS SE ENVIARON DISTRICOL MEDELLÍN SE DESMONTA PUBLICIDAD INSTALADA | W33: VISITA_TÉCNICA | X33: BA01Z147 | Y33: TIPO IV | Z33: TERRESTRE | AA33: DIAZ ZABALA FRANCIS DUBAN | AB33: 1 | AC33: =IF(AND(W33="SOPORTE_TELEFÓNICO",OR(U33="SIN CONTACTO CON EL CB",U33="NÚMEROS DE CONTACTO ERRADOS")),0,IF(W33="SOPORTE_TELEFÓNICO",'BASE DE LIQUIDACION 2025'!$B$9,IF(Y33="TIPO I",'BASE DE LIQUIDACION 2025'!$C$3,IF(Y33="TIPO II",'BASE DE LIQUIDACION 2025'!$C$4,IF(Y33="TIPO III",'BASE DE LIQUIDACION 2025'!$C$5,'BASE DE LIQUIDACION 2025'!$C$6))))) -> 464809.37 | AD33: =IF(W33="SOPORTE_TELEFÓNICO",AC33,CIERRES!AB33*CIERRES!AC33) -> 464809.37
A34: YOPAL | B34: =VLOOKUP(A34,'CENTRO DE COSTOS'!A:D,4,FALSE) -> KEVIN ALEXIS CORZO BUSTOS | C34: =VLOOKUP(A34,'CENTRO DE COSTOS'!A:C,2,FALSE) -> 0004-0007 | D34: 85001 | E34: TA-25-835645 | F34: 77381 | G34: ORDEN DE CAMBIO | H34: CASANARE | I34: YOPAL | J34: BARRIO CIUDADELA COMFACASANARE YOPAL | K34: REDEBAN | L34: FO-25-1186224 | M34: 45842.69 | N34: 45849.481 | P34: CIERRE | Q34: CIERRE | R34: CB UNO A UNO | S34: CB UNO A UNO | T34: NO_EXITOSO | U34: MIXTO UNO A UNO NO COBRAR | V34: 11-07-2025 EN COMUNICACIÓN CON EL SEÑOR ENRIQUE CAMACHO, SE VISITA SITIO INDICADO. SE LLEGA AL SITO EN COMUNICACIÓN CON EL SEÑOR ENRIQUE INDICA QUE NO PUEDE ENTREGAR LOS EQUIPOS, EL NO SE ENCUENTRA EN MUNICIPIO Y LA PERSONA QUE VA HACER EL FAVOR DE ENTREGAR NO TIENE LAS LLAVES PARA ACCEDER AL COMERCIO. SE LE INFORMA UNA VEZ SE ENCUENTRE A DISPOSICIÓN DE ENTREGA SE COMUNIQUE A LA LINEA DEL BANCO Y SOLICITE LA ENTREGA. | W34: VISITA_TÉCNICA | X34: NONE | Y34: TIPO I | Z34: TERRESTRE | AA34: BERNAL ELAICA EDGAR ALEXIS | AB34: 1 | AC34: =IF(AND(W34="SOPORTE_TELEFÓNICO",OR(U34="SIN CONTACTO CON EL CB",U34="NÚMEROS DE CONTACTO ERRADOS")),0,IF(W34="SOPORTE_TELEFÓNICO",'BASE DE LIQUIDACION 2025'!$B$9,IF(Y34="TIPO I",'BASE DE LIQUIDACION 2025'!$C$3,IF(Y34="TIPO II",'BASE DE LIQUIDACION 2025'!$C$4,IF(Y34="TIPO III",'BASE DE LIQUIDACION 2025'!$C$5,'BASE DE LIQUIDACION 2025'!$C$6))))) -> 44559.564 | AD34: =IF(W34="SOPORTE_TELEFÓNICO",AC34,CIERRES!AB34*CIERRES!AC34) -> 44559.564
A35: MEDELLIN | B35: =VLOOKUP(A35,'CENTRO DE COSTOS'!A:D,4,FALSE) -> JUAN SEBASTIÁN RÍOS CASTRILLÓN | C35: =VLOOKUP(A35,'CENTRO DE COSTOS'!A:C,2,FALSE) -> 0004-0005 | D35: 5591 | E35: TA-25-846840 | F35: 49149 | G35: ORDEN DE CAMBIO | H35: ANTIOQUIA | I35: PUERTO TRIUNFO | J35: DISTRICOL VA EMMANUEL DORADAL | K35: REDEBAN | L35: FO-25-1205653 | M35: 45847.453 | N35: 45849.542 | P35: CIERRE | Q35: CIERRE | R35: AGREGADOR | S35: DISTRICOL | T35: NO_EXITOSO | U35: CB NO ENTREGA EQUIPO | V35: 11-07-2025 USUARIO MANIFISTA QUÉ YA LOS EQUIPOS FUERON ENVIADOS A DISTRICOL MEDELLÍN | W35: VISITA_TÉCNICA | X35: NA | Y35: TIPO IV | Z35: TERRESTRE | AA35: DIAZ ZABALA FRANCIS DUBAN | AB35: 1 | AC35: =IF(AND(W35="SOPORTE_TELEFÓNICO",OR(U35="SIN CONTACTO CON EL CB",U35="NÚMEROS DE CONTACTO ERRADOS")),0,IF(W35="SOPORTE_TELEFÓNICO",'BASE DE LIQUIDACION 2025'!$B$9,IF(Y35="TIPO I",'BASE DE LIQUIDACION 2025'!$C$3,IF(Y35="TIPO II",'BASE DE LIQUIDACION 2025'!$C$4,IF(Y35="TIPO III",'BASE DE LIQUIDACION 2025'!$C$5,'BASE DE LIQUIDACION 2025'!$C$6))))) -> 464809.37 | AD35: =IF(W35="SOPORTE_TELEFÓNICO",AC35,CIERRES!AB35*CIERRES!AC35) -> 464809.37
A36: BOGOTA | B36: =VLOOKUP(A36,'CENTRO DE COSTOS'!A:D,4,FALSE) -> WILLIAM ASDRUBAL ROZO ROZO | C36: =VLOOKUP(A36,'CENTRO DE COSTOS'!A:C,2,FALSE) -> 0004-0004 | D36: 25785 | E36: TA-25-839180 | F36: 51358 | G36: ORDEN DE CAMBIO | H36: CUNDINAMARCA | I36: TABIO | J36: CONTIGO_SUPERMARKET | K36: REDEBAN | L36: FO-25-1195929 | M36: 45845.639 | N36: 45849.717 | P36: CIERRE | Q36: RETIRO VOLUNTARIO | R36: RETAIL | S36: CONTIGO | T36: NO_EXITOSO | U36: CB NO ENTREGA EQUIPO | V36: 11-07-2025 SE REALIZA VISITA AL COMERCIO NOS ATIENDE LA SEÑORA DANIELA CASTRO LA CUAL NOS INDICA QUE YA FUE REALIZÓ LA ENTREGA DE LOS EQUIPOS | W36: VISITA_TÉCNICA | X36: NA | Y36: TIPO II | Z36: TERRESTRE | AA36: HERNANDEZ NARANJO OSCAR EDUARDO | AB36: 1 | AC36: =IF(AND(W36="SOPORTE_TELEFÓNICO",OR(U36="SIN CONTACTO CON EL CB",U36="NÚMEROS DE CONTACTO ERRADOS")),0,IF(W36="SOPORTE_TELEFÓNICO",'BASE DE LIQUIDACION 2025'!$B$9,IF(Y36="TIPO I",'BASE DE LIQUIDACION 2025'!$C$3,IF(Y36="TIPO II",'BASE DE LIQUIDACION 2025'!$C$4,IF(Y36="TIPO III",'BASE DE LIQUIDACION 2025'!$C$5,'BASE DE LIQUIDACION 2025'!$C$6))))) -> 134410.88 | AD36: =IF(W36="SOPORTE_TELEFÓNICO",AC36,CIERRES!AB36*CIERRES!AC36) -> 134410.88
A37: MONTERIA | B37: =VLOOKUP(A37,'CENTRO DE COSTOS'!A:D,4,FALSE) -> JOSE MAURICIO HERNANDEZ ROJAS | C37: =VLOOKUP(A37,'CENTRO DE COSTOS'!A:C,2,FALSE) -> 0004-0001 | D37: 23079 | E37: TA-25-839276 | F37: 62995 | G37: ORDEN DE CAMBIO | H37: CORDOBA | I37: BUENAVISTA | J37: BARRIO BOGOTA BUENAVISTA 1 | K37: REDEBAN | L37: FO-25-1196112 | M37: 45845.653 | N37: 45849.718 | P37: CIERRE | Q37: CIERRE | R37: CB UNO A UNO | S37: CB UNO A UNO | T37: ILOCALIZADO | U37: CB CERRADO - DESOCUPADO | V37: 11-07-2025 SE VISITA CB EN DIRECCIÓN DE RETIRO CRA 22 CLL 12F PERO NO SE ENCUENTRA QUIEN ENTREGUE EQUIPOS, LOCAL CERRADO. SE INTENTA COMUNICACIÓN AL NÚMERO 3145206981 PERO NO RESPONDE.SE CIERRA ACTIVIDAD COMO FALLIDA YA QUE NO SE LOGRA COMUNICACIÓN NI SE ENCUENTRA CB EN SITIO. | W37: VISITA_TÉCNICA | X37: NO SE INTERVIENE | Y37: TIPO II | Z37: TERRESTRE | AA37: COGOLLO VERTEL EDER LUIS | AB37: 1 | AC37: =IF(AND(W37="SOPORTE_TELEFÓNICO",OR(U37="SIN CONTACTO CON EL CB",U37="NÚMEROS DE CONTACTO ERRADOS")),0,IF(W37="SOPORTE_TELEFÓNICO",'BASE DE LIQUIDACION 2025'!$B$9,IF(Y37="TIPO I",'BASE DE LIQUIDACION 2025'!$C$3,IF(Y37="TIPO II",'BASE DE LIQUIDACION 2025'!$C$4,IF(Y37="TIPO III",'BASE DE LIQUIDACION 2025'!$C$5,'BASE DE LIQUIDACION 2025'!$C$6))))) -> 134410.88 | AD37: =IF(W37="SOPORTE_TELEFÓNICO",AC37,CIERRES!AB37*CIERRES!AC37) -> 134410.88
A38: TUNJA | B38: =VLOOKUP(A38,'CENTRO DE COSTOS'!A:D,4,FALSE) -> MIGUEL JULIÁN HERNÁNDEZ GUARÍN | C38: =VLOOKUP(A38,'CENTRO DE COSTOS'!A:C,2,FALSE) -> 0004-0008 | D38: 15238 | E38: TA-25-839281 | F38: 75698 | G38: ORDEN DE CAMBIO | H38: BOYACA | I38: DUITAMA | J38: BARRIO MANZANARES DUITAMA 4 | K38: REDEBAN | L38: FO-25-1202695 | M38: 45845.653 | N38: 45849.722 | P38: CIERRE | Q38: CIERRE | R38: CB UNO A UNO | S38: CB UNO A UNO | T38: EJECUTADO_EXITOSO | U38: CIERRE EXITOSO | V38: 11-07-2025 SE EJECUTA CIERRE CORRESPONSAL BANCARIO BANCOLOMBIA RETIRANDO LOS EQUIPOS EXISTENTES COMERCIO SIN PUBLICIDAD SE RETIRAN EL LA CALLE 15#9A-02 PUBLICIDAD EXISTENTE EN LA FACHADA CORRESPONDE AL CB 59684 EXISTENTE EN LA DIRECCIÓN DE ENTREGA. | W38: VISITA_TÉCNICA | X38: 1000R516 | Y38: TIPO II | Z38: TERRESTRE | AA38: RODRIGUEZ MURCIA YERSON IVAN | AB38: 1 | AC38: =IF(AND(W38="SOPORTE_TELEFÓNICO",OR(U38="SIN CONTACTO CON EL CB",U38="NÚMEROS DE CONTACTO ERRADOS")),0,IF(W38="SOPORTE_TELEFÓNICO",'BASE DE LIQUIDACION 2025'!$B$9,IF(Y38="TIPO I",'BASE DE LIQUIDACION 2025'!$C$3,IF(Y38="TIPO II",'BASE DE LIQUIDACION 2025'!$C$4,IF(Y38="TIPO III",'BASE DE LIQUIDACION 2025'!$C$5,'BASE DE LIQUIDACION 2025'!$C$6))))) -> 134410.88 | AD38: =IF(W38="SOPORTE_TELEFÓNICO",AC38,CIERRES!AB38*CIERRES!AC38) -> 134410.88
A39: CALI | B39: =VLOOKUP(A39,'CENTRO DE COSTOS'!A:D,4,FALSE) -> DIEGO FERNANDO HENAO CARDONA | C39: =VLOOKUP(A39,'CENTRO DE COSTOS'!A:C,2,FALSE) -> 0004-0003 | D39: 76001 | E39: TA-25-839293 | F39: 40257 | G39: ORDEN DE CAMBIO | H39: VALLE DEL CAUCA | I39: CALI | J39: PTM CALI EXITORNILLOS | K39: REDEBAN | L39: FO-25-1208329 | M39: 45845.653 | N39: 45849.744 | P39: CIERRE | Q39: CIERRE | R39: AGREGADOR | S39: COMCARD - PTM | T39: EJECUTADO_EXITOSO | U39: CIERRE EXITOSO | V39: 11-07-2025 SE REALIZA RETIRO DE EQUIPOS Y ACCESORIOS DE CB BANCOLOMBIA MIXTO, SON ENTREGADOS EN BODEGA DE LINEA COMUNICACIONES, LOS EQUIPOS SON RECOGIDOS EN DIRECCIÓN DIFERENTE A LA DEL COMERCIO EL CLIENTE NO CUENTA CON PUBLICIDAD. | W39: VISITA_TÉCNICA | X39: AB0HZ963 - UV001666 | Y39: TIPO I | Z39: TERRESTRE | AA39: MONTERO MUESES GIAN CARLO | AB39: 1 | AC39: =IF(AND(W39="SOPORTE_TELEFÓNICO",OR(U39="SIN CONTACTO CON EL CB",U39="NÚMEROS DE CONTACTO ERRADOS")),0,IF(W39="SOPORTE_TELEFÓNICO",'BASE DE LIQUIDACION 2025'!$B$9,IF(Y39="TIPO I",'BASE DE LIQUIDACION 2025'!$C$3,IF(Y39="TIPO II",'BASE DE LIQUIDACION 2025'!$C$4,IF(Y39="TIPO III",'BASE DE LIQUIDACION 2025'!$C$5,'BASE DE LIQUIDACION 2025'!$C$6))))) -> 44559.564 | AD39: =IF(W39="SOPORTE_TELEFÓNICO",AC39,CIERRES!AB39*CIERRES!AC39) -> 44559.564
A40: CUCUTA | B40: =VLOOKUP(A40,'CENTRO DE COSTOS'!A:D,4,FALSE) -> MIGUEL JULIÁN HERNÁNDEZ GUARÍN | C40: =VLOOKUP(A40,'CENTRO DE COSTOS'!A:C,2,FALSE) -> 0004-0008 | D40: 54405 | E40: TA-25-846847 | F40: 77857 | G40: ORDEN DE CAMBIO | H40: NORTE DE SANTANDER | I40: LOS PATIOS | J40: PTM PUNTOSERVIS LOS PATIOS 1 L | K40: REDEBAN | L40: FO-25-1205688 | M40: 45847.453 | N40: 45849.747 | P40: CIERRE | Q40: CIERRE | R40: AGREGADOR | S40: COMCARD - PTM | T40: ILOCALIZADO | U40: CB CERRADO - DESOCUPADO | V40: 11-07-2025 SE VISITA DIRECCIÓN DEL CB SE ENCUENTRA CERRADO, SE LLAMA AL CLIENTE SE VA BUZÓN DE VOZ, SE DEJA MENSAJE NO SE OBTIENE RESPUESTA. | W40: VISITA_TÉCNICA | X40: NA | Y40: TIPO I | Z40: TERRESTRE | AA40: TORRES MANTILLA JOSE DANIEL | AB40: 1 | AC40: =IF(AND(W40="SOPORTE_TELEFÓNICO",OR(U40="SIN CONTACTO CON EL CB",U40="NÚMEROS DE CONTACTO ERRADOS")),0,IF(W40="SOPORTE_TELEFÓNICO",'BASE DE LIQUIDACION 2025'!$B$9,IF(Y40="TIPO I",'BASE DE LIQUIDACION 2025'!$C$3,IF(Y40="TIPO II",'BASE DE LIQUIDACION 2025'!$C$4,IF(Y40="TIPO III",'BASE DE LIQUIDACION 2025'!$C$5,'BASE DE LIQUIDACION 2025'!$C$6))))) -> 44559.564 | AD40: =IF(W40="SOPORTE_TELEFÓNICO",AC40,CIERRES!AB40*CIERRES!AC40) -> 44559.564
...

Sheet TIPOLOGIAS
A1: COD. CIUDAD | B1: CIUDAD | C1: DEPARTAMENTO | D1: DESDE DONDE SE ATIENDE | E1: TIPO DE TRAYECTO NUEVO | F1: TIPOLOGIA NUEVA
A2: 91430 | B2: LA VICTORIA | C2: AMAZONAS | D2: BOGOTA | E2: AEREO | F2: TIPO IV ESPECIAL
A3: 91669 | B3: PUERTO SANTANDER | C3: AMAZONAS | D3: BOGOTA | E3: AEREO | F3: TIPO IV ESPECIAL
A4: 91263 | B4: EL ENCANTO | C4: AMAZONAS | D4: BOGOTA | E4: AEREO | F4: TIPO IV ESPECIAL
A5: 91405 | B5: LA CHORRERA | C5: AMAZONAS | D5: BOGOTA | E5: AEREO | F5: TIPO IV ESPECIAL
A6: 91407 | B6: LA PEDRERA | C6: AMAZONAS | D6: BOGOTA | E6: AEREO | F6: TIPO IV ESPECIAL
A7: 91001 | B7: LETICIA | C7: AMAZONAS | D7: BOGOTA | E7: AEREO | F7: TIPO IV ESPECIAL
A8: 91460 | B8: MIRITI - PARANA | C8: AMAZONAS | D8: BOGOTA | E8: AEREO | F8: TIPO IV ESPECIAL
A9: 91530 | B9: PUERTO ALEGRIA | C9: AMAZONAS | D9: BOGOTA | E9: AEREO | F9: TIPO IV ESPECIAL
A10: 91536 | B10: PUERTO ARICA | C10: AMAZONAS | D10: BOGOTA | E10: AEREO | F10: TIPO IV ESPECIAL
A11: 91540 | B11: PUERTO NARIÑO | C11: AMAZONAS | D11: BOGOTA | E11: AEREO | F11: TIPO IV ESPECIAL
A12: 91798 | B12: TARAPACA | C12: AMAZONAS | D12: BOGOTA | E12: AEREO | F12: TIPO IV ESPECIAL
A13: 5055 | B13: ARGELIA | C13: ANTIOQUIA | D13: MEDELLIN | E13: TERRESTRE | F13: TIPO IV
... A1124: 23682 | B1124: SAN JOSE DE URE | C1124: CORDOBA | D1124: MONTERIA | E1124: TERRESTRE | F1124: TIPO III

Sheet CENTRO DE COSTOS
A1: CIUDAD | B1: CENTRO_COSTO | C1: DESCRIPCION | D1: COORDINADOR
A2: APARTADO | B2: 0004-0005 | C2: Redeban Noroccidente (Medellín) | D2: JUAN SEBASTIÁN RÍOS CASTRILLÓN
A3: BARRANQUILLA | B3: 0004-0001 | C3: Redeban Costa (Barranqullla) | D3: JOSE MAURICIO HERNANDEZ ROJAS
A4: BOGOTA | B4: 0004-0004 | C4: Redeban Centro ( Bogotá) | D4: WILLIAM ASDRUBAL ROZO ROZO
A5: BUCARAMANGA | B5: 0004-0008 | C5: Redeban Santander | D5: MIGUEL JULIÁN HERNÁNDEZ GUARÍN
A6: CALI | B6: 0004-0003 | C6: Redeban Suroccidente (Cali) | D6: DIEGO FERNANDO HENAO CARDONA
A7: CARTAGENA | B7: 0004-0001 | C7: Redeban Costa (Barranqullla) | D7: JOSE MAURICIO HERNANDEZ ROJAS
A8: CUCUTA | B8: 0004-0008 | C8: Redeban Santander | D8: MIGUEL JULIÁN HERNÁNDEZ GUARÍN
A9: FLORENCIA | B9: 0004-0007 | C9: Redeban Oriente (Otros) | D9: KEVIN ALEXIS CORZO BUSTOS
A10: IBAGUE | B10: 0004-0007 | C10: Redeban Oriente (Otros) | D10: KEVIN ALEXIS CORZO BUSTOS
A11: MANIZALES | B11: 0004-0002 | C11: Redeban Eje Cafetero (Pereira) | D11: DIEGO FERNANDO HENAO CARDONA
A12: MEDELLIN | B12: 0004-0005 | C12: Redeban Noroccidente (Medellín) | D12: JUAN SEBASTIÁN RÍOS CASTRILLÓN
... A23: YOPAL | B23: 0004-0007 | C23: Redeban Oriente (Otros) | D23: KEVIN ALEXIS CORZO BUSTOS
