Workbook
Name A: #REF!
Name A: #REF!
Name ACTIVIDAD: [1]Hoja2!$P$2:$P$30
Name Actividad: [2]Formulas!$H$2:$H$5000
Name Analistas: '[3]Listas Desplegables'!$T$2:$T$7
Name arearesponsable: '[4]Listas desplegables'!$BB$2:$BB$100
Name CCO: [5]Tecnicos!$A$2:$A$1000
Name Clientes: [6]Clientes!$A$2:$A$100
Name Clientes: [2]Clientes!$A$2:$A$100
Name COORDINADOR: [1]Hoja2!$D$2:$D$30
Name Coordinadores: [7]Coordinadores!$A$2:$A$1000
Name Coordinadores: [2]Coordinadores!$A$2:$A$1000
Name DOCUMENTADOR: [1]Hoja2!$A$2:$A$30
Name ES: [1]Hoja2!$K$2:$K$30
Name ESS: [1]Hoja2!$K$2:$K$30
Name Estado: [6]Formulas!$K$2:$K$5000
Name Estado: [2]Formulas!$K$2:$K$5000
Name ESTADOACTIVIDAD: [1]Hoja2!$M$2:$M$30
Name ESTADOS: '[8]Listas desplegables'!$B$1:$D$1
Name ESTADOS: '[9]Listas desplegables'!$B$1:$D$1
Name ESTADOSCIERRES: '[10]lista desplegable'!$CX$1:$DA$1
Name Facturacion: '[11]Listas desplegables'!$AO$1:$AR$1
Name FACTURACIÓN: '[8]Listas desplegables'!$Y$1:$AB$1
Name FACTURACIÓN: '[9]Listas desplegables'!$Y$1:$AB$1
Name falla: #REF!
Name Fallas: '[12]Listas desplegables'!$F$2:$L$2
Name Fallas: '[13]Listas desplegables'!$F$2:$L$2
Name Grupo_Falla: '[14]Listas Desplegables'!$CH$2:$CH$5
Name Grupo_Falla: '[15]Listas Desplegables'!$CH$2:$CH$5
Name inconservmanager: '[16]Listas desplegables'!$BC$2:$BC$100
Name inconservmanager: '[4]Listas desplegables'!$BC$2:$BC$100
Name INCUMPLIMIENTO: '[4]Listas desplegables'!$AK$1:$AN$1
Name INCUMPLIMIENTO: '[17]Listas desplegables'!$AT$1:$AX$1
Name LISTA: [18]Dptos!$A$1139:$A$1171
Name LISTA: [19]Dptos!$A$1139:$A$1171
Name LISTA2: #REF!
Name LISTA2: [20]Hoja3!$A$1:$A$26
Name LOLO: [21]Coordinadores!$A$2:$A$1000
Name solicitudes: '[11]Listas desplegables'!$U$1:$AF$1
Name solicitudes: '[11]Listas desplegables'!$U$1:$AF$1
Name Tecnicos: [6]Tecnicos!$A$2:$A$1000
Name Tecnicos: [2]Tecnicos!$A$2:$A$1000
Name Version: [22]Formulas!$I$2:$I$3
Name Version: [2]Formulas!$I$2:$I$3

Sheet RESUMEN
A1: =CONCATENATE("TOTAL GENERAL MES ",A3) -> TOTAL GENERAL MES JULIO DE 2025 | J1: FACTURACIÓN CORRESPONSALES BANCARIOS TIQUIETES AEREOS
A2: MES | B2: NIT Proveedor | C2: Nombre Proveedor (el proveedor ya debe estar creado para el Grupo Bancolombia) | D2: Concepto Facturación | E2: Público al que le instalo la publicidad | F2: No. personas impactadas | G2: Valor a Facturar sin IVA | H2: Valor a Facturar con IVA | J2: CONCEPTOS | K2: TRAYECTOS | L2: TOTAL | M2: % Administración | N2: TOTAL
A3: JULIO DE 2025 | B3: 811013990-5 | C3: LINEA COMUNICACIONES S.A.S | D3: INSTALACION PUBLICIDAD APERTURAS CORRESPONSALES BANCARIOS | E3: OPERADOR DEL CORRESPONSAL BANCARIO | F3: =COUNTA('PUBLICIDAD APERTURAS'!A:A)-1 -> 631 | G3: ='PUBLICIDAD APERTURAS'!AE633 -> 1.4140627e+08 | H3: =G3*1.19 -> 1.6827346e+08 | J3: APERTURA CB 79956 | K3: CALI-TIMBIQUI-CALI | L3: 423000 | M3: =L3*0.12 -> 50760 | N3: =L3+M3 -> 473760
A4: =A3 -> JULIO DE 2025 | B4: 811013990-5 | C4: LINEA COMUNICACIONES S.A.S | D4: ORDENES DE CAMBIO POR DEMANDA | E4: OPERADOR DEL CORRESPONSAL BANCARIO | F4: =COUNTA('PUBLICIDAD OC'!A:A)-1 -> 126 | G4: ='PUBLICIDAD OC'!AF128 -> 28898150 | H4: =G4*1.19 -> 34388799 | J4: APERTURA CB 80067 | K4: APARTADO-BAJO BAUDO-APARTADO | L4: 685449 | M4: =L4*0.12 -> 82253.88 | N4: =L4+M4 -> 767702.88
A5: =A4 -> JULIO DE 2025 | B5: 811013990-5 | C5: LINEA COMUNICACIONES S.A.S | D5: TRAYECTOS ESPECIALES OC | E5: OPERADOR DEL CORRESPONSAL BANCARIO | F5: 11 | G5: =N13 -> 6569973.8 | H5: =G5*1.19 -> 7818268.8 | J5: APERTURA CB 80165 - 80166 | K5: MEDELLIN-ISTMINA-MEDELLIN | L5: 529500 | M5: =L5*0.12 -> 63540 | N5: =L5+M5 -> 593040
A6: TOTAL A FACTURAR | F6: =SUM(F3:F5) -> 768 | G6: =SUM(G3:G5) -> 1.7687439e+08 | H6: =SUM(H3:H5) -> 2.1048053e+08 | J6: APERTURA CB 80173 | K6: PASTO-OLAYA HERRERA-PASTO | L6: 300000 | M6: =L6*0.12 -> 36000 | N6: =L6+M6 -> 336000
J7: APERTURA CB 80365 | K7: MEDELLIN-QUIBDO-ME | L7: 292599 | M7: =L7*0.12 -> 35111.88 | N7: =L7+M7 -> 327710.88
J8: APERTURA CB 80455-80490-80382 | K8: MEDELLIN-ISTMINA-MEDELLIN | L8: 786900 | M8: =L8*0.12 -> 94428 | N8: =L8+M8 -> 881328
J9: APERTURA CB 80447 | K9: MEDELLIN-QUIBDO-MEDELLIN | L9: 392850 | M9: =L9*0.12 -> 47142 | N9: =L9+M9 -> 439992
J10: APERTURA CB 80530 | K10: CALI-GUAPI-CALI | L10: 571900 | M10: =L10*0.12 -> 68628 | N10: =L10+M10 -> 640528
J11: APERTURA CB 80541 | K11: TADO-MEDELLIN | L11: 392850 | M11: =L11*0.12 -> 47142 | N11: =L11+M11 -> 439992
J12: ORDEN DE CAMBIO CB 77681 | K12: VILLAVICENCIO-MAPIRIPAN-VILLAVICENCIO | L12: 1491000 | M12: =L12*0.12 -> 178920 | N12: =L12+M12 -> 1669920
J13: TOTAL | L13: =SUM(L3:L12) -> 5866048 | M13: =SUM(M3:M12) -> 703925.76 | N13: =SUM(N3:N12) -> 6569973.8

Sheet BASE DE LIQUIDACION 2025
A1: TARIFAS AÑO 2025 | G1: TARIFAS AÑO 2025 | N1: Incremento 2025
A2: TIPOLOGÍA | B2: Instalación de avisos internos | C2: Instalación de avisos EXTERNOS | D2: Transporte de señalización y aviso de 1,50m x 50 cm. | E2: Total Valor Actividad | G2: ORDENES DE CAMBIO | N2: 0.052
A3: TIPO I | B3: =10695.08*(1+$N$2) -> 11251.224 | C3: =120073.31*(1+$N$2) -> 126317.12 | D3: =54574.12*(1+$N$2) -> 57411.974 | E3: =185342.51*(1+$N$2) -> 194980.32 | G3: Tipificación | H3: Descripción | I3: Dia actividad | J3: Transporte | K3: Envio operador Logistico | L3: Gestión telefónica
A4: TIPO II - TIPO III - TIPO IV | B4: =10695.08*(1+$N$2) -> 11251.224 | C4: =120073.31*(1+$N$2) -> 126317.12 | D4: =105331.06*(1+$N$2) -> 110808.28 | E4: =236099.45*(1+$N$2) -> 248376.62 | G4: Tipo I | H4: Metropolitano | I4: =91255.89*(1+$N$2) -> 96001.196 | J4: =54574.12*(1+$N$2) -> 57411.974 | K4: =53547.34*(1+$N$2) -> 56331.802 | L4: =36031.04*(1+$N$2) -> 37904.654
G5: Tipo II | H5: Hasta 3 horas | I5: =221348.48*(1+$N$2) -> 232858.6 | J5: =105331.06*(1+$N$2) -> 110808.28 | K5: =53547.34*(1+$N$2) -> 56331.802 | L5: =36031.04*(1+$N$2) -> 37904.654
G6: Tipo III | H6: De 3 a 5 horas | I6: =327732.48*(1+$N$2) -> 344774.57 | J6: =105331.06*(1+$N$2) -> 110808.28 | K6: =53547.34*(1+$N$2) -> 56331.802 | L6: =36031.04*(1+$N$2) -> 37904.654
G7: Tipo IV | H7: Más de 5 horas | I7: =521514.86*(1+$N$2) -> 548633.63 | J7: =105331.06*(1+$N$2) -> 110808.28 | K7: =53547.34*(1+$N$2) -> 56331.802 | L7: =36031.04*(1+$N$2) -> 37904.654
G8: Destino Aereo* | H8: Viaje en Avión | I8: =521514.86*(1+$N$2) -> 548633.63 | J8: =105331.06*(1+$N$2) -> 110808.28 | K8: =53547.34*(1+$N$2) -> 56331.802 | L8: =36031.04*(1+$N$2) -> 37904.654
G9: * donde se requiera transporte aéreo o fluvial se factura adicional a tarifa TIPO IV el valor del tiquete + el 12% de admon

Sheet Tabla dinámica
A2: PUBLICIDAD APERTURAS | J2: NOMBRE CC | K2: Suma de VALOR | L2: Suma de VALOR2
A3: COORDINADOR | B3: CENTRO DE COSTOS LÍNEACOM | C3: % | D3: $ | E3: NOMBRE CC | F3: VALOR | J3: Redeban Centro ( Bogotá) | K3: 25583772 | L3: 0.15022377
A4: DIEGO FERNANDO HENAO CARDONA | B4: 0004-0002 | C4: 0.055926092 | D4: 7908299.9 | E4: =VLOOKUP(B4,'CENTRO DE COSTOS'!B:C,2,0) -> Redeban Eje Cafetero (Pereira) | F4: =D4 -> 7908299.9 | J4: Redeban Costa (Barranqullla) | K4: 24724978 | L4: 0.14518107
B5: 0004-0003 | C5: 0.15232589 | D5: 21539836 | E5: =VLOOKUP(B5,'CENTRO DE COSTOS'!B:C,2,0) -> Redeban Suroccidente (Cali) | F5: =D5 -> 21539836 | J5: Redeban Eje Cafetero (Pereira) | K5: 9321202.3 | L5: 0.054732593
A6: JOSE MAURICIO HERNANDEZ ROJAS | B6: 0004-0001 | C6: 0.13380842 | D6: 18921349 | E6: =VLOOKUP(B6,'CENTRO DE COSTOS'!B:C,2,0) -> Redeban Costa (Barranqullla) | F6: =D6 -> 18921349 | J6: Redeban Noroccidente (Medellín) | K6: 25905448 | L6: 0.1521126
A7: JUAN SEBASTIÁN RÍOS CASTRILLÓN | B7: 0004-0005 | C7: 0.14609403 | D7: 20658611 | E7: =VLOOKUP(B7,'CENTRO DE COSTOS'!B:C,2,0) -> Redeban Noroccidente (Medellín) | F7: =D7 -> 20658611 | J7: Redeban Oriente (Otros) | K7: 30795946 | L7: 0.18082881
A8: KEVIN ALEXIS CORZO BUSTOS | B8: 0004-0007 | C8: 0.19281002 | D8: 27264545 | E8: =VLOOKUP(B8,'CENTRO DE COSTOS'!B:C,2,0) -> Redeban Oriente (Otros) | F8: =D8 -> 27264545 | J8: Redeban Santander | K8: 28770277 | L8: 0.16893441
A9: MIGUEL JULIÁN HERNÁNDEZ GUARÍN | B9: 0004-0008 | C9: 0.17098927 | D9: 24178954 | E9: =VLOOKUP(B9,'CENTRO DE COSTOS'!B:C,2,0) -> Redeban Santander | F9: =D9 -> 24178954 | J9: Redeban Suroccidente (Cali) | K9: 25202795 | L9: 0.14798674
A10: WILLIAM ASDRUBAL ROZO ROZO | B10: 0004-0004 | C10: 0.14804629 | D10: 20934673 | E10: =VLOOKUP(B10,'CENTRO DE COSTOS'!B:C,2,0) -> Redeban Centro ( Bogotá) | F10: =D10 -> 20934673 | J10: Total general | K10: 1.7030442e+08 | L10: 1
A11: Total general | C11: 1 | D11: 1.4140627e+08
A21: COORDINADOR | B21: CENTRO DE COSTOS LÍNEACOM | C21: % | D21: $ | E21: NOMBRE CC | F21: VALOR
A22: DIEGO FERNANDO HENAO CARDONA | B22: 0004-0002 | C22: 0.048892486 | D22: 1412902.4 | E22: =VLOOKUP(B22,'CENTRO DE COSTOS'!B:C,2,0) -> Redeban Eje Cafetero (Pereira) | F22: =D22 -> 1412902.4
B23: 0004-0003 | C23: 0.12675411 | D23: 3662959.2 | E23: =VLOOKUP(B23,'CENTRO DE COSTOS'!B:C,2,0) -> Redeban Suroccidente (Cali) | F23: =D23 -> 3662959.2
A24: JOSE MAURICIO HERNANDEZ ROJAS | B24: 0004-0001 | C24: 0.20083045 | D24: 5803628.4 | E24: =VLOOKUP(B24,'CENTRO DE COSTOS'!B:C,2,0) -> Redeban Costa (Barranqullla) | F24: =D24 -> 5803628.4
A25: JUAN SEBASTIÁN RÍOS CASTRILLÓN | B25: 0004-0005 | C25: 0.18156309 | D25: 5246837.3 | E25: =VLOOKUP(B25,'CENTRO DE COSTOS'!B:C,2,0) -> Redeban Noroccidente (Medellín) | F25: =D25 -> 5246837.3
A26: KEVIN ALEXIS CORZO BUSTOS | B26: 0004-0007 | C26: 0.12220161 | D26: 3531400.6 | E26: =VLOOKUP(B26,'CENTRO DE COSTOS'!B:C,2,0) -> Redeban Oriente (Otros) | F26: =D26 -> 3531400.6
A27: MIGUEL JULIÁN HERNÁNDEZ GUARÍN | B27: 0004-0008 | C27: 0.15887947 | D27: 4591322.8 | E27: =VLOOKUP(B27,'CENTRO DE COSTOS'!B:C,2,0) -> Redeban Santander | F27: =D27 -> 4591322.8
A28: WILLIAM ASDRUBAL ROZO ROZO | B28: 0004-0004 | C28: 0.16087879 | D28: 4649099.4 | E28: =VLOOKUP(B28,'CENTRO DE COSTOS'!B:C,2,0) -> Redeban Centro ( Bogotá) | F28: =D28 -> 4649099.4
A29: Total general | C29: 1 | D29: 28898150

Sheet PUBLICIDAD APERTURAS
A1: CIUDAD SEDE | B1: COORDINADOR | C1: CENTRO DE COSTOS LÍNEACOM | D1: CÓDIGO DANE | E1: TA/CODIGO ACTIVIDAD | F1: CODIGO CB | G1: ACTIVIDAD | H1: TIPO DE APERTURA | I1: DEPARTAMENTO | J1: CIUDAD | K1: NOMBRE DEL CB | L1: RED | M1: FO | N1: FECHA LISTA | O1: FECHA ULTIMA ACTUALIZACION | P1: FORMATO | Q1: CADENA | R1: ESTADO | S1: OBSERVACIONES CLIENTE | T1: FORMA DE ATENCIÓN | U1: TERMINALES | V1: TIPIFICACION | W1: TIPO DE TRAYECTO | X1: NOMBRE DEL TECNICO | Y1: FLANGER, DISPLAY LEGAL, DISPLAY CARTA O TABLOIDE | Z1: INSTALACIÓN DE AVISOS EXTERNOS | AA1: TRANSPORTE DE AVISO POR INSTALACION O POR NO INSTALACION (IDA-REGRESO) | AB1: VALOR FLANGER, SEPARADOR, STICKER, DISPLAY | AC1: VALOR INSTALACIÓN DE AVISOS EXTERNOS | AD1: VALOR TRANSPORTE DE AVISO | AE1: VALOR TOTAL INSTALACION DE PUBLICIDAD
A2: MEDELLIN | B2: =VLOOKUP(A2,'CENTRO DE COSTOS'!A:D,4,FALSE) -> JUAN SEBASTIÁN RÍOS CASTRILLÓN | C2: =VLOOKUP(A2,'CENTRO DE COSTOS'!A:D,2,FALSE) -> 0004-0005 | D2: 5091 | E2: TA-25-792913 | F2: 79058 | G2: APERTURA | H2: CB CRECIMIENTO - OTRAS LISTAS | I2: ANTIOQUIA | J2: BETANIA | K2: BARRIO BETANIA ANTIOQUIA BETANIA | L2: REDEBAN | M2: FO-25-1167345 | N2: 45821 | O2: 45842 | P2: UNO A UNO | Q2: UNO A UNO | R2: EJECUTADO | S2: 13-06 SE ESTABLECE COMUNICACIÓN CON EL USUARIO EL CUAL IDNICA QUE EL NECESITA ES UN CORRESPONSAL CON UN CUPO BASTANTES GRANDE, QUE SI EL CORRESPONSAL ES SOLO POR 10 MILLONES NO LE INTERESA - COMUNICACIÓN POR WPP 13/6/2025 ESTE PUNTO FUE ENVIADO EN LA LISTA DE AYER, ME APOYAN POR FAVOR DEJÁNDOLO PENDIENTE HASTA LAS HORAS DE LA TARDE, ES DECIR, NO PROCESEN LA PROGRAMACIÓN, PERO TAMPOCO LO CANCELEN. 19/6/2025 POR FAVOR PROCEDER CON LA IMPLEMENTACIÓN, AGRADEZCO NOS CONFIRMEN CUANDO SE PROGRAME EL PUNTO. 26/6/2025 SE REALIZÓ VISITA NO SE LOGRA INSTALAR YA QUE EL CUPO ASIGNADO ES DE 10 MILLONES EL CB SOLICITO QUE FUERA MÁS ALTO, SE ESCALO TEMA A BANCO Y NO BRINDAN INFORMACIÓN OPORTUNA ADICIONAL NOS INDICA QUE SE DEBE CORREGIR EL CORREO ELECTRÓNICO RDESCOBARARANGO@YAHOO.ES SE POSPONE ACTIVIDAD 4/7/2025 SE REALIZA INSTALACIÓN DE CORRESPONSAL, SE INSTALAN EQUIPOS CON PRUEBAS EXITOSAS, SE CAPACITA Y SE EVALÚA AL CLIENTE, SE INSTALA PUBLICIDAD COMPLETA, CB QUEDA OPERATIVO. USUARIO SOMOS BANCOLOMBIA ACTIVO | T2: VISITA_TÉCNICA | U2: SASZZ633 | V2: TIPO III | W2: TERRESTRE | X2: QUINTERO SANCHEZ JUAN SEBASTIAN | Y2: 1 | Z2: 1 | AA2: 3 | AB2: =IF(V2="TIPO I",'BASE DE LIQUIDACION 2025'!$B$3,'BASE DE LIQUIDACION 2025'!$B$4) -> 11251.224 | AC2: =IF(V2="TIPO I",'BASE DE LIQUIDACION 2025'!$C$3,'BASE DE LIQUIDACION 2025'!$C$4) -> 126317.12 | AD2: =IF(V2="TIPO I",'BASE DE LIQUIDACION 2025'!$D$3,'BASE DE LIQUIDACION 2025'!$D$4) -> 110808.28 | AE2: =AB2*Y2+Z2*AC2+AA2*AD2 -> 469993.17
A3: SANTA MARTA | B3: =VLOOKUP(A3,'CENTRO DE COSTOS'!A:D,4,FALSE) -> JOSE MAURICIO HERNANDEZ ROJAS | C3: =VLOOKUP(A3,'CENTRO DE COSTOS'!A:D,2,FALSE) -> 0004-0001 | D3: 44430 | E3: TA-25-790987 | F3: 79898 | G3: APERTURA | H3: CB CRECIMIENTO ALIANZA - NUEVO | I3: LA GUAJIRA | J3: MAICAO | K3: DISTRICOL COMERCIALIZADORA | L3: REDEBAN | M3: FO-25-1186686 | N3: 45826 | O3: 45843 | P3: AGREGADOR | Q3: DISTRICOL | R3: EJECUTADO | S3: 18-06 PROGRAMACIÓN REALIZADA POR LA ALIANZA 21/6/2025 EN COMUNICACIÓN CON EL SEÑOR FRANCISCO VELÁZQUEZ AL NÚMERO 3003299172, ME INFORMA QUE EL PEAJE ENTRE MAICAO Y RIOHACHA FUE VOLADO POR EL ELN, Y QUE EL SECTOR ESTÁ EN ZONA ROJA POR PROBLEMAS DE ORDEN PÚBLICO , SE REPROGRAMA LA VISITA PARA LA PRÓXIMA SEMANA QUE SE RESTABLEZCA EL ORDEN EN EL SECTOR 26/6/2025 LA ALTERACIÓN AUN CONTINUA POR ESTE MOTIVO NO SE HA PODIDO REALIZAR IMPLEMENTACIÓN 2/7/2025 SE PROGRAMA VISITA PARA EL 04-07 04-07 NO SE LOGRA COMPLETAR LA APERTURA YA QUE EL CLIENTE MANIFIESTA NO TENER DISPOSICIÓN POR COMPROMISO FAMILIAR, QUEDA PENDIENTE LA CAPACITACIÓN ESTÁ QUEDA APLAZADA PARA EL DÍA SÁBADO 5 DE JULIO 5/7/2025 SE REALIZA INSTALACIÓN DE CORRESPONSAL, SE INSTALAN EQUIPOS CON PRUEBAS EXITOSAS, SE CAPACITA Y SE EVALÚA AL CLIENTE, SE INSTALA PUBLICIDAD COMPLETA, CB QUEDA OPERATIVO. USUARIO SOMOS BANCOLOMBIA ACTIVO | T3: VISITA_TÉCNICA | U3: SAUZZ961 | V3: TIPO IV | W3: TERRESTRE | X3: THOMAS CAMPO SIGIFREDO SEGUNDO | Y3: 1 | Z3: 1 | AA3: 3 | AB3: =IF(V3="TIPO I",'BASE DE LIQUIDACION 2025'!$B$3,'BASE DE LIQUIDACION 2025'!$B$4) -> 11251.224 | AC3: =IF(V3="TIPO I",'BASE DE LIQUIDACION 2025'!$C$3,'BASE DE LIQUIDACION 2025'!$C$4) -> 126317.12 | AD3: =IF(V3="TIPO I",'BASE DE LIQUIDACION 2025'!$D$3,'BASE DE LIQUIDACION 2025'!$D$4) -> 110808.28 | AE3: =AB3*Y3+Z3*AC3+AA3*AD3 -> 469993.17
A4: PASTO | B4: =VLOOKUP(A4,'CENTRO DE COSTOS'!A:D,4,FALSE) -> DIEGO FERNANDO HENAO CARDONA | C4: =VLOOKUP(A4,'CENTRO DE COSTOS'!A:D,2,FALSE) -> 0004-0003 | D4: 86568 | E4: TA-25-791021 | F4: 79905 | G4: APERTURA | H4: CB CRECIMIENTO ALIANZA - NUEVO | I4: PUTUMAYO | J4: PUERTO ASIS | K4: DISTRICOL AGROFER Y MAQ ASIS | L4: REDEBAN | M4: FO-25-1108021 | N4: 45826 | O4: 45852 | P4: AGREGADOR | Q4: DISTRICOL | R4: EJECUTADO | S4: 18-06 PROGRAMACIÓN REALIZADA POR LA ALIANZA (POR FAVOR CONTACTAR AL OPERADOR DEL PUNTO DE NOMBRE DANIEL MARCILIA, CEL: 3144338225 TODA VEZ QUE SERÁ LA PERSONA QUE RECIBIRÁ AL TÉCNICO. SE SOLICITA CONTACTO PREFERIBLEMENTE POR WHATSAPP YA QUE LA SEÑAL ES BASTANTE DÉBIL EN LA ZONA DE UBICACIÓN DEL PUNTO ) 20/6/2025 NO ES POSIBLE REALIZAR EL DESPLAZAMIENTO HACIA PUTUMAYO PARA REALIZAR APERTURA EL DIA 20 DE JUNIO, YA QUE DEBIDO A PROBLEMAS EN LA VIA CAIDA DE PUENTE EN EL MUNICIPIO DE COLON SE RESTRINGE EL PASO VEHICULAR HACIA LA ZONA Y NO SE ENCUENTRA TRANSPORTE DISPONIBLE 24/6/2025 LA APERTURA QUE SE MENCIONA A CONTINUACION NO HA SIDO POSIBLE LA REALIZACION YA QUE POR PROBLEMAS EN LA VIA, DERUMBE DE PUENTE HACIA EL MUNICIPIO DE COLON, NO HAY PASO PARA EL DEPARTAMENTO DE PUTUMAYO, SE VALIDO CON LA EMPRESA DE TRANSPORTES PERO ESTA NO ESTABA DESPACHANDO BUSES YA QUE SE ESTABAN QUEDANDO HASTA 12 HORAS EN LA VIA ESPERANDO UN PASO INTERMITENTE POR UNA ZONA PROVISIONAL, POR TANTO SE QUEDA A LA ESPERA DE QUE SE APERTURE LA VIA O SE PUEDE TENER UNA VIA ALTERNA EN CONDICIONES DE DESPLAZAMIENTO. 01-07 SE INTENTO VIAJAR PERO LOS BUSES HACIA LA ZONA NO ESTAN SALIENDO 09-07 SE ENCUENTRA AÚN NOVEDAD EN LA VÍA QUE DEL DEPARTAMENTO DE NARIÑO COMUNICA CON EL DEPARTAMENTO DE PUTUMAYO , YA QUE POR LA CAÍDA DEL PUENTE LA VÍA SE CERRÓ Y SE HABILITO UN PASO ALTERNO QUE DEBIDO AL INVIERNO SOLO ESTÁ PERMITIENDO EL PASO DE VEHÍCULOS LIVIANOS. 14-07 SE REALIZA INSTALACIÓN DE CORRESPONSAL, SE INSTALAN EQUIPOS CON PRUEBAS EXITOSAS, SE CAPACITA Y SE EVALÚA AL CLIENTE, SE INSTALA PUBLICIDAD COMPLETA, CB QUEDA OPERATIVO. USUARIO SOMOS BANCOLOMBIA ACTIV | T4: VISITA_TÉCNICA | U4: SAUZZ979 | V4: TIPO IV | W4: TERRESTRE | X4: ROMERO ROJAS BREIDY JHOHAN | Y4: 1 | Z4: 1 | AA4: 1 | AB4: =IF(V4="TIPO I",'BASE DE LIQUIDACION 2025'!$B$3,'BASE DE LIQUIDACION 2025'!$B$4) -> 11251.224 | AC4: =IF(V4="TIPO I",'BASE DE LIQUIDACION 2025'!$C$3,'BASE DE LIQUIDACION 2025'!$C$4) -> 126317.12 | AD4: =IF(V4="TIPO I",'BASE DE LIQUIDACION 2025'!$D$3,'BASE DE LIQUIDACION 2025'!$D$4) -> 110808.28 | AE4: =AB4*Y4+Z4*AC4+AA4*AD4 -> 248376.62
A5: CALI | B5: =VLOOKUP(A5,'CENTRO DE COSTOS'!A:D,4,FALSE) -> DIEGO FERNANDO HENAO CARDONA | C5: =VLOOKUP(A5,'CENTRO DE COSTOS'!A:D,2,FALSE) -> 0004-0003 | D5: 19809 | E5: TA-25-790617 | F5: 79956 | G5: APERTURA | H5: CB CRECIMIENTO - NUEVO | I5: CAUCA | J5: TIMBIQUI | K5: BARRIO LAS BRISAS TIMBIQUI | L5: REDEBAN | M5: FO-25-1107284 | N5: 45826 | O5: 45841 | P5: UNO A UNO | Q5: UNO A UNO | R5: EJECUTADO | S5: 18-06-2025 SE REALIZA LLAMADA AL CLIENTE, SE HABLA CON LA SRA YOLANDA TORRES PORTOCARRERO SE VALIDA DIRECCIÓN OK, CANAL OK, DISPONIBILIDAD TOTAL, LLAMAR EL DÍA LA INSTALACIÓN PARA CONFIRMAR VISITA, AVISO EXTERIOR ALTURA APROX 2 METROS; TOMACORRIENTE CERCANO: SI; TIENE CABINA DE SEGURIDAD: SI // CONTACTO REALIZADO POR WHATSAPP - ACTIVIDAD PROGRAMADA PARA DICHA FECHA POR TRANSPORTE 1/7/2025 SE REALIZARA VISITA DE APERTURA EL DIA 3 DE JULIO DADO NO SE LOGRA CONSEGUIR VUELO PARA ANTES 4/7/2025 SE REALIZA INSTALACIÓN DE CORRESPONSAL, SE INSTALAN EQUIPOS CON PRUEBAS EXITOSAS, SE CAPACITA Y SE EVALÚA AL CLIENTE, SE INSTALA PUBLICIDAD COMPLETA, CB QUEDA OPERATIVO. USUARIO SOMOS BANCOLOMBIA ACTIVO | T5: VISITA_TÉCNICA | U5: SAVZZ118 | V5: TIPO IV ESPECIAL | W5: AEREO | X5: PAREDES CASTILLO DIEGO | Y5: 1 | Z5: 1 | AA5: 1 | AB5: =IF(V5="TIPO I",'BASE DE LIQUIDACION 2025'!$B$3,'BASE DE LIQUIDACION 2025'!$B$4) -> 11251.224 | AC5: =IF(V5="TIPO I",'BASE DE LIQUIDACION 2025'!$C$3,'BASE DE LIQUIDACION 2025'!$C$4) -> 126317.12 | AD5: =IF(V5="TIPO I",'BASE DE LIQUIDACION 2025'!$D$3,'BASE DE LIQUIDACION 2025'!$D$4) -> 110808.28 | AE5: =AB5*Y5+Z5*AC5+AA5*AD5 -> 248376.62
A6: VILLAVICENCIO | B6: =VLOOKUP(A6,'CENTRO DE COSTOS'!A:D,4,FALSE) -> KEVIN ALEXIS CORZO BUSTOS | C6: =VLOOKUP(A6,'CENTRO DE COSTOS'!A:D,2,FALSE) -> 0004-0007 | D6: 95001 | E6: TA-25-799127 | F6: 80059 | G6: APERTURA | H6: CB CRECIMIENTO - NUEVO | I6: GUAVIARE | J6: SAN JOSE DEL GUAVIARE | K6: BARRIO EL PORVENIR SAN JOSE DEL GUAVIARE 4 | L6: REDEBAN | M6: FO-25-1128664 | N6: 45832 | O6: 45839 | P6: UNO A UNO | Q6: UNO A UNO | R6: EJECUTADO | S6: 21-06 SE REALIZA LLAMADA AL CLIENTE, SE HABLA CON LA SRA CLAUDIA FERNANDA PERDOMO GONZALEZ, SE VALIDA DIRECCIÓN OK, CANAL OK, DISPONIBILIDAD TOTAL, LLAMAR EL DÍA LA INSTALACIÓN PARA CONFIRMAR VISITA, AVISO EXTERIOR ALTURA APROX DONDE EL TECNICO LO VEA CONVENIENTE; TOMACORRIENTE CERCANO:SI; TIENE CABINA DE SEGURIDAD:NO// MODEM NO TIENE PUERTOS DISPONIBLES 26-6 EN COMUNICACIÓN CON EL USUARIO INDICA QUE NOS ATIENDE EL DIA MARTES POR QUE AUN ESTA ADECUANDO EL LOCAL 1/7/2025 SE REALIZA INSTALACIÓN DE CORRESPONSAL, SE INSTALAN EQUIPOS CON PRUEBAS EXITOSAS, SE CAPACITA Y SE EVALÚA AL CLIENTE, SE INSTALA PUBLICIDAD COMPLETA, CB QUEDA OPERATIVO. USUARIO SOMOS BANCOLOMBIA ACTIVO. SE INSTAAN 15 MT DE CABLE UTP | T6: VISITA_TÉCNICA | U6: SAXZZ468 | V6: TIPO IV | W6: TERRESTRE | X6: PEDREROS CONTRERAS MICHAEL STEVENS | Y6: 1 | Z6: 1 | AA6: 1 | AB6: =IF(V6="TIPO I",'BASE DE LIQUIDACION 2025'!$B$3,'BASE DE LIQUIDACION 2025'!$B$4) -> 11251.224 | AC6: =IF(V6="TIPO I",'BASE DE LIQUIDACION 2025'!$C$3,'BASE DE LIQUIDACION 2025'!$C$4) -> 126317.12 | AD6: =IF(V6="TIPO I",'BASE DE LIQUIDACION 2025'!$D$3,'BASE DE LIQUIDACION 2025'!$D$4) -> 110808.28 | AE6: =AB6*Y6+Z6*AC6+AA6*AD6 -> 248376.62
A7: PEREIRA | B7: =VLOOKUP(A7,'CENTRO DE COSTOS'!A:D,4,FALSE) -> DIEGO FERNANDO HENAO CARDONA | C7: =VLOOKUP(A7,'CENTRO DE COSTOS'!A:D,2,FALSE) -> 0004-0002 | D7: 66318 | E7: TA-25-799134 | F7: 80021 | G7: APERTURA | H7: CB CRECIMIENTO - NUEVO | I7: RISARALDA | J7: GUATICA | K7: BARRIO CENTRO GUATICA 4 | L7: REDEBAN | M7: FO-25-1158501 | N7: 45832 | O7: 45847 | P7: UNO A UNO | Q7: UNO A UNO | R7: EJECUTADO | S7: 24-06-2025 SE REALIZA LLAMADA AL CLIENTE, SE HABLA CON LA SRA ZHARICK QUINTERO TABARES SE VALIDA DIRECCIÓN OK, CANAL OK, DISPONIBILIDAD TOTAL, LLAMAR EL DÍA LA INSTALACIÓN PARA CONFIRMAR VISITA, AVISO EXTERIOR ALTURA APROX 3 METROS; TOMACORRIENTE CERCANO: SI; TIENE CABINA DE SEGURIDAD: SI // CONTACTO REALIZADO POR LA APP 27/6/2025 SE REALIZA VISITA DE APERTURA AL CB UNO A UNO CON CÓDIGO 3007080021 BARRIO CENTRO GUATICA 44, DIRECCIÓN CR 5 12 32 , COORDENADAS 5.315427, -75.798033, PERO SE ENCUENTRA CERCANÍA CON CORRESPONSAL DISTRICOL INSTALADO CON CÓDIGO 3007070765 DISTRICOL UNIVERSO ESCOLAR , DIRECCIÓN CL 13 12 66, COORDENADAS 5.315486, -75.797833, QUEDANDO A MENOS DE 25 MTS DE DISTANCIA UNO DEL OTRO A DOS CASAS EN LA MISMA CUADRA, SE REALIZA ESCALAMIENTO POR CERCANÍA EN ESPERA DE COMO PROCEDER. / ENTIDAD APRUEBA INSTALACIÓN 9/7/2025 SE REALIZA INSTALACIÓN DE CORRESPONSAL, SE INSTALAN EQUIPOS CON PRUEBAS EXITOSAS, SE CAPACITA Y SE EVALÚA AL CLIENTE, SE INSTALA PUBLICIDAD COMPLETA, CB QUEDA OPERATIVO. USUARIO SOMOS BANCOLOMBIA ACTIVO | T7: VISITA_TÉCNICA | U7: SAXZZ471 | V7: TIPO II | W7: TERRESTRE | X7: ARROYAVE CANO MANUEL GUILLERMO | Y7: 1 | Z7: 1 | AA7: 3 | AB7: =IF(V7="TIPO I",'BASE DE LIQUIDACION 2025'!$B$3,'BASE DE LIQUIDACION 2025'!$B$4) -> 11251.224 | AC7: =IF(V7="TIPO I",'BASE DE LIQUIDACION 2025'!$C$3,'BASE DE LIQUIDACION 2025'!$C$4) -> 126317.12 | AD7: =IF(V7="TIPO I",'BASE DE LIQUIDACION 2025'!$D$3,'BASE DE LIQUIDACION 2025'!$D$4) -> 110808.28 | AE7: =AB7*Y7+Z7*AC7+AA7*AD7 -> 469993.17
A8: APARTADO | B8: =VLOOKUP(A8,'CENTRO DE COSTOS'!A:D,4,FALSE) -> JUAN SEBASTIÁN RÍOS CASTRILLÓN | C8: =VLOOKUP(A8,'CENTRO DE COSTOS'!A:D,2,FALSE) -> 0004-0005 | D8: 27077 | E8: TA-25-799154 | F8: 80067 | G8: APERTURA | H8: CB CRECIMIENTO - NUEVO | I8: CHOCO | J8: BAJO BAUDO | K8: BARRIO EL SILENCIO BAJO BAUDO PIZARRO BAJO BAUDO | L8: REDEBAN | M8: FO-25-1128775 | N8: 45832 | O8: 45841 | P8: UNO A UNO | Q8: UNO A UNO | R8: EJECUTADO | S8: 24-06 SE REALIZA LLAMADA AL CLIENTE, SE HABLA CON LA SR KEYNER ESTIVEN IBARGUEN MINA SE VALIDA DIRECCIÓN OK, CANAL OK, DISPONIBILIDAD TOTAL, LLAMAR EL DÍA LA INSTALACIÓN PARA CONFIRMAR VISITA, AVISO EXTERIOR ALTURA APROX 2 METROS; TOMACORRIENTE CERCANO: SI; TIENE CABINA DE SEGURIDAD: SI 03-07 SE REALIZA INSTALACIÓN DE CORRESPONSAL, SE INSTALAN EQUIPOS CON PRUEBAS EXITOSAS, SE CAPACITA Y SE EVALÚA AL CLIENTE, SE INSTALA PUBLICIDAD COMPLETA, CB QUEDA OPERATIVO. USUARIO SOMOS BANCOLOMBIA ACTIVO | T8: VISITA_TÉCNICA | U8: SAXZZ488 | V8: TIPO IV ESPECIAL | W8: AEREO | X8: ROBLEDO DIAZ ANDRES FELIPE | Y8: 1 | Z8: 1 | AA8: 1 | AB8: =IF(V8="TIPO I",'BASE DE LIQUIDACION 2025'!$B$3,'BASE DE LIQUIDACION 2025'!$B$4) -> 11251.224 | AC8: =IF(V8="TIPO I",'BASE DE LIQUIDACION 2025'!$C$3,'BASE DE LIQUIDACION 2025'!$C$4) -> 126317.12 | AD8: =IF(V8="TIPO I",'BASE DE LIQUIDACION 2025'!$D$3,'BASE DE LIQUIDACION 2025'!$D$4) -> 110808.28 | AE8: =AB8*Y8+Z8*AC8+AA8*AD8 -> 248376.62
A9: PASTO | B9: =VLOOKUP(A9,'CENTRO DE COSTOS'!A:D,4,FALSE) -> DIEGO FERNANDO HENAO CARDONA | C9: =VLOOKUP(A9,'CENTRO DE COSTOS'!A:D,2,FALSE) -> 0004-0003 | D9: 52317 | E9: TA-25-799157 | F9: 80019 | G9: APERTURA | H9: CB CRECIMIENTO - NUEVO | I9: NARIÑO | J9: GUACHUCAL | K9: BARRIO CRR DE MIRAFLORES GUACHUCAL | L9: REDEBAN | M9: FO-25-1128785 | N9: 45832 | O9: 45839 | P9: UNO A UNO | Q9: UNO A UNO | R9: EJECUTADO | S9: 24-06 SE REALIZA LLAMADA AL CLIENTE, SE HABLA CON LA SR ARLEY ALEXANDER NARVAEZ CORTES SE VALIDA DIRECCIÓN OK, DISPONIBILIDAD TOTAL, LLAMAR EL DÍA LA INSTALACIÓN PARA CONFIRMAR VISITA, AVISO EXTERIOR ALTURA APROX 1.50 METROS; TOMA CORRIENTE CERCANO: SI; TIENE CABINA DE SEGURIDAD: SI , USUARIO INDICA QUE SE EL MODEN SE ENCUENTRA 5 METROS 26-06 POR MOTIVOS DE CIERRE DE LA VIA HACIA LA ZONA NO SE PUEDE REALIZAR DESPLAZAMIENTO HASTA EL SITIO POR LO CUAL SE DEBE REPROGRAMAR LA ACTIVIDAD PARA EL DÍA LUNES QUE YA SE NORMALICE EL TRANSPORTE HACIA EL LUGAR 1/7/2025 SE REALIZA INSTALACIÓN DE CORRESPONSAL, SE INSTALAN EQUIPOS CON PRUEBAS EXITOSAS, SE CAPACITA Y SE EVALÚA AL CLIENTE, SE INSTALA PUBLICIDAD COMPLETA, CB QUEDA OPERATIVO. USUARIO SOMOS BANCOLOMBIA ACTIVO | T9: VISITA_TÉCNICA | U9: SAXZZ491 | V9: TIPO II | W9: TERRESTRE | X9: PAZ MARTINEZ RICHARD HUMBERTO | Y9: 1 | Z9: 1 | AA9: 1 | AB9: =IF(V9="TIPO I",'BASE DE LIQUIDACION 2025'!$B$3,'BASE DE LIQUIDACION 2025'!$B$4) -> 11251.224 | AC9: =IF(V9="TIPO I",'BASE DE LIQUIDACION 2025'!$C$3,'BASE DE LIQUIDACION 2025'!$C$4) -> 126317.12 | AD9: =IF(V9="TIPO I",'BASE DE LIQUIDACION 2025'!$D$3,'BASE DE LIQUIDACION 2025'!$D$4) -> 110808.28 | AE9: =AB9*Y9+Z9*AC9+AA9*AD9 -> 248376.62
A10: BOGOTA | B10: =VLOOKUP(A10,'CENTRO DE COSTOS'!A:D,4,FALSE) -> WILLIAM ASDRUBAL ROZO ROZO | C10: =VLOOKUP(A10,'CENTRO DE COSTOS'!A:D,2,FALSE) -> 0004-0004 | D10: 25181 | E10: TA-25-799210 | F10: 80024 | G10: APERTURA | H10: CAMBIO DE RAZON SOCIAL | I10: CUNDINAMARCA | J10: CHOACHI | K10: BARRIO LAS PALMAS CHOACHÍ | L10: REDEBAN | M10: FO-25-1128955 | N10: 45832 | O10: 45839 | P10: UNO A UNO | Q10: UNO A UNO | R10: EJECUTADO | S10: 24-06 SE REALIZA LLAMADA AL CLIENTE, SE HABLA CON LA SRA NIDIA CAMILA BORBON RODRIGUEZ, SE VALIDA DIRECCIÓN OK, CANAL OK, DISPONIBILIDAD TOTAL, LLAMAR EL DÍA LA INSTALACIÓN PARA CONFIRMAR VISITA, AVISO EXTERIOR ALTURA APROX DONDE EL TECNICO LO VEA CONVENIENTE; TOMACORRIENTE CERCANO: SI; TIENE CABINA DE SEGURIDAD: NO 25-06 25-06 EN COMUNICACIÓN CON EL COMERCIO AL # 3115056967 LA SRA NIDIA PARA ADELANTAR APERTURA PARA EL DÍA DE MAÑANA 26-06-2025, SIN NOVEDAD / NUEVAMENTE EN COMUNICACIÓN CON EL COMERCIO AL # 3115056967 LA SRA NIDIA MANIFIESTA QUE NO PUEDE RECIBIR LA INSTALACIÓN EL DÍA 26 NI 27 DE JUNIO, PIDE SEA REPROGRAMADA PARA EL DÍA 01 Ó 02 DE JULIO YA QUE DEBE HACER CIERRE DEL COMERCIO EXISTENTE. 1/7/2025 SE REALIZA INSTALACIÓN DE CORRESPONSAL, SE INSTALAN EQUIPOS CON PRUEBAS EXITOSAS, SE CAPACITA Y SE EVALÚA AL CLIENTE, SE INSTALA PUBLICIDAD COMPLETA, CB QUEDA OPERATIVO. USUARIO SOMOS BANCOLOMBIA ACTIVO | T10: VISITA_TÉCNICA | U10: SAXZZ523 | V10: TIPO II | W10: TERRESTRE | X10: BUSTOS MORA DIEGO MANUEL | Y10: 1 | Z10: 1 | AA10: 1 | AB10: =IF(V10="TIPO I",'BASE DE LIQUIDACION 2025'!$B$3,'BASE DE LIQUIDACION 2025'!$B$4) -> 11251.224 | AC10: =IF(V10="TIPO I",'BASE DE LIQUIDACION 2025'!$C$3,'BASE DE LIQUIDACION 2025'!$C$4) -> 126317.12 | AD10: =IF(V10="TIPO I",'BASE DE LIQUIDACION 2025'!$D$3,'BASE DE LIQUIDACION 2025'!$D$4) -> 110808.28 | AE10: =AB10*Y10+Z10*AC10+AA10*AD10 -> 248376.62
A11: PASTO | B11: =VLOOKUP(A11,'CENTRO DE COSTOS'!A:D,4,FALSE) -> DIEGO FERNANDO HENAO CARDONA | C11: =VLOOKUP(A11,'CENTRO DE COSTOS'!A:D,2,FALSE) -> 0004-0003 | D11: 52696 | E11: TA-25-799256 | F11: 80061 | G11: APERTURA | H11: CB CRECIMIENTO - NUEVO | I11: NARIÑO | J11: SANTA BARBARA | K11: BARRIO LOS ANGELES SANTA BARBARA | L11: REDEBAN | M11: FO-25-1129108 | N11: 45832 | O11: 45846 | P11: UNO A UNO | Q11: UNO A UNO | R11: EJECUTADO | S11: 24-06 SE REALIZA LLAMADA AL CLIENTE, SE HABLA CON LA SR ALBERS ANDRES MARTINEZ CABALLERO SE VALIDA DIRECCIÓN OK, CANAL OK, DISPONIBILIDAD TOTAL, LLAMAR EL DÍA LA INSTALACIÓN PARA CONFIRMAR VISITA, AVISO EXTERIOR ALTURA APROX 2 METROS; TOMACORRIENTE CERCANO: SI; TIENE CABINA DE SEGURIDAD: NO 04-07 DEBIDO A QUE SE DEBE TOMAR TRANSPORTE FLUVIAL NO ES POSIBLE REALIZAR LA VISITA EL DIA DE HOY PUES NO SE LOGRA CONSEGUIR DESPLAZAMIENTO , SE REALIZARA DESPLAZAMIENTO LA PRÓXIMA SEMANA PARA VALIDAR SI SE CONSIGUE LANCHA PARA EL SITIO 08-07 SE REALIZA INSTALACIÓN DE CORRESPONSAL, SE INSTALAN EQUIPOS CON PRUEBAS EXITOSAS, SE CAPACITA Y SE EVALÚA AL CLIENTE, SE INSTALA PUBLICIDAD COMPLETA, CB QUEDA OPERATIVO. USUARIO SOMOS BANCOLOMBIA ACTIVO | T11: VISITA_TÉCNICA | U11: SAXZZ549 | V11: TIPO IV ESPECIAL | W11: TERRESTRE/FLUVIAL | X11: PAZ MARTINEZ RICHARD HUMBERTO | Y11: 1 | Z11: 1 | AA11: 1 | AB11: =IF(V11="TIPO I",'BASE DE LIQUIDACION 2025'!$B$3,'BASE DE LIQUIDACION 2025'!$B$4) -> 11251.224 | AC11: =IF(V11="TIPO I",'BASE DE LIQUIDACION 2025'!$C$3,'BASE DE LIQUIDACION 2025'!$C$4) -> 126317.12 | AD11: =IF(V11="TIPO I",'BASE DE LIQUIDACION 2025'!$D$3,'BASE DE LIQUIDACION 2025'!$D$4) -> 110808.28 | AE11: =AB11*Y11+Z11*AC11+AA11*AD11 -> 248376.62
A12: MANIZALES | B12: =VLOOKUP(A12,'CENTRO DE COSTOS'!A:D,4,FALSE) -> DIEGO FERNANDO HENAO CARDONA | C12: =VLOOKUP(A12,'CENTRO DE COSTOS'!A:D,2,FALSE) -> 0004-0002 | D12: 17001 | E12: TA-25-803977 | F12: 80103 | G12: APERTURA | H12: CB CRECIMIENTO ALIANZA - NUEVO | I12: CALDAS | J12: MANIZALES | K12: DISTRICOL TIENDA PLAN B | L12: REDEBAN | M12: FO-25-1138942 | N12: 45834 | O12: 45839 | P12: AGREGADOR | Q12: DISTRICOL | R12: EJECUTADO | S12: 26-06 PROGRAMACIÓN REALIZADA POR LA ALIANZA 1/7/2025 SE REALIZA INSTALACIÓN DE CORRESPONSAL, SE INSTALAN EQUIPOS CON PRUEBAS EXITOSAS, SE CAPACITA Y SE EVALÚA AL CLIENTE, SE INSTALA PUBLICIDAD COMPLETA, CB QUEDA OPERATIVO. USUARIO SOMOS BANCOLOMBIA ACTIVO | T12: VISITA_TÉCNICA | U12: V1ZZZ953 | V12: TIPO I | W12: TERRESTRE | X12: ARROYAVE CANO MANUEL GUILLERMO | Y12: 1 | Z12: 1 | AA12: 1 | AB12: =IF(V12="TIPO I",'BASE DE LIQUIDACION 2025'!$B$3,'BASE DE LIQUIDACION 2025'!$B$4) -> 11251.224 | AC12: =IF(V12="TIPO I",'BASE DE LIQUIDACION 2025'!$C$3,'BASE DE LIQUIDACION 2025'!$C$4) -> 126317.12 | AD12: =IF(V12="TIPO I",'BASE DE LIQUIDACION 2025'!$D$3,'BASE DE LIQUIDACION 2025'!$D$4) -> 57411.974 | AE12: =AB12*Y12+Z12*AC12+AA12*AD12 -> 194980.32
A13: NEIVA | B13: =VLOOKUP(A13,'CENTRO DE COSTOS'!A:D,4,FALSE) -> KEVIN ALEXIS CORZO BUSTOS | C13: =VLOOKUP(A13,'CENTRO DE COSTOS'!A:D,2,FALSE) -> 0004-0007 | D13: 18753 | E13: TA-25-803980 | F13: 80108 | G13: APERTURA | H13: CB CRECIMIENTO ALIANZA - NUEVO | I13: CAQUETA | J13: SAN VICENTE DEL CAGUAN | K13: DISTRICOL GUACAMAYAS.NET | L13: REDEBAN | M13: FO-25-1138951 | N13: 45834 | O13: 45842 | P13: AGREGADOR | Q13: DISTRICOL | R13: EJECUTADO | S13: 26-06 PROGRAMACIÓN REALIZADA POR LA ALIANZA 4/7/2025 SE REALIZA INSTALACIÓN DE CORRESPONSAL, SE INSTALAN EQUIPOS CON PRUEBAS EXITOSAS, SE CAPACITA Y SE EVALÚA AL CLIENTE, SE INSTALA PUBLICIDAD COMPLETA, CB QUEDA OPERATIVO. USUARIO SOMOS BANCOLOMBIA ACTIVO | T13: VISITA_TÉCNICA | U13: V1ZZZ954 | V13: TIPO IV ESPECIAL | W13: TERRESTRE / AEREO | X13: BERMUDEZ SANCHEZ JOSE NEYBER | Y13: 1 | Z13: 1 | AA13: 1 | AB13: =IF(V13="TIPO I",'BASE DE LIQUIDACION 2025'!$B$3,'BASE DE LIQUIDACION 2025'!$B$4) -> 11251.224 | AC13: =IF(V13="TIPO I",'BASE DE LIQUIDACION 2025'!$C$3,'BASE DE LIQUIDACION 2025'!$C$4) -> 126317.12 | AD13: =IF(V13="TIPO I",'BASE DE LIQUIDACION 2025'!$D$3,'BASE DE LIQUIDACION 2025'!$D$4) -> 110808.28 | AE13: =AB13*Y13+Z13*AC13+AA13*AD13 -> 248376.62
... A632: MONTERIA | B632: =VLOOKUP(A632,'CENTRO DE COSTOS'!A:D,4,FALSE) -> JOSE MAURICIO HERNANDEZ ROJAS | C632: =VLOOKUP(A632,'CENTRO DE COSTOS'!A:D,2,FALSE) -> 0004-0001 | D632: 23001 | E632: TA-25-904099 | F632: 80741 | G632: APERTURA | H632: CB CRECIMIENTO - NUEVO | I632: CORDOBA | J632: MONTERIA | K632: BARRIO VILLA ROCIO MONTERIA 1 | L632: REDEBAN | M632: FO-25-1305089 | N632: 45868 | O632: 45869 | P632: UNO A UNO | Q632: UNO A UNO | R632: EJECUTADO/CANCELADO | S632: 30-07-2025 SE REALIZA LLAMADA AL CLIENTE, SE HABLA CON EL SR EXNEIDER ANTONIO HERRERA NARVAEZ, VALIDA DIRECCIÓN OK, CANAL OK, DISPONIBILIDAD TOTAL, LLAMAR EL DÍA LA INSTALACIÓN PARA CONFIRMAR VISITA, AVISO EXTERIOR ALTURA APROX 2 METROS; TOMACORRIENTE CERCANO: SI; TIENE CABINA DE SEGURIDAD: NO 31/07/2025 INSTALACIÓN FALLIDA, SE LLEGÓ HASTA LA DIRECCIÓN Y EL LOCAL COMERCIAL TIENE UN NOMBRE DIFERENTE AL QUE SE RELACIONA EN LA LISTA DE CHEQUEO, SE ESCALÓ EL CASO A RBM Y SE LE INFORMA AL CLIENTE QUE DEBE ACTUALIZAR LA CÁMARA DE COMERCIO CON EL NOMBRE ACTUAL Y ESTE INFORMA QUE NO VA A REALIZAR EL PROCESO PORQUE LE GENERA GASTOS, ADICIONAL INFORMA QUE NO TIENE LA PERSONA PARA QUE LE ATIENDA EL CB Y DEBE CONTRATAR INTERNET Y ES COSTOSO. | T632: VISITA_TÉCNICA | U632: VAZZZ387 | V632: TIPO I | W632: TERRESTRE | X632: CALDERA SALCEDO CARLOS JULIO | Y632: 0 | Z632: 0 | AA632: 2 | AB632: =IF(V632="TIPO I",'BASE DE LIQUIDACION 2025'!$B$3,'BASE DE LIQUIDACION 2025'!$B$4) -> 11251.224 | AC632: =IF(V632="TIPO I",'BASE DE LIQUIDACION 2025'!$C$3,'BASE DE LIQUIDACION 2025'!$C$4) -> 126317.12 | AD632: =IF(V632="TIPO I",'BASE DE LIQUIDACION 2025'!$D$3,'BASE DE LIQUIDACION 2025'!$D$4) -> 57411.974 | AE632: =AB632*Y632+Z632*AC632+AA632*AD632 -> 114823.95
AE633: =SUM(AE2:AE632) -> 1.4140627e+08

Sheet PUBLICIDAD OC
A1: CIUDAD SEDE | B1: COORDINADOR | C1: CENTRO DE COSTOS LÍNEACOM | D1: CÓDIGO DANE | E1: TA/CODIGO ACTIVIDAD | F1: CODIGO CB | G1: ACTIVIDAD | H1: DEPARTAMENTO | I1: CIUDAD | J1: NOMBRE DEL CB | K1: RED | L1: FO | M1: FECHA ASIGNACION A LINEA COMUNICACIONES | N1: FECHA DEL CIERRE DEL TICKET (DD/MM/AAAA) | O1: ACOMETIDA | P1: SOLICITUD | Q1: DESCRIPCIÓN | R1: FORMATO | S1: CADENA | T1: ESTADO | U1: CAUSAL ESTADO | V1: OBSERVACION | W1: FORMA DE ATENCIÓN | X1: TERMINAL | Y1: TIPIFICACION | Z1: TIPO DE TRAYECTO | AA1: NOMBRE DEL TECNICO | AB1: DIAS DE VISITA | AC1: TRANSPORTE AVISO EXTERIOR | AD1: VALOR ACTIVIDAD | AE1: VALOR TRANSPORTE AVISO | AF1: VALOR TOTAL INSTALACION DE PUBLICIDAD
A2: MONTERIA | B2: =VLOOKUP(A2,'CENTRO DE COSTOS'!A:D,4,FALSE) -> JOSE MAURICIO HERNANDEZ ROJAS | C2: =VLOOKUP(A2,'CENTRO DE COSTOS'!A:D,2,FALSE) -> 0004-0001 | D2: 23682 | E2: 2352579 | F2: 37678 | G2: ORDEN DE CAMBIO | H2: CORDOBA | I2: SAN JOSE DE URE | J2: DISTRICOL FERRETERIA E INSUMOS | K2: REDEBAN | L2: FO-25-1133393 | M2: 45833.447 | N2: 45839.54 | P2: PUBLICIDAD | Q2: AVISO EXTERIOR | R2: AGREGADOR | S2: DISTRICOL | T2: EJECUTADO_EXITOSO | U2: EJECUTADO EXITOSO | V2: SE COMUNICA CB SR(A)JOSE, PARA SOLICITAR EL AVISO EXTERIOR YA QUE SE LE DAÑO 0 01/07/2025 SE INSTALA AVISO EXTERNO, CB INDICA QUE NUNCA INSTALARON OK. CERRAR | W2: VISITA_TÉCNICA | X2: 0 | Y2: TIPO III | Z2: TERRESTRE | AA2: COGOLLO VERTEL EDER LUIS | AB2: 1 | AC2: 1 | AD2: =IF(OR(W2="SOPORTE_TELEFÓNICO",W2="ENVÍO"),0,IF(Y2="TIPO I",'BASE DE LIQUIDACION 2025'!$I$4,IF(Y2="TIPO II",'BASE DE LIQUIDACION 2025'!$I$5,IF(Y2="TIPO III",'BASE DE LIQUIDACION 2025'!$I$6,IF(Y2="TIPO IV",'BASE DE LIQUIDACION 2025'!$I$7,'BASE DE LIQUIDACION 2025'!$I$8))))) -> 344774.57 | AE2: =IF(OR(W2="SOPORTE_TELEFÓNICO",W2="ENVÍO"),0,IF(Y2="TIPO I",'BASE DE LIQUIDACION 2025'!$J$4,IF(Y2="TIPO II",'BASE DE LIQUIDACION 2025'!$J$5,IF(Y2="TIPO III",'BASE DE LIQUIDACION 2025'!$J$6,IF(Y2="TIPO IV",'BASE DE LIQUIDACION 2025'!$J$7,'BASE DE LIQUIDACION 2025'!$J$8))))) -> 110808.28 | AF2: =IF(W2="SOPORTE_TELEFÓNICO",'BASE DE LIQUIDACION 2025'!$L$4,IF(W2="ENVÍO",'BASE DE LIQUIDACION 2025'!$K$4,AD2*AB2+AE2*AC2)) -> 455582.84
A3: MEDELLIN | B3: =VLOOKUP(A3,'CENTRO DE COSTOS'!A:D,4,FALSE) -> JUAN SEBASTIÁN RÍOS CASTRILLÓN | C3: =VLOOKUP(A3,'CENTRO DE COSTOS'!A:D,2,FALSE) -> 0004-0005 | D3: 5360 | E3: 2353671 | F3: 58298 | G3: ORDEN DE CAMBIO | H3: ANTIOQUIA | I3: ITAGUI | J3: BARRIO SANTA MARIA ITAGUI 8 | K3: REDEBAN | L3: FO-25-1134419 | M3: 45833.553 | N3: 45839.548 | P3: PUBLICIDAD | Q3: AVISO EXTERIOR | R3: CB UNO A UNO | S3: CB UNO A UNO | T3: EJECUTADO_EXITOSO | U3: EJECUTADO EXITOSO | V3: SE COMUNICA CB SR(A) GINA PARA SOLICITAR AVISO EXTERIOR EL QUE TENIA SE LE ROMPIÓ 01/07/2025 CLIENTE ABRE A LAS 10 01/07/2025 SE INSTALA AVISO EXTERIOR CERRAR | W3: VISITA_TÉCNICA | X3: 0 | Y3: TIPO I | Z3: TERRESTRE | AA3: MORENO MEDINA JUAN PABLO | AB3: 1 | AC3: 1 | AD3: =IF(OR(W3="SOPORTE_TELEFÓNICO",W3="ENVÍO"),0,IF(Y3="TIPO I",'BASE DE LIQUIDACION 2025'!$I$4,IF(Y3="TIPO II",'BASE DE LIQUIDACION 2025'!$I$5,IF(Y3="TIPO III",'BASE DE LIQUIDACION 2025'!$I$6,IF(Y3="TIPO IV",'BASE DE LIQUIDACION 2025'!$I$7,'BASE DE LIQUIDACION 2025'!$I$8))))) -> 96001.196 | AE3: =IF(OR(W3="SOPORTE_TELEFÓNICO",W3="ENVÍO"),0,IF(Y3="TIPO I",'BASE DE LIQUIDACION 2025'!$J$4,IF(Y3="TIPO II",'BASE DE LIQUIDACION 2025'!$J$5,IF(Y3="TIPO III",'BASE DE LIQUIDACION 2025'!$J$6,IF(Y3="TIPO IV",'BASE DE LIQUIDACION 2025'!$J$7,'BASE DE LIQUIDACION 2025'!$J$8))))) -> 57411.974 | AF3: =IF(W3="SOPORTE_TELEFÓNICO",'BASE DE LIQUIDACION 2025'!$L$4,IF(W3="ENVÍO",'BASE DE LIQUIDACION 2025'!$K$4,AD3*AB3+AE3*AC3)) -> 153413.17
A4: MEDELLIN | B4: =VLOOKUP(A4,'CENTRO DE COSTOS'!A:D,4,FALSE) -> JUAN SEBASTIÁN RÍOS CASTRILLÓN | C4: =VLOOKUP(A4,'CENTRO DE COSTOS'!A:D,2,FALSE) -> 0004-0005 | D4: 5001 | E4: 2355189 | F4: 46636 | G4: ORDEN DE CAMBIO | H4: ANTIOQUIA | I4: MEDELLIN | J4: BARRIO BELENCITO CORAZON MEDEL | K4: REDEBAN | L4: FO-25-1135724 | M4: 45833.669 | N4: 45839.565 | P4: PUBLICIDAD | Q4: AVISO EXTERIOR | R4: CB UNO A UNO | S4: CB UNO A UNO | T4: EJECUTADO_CANCELADO | U4: PETICIÓN BANCOLOMBIA | V4: SE COMUNICA SR@ OLGA BERRIO SOLICITA AVISO EXTERIOR POR DAÑO TOTAL 0 01/07/2025 SE VISITIA PUNTO Y NO SE INSTALA PUBLICIDAD PORQ YA CUENTA CON AVISO EXTERIOR EN BUEN ESTADO CERRAR | W4: VISITA_TÉCNICA | X4: 0 | Y4: TIPO I | Z4: TERRESTRE | AA4: HERNANDEZ CHAVARRIA JUAN CAMILO | AB4: 1 | AC4: 1 | AD4: =IF(OR(W4="SOPORTE_TELEFÓNICO",W4="ENVÍO"),0,IF(Y4="TIPO I",'BASE DE LIQUIDACION 2025'!$I$4,IF(Y4="TIPO II",'BASE DE LIQUIDACION 2025'!$I$5,IF(Y4="TIPO III",'BASE DE LIQUIDACION 2025'!$I$6,IF(Y4="TIPO IV",'BASE DE LIQUIDACION 2025'!$I$7,'BASE DE LIQUIDACION 2025'!$I$8))))) -> 96001.196 | AE4: =IF(OR(W4="SOPORTE_TELEFÓNICO",W4="ENVÍO"),0,IF(Y4="TIPO I",'BASE DE LIQUIDACION 2025'!$J$4,IF(Y4="TIPO II",'BASE DE LIQUIDACION 2025'!$J$5,IF(Y4="TIPO III",'BASE DE LIQUIDACION 2025'!$J$6,IF(Y4="TIPO IV",'BASE DE LIQUIDACION 2025'!$J$7,'BASE DE LIQUIDACION 2025'!$J$8))))) -> 57411.974 | AF4: =IF(W4="SOPORTE_TELEFÓNICO",'BASE DE LIQUIDACION 2025'!$L$4,IF(W4="ENVÍO",'BASE DE LIQUIDACION 2025'!$K$4,AD4*AB4+AE4*AC4)) -> 153413.17
A5: CUCUTA | B5: =VLOOKUP(A5,'CENTRO DE COSTOS'!A:D,4,FALSE) -> MIGUEL JULIÁN HERNÁNDEZ GUARÍN | C5: =VLOOKUP(A5,'CENTRO DE COSTOS'!A:D,2,FALSE) -> 0004-0008 | D5: 54001 | E5: 2362212 | F5: 33637 | G5: ORDEN DE CAMBIO | H5: NORTE DE SANTANDER | I5: CUCUTA | J5: BARRIO COLPET CUCUTA 1 | K5: REDEBAN | L5: FO-25-1142325 | M5: 45834.711 | N5: 45839.594 | P5: PUBLICIDAD | Q5: AVISO EXTERIOR | R5: CB UNO A UNO | S5: CB UNO A UNO | T5: EJECUTADO_EXITOSO | U5: EJECUTADO EXITOSO | V5: SE COMUNICA CB SR(A)ERIKA, INDICA QUE EL AVISO EXTERIOR EL NEGRO EL VIENTO LO TUMBO Y SE PARTIÓ SOLICITA LE COLABOREN POR FAVOR 0 01/07/2025 SE REALIZA INSTALACIÓN DE AVISO EXTERIOR OK CERRAR | W5: VISITA_TÉCNICA | X5: 9B00G007 | Y5: TIPO I | Z5: TERRESTRE | AA5: DURAN ACOSTA FRANK YONNY | AB5: 1 | AC5: 1 | AD5: =IF(OR(W5="SOPORTE_TELEFÓNICO",W5="ENVÍO"),0,IF(Y5="TIPO I",'BASE DE LIQUIDACION 2025'!$I$4,IF(Y5="TIPO II",'BASE DE LIQUIDACION 2025'!$I$5,IF(Y5="TIPO III",'BASE DE LIQUIDACION 2025'!$I$6,IF(Y5="TIPO IV",'BASE DE LIQUIDACION 2025'!$I$7,'BASE DE LIQUIDACION 2025'!$I$8))))) -> 96001.196 | AE5: =IF(OR(W5="SOPORTE_TELEFÓNICO",W5="ENVÍO"),0,IF(Y5="TIPO I",'BASE DE LIQUIDACION 2025'!$J$4,IF(Y5="TIPO II",'BASE DE LIQUIDACION 2025'!$J$5,IF(Y5="TIPO III",'BASE DE LIQUIDACION 2025'!$J$6,IF(Y5="TIPO IV",'BASE DE LIQUIDACION 2025'!$J$7,'BASE DE LIQUIDACION 2025'!$J$8))))) -> 57411.974 | AF5: =IF(W5="SOPORTE_TELEFÓNICO",'BASE DE LIQUIDACION 2025'!$L$4,IF(W5="ENVÍO",'BASE DE LIQUIDACION 2025'!$K$4,AD5*AB5+AE5*AC5)) -> 153413.17
A6: IBAGUE | B6: =VLOOKUP(A6,'CENTRO DE COSTOS'!A:D,4,FALSE) -> KEVIN ALEXIS CORZO BUSTOS | C6: =VLOOKUP(A6,'CENTRO DE COSTOS'!A:D,2,FALSE) -> 0004-0007 | D6: 73001 | E6: 2365966 | F6: 62018 | G6: ORDEN DE CAMBIO | H6: TOLIMA | I6: IBAGUE | J6: PTM IBAGUE VARIEDADES JENNY ' | K6: REDEBAN | L6: FO-25-1145290 | M6: 45835.522 | N6: 45839.599 | P6: PUBLICIDAD | Q6: AVISO EXTERIOR | R6: AGREGADOR | S6: COMCARD - PTM | T6: EJECUTADO_EXITOSO | U6: EJECUTADO EXITOSO | V6: SE COMUNICA CB SR(A) YENNY CASTRO PARA SOLICITAR AVISO EXTERIOR POR DAÑO TOTAL 0 01/07/2025 SE REALIZA INSTALACIÓN DE AVISO EXTERIOR SIN MARCO POR SOLICITUD DEL CLIENTE, INDICA ROBO CONSTANTE DE MARCO DE ALUMINIO. CERRAR | W6: VISITA_TÉCNICA | X6: KA00M290 | Y6: TIPO I | Z6: TERRESTRE | AA6: BARRAGAN TAFUR EDWIN ESTEBAN | AB6: 1 | AC6: 1 | AD6: =IF(OR(W6="SOPORTE_TELEFÓNICO",W6="ENVÍO"),0,IF(Y6="TIPO I",'BASE DE LIQUIDACION 2025'!$I$4,IF(Y6="TIPO II",'BASE DE LIQUIDACION 2025'!$I$5,IF(Y6="TIPO III",'BASE DE LIQUIDACION 2025'!$I$6,IF(Y6="TIPO IV",'BASE DE LIQUIDACION 2025'!$I$7,'BASE DE LIQUIDACION 2025'!$I$8))))) -> 96001.196 | AE6: =IF(OR(W6="SOPORTE_TELEFÓNICO",W6="ENVÍO"),0,IF(Y6="TIPO I",'BASE DE LIQUIDACION 2025'!$J$4,IF(Y6="TIPO II",'BASE DE LIQUIDACION 2025'!$J$5,IF(Y6="TIPO III",'BASE DE LIQUIDACION 2025'!$J$6,IF(Y6="TIPO IV",'BASE DE LIQUIDACION 2025'!$J$7,'BASE DE LIQUIDACION 2025'!$J$8))))) -> 57411.974 | AF6: =IF(W6="SOPORTE_TELEFÓNICO",'BASE DE LIQUIDACION 2025'!$L$4,IF(W6="ENVÍO",'BASE DE LIQUIDACION 2025'!$K$4,AD6*AB6+AE6*AC6)) -> 153413.17
A7: BOGOTA | B7: =VLOOKUP(A7,'CENTRO DE COSTOS'!A:D,4,FALSE) -> WILLIAM ASDRUBAL ROZO ROZO | C7: =VLOOKUP(A7,'CENTRO DE COSTOS'!A:D,2,FALSE) -> 0004-0004 | D7: 11001 | E7: 2367013 | F7: 39356 | G7: ORDEN DE CAMBIO | H7: CUNDINAMARCA | I7: BOGOTA | J7: PTM BOGOTA CENTRO DE PAGOS | K7: REDEBAN | L7: FO-25-1146812 | M7: 45835.648 | N7: 45839.693 | P7: PUBLICIDAD | Q7: AVISO EXTERIOR | R7: AGREGADOR | S7: COMCARD - PTM | T7: EJECUTADO_EXITOSO | U7: EJECUTADO EXITOSO | V7: SE COMUNICA CB SR(A) MARITZA CHAVES PARA SOLICITAR EL AVISO EXTERIOR YA QUE SE DAÑO, 0 01/07/2025 SE REALIZA VISITA AL COMERCIO PARA EJECUTAR INSTALACIÓN DE AVISO EXTERIOR POR SOLICITUD DEL CLIENTE OK CERRAR | W7: VISITA_TÉCNICA | X7: 0 | Y7: TIPO I | Z7: TERRESTRE | AA7: CORTES VELANDIA MIGUEL ANGEL | AB7: 1 | AC7: 1 | AD7: =IF(OR(W7="SOPORTE_TELEFÓNICO",W7="ENVÍO"),0,IF(Y7="TIPO I",'BASE DE LIQUIDACION 2025'!$I$4,IF(Y7="TIPO II",'BASE DE LIQUIDACION 2025'!$I$5,IF(Y7="TIPO III",'BASE DE LIQUIDACION 2025'!$I$6,IF(Y7="TIPO IV",'BASE DE LIQUIDACION 2025'!$I$7,'BASE DE LIQUIDACION 2025'!$I$8))))) -> 96001.196 | AE7: =IF(OR(W7="SOPORTE_TELEFÓNICO",W7="ENVÍO"),0,IF(Y7="TIPO I",'BASE DE LIQUIDACION 2025'!$J$4,IF(Y7="TIPO II",'BASE DE LIQUIDACION 2025'!$J$5,IF(Y7="TIPO III",'BASE DE LIQUIDACION 2025'!$J$6,IF(Y7="TIPO IV",'BASE DE LIQUIDACION 2025'!$J$7,'BASE DE LIQUIDACION 2025'!$J$8))))) -> 57411.974 | AF7: =IF(W7="SOPORTE_TELEFÓNICO",'BASE DE LIQUIDACION 2025'!$L$4,IF(W7="ENVÍO",'BASE DE LIQUIDACION 2025'!$K$4,AD7*AB7+AE7*AC7)) -> 153413.17
A8: CUCUTA | B8: =VLOOKUP(A8,'CENTRO DE COSTOS'!A:D,4,FALSE) -> MIGUEL JULIÁN HERNÁNDEZ GUARÍN | C8: =VLOOKUP(A8,'CENTRO DE COSTOS'!A:D,2,FALSE) -> 0004-0008 | D8: 54001 | E8: 2376015 | F8: 75195 | G8: ORDEN DE CAMBIO | H8: NORTE DE SANTANDER | I8: CUCUTA | J8: BARRIO TRIGAL DEL NORTE CUCUT | K8: REDEBAN | L8: FO-25-1163467 | M8: 45839.501 | N8: 45840.471 | P8: PUBLICIDAD | Q8: AVISO EXTERIOR | R8: CB UNO A UNO | S8: CB UNO A UNO | T8: EJECUTADO_EXITOSO | U8: EJECUTADO EXITOSO | V8: SE COMUNICA CB SR(A) SOFÍA PARA REPORTAR QUE LE ROBARON EL AVISO EXTERIOR EL NEGRO, SOLICITA LE COLABOREN POR FAVOR 0 02/07/2025 SE REALIZA INSTALACIÓN DE AVISO EXTERIOR OK CERRAR | W8: VISITA_TÉCNICA | X8: 0 | Y8: TIPO I | Z8: TERRESTRE | AA8: DURAN ACOSTA FRANK YONNY | AB8: 1 | AC8: 1 | AD8: =IF(OR(W8="SOPORTE_TELEFÓNICO",W8="ENVÍO"),0,IF(Y8="TIPO I",'BASE DE LIQUIDACION 2025'!$I$4,IF(Y8="TIPO II",'BASE DE LIQUIDACION 2025'!$I$5,IF(Y8="TIPO III",'BASE DE LIQUIDACION 2025'!$I$6,IF(Y8="TIPO IV",'BASE DE LIQUIDACION 2025'!$I$7,'BASE DE LIQUIDACION 2025'!$I$8))))) -> 96001.196 | AE8: =IF(OR(W8="SOPORTE_TELEFÓNICO",W8="ENVÍO"),0,IF(Y8="TIPO I",'BASE DE LIQUIDACION 2025'!$J$4,IF(Y8="TIPO II",'BASE DE LIQUIDACION 2025'!$J$5,IF(Y8="TIPO III",'BASE DE LIQUIDACION 2025'!$J$6,IF(Y8="TIPO IV",'BASE DE LIQUIDACION 2025'!$J$7,'BASE DE LIQUIDACION 2025'!$J$8))))) -> 57411.974 | AF8: =IF(W8="SOPORTE_TELEFÓNICO",'BASE DE LIQUIDACION 2025'!$L$4,IF(W8="ENVÍO",'BASE DE LIQUIDACION 2025'!$K$4,AD8*AB8+AE8*AC8)) -> 153413.17
A9: CALI | B9: =VLOOKUP(A9,'CENTRO DE COSTOS'!A:D,4,FALSE) -> DIEGO FERNANDO HENAO CARDONA | C9: =VLOOKUP(A9,'CENTRO DE COSTOS'!A:D,2,FALSE) -> 0004-0003 | D9: 76001 | E9: 2373408 | F9: 58951 | G9: ORDEN DE CAMBIO | H9: VALLE DEL CAUCA | I9: CALI | J9: BARRIO CENTRO CALI 34 | K9: REDEBAN | L9: FO-25-1162630 | M9: 45839.404 | N9: 45840.49 | P9: PUBLICIDAD | Q9: AVISO EXTERIOR | R9: CB UNO A UNO | S9: CB UNO A UNO | T9: EJECUTADO_EXITOSO | U9: EJECUTADO EXITOSO | V9: SE COMUNICA ANGIE, SOLICITA AVISO EXTERIOR, YA QUE EL QUE TENÍA FUE HURTADO. 0 02/07/2025 SE REALIZA INSTALACIÓN DE AVISO EXTERIOR SIN NOVEDAD. CERRAR | W9: VISITA_TÉCNICA | X9: 0 | Y9: TIPO I | Z9: TERRESTRE | AA9: TORRES GARCIA JENDRY JOSE | AB9: 1 | AC9: 1 | AD9: =IF(OR(W9="SOPORTE_TELEFÓNICO",W9="ENVÍO"),0,IF(Y9="TIPO I",'BASE DE LIQUIDACION 2025'!$I$4,IF(Y9="TIPO II",'BASE DE LIQUIDACION 2025'!$I$5,IF(Y9="TIPO III",'BASE DE LIQUIDACION 2025'!$I$6,IF(Y9="TIPO IV",'BASE DE LIQUIDACION 2025'!$I$7,'BASE DE LIQUIDACION 2025'!$I$8))))) -> 96001.196 | AE9: =IF(OR(W9="SOPORTE_TELEFÓNICO",W9="ENVÍO"),0,IF(Y9="TIPO I",'BASE DE LIQUIDACION 2025'!$J$4,IF(Y9="TIPO II",'BASE DE LIQUIDACION 2025'!$J$5,IF(Y9="TIPO III",'BASE DE LIQUIDACION 2025'!$J$6,IF(Y9="TIPO IV",'BASE DE LIQUIDACION 2025'!$J$7,'BASE DE LIQUIDACION 2025'!$J$8))))) -> 57411.974 | AF9: =IF(W9="SOPORTE_TELEFÓNICO",'BASE DE LIQUIDACION 2025'!$L$4,IF(W9="ENVÍO",'BASE DE LIQUIDACION 2025'!$K$4,AD9*AB9+AE9*AC9)) -> 153413.17
A10: CARTAGENA | B10: =VLOOKUP(A10,'CENTRO DE COSTOS'!A:D,4,FALSE) -> JOSE MAURICIO HERNANDEZ ROJAS | C10: =VLOOKUP(A10,'CENTRO DE COSTOS'!A:D,2,FALSE) -> 0004-0001 | D10: 13873 | E10: 2374317 | F10: 71584 | G10: ORDEN DE CAMBIO | H10: BOLIVAR | I10: VILLANUEVA | J10: BARRIO CALLE REAL | K10: REDEBAN | L10: FO-25-1162690 | M10: 45839.431 | N10: 45841.522 | P10: PUBLICIDAD | Q10: AVISO EXTERIOR | R10: CB UNO A UNO | S10: CB UNO A UNO | T10: EJECUTADO_EXITOSO | U10: EJECUTADO EXITOSO | V10: SE COMUNICA CB SR(A) NAYIB MALAMBO, PARA SOLICITAR AVISO EXTERIOR YA QUE EL QUE TENÍA LO DAÑARON Y SE ROBARON EL ACRÍLICO, SOLICITA DE SU AYUDA 0 03/07/2025 SE INSTALA AVISO EXTERIOR TODO OK CERRAR | W10: VISITA_TÉCNICA | X10: 0 | Y10: TIPO II | Z10: TERRESTRE | AA10: CANEDO HERRERA ALEXANDER | AB10: 1 | AC10: 1 | AD10: =IF(OR(W10="SOPORTE_TELEFÓNICO",W10="ENVÍO"),0,IF(Y10="TIPO I",'BASE DE LIQUIDACION 2025'!$I$4,IF(Y10="TIPO II",'BASE DE LIQUIDACION 2025'!$I$5,IF(Y10="TIPO III",'BASE DE LIQUIDACION 2025'!$I$6,IF(Y10="TIPO IV",'BASE DE LIQUIDACION 2025'!$I$7,'BASE DE LIQUIDACION 2025'!$I$8))))) -> 232858.6 | AE10: =IF(OR(W10="SOPORTE_TELEFÓNICO",W10="ENVÍO"),0,IF(Y10="TIPO I",'BASE DE LIQUIDACION 2025'!$J$4,IF(Y10="TIPO II",'BASE DE LIQUIDACION 2025'!$J$5,IF(Y10="TIPO III",'BASE DE LIQUIDACION 2025'!$J$6,IF(Y10="TIPO IV",'BASE DE LIQUIDACION 2025'!$J$7,'BASE DE LIQUIDACION 2025'!$J$8))))) -> 110808.28 | AF10: =IF(W10="SOPORTE_TELEFÓNICO",'BASE DE LIQUIDACION 2025'!$L$4,IF(W10="ENVÍO",'BASE DE LIQUIDACION 2025'!$K$4,AD10*AB10+AE10*AC10)) -> 343666.88
A11: BARRANQUILLA | B11: =VLOOKUP(A11,'CENTRO DE COSTOS'!A:D,4,FALSE) -> JOSE MAURICIO HERNANDEZ ROJAS | C11: =VLOOKUP(A11,'CENTRO DE COSTOS'!A:D,2,FALSE) -> 0004-0001 | D11: 8001 | E11: 2364133 | F11: 29787 | G11: ORDEN DE CAMBIO | H11: ATLANTICO | I11: BARRANQUILLA | J11: BARRIO UNION BARRANQUILLA | K11: REDEBAN | L11: FO-25-1142908 | M11: 45835.383 | N11: 45841.719 | P11: PUBLICIDAD | Q11: AVISO EXTERIOR | R11: CB UNO A UNO | S11: CB UNO A UNO | T11: EJECUTADO_EXITOSO | U11: EJECUTADO EXITOSO | V11: SE COMUNICA CB SR(A) PAOLA RINCÓN SOLICITA AVISO EXTERIOR POR HURTO, ESPERO LE PUEDAN COLABORAR 0 03/07/2025 SE INSTALA AVISO EXTERIOR, EL QUE ESTABA SE LO ROBARON CERRAR | W11: VISITA_TÉCNICA | X11: 0 | Y11: TIPO I | Z11: TERRESTRE | AA11: DE AVILA SIADES ALBERTO ENRIQUE | AB11: 1 | AC11: 1 | AD11: =IF(OR(W11="SOPORTE_TELEFÓNICO",W11="ENVÍO"),0,IF(Y11="TIPO I",'BASE DE LIQUIDACION 2025'!$I$4,IF(Y11="TIPO II",'BASE DE LIQUIDACION 2025'!$I$5,IF(Y11="TIPO III",'BASE DE LIQUIDACION 2025'!$I$6,IF(Y11="TIPO IV",'BASE DE LIQUIDACION 2025'!$I$7,'BASE DE LIQUIDACION 2025'!$I$8))))) -> 96001.196 | AE11: =IF(OR(W11="SOPORTE_TELEFÓNICO",W11="ENVÍO"),0,IF(Y11="TIPO I",'BASE DE LIQUIDACION 2025'!$J$4,IF(Y11="TIPO II",'BASE DE LIQUIDACION 2025'!$J$5,IF(Y11="TIPO III",'BASE DE LIQUIDACION 2025'!$J$6,IF(Y11="TIPO IV",'BASE DE LIQUIDACION 2025'!$J$7,'BASE DE LIQUIDACION 2025'!$J$8))))) -> 57411.974 | AF11: =IF(W11="SOPORTE_TELEFÓNICO",'BASE DE LIQUIDACION 2025'!$L$4,IF(W11="ENVÍO",'BASE DE LIQUIDACION 2025'!$K$4,AD11*AB11+AE11*AC11)) -> 153413.17
A12: VILLAVICENCIO | B12: =VLOOKUP(A12,'CENTRO DE COSTOS'!A:D,4,FALSE) -> KEVIN ALEXIS CORZO BUSTOS | C12: =VLOOKUP(A12,'CENTRO DE COSTOS'!A:D,2,FALSE) -> 0004-0007 | D12: 50313 | E12: 2358758 | F12: 72900 | G12: ORDEN DE CAMBIO | H12: META | I12: GRANADA | J12: GRANADA CENTRO | K12: REDEBAN | L12: FO-25-1138474 | M12: 45834.435 | N12: 45842.499 | P12: PUBLICIDAD | Q12: AVISO EXTERIOR | R12: CB UNO A UNO | S12: CB UNO A UNO | T12: EJECUTADO_EXITOSO | U12: EJECUTADO EXITOSO | V12: SE COMUNICA CB SR(A) LAURA PARA SOLICITAR AVISO EXTERIOR POR QUE SE LO ROBARON, 0 04/07/2025 SE INSTALA AVISO EXTERIOR OK SIN NOVEDADES SE LO ROBARON CERRAR | W12: VISITA_TÉCNICA | X12: 0 | Y12: TIPO II | Z12: TERRESTRE | AA12: CASTRILLON URREA LONDIER LEANDRO | AB12: 1 | AC12: 1 | AD12: =IF(OR(W12="SOPORTE_TELEFÓNICO",W12="ENVÍO"),0,IF(Y12="TIPO I",'BASE DE LIQUIDACION 2025'!$I$4,IF(Y12="TIPO II",'BASE DE LIQUIDACION 2025'!$I$5,IF(Y12="TIPO III",'BASE DE LIQUIDACION 2025'!$I$6,IF(Y12="TIPO IV",'BASE DE LIQUIDACION 2025'!$I$7,'BASE DE LIQUIDACION 2025'!$I$8))))) -> 232858.6 | AE12: =IF(OR(W12="SOPORTE_TELEFÓNICO",W12="ENVÍO"),0,IF(Y12="TIPO I",'BASE DE LIQUIDACION 2025'!$J$4,IF(Y12="TIPO II",'BASE DE LIQUIDACION 2025'!$J$5,IF(Y12="TIPO III",'BASE DE LIQUIDACION 2025'!$J$6,IF(Y12="TIPO IV",'BASE DE LIQUIDACION 2025'!$J$7,'BASE DE LIQUIDACION 2025'!$J$8))))) -> 110808.28 | AF12: =IF(W12="SOPORTE_TELEFÓNICO",'BASE DE LIQUIDACION 2025'!$L$4,IF(W12="ENVÍO",'BASE DE LIQUIDACION 2025'!$K$4,AD12*AB12+AE12*AC12)) -> 343666.88
A13: CUCUTA | B13: =VLOOKUP(A13,'CENTRO DE COSTOS'!A:D,4,FALSE) -> MIGUEL JULIÁN HERNÁNDEZ GUARÍN | C13: =VLOOKUP(A13,'CENTRO DE COSTOS'!A:D,2,FALSE) -> 0004-0008 | D13: 54261 | E13: 2368973 | F13: 55083 | G13: ORDEN DE CAMBIO | H13: NORTE DE SANTANDER | I13: EL ZULIA | J13: BARRIO VEREDA EL TABLAZO VIA A | K13: REDEBAN | L13: FO-25-1151928 | M13: 45839.333 | N13: 45842.505 | P13: PUBLICIDAD | Q13: AVISO EXTERIOR | R13: CB UNO A UNO | S13: CB UNO A UNO | T13: EJECUTADO_EXITOSO | U13: EJECUTADO EXITOSO | V13: SR(A) ASTRID SOLICITANDO AVISO EXTERIOR YA QUE EL QUE TENIA INSTALADO SE DAÑO. GRACIAS 01/07/2025 EN COMUNICACIÓN CON EL CLIENTE SE LE INFORMA A LA SRA ASTRID ROLON 3228570293 QUE EN EL MOMENTO POR ALTERACIÓN DE ORDEN PÚBLICO EN LA ZONA DEL CATATUMBO NO SE PODRÍA VIAJAR A REALIZAR LA ACTIVIDAD,SE PROGRAMA VISITA A LA ESPERA DE NORMALIDAD EN LA ZONA 04/07/2025 SE INSTALA AVISO EXTERIOR CERRAR | W13: VISITA_TÉCNICA | X13: 0 | Y13: TIPO II | Z13: TERRESTRE | AA13: PACHECO BUITRAGO JAVIER ALONSO | AB13: 1 | AC13: 1 | AD13: =IF(OR(W13="SOPORTE_TELEFÓNICO",W13="ENVÍO"),0,IF(Y13="TIPO I",'BASE DE LIQUIDACION 2025'!$I$4,IF(Y13="TIPO II",'BASE DE LIQUIDACION 2025'!$I$5,IF(Y13="TIPO III",'BASE DE LIQUIDACION 2025'!$I$6,IF(Y13="TIPO IV",'BASE DE LIQUIDACION 2025'!$I$7,'BASE DE LIQUIDACION 2025'!$I$8))))) -> 232858.6 | AE13: =IF(OR(W13="SOPORTE_TELEFÓNICO",W13="ENVÍO"),0,IF(Y13="TIPO I",'BASE DE LIQUIDACION 2025'!$J$4,IF(Y13="TIPO II",'BASE DE LIQUIDACION 2025'!$J$5,IF(Y13="TIPO III",'BASE DE LIQUIDACION 2025'!$J$6,IF(Y13="TIPO IV",'BASE DE LIQUIDACION 2025'!$J$7,'BASE DE LIQUIDACION 2025'!$J$8))))) -> 110808.28 | AF13: =IF(W13="SOPORTE_TELEFÓNICO",'BASE DE LIQUIDACION 2025'!$L$4,IF(W13="ENVÍO",'BASE DE LIQUIDACION 2025'!$K$4,AD13*AB13+AE13*AC13)) -> 343666.88
A14: IBAGUE | B14: =VLOOKUP(A14,'CENTRO DE COSTOS'!A:D,4,FALSE) -> KEVIN ALEXIS CORZO BUSTOS | C14: =VLOOKUP(A14,'CENTRO DE COSTOS'!A:D,2,FALSE) -> 0004-0007 | D14: 73001 | E14: 2391008 | F14: 77020 | G14: ORDEN DE CAMBIO | H14: TOLIMA | I14: IBAGUE | J14: BARRIO ARKALA IBAGUE 2 | K14: REDEBAN | L14: FO-25-1178683 | M14: 45841.488 | N14: 45842.528 | P14: PUBLICIDAD | Q14: AVISO EXTERIOR | R14: CB UNO A UNO | S14: CB UNO A UNO | T14: EJECUTADO_EXITOSO | U14: EJECUTADO EXITOSO | V14: SE COMUNICA CB SR(A) OSCAR PARA SOLICITAR AVISO EXTERIOR, EL ACTUAL SE LO ROBARON 0 04/07/2025 SE REALIZA INSTALACIÓN DE AVISO EXTERIOR "SE LO ROBARON CON MARCO" SOLICITUD DEL CLIENTE CERRAR | W14: VISITA_TÉCNICA | X14: 0 | Y14: TIPO I | Z14: TERRESTRE | AA14: GUTIERREZ CAMILO ANDRES | AB14: 1 | AC14: 1 | AD14: =IF(OR(W14="SOPORTE_TELEFÓNICO",W14="ENVÍO"),0,IF(Y14="TIPO I",'BASE DE LIQUIDACION 2025'!$I$4,IF(Y14="TIPO II",'BASE DE LIQUIDACION 2025'!$I$5,IF(Y14="TIPO III",'BASE DE LIQUIDACION 2025'!$I$6,IF(Y14="TIPO IV",'BASE DE LIQUIDACION 2025'!$I$7,'BASE DE LIQUIDACION 2025'!$I$8))))) -> 96001.196 | AE14: =IF(OR(W14="SOPORTE_TELEFÓNICO",W14="ENVÍO"),0,IF(Y14="TIPO I",'BASE DE LIQUIDACION 2025'!$J$4,IF(Y14="TIPO II",'BASE DE LIQUIDACION 2025'!$J$5,IF(Y14="TIPO III",'BASE DE LIQUIDACION 2025'!$J$6,IF(Y14="TIPO IV",'BASE DE LIQUIDACION 2025'!$J$7,'BASE DE LIQUIDACION 2025'!$J$8))))) -> 57411.974 | AF14: =IF(W14="SOPORTE_TELEFÓNICO",'BASE DE LIQUIDACION 2025'!$L$4,IF(W14="ENVÍO",'BASE DE LIQUIDACION 2025'!$K$4,AD14*AB14+AE14*AC14)) -> 153413.17
A15: BOGOTA | B15: =VLOOKUP(A15,'CENTRO DE COSTOS'!A:D,4,FALSE) -> WILLIAM ASDRUBAL ROZO ROZO | C15: =VLOOKUP(A15,'CENTRO DE COSTOS'!A:D,2,FALSE) -> 0004-0004 | D15: 11001 | E15: 2373262 | F15: 74893 | G15: ORDEN DE CAMBIO | H15: CUNDINAMARCA | I15: BOGOTA | J15: BARRIO POLICARPA BOGOTA 5 | K15: REDEBAN | L15: FO-25-1162642 | M15: 45839.401 | N15: 45842.576 | P15: PUBLICIDAD | Q15: AVISO EXTERIOR | R15: CB UNO A UNO | S15: CB UNO A UNO | T15: EJECUTADO_EXITOSO | U15: EJECUTADO EXITOSO | V15: SE COMUNICA CB SR(A) ALEJANDRO PARA SOLICITAR AVISO EXTERIOR YA QUE SE LO ROBARON 0 04/07/2025 SE LLEGA A LA DIRECCIÓN INDICADA, SE INSTALA AVISO EXTERIOR, NO SE MANIPULAN DATÁFONOS CERRAR | W15: VISITA_TÉCNICA | X15: 0 | Y15: TIPO I | Z15: TERRESTRE | AA15: GARCIA PASTRANA KEVIN FERNANDO | AB15: 1 | AC15: 1 | AD15: =IF(OR(W15="SOPORTE_TELEFÓNICO",W15="ENVÍO"),0,IF(Y15="TIPO I",'BASE DE LIQUIDACION 2025'!$I$4,IF(Y15="TIPO II",'BASE DE LIQUIDACION 2025'!$I$5,IF(Y15="TIPO III",'BASE DE LIQUIDACION 2025'!$I$6,IF(Y15="TIPO IV",'BASE DE LIQUIDACION 2025'!$I$7,'BASE DE LIQUIDACION 2025'!$I$8))))) -> 96001.196 | AE15: =IF(OR(W15="SOPORTE_TELEFÓNICO",W15="ENVÍO"),0,IF(Y15="TIPO I",'BASE DE LIQUIDACION 2025'!$J$4,IF(Y15="TIPO II",'BASE DE LIQUIDACION 2025'!$J$5,IF(Y15="TIPO III",'BASE DE LIQUIDACION 2025'!$J$6,IF(Y15="TIPO IV",'BASE DE LIQUIDACION 2025'!$J$7,'BASE DE LIQUIDACION 2025'!$J$8))))) -> 57411.974 | AF15: =IF(W15="SOPORTE_TELEFÓNICO",'BASE DE LIQUIDACION 2025'!$L$4,IF(W15="ENVÍO",'BASE DE LIQUIDACION 2025'!$K$4,AD15*AB15+AE15*AC15)) -> 153413.17
A16: BOGOTA | B16: =VLOOKUP(A16,'CENTRO DE COSTOS'!A:D,4,FALSE) -> WILLIAM ASDRUBAL ROZO ROZO | C16: =VLOOKUP(A16,'CENTRO DE COSTOS'!A:D,2,FALSE) -> 0004-0004 | D16: 11001 | E16: TA-25-830126 | F16: 43352 | G16: ORDEN DE CAMBIO | H16: CUNDINAMARCA | I16: BOGOTA | J16: BARRIO CORABASTOS BOGOTA 2 | K16: REDEBAN | L16: FO-25-1176456 | M16: 45841.333 | N16: 45842.581 | P16: PUBLICIDAD | Q16: AVISO EXTERIOR | R16: CB UNO A UNO | S16: CB UNO A UNO | T16: EJECUTADO_EXITOSO | U16: EJECUTADO EXITOSO | V16: SOLICITO POR FAVOR QUE PROGRAMEMOS LA INSTALACIÓN DE LA PUBLICIDAD (AVISO EXTERIOR), YA QUE EN ESTA OCASIÓN EL COMERCIO REQUIERE CONTAR CON ELLA Y LA ENTIDAD HA DADO SU APROBACIÓN PARA SU INSTALACIÓN 0 04/07/2025 SE REALIZA VISITA DE CAMPO DONDE SE INSTALA AVISO EXTERIOR DE ACUERDO A INDICACIONES A CLIENTE, NO SE MANIPULA EQUIPOS. CERRAR | W16: VISITA_TÉCNICA | X16: 0 | Y16: TIPO I | Z16: TERRESTRE | AA16: LOZADA ROJAS CHRISTIAN ANDRES | AB16: 1 | AC16: 1 | AD16: =IF(OR(W16="SOPORTE_TELEFÓNICO",W16="ENVÍO"),0,IF(Y16="TIPO I",'BASE DE LIQUIDACION 2025'!$I$4,IF(Y16="TIPO II",'BASE DE LIQUIDACION 2025'!$I$5,IF(Y16="TIPO III",'BASE DE LIQUIDACION 2025'!$I$6,IF(Y16="TIPO IV",'BASE DE LIQUIDACION 2025'!$I$7,'BASE DE LIQUIDACION 2025'!$I$8))))) -> 96001.196 | AE16: =IF(OR(W16="SOPORTE_TELEFÓNICO",W16="ENVÍO"),0,IF(Y16="TIPO I",'BASE DE LIQUIDACION 2025'!$J$4,IF(Y16="TIPO II",'BASE DE LIQUIDACION 2025'!$J$5,IF(Y16="TIPO III",'BASE DE LIQUIDACION 2025'!$J$6,IF(Y16="TIPO IV",'BASE DE LIQUIDACION 2025'!$J$7,'BASE DE LIQUIDACION 2025'!$J$8))))) -> 57411.974 | AF16: =IF(W16="SOPORTE_TELEFÓNICO",'BASE DE LIQUIDACION 2025'!$L$4,IF(W16="ENVÍO",'BASE DE LIQUIDACION 2025'!$K$4,AD16*AB16+AE16*AC16)) -> 153413.17
A17: BUCARAMANGA | B17: =VLOOKUP(A17,'CENTRO DE COSTOS'!A:D,4,FALSE) -> MIGUEL JULIÁN HERNÁNDEZ GUARÍN | C17: =VLOOKUP(A17,'CENTRO DE COSTOS'!A:D,2,FALSE) -> 0004-0008 | D17: 20710 | E17: 2390767 | F17: 40387 | G17: ORDEN DE CAMBIO | H17: CESAR | I17: SAN ALBERTO | J17: BARRIO LA PALMA SAN ALBERTO CE | K17: REDEBAN | L17: FO-25-1178682 | M17: 45841.491 | N17: 45843.378 | P17: PUBLICIDAD | Q17: AVISO EXTERIOR | R17: CB UNO A UNO | S17: CB UNO A UNO | T17: EJECUTADO_EXITOSO | U17: EJECUTADO EXITOSO | V17: SE COMUNICA CB SR(A)YESICA, PARA SOLICITAR AVISO PRINCIPAL EXTERIOR, EL QUE TENIA UN VENTARRÓN LO TUMBO Y LO PARTIO POR COMPLETO, 0 04/07/2025 INSTALACIÓN DE AVISO EXTERIOR, NO SE MANIPULA EQUIPOS. CERRAR | W17: VISITA_TÉCNICA | X17: 0 | Y17: TIPO III | Z17: TERRESTRE | AA17: SANTOS GONZALEZ JOHAN FABIAN | AB17: 1 | AC17: 1 | AD17: =IF(OR(W17="SOPORTE_TELEFÓNICO",W17="ENVÍO"),0,IF(Y17="TIPO I",'BASE DE LIQUIDACION 2025'!$I$4,IF(Y17="TIPO II",'BASE DE LIQUIDACION 2025'!$I$5,IF(Y17="TIPO III",'BASE DE LIQUIDACION 2025'!$I$6,IF(Y17="TIPO IV",'BASE DE LIQUIDACION 2025'!$I$7,'BASE DE LIQUIDACION 2025'!$I$8))))) -> 344774.57 | AE17: =IF(OR(W17="SOPORTE_TELEFÓNICO",W17="ENVÍO"),0,IF(Y17="TIPO I",'BASE DE LIQUIDACION 2025'!$J$4,IF(Y17="TIPO II",'BASE DE LIQUIDACION 2025'!$J$5,IF(Y17="TIPO III",'BASE DE LIQUIDACION 2025'!$J$6,IF(Y17="TIPO IV",'BASE DE LIQUIDACION 2025'!$J$7,'BASE DE LIQUIDACION 2025'!$J$8))))) -> 110808.28 | AF17: =IF(W17="SOPORTE_TELEFÓNICO",'BASE DE LIQUIDACION 2025'!$L$4,IF(W17="ENVÍO",'BASE DE LIQUIDACION 2025'!$K$4,AD17*AB17+AE17*AC17)) -> 455582.84
