Workbook
Name A: #REF!
Name Actividad: [1]Formulas!$H$2:$H$5000
Name arearesponsable: '[2]Listas desplegables'!$BB$2:$BB$100
Name Clientes: [1]Clientes!$A$2:$A$100
Name COORDINADOR: [3]Hoja2!$D$2:$D$30
Name Coordinadores: [1]Coordinadores!$A$2:$A$1000
Name DOCUMENTADOR: [3]Hoja2!$A$2:$A$30
Name ES: [3]Hoja2!$K$2:$K$30
Name ESS: [3]Hoja2!$K$2:$K$30
Name Estado: [1]Formulas!$K$2:$K$5000
Name ESTADOACTIVIDAD: [3]Hoja2!$M$2:$M$30
Name ESTADOS: '[4]Listas desplegables'!$B$1:$D$1
Name ESTADOSCIERRES: '[5]lista desplegable'!$CX$1:$DA$1
Name Facturacion: '[6]Listas desplegables'!$AO$1:$AR$1
Name FACTURACIÓN: '[4]Listas desplegables'!$Y$1:$AB$1
Name falla: #REF!
Name Fallas: '[7]Listas desplegables'!$F$2:$L$2
Name Grupo_Falla: '[8]Listas Desplegables'!$CH$2:$CH$5
Name inconservmanager: '[9]Listas desplegables'!$BC$2:$BC$100
Name INCUMPLIMIENTO: '[2]Listas desplegables'!$AK$1:$AN$1
Name LISTA: [10]Dptos!$A$1139:$A$1171
Name LISTA2: #REF!
Name LOLO: [11]Coordinadores!$A$2:$A$1000
Name solicitudes: '[12]Listas desplegables'!$AF$1:$AQ$1
Name Tecnicos: [1]Tecnicos!$A$2:$A$1000
Name Version: [1]Formulas!$I$2:$I$3

Sheet BASE LIQUIDACION
A1: TARIFAS 2025 | E1: Incremento 2025
A2: Tipificación | B2: Descripción | C2: Dia actividad Exitosa | D2: Dia actividad Fallida | E2: 0.052
A3: Tipo I | B3: Metropolitano | C3: =62700.07*(1+$E$2) -> 65960.474 | D3: =42357.4*(1+$E$2) -> 44559.985
A4: Tipo II | B4: Hasta 3 horas | C4: =155716.31*(1+$E$2) -> 163813.56 | D4: =127766.53*(1+$E$2) -> 134410.39
A5: Tipo III | B5: De 3 a 5 horas | C5: =262099.22*(1+$E$2) -> 275728.38 | D5: =211886.19*(1+$E$2) -> 222904.27
A6: Tipo IV | B6: Más de 5 horas | C6: =455883.78*(1+$E$2) -> 479589.74 | D6: =441833.68*(1+$E$2) -> 464809.03
A7: Destino aereo | B7: No incluye valor del Tiquete | C7: =455883.78*(1+$E$2) -> 479589.74 | D7: =441833.68*(1+$E$2) -> 464809.03
A8: *Donde se requiera transporte aéreo o fluvial se factura adicional a tarifa TIPO IV el valor del tiquete + el 12% de admon.
A10: Gestión Telefónica | B10: =36031.04*(1+$E$2) -> 37904.654
A11: Mts Acometida electrica | B11: =30182.1*(1+$E$2) -> 31751.569
A12: Mts Acometida datos | B12: =15432.22*(1+$E$2) -> 16234.695
A13: switche | B13: =244669.03*(1+$E$2) -> 257391.82
A14: Router | B14: =291399.51*(1+$E$2) -> 306552.28
A15: Envio operador Logistico | B15: =53547.34*(1+$E$2) -> 56331.802

Sheet RESUMEN LIQUIDACIONES
A1: LÍNEA COMUNICACIONES S.A.S | F1: FACTURACIÓN CORRESPONSALES BANCARIOS TIQUIETES AEREOS
A2: FACTURACIÓN PROYECTO CB BANCOLOMBIA | F2: =A3 -> 45962
A3: 45962
F4: CONCEPTOS | G4: TRAYECTOS | H4: TOTAL | I4: % Administración | J4: TOTAL
A5: CONCEPTOS | B5: CANTIDAD | C5: VALOR UNITARIO | D5: VALOR TOTAL | F5: INCIDENTE 3003898 | G5: BUCARAMANGA - ARAUCA - BUCARAMANGA | H5: =440000+285800 -> 725800 | I5: =H5*0.12 -> 87096 | J5: =H5+I5 -> 812896
A6: Adecuaciones CB | B6: =COUNTA(ADECUCACIONES!A:A)-1 -> 7 | C6: 0 | D6: =SUM(ADECUCACIONES!AE2:AE10000) -> 2274665 | I6: =H6*0.12 -> 0 | J6: =H6+I6 -> 0
A7: Incidentes | B7: =COUNTA(INCIDENTES!A:A)-1 -> 88 | C7: 0 | D7: =SUM(INCIDENTES!AH2:AH9913) -> 9077759 | I7: =H7*0.12 -> 0 | J7: =H7+I7 -> 0
A8: Ordenes de Cambio | B8: =COUNTA(OC!A:A)-1 -> 4 | C8: 0 | D8: =SUM(OC!AG2:AG10000) -> 263840 | I8: =H8*0.12 -> 0 | J8: =H8+I8 -> 0
A9: Tiquetes | B9: 1 | C9: 0 | D9: =J12 -> 812896 | I9: =H9*0.12 -> 0 | J9: =H9+I9 -> 0
A10: SUBTOTAL | D10: =SUM(D6:D9) -> 12429160 | I10: =H10*0.12 -> 0 | J10: =H10+I10 -> 0
A11: Iva | D11: =D10*0.19 -> 2361540.4 | I11: =H11*0.12 -> 0 | J11: =H11+I11 -> 0
A12: TOTAL | D12: =D10+D11 -> 14790700 | F12: TOTAL | H12: =SUM(H5:H11) -> 725800 | I12: =SUM(I5:I11) -> 87096 | J12: =SUM(J5:J11) -> 812896

Sheet ADECUCACIONES
A1: CIUDAD SEDE | B1: ZONA | C1: CENTRO DE COSTOS LINEACOM | D1: CODIGO DANE | E1: TA/CODIGO ACTIVIDAD | F1: CODIGO CB | G1: ACTIVIDAD | H1: TIPO DE APERTURA | I1: DEPARTAMENTO | J1: CIUDAD | K1: NOMBRE DEL CB | L1: RED | M1: FO | N1: FECHA LISTA | O1: FECHA ULTIMA ACTUALIZACION | P1: FORMATO | Q1: CADENA | R1: ESTADO | S1: OBSERVACIONES CLIENTE | T1: FORMA DE ATENCION | U1: TERMINAL(ES) | V1: TIPIFICACION | W1: TIPO DE TRAYECTO | X1: NOMBRE DEL TECNICO | Y1: ACOMETIDA DATOS | Z1: ACOMETIDA ELECTRICA | AA1: SWITCH | AB1: ROUTER | AC1: VALOR DIAS ACTIVIDAD FACTURABLES | AD1: DIAS ACTIVIDAD FACTURABLES | AE1: VALOR TOTAL INSTALACION DE PUBLICIDAD
A2: MEDELLIN | B2: NOROCCIDENTE | C2: 0004-0005 | D2: 5736 | E2: TA-25-1247964 | F2: 3007082061 | G2: APERTURA | H2: CB CRECIMIENTO ALIANZA - NUEVO | I2: ANTIOQUIA | J2: SEGOVIA | K2: DISTRICOL PLANETARIO 2000 | L2: REDEBAN | M2: FO-25-1765343 | FO-25-1751719 | N2: 45959.882 | O2: 45965.644 | P2: AGREGADOR | Q2: DISTRICOL | R2: CANCELADO | EJECUTADO/CANCELADO | S2: 04/11/2025 ENTIDAD SOLICITA CANCELAR LA INSTALACIÓN | T2: SOPORTE TELEFONICO | V2: TIPO IV | W2: TERRESTRE | X2: ECHEVERRI ECHEVERRI EVELIN DANIELA | Y2: 0 | Z2: 0 | AA2: 0 | AB2: 0 | AC2: 1 | AD2: 464809 | AE2: 464809
A3: APARTADO | B3: NOROCCIDENTE | C3: 0004-0005 | D3: 27006 | E3: TA-25-1247980 | F3: 3007082025 | G3: APERTURA | H3: CB CRECIMIENTO ALIANZA - NUEVO | I3: CHOCO | J3: ACANDI | K3: DISTRICOL CONFITERIA VENTANITA | L3: REDEBAN | M3: FO-25-1751759 | N3: 45959.724 | O3: 45966.822 | P3: AGREGADOR | Q3: DISTRICOL | R3: EJECUTADO/CANCELADO | S3: 29/10/2025 29-10 PROGRAMACIÓN REALIZADA POR LA ALIANZA| INSTALACIÓN PROGRAMADA PARA EL 2025-11-05 | 06/11/2025 SE LLEGA A SITIO, SE ENCUENTRA QUE EL COMERCIO ES UN RESTAURANTE PANADERÍA, NO SE VE COMO CONFITERÍA. ADICIONAL EN TODO EL FRENTE TIENE UN CORRESPONSAL BANCOLOMBIA Y AL LADO IZQUIERDO A 40 METROS TIENE OTRO CORRESPONSAL. SE ESCALA TEMA A COORDINADOR EL CUAL INDICA NO INSTALAR POR PROXIMIDAD ENTRE CORRESPONSALES. | T3: VISITA TECNICA | V3: TIPO V | W3: AEREO | X3: CASTRO HENAO DANIEL ESTEBAN | Y3: 0 | Z3: 0 | AA3: 0 | AB3: 0 | AC3: 1 | AD3: 988463 | AE3: 988463
A4: PASTO | B4: SUROCCIDENTE Y EJE CAFETERO | C4: 0004-0003 | D4: 86865 | E4: TA-25-1248008 | F4: 3007082070 | G4: APERTURA | H4: CB CRECIMIENTO ALIANZA - NUEVO | I4: PUTUMAYO | J4: VALLE DEL GUAMUEZ | K4: DISTRICOL ESTILO REAL | L4: REDEBAN | M4: FO-25-1751843 | N4: 45959.876 | O4: 45966.833 | P4: AGREGADOR | Q4: DISTRICOL | R4: EJECUTADO/CANCELADO | S4: 29/10/2025 29-10 PROGRAMACIÓN REALIZADA POR LA ALIANZA| INSTALACIÓN PROGRAMADA PARA EL 2025-10-31 | 31/10/2025 NO ES POSIBLE VIAJAR EL DIA DE HOY HACIA EL DEPARTAMENTO DEL PUTUMAYO POR PROBLEMAS DE TRANSPORTE SE REALIZARA DESPLAZAMIENTO AL DIA MARTES | 06/11/2025 SE VISITA EL COMERCIO PARA DAR APERTURA AL CB PERO NO ES POSIBLE YA QUE EL CLIENTE AUN NO TIENE LA ADECUACIÓN DE DATOS Y ENERGIA LISTOS DONDE VA A QUEDAR UBICADO EL DATAFONO, INFORMA QUE CUANDO TENGA DICHA ADECUACION INFORMARA PARA HACER LA INSTALACIÓN | T4: VISITA TECNICA | V4: TIPO IV | W4: TERRESTRE | X4: GUERRERO RAMIREZ OSCAR DARIO | Y4: 0 | Z4: 0 | AA4: 0 | AB4: 0 | AC4: 1 | AD4: 464809 | AE4: 464809
A5: CALI | B5: SUROCCIDENTE Y EJE CAFETERO | C5: 0004-0003 | D5: 76520 | E5: TA-25-1315926 | F5: 3007082246 | G5: APERTURA | H5: CB CRECIMIENTO ALIANZA - NUEVO | I5: VALLE DEL CAUCA | J5: PALMIRA | K5: PTM PALMIRA TIENDA Y VARIEDADE | L5: REDEBAN | M5: FO-25-1852593 | N5: 45982.333 | O5: 45985.506 | R5: EJECUTADO/CANCELADO | S5: 20/11/2025 20-11 PROGRAMACION REALIZADA POR LA ALIANZA| INSTALACIÓN PROGRAMADA PARA EL 2025-11-24 | 24/11/2025 SE PROCEDE LLAMA AL CONTACTO PARA CONFIRMAR VISITA, DONDE SE EVIDENCIA QUÉ DIRECCIÓN EN ORDEN DE INSTALACIÓN NO COINCIDE CON LA DIRECCIÓN FÍSICA DEL CLIENTE. SE PROCEDE A VISITAR PARA CONFIRMAR. DIRECCIÓN CORRECTA DEL COMERCIO ES CARRERA 27 B # 3 0-6. SE EVIDENCIÓ QUE CÁMARA Y COMERCIO ESTÁ ERRADA Y SE LE INDICA AL CLIENTE QUE DEBE CORREGIR Y ENVIAR DATOS NUEVAMENTE. | T5: VISITA TECNICA | V5: TIPO I | W5: TERRESTRE | X5: BOLAÑOS TABORDA JORGE ENRIQUE | Y5: 0 | Z5: 0 | AA5: 0 | AB5: 0 | AC5: 1 | AD5: 44560 | AE5: 44560
A6: MEDELLIN | B6: NOROCCIDENTE | C6: 0004-0005 | D6: 5001 | E6: TA-25-1315934 | F6: 3007079707 | G6: APERTURA | H6: DATAFONO ADICIONAL - ALIANZA | I6: ANTIOQUIA | J6: MEDELLIN | K6: PTM MEDELLIN PAPELERIA Y VARIE | L6: REDEBAN | M6: FO-25-1852618 | N6: 45982.333 | O6: 45983.515 | P6: AGREGADOR | Q6: COMCARD - PTM | R6: EJECUTADO/CANCELADO | S6: 20/11/2025 20-11 PROGRAMACION REALIZADA POR LA ALIANZA| INSTALACIÓN PROGRAMADA PARA EL 2025-11-21 | 22/11/2025 NO SE HACE LA INSTALACIÓN DEL DATAFONO ADICIONAL PORQUE EN EL PUNTO HAY UN EFECTY, ESCALO LO SUCEDIDO Y NO PERMITEN LA VISITA | T6: VISITA TECNICA | V6: TIPO I | W6: TERRESTRE | X6: RUA ALVAREZ RICHARD ANDRES | Y6: 0 | Z6: 0 | AA6: 0 | AB6: 0 | AC6: 1 | AD6: 44560 | AE6: 44560
A7: BOGOTA | B7: CUNDINAMARCA | C7: 0004-0004 | D7: 25599 | E7: TA-25-1319223 | F7: 3007082265 | G7: APERTURA | H7: CB CRECIMIENTO ALIANZA - NUEVO | I7: CUNDINAMARCA | J7: APULO | K7: DISTRICOL AUTOSERVICIO APULO | L7: REDEBAN | M7: FO-25-1859233 | N7: 45985.333 | O7: 45986.422 | R7: EJECUTADO/CANCELADO | S7: 21/11/2025 21-11 PROGRAMACION REALIZADA POR LA ALIANZA| INSTALACIÓN PROGRAMADA PARA EL 2025-11-25 | 25/11/2025 SE VISITA COMERCIO, SE VALIDA CB CERCANO Y NO SE PUEDE REALIZAR LA INSTALACIÓN. SE ESCALA CON EL COORDINADOR INDICANDO QUE SE CIERRA | T7: VISITA TECNICA | V7: TIPO III | W7: TERRESTRE | X7: ARIAS QUILINDO JULIAN | Y7: 0 | Z7: 0 | AA7: 0 | AB7: 0 | AC7: 1 | AD7: 222904 | AE7: 222904
A8: BOGOTA | B8: CUNDINAMARCA | C8: 0004-0004 | D8: 11001 | E8: TA-25-1330513 | F8: 3007082234 | G8: APERTURA | H8: CB CRECIMIENTO ALIANZA - OTRAS LISTAS | I8: CUNDINAMARCA | J8: BOGOTA | K8: PTM BOGOTA DROGUERIA SPECIALME | L8: REDEBAN | M8: FO-25-1904464 | FO-25-1884063 | N8: 45988.333 | O8: 45989.711 | R8: EJECUTADO | EJECUTADO/CANCELADO | S8: 28/11/2025 SE REALIZA INSTALACIÓN DE CB, SE INSTALA DATÁFONO, LECTORA, BASE, 40 ROLLOS, CABLE DE RED Y SE REALIZA CAPACITACIÓN DEL CB AL SR SERGIO | T8: VISITA TECNICA | U8: AE006359 | V8: TIPO I | W8: TERRESTRE | X8: ALARCON AREVALO JOHAN STIVEN | Y8: 0 | Z8: 0 | AA8: 0 | AB8: 0 | AC8: 1 | AD8: 44560 | AE8: 44560

Sheet INCIDENTES
A1: CIUDAD SEDE | B1: ZONA | C1: CENTRO DE COSTOS LINEACOM | D1: CODIGO DANE | E1: TA/CODIGO ACTIVIDAD | F1: CODIGO CB | G1: ACTIVIDAD | H1: DEPARTAMENTO | I1: CIUDAD | J1: NOMBRE DEL CB | K1: RED | L1: FO | M1: FECHA ASIGNACION A LINEA COMUNICACIONES | N1: FECHA CIERRE DEL TICKET (DD/MM/AAAA HH:MM) | O1: ACOMETIDA | P1: GRUPO_FALLA | Q1: CATEGORIA | R1: FALLA | S1: FORMATO | T1: CADENA | U1: ESTADO | V1: OBSERVACION | W1: FORMA DE ATENCION | X1: TERMINAL(ES) | Y1: TIPIFICACION | Z1: TIPO DE TRAYECTO | AA1: NOMBRE DEL TECNICO | AB1: DIAS DE VISITA | AC1: ACOMETIDA DATOS | AD1: ACOMETIDA ELÉCTRICA | AE1: SWITCH | AF1: ROUTER | AG1: VALOR DIAS ACTIVIDAD FACTURABLES | AH1: VALOR DIAS ACOMPAÑAMIENTO FACTURABLES
A2: PASTO | B2: SUROCCIDENTE Y EJE CAFETERO | C2: 0004-0003 | D2: 86568 | E2: 2958278 | F2: 3007065915 | G2: INCIDENTE | H2: PUTUMAYO | I2: PUERTO ASIS | J2: BARRIO LAS AMERICAS PUERTO ASI | K2: REDEBAN | L2: FO-25-1757311 | M2: 45960.462 | N2: 45967.49 | O2: NO | P2: USUARIO | Q2: CIERRE | R2: COMERCIO NO REALIZA CIERRE | S2: CB UNO A UNO | T2: CB UNO A UNO | U2: EJECUTADO | V2: 30/10/2025 SE ESCALA PARA VISITA. LLAMAR ANTES DE VISITAR, CONFIRMAR FALLA Y DATOS | 01/11/2025 SE DEBE REALIZAR DESPLZAMIENTO EL DIA MARTES YA QUE POR PROBLEMAS EN LA VIA HACIA PUTUMAYO NO SE PUEDE VIAJAR ESTA SEMANA. | 06/11/2025 SE INICIA DESPLAZAMIENTO HASTA EL MPO | 06/11/2025 SE REALIZA VISITA AL CB PARA REVISAR FALLA USUARIO NO PODIA REALIZAR CIERRE DE FORMA CORRECTA, SE REALIZA BORRADO DE DATÁFONO Y SE REINSTALA SOFTWARE Y VERSIÓN, SE INICIALIZA OK, SE HACE PIERNAS OK Y SE EXPLICA A USUARIA COMO DEBE REALIZAR EL CIERRE DE FORMA CORRECTA, CB OPERATIVO | W2: VISITA TECNICA | X2: 3A00G829 | Y2: TIPO IV | Z2: TERRESTRE | AA2: GUERRERO RAMIREZ OSCAR DARIO | AB2: 1 | AC2: 0 | AD2: 0 | AE2: 0 | AF2: 0 | AG2: 479590 | AH2: 479590
A3: NEIVA | B3: REMOTAS | C3: 0004-0007 | D3: 41001 | E3: 2962236 | F3: 3007031706 | G3: INCIDENTE | H3: HUILA | I3: NEIVA | J3: BARRIO CENTRO 3 NEIVA | K3: REDEBAN | L3: FO-25-1763637 | M3: 45961.383 | N3: 45962.361 | O3: NO | P3: USUARIO | Q3: USUARIOS | R3: CREACION DE USUARIOS | S3: CB UNO A UNO | T3: CB UNO A UNO | V3: 31/10/2025 SE ESCALA PARA VISITA. LLAMAR ANTES DE VISITAR, CONFIRMAR FALLA Y DATOS | 01/11/2025 EN LLAMADA CON CLIENTE JUAN CARLOS LOZADA SE REALIZA CONFIGURACIÓN DE CLAVE DE SUPERVISOR. | W3: SOPORTE TELEFONICO | Y3: TIPO I | Z3: TERRESTRE | AA3: DIAZ VARGAS JONATHAN MIGUEL | AB3: 0 | AC3: 0 | AD3: 0 | AE3: 0 | AF3: 0 | AG3: 37905 | AH3: 37905
A4: TUNJA | B4: SANTANDERES | C4: 0004-0008 | D4: 15238 | E4: 2963361 | F4: 3007026691 | G4: INCIDENTE | H4: BOYACA | I4: DUITAMA | J4: BARRIO POLIDEPORTIVO LAS AMERI | K4: REDEBAN | L4: FO-25-1765119 | M4: 45961.475 | N4: 45962.451 | O4: NO | P4: USUARIO | Q4: COMUNICACION | R4: CANAL DEL COMERCIO | S4: UNO A UNO | T4: CB UNO A UNO | V4: 31/10/2025 SE ESCALA PARA VISITA. LLAMAR ANTES DE VISITAR, CONFIRMAR FALLA Y DATOS | 01/11/2025 EN COMUNICACIÓN CON LA CLIENTE, SEÑORA ANGIE SIERRA, AL NÚMERO CELULAR 3154643408, SE CONFIRMA QUE ACTUALMENTE EL PUNTO SE ENCUENTRA OPERANDO CORRECTAMENTE, CON COMUNICACIÓN EXITOSA. LA CLIENTE INFORMA QUE NO AUTORIZA LA ATENCIÓN DE LA VISITA TÉCNICA HASTA QUE EL NUEVO PROVEEDOR DE INTERNET HAYA COMPLETADO LA INSTALACIÓN Y DEJADO OPERATIVO EL SERVICIO EN EL COMERCIO, A FIN DE REALIZAR POSTERIORMENTE LA CONFIGURACIÓN DE LAS DIRECCIONES IP DE COMUNICACIÓN PARA CADA EQUIPO. SE LE INDICA A LA CLIENTE QUE, DADO LO ANTERIOR, SE PROCEDERÁ CON EL CIERRE DE LA ORDEN ACTUAL, Y QUE DEBERÁ COMUNICARSE NUEVAMENTE PARA SOLICITAR MANTENIMIENTO UNA VEZ EL COMERCIO CUENTE CON EL NUEVO CANAL DE COMUNICACIÓN HABILITADO. | W4: SOPORTE TELEFONICO | Y4: TIPO II | Z4: TERRESTRE | AA4: ALVARADO MORENO CRISTHIAN | AB4: 0 | AC4: 0 | AD4: 0 | AE4: 0 | AF4: 0 | AG4: 37905 | AH4: 37905
A5: BUCARAMANGA | B5: SANTANDERES | C5: 0004-0008 | D5: 68855 | E5: 2964118 | F5: 3007078026 | G5: INCIDENTE | H5: SANTANDER | I5: VALLE DE SAN JOSE | J5: BARRIO SAN ROQUE VALLE DE SAN | K5: REDEBAN | L5: FO-25-1765828 | M5: 45961.538 | N5: 45965.408 | O5: NO | P5: USUARIO | Q5: LECTOR DE TARJETAS | R5: OBSTRUCCION DEL LECTOR | S5: CB UNO A UNO | T5: CB UNO A UNO | V5: 31/10/2025 SE ESCALA PARA VISITA. LLAMAR ANTES DE VISITAR, CONFIRMAR FALLA Y DATOS | 03/11/2025 SE ESTABLECE COMUNICACIÓN CON LA SEÑORA GINA AL NÚMERO 3167092023 QUIEN INFORMA QUE EL DATÁFONO NO LE LEE NINGUNA TARJETA SE LE INFORMA QUE EL DIA DE HOY NO SE CUENTA CON SOPORTE DE REDEBAN PARA PODER REALIZAR EL CAMBIO DE EQUIPO POR LO QUE SE REPROGRAMA LA ACTIVIDAD PARA EL DIA MIÉRCOLES EN EL TRANSCURSO DEL DÍA CLIENTE INFORMA QUE NO TIENE NINGÚN INCONVENIENTE | 04/11/2025 SE ESTABLECE COMUNICACIÓN CON LA SEÑORA CLAUDIA AL NÚMERO 3187317848 INFORMA QUE EL EQUIPO EL DIA DE HOY YA LE ESTA LEYENDO LAS TARJETAS SE SOLICITA FOTO DE BAUCHER COMO EVIDENCIA Y SE PROCEDE A CERRAR ORDEN | W5: SOPORTE TELEFONICO | Y5: TIPO III | Z5: TERRESTRE | AA5: BARRERA ORTEGA MARLON STWAR | AB5: 0 | AC5: 0 | AD5: 0 | AE5: 0 | AF5: 0 | AG5: 37905 | AH5: 37905
A6: CARTAGENA | B6: COSTA | C6: 0004-0001 | D6: 13001 | E6: 2965065 | F6: 3007030332 | G6: INCIDENTE | H6: BOLIVAR | I6: CARTAGENA | J6: BARRIO MANGA CARTAGENA DE INDI | K6: REDEBAN | L6: FO-25-1766919 | M6: 45961.66 | N6: 45962.411 | O6: NO | P6: USUARIO | Q6: CIERRE | R6: COMERCIO NO REALIZA CIERRE | S6: CB UNO A UNO | T6: CB UNO A UNO | U6: EJECUTADO | V6: 31/10/2025 SE ESCALA PARA VISITA. LLAMAR ANTES DE VISITAR, CONFIRMAR FALLA Y DATOS | 01/11/2025 CLIENTE PROBLEMA CON LA CLAVE DEL CIERRE SE INGRESA Y SE COLOCA NUEVAMENTE LA CLAVE SE HACEN PRUEBAS TODO OK | W6: VISITA TECNICA | X6: AB11T106 | Y6: TIPO I | Z6: TERRESTRE | AA6: CANEDO HERRERA ALEXANDER | AB6: 1 | AC6: 0 | AD6: 0 | AE6: 0 | AF6: 0 | AG6: 65960 | AH6: 65960
A7: MEDELLIN | B7: NOROCCIDENTE | C7: 0004-0005 | D7: 5148 | E7: 2966577 | F7: 3007072668 | G7: INCIDENTE | H7: ANTIOQUIA | I7: EL CARMEN DE VIBORAL | J7: SAN JOSE EL CARMEN DE VIBORAL | K7: REDEBAN | L7: FO-25-1768943 | M7: 45962.453 | N7: 45964.378 | O7: NO | P7: USUARIO | Q7: NO ENCIENDE | R7: CONEXIONES DE COMERCIO | S7: CB UNO A UNO | T7: CB UNO A UNO | V7: 01/11/2025 SE ESCALA PARA VISITA. LLAMAR ANTES DE VISITAR, CONFIRMAR FALLA Y DATOS | 03/11/2025 SE HABLA CON USUARIO Y NOS INFORMA QUE DATAFONO YA ESTÁ FUNCIONAL, NO RESPONDIA EL EQUIPO Y MOSTRABA TECLADO BLOQUEADO PERO CB YA ESTA OPERATIVO, SE CIERRA INCIENTE. | W7: SOPORTE TELEFONICO | Y7: TIPO II | Z7: TERRESTRE | AA7: RIOS CASTRILLON JUAN SEBASTIAN | AB7: 0 | AC7: 0 | AD7: 0 | AE7: 0 | AF7: 0 | AG7: 37905 | AH7: 37905
A8: BOGOTA | B8: CUNDINAMARCA | C8: 0004-0004 | D8: 11001 | E8: 2966634 | F8: 3007026555 | G8: INCIDENTE | H8: CUNDINAMARCA | I8: BOGOTA | J8: PAGAFACIL BOSA | K8: REDEBAN | L8: FO-25-1768619 | M8: 45962.428 | N8: 45962.563 | O8: NO | P8: USUARIO | Q8: MANTENIMIENTO | R8: MANTENIMIENTO GENERAL | S8: ROBUSTO | T8: PAGAFACIL | U8: EJECUTADO | V8: 01/11/2025 SE ESCALA PARA VISITA. LLAMAR ANTES DE VISITAR, CONFIRMAR FALLA Y DATOS | 01/11/2025 SE REALIZA REVISIÓN DEL CABLEADO Y SE OBSERVA QUE EL CABLE DEL PINPAD SE ENCUENTRA DESCONECTADO | W8: VISITA TECNICA | X8: 9999I348 | Y8: TIPO I | Z8: TERRESTRE | AA8: ALARCON AREVALO JOHAN STIVEN | AB8: 1 | AC8: 0 | AD8: 0 | AE8: 0 | AF8: 0 | AG8: 65960 | AH8: 65960
A9: PASTO | B9: SUROCCIDENTE Y EJE CAFETERO | C9: 0004-0003 | D9: 52001 | E9: 2966652 | F9: 3007071128 | G9: INCIDENTE | H9: NARIÑO | I9: PASTO | J9: PTM PASTO TIENDA MARTINNA | K9: REDEBAN | L9: FO-25-1768874 | M9: 45962.449 | N9: 45965.563 | O9: NO | P9: USUARIO | Q9: COMUNICACION | R9: CANAL DEL COMERCIO | S9: AGREGADOR | T9: COMCARD - PTM | V9: 01/11/2025 SE ESCALA PARA VISITA. LLAMAR ANTES DE VISITAR, CONFIRMAR FALLA Y DATOS | 01/11/2025 SE VALIDA CLIENTE VALIDARA CON PROVEEDOR DE INTERNET YA QUE TIENE PROBLEMAS CON MAS DISPOSITIVOS, PIDE QUE VALIDEMOS EL MARTES PARA REVISAR SI ES NECESARIA LA VISITA, NO LABORA FIN DE SEMANA | 04/11/2025 SE REALIZA LLAMADA TELEFÓNICA PARA CONFIRMAR VISITA,SE CONTACTA CON LA SEÑORA PAOLA GUERRERO LA CUÁL INFORMA QUE EL DÍA QUE LLAMO NO CONECTABA EL DATÁFONO A INTERNET PERO QUE AL DÍA SIGUIENTE YA FUNCIONÓ NORMALMENTE POR LO CUAL YA NO DESEA VISITA EN EL COMERCIO Y AUTORIZA CERRAR LA TA... | W9: SOPORTE TELEFONICO | Y9: TIPO I | Z9: TERRESTRE | AA9: PAZ MARTINEZ RICHARD HUMBERTO | AB9: 0 | AC9: 0 | AD9: 0 | AE9: 0 | AF9: 0 | AG9: 37905 | AH9: 37905
A10: NEIVA | B10: REMOTAS | C10: 0004-0007 | D10: 41132 | E10: 2966657 | F10: 3007037411 | G10: INCIDENTE | H10: HUILA | I10: CAMPOALEGRE | J10: BARRIO CENTRO CAMPOALEGRE 1 | K10: REDEBAN | L10: FO-25-1768868 | M10: 45962.451 | N10: 45965.628 | O10: NO | P10: USUARIO | Q10: COMUNICACION | R10: CONEXIONES DE COMERCIO | S10: UNO A UNO | T10: CB UNO A UNO | U10: EJECUTADO | V10: 01/11/2025 SE ESCALA PARA VISITA. LLAMAR ANTES DE VISITAR, CONFIRMAR FALLA Y DATOS | 03/11/2025 SIN SOPORTE DE REDEBAN PARA CAMBIO DE EQUIPO | 04/11/2025 SE REALIZA REVISIÓN DE CABLEADO ENCONTRANDO CONECTOR SUELTO DE UNA DERIVACIÓN, SE CONECTA AL MÓDEM , SE EVIDENCIA CONEXIÓN EXITOSA Y SE REALIZA PRUEBAS OK | W10: VISITA TECNICA | X10: AB00M753 | Y10: TIPO II | Z10: TERRESTRE | AA10: ANDRADE HERNANDEZ JUAN CARLOS | AB10: 1 | AC10: 0 | AD10: 0 | AE10: 0 | AF10: 0 | AG10: 163814 | AH10: 163814
A11: PASTO | B11: SUROCCIDENTE Y EJE CAFETERO | C11: 0004-0003 | D11: 52560 | E11: 2967577 | F11: 3007029267 | G11: INCIDENTE | H11: NARIÑO | I11: POTOSI | J11: BARRIO PARQUE BOLIVAR POTOSI | K11: REDEBAN | L11: FO-25-1771261 | M11: 45963.587 | N11: 45965.531 | O11: NO | P11: USUARIO | Q11: MANTENIMIENTO | R11: MANTENIMIENTO GENERAL | S11: CB UNO A UNO | T11: CB UNO A UNO | V11: 02/11/2025 SE ESCALA PARA VISITA. LLAMAR ANTES DE VISITAR, CONFIRMAR FALLA Y DATOS | 04/11/2025 SE REALIZA COMUNICACIÓN TELEFÓNICA CON EL CLIENTE PARA CONFIRMAR VISITA TÉCNICA PERO INFORMA QUE EL LE HIZO LIMPIEZA A LA IMPRESORA Y QUEDÓ FUNCIONANDO CORRECTAMENTE, INDICA QUE NO ES NECESARIO VISITAR. CLIENTE AUTORIZA CERRAR ACTIVIDAD | W11: SOPORTE TELEFONICO | Y11: TIPO II | Z11: TERRESTRE | AA11: CASTILLO HERRERA ALEX RICARDO | AB11: 0 | AC11: 0 | AD11: 0 | AE11: 0 | AF11: 0 | AG11: 37905 | AH11: 37905
A12: BOGOTA | B12: CUNDINAMARCA | C12: 0004-0004 | D12: 25126 | E12: 2967584 | F12: 3007034784 | G12: INCIDENTE | H12: CUNDINAMARCA | I12: CAJICA | J12: DISTRICOL ESCOLARES Y PAPELE 2 | K12: REDEBAN | L12: FO-25-1771260 | M12: 45963.608 | N12: 45965.631 | O12: NO | P12: USUARIO | Q12: NO ENCIENDE | R12: CONEXIONES DE COMERCIO | S12: AGREGADOR | T12: DISTRICOL | U12: EJECUTADO | V12: 02/11/2025 SE ESCALA PARA VISITA. LLAMAR ANTES DE VISITAR, CONFIRMAR FALLA Y DATOS | 02/11/2025 NO HAY SOPORTE DE ACTIVOS PARA ATENDER ACTIVIDAD | 04/11/2025 DURANTE LA VISITA TECNICA PARA ATENDER INCIDENTE REPORTADO POR CORRESPONSAL BANCARIO, CORRESPONSAL NOS INDICA QUE EL DAÑO YA FUE SOLUCIONADO, SE HACEN PRUEBAS CONFIRMANDO QUE SERVICIO SE ENCUENTRA FUNCIONAL Y OPERATIVO A CONFORMIDAD DEL CB SIN NOVEDAD EN EL INCIDENTE SALDO OK NOTA NO SE INGRESA A COMERCIO NO SE MANIPULA EQUIPOS NO SE TOMA FOTO DE PLACAS | W12: VISITA TECNICA | X12: BL01F357 | Y12: TIPO II | Z12: TERRESTRE | AA12: GALEANO SORIANO JUAN DAVID | AB12: 1 | AC12: 0 | AD12: 0 | AE12: 0 | AF12: 0 | AG12: 163814 | AH12: 163814
A13: IBAGUE | B13: REMOTAS | C13: 0004-0007 | D13: 73001 | E13: 2969545 | F13: 3007073613 | G13: INCIDENTE | H13: TOLIMA | I13: IBAGUE | J13: PTM IBAGUE MERK' ABASTO | K13: REDEBAN | L13: FO-25-1775218 | M13: 45965.387 | N13: 45966.408 | O13: NO | P13: USUARIO | Q13: COMUNICACION | R13: CANAL DEL COMERCIO | S13: AGREGADOR | T13: COMCARD - PTM | V13: 04/11/2025 SE ESCALA PARA VISITA. LLAMAR ANTES DE VISITAR, CONFIRMAR FALLA Y DATOS | 05/11/2025 SE COMUNICA AL NÚMERO 3142681316, LA SEÑORA SOL ESCAMILLA INDICA HABER PRESENTADO PROBLEMAS DE CONEXIÓN. SOLICITA VALIDAR NUEVAMENTE A PARTIR DE LAS 10 AM DEL DÍA DE HOY DEBIDO A QUE SE ENCUENTRA REALIZANDO COMPENSACIÓN. GESTIÓN TELEFÓNICA | 05/11/2025 SE COMUNICA AL 3142681316, EL CLIENTE INDICA HABER PRESENTADO FALLAS EN SERVICIO DE INTERNET, SE VERIFICA FUNCIONAMIENTO DEL EQUIPO OK. | W13: SOPORTE TELEFONICO | Y13: TIPO I | Z13: TERRESTRE | AA13: BARRAGAN TAFUR EDWIN ESTEBAN | AB13: 0 | AC13: 0 | AD13: 0 | AE13: 0 | AF13: 0 | AG13: 37905 | AH13: 37905
A14: CARTAGENA | B14: COSTA | C14: 0004-0001 | D14: 13244 | E14: 2970043 | F14: 3007017580 | G14: INCIDENTE | H14: BOLIVAR | I14: EL CARMEN DE BOLIVAR | J14: BARRIO CENTRO II EL CARMEN DE | K14: REDEBAN | L14: FO-25-1775337 | M14: 45965.408 | N14: 45968.389 | O14: NO | P14: USUARIO | Q14: COMUNICACION | R14: CANAL DEL COMERCIO | S14: CB UNO A UNO | T14: CB UNO A UNO | U14: EJECUTADO / CANCELADO | V14: 04/11/2025 SE ESCALA PARA VISITA. LLAMAR ANTES DE VISITAR, CONFIRMAR FALLA Y DATOS | 06/11/2025 SE LLEGA AL SITIO INFORMAN QUE EN EL DIA DE HOY CASUALMENTE UN CAMIÓN PASO Y ROMPIÓ EL CABLE DEL INTERNET EN EL MOMENTO NO TIENEN SERVICIO PERO SE VA VALIDAR EN SITIO UN TIEMPO SE ESPERA PARA VER SI SE RESUELVE LA NOVEDAD | 07/11/2025 SE INTENTO VALIDAR LA NOVEDAD PERO DEBIDO A QUE EL CLIENTE QUEDÓ SIN INTERNET POR QUE UN CAMIÓN ROMPIÓ EL CABLE DEL INTERNET NO FUE POSIBLE GESTIONAR LA NOVEDAD Y TAMPOCO REALIZAR PRUEBAS CON EL EQUIPO AFECTADO EL CUAL SE INTENTO PROBAR Y NO TIENE CONEXIÓN A INTERNET SE LE INDICA AL CLIENTE QUE DEBE LLAMAR NUEVAMENTE A LA LINEA CUANDO LE ARREGLEN EL DAÑO QUE TIENE CON EL PROVEEDOR DE INTERNET PARA PODER VALIDAR | W14: VISITA TECNICA | X14: 9B08Z086 | Y14: TIPO III | Z14: TERRESTRE | AA14: MARTINEZ SALGUEDO ANDRES AUGUSTO | AB14: 1 | AC14: 0 | AD14: 0 | AE14: 0 | AF14: 0 | AG14: 275728 | AH14: 275728
A15: BUCARAMANGA | B15: SANTANDERES | C15: 0004-0008 | D15: 68276 | E15: 2974237 | F15: 3007036258 | G15: INCIDENTE | H15: SANTANDER | I15: FLORIDABLANCA | J15: BARRIO ALARES FLORIDABLANCA 1 | K15: REDEBAN | L15: FO-25-1778544 | M15: 45965.67 | N15: 45966.652 | O15: NO | P15: USUARIO | Q15: COMUNICACION | R15: CANAL DEL COMERCIO | S15: CB UNO A UNO | T15: CB UNO A UNO | U15: EJECUTADO | V15: 04/11/2025 SE ESCALA PARA VISITA. LLAMAR ANTES DE VISITAR, CONFIRMAR FALLA Y DATOS | 05/11/2025 SE REALIZA VISITA, SE VÁLIDA CONEXIÓNES Y CORRESPONSAL PRESENTA ERROR DE CONEXIÓN, SE VÁLIDA CON OTRO DATÁFONO Y LA FALLA PERSISTE, SE CAMBIA DE CONEXIONES A OTROS PUERTO Y A OTRO SWICH Y AÚN CONTINÚA CON LA FALLA, SE COMPARTE INTERNET DEL CELULAR A UN PORTÁTIL SE REALIZAN PRUEBAS EXITOSA, CLIENTE PROCEDE A COMUNICARSE CON EL OPERADOR DE ETHERNET, ACTUALIZAN, SE REINICIA MODEM Y DATÁFONO EMPIEZA A OPERAR EXITOSAMENTE, SE REALIZAN PRUEBAS EXITOSA. | W15: VISITA TECNICA | X15: 9A00G111 | Y15: TIPO I | Z15: TERRESTRE | AA15: MARTINEZ FLOREZ DONIS ALBERTO | AB15: 1 | AC15: 0 | AD15: 0 | AE15: 0 | AF15: 0 | AG15: 65960 | AH15: 65960
A16: CALI | B16: SUROCCIDENTE Y EJE CAFETERO | C16: 0004-0003 | D16: 76001 | E16: 2975677 | F16: 3007081193 | G16: INCIDENTE | H16: VALLE DEL CAUCA | I16: CALI | J16: BARRIO ULPIANO LLOREDA CALI 1 | K16: REDEBAN | L16: FO-25-1780957 | M16: 45966.348 | N16: 45966.475 | O16: NO | P16: USUARIO | Q16: CIERRE | R16: COMERCIO NO REALIZA CIERRE | S16: UNO A UNO | T16: UNO A UNO | U16: EJECUTADO | V16: 05/11/2025 SE ESCALA PARA VISITA. LLAMAR ANTES DE VISITAR, CONFIRMAR FALLA Y DATOS | 05/11/2025 SE VISITA CORRESPONSAL Y SE REALIZA CIERRE Y BORRADO DE MEMORIA. TRANSACCIONES DE PRUEBA EXITOSAS. | W16: VISITA TECNICA | X16: FKZZZ652 | Y16: TIPO I | Z16: TERRESTRE | AA16: BOLAÑOS TABORDA JORGE ENRIQUE | AB16: 1 | AC16: 0 | AD16: 0 | AE16: 0 | AF16: 0 | AG16: 65960 | AH16: 65960
A17: MEDELLIN | B17: NOROCCIDENTE | C17: 0004-0005 | D17: 15572 | E17: 2978682 | F17: 3007030721 | G17: INCIDENTE | H17: BOYACA | I17: PUERTO BOYACA | J17: DISTRICOL MISCELANEA LOS CHIQU | K17: REDEBAN | L17: FO-25-1784703 | M17: 45966.55 | N17: 45968.408 | O17: NO | P17: USUARIO | Q17: LECTOR DE TARJETAS | R17: OBSTRUCCION DEL LECTOR | S17: AGREGADOR | T17: DISTRICOL | V17: 06/11/2025 SE ESCALA PARA VISITA. LLAMAR ANTES DE VISITAR, CONFIRMAR FALLA Y DATOS | 07/11/2025 SE HABLA CON EL USUARIO E INDICA QUE EL PINPAD YA ESTÁ BUENO Y EL CB ESTÁ TOTALMENTE OPERATIVO , CB OK | W17: SOPORTE TELEFONICO | Y17: TIPO IV | Z17: TERRESTRE | AA17: MONTOYA VELEZ ANDRES FELIPE | AB17: 0 | AC17: 0 | AD17: 0 | AE17: 0 | AF17: 0 | AG17: 37905 | AH17: 37905
A18: MONTERIA | B18: COSTA | C18: 0004-0001 | D18: 23001 | E18: 2980491 | F18: 3007082047 | G18: INCIDENTE | H18: CORDOBA | I18: MONTERIA | J18: DISTRICOL COFFE MARK 3 | K18: REDEBAN | L18: FO-25-1784870 | M18: 45966.7 | N18: 45967.572 | O18: NO | P18: USUARIO | Q18: COMUNICACION | R18: CANAL DEL COMERCIO | S18: AGREGADOR | T18: DISTRICOL | U18: EJECUTADO / CANCELADO | V18: 05/11/2025 SE ESCALA PARA VISITA. LLAMAR ANTES DE VISITAR, CONFIRMAR FALLA Y DATOS | 06/11/2025 SE LLEGA AL SITIO, SE ENCUENTRA CERRADO SE REALIZA LLAMADA AL CONTACTO DEL CB INDICANDO, ESPERAR 20 MINUTOS PARA LLEGAR AL PUNTO Y PODER RECIBIR LA VISITA TÉCNICA | 06/11/2025 SE LLEGA AL COMERCIO SE ENCUENTRA CERRADO, SE PROCEDE A CONTACTAR AL SEÑOR KEVIN CONTRERAS 3046700913 INDICA AL TÉCNICO ESPERAR 15 MINUTOS PARA LLEGAR AL COMERCIO Y RECIBIR LA VISITA TÉCNICA, TÉCNICO LLEVA 60 MINUTOS A QUE EL SEÑOR LLEGUE, PERO NO LLEGO AL PUNTO SE PROCEDE A DOCUMENTAR LA TAREA. VISITA FALLIDA, NO SE MANIPULA EQUIPOS | W18: VISITA TECNICA | X18: CA002291 | Y18: TIPO I | Z18: TERRESTRE | AA18: ARRAZOLA HERNANDEZ NICOLAS AUGUSTO | AB18: 1 | AC18: 0 | AD18: 0 | AE18: 0 | AF18: 0 | AG18: 65960 | AH18: 65960
A19: MEDELLIN | B19: NOROCCIDENTE | C19: 0004-0005 | D19: 5001 | E19: 2983143 | F19: 3007029997 | G19: INCIDENTE | H19: ANTIOQUIA | I19: MEDELLIN | J19: PAGAFACIL VIVA LAURELES | K19: REDEBAN | L19: FO-25-1787147 | M19: 45967.427 | N19: 45967.627 | O19: NO | P19: USUARIO | Q19: MANTENIMIENTO | R19: MANTENIMIENTO GENERAL | S19: ROBUSTO | T19: PAGAFACIL | U19: EJECUTADO | V19: 06/11/2025 SE ESCALA PARA VISITA. LLAMAR ANTES DE VISITAR, CONFIRMAR FALLA Y DATOS | 06/11/2025 SE LLAMA A CLIENTE PARA CONFIRMAR VISITA Y NOS COMENTA QUE PUEDE ATENDER A PARTIR DE LAS 2PM | 06/11/2025 SE REALIZA MANTENIMIENTO DE DATÁFONO, PRUBAS OK | W19: VISITA TECNICA | X19: BBNZZ971 | Y19: TIPO I | Z19: TERRESTRE | AA19: CARDONA MOLINA BROLIN STIVEN | AB19: 1 | AC19: 0 | AD19: 0 | AE19: 0 | AF19: 0 | AG19: 65960 | AH19: 65960
A20: MEDELLIN | B20: NOROCCIDENTE | C20: 0004-0005 | D20: 5664 | E20: 2983582 | F20: 3007048480 | G20: INCIDENTE | H20: ANTIOQUIA | I20: SAN PEDRO DE LOS MILAGROS | J20: BARRIO PARQUE SAN PEDRO DE LOS | K20: REDEBAN | L20: FO-25-1787207 | M20: 45967.457 | N20: 45968.708 | O20: NO | P20: USUARIO | Q20: COMUNICACION | R20: CANAL DEL COMERCIO | S20: CB UNO A UNO | T20: CB UNO A UNO | V20: 06/11/2025 SE ESCALA PARA VISITA. LLAMAR ANTES DE VISITAR, CONFIRMAR FALLA Y DATOS | 08/11/2025 OPERARIA INFORMA QUE LUEGO DE UN PAR DE HORAS EL EQUIPO FUNCIONO SIN PROBLEMA. CB OPERATIVO, SE CIERRA INCIDENTE. | W20: SOPORTE TELEFONICO | Y20: TIPO II | Z20: TERRESTRE | AA20: ZAPATA LOPEZ EDWARD ASDRUBAL | AB20: 0 | AC20: 0 | AD20: 0 | AE20: 0 | AF20: 0 | AG20: 37905 | AH20: 37905
A21: NEIVA | B21: REMOTAS | C21: 0004-0007 | D21: 41132 | E21: 2984757 | F21: 3007061198 | G21: INCIDENTE | H21: HUILA | I21: CAMPOALEGRE | J21: BARRIO CENTRO CAMPOALEGRE 5 | K21: REDEBAN | L21: FO-25-1790600 | M21: 45967.539 | N21: 45968.447 | O21: NO | P21: ENTIDAD | Q21: ERROR DE TRANSACCIONES | R21: TRANSACCION NO PERMITIDA | S21: CB UNO A UNO | T21: CB UNO A UNO | U21: EJECUTADO | V21: 06/11/2025 SE ESCALA PARA VISITA. LLAMAR ANTES DE VISITAR, CONFIRMAR FALLA Y DATOS | 07/11/2025 SE REALIZA VISITA AL PUNTO, CLIENTE INDICA QUE EQUIPO PRESENTABA LETRERO ROJO EN LA PANTALLA Y NO PERMITÍA HACER NINGÚNA TRANSACCIÓN SE REALIZA VALIDACIÓN EN PUNTO, SE EVIDENCIA EQUIPO SE ENCUENTRA OPERANDO CON NORMALIDAD, YA QUE EL PROBLEMA FUE UNA CAÍDANO BLOQUEA DE LA PLATAFORMA . CB OPERATIVO | W21: VISITA TECNICA | X21: 9TZZZ261 | Y21: TIPO II | Z21: TERRESTRE | AA21: DEVIA REINOSO JUAN CARLOS | AB21: 1 | AC21: 0 | AD21: 0 | AE21: 0 | AF21: 0 | AG21: 163814 | AH21: 163814
A22: MEDELLIN | B22: NOROCCIDENTE | C22: 0004-0005 | D22: 5390 | E22: 2986974 | F22: 3007063733 | G22: INCIDENTE | H22: ANTIOQUIA | I22: LA PINTADA | J22: BARRIO SECTOR EL CRUCERO LA PI | K22: REDEBAN | L22: FO-25-1793198 | M22: 45967.73 | N22: 45968.709 | O22: NO | P22: USUARIO | Q22: MANTENIMIENTO | R22: MANTENIMIENTO GENERAL | S22: CB UNO A UNO | T22: CB UNO A UNO | V22: 06/11/2025 SE ESCALA PARA VISITA. LLAMAR ANTES DE VISITAR, CONFIRMAR FALLA Y DATOS | 08/11/2025 USUARIO INFORMA QUE LUEGO DE DESCONECTAR BATERIA Y VOLVER A CONECTAR YA FUNCIONO NUEVAMENTE EL EQUIPO, SE VOLVIO A PRESENTAR LUEGO LA NOVEDAD PERO VOLVIO A SOLUCIONAR DE LA MISMA FORMA Y HOY HA ESTADO OPERANDO SIN PROBLEMA, CB OPERATIVO, SE CIERRA INCIDENTE. | W22: SOPORTE TELEFONICO | Y22: TIPO II | Z22: TERRESTRE | AA22: ZAPATA LOPEZ EDWARD ASDRUBAL | AB22: 0 | AC22: 0 | AD22: 0 | AE22: 0 | AF22: 0 | AG22: 37905 | AH22: 37905
A23: BUCARAMANGA | B23: SANTANDERES | C23: 0004-0008 | D23: 68276 | E23: 2987238 | F23: 3007045683 | G23: INCIDENTE | H23: SANTANDER | I23: FLORIDABLANCA | J23: BARRIO OASIS FLORIDABLANCA 1 | K23: REDEBAN | L23: FO-25-1793891 | M23: 45968.333 | N23: 45969.619 | O23: NO | P23: USUARIO | Q23: NO ENCIENDE | R23: CONEXIONES DE COMERCIO | S23: CB UNO A UNO | T23: CB UNO A UNO | V23: 07/11/2025 SE ESCALA PARA VISITA. LLAMAR ANTES DE VISITAR, CONFIRMAR FALLA Y DATOS | 08/11/2025 EN COMUNICACIÓN TELEFÓNICA CON SEÑOR ALEJANDRO MORÓN PARA ATENDER INCIDENTE, NOS PREGUNTA SI YO LE LLEVO EL DATÁFONO DE WOMPI LE INDICO QUE NO QUE VOY POR UNA SOLICITUD DE REDEBAN POR ALGÚN DAÑO EN EL EQUIPO, PERO NOS INDICA QUE EL PENSABA QUE YO LE IBA A INSTALAR YLS NUEVA TECNOLOGÍA POR LO TANTO INDICA QUE POR ESTE MOTIVO ERA LA LLAMADA ENTONCES CANCELA LA VISITA TÉCNICA | W23: SOPORTE TELEFONICO | Y23: TIPO I | Z23: TERRESTRE | AA23: PEÑA DIAZ IVAN YESID | AB23: 0 | AC23: 0 | AD23: 0 | AE23: 0 | AF23: 0 | AG23: 37905 | AH23: 37905
A24: PEREIRA | B24: SUROCCIDENTE Y EJE CAFETERO | C24: 0004-0002 | D24: 66001 | E24: 2988056 | F24: 3007017109 | G24: INCIDENTE | H24: RISARALDA | I24: PEREIRA | J24: BARRIO HAMBURGO PEREIRA | K24: REDEBAN | L24: FO-25-1794764 | M24: 45968.358 | N24: 45968.681 | O24: NO | P24: USUARIO | Q24: CIERRE | R24: COMERCIO NO REALIZA CIERRE | S24: CB UNO A UNO | T24: CB UNO A UNO | U24: EJECUTADO | V24: 07/11/2025 SE ESCALA PARA VISITA. LLAMAR ANTES DE VISITAR, CONFIRMAR FALLA Y DATOS | 07/11/2025 SE VISITA COMERCIO SE IDENTIFICA DATÁFONO DESCONFIGURADO SE REINSTALA APLICATIVO SE REALIZA PRUEBAS OK | W24: VISITA TECNICA | X24: AB000095 | Y24: TIPO I | Z24: TERRESTRE | AA24: LOAIZA LOPEZ JHON FREDDY | AB24: 1 | AC24: 0 | AD24: 0 | AE24: 0 | AF24: 0 | AG24: 65960 | AH24: 65960
A25: MEDELLIN | B25: NOROCCIDENTE | C25: 0004-0005 | D25: 5088 | E25: 2989510 | F25: 3007046702 | G25: INCIDENTE | H25: ANTIOQUIA | I25: BELLO | J25: DISTRICOL PAPELERIA Y MISCELAN | K25: REDEBAN | L25: FO-25-1795477 | M25: 45968.438 | N25: 45968.507 | O25: NO | P25: USUARIO | Q25: COMUNICACION | R25: CONEXIONES DE COMERCIO | S25: AGREGADOR | T25: DISTRICOL | V25: 07/11/2025 SE ESCALA PARA VISITA. LLAMAR ANTES DE VISITAR, CONFIRMAR FALLA Y DATOS | 07/11/2025 SE REALIZA CONTACTO TELEFÓNICO CON EL USUARIO PARA CONFIRMAR EL INCIDENTE PREVIAMENTE REPORTADO RELACIONADO CON EL DATÁFONO. EL USUARIO INDICA QUE LA FALLA PRESENTADA CORRESPONDÍA A PROBLEMAS DE CONEXIÓN DEL COMERCIO, NO DEL DISPOSITIVO. TRAS REALIZAR LAS VALIDACIONES PERTINENTES, SE CONFIRMA QUE EL DATÁFONO SE ENCUENTRA ACTUALMENTE OPERATIVO Y FUNCIONANDO CON NORMALIDAD | W25: SOPORTE TELEFONICO | Y25: TIPO I | Z25: TERRESTRE | AA25: MARTINEZ TOVAR OSCAR DAVID | AB25: 0 | AC25: 0 | AD25: 0 | AE25: 0 | AF25: 0 | AG25: 37905 | AH25: 37905
A26: NEIVA | B26: REMOTAS | C26: 0004-0007 | D26: 18001 | E26: 2990957 | F26: 3007053542 | G26: INCIDENTE | H26: CAQUETA | I26: FLORENCIA | J26: DISTRICOL VARIEDADES MARY | K26: REDEBAN | L26: FO-25-1796632 | M26: 45968.596 | N26: 45971.43 | O26: NO | P26: USUARIO | Q26: USUARIOS | R26: MALA MANIPULACION POS | S26: AGREGADOR | T26: DISTRICOL | U26: EJECUTADO / CANCELADO | V26: 07/11/2025 SE ESCALA PARA VISITA. LLAMAR ANTES DE VISITAR, CONFIRMAR FALLA Y DATOS | 11/11/2025 SE LLEGA AL CB Y SE CB SE ENCUENTRA TRABAJANDO CON NORMALIDAD, CLIENTE ESTÁ INCONFORME CON EL EQUIPO DESK2600 QUE SE LE DEJO INSTALADO YA QUE ELLA QUIERE ES EL DESK3500 SE LE INDICA QUE EQUIPOS DESK3500 NO SE TIENEN Y QUE EL DESK2600 QUE SE LE INSTALO ES UN EQUIPO NUEVO Y QUE SE ENCUENTRA FUNCIONANDO CON NORMALIDAD Y ESTÁ EN BUEN ESTADO. | W26: VISITA TECNICA | X26: TR0VZ619 | Y26: TIPO IV | Z26: TERRESTRE | AA26: BERMUDEZ SANCHEZ JOSE NEYBER | AB26: 1 | AC26: 0 | AD26: 0 | AE26: 0 | AF26: 0 | AG26: 479590 | AH26: 479590
A27: IBAGUE | B27: REMOTAS | C27: 0004-0007 | D27: 73001 | E27: 2992385 | F27: 3007076197 | G27: INCIDENTE | H27: TOLIMA | I27: IBAGUE | J27: DISTRICOL DROGUERIA SALUD PLUS | K27: REDEBAN | L27: FO-25-1797901 | M27: 45968.691 | N27: 45969.489 | O27: NO | P27: USUARIO | Q27: NO ENCIENDE | R27: CONEXIONES DE COMERCIO | S27: AGREGADOR | T27: DISTRICOL | U27: EJECUTADO | V27: 08/11/2025 SE VALIDA CABLE MAGIC BOX DETERIORADO, SE REEMPLAZA Y SE REALIZA PRUEBAS DE FUNCIONAMIENTO EXITOSAS. CUBRE CLAVE INSTALADO | W27: VISITA TECNICA | X27: FA0GZ489 | Y27: TIPO I | Z27: TERRESTRE | AA27: BARRAGAN TAFUR EDWIN ESTEBAN | AB27: 1 | AC27: 0 | AD27: 0 | AE27: 0 | AF27: 0 | AG27: 65960 | AH27: 65960
A28: CALI | B28: SUROCCIDENTE Y EJE CAFETERO | C28: 0004-0003 | D28: 76520 | E28: 2992927 | F28: 3007069957 | G28: INCIDENTE | H28: VALLE DEL CAUCA | I28: PALMIRA | J28: PTM PALMIRA ELECTROMUEBLES PAL | K28: REDEBAN | L28: FO-25-1798119 | M28: 45968.745 | N28: 45969.531 | O28: NO | P28: USUARIO | Q28: COMUNICACION | R28: CONEXIONES DE COMERCIO | S28: AGREGADOR | T28: COMCARD - PTM | U28: EJECUTADO | V28: 07/11/2025 SE ESCALA PARA VISITA. LLAMAR ANTES DE VISITAR, CONFIRMAR FALLA Y DATOS | 08/11/2025 SE LLEGA AL COMERCIO PERO EL EQUIPO ESTA FUNCIONANDO CORRECTAMENTE SE ACTUALIZA A ULTIMA VERSIÓN SE HACEN PRUEBAS Y QUEDA FUNCIONANDO CORRECTAMENTE | W28: VISITA TECNICA | X28: TV002835 A300R558 | Y28: TIPO I | Z28: TERRESTRE | AA28: CUERO RUIZ JHONNY | AB28: 1 | AC28: 0 | AD28: 0 | AE28: 0 | AF28: 0 | AG28: 65960 | AH28: 65960
A29: CALI | B29: SUROCCIDENTE Y EJE CAFETERO | C29: 0004-0003 | D29: 76001 | E29: 2993386 | F29: 3007058730 | G29: INCIDENTE | H29: VALLE DEL CAUCA | I29: CALI | J29: PTM CALI CASA DIGITAL 73 | K29: REDEBAN | L29: FO-25-1800431 | M29: 45969.499 | N29: 45971.637 | O29: NO | P29: USUARIO | Q29: MANTENIMIENTO | R29: MANTENIMIENTO GENERAL | S29: AGREGADOR | T29: COMCARD - PTM | U29: EJECUTADO / CANCELADO | V29: 08/11/2025 SE ESCALA PARA VISITA. LLAMAR ANTES DE VISITAR, CONFIRMAR FALLA Y DATOS | 09/11/2025 SE LLAMA AL CLIENTE E INDICA QUE NO SE ENCUENTRA EN EL COMERCIO QUE SI PODEMOS VISITAR EL DIA DE MAÑANA | 10/11/2025 SE LLEGA A LA DIRECCION Y SE ENCUENTRA EL CB CERRADO, AUNQUE SE INTENTO COMUNICACION NO FUE EXITOSO. | W29: VISITA TECNICA | X29: 000000 | Y29: TIPO I | Z29: TERRESTRE | AA29: TORRES GARCIA JENDRY JOSE | AB29: 1 | AC29: 0 | AD29: 0 | AE29: 0 | AF29: 0 | AG29: 65960 | AH29: 65960
A30: BUCARAMANGA | B30: SANTANDERES | C30: 0004-0008 | D30: 13744 | E30: 2993450 | F30: 3007047102 | G30: INCIDENTE | H30: BOLIVAR | I30: SIMITI | J30: BARRIO CENTRO SIMITI | K30: REDEBAN | L30: FO-25-1799544 | M30: 45969.403 | N30: 45972.727 | O30: NO | P30: USUARIO | Q30: COMUNICACION | R30: CONEXIONES DE COMERCIO | S30: CB UNO A UNO | T30: CB UNO A UNO | V30: 08/11/2025 SE ESCALA PARA VISITA. LLAMAR ANTES DE VISITAR, CONFIRMAR FALLA Y DATOS | 11/11/2025 SE ESTABLECE CONTACTO VÍA WHATSAPP CON LA SEÑORA SURLEY GUZMÁN 3170767829 YA QUE EN LA ZONA NO FUNCIONA LA RED DE LÍNEA CELULAR, LA CLIENTE NOS COMENTA QUE EL INCONVENIENTE ESTABA EN LA CONEXIÓN DEL CABLE DE RED DEL COMERCIO POR TAL MOTIVO LA CLIENTE LO CAMBIÓ Y SE RESTABLECIÓ EL SERVICIO, COMENTA TAMBIÉN QUE NO HAY NECESIDAD QUE LA VISITEMOS YA QUE EL DATÁFONO ESTÁ OPERATIVO, ADICIONAL ARGUMENTA QUE PARA ENTRAR A LA ZONA ESTÁ BASTANTE PELIGROSO YA QUE ES ZONA ROJA | W30: SOPORTE TELEFONICO | Y30: TIPO V | Z30: TERRESTRE/FLUVIAL | AA30: GONZALEZ ESTUPIÑAN YEISON WALTER ANTONIO | AB30: 0 | AC30: 0 | AD30: 0 | AE30: 0 | AF30: 0 | AG30: 37905 | AH30: 37905
A31: MEDELLIN | B31: NOROCCIDENTE | C31: 0004-0005 | D31: 5761 | E31: 2993579 | F31: 3007076161 | G31: INCIDENTE | H31: ANTIOQUIA | I31: SOPETRAN | J31: BARRIO VEREDA LLANO DE MONTANA | K31: REDEBAN | L31: FO-25-1801309 | M31: 45969.543 | N31: 45971.462 | O31: NO | P31: USUARIO | Q31: MANTENIMIENTO | R31: MANTENIMIENTO GENERAL | S31: CB UNO A UNO | T31: CB UNO A UNO | U31: EJECUTADO | V31: 08/11/2025 SE ESCALA PARA VISITA. LLAMAR ANTES DE VISITAR, CONFIRMAR FALLA Y DATOS | 10/11/2025 SE REALIZA MANTENIMIENTO Y LIMPIEZA AL DATÁFONO YA QUE NO LEÍA NINGUNA TARJETA, LUEGO DEL MATENIMIETO QUEDA FUNCIONAL, PRUEBAS OK | W31: VISITA TECNICA | X31: FA0LZ814 | Y31: TIPO II | Z31: TERRESTRE | AA31: CARDONA MOLINA BROLIN STIVEN | AB31: 1 | AC31: 0 | AD31: 0 | AE31: 0 | AF31: 0 | AG31: 163814 | AH31: 163814
A32: BUCARAMANGA | B32: SANTANDERES | C32: 0004-0008 | D32: 68307 | E32: 2994001 | F32: 3007073607 | G32: INCIDENTE | H32: SANTANDER | I32: GIRON | J32: PTM LA REPUBLICA GIRON SUPERME | K32: REDEBAN | L32: FO-25-1801883 | M32: 45970.385 | N32: 45971.342 | O32: NO | P32: USUARIO | Q32: NO ENCIENDE | R32: CONEXIONES DE COMERCIO | S32: AGREGADOR | T32: COMCARD - PTM | V32: 09/11/2025 SE ESCALA PARA VISITA. LLAMAR ANTES DE VISITAR, CONFIRMAR FALLA Y DATOS | 09/11/2025 EN COMUNICACIÓN CON EL EL SEÑOR JESÚS RUEDA RÍOS AL NÚMERO 3212449499 SE LE INDICA QUE ESTAREMOS REALIZANDO LA VISITA TÉCNICA EL DÍA 10 DE NOVIEMBRE A PARTIR DE LAS 8 AM DEBIDO A QUE EL DÍA DE HOY NO HAY SOPORTE REDEBAN PARA CAMBIO | 10/11/2025 EN COMUNICACIÓN CON EL SEÑOR JESÚS AL MOVIL 3212449499, INDICA QUE NO SE ENCUENTRA EN EL LOCAL YA QUE VA REALIZAR EL. PROCESO DE COMPENSACIÓN, NOS SUMINISTRA EL NÚMERO DE LA SEÑORITA MARGY, E INDICA QUE NO ES NECESARIO REALIZAR EL DESPLAZAMIENTO AL SITIO YA QUE EL EQUIPO EL DÍA DE HOY ESTÁ FUNCIONANDO CORRECTAMENTE. | 10/11/2025 EN COMUNICACIÓN CON LA SEÑORA MARGY AL MOVIL 3227216243, INDICA QUE NO ES NECESARIO EL DESPLAZAMIENTO AL SITIO DEBIDO A QUE EL EQUIPO EL DÍA DE HOY ESTÁ FUNCIONANDO CORRECTAMENTE, SE LE INDICA QUE SE VA REALIZAR EL CIERRE DE LA ORDEN, CLIENTE CONFORME INDICA QUE SI PRESENTE UNA NUEVA NOVEDAD LLAMARA A SOLICITAR NUEVAMENTE LA VISITA. SE LE INDICA A CLIENTE DE REALIZAR UNA PRUEBA PERO INDICA QUE NO ES POSIBLE REALIZAR TRANSACCIONES YA QUE ESTA EN PROCESO DE COMPENSACIÓN A CERO. | W32: SOPORTE TELEFONICO | Y32: TIPO I | Z32: TERRESTRE | AA32: SANTOS GONZALEZ JOHAN FABIAN | AB32: 0 | AC32: 0 | AD32: 0 | AE32: 0 | AF32: 0 | AG32: 37905 | AH32: 37905
A33: MANIZALES | B33: SUROCCIDENTE Y EJE CAFETERO | C33: 0004-0002 | D33: 17867 | E33: 2994976 | F33: 3007062494 | G33: INCIDENTE | H33: CALDAS | I33: VICTORIA | J33: DISTRICOL DONDE LUCY | K33: REDEBAN | L33: FO-25-1804475 | M33: 45971.396 | N33: 45972.709 | O33: NO | P33: USUARIO | Q33: NO ENCIENDE | R33: CONEXIONES DE COMERCIO | S33: AGREGADOR | T33: DISTRICOL | V33: 10/11/2025 SE ESCALA PARA VISITA. LLAMAR ANTES DE VISITAR, CONFIRMAR FALLA Y DATOS | 11/11/2025 SE REALIZA LLAMADA CON USUARIO PARA VALIDAR DAÑO EL CUAL INDICA QUE YA LE ESTA TRABAJANDO CON NORMALIDAD Y NO REQUIERE LA VISITA | W33: SOPORTE TELEFONICO | Y33: TIPO III | Z33: TERRESTRE | AA33: AGUIRRE HENAO RAUL EDUARDO | AB33: 0 | AC33: 0 | AD33: 0 | AE33: 0 | AF33: 0 | AG33: 37905 | AH33: 37905
A34: NEIVA | B34: REMOTAS | C34: 0004-0007 | D34: 41551 | E34: 2996005 | F34: 3007072154 | G34: INCIDENTE | H34: HUILA | I34: PITALITO | J34: DISTRICOL OPTIMERKA SAN RAFAEL | K34: REDEBAN | L34: FO-25-1805098 | M34: 45971.443 | N34: 45972.463 | O34: NO | P34: USUARIO | Q34: COMUNICACION | R34: CONEXIONES DE COMERCIO | S34: AGREGADOR | T34: DISTRICOL | U34: EJECUTADO | V34: 10/11/2025 SE ESCALA PARA VISITA. LLAMAR ANTES DE VISITAR, CONFIRMAR FALLA Y DATOS | 11/11/2025 SE REALIZA VISITA AL PUNTO, SE CORRIGE CON EL INGENIERO ENCARGADO UNA FALLA DE IP'S QUE SE PRESENTA EN EL PUNTO , SE CAMBIAN IP FIJAS PRUEBAS CB OK, CB OPERATIVO. | W34: VISITA TECNICA | X34: NN00N623 | Y34: TIPO III | Z34: TERRESTRE | AA34: DEVIA REINOSO JUAN CARLOS | AB34: 1 | AC34: 0 | AD34: 0 | AE34: 0 | AF34: 0 | AG34: 275728 | AH34: 275728
A35: MEDELLIN | B35: NOROCCIDENTE | C35: 0004-0005 | D35: 5001 | E35: 2999185 | F35: 3007030841 | G35: INCIDENTE | H35: ANTIOQUIA | I35: MEDELLIN | J35: PAPELERIA Y COMERCIALIZADORA | K35: REDEBAN | L35: FO-25-1809738 | M35: 45972.333 | N35: 45972.581 | O35: NO | P35: USUARIO | Q35: CIERRE | R35: COMERCIO NO REALIZA CIERRE | S35: AGREGADOR | T35: COMCARD - PTM | U35: EJECUTADO | V35: 11/11/2025 SE ESCALA PARA VISITA. LLAMAR ANTES DE VISITAR, CONFIRMAR FALLA Y DATOS | 11/11/2025 SE BORRA TRANSACCIONES Y RECONFIGURA SI SE LE EXPLICA AL CLIENTE CIERRE | W35: VISITA TECNICA | X35: BVZZZ224 TRZZZ883 | Y35: TIPO I | Z35: TERRESTRE | AA35: ALVAREZ ARENAS VICTOR HUGO | AB35: 1 | AC35: 0 | AD35: 0 | AE35: 0 | AF35: 0 | AG35: 65960 | AH35: 65960
A36: TUNJA | B36: SANTANDERES | C36: 0004-0008 | D36: 15176 | E36: 3001520 | F36: 3007077395 | G36: INCIDENTE | H36: BOYACA | I36: CHIQUINQUIRA | J36: BARRIO VILLA REPUBLICANA CHIQUINQUIRA | K36: REDEBAN | L36: FO-25-1810798 | M36: 45972.416 | N36: 45972.52 | O36: NO | P36: USUARIO | Q36: COMUNICACION | R36: CANAL DEL COMERCIO | S36: UNO A UNO | T36: UNO A UNO | U36: EJECUTADO | V36: 11/11/2025 SE ESCALA PARA VISITA. LLAMAR ANTES DE VISITAR, CONFIRMAR FALLA Y DATOS | 11/11/2025 SE VISITA PUNTO EVIDENCIANDO QUE LA FALLA REPORTADA ES DEBIDO AL INTERNET DEL COMERCIO ROUTER REPETIDOR DESCONFIGURADO SE REALIZAN CORRECCIONES PRUEBAS OK CLIENTE CONFORME | W36: VISITA TECNICA | X36: SAAZZ158 | Y36: TIPO III | Z36: TERRESTRE | AA36: RODRIGUEZ MURCIA YERSON IVAN | AB36: 1 | AC36: 0 | AD36: 0 | AE36: 0 | AF36: 0 | AG36: 275728 | AH36: 275728
A37: PEREIRA | B37: SUROCCIDENTE Y EJE CAFETERO | C37: 0004-0002 | D37: 66001 | E37: 3003644 | F37: 3007033989 | G37: INCIDENTE | H37: RISARALDA | I37: PEREIRA | J37: PAGAFACIL LA 14 PEREIRA | K37: REDEBAN | L37: FO-25-1813145 | M37: 45972.582 | N37: 45973.386 | O37: NO | P37: USUARIO | Q37: MANTENIMIENTO | R37: MANTENIMIENTO GENERAL | S37: ROBUSTO | T37: PAGAFACIL | U37: EJECUTADO / CANCELADO | V37: 12/11/2025 VISITAMOS COMERCIO PERO NO ES POSIBLE REALIZAR LA ACTIVIDAD YA QUE PASARON 50 MINUTOS Y EL JEFE AÚN NO AUTORIZA EL INGRESO DEL TÉCNICO, LE INDICAMOS A LA SRA MARCELA QUE SE DEBE CANCELAR YA QUE TENEMOS MÁS ACTIVIDADES POR HACER Y CUANDO NOS PUEDAN ATENDER LLAMAR NUEVAMENTE Y SOLICITAR UNA VISITA, NO FIRMAN CONTROL DE VISITA. | W37: VISITA TECNICA | Y37: TIPO I | Z37: TERRESTRE | AA37: ARROYAVE CANO MANUEL GUILLERMO | AB37: 1 | AC37: 0 | AD37: 0 | AE37: 0 | AF37: 0 | AG37: 65960 | AH37: 65960
A38: BUCARAMANGA | B38: SANTANDERES | C38: 0004-0008 | D38: 81001 | E38: 3003898 | F38: 3007079030 | G38: INCIDENTE | H38: ARAUCA | I38: ARAUCA | J38: BARRIO SAN LUCAS ARAUCA 1 | K38: REDEBAN | L38: FO-25-1813134 | M38: 45972.611 | N38: 45981.381 | O38: NO | P38: USUARIO | Q38: COMUNICACION | R38: CONEXIONES DE COMERCIO | S38: CB UNO A UNO | T38: CB UNO A UNO | U38: EJECUTADO | V38: 11/11/2025 SE ESCALA PARA VISITA. LLAMAR ANTES DE VISITAR, CONFIRMAR FALLA Y DATOS | 19/11/2025 SE ESTABLECE COMUNICACIÓN CON EL SEÑOR JUAN BELEÑO AL NÚMERO 3103204648 VIA WHATSAPP SE LE INFORMA QUE EL DIA DE MAÑANA SE ESTARA VISITANDO PARA REALIZAR EL RESPECTIVO MANTENIMIENTO DEBIDO A QUE NO SE PODIA VISITAR ANTES YA QUE NO HABIAN VUELOS DISPONIBLES Y EL ORDEN PÚBLICO EN LA ZONA ESTABA ALTERADO | 20/11/2025 SE HACE PRESENCIA EN COMERCIO SE VALIDA CONEXIONES DE RED LAS CUALES ESTAN OK SE VALIDA LA FALLA CLIENTE INFORMA QUE LOS DIAS QUE SE PRESENTO LA FALLA FUE DEBIDO A UNA CAIDA DE SEÑAL EN EL DEPARTAMENTO Y POR ESO PRESENTABA DICHO INCONVENIENTE SE TOMA REGISTRO FOTOGRÁFICO Y SE PROCEDE A CERRAR ORDEN | W38: VISITA TECNICA | X38: SASZZ605 | Y38: TIPO V | Z38: AEREO | AA38: BARRERA ORTEGA MARLON STWAR | AB38: 1 | AC38: 0 | AD38: 0 | AE38: 0 | AF38: 0 | AG38: 988463 | AH38: 988463
A39: APARTADO | B39: NOROCCIDENTE | C39: 0004-0005 | D39: 5045 | E39: 3007357 | F39: 3007064886 | G39: INCIDENTE | H39: ANTIOQUIA | I39: APARTADO | J39: DISRICOL PREMIUM CELL LA 97 | K39: REDEBAN | L39: FO-25-1816403 | M39: 45973.396 | N39: 45973.599 | O39: NO | P39: USUARIO | Q39: COMUNICACION | R39: CANAL DEL COMERCIO | S39: AGREGADOR | T39: DISTRICOL | U39: EJECUTADO | V39: 12/11/2025 SE ESCALA PARA VISITA. LLAMAR ANTES DE VISITAR, CONFIRMAR FALLA Y DATOS | 12/11/2025 ERROR DE CONEXIÓN SIN TONO, SE REPISA PARAMETRO Y SARAFONO QUEDA FUNCIONADO. | W39: VISITA TECNICA | X39: 5A002508 | Y39: TIPO I | Z39: TERRESTRE | AA39: CASTRO HENAO DANIEL ESTEBAN | AB39: 1 | AC39: 0 | AD39: 0 | AE39: 0 | AF39: 0 | AG39: 65960 | AH39: 65960
A40: MEDELLIN | B40: NOROCCIDENTE | C40: 0004-0005 | D40: 5001 | E40: 3008587 | F40: 3007038794 | G40: INCIDENTE | H40: ANTIOQUIA | I40: MEDELLIN | J40: PTM MED CHQUI | K40: REDEBAN | L40: FO-25-1817489 | M40: 45973.47 | N40: 45974.397 | O40: NO | P40: USUARIO | Q40: LECTOR DE BARRAS | R40: CAPACITACION MANIPULACION DE COMERCIO | S40: AGREGADOR | T40: COMCARD - PTM | V40: 12/11/2025 SE ESCALA PARA VISITA. LLAMAR ANTES DE VISITAR, CONFIRMAR FALLA Y DATOS | 13/11/2025 SE LLAMA AL CLIENTE Y BOS CONENTA QUE HACE 2 DÍAS NO LE FUNCIONABA EL LECTOR DE BARRAS, SE LE INDICA COMO HABITILARLO Y QUEDA OPERATIVO | W40: SOPORTE TELEFONICO | Y40: TIPO I | Z40: TERRESTRE | AA40: CARDONA MOLINA BROLIN STIVEN | AB40: 0 | AC40: 0 | AD40: 0 | AE40: 0 | AF40: 0 | AG40: 37905 | AH40: 37905
...

Sheet OC
A1: CIUDAD SEDE | B1: ZONA | C1: CENTRO DE COSTOS LINEACOM | D1: CODIGO DANE | E1: TA/CODIGO ACTIVIDAD | F1: CODIGO CB | G1: ACTIVIDAD | H1: DEPARTAMENTO | I1: CIUDAD | J1: NOMBRE DEL CB | K1: RED | L1: FO | M1: FECHA ASIGNACION A LINEA COMUNICACIONES | N1: FECHA CIERRE DEL TICKET (DD/MM/AAAA HH:MM) | O1: ACOMETIDA | P1: SOLICITUD | Q1: DESCRIPCION | R1: FORMATO | S1: CADENA | T1: ESTADO | U1: CAUSAL ESTADO | V1: OBSERVACION | W1: FORMA DE ATENCION | X1: TERMINAL(ES) | Y1: TIPIFICACION | Z1: TIPO DE TRAYECTO | AA1: NOMBRE DEL TECNICO | AB1: DIAS DE VISITA | AC1: SWITCH | AD1: ACOMETIDA DATOS | AE1: ACOMETIDA ELÉCTRICA | AF1: VALOR ACTIVIDAD | AG1: VALOR TOTAL
A2: MONTERIA | B2: COSTA | C2: 0004-0001 | D2: 23001 | E2: 14316455 | F2: 3007080792 | G2: OC TRASLADO | H2: CORDOBA | I2: MONTERIA | J2: BARRIO URBINA MONTERIA | K2: REDEBAN | L2: FO-25-1782612 | M2: 45965.703 | N2: 45967.631 | O2: NO | P2: TRASLADO | Q2: TRASLADO EXTERNO | R2: UNO A UNO | S2: UNO A UNO | T2: EJECUTADO / CANCELADO | U2: PETICIÓN USUARIO | V2: 05/11/2025 SE LLAMA A EL NUMERO 3244366733 3008019110 NO HAY COMUNICACION POR FAVOR, COMUNICARSE CON USUARIO PARA CONFIRMAR UBICACION, SOLICITUD Y PROGRAMAR VISITA TECNICA | W2: VISITA TECNICA | Y2: TIPO I | Z2: TERRESTRE | AA2: ARRAZOLA HERNANDEZ NICOLAS AUGUSTO | AB2: 1 | AC2: 0 | AD2: 0 | AE2: 0 | AF2: 65960 | AG2: 65960
A3: MANIZALES | B3: SUROCCIDENTE Y EJE CAFETERO | C3: 0004-0002 | D3: 17001 | E3: 14318975-1 | F3: 3007080031 | G3: OC TRASLADO | H3: CALDAS | I3: MANIZALES | J3: BARRIO PALERMO MANIZALES 7 | K3: REDEBAN | L3: FO-25-1782613 | M3: 45965.703 | N3: 45967.573 | O3: NO | P3: TRASLADO | Q3: TRASLADO EXTERNO | R3: UNO A UNO | S3: UNO A UNO | T3: EJECUTADO / CANCELADO | U3: PETICIÓN RED | V3: 05/11/2025 SE LLAMA A EL NUMERO 3016020848 3023843981 NO HAY COMUNICACION POR FAVOR, COMUNICARSE CON USUARIO PARA CONFIRMAR UBICACION, SOLICITUD Y PROGRAMAR VISITA TECNICA | W3: VISITA TECNICA | Y3: TIPO I | Z3: TERRESTRE | AA3: AGUIRRE HENAO RAUL EDUARDO | AB3: 1 | AC3: 0 | AD3: 0 | AE3: 0 | AF3: 65960 | AG3: 65960
A4: BOGOTA | B4: CUNDINAMARCA | C4: 0004-0004 | D4: 11001 | E4: 14375539 | F4: 3007072000 | G4: OC TRASLADO | H4: CUNDINAMARCA | I4: BOGOTA | J4: MARATU | K4: REDEBAN | L4: FO-25-1829717 | M4: 45975.516 | N4: 45980.464 | O4: NO | P4: TRASLADO | Q4: TRASLADO EXTERNO | R4: CB UNO A UNO | S4: CB UNO A UNO | T4: EJECUTADO | U4: PETICIÓN RED | V4: 14/11/2025 POR FAVOR, COMUNICARSE CON USUARIO PARA CONFIRMAR UBICACION, SOLICITUD Y PROGRAMAR VISITA TECNICA | 19/11/2025 SE LLEGA ALA DIRECCIÓN INDICADA Y NO ES POSIBLE REALIZAR EL TRASLADO A LA DIRECCIÓN CR 94 # 68 A 68 YA QUE EL EQUIPO SE BLOQUEÓ AL INICIALIZARLO, COMERCIO REALIZA LLAMADA PARA SOLICITAR EL INCIDENTE Y PODER CAMBIAR EQUIPOS. | W4: VISITA TECNICA | X4: LN00M210 | Y4: TIPO I | Z4: TERRESTRE | AA4: GARCIA PASTRANA KEVIN FERNANDO | AB4: 1 | AC4: 0 | AD4: 0 | AE4: 0 | AF4: 65960 | AG4: 65960
A5: BOGOTA | B5: CUNDINAMARCA | C5: 0004-0004 | D5: 11001 | E5: 14378101 | F5: 3007042330 | G5: OC TRASLADO | H5: CUNDINAMARCA | I5: BOGOTA | J5: BARRIO KENEDY BOGOTA | K5: REDEBAN | L5: FO-25-1833418 | FO-25-1829726 | M5: 45975.516 | N5: 45979.596 | O5: NO | P5: TRASLADO | Q5: TRASLADO EXTERNO | R5: CB UNO A UNO | S5: CB UNO A UNO | T5: EJECUTADO | EJECUTADO / CANCELADO | U5: EJECUTADO EXITOSO | V5: 18/11/2025 DURANTE LA VISITA TECNICA SE REALIZA TRASLADO DE CORRESPONSAL EN LUGARES INDICADOS POR CORRESPONSAL SIN NOVEDAD EN INSTALACIÓN PRUEBAS OK SALDO OK A CONFORMIDAD DE CORRESPONSAL | W5: VISITA TECNICA | X5: AA2ZZ072 | Y5: TIPO I | Z5: TERRESTRE | AA5: GALEANO SORIANO JUAN DAVID | AB5: 1 | AC5: 0 | AD5: 0 | AE5: 0 | AF5: 65960 | AG5: 65960
