Workbook
Name A: #REF!
Name Actividad: #REF!
Name Analistas: #REF!
Name arearesponsable: #REF!
Name CCO: #REF!
Name Clientes: #REF!
Name COORDINADOR: #REF!
Name Coordinadores: #REF!
Name DOCUMENTADOR: #REF!
Name ES: #REF!
Name ESS: #REF!
Name Estado: #REF!
Name ESTADOACTIVIDAD: #REF!
Name ESTADOS: #REF!
Name ESTADOSCIERRES: #REF!
Name Facturacion: #REF!
Name FACTURACIÓN: #REF!
Name falla: #REF!
Name Fallas: #REF!
Name Grupo_Falla: #REF!
Name inconservmanager: #REF!
Name INCUMPLIMIENTO: #REF!
Name LISTA: #REF!
Name LISTA2: #REF!
Name LOLO: #REF!
Name solicitudes: #REF!
Name Tecnicos: #REF!
Name Version: #REF!

Sheet BASE LIQUIDACION REDEBAN 2025
A1: Tipificación | B1: Implementaciones | C1: Incidentes – Ordenes de Cambio | D1: Fallida | G1: Tipificación | H1: Actividad sin cambio de datafono | J1: Actividad + adicional cambio de datafono | L1: Visita Fallida | N1: Incremento 2025
A2: TIPO I | B2: =71384.4052*(1+$N$2) -> 75096.394 | C2: =62699.6885*(1+$N$2) -> 65960.072 | D2: =35693.4343*(1+$N$2) -> 37549.493 | H2: Instalación Pinpad + HUB | I2: Segunda actividad en mismo comercio, misma visita | J2: Instalación Pinpad + HUB | K2: Segunda actividad en mismo comercio, misma visita | N2: 0.052
A3: TIPO II | B3: =155716.4408*(1+$N$2) -> 163813.7 | C3: =137802.16*(1+$N$2) -> 144967.87 | D3: =117879.8485*(1+$N$2) -> 124009.6 | G3: Tipo I | H3: =31819.23994686*(1+$N$2) -> 33473.84 | I3: =26222.67548178*(1+$N$2) -> 27586.255 | J3: =51196.46628516*(1+$N$2) -> 53858.683 | K3: =42157.66342524*(1+$N$2) -> 44349.862 | L3: =28948.10610808*(1+$N$2) -> 30453.408
A4: TIPO III | B4: =262099.6015*(1+$N$2) -> 275728.78 | C4: =262099.6015*(1+$N$2) -> 275728.78 | D4: =262099.6015*(1+$N$2) -> 275728.78 | G4: Tipo II | H4: =98014.03066668*(1+$N$2) -> 103110.76 | I4: =26222.67548178*(1+$N$2) -> 27586.255 | J4: =119562.49505524*(1+$N$2) -> 125779.74 | K4: =42157.66342524*(1+$N$2) -> 44349.862 | L4: =94765.6295813*(1+$N$2) -> 99693.442
A5: TIPO IV | B5: =479878.9419*(1+$N$2) -> 504832.65 | C5: =455882.9625*(1+$N$2) -> 479588.88 | D5: =370911.6746*(1+$N$2) -> 390199.08 | G5: Tipo III | H5: =189140.9827006*(1+$N$2) -> 198976.31 | I5: =26222.67548178*(1+$N$2) -> 27586.255 | J5: =200461.60194168*(1+$N$2) -> 210885.61 | K5: =42157.66342524*(1+$N$2) -> 44349.862 | L5: =171492.68108896*(1+$N$2) -> 180410.3
A6: Destino Aéreo | B6: =939603.5767*(1+$N$2) -> 988462.96 | C6: a partir del 5to servicio | G6: Tipo IV | H6: =461621.60109668*(1+$N$2) -> 485625.92 | I6: =26222.67548178*(1+$N$2) -> 27586.255 | J6: =461621.60109668*(1+$N$2) -> 485625.92 | K6: =42157.66342524*(1+$N$2) -> 44349.862 | L6: =461621.60109668*(1+$N$2) -> 485625.92
G7: * Tipo IV Especial Donde se requiera desplazamiento aéreo o fluvial será facturado el valor de la actividad y adicional el valor de $988.463 por cada 5 actividades de esta tipología
A8: Tarifas para día adicional de actividades:
A9: Tipificación | B9: Día adicional- menos de dos horas | C9: Medio día adicional | D9: Día adicional- más de 4 horas
A10: Tipo I | B10: =71384.4052*(1+$N$2) -> 75096.394 | C10: =133455.9267*(1+$N$2) -> 140395.63 | D10: =191225.1201*(1+$N$2) -> 201168.83 | G10: Actividad | H10: Unidad | I10: Valor Unitario
A11: Tipo II | B11: =133455.9267*(1+$N$2) -> 140395.63 | C11: =191225.1201*(1+$N$2) -> 201168.83 | D11: =257740.6152*(1+$N$2) -> 271143.13 | G11: Gestión telefónica y cierre de incidente de bloqueo | H11: Unidad | I11: =17639.19516086*(1+$N$2) -> 18556.433
A12: Tipo III | B12: =186821.7926*(1+$N$2) -> 196536.53 | C12: =248892.0824*(1+$N$2) -> 261834.47 | D12: =306662.5075*(1+$N$2) -> 322608.96 | G12: Servicio de cierre de incidente de bloqueo | H12: Unidad | I12: =4810.80785492*(1+$N$2) -> 5060.9699
A13: Tipo IV | B13: =186821.7926*(1+$N$2) -> 196536.53 | C13: =248892.0824*(1+$N$2) -> 261834.47 | D13: =306662.5075*(1+$N$2) -> 322608.96
A16: Servicio | B16: Tarifa actividad | D16: VALOR DE LA TERMINAL ADICIONAL | E16: VALOR DE INSTALACIÓN DE BASE EN "Y"
A17: Papelería – Tarifa única | B17: =34010.9321*(1+$N$2) -> 35779.501 | D17: =20537.3658*(1+$N$2) -> 21605.309 | E17: =10737.9606*(1+$N$2) -> 11296.335
A18: Papelería Tipo II - Visita técnica | B18: =64310*(1+$N$2) -> 67654.12
A19: Solución telefónica | B19: =39202.5476*(1+$N$2) -> 41241.08
A22: Traifas 2024
A23: Tipificación | B23: Implementaciones | C23: Incidentes – Ordenes de Cambio | D23: Fallida | G23: Tipificación | H23: Actividad sin cambio de datafono | J23: Actividad + adicional cambio de datafono | L23: Visita Fallida
A24: TIPO I | B24: 71384.405 | C24: 62699.688 | D24: 35693.434 | H24: Instalación Pinpad + HUB | I24: Segunda actividad en mismo comercio, misma visita | J24: Instalación Pinpad + HUB | K24: Segunda actividad en mismo comercio, misma visita
A25: TIPO II | B25: 155716.44 | C25: 137802.16 | D25: 117879.85 | G25: Tipo I | H25: 31819.24 | I25: 26222.675 | J25: 51196.466 | K25: 42157.663 | L25: 28948.106
A26: TIPO III | B26: 262099.6 | C26: 262099.6 | D26: 262099.6 | G26: Tipo II | H26: 98014.031 | I26: 26222.675 | J26: 119562.5 | K26: 42157.663 | L26: 94765.63
A27: TIPO IV | B27: 479878.94 | C27: 455882.96 | D27: 370911.67 | G27: Tipo III | H27: 189140.98 | I27: 26222.675 | J27: 200461.6 | K27: 42157.663 | L27: 171492.68
A28: Destino Aéreo | B28: 939603.58 | C28: a partir del 5to servicio | G28: Tipo IV | H28: 461621.6 | I28: 26222.675 | J28: 461621.6 | K28: 42157.663 | L28: 461621.6
G29: * Tipo IV Especial Donde se requiera desplazamiento aéreo o fluvial será facturado el valor de la actividad y adicional el valor de $939,604 por cada 5 actividades de esta tipología
A30: Tarifas para día adicional de actividades:
A31: Tipificación | B31: Día adicional- menos de dos horas | C31: Medio día adicional | D31: Día adicional- más de 4 horas
A32: Tipo I | B32: 71384.405 | C32: 133455.93 | D32: 191225.12 | G32: Actividad | H32: Unidad | I32: Valor Unitario
A33: Tipo II | B33: 133455.93 | C33: 191225.12 | D33: 257740.62 | G33: Gestión telefónica y cierre de incidente de bloqueo | H33: Unidad | I33: 17639.195
A34: Tipo III | B34: 186821.79 | C34: 248892.08 | D34: 306662.51 | G34: Servicio de cierre de incidente de bloqueo | H34: Unidad | I34: 4810.8079
A35: Tipo IV | B35: 186821.79 | C35: 248892.08 | D35: 306662.51
A38: Servicio | B38: Tarifa actividad | D38: VALOR DE LA TERMINAL ADICIONAL | E38: VALOR DE INSTALACIÓN DE BASE EN "Y"
A39: Papelería – Tarifa única | B39: 34010.932 | D39: 20537.366 | E39: 10737.961
A40: Papelería Tipo II - Visita técnica | B40: 64310
A41: Solución telefónica | B41: 39202.548

Sheet RESUMEN LIQUIDACION
B1: Fecha | C1: 45991
A3: FACTURACIÓN ACTIVIDADES REDEBAN CB BANCOLOMBIA Y AVAL
A4: =UPPER("01" & " al " & TEXT(DAY(EOMONTH(C1,0)),"00") & " de " & TEXT(C1,"MMMM") & " de " & YEAR(C1)) -> 01 AL 30 DE NOVIEMBRE DE 2025
A6: CONCEPTOS | B6: CANTIDAD | C6: TOTAL
A7: Aperturas Bancolombia | B7: =IFERROR(COUNTA(APERTURAS_BANCOLOMBIA!A:A)-1,0) -> 134 | C7: =IFERROR(SUM(APERTURAS_BANCOLOMBIA!$AC$2:$AC$1048576),0) -> 21293919
A8: Incidentes Bancolombia | B8: =IFERROR(COUNTA(INCIDENTES_BANCOLOMBIA!A:A)-1,0) -> 878 | C8: =IFERROR(SUM(INCIDENTES_BANCOLOMBIA!$AF$2:$AF$1048576),0) -> 139839906
A9: Gestión de Campo Bancolombia | B9: =IFERROR(COUNTA(OC_BANCOLOMBIA!A:A)-1,0) -> 305 | C9: =IFERROR(SUM(OC_BANCOLOMBIA!$AF$2:$AF$1048576),0) -> 50610118
A10: Soporte Papelería Bancolombia | B10: =IFERROR(COUNTA(PAPELERIA!A:A)-1,0) -> 1252 | C10: =IFERROR(SUM(PAPELERIA!$AE$2:$AE$1048576),0) -> 53508554
A11: Aperturas Aval | B11: =IFERROR(COUNTA(APERTURAS_AVAL!A:A)-1,0) -> 146 | C11: =IFERROR(SUM(APERTURAS_AVAL!$AB$2:$AB$1048576),0) -> 27825072
A12: Incidentes Aval | B12: =IFERROR(COUNTA(INCIDENTES_AVAL!A:A)-1,0) -> 275 | C12: =IFERROR(SUM(INCIDENTES_AVAL!$AD$2:$AD$1048576),0) -> 33653822
A13: Gestión de Campo Aval | B13: =IFERROR(COUNTA(OC_AVAL!A:A)-1,0) -> 78 | C13: =IFERROR(SUM(OC_AVAL!$AF$2:$AF$1048576),0) -> 13701474
A14: Aperturas BBVA | B14: 0 | C14: =IFERROR(SUM([1]APERTURAS_BBVA!$AC$2:$AC$1048576),0) -> 0
A15: Gestión de Campo BBVA | B15: 0 | C15: =IFERROR(SUM([2]OC_BBVA!$AC$2:$AC$1048576),0) -> 0
A16: Incidentes BBVA | B16: =IFERROR(COUNTA(INCIDENTES_BBVA!A:A)-1,0) -> 2 | C16: =IFERROR(SUM(INCIDENTES_BBVA!$AB$2:$AB$1048576),0) -> 289936
A17: SUBTOTAL | C17: =SUM(C7:C16) -> 340722801
A18: Iva | C18: =C17*0.19 -> 64737332
A19: TOTAL | C19: =SUM(C17:C18) -> 4.0546013e+08

Sheet Hoja1
A2: aperturas bancol
A3: Etiquetas de fila | B3: Suma de VALOR TOTAL
A4: COSTA | B4: 2932879 | C4: cc | D4: valor
A5: 0004-0001 | B5: 2932879 | C5: =A5 -> 0004-0001 | D5: =B5 -> 2932879 | H5: Etiquetas de fila | I5: Suma de valor
A6: CUNDINAMARCA | B6: 1126440 | G6: costa | H6: 0004-0001 | I6: 54167362
A7: 0004-0004 | B7: 1126440 | C7: =A7 -> 0004-0004 | D7: =B7 -> 1126440 | G7: eje | H7: 0004-0002 | I7: 11543914
A8: NOROCCIDENTE | B8: 4230581 | G8: sur | H8: 0004-0003 | I8: 51231053
A9: 0004-0005 | B9: 4230581 | C9: =A9 -> 0004-0005 | D9: =B9 -> 4230581 | G9: centro | H9: 0004-0004 | I9: 38277806
A10: REMOTAS | B10: 1152226 | G10: noroccidente | H10: 0004-0005 | I10: 82920705
A11: 0004-0007 | B11: 1152226 | C11: =A11 -> 0004-0007 | D11: =B11 -> 1152226 | G11: oriente | H11: 0004-0007 | I11: 42377442
A12: SANTANDERES | B12: 5067578 | G12: santanderes | H12: 0004-0008 | I12: 60204519
A13: 0004-0008 | B13: 5067578 | C13: =A13 -> 0004-0008 | D13: =B13 -> 5067578 | H13: Total general | I13: 340722801
A14: SUROCCIDENTE Y EJE CAFETERO | B14: 6784215
A15: 0004-0002 | B15: 464198 | C15: =A15 -> 0004-0002 | D15: =B15 -> 464198
A16: 0004-0003 | B16: 6320017 | C16: =A16 -> 0004-0003 | D16: =B16 -> 6320017
A17: Total general | B17: 21293919
A19: incidentes bancol
A20: Etiquetas de fila | B20: Suma de VALOR TOTAL
A21: COSTA | B21: 25995256
A22: 0004-0001 | B22: 25995256 | C22: =A22 -> 0004-0001 | D22: =B22 -> 25995256
A23: CUNDINAMARCA | B23: 10394203
A24: 0004-0004 | B24: 10394203 | C24: =A24 -> 0004-0004 | D24: =B24 -> 10394203
A25: NOROCCIDENTE | B25: 40490024
A26: 0004-0005 | B26: 40490024 | C26: =A26 -> 0004-0005 | D26: =B26 -> 40490024
A27: REMOTAS | B27: 15077936
A28: 0004-0007 | B28: 15077936 | C28: =A28 -> 0004-0007 | D28: =B28 -> 15077936
A29: SANTANDERES | B29: 19749698
A30: 0004-0008 | B30: 19749698 | C30: =A30 -> 0004-0008 | D30: =B30 -> 19749698
A31: SUROCCIDENTE Y EJE CAFETERO | B31: 28132789
A32: 0004-0002 | B32: 4963142 | C32: =A32 -> 0004-0002 | D32: =B32 -> 4963142
A33: 0004-0003 | B33: 23169647 | C33: =A33 -> 0004-0003 | D33: =B33 -> 23169647
A34: Total general | B34: 139839906
A37: oc bancol
A38: Etiquetas de fila | B38: Suma de VALOR TOTAL
A39: COSTA | B39: 6529016
A40: 0004-0001 | B40: 6529016 | C40: =A40 -> 0004-0001 | D40: =B40 -> 6529016
A41: CUNDINAMARCA | B41: 5550587
A42: 0004-0004 | B42: 5550587 | C42: =A42 -> 0004-0004 | D42: =B42 -> 5550587
A43: NOROCCIDENTE | B43: 11903874
A44: 0004-0005 | B44: 11903874 | C44: =A44 -> 0004-0005 | D44: =B44 -> 11903874
...

Sheet APERTURAS_BANCOLOMBIA
A1: CIUDAD SEDE | B1: ZONA | C1: CENTRO DE COSTOS LINEACOM | D1: CODIGO DANE | E1: TA/CODIGO ACTIVIDAD | F1: CODIGO CB | G1: ACTIVIDAD | H1: TIPO DE APERTURA | I1: DEPARTAMENTO | J1: CIUDAD | K1: NOMBRE DEL CB | L1: RED | M1: FO | N1: FECHA LISTA | O1: FECHA ULTIMA ACTUALIZACION | P1: FORMATO | Q1: CADENA | R1: ESTADO | S1: OBSERVACIONES CLIENTE | T1: FORMA DE ATENCION | U1: TERMINAL(ES) | V1: TIPIFICACION | W1: TIPO DE TRAYECTO | X1: NOMBRE DEL TECNICO | Y1: DIAS DE VISITA | Z1: DIA ADICIONAL | AA1: VALOR DIAS ACTIVIDAD FACTURABLES | AB1: VALOR DIAS ACOMPAÑAMIENTO FACTURABLES | AC1: VALOR TOTAL
A2: PASTO | B2: SUROCCIDENTE Y EJE CAFETERO | C2: 0004-0003 | D2: 52399 | E2: TA-25-1247989 | F2: 3007082042 | G2: APERTURA | H2: CB CRECIMIENTO ALIANZA - NUEVO | I2: NARIÑO | J2: LA UNION | K2: DISTRICOL DISTRI SALSAS LOPEZ | L2: REDEBAN | M2: FO-25-1751786 | N2: 45959.86 | O2: 45965.71 | P2: AGREGADOR | Q2: DISTRICOL | R2: EJECUTADO | S2: 29/10/2025 29-10 PROGRAMACIÓN REALIZADA POR LA ALIANZA| INSTALACIÓN PROGRAMADA PARA EL 2025-11-03 | 05/11/2025 SE REALIZA INSTALACIÓN DE CORRESPONSAL BANCARIO SE INSTALA VERSION SE CONFIGURA PARÁMETROS SE INICIALIZA SE REALIZA INSTALACIÓN DE PUBLICIDAD SE DICTA CAPACITACIÓN PRUEBAS DE FUNCIONAMIENTO EXITOSAS CB QUEDA OPERATIVO | T2: VISITA TECNICA | U2: CA002301 | V2: TIPO III | W2: TERRESTRE | X2: BRAVO MADROÑERO OSCAR ESTEBAN | Y2: 1 | Z2: 0 | AA2: 275729 | AB2: 196537 | AC2: 275729
A3: PASTO | B3: SUROCCIDENTE Y EJE CAFETERO | C3: 0004-0003 | D3: 52399 | E3: TA-25-1247990 | F3: 3007082043 | G3: APERTURA | H3: CB CRECIMIENTO ALIANZA - NUEVO | I3: NARIÑO | J3: LA UNION | K3: DISTRICOL PAP Y MIS DEL PARQUE | L3: REDEBAN | M3: FO-25-1751788 | N3: 45959.861 | O3: 45966.826 | P3: AGREGADOR | Q3: DISTRICOL | R3: EJECUTADO | S3: 29/10/2025 29-10 PROGRAMACIÓN REALIZADA POR LA ALIANZA| INSTALACIÓN PROGRAMADA PARA EL 2025-11-03 | 04/11/2025 SE ESTABLECE COMUNICACIÓN CON CLIENTE SE LE INFORMA QUE POR NOVEDAD EN LA VÍA NO FUE POSIBLE REALIZAR INSTALACIÓN EL DÍA DE HOY SE PROGRAMA VISITA PARA EL DÍA DE MAÑANA 05/11 | 05/11/2025 SE LLEGA A CORRESPONSAL A REALIZAR INSTALACIÓN DE CORRESPONSAL BANCARIO SE INICIA CONFIGURACIÓN DE DATAFONO SE VERIFICA QUE PLACA NO CONCUERDA CON TERMINAL Y NOMBRE DE CB SE ESCALA A RBM REALIZAN ACTUALIZACIÓN DE TERMINAL SE CONFIGURA PARÁMETROS SE INICIALIZA SE REALIZA INSTALACIÓN DE PUBLICIDAD SE DICTA CAPACITACIÓN PRUEBAS DE FUNCIONAMIENTO EXITOSAS CB QUEDA OPERATIVO | T3: VISITA TECNICA | U3: CA002302 | V3: TIPO III | W3: TERRESTRE | X3: BRAVO MADROÑERO OSCAR ESTEBAN | Y3: 1 | Z3: 0 | AA3: 275729 | AB3: 196537 | AC3: 275729
A4: BUCARAMANGA | B4: SANTANDERES | C4: 0004-0008 | D4: 81736 | E4: TA-25-1248004 | F4: 3007082067 | G4: APERTURA | H4: CB CRECIMIENTO ALIANZA - NUEVO | I4: ARAUCA | J4: SARAVENA | K4: DISTRICOL SOLUCIONES EMPRESARI | L4: REDEBAN | M4: FO-25-1751834 | N4: 45959.71 | O4: 45965.713 | P4: AGREGADOR | Q4: DISTRICOL | R4: EJECUTADO | S4: 29/10/2025 29-10 PROGRAMACIÓN REALIZADA POR LA ALIANZA| INSTALACIÓN PROGRAMADA PARA EL 2025-11-06 | 31/10/2025 EN COMUNICACIÓN CON EL SEÑOR FIDEL AL MOVIL 3162733574, EN COMUNICACIÓN CON EL SEÑOR FIDEL AL MOVIL 3162733574, NO SE LE INFORMA QUE ESTAMOS A LA ESPERA DE LA DISPONIBILIDAD DEL VUELO, QUÉ ESTARÍAMOS VISITANDOLO PARA REALIZAR LA INSTALACIÓN DESPUÉS DEL MARTES 4 DE NOVIEMBRE | 04/11/2025 EN COMUNICACIÓN CON EL SEÑOR FIDEL AL MOVIL 3162733574, SE CONFIRMA CANAL A DE DATOS Y SERVICIO ELECTRICO OK, SE VALIDA DISPONIBILIDAD DE ATENCIÓN PARA EL DÍA DE HOY 4 DE NOVIEMBRE | 04/11/2025 INSTALACIÓN DE CB BANCOLOMBIA, INSTALACION DE DATAFONO LECTORA FUENTE CABLE PACTHCORD Y BASE FUENTE Y CUBRE CLAVE, SE CAPACITA SOBRE LA WEB SOMOS BANCOLOMBIA, SE CAPACITA SOBRE RETIROS DEPÓSITOS RECUADOS TRASFERENCIAS SALDO Y SE EXPLICA SOBRE CIERRE Y CUADRE DIARIO. | T4: VISITA TECNICA | U4: CA002315 | V4: TIPO V | W4: AEREO | X4: SANTOS GONZALEZ JOHAN FABIAN | Y4: 1 | Z4: 0 | AA4: 988463 | AB4: 196537 | AC4: 988463
A5: PASTO | B5: SUROCCIDENTE Y EJE CAFETERO | C5: 0004-0003 | D5: 86320 | E5: TA-25-1248007 | F5: 3007082049 | G5: APERTURA | H5: CB CRECIMIENTO ALIANZA - NUEVO | I5: PUTUMAYO | J5: ORITO | K5: DISTRICOL ATLANTHA CJ | L5: REDEBAN | M5: FO-25-1751838 | N5: 45959.876 | O5: 45966.828 | P5: AGREGADOR | Q5: DISTRICOL | R5: EJECUTADO | S5: 29/10/2025 29-10 PROGRAMACIÓN REALIZADA POR LA ALIANZA| INSTALACIÓN PROGRAMADA PARA EL 2025-10-31 | 31/10/2025 NO ES POSIBLE VIAJAR EL DIA DE HOY HACIA EL DEPARTAMENTO DEL PUTUMAYO POR PROBLEMAS DE TRANSPORTE SE REALIZARA DESPLAZAMIENTO AL DIA MARTES . | 05/11/2025 SE VISITA EL COMERCIO PARA DAR APERTURA AL CB, SE INSTALA DATÁFONO CON MAGIC BOX, BASE, LECTORA, SE INSTALA PUBLICIDAD, SE DEJA ROLLOS, SE HACE PRUEBAS EXCEPTO DE RECAUDO POR NO TENER RECURSOS PARA HACERLO, SE CAPACITA OK, SOMOS BANCOLOMBIA OK CB OPERATIVO | T5: VISITA TECNICA | U5: CA002316 | V5: TIPO IV | W5: TERRESTRE | X5: GUERRERO RAMIREZ OSCAR DARIO | Y5: 1 | Z5: 0 | AA5: 504833 | AB5: 196537 | AC5: 504833
A6: MEDELLIN | B6: NOROCCIDENTE | C6: 0004-0005 | D6: 5001 | E6: TA-25-1253196 | F6: 3007082082 | G6: APERTURA | H6: CB CRECIMIENTO ALIANZA - NUEVO | I6: ANTIOQUIA | J6: MEDELLIN | K6: OPRAP MALL LA FRONTERA | L6: REDEBAN | M6: FO-25-1762877 | N6: 45961.726 | O6: 45971.701 | P6: ROBUSTO | Q6: OPRAP | R6: EJECUTADO | S6: 31/10/2025 31-10 SE REALIZA LLAMADA AL CLIENTE, SE HABLA CON EL SR WILLIAM CABRERA SE VALIDA DIRECCIÓN OK, CANAL OK, DISPONIBILIDAD TOTAL, SOLICITA PROGRAMAR VISITA EL 10-11-2025 POR QUE ESE DÍA COMIENZA A OPERAR EL PUNTO - COMUNICACIÓN POR WPP | 10/11/2025 SE REALIZA INSTALACIÓN DE CB ROBUSTO OK PRUEBAS OK NO SE CAPACITACIÓN CB ROBUSTO PUBLICIDAD INTERNA OK NO TELECARGA CUBRE CLAVE OK | T6: VISITA TECNICA | U6: CA003547 | V6: TIPO I | W6: TERRESTRE | X6: PAREJA ECHAVARRIA JHON DAVID | Y6: 1 | Z6: 0 | AA6: 75096 | AB6: 75096 | AC6: 75096
A7: BOGOTA | B7: CUNDINAMARCA | C7: 0004-0004 | D7: 11001 | E7: TA-25-1253197 | F7: 3007082080 | G7: APERTURA | H7: CB CRECIMIENTO ALIANZA - NUEVO | I7: CUNDINAMARCA | J7: BOGOTA | K7: OPRAP PLAZA DE LAS AMÉRICAS II | L7: REDEBAN | M7: FO-25-1762880 | N7: 45961.831 | O7: 45965.799 | P7: ROBUSTO | Q7: OPRAP | R7: EJECUTADO | S7: 31/10/2025 31-10 SE REALIZA LLAMADA AL CLIENTE, SE HABLA CON EL SR WILLIAM CABRERA SE VALIDA DIRECCIÓN OK, CANAL OK, DISPONIBILIDAD TOTAL | SOLICITA PROGRAMAR LA VISITA PARA LAS 4 PM EL 4-11-2025 - COMUNICACIÓN POR WPP | 05/11/2025 INSTALACIÓN DE CORRESPONSAL BANCARIO ROBUSTO OPRAP. EN EL CENTRO COMERCIAL PLAZA LAS AMÉRICAS SE REALIZA INSTALACIÓN DE SEIS CAJAS PRUEBAS CON CLIENTE A CADA UNA DE ELLAS CONFIGURACIÓN ACTIVACIÓN DE SERVICIOS NO SE INSTALA PUBLICIDAD YA QUE ES UN ROBUSTO NI SE DA CAPACITACIÓN AL CLIENTE | T7: VISITA TECNICA | U7: CA003641 | V7: TIPO I | W7: TERRESTRE | X7: GOMEZ VEGA DAVID SNEYDER | Y7: 1 | Z7: 0 | AA7: 75096 | AB7: 75096 | AC7: 75096
A8: MEDELLIN | B8: NOROCCIDENTE | C8: 0004-0005 | D8: 5001 | E8: TA-25-1270687 | F8: 3007082151 | G8: APERTURA | H8: CB CRECIMIENTO ALIANZA - NUEVO | I8: ANTIOQUIA | J8: MEDELLIN | K8: DISTRICOL LA ABUNDANCIA SHALOM | L8: REDEBAN | M8: FO-25-1790280 | N8: 45968.333 | O8: 45968.644 | R8: EJECUTADO | S8: 06/11/2025 06-11 PROGRAMACION REALIZADA POR LA ALIANZA| INSTALACIÓN PROGRAMADA PARA EL 2025-11-07 | 07/11/2025 SE INSTALA EQUIPO, SE REALIZA CAPACITACIÓN SE INSTALA PUBLICIDAD SE REALIZAN PRUEBAS EXITOSAS SERVICIO OPERATIVO OK | T8: VISITA TECNICA | U8: DA000378 | V8: TIPO I | W8: TERRESTRE | X8: ZAPATA LOPEZ EDWARD ASDRUBAL | Y8: 1 | Z8: 0 | AA8: 75096 | AB8: 75096 | AC8: 75096
A9: MEDELLIN | B9: NOROCCIDENTE | C9: 0004-0005 | D9: 5001 | E9: TA-25-1270688 | F9: 3007082152 | G9: APERTURA | H9: CB CRECIMIENTO ALIANZA - NUEVO | I9: ANTIOQUIA | J9: MEDELLIN | K9: DISTRICOL MERCOFERTAS | L9: REDEBAN | M9: FO-25-1790283 | N9: 45968.333 | O9: 45971.506 | R9: EJECUTADO | S9: 06/11/2025 06-11 PROGRAMACION REALIZADA POR LA ALIANZA| INSTALACIÓN PROGRAMADA PARA EL 2025-11-08 | 07/11/2025 INSTALACIÓN SE REPROGRAMA PARA DÍA LUNES 10 POR PREVENCIÓN DE NOVEDADES QUE SE PUEDAN PRESENTAR DÍA SÁBADO. SE INFORMÓ A USUARIO Y CON SU APROBACIÓN SE ACUERDA VISITA DÍA LUNES. | 11/11/2025 SE INSTALA PUBLICIDAD Y EQUIPOS A PETICIÓN DEL USUARIO, SE DEJAN SERVICIOS FUNCIONANDO CORRECTAMENTE, CAPACITACIÓN OK. | T9: VISITA TECNICA | U9: DA000379 | V9: TIPO I | W9: TERRESTRE | X9: BARRIENTOS HERNANDEZ CRISTIAN HORACIO | Y9: 1 | Z9: 0 | AA9: 75096 | AB9: 75096 | AC9: 75096
A10: MEDELLIN | B10: NOROCCIDENTE | C10: 0004-0005 | D10: 5001 | E10: TA-25-1270689 | F10: 3007082153 | G10: APERTURA | H10: CB CRECIMIENTO ALIANZA - NUEVO | I10: ANTIOQUIA | J10: MEDELLIN | K10: PTM MEDELLIN THE ALBANS | L10: REDEBAN | M10: FO-25-1790289 | N10: 45968.333 | O10: 45971.638 | R10: EJECUTADO | S10: 06/11/2025 06-11 PROGRAMACION REALIZADA POR LA ALIANZA| INSTALACIÓN PROGRAMADA PARA EL 2025-11-08 | 07/11/2025 INSTALACIÓN SE REPROGRAMA PARA DÍA LUNES 10 POR PREVENCIÓN DE NOVEDADES QUE SE PUEDAN PRESENTAR DÍA SÁBADO. SE INFORMÓ A USUARIO Y CON SU APROBACIÓN SE ACUERDA VISITA DÍA LUNES. | 11/11/2025 SE INSTALA PUBLICIDAD Y EQUIPOS A PETICIÓN DEL USUARIO, SE DEJAN SERVICIOS FUNCIONANDO CORRECTAMENTE | T10: VISITA TECNICA | U10: DA000380-DA000313 | V10: TIPO I | W10: TERRESTRE | X10: BARRIENTOS HERNANDEZ CRISTIAN HORACIO | Y10: 1 | Z10: 0 | AA10: 75096 | AB10: 75096 | AC10: 75096
A11: MEDELLIN | B11: NOROCCIDENTE | C11: 0004-0005 | D11: 5001 | E11: TA-25-1270690 | F11: 3007082154 | G11: APERTURA | H11: CB CRECIMIENTO ALIANZA - NUEVO | I11: ANTIOQUIA | J11: MEDELLIN | K11: PTM MEDELLIN DISTRIBUIDORA A&M | L11: REDEBAN | M11: FO-25-1790295 | N11: 45968.333 | O11: 45971.749 | R11: EJECUTADO | S11: 06/11/2025 06-11 PROGRAMACION REALIZADA POR LA ALIANZA| INSTALACIÓN PROGRAMADA PARA EL 2025-11-08 | 07/11/2025 INSTALACIÓN SE REPROGRAMA PARA DÍA LUNES 10 POR PREVENCIÓN DE NOVEDADES QUE SE PUEDAN PRESENTAR DÍA SÁBADO. SE INFORMÓ A USUARIO Y CON SU APROBACIÓN SE ACUERDA VISITA DÍA LUNES. | 10/11/2025 SE REALIZÓ VISITA TÉCNICA PARA LA INSTALACIÓN DEL CORRESPONSAL BANCOLOMBIA. EL USUARIO CONFIRMÓ SU IDENTIFICACIÓN Y SE VALIDARON LAS CONDICIONES DEL LUGAR, VERIFICANDO QUE CUMPLIERA CON LOS REQUISITOS NECESARIOS PARA LA INSTALACIÓN. UNA VEZ APROBADO EL ESPACIO, SE PROCEDIÓ CON LA INSTALACIÓN DE LOS EQUIPOS CORRESPONDIENTES. SE REALIZARON PRUEBAS FUNCIONALES, TODAS CON RESULTADOS EXITOSOS, GARANTIZANDO EL CORRECTO DESEMPEÑO DE LOS DISPOSITIVOS. POSTERIORMENTE, SE BRINDÓ CAPACITACIÓN AL USUARIO SOBRE EL USO DE LA PLATAFORMA SOMOS BANCOLOMBIA, INCLUYENDO EL MANEJO DE LOS EQUIPOS Y LA EJECUCIÓN DE TRANSACCIONES. TAMBIÉN SE INSTALARON LOS AVISOS INFORMATIVOS SEGÚN LAS INDICACIONES DEL CLIENTE. FINALIZADA LA INTERVENCIÓN, EL PUNTO QUEDÓ COMPLETAMENTE OPERATIVO Y LISTO PARA INICIAR ACTIVIDADES. | T11: VISITA TECNICA | U11: DA000381- DA000314 | V11: TIPO I | W11: TERRESTRE | X11: MARTINEZ TOVAR OSCAR DAVID | Y11: 1 | Z11: 0 | AA11: 75096 | AB11: 75096 | AC11: 75096
A12: MEDELLIN | B12: NOROCCIDENTE | C12: 0004-0005 | D12: 5001 | E12: TA-25-1270692 | F12: 3007082155 | G12: APERTURA | H12: CB CRECIMIENTO ALIANZA - NUEVO | I12: ANTIOQUIA | J12: MEDELLIN | K12: PTM MEDELLIN TU CYBER ESPACIO | L12: REDEBAN | M12: FO-25-1790300 | N12: 45968.333 | O12: 45971.551 | R12: EJECUTADO | S12: 06/11/2025 06-11 PROGRAMACION REALIZADA POR LA ALIANZA| INSTALACIÓN PROGRAMADA PARA EL 2025-11-08 | 10/11/2025 INSTALACIÓN SE REPROGRAMA PARA DÍA LUNES 10 POR PREVENCIÓN DE NOVEDADES QUE SE PUEDAN PRESENTAR DÍA SÁBADO. SE INFORMÓ A USUARIO Y CON SU APROBACIÓN SE ACUERDA VISITA DÍA LUNES. | 10/11/2025 SE REALIZÓ VISITA TÉCNICA PARA LA INSTALACIÓN DEL CORRESPONSAL BANCOLOMBIA. EL USUARIO CONFIRMÓ SU IDENTIFICACIÓN Y SE VALIDARON LAS CONDICIONES DEL LUGAR, VERIFICANDO QUE CUMPLIERA CON LOS REQUISITOS NECESARIOS PARA LA INSTALACIÓN. UNA VEZ APROBADO EL ESPACIO, SE PROCEDIÓ CON LA INSTALACIÓN DE LOS EQUIPOS CORRESPONDIENTES. SE REALIZARON PRUEBAS FUNCIONALES, TODAS CON RESULTADOS EXITOSOS, GARANTIZANDO EL CORRECTO DESEMPEÑO DE LOS DISPOSITIVOS. POSTERIORMENTE, SE BRINDÓ CAPACITACIÓN AL USUARIO SOBRE EL USO DE LA PLATAFORMA SOMOS BANCOLOMBIA, INCLUYENDO EL MANEJO DE LOS EQUIPOS Y LA EJECUCIÓN DE TRANSACCIONES. TAMBIÉN SE INSTALARON LOS AVISOS INFORMATIVOS SEGÚN LAS INDICACIONES DEL CLIENTE. FINALIZADA LA INTERVENCIÓN, EL PUNTO QUEDÓ COMPLETAMENTE OPERATIVO Y LISTO PARA INICIAR ACTIVIDADES. | T12: VISITA TECNICA | U12: DA000382- DA000315 | V12: TIPO I | W12: TERRESTRE | X12: MARTINEZ TOVAR OSCAR DAVID | Y12: 1 | Z12: 0 | AA12: 75096 | AB12: 75096 | AC12: 75096
A13: MEDELLIN | B13: NOROCCIDENTE | C13: 0004-0005 | D13: 5088 | E13: TA-25-1270694 | F13: 3007082149 | G13: APERTURA | H13: CB CRECIMIENTO ALIANZA - NUEVO | I13: ANTIOQUIA | J13: BELLO | K13: DISTRICOL ENTRECERRO | L13: REDEBAN | M13: FO-25-1790303 | N13: 45968.333 | O13: 45968.671 | R13: EJECUTADO | S13: 06/11/2025 06-11 PROGRAMACION REALIZADA POR LA ALIANZA| INSTALACIÓN PROGRAMADA PARA EL 2025-11-07 | 11/11/2025 SE INSTALA PUBLICIDAD Y EQUIPOS A PETICIÓN DEL USUARIO, SE DEJAN SERVICIOS FUNCIONANDO CORRECTAMENTE Y CAPACITACIÓN OK | T13: VISITA TECNICA | U13: DA000383 | V13: TIPO I | W13: TERRESTRE | X13: BARRIENTOS HERNANDEZ CRISTIAN HORACIO | Y13: 1 | Z13: 0 | AA13: 75096 | AB13: 75096 | AC13: 75096
A14: MEDELLIN | B14: NOROCCIDENTE | C14: 0004-0005 | D14: 5212 | E14: TA-25-1270696 | F14: 3007082126 | G14: APERTURA | H14: CB CRECIMIENTO ALIANZA - NUEVO | I14: ANTIOQUIA | J14: COPACABANA | K14: DISTRICOL LIDER | L14: REDEBAN | M14: FO-25-1790312 | N14: 45968.333 | O14: 45968.56 | R14: EJECUTADO | S14: 06/11/2025 06-11 PROGRAMACION REALIZADA POR LA ALIANZA| INSTALACIÓN PROGRAMADA PARA EL 2025-11-07 | 07/11/2025 SE INSTALA PUBLICIDAD Y EQUIPOS A PETICIÓN DEL USUARIO, SERVICIOS FUNCIONANDO CORRECTAMENTE Y CAPACITACIÓN OK | T14: VISITA TECNICA | U14: DA000384 | V14: TIPO I | W14: TERRESTRE | X14: BARRIENTOS HERNANDEZ CRISTIAN HORACIO | Y14: 1 | Z14: 0 | AA14: 75096 | AB14: 75096 | AC14: 75096
A15: MEDELLIN | B15: NOROCCIDENTE | C15: 0004-0005 | D15: 5318 | E15: TA-25-1270697 | F15: 3007082150 | G15: APERTURA | H15: CB CRECIMIENTO ALIANZA - NUEVO | I15: ANTIOQUIA | J15: GUARNE | K15: DISTRICOL TECNOVA GUARNE | L15: REDEBAN | M15: FO-25-1790317 | N15: 45968.333 | O15: 45968.624 | R15: EJECUTADO | S15: 06/11/2025 06-11 PROGRAMACION REALIZADA POR LA ALIANZA| INSTALACIÓN PROGRAMADA PARA EL 2025-11-07 | 07/11/2025 SE HACE IMPLEMENTACION OK EQUIPOS OPERATIVOS PRUEBAS EXITOSAS SOMOS BANCOLOMBIA INACTIVO | T15: VISITA TECNICA | U15: DA00385 | V15: TIPO II | W15: TERRESTRE | X15: DIAZ ZABALA FRANCIS DUBAN | Y15: 1 | Z15: 0 | AA15: 163814 | AB15: 140396 | AC15: 163814
A16: BUCARAMANGA | B16: SANTANDERES | C16: 0004-0008 | D16: 13670 | E16: TA-25-1270698 | F16: 3007082141 | G16: APERTURA | H16: CB CRECIMIENTO ALIANZA - NUEVO | I16: BOLIVAR | J16: SAN PABLO | K16: DISTRICOL PAPELERIA MARIETH | L16: REDEBAN | M16: FO-25-1790322 | N16: 45968.333 | O16: 45971.733 | R16: EJECUTADO | S16: 06/11/2025 06-11 PROGRAMACION REALIZADA POR LA ALIANZA| INSTALACIÓN PROGRAMADA PARA EL 2025-11-10 | 10/11/2025 SE REALIZA APERTURA CB BANCOLOMBIA PURO, SE INSTALA AVISO EXTERIOR, FLANGED, DISPLAY, BASE, DATÁFONO, LECTOR DE BARRAS,CUBRE CLAVES, SE HACE CREACION DE USUARIOS OK, CAPACITACIÓN GENERAL COMPLETA, SOMOS BANCOLOMBIA OK, PRUEBAS OK | T16: VISITA TECNICA | U16: DA000386 | V16: TIPO V | W16: TERRESTRE/FLUVIAL | X16: GONZALEZ ESTUPIÑAN YEISON WALTER ANTONIO | Y16: 1 | Z16: 0 | AA16: 504833 | AB16: 196537 | AC16: 504833
A17: BUCARAMANGA | B17: SANTANDERES | C17: 0004-0008 | D17: 13670 | E17: TA-25-1270699 | F17: 3007082142 | G17: APERTURA | H17: CB CRECIMIENTO ALIANZA - NUEVO | I17: BOLIVAR | J17: SAN PABLO | K17: DISTRICOL SERVISMART | L17: REDEBAN | M17: FO-25-1790328 | N17: 45968.333 | O17: 45972.451 | R17: EJECUTADO | S17: 06/11/2025 06-11 PROGRAMACION REALIZADA POR LA ALIANZA| INSTALACIÓN PROGRAMADA PARA EL 2025-11-11 | 11/11/2025 SE REALIZA APERTURA CB BANCOLOMBIA PURO, SE INSTALA AVISO EXTERIOR, FLANGED, DISPLAY,BASE, DATÁFONO, LECTOR DE BARRAS, CUBRE CLAVES, SE HACE CREACION DE USUARIOS A GUSTO DEL CLIENTE, SE HACE CAPACITACIÓN GENERAL COMPLETA, SE INDICA EL MANEJO CORRECTO DEL EQUIPO, SE HACEN PRUEBAS DEJANDO TODO OK | T17: VISITA TECNICA | U17: DA000387 | V17: TIPO V | W17: TERRESTRE/FLUVIAL | X17: GONZALEZ ESTUPIÑAN YEISON WALTER ANTONIO | Y17: 1 | Z17: 0 | AA17: 504833 | AB17: 196537 | AC17: 504833
A18: BUCARAMANGA | B18: SANTANDERES | C18: 0004-0008 | D18: 13670 | E18: TA-25-1270700 | F18: 3007082143 | G18: APERTURA | H18: CB CRECIMIENTO ALIANZA - NUEVO | I18: BOLIVAR | J18: SAN PABLO | K18: DISTRICOL DAYGLAT | L18: REDEBAN | M18: FO-25-1790336 | N18: 45968.333 | O18: 45972.675 | R18: EJECUTADO | S18: 06/11/2025 06-11 PROGRAMACION REALIZADA POR LA ALIANZA| INSTALACIÓN PROGRAMADA PARA EL 2025-11-11 | 11/11/2025 SE REALIZA CONTACTO TELEFÓNICO CON LA SEÑORA LILIANA RADA AL NÚMERO DE CONTACTO 3168226289 QUIEN COMENTA QUE TIENE LA DISPONIBLIDAD PARA ATENDERNOS, ADICIONAL SE LE PREGUNTA SOBRE SI HAY CERCANIA CON OTROS CB, LA CUAL ARGUMENTA QUE NO HAY PUNTOS CERCANOS NI TAMPOCO MANEJA DE OTROS BANCOS EN EL PUNTO DONDE SE INSTALA EL CORRESPONSAL | 11/11/2025 SE REALIZA APERTURA CB BANCOLOMBIA PURO, SE INSTALA AVISO EXTERIOR, FLANGED, DISPLAY,BASE, DATÁFONO, LECTOR DE BARRAS, CUBRE CLAVES, SE HACE CREACION DE USUARIOS A GUSTO DEL CLIENTE, SE HACE CAPACITACIÓN GENERAL COMPLETA, SE INDICA EL MANEJO CORRECTO DEL EQUIPO, SE HACEN PRUEBAS DEJANDO TODO OK | T18: VISITA TECNICA | U18: DA000388 | V18: TIPO V | W18: TERRESTRE/FLUVIAL | X18: GONZALEZ ESTUPIÑAN YEISON WALTER ANTONIO | Y18: 1 | Z18: 0 | AA18: 504833 | AB18: 196537 | AC18: 504833
A19: TUNJA | B19: SANTANDERES | C19: 0004-0008 | D19: 15224 | E19: TA-25-1270701 | F19: 3007082135 | G19: APERTURA | H19: CB CRECIMIENTO ALIANZA - NUEVO | I19: BOYACA | J19: CUCAITA | K19: PTM CUCAITA M Y S COMUNICACION | L19: REDEBAN | M19: FO-25-1790341 | N19: 45968.333 | O19: 45971.976 | R19: EJECUTADO | S19: 06/11/2025 06-11 PROGRAMACION REALIZADA POR LA ALIANZA| INSTALACIÓN PROGRAMADA PARA EL 2025-11-10 | 10/11/2025 SE INTENTA COMUNICACIÓN CON EL SEÑOR NELSON SUAREZ AL NÚMERO DE CONTACTO 3213096808 PARA CONFIRMAR LA DISPONIBILIDAD PARA EL DÍA DE HOY NO SE LOGRA CONTACTO SE DEJA MENSAJE POR WHATSAPP A ESPERA DE UNA RESPUESTA. | 10/11/2025 SE CONTACTA CLIENTE QUIÉN CONFIRMA TENER LA DISPONIBILIDAD PARA ATENDER LA VISITA EL DÍA DE HOY ROUTER DE INTERNET CERCA A DONDE VA QUEDAR INSTALADO EL DATÁFONO | 10/11/2025 SE EJECUTA APERTURA BANCOLOMBIA EXITOSA RED RBM INSTALADO EQUIPOS Y PUBLICIDAD PERSONAL CAPACITADO PRUEBAS OK CLIENTE CONFORME | T19: VISITA TECNICA | U19: DA000389 | V19: TIPO II | W19: TERRESTRE | X19: RODRIGUEZ MURCIA YERSON IVAN | Y19: 1 | Z19: 0 | AA19: 163814 | AB19: 140396 | AC19: 163814
... A43: BOGOTA | B43: CUNDINAMARCA | C43: 0004-0004 | D43: 11001 | E43: TA-25-1270742 | F43: 3007082121 | G43: APERTURA | H43: CB CRECIMIENTO ALIANZA - NUEVO | I43: CUNDINAMARCA | J43: BOGOTA | K43: PTM BOGOTA SERVIFLEXORG | L43: REDEBAN | M43: FO-25-1790478 | N43: 45968.333 | O43: 45971.69 | R43: EJECUTADO | S43: 06/11/2025 06-11 PROGRAMACION REALIZADA POR LA ALIANZA| INSTALACIÓN PROGRAMADA PARA EL 2025-11-10 | 10/11/2025 SE REALIZA INSTALACIÓN DE CB BANCOLOMBIA SIN NOVEDAD PRUEBA OK SE CREAN USUARIOS Y SE HABILITAN CIERRES OK | T43: VISITA TECNICA | U43: DA000414 | V43: TIPO I | W43: TERRESTRE | X43: ORTIZ MARTINEZ STIVEN | Y43: 1 | Z43: 0 | AA43: 75096 | AB43: 75096 | AC43: 75096
A44: PASTO | B44: SUROCCIDENTE Y EJE CAFETERO | C44: 0004-0003 | D44: 52001 | E44: TA-25-1270743 | F44: 3007040058 | G44: APERTURA | H44: DATAFONO ADICIONAL - ALIANZA | I44: NARIÑO | J44: PASTO | K44: DISTRICOL DROGUERIA SAN ANDRES | L44: REDEBAN | M44: FO-25-1790484 | N44: 45968.333 | O44: 45971.671 | P44: AGREGADOR | Q44: DISTRICOL | R44: EJECUTADO | S44: 06/11/2025 06-11 PROGRAMACION REALIZADA POR LA ALIANZA| INSTALACIÓN PROGRAMADA PARA EL 2025-11-10 | 10/11/2025 SE REALIZÓ LA INSTALACIÓN DE EQUIPOS Y ACCESORIOS POR DATÁFONO ADICIONAL, SE EXPLICA EL MANEJO DE DATÁFONO Y CIERRE DE TX, CLIENTE YA CONOCE EL MANEJO DE CB SE EJECUTAN PRUEBAS TX EXITOSAS QUEDA OPERATIVO. | T44: VISITA TECNICA | U44: DA000415 | V44: TIPO I | W44: TERRESTRE | X44: REMICIO AMADO JOHN HEBER | Y44: 1 | Z44: 0 | AA44: 75096 | AB44: 75096 | AC44: 75096
A45: IBAGUE | B45: REMOTAS | C45: 0004-0007 | D45: 73001 | E45: TA-25-1270744 | F45: 3007072312 | G45: APERTURA | H45: DATAFONO ADICIONAL - ALIANZA | I45: TOLIMA | J45: IBAGUE | K45: PTM IBAGUE TIENDA FRUVER TTATT | L45: REDEBAN | M45: FO-25-1790488 | N45: 45968.333 | O45: 45969.303 | P45: AGREGADOR | Q45: COMCARD - PTM | R45: EJECUTADO | S45: 08/11/2025 SE REALIZA INSTALACIÓN DE DATÁFONO ADICIONAL, SE REALIZA PRUEBAS DE FUNCIONAMIENTO EXITOSAS. CUBRE CLAVE INSTALADO | T45: VISITA TECNICA | U45: DA000416 | V45: TIPO I | W45: TERRESTRE | X45: BARRAGAN TAFUR EDWIN ESTEBAN | Y45: 1 | Z45: 0 | AA45: 75096 | AB45: 75096 | AC45: 75096
A46: CALI | B46: SUROCCIDENTE Y EJE CAFETERO | C46: 0004-0003 | D46: 76001 | E46: TA-25-1270746 | F46: 3007034986 | G46: APERTURA | H46: DATAFONO ADICIONAL - ALIANZA | I46: VALLE DEL CAUCA | J46: CALI | K46: DISTRICOL INTEGRAL CENTRO DE S | L46: REDEBAN | M46: FO-25-1790494 | N46: 45968.333 | O46: 45968.525 | P46: AGREGADOR | Q46: DISTRICOL | R46: EJECUTADO | S46: 06/11/2025 06-11 PROGRAMACION REALIZADA POR LA ALIANZA| INSTALACIÓN PROGRAMADA PARA EL 2025-11-07 | 07/11/2025 SE LLAMA AL CLIENTE Y SE VALIDA INSTALACIÓN Y DIRECCIÓN, SE VISITA EL COMERCIO, SE INSTALA DATAFONO, LECTORA, PINPAD, MAGIC BOX EN ADICIONAL CB BANCOLOMBIA PURO, PRUEBAS OK, TELECARGA TRNA | T46: VISITA TECNICA | U46: DA000417 | V46: TIPO I | W46: TERRESTRE | X46: HERRERA MONAR GEOVANNY | Y46: 1 | Z46: 0 | AA46: 75096 | AB46: 75096 | AC46: 75096
A47: CALI | B47: SUROCCIDENTE Y EJE CAFETERO | C47: 0004-0003 | D47: 76834 | E47: TA-25-1270747 | F47: 3007081986 | G47: APERTURA | H47: CB CRECIMIENTO ALIANZA - OTRAS LISTAS | I47: VALLE DEL CAUCA | J47: TULUA | K47: PTM TULUA YUAN CITY TULUA | L47: REDEBAN | M47: FO-25-1790502 | N47: 45968.333 | O47: 45971.783 | P47: AGREGADOR | Q47: COMCARD - PTM | R47: EJECUTADO | S47: 06/11/2025 06-11 PROGRAMACION REALIZADA POR LA ALIANZA| INSTALACIÓN PROGRAMADA PARA EL 2025-11-10 | 10/11/2025 SE INSTALA EQUIPO, LECTOR Y ACCESORIOS, LUEGO SE CAPACITA Y SE INSTALA PUBLICIDAD, PRUEBAS OK | T47: VISITA TECNICA | U47: DA000418 - CA000576 | V47: TIPO II | W47: TERRESTRE | X47: PAREDES CASTILLO DIEGO | Y47: 1 | Z47: 0 | AA47: 163814 | AB47: 140396 | AC47: 163814
A48: MEDELLIN | B48: NOROCCIDENTE | C48: 0004-0005 | D48: 5001 | E48: TA-25-1288927 | F48: 3007082177 | G48: APERTURA | H48: CB CRECIMIENTO ALIANZA - NUEVO | I48: ANTIOQUIA | J48: MEDELLIN | K48: PTM MEDELLIN VARIEDADES PICACH | L48: REDEBAN | M48: FO-25-1818137 | N48: 45974.333 | O48: 45975.57 | R48: EJECUTADO | S48: 12/11/2025 12-11 PROGRAMACION REALIZADA POR LA ALIANZA| INSTALACIÓN PROGRAMADA PARA EL 2025-11-14 | 14/11/2025 INSTALACIÓN DE CB MIXTO OK PUBLICIDAD Y CAPACITACIÓN OK PRUEBAS SOLO CONSULTA DE SALDO NO HAY PARA MÁS PRUEBAS CUBRE CLAVE OK NO TELECARGA | T48: VISITA TECNICA | U48: FB001812 - FB001591 | V48: TIPO I | W48: TERRESTRE | X48: PAREJA ECHAVARRIA JHON DAVID | Y48: 1 | Z48: 0 | AA48: 75096 | AB48: 75096 | AC48: 75096
A49: MEDELLIN | B49: NOROCCIDENTE | C49: 0004-0005 | D49: 5360 | E49: TA-25-1288928 | F49: 3007082169 | G49: APERTURA | H49: CB CRECIMIENTO ALIANZA - NUEVO | I49: ANTIOQUIA | J49: ITAGUI | K49: PTM ITAGUI GRANERO SUPER HISTO | L49: REDEBAN | M49: FO-25-1818139 | N49: 45974.333 | O49: 45975.688 | R49: EJECUTADO | S49: 12/11/2025 12-11 PROGRAMACION REALIZADA POR LA ALIANZA| INSTALACIÓN PROGRAMADA PARA EL 2025-11-14 | 15/11/2025 INSTALACIÓN CB OK | T49: VISITA TECNICA | U49: FB001813-FB001543 | V49: TIPO I | W49: TERRESTRE | X49: BADEL ACUÑA LUIS ALBERTO | Y49: 1 | Z49: 0 | AA49: 75096 | AB49: 75096 | AC49: 75096
A50: MEDELLIN | B50: NOROCCIDENTE | C50: 0004-0005 | D50: 5360 | E50: TA-25-1288929 | F50: 3007082170 | G50: APERTURA | H50: CB CRECIMIENTO ALIANZA - NUEVO | I50: ANTIOQUIA | J50: ITAGUI | K50: PTM ITAGUI MOTO CLUB S&S | L50: REDEBAN | M50: FO-25-1818143 | N50: 45974.333 | O50: 45975.564 | R50: EJECUTADO | S50: 12/11/2025 12-11 PROGRAMACION REALIZADA POR LA ALIANZA| INSTALACIÓN PROGRAMADA PARA EL 2025-11-14 | 14/11/2025 INSTALACIÓN CB OK | T50: VISITA TECNICA | U50: FB001814-FB001551 | V50: TIPO I | W50: TERRESTRE | X50: BADEL ACUÑA LUIS ALBERTO | Y50: 1 | Z50: 0 | AA50: 75096 | AB50: 75096 | AC50: 75096
A51: APARTADO | B51: NOROCCIDENTE | C51: 0004-0005 | D51: 5837 | E51: TA-25-1288930 | F51: 3007082172 | G51: APERTURA | H51: CB CRECIMIENTO ALIANZA - NUEVO | I51: ANTIOQUIA | J51: TURBO | K51: PTM TURBO TIENDA ARBASU | L51: REDEBAN | M51: FO-25-1818147 | N51: 45974.333 | O51: 45975.694 | R51: EJECUTADO | S51: 12/11/2025 12-11 PROGRAMACION REALIZADA POR LA ALIANZA| INSTALACIÓN PROGRAMADA PARA EL 2025-11-14 | 15/11/2025 SE INSTALA DATAFONO,MAGIBOX.LECTORA.BASE DATAFONO, PIN PAD Y PUBLICIDAD. SE DA CAPACITACION DE MANEJO DE EQUIPO Y PLATAFORMA SOMOS BANCOLOMBIA. SE HACEN PRUEBAS DE RETIRO,CONSULTA DE SALDO,CONSIGNACON, PRUEBA DE LECTORA Y SE DEJA TODO OK | T51: VISITA TECNICA | U51: FB001815 | V51: TIPO II | W51: TERRESTRE | X51: SALDARRIAGA MIRANDA SANTIAGO | Y51: 1 | Z51: 0 | AA51: 163814 | AB51: 140396 | AC51: 163814
A52: SANTA MARTA | B52: COSTA | C52: 0004-0001 | D52: 44847 | E52: TA-25-1288931 | F52: 3007082175 | G52: APERTURA | H52: CB CRECIMIENTO ALIANZA - NUEVO | I52: LA GUAJIRA | J52: URIBIA | K52: PTM URIBIA TIENDA Y VERDURERA | L52: REDEBAN | M52: FO-25-1818152 | N52: 45974.333 | O52: 45975.704 | R52: EJECUTADO | S52: 12/11/2025 12-11 PROGRAMACION REALIZADA POR LA ALIANZA| INSTALACIÓN PROGRAMADA PARA EL 2025-11-14 | 14/11/2025 SE REALIZA APERTURA DE CB, SE INSTALA DATAFONO, LECTOR Y PUBLICIDAD,SE ENTREGAN 40 ROLLOS, SE BRINDA CAPACITACIÓN, SE REALIZAN PRUEBAS DE DEPOSITO, RETIRO, TRANSFERENCIA, CONSULTA DE SALDO, ENTRE OTRAS, DEJANDO EL SERVICIO FUNCIONAL AL 100 % | T52: VISITA TECNICA | U52: FB001816 | V52: TIPO IV | W52: TERRESTRE | X52: MONTES DIAZ JOHN FRED | Y52: 1 | Z52: 0 | AA52: 504833 | AB52: 196537 | AC52: 504833
A53: PASTO | B53: SUROCCIDENTE Y EJE CAFETERO | C53: 0004-0003 | D53: 52001 | E53: TA-25-1288932 | F53: 3007082173 | G53: APERTURA | H53: CB CRECIMIENTO ALIANZA - NUEVO | I53: NARIÑO | J53: PASTO | K53: PTM PASTO IMPACTO NARIÑO 23 | L53: REDEBAN | M53: FO-25-1818158 | N53: 45974.333 | O53: 45974.626 | R53: EJECUTADO | S53: 12/11/2025 12-11 PROGRAMACION REALIZADA POR LA ALIANZA| INSTALACIÓN PROGRAMADA PARA EL 2025-11-13 | 13/11/2025 SE REALIZÓ LA INSTALACIÓN DE EQUIPOS PUBLICIDAD Y ACCESORIOS PARA APERTURA CB BANCOLOMBIA SE DIO CAPACITACIÓN MANEJO DE DATÁFONO CB Y SOMOS BANCOLOMBIA SE EJECUTAN PRUEBAS TX EXITOSAS QUEDA OPERATIVO | T53: VISITA TECNICA | U53: FB001818 - FB001566 | V53: TIPO I | W53: TERRESTRE | X53: REMICIO AMADO JOHN HEBER | Y53: 1 | Z53: 0 | AA53: 75096 | AB53: 75096 | AC53: 75096
A54: PASTO | B54: SUROCCIDENTE Y EJE CAFETERO | C54: 0004-0003 | D54: 52215 | E54: TA-25-1288933 | F54: 3007082171 | G54: APERTURA | H54: CB CRECIMIENTO ALIANZA - NUEVO | I54: NARIÑO | J54: CORDOBA | K54: PTM CORDOBA DROGUERIA EL COMER | L54: REDEBAN | M54: FO-25-1818160 | N54: 45974.333 | O54: 45975.709 | R54: EJECUTADO | S54: 12/11/2025 12-11 PROGRAMACION REALIZADA POR LA ALIANZA| INSTALACIÓN PROGRAMADA PARA EL 2025-11-14 | 14/11/2025 SE REALIZA INSTALACIÓN DE CB. SE CAPACITA SOBRE SOMOS BANCOLOMBIA, MANEJO DE DATAFONO Y PARTE ADMINISTRATIVA. SE INSTALA AVISO EXTERIOR, FLANGER Y DISPLAY LEGAL CON INSERTO HORARIO, TARIFAS Y NÚMERO DE CB. SE ENTREGAN 40 ROLLOS. SE REALIZA PRUEBAS TX EXITOSAS. QUEDA OPERATIVO | T54: VISITA TECNICA | U54: FB001819 | V54: TIPO II | W54: TERRESTRE | X54: CASTILLO HERRERA ALEX RICARDO | Y54: 1 | Z54: 0 | AA54: 163814 | AB54: 140396 | AC54: 163814
A55: BUCARAMANGA | B55: SANTANDERES | C55: 0004-0008 | D55: 68001 | E55: TA-25-1288937 | F55: 3007082166 | G55: APERTURA | H55: CB CRECIMIENTO ALIANZA - NUEVO | I55: SANTANDER | J55: BUCARAMANGA | K55: PTM BUCARAMANGA PAPELERIA NOGA | L55: REDEBAN | M55: FO-25-1818166 | N55: 45974.333 | O55: 45974.301 | R55: EJECUTADO | S55: 12/11/2025 12-11 PROGRAMACION REALIZADA POR LA ALIANZA| INSTALACIÓN PROGRAMADA PARA EL 2025-11-13 | 13/11/2025 EN COMUNICACIÓN CON CLIENTE INDICA Q NOS ATIENDES DESPUES DE LAS 3PM Q ABRE EL LOCAL, SE CONFIRMA INTERNET OK | 14/11/2025 SE INSTALA PUBLICIDAD COMPLETA ,DATAFONO ,LECTOR , CABLES Y FUENTE DE PODER. 40 ROLLOS, BASE, SE CAPACITAN CLIENTE MANEJO CORRESPONSAL CIERRES CUADRE DIARIO COMPENSACIÓN,MANEJO DATAFONO OK , VISITA EXITOSA PRUEBAS OK | T55: VISITA TECNICA | U55: FB001820 | V55: TIPO I | W55: TERRESTRE | X55: GELVEZ MOGOLLON JOSE ELISEO | Y55: 1 | Z55: 0 | AA55: 75096 | AB55: 75096 | AC55: 75096
A56: CALI | B56: SUROCCIDENTE Y EJE CAFETERO | C56: 0004-0003 | D56: 76001 | E56: TA-25-1288939 | F56: 3007082167 | G56: APERTURA | H56: CB CRECIMIENTO ALIANZA - NUEVO | I56: VALLE DEL CAUCA | J56: CALI | K56: PTM CALI SKYNET 2.2 | L56: REDEBAN | M56: FO-25-1818168 | N56: 45974.333 | O56: 45974.61 | R56: EJECUTADO | S56: 12/11/2025 12-11 PROGRAMACION REALIZADA POR LA ALIANZA| INSTALACIÓN PROGRAMADA PARA EL 2025-11-13 | 13/11/2025 SE INSTALA EQUIPO, LECTOR Y ACCESORIOS, LUEGO SE CAPACITA Y SE INSTALA PUBLICIDAD, PRUEBAS OK | T56: VISITA TECNICA | U56: FB001821 - FJZZZ533 | V56: TIPO I | W56: TERRESTRE | X56: PAREDES CASTILLO DIEGO | Y56: 1 | Z56: 0 | AA56: 75096 | AB56: 75096 | AC56: 75096
A57: CALI | B57: SUROCCIDENTE Y EJE CAFETERO | C57: 0004-0003 | D57: 76001 | E57: TA-25-1288940 | F57: 3007082168 | G57: APERTURA | H57: CB CRECIMIENTO ALIANZA - NUEVO | I57: VALLE DEL CAUCA | J57: CALI | K57: PTM CALI VARIEDADES BLU | L57: REDEBAN | M57: FO-25-1818172 | N57: 45974.333 | O57: 45974.304 | R57: EJECUTADO | S57: 12/11/2025 12-11 PROGRAMACION REALIZADA POR LA ALIANZA| INSTALACIÓN PROGRAMADA PARA EL 2025-11-13 | 14/11/2025 SE VISITA ESTABLECIMIENTO, SE REALIZA INSTALACIÓN CORRESPONSAL BANCOLOMBIA MIXTO M. TRANSACCIONES DE PRUEBA EXITOSAS. SE CAPACITA Y SE INSTALA PUBLICIDAD COMPLETA. COMERCIO SIN AVISO PUBLICITARIO, SIN EMBARGO SI ES EL MISMO OBJETIVO COMERCIAL, LA DIRECCION COINCIDE Y LA CÁMARA DE COMERCIO TAMBIEN TIENE EL MISMO NOMBRE DE LISTA DE CHEQUEO. | T57: VISITA TECNICA | U57: FB001822, FB001570 | V57: TIPO I | W57: TERRESTRE | X57: BOLAÑOS TABORDA JORGE ENRIQUE | Y57: 1 | Z57: 0 | AA57: 75096 | AB57: 75096 | AC57: 75096
A58: CALI | B58: SUROCCIDENTE Y EJE CAFETERO | C58: 0004-0003 | D58: 76869 | E58: TA-25-1288942 | F58: 3007082176 | G58: APERTURA | H58: CB CRECIMIENTO ALIANZA - NUEVO | I58: VALLE DEL CAUCA | J58: VIJES | K58: PTM VIJES DROGAS LA SUPERIOR | L58: REDEBAN | M58: FO-25-1818178 | N58: 45974.333 | O58: 45975.713 | R58: EJECUTADO | S58: 12/11/2025 12-11 PROGRAMACION REALIZADA POR LA ALIANZA| INSTALACIÓN PROGRAMADA PARA EL 2025-11-14 | 14/11/2025 SE LLAMA AL CLIENTE Y SE VÁLIDA INSTALACIÓN, DIRECCIÓN Y DISPONIBILIDAD, SE VISITA EL COMERCIO, SE INSTALA DATAFONO, LECTORA, ACCESORIOS EN APERTURA CB BANCOLOMBIA MIXTO, SE CAPACITA, PRUEBAS OK, TELECARGA TRNA | T58: VISITA TECNICA | U58: FB001823 - FB001580 | V58: TIPO II | W58: TERRESTRE | X58: HERRERA MONAR GEOVANNY | Y58: 1 | Z58: 0 | AA58: 163814 | AB58: 140396 | AC58: 163814
A59: BOGOTA | B59: CUNDINAMARCA | C59: 0004-0004 | D59: 11001 | E59: TA-25-1288948 | F59: 3007082165 | G59: APERTURA | H59: CB CRECIMIENTO ALIANZA - NUEVO | I59: CUNDINAMARCA | J59: BOGOTA | K59: PTM BOGOTA SHOESTYLE CALZADO | L59: REDEBAN | M59: FO-25-1818181 | N59: 45974.333 | O59: 45975.578 | R59: EJECUTADO | S59: 12/11/2025 12-11 PROGRAMACION REALIZADA POR LA ALIANZA| INSTALACIÓN PROGRAMADA PARA EL 2025-11-14 | 18/11/2025 APERTURA BANCOLOMBIA OK CAPACITACIÓN OK PUBLICIDAD OK SERVICIO OPERATIVO SOLO SE REALIZAN PRUEBAS CON AN INFORMACIÓN QUE NOS SUMINISTRO EL CLIENTE YA QUE NO SE CUENTA CON TARJETA DE PRUEBAS SUMISTRADA POR LA EMPRESA | T59: VISITA TECNICA | U59: FB001824 - FB001581 | V59: TIPO I | W59: TERRESTRE | X59: HERNANDEZ NARANJO OSCAR EDUARDO | Y59: 1 | Z59: 0 | AA59: 75096 | AB59: 75096 | AC59: 75096
A60: MONTERIA | B60: COSTA | C60: 0004-0001 | D60: 23555 | E60: TA-25-1288950 | F60: 3007035595 | G60: APERTURA | H60: DATAFONO ADICIONAL - ALIANZA | I60: CORDOBA | J60: PLANETA RICA | K60: DISTRICOL MULTIYA PARQUE | L60: REDEBAN | M60: FO-25-1818189 | N60: 45974.333 | O60: 45974.616 | P60: AGREGADOR | Q60: DISTRICOL | R60: EJECUTADO | S60: 12/11/2025 12-11 PROGRAMACION REALIZADA POR LA ALIANZA| INSTALACIÓN PROGRAMADA PARA EL 2025-11-13 | 13/11/2025 SE REALIZA LA INSTALACIÓN DE DATAFONO ADICIONAL, SE LE CREAN USUARIOS OPERADOR Y ADMINISTRADOR, SE REALIZAN PRUEBAS OK, CB OPERANDO CON NORMALIDAD | T60: VISITA TECNICA | U60: FB001825 | V60: TIPO II | W60: TERRESTRE | X60: ARRAZOLA HERNANDEZ NICOLAS AUGUSTO | Y60: 1 | Z60: 0 | AA60: 163814 | AB60: 140396 | AC60: 163814
A61: SINCELEJO | B61: COSTA | C61: 0004-0001 | D61: 70708 | E61: TA-25-1288955 | F61: 3007082064 | G61: APERTURA | H61: CB CRECIMIENTO ALIANZA - OTRAS LISTAS | I61: SUCRE | J61: SAN MARCOS | K61: DISTRICOL DROGUERÍA FARMASUCRE | L61: REDEBAN | M61: FO-25-1818199 | N61: 45974.333 | O61: 45974.622 | P61: AGREGADOR | Q61: DISTRICOL | R61: EJECUTADO | S61: 12/11/2025 12-11 PROGRAMACION REALIZADA POR LA ALIANZA| INSTALACIÓN PROGRAMADA PARA EL 2025-11-13 | 13/11/2025 SE REALIZA INSTALACIÓN DE CORRESPONSAL BANCOLOMBIA PURO OK, EQUIPOS INSTALADOS OPERATIVOS OK, PRUEBAS DE TRANSACCIONES EXITOSAS, PERSONAL CAPACITADO OK, CLIENTE CB VALIDA SALDO EN CERO DESPUES DE LA INSTALACIÓN OK, CB SE DEJA OPERATIVO SIN NOVEDAD | T61: VISITA TECNICA | U61: CA001882 | V61: TIPO III | W61: TERRESTRE | X61: GONZALEZ FERRER JESUS ALEXANDER | Y61: 1 | Z61: 0 | AA61: 275729 | AB61: 196537 | AC61: 275729
A62: CALI | B62: SUROCCIDENTE Y EJE CAFETERO | C62: 0004-0003 | D62: 76111 | E62: TA-25-1296774 | F62: 3007015527 | G62: APERTURA | H62: DATAFONO ADICIONAL - ALIANZA | I62: VALLE DEL CAUCA | J62: GUADALAJARA DE BUGA | K62: MULTIPAGAS BUGA | L62: REDEBAN | M62: FO-25-1828306 | N62: 45979.333 | O62: 45979.639 | P62: ROBUSTO | Q62: MULTIPAGAS | R62: EJECUTADO | S62: 14/11/2025 14-11 SE REALIZA LLAMADA AL CLIENTE, SE HABLA CON LA SRA CINDY PAOLA ANGARITA AL NUMERO 3158673642 SE VALIDA DIRECCIÓN OK, CANAL OK, DISPONIBILIDAD TOTAL, LLAMAR EL DÍA LA INSTALACIÓN PARA CONFIRMAR VISITA (PREFERIBLEMENTE EN HORAS DE LA MAÑANA) | 18/11/2025 SE VISITA CORRESPONSAL Y SE REALIZA INSTALACIÓN DATÁFONO ADICIONAL. TRANSACCIONES DE PRUEBA EXITOSAS | T62: VISITA TECNICA | U62: FB003614 | V62: TIPO II | W62: TERRESTRE | X62: BOLAÑOS TABORDA JORGE ENRIQUE | Y62: 1 | Z62: 0 | AA62: 163814 | AB62: 140396 | AC62: 163814
A63: YOPAL | B63: REMOTAS | C63: 0004-0007 | D63: 85001 | E63: TA-25-1296775 | F63: 3007023134 | G63: APERTURA | H63: DATAFONO ADICIONAL - ALIANZA | I63: CASANARE | J63: YOPAL | K63: MULTIPAGAS YOPAL | L63: REDEBAN | M63: FO-25-1828308 | N63: 45979.333 | O63: 45980.483 | P63: ROBUSTO | Q63: MULTIPAGAS | R63: EJECUTADO | S63: 14/11/2025 14-11 SE REALIZA LLAMADA AL CLIENTE, SE HABLA CON LA SRA ADRIANA RAMIREZ AL NUMERO 3115545295 SE VALIDA DIRECCIÓN OK, CANAL OK, DISPONIBILIDAD TOTAL, LLAMAR EL DÍA LA INSTALACIÓN PARA CONFIRMAR VISITA | 19/11/2025 SE VISITA COMERCIO, SE INSTALA DATÁFONO LECTOR Y PINPAD ADICIONAL. PRUEBAS OK. OPERATIVO EL SERVICIO. CB INDICA NO REQUIERE BASE. NO SE REGISTRA TIRILLA DE TRANSFERENCIA NO SE CUENTA CON TARJETA | T63: VISITA TECNICA | U63: FB003617 | V63: TIPO I | W63: TERRESTRE | X63: BERNAL ELAICA EDGAR ALEXIS | Y63: 1 | Z63: 0 | AA63: 75096 | AB63: 75096 | AC63: 75096
...

Sheet INCIDENTES_BANCOLOMBIA
A1: CIUDAD SEDE | B1: ZONA | C1: CENTRO DE COSTOS LINEACOM | D1: CODIGO DANE | E1: TA/CODIGO ACTIVIDAD | F1: CODIGO CB | G1: ACTIVIDAD | H1: DEPARTAMENTO | I1: CIUDAD | J1: NOMBRE DEL CB | K1: RED | L1: FO | M1: FECHA ASIGNACION A LINEA COMUNICACIONES | N1: FECHA CIERRE DEL TICKET (DD/MM/AAAA HH:MM) | O1: ACOMETIDA | P1: GRUPO_FALLA | Q1: CATEGORIA | R1: FALLA | S1: FORMATO | T1: CADENA | U1: ESTADO | V1: OBSERVACION | W1: FORMA DE ATENCION | X1: TERMINAL(ES) | Y1: TIPIFICACION | Z1: TIPO DE TRAYECTO | AA1: NOMBRE DEL TECNICO | AB1: DIAS DE VISITA | AC1: DIA ADICIONAL | AD1: VALOR DIAS ACTIVIDAD FACTURABLES | AE1: VALOR DIAS ACOMPAÑAMIENTO FACTURABLES | AF1: VALOR TOTAL
A2: CALI | B2: SUROCCIDENTE Y EJE CAFETERO | C2: 0004-0003 | D2: 19075 | E2: 2940406 | F2: 3007029797 | G2: INCIDENTE | H2: CAUCA | I2: BALBOA | J2: BARRIO BELLO HORIZONTE BALBOA | K2: REDEBAN | L2: FO-25-1739872 | M2: 45957.543 | N2: 45966.606 | O2: NO | P2: HARDWARE | Q2: NO ENCIENDE | R2: DAÑO POS | S2: UNO A UNO | T2: CB UNO A UNO | U2: EJECUTADO | V2: 27/10/2025 EN COMUNICACION CON EL SR DANIELA BOTINA AL NUMERO 3112131929 SE CONFIRMAR FALLA Y DATOS . SE ESCALA PARA VISITA. | 31/10/2025 SE DDEBE VALIDAR DESPLAZAMIENTO PARA LA PROXIMA SEMANA YA QUE POR TEMAS DE ORDEN PUBLICO NO ES POSIBLE DESPLAZARSE EN EL MOMENTO. | 05/11/2025 EQUIPO NO ENCIENDE SE PROCEDE A CAMBIAR SE HACEN PRUEBAS OK TELECARGA DRNA | W2: VISITA TECNICA | X2: BL01Y339 | Y2: TIPO IV | Z2: TERRESTRE | AA2: GIMBUEL LASSO LUIS GERMAN | AB2: 1 | AC2: 0 | AD2: 479589 | AE2: 196537 | AF2: 479589
A3: MANIZALES | B3: SUROCCIDENTE Y EJE CAFETERO | C3: 0004-0002 | D3: 17513 | E3: 2949931 | F3: 3007057847 | G3: INCIDENTE | H3: CALDAS | I3: PACORA | J3: BARRIO PARQUE PRINCIPAL PACORA | K3: REDEBAN | L3: FO-25-1748333 | M3: 45959.333 | N3: 45966.716 | O3: NO | P3: HARDWARE | Q3: NO ENCIENDE | R3: DAÑO POS | S3: CB UNO A UNO | T3: CB UNO A UNO | U3: EJECUTADO | V3: 29/10/2025 SE ESCALA PARA VISITA. LLAMAR ANTES DE VISITAR, CONFIRMAR FALLA Y DATOS | 31/10/2025 SE ENCUENTRA PROBLEMAS CON LA VIA HACIA PACORA NO SE PUEDE REALIZAR DESPLAZAMIENTO , SE VALIDARA LA PROXIMA SEMANA | 05/11/2025 SE VISITA COMERCIO SE IDENTIFICA DATÁFONO SIN ENCENDER SOLO PITA SE REALIZA CAMBIO DE DATÁFONO SE REALIZA PRUEBAS OK | W3: VISITA TECNICA | X3: HA00F657 | Y3: TIPO III | Z3: TERRESTRE | AA3: LOAIZA LOPEZ JHON FREDDY | AB3: 1 | AC3: 0 | AD3: 275729 | AE3: 196537 | AF3: 275729
A4: PASTO | B4: SUROCCIDENTE Y EJE CAFETERO | C4: 0004-0003 | D4: 86749 | E4: 2952163 | F4: 3007032851 | G4: INCIDENTE | H4: PUTUMAYO | I4: SIBUNDOY | J4: BARRIO CASTELVI SIBUNDOY | K4: REDEBAN | L4: FO-25-1750657 | M4: 45959.437 | N4: 45966.622 | O4: NO | P4: HARDWARE | Q4: TECLADO | R4: DAÑO POS | S4: CB UNO A UNO | T4: CB UNO A UNO | U4: EJECUTADO | V4: 29/10/2025 SE ESCALA PARA VISITA. LLAMAR ANTES DE VISITAR, CONFIRMAR FALLA Y DATOS | 01/11/2025 SE DEBE REALIZAR DESPLAZAMIENTO LA PROXIMA SEMANA YA QUE POR PROBLEMAS EN LA VIA NO SE PUEDDE VIAJAR. | 05/11/2025 SE REALIZA CAMBIO DE DATÁFONO POR DAÑO EN TECLADO, SE RECONFIGURA OK PARÁMETROS OK Y SE REALIZAN PRUEBAS EXITOSAS DE TRANSACCIÓNES | W4: VISITA TECNICA | X4: 9A002709 | Y4: TIPO III | Z4: TERRESTRE | AA4: PAZ MARTINEZ RICHARD HUMBERTO | AB4: 1 | AC4: 0 | AD4: 275729 | AE4: 196537 | AF4: 275729
A5: MEDELLIN | B5: NOROCCIDENTE | C5: 0004-0005 | D5: 5411 | E5: 2954435 | F5: 3007019441 | G5: INCIDENTE | H5: ANTIOQUIA | I5: LIBORINA | J5: SIMON BOLIVAR LIBORINA | K5: REDEBAN | L5: FO-25-1753516 | M5: 45959.634 | N5: 45962.394 | O5: NO | P5: HARDWARE | Q5: LECTOR DE BARRAS | R5: CABLE LECTORA AVERIADO | S5: CB UNO A UNO | T5: CB UNO A UNO | U5: EJECUTADO | V5: 29/10/2025 SE ESCALA PARA VISITA. LLAMAR ANTES DE VISITAR, CONFIRMAR FALLA Y DATOS | 01/11/2025 SE CAMBIA CABLE DE LECTOR | W5: VISITA TECNICA | X5: AAAAA342 | Y5: TIPO III | Z5: TERRESTRE | AA5: CASTAÑEDA PALACIO CARLOS FELIPE | AB5: 1 | AC5: 0 | AD5: 275729 | AE5: 196537 | AF5: 275729
A6: MEDELLIN | B6: NOROCCIDENTE | C6: 0004-0005 | D6: 5861 | E6: 2956913 | F6: 3007018510 | G6: INCIDENTE | H6: ANTIOQUIA | I6: VENECIA | J6: PARQUE PPAL II VENECIA | K6: REDEBAN | L6: FO-25-1755916 | M6: 45960.372 | N6: 45962.545 | O6: NO | P6: HARDWARE | Q6: COMUNICACION | R6: DAÑO POS | S6: CB UNO A UNO | T6: CB UNO A UNO | U6: EJECUTADO | V6: 30/10/2025 SE ESCALA PARA VISITA. LLAMAR ANTES DE VISITAR, CONFIRMAR FALLA Y DATOS | 01/11/2025 CIERRE EN LA VÍA POR DERRUMBE , SE ESPERA EL ACCESO EN LA VÍA | 01/11/2025 SE REALIZA CAMBIO DE EQUIPO PORQUE NO INICIALIZA SE HACEN PRUEBAS OK | W6: VISITA TECNICA | X6: BL01Y316 | Y6: TIPO II | Z6: TERRESTRE | AA6: MONTOYA VELEZ ANDRES FELIPE | AB6: 1 | AC6: 0 | AD6: 144968 | AE6: 140396 | AF6: 144968
A7: CALI | B7: SUROCCIDENTE Y EJE CAFETERO | C7: 0004-0003 | D7: 19001 | E7: 2958591 | F7: 3007080294 | G7: INCIDENTE | H7: CAUCA | I7: POPAYAN | J7: BARRIO NUEVA FRONTERA POPAYAN | K7: REDEBAN | L7: FO-25-1758927 | M7: 45960.488 | N7: 45962.561 | O7: NO | P7: HARDWARE | Q7: CIERRE | R7: MEMORIA DEL DISPOSITIVO INSUFICIENTE | S7: UNO A UNO | T7: UNO A UNO | U7: EJECUTADO / CANCELADO | V7: 30/10/2025 SE ESCALA PARA VISITA. LLAMAR ANTES DE VISITAR, CONFIRMAR FALLA Y DATOS | 01/11/2025 SE REALIZA LLAMADA CON EL CLIENTE INFORMA SI PUEDE ATENDER TIENE PROBLEMAS CON EL CIERRE GENERAL SE LLEGA AL SITIO Y SE ENCUENTA CERRADO SE LLAMA AL CLIENTE INFORMA SE LE PRESENTO UN ASUNTO PERSONAL POR TANTO NO PUDO ATENDER SE LE INFORMA CERRAMOS EL CASO Y LLAMAR NUEVAMENTE CUANDO ESTE EN EL LOCAL | W7: VISITA TECNICA | X7: NO APLICA | Y7: TIPO III | Z7: TERRESTRE | AA7: GIMBUEL LASSO LUIS GERMAN | AB7: 1 | AC7: 0 | AD7: 275729 | AE7: 196537 | AF7: 275729
A8: CALI | B8: SUROCCIDENTE Y EJE CAFETERO | C8: 0004-0003 | D8: 19001 | E8: 2958748 | F8: 3007079319 | G8: INCIDENTE | H8: CAUCA | I8: POPAYAN | J8: BARRIO EL RECUERDO POPAYAN 4 | K8: REDEBAN | L8: FO-25-1759244 | M8: 45960.494 | N8: 45962.492 | O8: NO | P8: HARDWARE | Q8: ALERT IRRUPTION | R8: ALERT IRRUPTION | S8: UNO A UNO | T8: UNO A UNO | U8: EJECUTADO / CANCELADO | V8: 30/10/2025 SE ESCALA PARA VISITA. LLAMAR ANTES DE VISITAR, CONFIRMAR FALLA Y DATOS | 01/11/2025 SE LLEGA AL SITIO SE ENCUENTRA QUE EL DIA DE AYER EN LA TARDE AL CLIENTE LE MIGRARON A WOMPI POR TANTO NO SE ATIENDE CASO | W8: VISITA TECNICA | X8: NO APLICA | Y8: TIPO III | Z8: TERRESTRE | AA8: GIMBUEL LASSO LUIS GERMAN | AB8: 1 | AC8: 0 | AD8: 275729 | AE8: 196537 | AF8: 275729
A9: CALI | B9: SUROCCIDENTE Y EJE CAFETERO | C9: 0004-0003 | D9: 19001 | E9: 2958800 | F9: 3007035736 | G9: INCIDENTE | H9: CAUCA | I9: POPAYAN | J9: BARRIO LOS HOYOS POPAYAN | K9: REDEBAN | L9: FO-25-1758919 | M9: 45960.489 | N9: 45962.427 | P9: HARDWARE | Q9: LECTOR DE TARJETAS | R9: MENSAJE RETIRE TARJETA | S9: CB UNO A UNO | T9: CB UNO A UNO | V9: 30/10/2025 SE ESCALA PARA VISITA. LLAMAR ANTES DE VISITAR, CONFIRMAR FALLA Y DATOS | 01/11/2025 SE REALIZA LLAMADA CON EL SEÑOR IGNACIO INFORMA EL PIN PAD YA ESTA FUNCIONANDO CORRECTAMENTE YA LEE LAS TARJETAS OK | W9: SOPORTE TELEFONICO | Y9: TIPO III | Z9: TERRESTRE | AA9: GIMBUEL LASSO LUIS GERMAN | AB9: 0 | AC9: 0 | AD9: 41241 | AE9: 0 | AF9: 41241
A10: APARTADO | B10: NOROCCIDENTE | C10: 0004-0005 | D10: 5147 | E10: 2961166 | F10: 3007048955 | G10: INCIDENTE | H10: ANTIOQUIA | I10: CAREPA | J10: DISTRICOL INSUMOS EL PANADERO | K10: REDEBAN | L10: FO-25-1762976 | M10: 45961.333 | N10: 45962.526 | O10: NO | P10: HARDWARE | Q10: NO ENCIENDE | R10: DAÑO POS | S10: AGREGADOR | T10: DISTRICOL | U10: EJECUTADO | V10: 31/10/2025 SE ESCALA PARA VISITA. LLAMAR ANTES DE VISITAR, CONFIRMAR FALLA Y DATOS | 01/11/2025 DATAFONO APAGADO COMPLETAMENTE. DAÑO POS. USUARIA REPORTA QUE SE REINICIABA ALMOMENTO DE HACER UNA TRANSFERENCIA. SE HACE CAMBIO DE DATAFONO, SE CAMBIA LECTORA YA QUE LA ACTUAL NO ES COMPATIBLE CON DATAFONO DESK 2600 TIENE EL CANLE MUY CORTO. SE HACEN PRUEBAS DE CONSULTA DE SALDO,RETIRO Y CONIGNCION DEJANDO TODO OK | W10: VISITA TECNICA | X10: AD00O592 | Y10: TIPO I | Z10: TERRESTRE | AA10: SALDARRIAGA MIRANDA SANTIAGO | AB10: 1 | AC10: 0 | AD10: 65960 | AE10: 75096 | AF10: 65960
A11: CUCUTA | B11: SANTANDERES | C11: 0004-0008 | D11: 54599 | E11: 2961229 | F11: 3007054574 | G11: INCIDENTE | H11: NORTE DE SANTANDER | I11: RAGONVALIA | J11: BARRIO CENTENARIO RAGONVALIA | K11: REDEBAN | L11: FO-25-1762973 | M11: 45961.333 | N11: 45965.555 | O11: NO | P11: HARDWARE | Q11: LECTOR DE TARJETAS | R11: MENSAJE RETIRE TARJETA | S11: CB UNO A UNO | T11: CB UNO A UNO | U11: EJECUTADO | V11: 31/10/2025 SE ESCALA PARA VISITA. LLAMAR ANTES DE VISITAR, CONFIRMAR FALLA Y DATOS | 02/11/2025 SE REALIZA LLAMADA AL NÚMERO 3138511784 Y SE ESTABLECE COMUNICACIÓN CON LA SEÑORA MARTA LOZANO, A QUIEN SE INFORMA QUE, POR MOTIVOS DE DISPONIBILIDAD DE TRANSPORTE Y DÍAS FESTIVOS EN LA ZONA, NO ES POSIBLE EFECTUAR EL DESPLAZAMIENTO AL MUNICIPIO EN LA FECHA PREVISTA. SE REPROGRAMA LA VISITA TÉCNICA PARA EL DÍA 04/11/2025, A PARTIR DE LAS 10:00 A.M. | 04/11/2025 SE VISITA COMERCIO Y SE REALIZA CAMBIO DE DETAFONO POR DAÑO DE RETIRE SU TARJETA, SE REALIZAN CIERRES Y PRUEBAS OK. | W11: VISITA TECNICA | X11: II5ZZ964 | Y11: TIPO III | Z11: TERRESTRE | AA11: TORRES MANTILLA JOSE DANIEL | AB11: 1 | AC11: 0 | AD11: 275729 | AE11: 196537 | AF11: 275729
A12: MEDELLIN | B12: NOROCCIDENTE | C12: 0004-0005 | D12: 5579 | E12: 2961791 | F12: 3007059964 | G12: INCIDENTE | H12: ANTIOQUIA | I12: PUERTO BERRIO | J12: BARRIO BRR CENTRO PUERTO BERRI | K12: REDEBAN | L12: FO-25-1763641 | M12: 45961.37 | N12: 45965.405 | O12: NO | P12: HARDWARE | Q12: SE REINICIA | R12: DAÑO POS | S12: CB UNO A UNO | T12: CB UNO A UNO | U12: EJECUTADO | V12: 31/10/2025 SE ESCALA PARA VISITA. LLAMAR ANTES DE VISITAR, CONFIRMAR FALLA Y DATOS | 03/11/2025 SITIO TIPO III NO SE LOGRÓ VISITAR DÍA SÁBADO POR LEJANÍA DE MUNICIPIO. POR PROBLEMA DE DATAFONO Y SOPORTE PARA CAMBIOS VISITA DEBE SER REALIZADA EN DÍA HÁBIL PARA PODER REALIZAR CAMBIO DE EQUIPO POR REINICIOS. | 04/11/2025 SE CAMBIA EQUIPO POR DAÑO EN PUERTO DE ENERGÍA TODO QUEDA OK | W12: VISITA TECNICA | X12: LA00A058 | Y12: TIPO III | Z12: TERRESTRE | AA12: ALVAREZ ARENAS VICTOR HUGO | AB12: 1 | AC12: 0 | AD12: 275729 | AE12: 196537 | AF12: 275729
A13: MEDELLIN | B13: NOROCCIDENTE | C13: 0004-0005 | D13: 5145 | E13: 2961932 | F13: 3007037596 | G13: INCIDENTE | H13: ANTIOQUIA | I13: CARAMANTA | J13: DISTRICOL SURTICARAMANTA | K13: REDEBAN | L13: FO-25-1763651 | M13: 45961.365 | N13: 45965.51 | O13: NO | P13: SOFTWARE | Q13: COMUNICACION | R13: VERIFIQUE PARAMETROS | S13: AGREGADOR | T13: DISTRICOL | U13: EJECUTADO | V13: 31/10/2025 SE ESCALA PARA VISITA. LLAMAR ANTES DE VISITAR, CONFIRMAR FALLA Y DATOS | 03/11/2025 SITIO TIPO III NO SE LOGRÓ AGENDAR PARA VISITA EL DÍA SÁBADO POR LEJANÍA DE MUNICIPIO. VISITA SERÁ REALIZADA DÍA MARTES. | 04/11/2025 SE REALIZÓ CONFIGURACIÓN DE COMUNICACIÓN | W13: VISITA TECNICA | X13: 9A00Q949 | Y13: TIPO III | Z13: TERRESTRE | AA13: CASTAÑEDA PALACIO CARLOS FELIPE | AB13: 1 | AC13: 0 | AD13: 275729 | AE13: 196537 | AF13: 275729
A14: VILLAVICENCIO | B14: REMOTAS | C14: 0004-0007 | D14: 50001 | E14: 2962225 | F14: 3007059982 | G14: INCIDENTE | H14: META | I14: VILLAVICENCIO | J14: BARRIO BRR ROSA BLANCA VILLAVI | K14: REDEBAN | L14: FO-25-1763638 | M14: 45961.383 | N14: 45962.357 | O14: NO | P14: HARDWARE | Q14: IMPRESION | R14: NO IMPRIME UNO O VARIOS CARACTERES | S14: CB UNO A UNO | T14: CB UNO A UNO | U14: EJECUTADO / CANCELADO | V14: 31/10/2025 SE ESCALA PARA VISITA. LLAMAR ANTES DE VISITAR, CONFIRMAR FALLA Y DATOS | 01/11/2025 SE REALIZA VISITA A COMERCIO LOCAL CERRADO SE REALIZA INTENTO DE COMUNICACIÓN VÍA TELEFÓNICA AL NÚMERO TELEFÓNICO 3203783078 NO ES POSIBLE CONTACTAR A TITULAR | W14: VISITA TECNICA | X14: NA | Y14: TIPO I | Z14: TERRESTRE | AA14: CASTRILLON URREA LONDIER LEANDRO | AB14: 1 | AC14: 0 | AD14: 65960 | AE14: 75096 | AF14: 65960
A15: MEDELLIN | B15: NOROCCIDENTE | C15: 0004-0005 | D15: 5129 | E15: 2962528 | F15: 3007081006 | G15: INCIDENTE | H15: ANTIOQUIA | I15: CALDAS | J15: PTM CALDAS BOTANICASALOMON | K15: REDEBAN | L15: FO-25-1764078 | M15: 45961.406 | N15: 45962.364 | O15: NO | P15: HARDWARE | Q15: LECTOR DE BARRAS | R15: FORMATO INVALIDO LECTOR DAÑADO | S15: AGREGADOR | T15: COMCARD - PTM | U15: EJECUTADO | V15: 31/10/2025 SE ESCALA PARA VISITA. LLAMAR ANTES DE VISITAR, CONFIRMAR FALLA Y DATOS | 31/10/2025 SE REALIZA CAMBIO DE LECTORA YA QUE NO LEÍA LAS FACTURAS. | W15: VISITA TECNICA | X15: FJZZZ896 FJZZZ502 | Y15: TIPO I | Z15: TERRESTRE | AA15: RAMIREZ TABARES JUAN DIEGO | AB15: 1 | AC15: 0 | AD15: 65960 | AE15: 75096 | AF15: 65960
A16: VILLAVICENCIO | B16: REMOTAS | C16: 0004-0007 | D16: 50001 | E16: 2962900 | F16: 3007065243 | G16: INCIDENTE | H16: META | I16: VILLAVICENCIO | J16: BARRIO VEREDA APIAY VILLAVICEN | K16: REDEBAN | L16: FO-25-1764704 | M16: 45961.439 | N16: 45962.397 | O16: NO | P16: HARDWARE | Q16: TECLADO | R16: DAÑO POS | S16: UNO A UNO | T16: CB UNO A UNO | U16: EJECUTADO | V16: 31/10/2025 SE ESCALA PARA VISITA. LLAMAR ANTES DE VISITAR, CONFIRMAR FALLA Y DATOS | 01/11/2025 SE VISITA CB Y SE REALIZA CAMBIO DE DATÁFONO POR DALO RN RL TECLADO. SE INSTALA NUEVO EQUIPO SE CONFIGURA POS SE INICIALIZA SE CREAN USUARIOS CORRECTAMENTE Y SE REALIZA PRUEBAS EXITOSAS PRUEBAS OK | W16: VISITA TECNICA | X16: 2A008782 | Y16: TIPO I | Z16: TERRESTRE | AA16: GARZON RUIZ LUIS MIGUEL | AB16: 1 | AC16: 0 | AD16: 65960 | AE16: 75096 | AF16: 65960
